{
  "version": 8,
  "blockIdVersion": 11,
  "anchorX": 0,
  "anchorY": 4,
  "anchorZ": 0,
  "blocks": [
    {
      "x": -4,
      "y": 2,
      "z": -4,
      "name": "Rock_Sandstone"
    },
    {
      "x": -4,
      "y": 3,
      "z": -4,
      "name": "Soil_Dirt_Dry"
    },
    {
      "x": -4,
      "y": 4,
      "z": -4,
      "name": "Soil_Dirt_Dry"
    },
    {
      "x": -4,
      "y": 2,
      "z": -3,
      "name": "Rock_Sandstone"
    },
    {
      "x": -4,
      "y": 3,
      "z": -3,
      "name": "Soil_Dirt_Dry"
    },
    {
      "x": -4,
      "y": 4,
      "z": -3,
      "name": "Soil_Dirt_Dry"
    },
    {
      "x": -4,
      "y": 2,
      "z": -2,
      "name": "Rock_Sandstone"
    },
    {
      "x": -4,
      "y": 3,
      "z": -2,
      "name": "Soil_Dirt_Dry"
    },
    {
      "x": -4,
      "y": 4,
      "z": -2,
      "name": "Soil_Dirt_Dry"
    },
    {
      "x": -4,
      "y": 2,
      "z": -1,
      "name": "Rock_Sandstone"
    },
    {
      "x": -4,
      "y": 3,
      "z": -1,
      "name": "Soil_Dirt_Dry"
    },
    {
      "x": -4,
      "y": 4,
      "z": -1,
      "name": "Soil_Dirt_Dry"
    },
    {
      "x": -4,
      "y": 2,
      "z": 0,
      "name": "Rock_Sandstone"
    },
    {
      "x": -4,
      "y": 3,
      "z": 0,
      "name": "Soil_Dirt_Dry"
    },
    {
      "x": -4,
      "y": 4,
      "z": 0,
      "name": "Soil_Dirt_Dry"
    },
    {
      "x": -4,
      "y": 2,
      "z": 1,
      "name": "Rock_Sandstone"
    },
    {
      "x": -4,
      "y": 3,
      "z": 1,
      "name": "Soil_Dirt_Dry"
    },
    {
      "x": -4,
      "y": 4,
      "z": 1,
      "name": "Soil_Dirt_Dry"
    },
    {
      "x": -4,
      "y": 2,
      "z": 2,
      "name": "Rock_Sandstone"
    },
    {
      "x": -4,
      "y": 3,
      "z": 2,
      "name": "Soil_Dirt_Dry"
    },
    {
      "x": -4,
      "y": 4,
      "z": 2,
      "name": "Soil_Dirt_Dry"
    },
    {
      "x": -4,
      "y": 2,
      "z": 3,
      "name": "Rock_Sandstone"
    },
    {
      "x": -4,
      "y": 3,
      "z": 3,
      "name": "Soil_Dirt_Dry"
    },
    {
      "x": -4,
      "y": 4,
      "z": 3,
      "name": "Soil_Dirt_Dry"
    },
    {
      "x": -4,
      "y": 2,
      "z": 4,
      "name": "Rock_Sandstone"
    },
    {
      "x": -4,
      "y": 3,
      "z": 4,
      "name": "Soil_Dirt_Dry"
    },
    {
      "x": -4,
      "y": 4,
      "z": 4,
      "name": "Soil_Dirt_Dry"
    },
    {
      "x": -3,
      "y": 2,
      "z": -4,
      "name": "Rock_Sandstone"
    },
    {
      "x": -3,
      "y": 3,
      "z": -4,
      "name": "Soil_Dirt_Dry"
    },
    {
      "x": -3,
      "y": 4,
      "z": -4,
      "name": "Soil_Dirt_Dry"
    },
    {
      "x": -3,
      "y": 1,
      "z": -3,
      "name": "Rock_Sandstone"
    },
    {
      "x": -3,
      "y": 2,
      "z": -3,
      "name": "Rock_Sandstone"
    },
    {
      "x": -3,
      "y": 3,
      "z": -3,
      "name": "Soil_Dirt_Dry"
    },
    {
      "x": -3,
      "y": 4,
      "z": -3,
      "name": "Soil_Dirt_Dry"
    },
    {
      "x": -3,
      "y": 5,
      "z": -3,
      "name": "Wood_Dry_Trunk",
      "support": 15,
      "rotation": 4
    },
    {
      "x": -3,
      "y": 6,
      "z": -3,
      "name": "Cloth_Roof_Hide",
      "rotation": 3
    },
    {
      "x": -3,
      "y": 1,
      "z": -2,
      "name": "Rock_Sandstone"
    },
    {
      "x": -3,
      "y": 2,
      "z": -2,
      "name": "Rock_Sandstone"
    },
    {
      "x": -3,
      "y": 3,
      "z": -2,
      "name": "Soil_Dirt_Dry"
    },
    {
      "x": -3,
      "y": 4,
      "z": -2,
      "name": "Soil_Dirt_Dry"
    },
    {
      "x": -3,
      "y": 5,
      "z": -2,
      "name": "Wood_Dry_Trunk",
      "support": 15,
      "rotation": 4
    },
    {
      "x": -3,
      "y": 6,
      "z": -2,
      "name": "Cloth_Roof_Hide",
      "rotation": 3
    },
    {
      "x": -3,
      "y": 1,
      "z": -1,
      "name": "Rock_Sandstone"
    },
    {
      "x": -3,
      "y": 2,
      "z": -1,
      "name": "Rock_Sandstone"
    },
    {
      "x": -3,
      "y": 3,
      "z": -1,
      "name": "Soil_Dirt_Dry"
    },
    {
      "x": -3,
      "y": 4,
      "z": -1,
      "name": "Soil_Dirt_Dry"
    },
    {
      "x": -3,
      "y": 5,
      "z": -1,
      "name": "Wood_Dry_Trunk",
      "support": 15,
      "rotation": 4
    },
    {
      "x": -3,
      "y": 6,
      "z": -1,
      "name": "Cloth_Roof_Hide",
      "rotation": 3
    },
    {
      "x": -3,
      "y": 1,
      "z": 0,
      "name": "Rock_Sandstone"
    },
    {
      "x": -3,
      "y": 2,
      "z": 0,
      "name": "Rock_Sandstone"
    },
    {
      "x": -3,
      "y": 3,
      "z": 0,
      "name": "Soil_Dirt_Dry"
    },
    {
      "x": -3,
      "y": 4,
      "z": 0,
      "name": "Soil_Dirt_Dry"
    },
    {
      "x": -3,
      "y": 5,
      "z": 0,
      "name": "Wood_Dry_Trunk",
      "support": 15,
      "rotation": 4
    },
    {
      "x": -3,
      "y": 6,
      "z": 0,
      "name": "Cloth_Roof_Hide",
      "rotation": 3
    },
    {
      "x": -3,
      "y": 1,
      "z": 1,
      "name": "Rock_Sandstone"
    },
    {
      "x": -3,
      "y": 2,
      "z": 1,
      "name": "Rock_Sandstone"
    },
    {
      "x": -3,
      "y": 3,
      "z": 1,
      "name": "Soil_Dirt_Dry"
    },
    {
      "x": -3,
      "y": 4,
      "z": 1,
      "name": "Soil_Dirt_Dry"
    },
    {
      "x": -3,
      "y": 5,
      "z": 1,
      "name": "Wood_Dry_Trunk",
      "support": 15,
      "rotation": 4
    },
    {
      "x": -3,
      "y": 6,
      "z": 1,
      "name": "Cloth_Roof_Hide",
      "rotation": 3
    },
    {
      "x": -3,
      "y": 1,
      "z": 2,
      "name": "Rock_Sandstone"
    },
    {
      "x": -3,
      "y": 2,
      "z": 2,
      "name": "Rock_Sandstone"
    },
    {
      "x": -3,
      "y": 3,
      "z": 2,
      "name": "Soil_Dirt_Dry"
    },
    {
      "x": -3,
      "y": 4,
      "z": 2,
      "name": "Soil_Dirt_Dry"
    },
    {
      "x": -3,
      "y": 5,
      "z": 2,
      "name": "Wood_Dry_Trunk",
      "support": 15,
      "rotation": 4
    },
    {
      "x": -3,
      "y": 6,
      "z": 2,
      "name": "Cloth_Roof_Hide",
      "rotation": 3
    },
    {
      "x": -3,
      "y": 1,
      "z": 3,
      "name": "Rock_Sandstone"
    },
    {
      "x": -3,
      "y": 2,
      "z": 3,
      "name": "Rock_Sandstone"
    },
    {
      "x": -3,
      "y": 3,
      "z": 3,
      "name": "Soil_Dirt_Dry"
    },
    {
      "x": -3,
      "y": 4,
      "z": 3,
      "name": "Soil_Dirt_Dry"
    },
    {
      "x": -3,
      "y": 2,
      "z": 4,
      "name": "Rock_Sandstone"
    },
    {
      "x": -3,
      "y": 3,
      "z": 4,
      "name": "Soil_Dirt_Dry"
    },
    {
      "x": -3,
      "y": 4,
      "z": 4,
      "name": "Soil_Dirt_Dry"
    },
    {
      "x": -2,
      "y": 2,
      "z": -4,
      "name": "Rock_Sandstone"
    },
    {
      "x": -2,
      "y": 3,
      "z": -4,
      "name": "Soil_Dirt_Dry"
    },
    {
      "x": -2,
      "y": 4,
      "z": -4,
      "name": "Soil_Dirt_Dry"
    },
    {
      "x": -2,
      "y": 1,
      "z": -3,
      "name": "Rock_Sandstone"
    },
    {
      "x": -2,
      "y": 2,
      "z": -3,
      "name": "Rock_Sandstone"
    },
    {
      "x": -2,
      "y": 3,
      "z": -3,
      "name": "Soil_Dirt_Dry"
    },
    {
      "x": -2,
      "y": 4,
      "z": -3,
      "name": "Soil_Dirt_Dry"
    },
    {
      "x": -2,
      "y": 5,
      "z": -3,
      "name": "Rock_Sandstone_Cobble"
    },
    {
      "x": -2,
      "y": 6,
      "z": -3,
      "name": "Rock_Sandstone_Cobble_Stairs",
      "rotation": 3
    },
    {
      "x": -2,
      "y": 7,
      "z": -3,
      "name": "Cloth_Roof_Hide",
      "rotation": 3
    },
    {
      "x": -2,
      "y": 0,
      "z": -2,
      "name": "Rock_Sandstone"
    },
    {
      "x": -2,
      "y": 1,
      "z": -2,
      "name": "Rock_Sandstone"
    },
    {
      "x": -2,
      "y": 2,
      "z": -2,
      "name": "Rock_Sandstone"
    },
    {
      "x": -2,
      "y": 3,
      "z": -2,
      "name": "Soil_Dirt_Dry"
    },
    {
      "x": -2,
      "y": 4,
      "z": -2,
      "name": "Soil_Dirt_Dry"
    },
    {
      "x": -2,
      "y": 5,
      "z": -2,
      "name": "Furniture_Crude_Bed",
      "components": {
        "Components": {
          "PlacedByInteraction": {
            "WhoPlacedUuid": {
              "$binary": "jmZp6ZgrSpi8/YFXQtu79Q==",
              "$type": "04"
            }
          },
          "RespawnBlock": {}
        }
      }
    },
    {
      "x": -2,
      "y": 7,
      "z": -2,
      "name": "Cloth_Roof_Hide",
      "rotation": 3
    },
    {
      "x": -2,
      "y": 0,
      "z": -1,
      "name": "Rock_Sandstone"
    },
    {
      "x": -2,
      "y": 1,
      "z": -1,
      "name": "Rock_Sandstone"
    },
    {
      "x": -2,
      "y": 2,
      "z": -1,
      "name": "Rock_Sandstone"
    },
    {
      "x": -2,
      "y": 3,
      "z": -1,
      "name": "Soil_Dirt_Dry"
    },
    {
      "x": -2,
      "y": 4,
      "z": -1,
      "name": "Soil_Dirt_Dry"
    },
    {
      "x": -2,
      "y": 5,
      "z": -1,
      "name": "Furniture_Crude_Bed",
      "filler": 32
    },
    {
      "x": -2,
      "y": 7,
      "z": -1,
      "name": "Cloth_Roof_Hide",
      "rotation": 3
    },
    {
      "x": -2,
      "y": 0,
      "z": 0,
      "name": "Rock_Sandstone"
    },
    {
      "x": -2,
      "y": 1,
      "z": 0,
      "name": "Rock_Sandstone"
    },
    {
      "x": -2,
      "y": 2,
      "z": 0,
      "name": "Rock_Sandstone"
    },
    {
      "x": -2,
      "y": 3,
      "z": 0,
      "name": "Soil_Dirt_Dry"
    },
    {
      "x": -2,
      "y": 4,
      "z": 0,
      "name": "Soil_Dirt_Dry"
    },
    {
      "x": -2,
      "y": 7,
      "z": 0,
      "name": "Cloth_Roof_Hide",
      "rotation": 3
    },
    {
      "x": -2,
      "y": 0,
      "z": 1,
      "name": "Rock_Sandstone"
    },
    {
      "x": -2,
      "y": 1,
      "z": 1,
      "name": "Rock_Sandstone"
    },
    {
      "x": -2,
      "y": 2,
      "z": 1,
      "name": "Rock_Sandstone"
    },
    {
      "x": -2,
      "y": 3,
      "z": 1,
      "name": "Soil_Dirt_Dry"
    },
    {
      "x": -2,
      "y": 4,
      "z": 1,
      "name": "Soil_Dirt_Dry"
    },
    {
      "x": -2,
      "y": 7,
      "z": 1,
      "name": "Cloth_Roof_Hide",
      "rotation": 3
    },
    {
      "x": -2,
      "y": 0,
      "z": 2,
      "name": "Rock_Sandstone"
    },
    {
      "x": -2,
      "y": 1,
      "z": 2,
      "name": "Rock_Sandstone"
    },
    {
      "x": -2,
      "y": 2,
      "z": 2,
      "name": "Rock_Sandstone"
    },
    {
      "x": -2,
      "y": 3,
      "z": 2,
      "name": "Soil_Dirt_Dry"
    },
    {
      "x": -2,
      "y": 4,
      "z": 2,
      "name": "Soil_Dirt_Dry"
    },
    {
      "x": -2,
      "y": 7,
      "z": 2,
      "name": "Cloth_Roof_Hide",
      "rotation": 3
    },
    {
      "x": -2,
      "y": 1,
      "z": 3,
      "name": "Rock_Sandstone"
    },
    {
      "x": -2,
      "y": 2,
      "z": 3,
      "name": "Rock_Sandstone"
    },
    {
      "x": -2,
      "y": 3,
      "z": 3,
      "name": "Soil_Dirt_Dry"
    },
    {
      "x": -2,
      "y": 4,
      "z": 3,
      "name": "Soil_Dirt_Dry"
    },
    {
      "x": -2,
      "y": 2,
      "z": 4,
      "name": "Rock_Sandstone"
    },
    {
      "x": -2,
      "y": 3,
      "z": 4,
      "name": "Soil_Dirt_Dry"
    },
    {
      "x": -2,
      "y": 4,
      "z": 4,
      "name": "Soil_Dirt_Dry"
    },
    {
      "x": -1,
      "y": 2,
      "z": -4,
      "name": "Rock_Sandstone"
    },
    {
      "x": -1,
      "y": 3,
      "z": -4,
      "name": "Soil_Dirt_Dry"
    },
    {
      "x": -1,
      "y": 4,
      "z": -4,
      "name": "Soil_Dirt_Dry"
    },
    {
      "x": -1,
      "y": 1,
      "z": -3,
      "name": "Rock_Sandstone"
    },
    {
      "x": -1,
      "y": 2,
      "z": -3,
      "name": "Rock_Sandstone"
    },
    {
      "x": -1,
      "y": 3,
      "z": -3,
      "name": "Soil_Dirt_Dry"
    },
    {
      "x": -1,
      "y": 4,
      "z": -3,
      "name": "Soil_Dirt_Dry"
    },
    {
      "x": -1,
      "y": 5,
      "z": -3,
      "name": "Rock_Sandstone_Cobble"
    },
    {
      "x": -1,
      "y": 6,
      "z": -3,
      "name": "Rock_Sandstone_Cobble"
    },
    {
      "x": -1,
      "y": 7,
      "z": -3,
      "name": "Rock_Sandstone_Cobble_Stairs",
      "rotation": 3
    },
    {
      "x": -1,
      "y": 8,
      "z": -3,
      "name": "Cloth_Roof_Hide",
      "rotation": 3
    },
    {
      "x": -1,
      "y": 0,
      "z": -2,
      "name": "Rock_Sandstone"
    },
    {
      "x": -1,
      "y": 1,
      "z": -2,
      "name": "Rock_Sandstone"
    },
    {
      "x": -1,
      "y": 2,
      "z": -2,
      "name": "Rock_Sandstone"
    },
    {
      "x": -1,
      "y": 3,
      "z": -2,
      "name": "Soil_Dirt_Dry"
    },
    {
      "x": -1,
      "y": 4,
      "z": -2,
      "name": "Soil_Dirt_Dry"
    },
    {
      "x": -1,
      "y": 8,
      "z": -2,
      "name": "Cloth_Roof_Hide",
      "rotation": 3
    },
    {
      "x": -1,
      "y": 0,
      "z": -1,
      "name": "Rock_Sandstone"
    },
    {
      "x": -1,
      "y": 1,
      "z": -1,
      "name": "Rock_Sandstone"
    },
    {
      "x": -1,
      "y": 2,
      "z": -1,
      "name": "Rock_Sandstone"
    },
    {
      "x": -1,
      "y": 3,
      "z": -1,
      "name": "Soil_Dirt_Dry"
    },
    {
      "x": -1,
      "y": 4,
      "z": -1,
      "name": "Soil_Dirt_Dry"
    },
    {
      "x": -1,
      "y": 8,
      "z": -1,
      "name": "Cloth_Roof_Hide",
      "rotation": 3
    },
    {
      "x": -1,
      "y": 0,
      "z": 0,
      "name": "Rock_Sandstone"
    },
    {
      "x": -1,
      "y": 1,
      "z": 0,
      "name": "Rock_Sandstone"
    },
    {
      "x": -1,
      "y": 2,
      "z": 0,
      "name": "Rock_Sandstone"
    },
    {
      "x": -1,
      "y": 3,
      "z": 0,
      "name": "Soil_Dirt_Dry"
    },
    {
      "x": -1,
      "y": 4,
      "z": 0,
      "name": "Soil_Dirt_Dry"
    },
    {
      "x": -1,
      "y": 8,
      "z": 0,
      "name": "Cloth_Roof_Hide",
      "rotation": 3
    },
    {
      "x": -1,
      "y": 0,
      "z": 1,
      "name": "Rock_Sandstone"
    },
    {
      "x": -1,
      "y": 1,
      "z": 1,
      "name": "Rock_Sandstone"
    },
    {
      "x": -1,
      "y": 2,
      "z": 1,
      "name": "Rock_Sandstone"
    },
    {
      "x": -1,
      "y": 3,
      "z": 1,
      "name": "Soil_Dirt_Dry"
    },
    {
      "x": -1,
      "y": 4,
      "z": 1,
      "name": "Soil_Dirt_Dry"
    },
    {
      "x": -1,
      "y": 8,
      "z": 1,
      "name": "Cloth_Roof_Hide",
      "rotation": 3
    },
    {
      "x": -1,
      "y": 0,
      "z": 2,
      "name": "Rock_Sandstone"
    },
    {
      "x": -1,
      "y": 1,
      "z": 2,
      "name": "Rock_Sandstone"
    },
    {
      "x": -1,
      "y": 2,
      "z": 2,
      "name": "Rock_Sandstone"
    },
    {
      "x": -1,
      "y": 3,
      "z": 2,
      "name": "Soil_Dirt_Dry"
    },
    {
      "x": -1,
      "y": 4,
      "z": 2,
      "name": "Soil_Dirt_Dry"
    },
    {
      "x": -1,
      "y": 8,
      "z": 2,
      "name": "Cloth_Roof_Hide",
      "rotation": 3
    },
    {
      "x": -1,
      "y": 1,
      "z": 3,
      "name": "Rock_Sandstone"
    },
    {
      "x": -1,
      "y": 2,
      "z": 3,
      "name": "Rock_Sandstone"
    },
    {
      "x": -1,
      "y": 3,
      "z": 3,
      "name": "Soil_Dirt_Dry"
    },
    {
      "x": -1,
      "y": 4,
      "z": 3,
      "name": "Soil_Dirt_Dry"
    },
    {
      "x": -1,
      "y": 2,
      "z": 4,
      "name": "Rock_Sandstone"
    },
    {
      "x": -1,
      "y": 3,
      "z": 4,
      "name": "Soil_Dirt_Dry"
    },
    {
      "x": -1,
      "y": 4,
      "z": 4,
      "name": "Soil_Dirt_Dry"
    },
    {
      "x": 0,
      "y": 2,
      "z": -4,
      "name": "Rock_Sandstone"
    },
    {
      "x": 0,
      "y": 3,
      "z": -4,
      "name": "Soil_Dirt_Dry"
    },
    {
      "x": 0,
      "y": 4,
      "z": -4,
      "name": "Soil_Dirt_Dry"
    },
    {
      "x": 0,
      "y": 1,
      "z": -3,
      "name": "Rock_Sandstone"
    },
    {
      "x": 0,
      "y": 2,
      "z": -3,
      "name": "Rock_Sandstone"
    },
    {
      "x": 0,
      "y": 3,
      "z": -3,
      "name": "Soil_Dirt_Dry"
    },
    {
      "x": 0,
      "y": 4,
      "z": -3,
      "name": "Soil_Dirt_Dry"
    },
    {
      "x": 0,
      "y": 5,
      "z": -3,
      "name": "Wood_Dry_Trunk_Full",
      "support": 15
    },
    {
      "x": 0,
      "y": 6,
      "z": -3,
      "name": "Wood_Dry_Trunk",
      "support": 15
    },
    {
      "x": 0,
      "y": 7,
      "z": -3,
      "name": "Wood_Dry_Trunk",
      "support": 15
    },
    {
      "x": 0,
      "y": 8,
      "z": -3,
      "name": "Wood_Dry_Trunk",
      "support": 15
    },
    {
      "x": 0,
      "y": 9,
      "z": -3,
      "name": "Cloth_Roof_Hide_Flat"
    },
    {
      "x": 0,
      "y": 0,
      "z": -2,
      "name": "Rock_Sandstone"
    },
    {
      "x": 0,
      "y": 1,
      "z": -2,
      "name": "Rock_Sandstone"
    },
    {
      "x": 0,
      "y": 2,
      "z": -2,
      "name": "Rock_Sandstone"
    },
    {
      "x": 0,
      "y": 3,
      "z": -2,
      "name": "Soil_Dirt_Dry"
    },
    {
      "x": 0,
      "y": 4,
      "z": -2,
      "name": "Soil_Dirt_Dry"
    },
    {
      "x": 0,
      "y": 8,
      "z": -2,
      "name": "Wood_Dry_Trunk",
      "support": 15,
      "rotation": 4
    },
    {
      "x": 0,
      "y": 9,
      "z": -2,
      "name": "Cloth_Roof_Hide_Flat"
    },
    {
      "x": 0,
      "y": 0,
      "z": -1,
      "name": "Rock_Sandstone"
    },
    {
      "x": 0,
      "y": 1,
      "z": -1,
      "name": "Rock_Sandstone"
    },
    {
      "x": 0,
      "y": 2,
      "z": -1,
      "name": "Rock_Sandstone"
    },
    {
      "x": 0,
      "y": 3,
      "z": -1,
      "name": "Soil_Dirt_Dry"
    },
    {
      "x": 0,
      "y": 4,
      "z": -1,
      "name": "Soil_Dirt_Dry"
    },
    {
      "x": 0,
      "y": 8,
      "z": -1,
      "name": "Wood_Dry_Trunk",
      "support": 15,
      "rotation": 4
    },
    {
      "x": 0,
      "y": 9,
      "z": -1,
      "name": "Cloth_Roof_Hide_Flat"
    },
    {
      "x": 0,
      "y": 0,
      "z": 0,
      "name": "Rock_Sandstone"
    },
    {
      "x": 0,
      "y": 1,
      "z": 0,
      "name": "Rock_Sandstone"
    },
    {
      "x": 0,
      "y": 2,
      "z": 0,
      "name": "Rock_Sandstone"
    },
    {
      "x": 0,
      "y": 3,
      "z": 0,
      "name": "Soil_Dirt_Dry"
    },
    {
      "x": 0,
      "y": 4,
      "z": 0,
      "name": "Rock_Sandstone"
    },
    {
      "x": 0,
      "y": 5,
      "z": 0,
      "name": "Furniture_Crude_Brazier"
    },
    {
      "x": 0,
      "y": 8,
      "z": 0,
      "name": "Wood_Dry_Trunk",
      "support": 15,
      "rotation": 4
    },
    {
      "x": 0,
      "y": 9,
      "z": 0,
      "name": "Cloth_Roof_Hide_Flat"
    },
    {
      "x": 0,
      "y": 0,
      "z": 1,
      "name": "Rock_Sandstone"
    },
    {
      "x": 0,
      "y": 1,
      "z": 1,
      "name": "Rock_Sandstone"
    },
    {
      "x": 0,
      "y": 2,
      "z": 1,
      "name": "Rock_Sandstone"
    },
    {
      "x": 0,
      "y": 3,
      "z": 1,
      "name": "Soil_Dirt_Dry"
    },
    {
      "x": 0,
      "y": 4,
      "z": 1,
      "name": "Soil_Dirt_Dry"
    },
    {
      "x": 0,
      "y": 8,
      "z": 1,
      "name": "Wood_Dry_Trunk",
      "support": 15,
      "rotation": 4
    },
    {
      "x": 0,
      "y": 9,
      "z": 1,
      "name": "Cloth_Roof_Hide_Flat"
    },
    {
      "x": 0,
      "y": 0,
      "z": 2,
      "name": "Rock_Sandstone"
    },
    {
      "x": 0,
      "y": 1,
      "z": 2,
      "name": "Rock_Sandstone"
    },
    {
      "x": 0,
      "y": 2,
      "z": 2,
      "name": "Rock_Sandstone"
    },
    {
      "x": 0,
      "y": 3,
      "z": 2,
      "name": "Soil_Dirt_Dry"
    },
    {
      "x": 0,
      "y": 4,
      "z": 2,
      "name": "Soil_Dirt_Dry"
    },
    {
      "x": 0,
      "y": 5,
      "z": 2,
      "name": "Wood_Dry_Branch_Long",
      "support": 15
    },
    {
      "x": 0,
      "y": 6,
      "z": 2,
      "name": "Wood_Dry_Branch_Long",
      "support": 15
    },
    {
      "x": 0,
      "y": 7,
      "z": 2,
      "name": "Wood_Dry_Branch_Long",
      "support": 15
    },
    {
      "x": 0,
      "y": 8,
      "z": 2,
      "name": "Wood_Dry_Trunk",
      "support": 15,
      "rotation": 4
    },
    {
      "x": 0,
      "y": 9,
      "z": 2,
      "name": "Cloth_Roof_Hide_Flat"
    },
    {
      "x": 0,
      "y": 1,
      "z": 3,
      "name": "Rock_Sandstone"
    },
    {
      "x": 0,
      "y": 2,
      "z": 3,
      "name": "Rock_Sandstone"
    },
    {
      "x": 0,
      "y": 3,
      "z": 3,
      "name": "Soil_Dirt_Dry"
    },
    {
      "x": 0,
      "y": 4,
      "z": 3,
      "name": "Soil_Dirt_Dry"
    },
    {
      "x": 0,
      "y": 2,
      "z": 4,
      "name": "Rock_Sandstone"
    },
    {
      "x": 0,
      "y": 3,
      "z": 4,
      "name": "Soil_Dirt_Dry"
    },
    {
      "x": 0,
      "y": 4,
      "z": 4,
      "name": "Soil_Dirt_Dry"
    },
    {
      "x": 1,
      "y": 2,
      "z": -4,
      "name": "Rock_Sandstone"
    },
    {
      "x": 1,
      "y": 3,
      "z": -4,
      "name": "Soil_Dirt_Dry"
    },
    {
      "x": 1,
      "y": 4,
      "z": -4,
      "name": "Soil_Dirt_Dry"
    },
    {
      "x": 1,
      "y": 1,
      "z": -3,
      "name": "Rock_Sandstone"
    },
    {
      "x": 1,
      "y": 2,
      "z": -3,
      "name": "Rock_Sandstone"
    },
    {
      "x": 1,
      "y": 3,
      "z": -3,
      "name": "Soil_Dirt_Dry"
    },
    {
      "x": 1,
      "y": 4,
      "z": -3,
      "name": "Soil_Dirt_Dry"
    },
    {
      "x": 1,
      "y": 5,
      "z": -3,
      "name": "Rock_Sandstone_Cobble"
    },
    {
      "x": 1,
      "y": 6,
      "z": -3,
      "name": "Rock_Sandstone_Cobble"
    },
    {
      "x": 1,
      "y": 7,
      "z": -3,
      "name": "Rock_Sandstone_Cobble_Stairs",
      "rotation": 1
    },
    {
      "x": 1,
      "y": 8,
      "z": -3,
      "name": "Cloth_Roof_Hide",
      "rotation": 1
    },
    {
      "x": 1,
      "y": 0,
      "z": -2,
      "name": "Rock_Sandstone"
    },
    {
      "x": 1,
      "y": 1,
      "z": -2,
      "name": "Rock_Sandstone"
    },
    {
      "x": 1,
      "y": 2,
      "z": -2,
      "name": "Rock_Sandstone"
    },
    {
      "x": 1,
      "y": 3,
      "z": -2,
      "name": "Soil_Dirt_Dry"
    },
    {
      "x": 1,
      "y": 4,
      "z": -2,
      "name": "Soil_Dirt_Dry"
    },
    {
      "x": 1,
      "y": 8,
      "z": -2,
      "name": "Cloth_Roof_Hide",
      "rotation": 1
    },
    {
      "x": 1,
      "y": 0,
      "z": -1,
      "name": "Rock_Sandstone"
    },
    {
      "x": 1,
      "y": 1,
      "z": -1,
      "name": "Rock_Sandstone"
    },
    {
      "x": 1,
      "y": 2,
      "z": -1,
      "name": "Rock_Sandstone"
    },
    {
      "x": 1,
      "y": 3,
      "z": -1,
      "name": "Soil_Dirt_Dry"
    },
    {
      "x": 1,
      "y": 4,
      "z": -1,
      "name": "Soil_Dirt_Dry"
    },
    {
      "x": 1,
      "y": 8,
      "z": -1,
      "name": "Cloth_Roof_Hide",
      "rotation": 1
    },
    {
      "x": 1,
      "y": 0,
      "z": 0,
      "name": "Rock_Sandstone"
    },
    {
      "x": 1,
      "y": 1,
      "z": 0,
      "name": "Rock_Sandstone"
    },
    {
      "x": 1,
      "y": 2,
      "z": 0,
      "name": "Rock_Sandstone"
    },
    {
      "x": 1,
      "y": 3,
      "z": 0,
      "name": "Soil_Dirt_Dry"
    },
    {
      "x": 1,
      "y": 4,
      "z": 0,
      "name": "Soil_Dirt_Dry"
    },
    {
      "x": 1,
      "y": 8,
      "z": 0,
      "name": "Cloth_Roof_Hide",
      "rotation": 1
    },
    {
      "x": 1,
      "y": 0,
      "z": 1,
      "name": "Rock_Sandstone"
    },
    {
      "x": 1,
      "y": 1,
      "z": 1,
      "name": "Rock_Sandstone"
    },
    {
      "x": 1,
      "y": 2,
      "z": 1,
      "name": "Rock_Sandstone"
    },
    {
      "x": 1,
      "y": 3,
      "z": 1,
      "name": "Soil_Dirt_Dry"
    },
    {
      "x": 1,
      "y": 4,
      "z": 1,
      "name": "Soil_Dirt_Dry"
    },
    {
      "x": 1,
      "y": 8,
      "z": 1,
      "name": "Cloth_Roof_Hide",
      "rotation": 1
    },
    {
      "x": 1,
      "y": 0,
      "z": 2,
      "name": "Rock_Sandstone"
    },
    {
      "x": 1,
      "y": 1,
      "z": 2,
      "name": "Rock_Sandstone"
    },
    {
      "x": 1,
      "y": 2,
      "z": 2,
      "name": "Rock_Sandstone"
    },
    {
      "x": 1,
      "y": 3,
      "z": 2,
      "name": "Soil_Dirt_Dry"
    },
    {
      "x": 1,
      "y": 4,
      "z": 2,
      "name": "Soil_Dirt_Dry"
    },
    {
      "x": 1,
      "y": 8,
      "z": 2,
      "name": "Cloth_Roof_Hide",
      "rotation": 1
    },
    {
      "x": 1,
      "y": 1,
      "z": 3,
      "name": "Rock_Sandstone"
    },
    {
      "x": 1,
      "y": 2,
      "z": 3,
      "name": "Rock_Sandstone"
    },
    {
      "x": 1,
      "y": 3,
      "z": 3,
      "name": "Soil_Dirt_Dry"
    },
    {
      "x": 1,
      "y": 4,
      "z": 3,
      "name": "Soil_Dirt_Dry"
    },
    {
      "x": 1,
      "y": 2,
      "z": 4,
      "name": "Rock_Sandstone"
    },
    {
      "x": 1,
      "y": 3,
      "z": 4,
      "name": "Soil_Dirt_Dry"
    },
    {
      "x": 1,
      "y": 4,
      "z": 4,
      "name": "Soil_Dirt_Dry"
    },
    {
      "x": 2,
      "y": 2,
      "z": -4,
      "name": "Rock_Sandstone"
    },
    {
      "x": 2,
      "y": 3,
      "z": -4,
      "name": "Soil_Dirt_Dry"
    },
    {
      "x": 2,
      "y": 4,
      "z": -4,
      "name": "Soil_Dirt_Dry"
    },
    {
      "x": 2,
      "y": 1,
      "z": -3,
      "name": "Rock_Sandstone"
    },
    {
      "x": 2,
      "y": 2,
      "z": -3,
      "name": "Rock_Sandstone"
    },
    {
      "x": 2,
      "y": 3,
      "z": -3,
      "name": "Soil_Dirt_Dry"
    },
    {
      "x": 2,
      "y": 4,
      "z": -3,
      "name": "Soil_Dirt_Dry"
    },
    {
      "x": 2,
      "y": 5,
      "z": -3,
      "name": "Rock_Sandstone_Cobble"
    },
    {
      "x": 2,
      "y": 6,
      "z": -3,
      "name": "Rock_Sandstone_Cobble_Stairs",
      "rotation": 1
    },
    {
      "x": 2,
      "y": 7,
      "z": -3,
      "name": "Cloth_Roof_Hide",
      "rotation": 1
    },
    {
      "x": 2,
      "y": 0,
      "z": -2,
      "name": "Rock_Sandstone"
    },
    {
      "x": 2,
      "y": 1,
      "z": -2,
      "name": "Rock_Sandstone"
    },
    {
      "x": 2,
      "y": 2,
      "z": -2,
      "name": "Rock_Sandstone"
    },
    {
      "x": 2,
      "y": 3,
      "z": -2,
      "name": "Soil_Dirt_Dry"
    },
    {
      "x": 2,
      "y": 4,
      "z": -2,
      "name": "Soil_Dirt_Dry"
    },
    {
      "x": 2,
      "y": 5,
      "z": -2,
      "name": "Furniture_Crude_Bed",
      "components": {
        "Components": {
          "PlacedByInteraction": {
            "WhoPlacedUuid": {
              "$binary": "jmZp6ZgrSpi8/YFXQtu79Q==",
              "$type": "04"
            }
          },
          "RespawnBlock": {}
        }
      }
    },
    {
      "x": 2,
      "y": 7,
      "z": -2,
      "name": "Cloth_Roof_Hide",
      "rotation": 1
    },
    {
      "x": 2,
      "y": 0,
      "z": -1,
      "name": "Rock_Sandstone"
    },
    {
      "x": 2,
      "y": 1,
      "z": -1,
      "name": "Rock_Sandstone"
    },
    {
      "x": 2,
      "y": 2,
      "z": -1,
      "name": "Rock_Sandstone"
    },
    {
      "x": 2,
      "y": 3,
      "z": -1,
      "name": "Soil_Dirt_Dry"
    },
    {
      "x": 2,
      "y": 4,
      "z": -1,
      "name": "Soil_Dirt_Dry"
    },
    {
      "x": 2,
      "y": 5,
      "z": -1,
      "name": "Furniture_Crude_Bed",
      "filler": 32
    },
    {
      "x": 2,
      "y": 7,
      "z": -1,
      "name": "Cloth_Roof_Hide",
      "rotation": 1
    },
    {
      "x": 2,
      "y": 0,
      "z": 0,
      "name": "Rock_Sandstone"
    },
    {
      "x": 2,
      "y": 1,
      "z": 0,
      "name": "Rock_Sandstone"
    },
    {
      "x": 2,
      "y": 2,
      "z": 0,
      "name": "Rock_Sandstone"
    },
    {
      "x": 2,
      "y": 3,
      "z": 0,
      "name": "Soil_Dirt_Dry"
    },
    {
      "x": 2,
      "y": 4,
      "z": 0,
      "name": "Soil_Dirt_Dry"
    },
    {
      "x": 2,
      "y": 7,
      "z": 0,
      "name": "Cloth_Roof_Hide",
      "rotation": 1
    },
    {
      "x": 2,
      "y": 0,
      "z": 1,
      "name": "Rock_Sandstone"
    },
    {
      "x": 2,
      "y": 1,
      "z": 1,
      "name": "Rock_Sandstone"
    },
    {
      "x": 2,
      "y": 2,
      "z": 1,
      "name": "Rock_Sandstone"
    },
    {
      "x": 2,
      "y": 3,
      "z": 1,
      "name": "Soil_Dirt_Dry"
    },
    {
      "x": 2,
      "y": 4,
      "z": 1,
      "name": "Soil_Dirt_Dry"
    },
    {
      "x": 2,
      "y": 7,
      "z": 1,
      "name": "Cloth_Roof_Hide",
      "rotation": 1
    },
    {
      "x": 2,
      "y": 0,
      "z": 2,
      "name": "Rock_Sandstone"
    },
    {
      "x": 2,
      "y": 1,
      "z": 2,
      "name": "Rock_Sandstone"
    },
    {
      "x": 2,
      "y": 2,
      "z": 2,
      "name": "Rock_Sandstone"
    },
    {
      "x": 2,
      "y": 3,
      "z": 2,
      "name": "Soil_Dirt_Dry"
    },
    {
      "x": 2,
      "y": 4,
      "z": 2,
      "name": "Soil_Dirt_Dry"
    },
    {
      "x": 2,
      "y": 7,
      "z": 2,
      "name": "Cloth_Roof_Hide",
      "rotation": 1
    },
    {
      "x": 2,
      "y": 1,
      "z": 3,
      "name": "Rock_Sandstone"
    },
    {
      "x": 2,
      "y": 2,
      "z": 3,
      "name": "Rock_Sandstone"
    },
    {
      "x": 2,
      "y": 3,
      "z": 3,
      "name": "Soil_Dirt_Dry"
    },
    {
      "x": 2,
      "y": 4,
      "z": 3,
      "name": "Soil_Dirt_Dry"
    },
    {
      "x": 2,
      "y": 2,
      "z": 4,
      "name": "Rock_Sandstone"
    },
    {
      "x": 2,
      "y": 3,
      "z": 4,
      "name": "Soil_Dirt_Dry"
    },
    {
      "x": 2,
      "y": 4,
      "z": 4,
      "name": "Soil_Dirt_Dry"
    },
    {
      "x": 3,
      "y": 2,
      "z": -4,
      "name": "Rock_Sandstone"
    },
    {
      "x": 3,
      "y": 3,
      "z": -4,
      "name": "Soil_Dirt_Dry"
    },
    {
      "x": 3,
      "y": 4,
      "z": -4,
      "name": "Soil_Dirt_Dry"
    },
    {
      "x": 3,
      "y": 1,
      "z": -3,
      "name": "Rock_Sandstone"
    },
    {
      "x": 3,
      "y": 2,
      "z": -3,
      "name": "Rock_Sandstone"
    },
    {
      "x": 3,
      "y": 3,
      "z": -3,
      "name": "Soil_Dirt_Dry"
    },
    {
      "x": 3,
      "y": 4,
      "z": -3,
      "name": "Soil_Dirt_Dry"
    },
    {
      "x": 3,
      "y": 5,
      "z": -3,
      "name": "Wood_Dry_Trunk",
      "support": 15,
      "rotation": 4
    },
    {
      "x": 3,
      "y": 6,
      "z": -3,
      "name": "Cloth_Roof_Hide",
      "rotation": 1
    },
    {
      "x": 3,
      "y": 1,
      "z": -2,
      "name": "Rock_Sandstone"
    },
    {
      "x": 3,
      "y": 2,
      "z": -2,
      "name": "Rock_Sandstone"
    },
    {
      "x": 3,
      "y": 3,
      "z": -2,
      "name": "Soil_Dirt_Dry"
    },
    {
      "x": 3,
      "y": 4,
      "z": -2,
      "name": "Soil_Dirt_Dry"
    },
    {
      "x": 3,
      "y": 5,
      "z": -2,
      "name": "Wood_Dry_Trunk",
      "support": 15,
      "rotation": 4
    },
    {
      "x": 3,
      "y": 6,
      "z": -2,
      "name": "Cloth_Roof_Hide",
      "rotation": 1
    },
    {
      "x": 3,
      "y": 1,
      "z": -1,
      "name": "Rock_Sandstone"
    },
    {
      "x": 3,
      "y": 2,
      "z": -1,
      "name": "Rock_Sandstone"
    },
    {
      "x": 3,
      "y": 3,
      "z": -1,
      "name": "Soil_Dirt_Dry"
    },
    {
      "x": 3,
      "y": 4,
      "z": -1,
      "name": "Soil_Dirt_Dry"
    },
    {
      "x": 3,
      "y": 5,
      "z": -1,
      "name": "Wood_Dry_Trunk",
      "support": 15,
      "rotation": 4
    },
    {
      "x": 3,
      "y": 6,
      "z": -1,
      "name": "Cloth_Roof_Hide",
      "rotation": 1
    },
    {
      "x": 3,
      "y": 1,
      "z": 0,
      "name": "Rock_Sandstone"
    },
    {
      "x": 3,
      "y": 2,
      "z": 0,
      "name": "Rock_Sandstone"
    },
    {
      "x": 3,
      "y": 3,
      "z": 0,
      "name": "Soil_Dirt_Dry"
    },
    {
      "x": 3,
      "y": 4,
      "z": 0,
      "name": "Soil_Dirt_Dry"
    },
    {
      "x": 3,
      "y": 5,
      "z": 0,
      "name": "Wood_Dry_Trunk",
      "support": 15,
      "rotation": 4
    },
    {
      "x": 3,
      "y": 6,
      "z": 0,
      "name": "Cloth_Roof_Hide",
      "rotation": 1
    },
    {
      "x": 3,
      "y": 1,
      "z": 1,
      "name": "Rock_Sandstone"
    },
    {
      "x": 3,
      "y": 2,
      "z": 1,
      "name": "Rock_Sandstone"
    },
    {
      "x": 3,
      "y": 3,
      "z": 1,
      "name": "Soil_Dirt_Dry"
    },
    {
      "x": 3,
      "y": 4,
      "z": 1,
      "name": "Soil_Dirt_Dry"
    },
    {
      "x": 3,
      "y": 5,
      "z": 1,
      "name": "Wood_Dry_Trunk",
      "support": 15,
      "rotation": 4
    },
    {
      "x": 3,
      "y": 6,
      "z": 1,
      "name": "Cloth_Roof_Hide",
      "rotation": 1
    },
    {
      "x": 3,
      "y": 1,
      "z": 2,
      "name": "Rock_Sandstone"
    },
    {
      "x": 3,
      "y": 2,
      "z": 2,
      "name": "Rock_Sandstone"
    },
    {
      "x": 3,
      "y": 3,
      "z": 2,
      "name": "Soil_Dirt_Dry"
    },
    {
      "x": 3,
      "y": 4,
      "z": 2,
      "name": "Soil_Dirt_Dry"
    },
    {
      "x": 3,
      "y": 5,
      "z": 2,
      "name": "Wood_Dry_Trunk",
      "support": 15,
      "rotation": 4
    },
    {
      "x": 3,
      "y": 6,
      "z": 2,
      "name": "Cloth_Roof_Hide",
      "rotation": 1
    },
    {
      "x": 3,
      "y": 1,
      "z": 3,
      "name": "Rock_Sandstone"
    },
    {
      "x": 3,
      "y": 2,
      "z": 3,
      "name": "Rock_Sandstone"
    },
    {
      "x": 3,
      "y": 3,
      "z": 3,
      "name": "Soil_Dirt_Dry"
    },
    {
      "x": 3,
      "y": 4,
      "z": 3,
      "name": "Soil_Dirt_Dry"
    },
    {
      "x": 3,
      "y": 2,
      "z": 4,
      "name": "Rock_Sandstone"
    },
    {
      "x": 3,
      "y": 3,
      "z": 4,
      "name": "Soil_Dirt_Dry"
    },
    {
      "x": 3,
      "y": 4,
      "z": 4,
      "name": "Soil_Dirt_Dry"
    },
    {
      "x": 4,
      "y": 2,
      "z": -4,
      "name": "Rock_Sandstone"
    },
    {
      "x": 4,
      "y": 3,
      "z": -4,
      "name": "Soil_Dirt_Dry"
    },
    {
      "x": 4,
      "y": 4,
      "z": -4,
      "name": "Soil_Dirt_Dry"
    },
    {
      "x": 4,
      "y": 2,
      "z": -3,
      "name": "Rock_Sandstone"
    },
    {
      "x": 4,
      "y": 3,
      "z": -3,
      "name": "Soil_Dirt_Dry"
    },
    {
      "x": 4,
      "y": 4,
      "z": -3,
      "name": "Soil_Dirt_Dry"
    },
    {
      "x": 4,
      "y": 2,
      "z": -2,
      "name": "Rock_Sandstone"
    },
    {
      "x": 4,
      "y": 3,
      "z": -2,
      "name": "Soil_Dirt_Dry"
    },
    {
      "x": 4,
      "y": 4,
      "z": -2,
      "name": "Soil_Dirt_Dry"
    },
    {
      "x": 4,
      "y": 2,
      "z": -1,
      "name": "Rock_Sandstone"
    },
    {
      "x": 4,
      "y": 3,
      "z": -1,
      "name": "Soil_Dirt_Dry"
    },
    {
      "x": 4,
      "y": 4,
      "z": -1,
      "name": "Soil_Dirt_Dry"
    },
    {
      "x": 4,
      "y": 2,
      "z": 0,
      "name": "Rock_Sandstone"
    },
    {
      "x": 4,
      "y": 3,
      "z": 0,
      "name": "Soil_Dirt_Dry"
    },
    {
      "x": 4,
      "y": 4,
      "z": 0,
      "name": "Soil_Dirt_Dry"
    },
    {
      "x": 4,
      "y": 2,
      "z": 1,
      "name": "Rock_Sandstone"
    },
    {
      "x": 4,
      "y": 3,
      "z": 1,
      "name": "Soil_Dirt_Dry"
    },
    {
      "x": 4,
      "y": 4,
      "z": 1,
      "name": "Soil_Dirt_Dry"
    },
    {
      "x": 4,
      "y": 2,
      "z": 2,
      "name": "Rock_Sandstone"
    },
    {
      "x": 4,
      "y": 3,
      "z": 2,
      "name": "Soil_Dirt_Dry"
    },
    {
      "x": 4,
      "y": 4,
      "z": 2,
      "name": "Soil_Dirt_Dry"
    },
    {
      "x": 4,
      "y": 2,
      "z": 3,
      "name": "Rock_Sandstone"
    },
    {
      "x": 4,
      "y": 3,
      "z": 3,
      "name": "Soil_Dirt_Dry"
    },
    {
      "x": 4,
      "y": 4,
      "z": 3,
      "name": "Soil_Dirt_Dry"
    },
    {
      "x": 4,
      "y": 2,
      "z": 4,
      "name": "Rock_Sandstone"
    },
    {
      "x": 4,
      "y": 3,
      "z": 4,
      "name": "Soil_Dirt_Dry"
    },
    {
      "x": 4,
      "y": 4,
      "z": 4,
      "name": "Soil_Dirt_Dry"
    }
  ],
  "entities": [
    {
        "Components": {
            "Nameplate": {
                "Text": "1"
            },
            "HiddenFromAdventurePlayer": {},
            "SpawnMarkerComponent": {
                "SpawnMarker": "TrorkEvo_Pool_Fodder",
                "RespawnTime": 0.0,
                "SpawnCount": 0,
                "NPCReferences": [],
                "PersistedFlock": {},
                "SpawnPosition": {
                    "X": 0.0,
                    "Y": 0.0,
                    "Z": 0.0
                }
            },
            "Prop": {},
            "Model": {
                "Model": {
                    "Id": "NPC_Spawn_Marker",
                    "Scale": 1.0,
                    "Static": true
                }
            },
            "Transform": {
                "Position": {
                    "X": -0.7102279663085938,
                    "Y": 5.337169647216797,
                    "Z": 2.4812088012695312
                },
                "Rotation": {
                    "Pitch": 0.0,
                    "Yaw": 3.1414027214050293,
                    "Roll": 0.0
                }
            },
            "UUID": {
                "UUID": {
                    "$binary": "ZvM+ERMzPyyr5Udnh+eREA==",
                    "$type": "04"
                }
            },
            "PrefabCopyable": {},
            "HeadRotation": {
                "Rotation": {
                    "Pitch": 0.0,
                    "Yaw": 3.1414027214050293,
                    "Roll": 0.0
                }
            }
        }
    },
    {
        "Components": {
            "Nameplate": {
                "Text": "2"
            },
            "HiddenFromAdventurePlayer": {},
            "SpawnMarkerComponent": {
                "SpawnMarker": "TrorkEvo_Pool_Fodder",
                "RespawnTime": 0.0,
                "SpawnCount": 0,
                "NPCReferences": [],
                "PersistedFlock": {},
                "SpawnPosition": {
                    "X": 0.0,
                    "Y": 0.0,
                    "Z": 0.0
                }
            },
            "Prop": {},
            "Model": {
                "Model": {
                    "Id": "NPC_Spawn_Marker",
                    "Scale": 1.0,
                    "Static": true
                }
            },
            "Transform": {
                "Position": {
                    "X": 1.7718505859375,
                    "Y": 5.227977752685547,
                    "Z": 0.8843841552734375
                },
                "Rotation": {
                    "Pitch": 0.0,
                    "Yaw": 3.1414027214050293,
                    "Roll": 0.0
                }
            },
            "UUID": {
                "UUID": {
                    "$binary": "ewGG8UoVMXCQKc9Zigkeng==",
                    "$type": "04"
                }
            },
            "PrefabCopyable": {},
            "HeadRotation": {
                "Rotation": {
                    "Pitch": 0.0,
                    "Yaw": 3.1414027214050293,
                    "Roll": 0.0
                }
            }
        }
    }
  ]
}