{
  "version": 8,
  "blockIdVersion": 11,
  "anchorX": 0,
  "anchorY": 0,
  "anchorZ": 0,
  "blocks": [
    {
      "x": -40,
      "y": 0,
      "z": -12,
      "name": "Rock_Sandstone_Cobble"
    },
    {
      "x": -40,
      "y": 1,
      "z": -12,
      "name": "Rock_Sandstone_Cobble"
    },
    {
      "x": -40,
      "y": 2,
      "z": -12,
      "name": "Soil_Dirt_Dry"
    },
    {
      "x": -40,
      "y": 0,
      "z": -11,
      "name": "Rock_Sandstone_Cobble"
    },
    {
      "x": -40,
      "y": 1,
      "z": -11,
      "name": "Rock_Sandstone_Cobble"
    },
    {
      "x": -40,
      "y": 2,
      "z": -11,
      "name": "Soil_Dirt_Dry"
    },
    {
      "x": -40,
      "y": 3,
      "z": -11,
      "name": "Soil_Dirt_Dry"
    },
    {
      "x": -40,
      "y": 0,
      "z": -10,
      "name": "Rock_Sandstone_Cobble"
    },
    {
      "x": -40,
      "y": 1,
      "z": -10,
      "name": "Rock_Sandstone_Cobble"
    },
    {
      "x": -40,
      "y": 2,
      "z": -10,
      "name": "Soil_Dirt_Dry"
    },
    {
      "x": -40,
      "y": 3,
      "z": -10,
      "name": "Soil_Dirt_Dry"
    },
    {
      "x": -40,
      "y": 0,
      "z": -9,
      "name": "Rock_Sandstone_Cobble"
    },
    {
      "x": -40,
      "y": 1,
      "z": -9,
      "name": "Rock_Sandstone_Cobble"
    },
    {
      "x": -40,
      "y": 2,
      "z": -9,
      "name": "Soil_Dirt_Dry"
    },
    {
      "x": -40,
      "y": 3,
      "z": -9,
      "name": "Soil_Dirt_Dry"
    },
    {
      "x": -40,
      "y": 0,
      "z": -8,
      "name": "Rock_Sandstone_Cobble"
    },
    {
      "x": -40,
      "y": 1,
      "z": -8,
      "name": "Rock_Sandstone_Cobble"
    },
    {
      "x": -40,
      "y": 2,
      "z": -8,
      "name": "Soil_Dirt_Dry"
    },
    {
      "x": -40,
      "y": 0,
      "z": -1,
      "name": "Rock_Sandstone_Cobble"
    },
    {
      "x": -40,
      "y": 1,
      "z": -1,
      "name": "Rock_Sandstone_Cobble"
    },
    {
      "x": -40,
      "y": 2,
      "z": -1,
      "name": "Rock_Sandstone_Cobble"
    },
    {
      "x": -40,
      "y": 0,
      "z": 0,
      "name": "Rock_Sandstone_Cobble"
    },
    {
      "x": -40,
      "y": 1,
      "z": 0,
      "name": "Rock_Sandstone_Cobble"
    },
    {
      "x": -40,
      "y": 2,
      "z": 0,
      "name": "Rock_Sandstone_Cobble"
    },
    {
      "x": -40,
      "y": 3,
      "z": 0,
      "name": "Soil_Dirt_Dry"
    },
    {
      "x": -40,
      "y": 0,
      "z": 1,
      "name": "Rock_Sandstone_Cobble"
    },
    {
      "x": -40,
      "y": 1,
      "z": 1,
      "name": "Rock_Sandstone_Cobble"
    },
    {
      "x": -40,
      "y": 2,
      "z": 1,
      "name": "Rock_Sandstone_Cobble"
    },
    {
      "x": -40,
      "y": 3,
      "z": 1,
      "name": "Soil_Dirt_Dry"
    },
    {
      "x": -40,
      "y": 0,
      "z": 2,
      "name": "Rock_Sandstone_Cobble"
    },
    {
      "x": -40,
      "y": 1,
      "z": 2,
      "name": "Rock_Sandstone_Cobble"
    },
    {
      "x": -40,
      "y": 2,
      "z": 2,
      "name": "Rock_Sandstone_Cobble"
    },
    {
      "x": -40,
      "y": 3,
      "z": 2,
      "name": "Soil_Dirt_Dry"
    },
    {
      "x": -40,
      "y": 0,
      "z": 3,
      "name": "Rock_Sandstone_Cobble"
    },
    {
      "x": -40,
      "y": 1,
      "z": 3,
      "name": "Rock_Sandstone_Cobble"
    },
    {
      "x": -40,
      "y": 2,
      "z": 3,
      "name": "Rock_Sandstone_Cobble"
    },
    {
      "x": -39,
      "y": 0,
      "z": -14,
      "name": "Rock_Sandstone_Cobble"
    },
    {
      "x": -39,
      "y": 1,
      "z": -14,
      "name": "Rock_Sandstone_Cobble"
    },
    {
      "x": -39,
      "y": 2,
      "z": -14,
      "name": "Soil_Dirt_Dry"
    },
    {
      "x": -39,
      "y": 0,
      "z": -13,
      "name": "Rock_Sandstone_Cobble"
    },
    {
      "x": -39,
      "y": 1,
      "z": -13,
      "name": "Rock_Sandstone_Cobble"
    },
    {
      "x": -39,
      "y": 2,
      "z": -13,
      "name": "Soil_Dirt_Dry"
    },
    {
      "x": -39,
      "y": 3,
      "z": -13,
      "name": "Soil_Dirt_Dry"
    },
    {
      "x": -39,
      "y": 0,
      "z": -12,
      "name": "Rock_Sandstone_Cobble"
    },
    {
      "x": -39,
      "y": 1,
      "z": -12,
      "name": "Rock_Sandstone_Cobble"
    },
    {
      "x": -39,
      "y": 2,
      "z": -12,
      "name": "Soil_Dirt_Dry"
    },
    {
      "x": -39,
      "y": 3,
      "z": -12,
      "name": "Soil_Dirt_Dry"
    },
    {
      "x": -39,
      "y": 0,
      "z": -11,
      "name": "Rock_Sandstone_Cobble"
    },
    {
      "x": -39,
      "y": 1,
      "z": -11,
      "name": "Rock_Sandstone_Cobble"
    },
    {
      "x": -39,
      "y": 2,
      "z": -11,
      "name": "Soil_Dirt_Dry"
    },
    {
      "x": -39,
      "y": 3,
      "z": -11,
      "name": "Soil_Dirt_Dry"
    },
    {
      "x": -39,
      "y": 0,
      "z": -10,
      "name": "Rock_Sandstone_Cobble"
    },
    {
      "x": -39,
      "y": 1,
      "z": -10,
      "name": "Rock_Sandstone_Cobble"
    },
    {
      "x": -39,
      "y": 2,
      "z": -10,
      "name": "Soil_Dirt_Dry"
    },
    {
      "x": -39,
      "y": 3,
      "z": -10,
      "name": "Soil_Dirt_Dry"
    },
    {
      "x": -39,
      "y": 4,
      "z": -10,
      "name": "Soil_Dirt_Dry"
    },
    {
      "x": -39,
      "y": 0,
      "z": -9,
      "name": "Rock_Sandstone_Cobble"
    },
    {
      "x": -39,
      "y": 1,
      "z": -9,
      "name": "Rock_Sandstone_Cobble"
    },
    {
      "x": -39,
      "y": 2,
      "z": -9,
      "name": "Soil_Dirt_Dry"
    },
    {
      "x": -39,
      "y": 3,
      "z": -9,
      "name": "Soil_Dirt_Dry"
    },
    {
      "x": -39,
      "y": 0,
      "z": -8,
      "name": "Rock_Sandstone_Cobble"
    },
    {
      "x": -39,
      "y": 1,
      "z": -8,
      "name": "Rock_Sandstone_Cobble"
    },
    {
      "x": -39,
      "y": 2,
      "z": -8,
      "name": "Soil_Dirt_Dry"
    },
    {
      "x": -39,
      "y": 3,
      "z": -8,
      "name": "Soil_Dirt_Dry"
    },
    {
      "x": -39,
      "y": 0,
      "z": -7,
      "name": "Rock_Sandstone_Cobble"
    },
    {
      "x": -39,
      "y": 1,
      "z": -7,
      "name": "Rock_Sandstone_Cobble"
    },
    {
      "x": -39,
      "y": 2,
      "z": -7,
      "name": "Soil_Dirt_Dry"
    },
    {
      "x": -39,
      "y": 3,
      "z": -7,
      "name": "Soil_Dirt_Dry"
    },
    {
      "x": -39,
      "y": 0,
      "z": -6,
      "name": "Rock_Sandstone_Cobble"
    },
    {
      "x": -39,
      "y": 1,
      "z": -6,
      "name": "Rock_Sandstone_Cobble"
    },
    {
      "x": -39,
      "y": 2,
      "z": -6,
      "name": "Soil_Dirt_Dry"
    },
    {
      "x": -39,
      "y": 0,
      "z": -3,
      "name": "Rock_Sandstone_Cobble"
    },
    {
      "x": -39,
      "y": 1,
      "z": -3,
      "name": "Rock_Sandstone_Cobble"
    },
    {
      "x": -39,
      "y": 2,
      "z": -3,
      "name": "Rock_Sandstone_Cobble"
    },
    {
      "x": -39,
      "y": 0,
      "z": -2,
      "name": "Rock_Sandstone_Cobble"
    },
    {
      "x": -39,
      "y": 1,
      "z": -2,
      "name": "Rock_Sandstone_Cobble"
    },
    {
      "x": -39,
      "y": 2,
      "z": -2,
      "name": "Rock_Sandstone_Cobble"
    },
    {
      "x": -39,
      "y": 3,
      "z": -2,
      "name": "Soil_Dirt_Dry"
    },
    {
      "x": -39,
      "y": 0,
      "z": -1,
      "name": "Rock_Sandstone_Cobble"
    },
    {
      "x": -39,
      "y": 1,
      "z": -1,
      "name": "Rock_Sandstone_Cobble"
    },
    {
      "x": -39,
      "y": 2,
      "z": -1,
      "name": "Rock_Sandstone_Cobble"
    },
    {
      "x": -39,
      "y": 3,
      "z": -1,
      "name": "Soil_Dirt_Dry"
    },
    {
      "x": -39,
      "y": 0,
      "z": 0,
      "name": "Rock_Sandstone_Cobble"
    },
    {
      "x": -39,
      "y": 1,
      "z": 0,
      "name": "Rock_Sandstone_Cobble"
    },
    {
      "x": -39,
      "y": 2,
      "z": 0,
      "name": "Rock_Sandstone_Cobble"
    },
    {
      "x": -39,
      "y": 3,
      "z": 0,
      "name": "Soil_Dirt_Dry"
    },
    {
      "x": -39,
      "y": 0,
      "z": 1,
      "name": "Rock_Sandstone_Cobble"
    },
    {
      "x": -39,
      "y": 1,
      "z": 1,
      "name": "Rock_Sandstone_Cobble"
    },
    {
      "x": -39,
      "y": 2,
      "z": 1,
      "name": "Rock_Sandstone_Cobble"
    },
    {
      "x": -39,
      "y": 3,
      "z": 1,
      "name": "Soil_Dirt_Dry"
    },
    {
      "x": -39,
      "y": 4,
      "z": 1,
      "name": "Soil_Dirt_Dry"
    },
    {
      "x": -39,
      "y": 0,
      "z": 2,
      "name": "Rock_Sandstone_Cobble"
    },
    {
      "x": -39,
      "y": 1,
      "z": 2,
      "name": "Rock_Sandstone_Cobble"
    },
    {
      "x": -39,
      "y": 2,
      "z": 2,
      "name": "Rock_Sandstone_Cobble"
    },
    {
      "x": -39,
      "y": 3,
      "z": 2,
      "name": "Soil_Dirt_Dry"
    },
    {
      "x": -39,
      "y": 0,
      "z": 3,
      "name": "Rock_Sandstone_Cobble"
    },
    {
      "x": -39,
      "y": 1,
      "z": 3,
      "name": "Rock_Sandstone_Cobble"
    },
    {
      "x": -39,
      "y": 2,
      "z": 3,
      "name": "Rock_Sandstone_Cobble"
    },
    {
      "x": -39,
      "y": 3,
      "z": 3,
      "name": "Soil_Dirt_Dry"
    },
    {
      "x": -39,
      "y": 0,
      "z": 4,
      "name": "Rock_Sandstone_Cobble"
    },
    {
      "x": -39,
      "y": 1,
      "z": 4,
      "name": "Rock_Sandstone_Cobble"
    },
    {
      "x": -39,
      "y": 2,
      "z": 4,
      "name": "Rock_Sandstone_Cobble"
    },
    {
      "x": -39,
      "y": 3,
      "z": 4,
      "name": "Soil_Dirt_Dry"
    },
    {
      "x": -39,
      "y": 0,
      "z": 5,
      "name": "Rock_Sandstone_Cobble"
    },
    {
      "x": -39,
      "y": 1,
      "z": 5,
      "name": "Rock_Sandstone_Cobble"
    },
    {
      "x": -39,
      "y": 2,
      "z": 5,
      "name": "Rock_Sandstone_Cobble"
    },
    {
      "x": -39,
      "y": 0,
      "z": 9,
      "name": "Rock_Sandstone_Cobble"
    },
    {
      "x": -39,
      "y": 1,
      "z": 9,
      "name": "Rock_Sandstone_Cobble"
    },
    {
      "x": -39,
      "y": 2,
      "z": 9,
      "name": "Rock_Sandstone_Cobble"
    },
    {
      "x": -39,
      "y": 0,
      "z": 10,
      "name": "Rock_Sandstone_Cobble"
    },
    {
      "x": -39,
      "y": 1,
      "z": 10,
      "name": "Rock_Sandstone_Cobble"
    },
    {
      "x": -39,
      "y": 2,
      "z": 10,
      "name": "Rock_Sandstone_Cobble"
    },
    {
      "x": -39,
      "y": 3,
      "z": 10,
      "name": "Soil_Dirt_Dry"
    },
    {
      "x": -39,
      "y": 0,
      "z": 11,
      "name": "Rock_Sandstone_Cobble"
    },
    {
      "x": -39,
      "y": 1,
      "z": 11,
      "name": "Rock_Sandstone_Cobble"
    },
    {
      "x": -39,
      "y": 2,
      "z": 11,
      "name": "Rock_Sandstone_Cobble"
    },
    {
      "x": -39,
      "y": 3,
      "z": 11,
      "name": "Soil_Dirt_Dry"
    },
    {
      "x": -39,
      "y": 0,
      "z": 12,
      "name": "Rock_Sandstone_Cobble"
    },
    {
      "x": -39,
      "y": 1,
      "z": 12,
      "name": "Rock_Sandstone_Cobble"
    },
    {
      "x": -39,
      "y": 2,
      "z": 12,
      "name": "Rock_Sandstone_Cobble"
    },
    {
      "x": -39,
      "y": 3,
      "z": 12,
      "name": "Soil_Dirt_Dry"
    },
    {
      "x": -39,
      "y": 0,
      "z": 13,
      "name": "Rock_Sandstone_Cobble"
    },
    {
      "x": -39,
      "y": 1,
      "z": 13,
      "name": "Rock_Sandstone_Cobble"
    },
    {
      "x": -39,
      "y": 2,
      "z": 13,
      "name": "Rock_Sandstone_Cobble"
    },
    {
      "x": -38,
      "y": 0,
      "z": -19,
      "name": "Rock_Sandstone_Cobble"
    },
    {
      "x": -38,
      "y": 1,
      "z": -19,
      "name": "Rock_Sandstone_Cobble"
    },
    {
      "x": -38,
      "y": 0,
      "z": -18,
      "name": "Rock_Sandstone_Cobble"
    },
    {
      "x": -38,
      "y": 1,
      "z": -18,
      "name": "Rock_Sandstone_Cobble"
    },
    {
      "x": -38,
      "y": 2,
      "z": -18,
      "name": "Soil_Dirt_Dry"
    },
    {
      "x": -38,
      "y": 0,
      "z": -17,
      "name": "Rock_Sandstone_Cobble"
    },
    {
      "x": -38,
      "y": 1,
      "z": -17,
      "name": "Rock_Sandstone_Cobble"
    },
    {
      "x": -38,
      "y": 2,
      "z": -17,
      "name": "Soil_Dirt_Dry"
    },
    {
      "x": -38,
      "y": 0,
      "z": -16,
      "name": "Rock_Sandstone_Cobble"
    },
    {
      "x": -38,
      "y": 1,
      "z": -16,
      "name": "Rock_Sandstone_Cobble"
    },
    {
      "x": -38,
      "y": 2,
      "z": -16,
      "name": "Soil_Dirt_Dry"
    },
    {
      "x": -38,
      "y": 0,
      "z": -15,
      "name": "Rock_Sandstone_Cobble"
    },
    {
      "x": -38,
      "y": 1,
      "z": -15,
      "name": "Rock_Sandstone_Cobble"
    },
    {
      "x": -38,
      "y": 2,
      "z": -15,
      "name": "Soil_Dirt_Dry"
    },
    {
      "x": -38,
      "y": 3,
      "z": -15,
      "name": "Soil_Dirt_Dry"
    },
    {
      "x": -38,
      "y": 0,
      "z": -14,
      "name": "Rock_Sandstone_Cobble"
    },
    {
      "x": -38,
      "y": 1,
      "z": -14,
      "name": "Rock_Sandstone_Cobble"
    },
    {
      "x": -38,
      "y": 2,
      "z": -14,
      "name": "Soil_Dirt_Dry"
    },
    {
      "x": -38,
      "y": 3,
      "z": -14,
      "name": "Soil_Dirt_Dry"
    },
    {
      "x": -38,
      "y": 0,
      "z": -13,
      "name": "Rock_Sandstone_Cobble"
    },
    {
      "x": -38,
      "y": 1,
      "z": -13,
      "name": "Rock_Sandstone_Cobble"
    },
    {
      "x": -38,
      "y": 2,
      "z": -13,
      "name": "Soil_Dirt_Dry"
    },
    {
      "x": -38,
      "y": 3,
      "z": -13,
      "name": "Soil_Dirt_Dry"
    },
    {
      "x": -38,
      "y": 4,
      "z": -13,
      "name": "Soil_Dirt_Dry"
    },
    {
      "x": -38,
      "y": 3,
      "z": -12,
      "name": "Soil_Dirt_Dry"
    },
    {
      "x": -38,
      "y": 4,
      "z": -12,
      "name": "Soil_Dirt_Dry"
    },
    {
      "x": -38,
      "y": 3,
      "z": -11,
      "name": "Soil_Dirt_Dry"
    },
    {
      "x": -38,
      "y": 4,
      "z": -11,
      "name": "Soil_Dirt_Dry"
    },
    {
      "x": -38,
      "y": 3,
      "z": -10,
      "name": "Soil_Dirt_Dry"
    },
    {
      "x": -38,
      "y": 4,
      "z": -10,
      "name": "Soil_Dirt_Dry"
    },
    {
      "x": -38,
      "y": 3,
      "z": -9,
      "name": "Soil_Dirt_Dry"
    },
    {
      "x": -38,
      "y": 4,
      "z": -9,
      "name": "Soil_Dirt_Dry"
    },
    {
      "x": -38,
      "y": 3,
      "z": -8,
      "name": "Soil_Dirt_Dry"
    },
    {
      "x": -38,
      "y": 4,
      "z": -8,
      "name": "Soil_Dirt_Dry"
    },
    {
      "x": -38,
      "y": 0,
      "z": -7,
      "name": "Rock_Sandstone_Cobble"
    },
    {
      "x": -38,
      "y": 1,
      "z": -7,
      "name": "Rock_Sandstone_Cobble"
    },
    {
      "x": -38,
      "y": 2,
      "z": -7,
      "name": "Rock_Sandstone_Cobble"
    },
    {
      "x": -38,
      "y": 3,
      "z": -7,
      "name": "Soil_Dirt_Dry"
    },
    {
      "x": -38,
      "y": 4,
      "z": -7,
      "name": "Soil_Dirt_Dry"
    },
    {
      "x": -38,
      "y": 0,
      "z": -6,
      "name": "Rock_Sandstone_Cobble"
    },
    {
      "x": -38,
      "y": 1,
      "z": -6,
      "name": "Rock_Sandstone_Cobble"
    },
    {
      "x": -38,
      "y": 2,
      "z": -6,
      "name": "Rock_Sandstone_Cobble"
    },
    {
      "x": -38,
      "y": 3,
      "z": -6,
      "name": "Soil_Dirt_Dry"
    },
    {
      "x": -38,
      "y": 0,
      "z": -5,
      "name": "Rock_Sandstone_Cobble"
    },
    {
      "x": -38,
      "y": 1,
      "z": -5,
      "name": "Rock_Sandstone_Cobble"
    },
    {
      "x": -38,
      "y": 2,
      "z": -5,
      "name": "Rock_Sandstone_Cobble"
    },
    {
      "x": -38,
      "y": 3,
      "z": -5,
      "name": "Soil_Dirt_Dry"
    },
    {
      "x": -38,
      "y": 0,
      "z": -4,
      "name": "Rock_Sandstone_Cobble"
    },
    {
      "x": -38,
      "y": 1,
      "z": -4,
      "name": "Rock_Sandstone_Cobble"
    },
    {
      "x": -38,
      "y": 2,
      "z": -4,
      "name": "Rock_Sandstone_Cobble"
    },
    {
      "x": -38,
      "y": 3,
      "z": -4,
      "name": "Soil_Dirt_Dry"
    },
    {
      "x": -38,
      "y": 0,
      "z": -3,
      "name": "Rock_Sandstone_Cobble"
    },
    {
      "x": -38,
      "y": 1,
      "z": -3,
      "name": "Rock_Sandstone_Cobble"
    },
    {
      "x": -38,
      "y": 2,
      "z": -3,
      "name": "Rock_Sandstone_Cobble"
    },
    {
      "x": -38,
      "y": 3,
      "z": -3,
      "name": "Soil_Dirt_Dry"
    },
    {
      "x": -38,
      "y": 0,
      "z": -2,
      "name": "Rock_Sandstone_Cobble"
    },
    {
      "x": -38,
      "y": 1,
      "z": -2,
      "name": "Rock_Sandstone_Cobble"
    },
    {
      "x": -38,
      "y": 2,
      "z": -2,
      "name": "Rock_Sandstone_Cobble"
    },
    {
      "x": -38,
      "y": 3,
      "z": -2,
      "name": "Soil_Dirt_Dry"
    },
    {
      "x": -38,
      "y": 4,
      "z": -2,
      "name": "Soil_Dirt_Dry"
    },
    {
      "x": -38,
      "y": 3,
      "z": -1,
      "name": "Soil_Dirt_Dry"
    },
    {
      "x": -38,
      "y": 4,
      "z": -1,
      "name": "Soil_Dirt_Dry"
    },
    {
      "x": -38,
      "y": 3,
      "z": 0,
      "name": "Soil_Dirt_Dry"
    },
    {
      "x": -38,
      "y": 4,
      "z": 0,
      "name": "Soil_Dirt_Dry"
    },
    {
      "x": -38,
      "y": 3,
      "z": 1,
      "name": "Soil_Dirt_Dry"
    },
    {
      "x": -38,
      "y": 4,
      "z": 1,
      "name": "Soil_Dirt_Dry"
    },
    {
      "x": -38,
      "y": 3,
      "z": 2,
      "name": "Soil_Dirt_Dry"
    },
    {
      "x": -38,
      "y": 4,
      "z": 2,
      "name": "Soil_Dirt_Dry"
    },
    {
      "x": -38,
      "y": 3,
      "z": 3,
      "name": "Soil_Dirt_Dry"
    },
    {
      "x": -38,
      "y": 4,
      "z": 3,
      "name": "Soil_Dirt_Dry"
    },
    {
      "x": -38,
      "y": 3,
      "z": 4,
      "name": "Soil_Dirt_Dry"
    },
    {
      "x": -38,
      "y": 4,
      "z": 4,
      "name": "Soil_Dirt_Dry"
    },
    {
      "x": -38,
      "y": 3,
      "z": 5,
      "name": "Soil_Dirt_Dry"
    },
    {
      "x": -38,
      "y": 0,
      "z": 6,
      "name": "Rock_Sandstone_Cobble"
    },
    {
      "x": -38,
      "y": 1,
      "z": 6,
      "name": "Rock_Sandstone_Cobble"
    },
    {
      "x": -38,
      "y": 2,
      "z": 6,
      "name": "Rock_Sandstone_Cobble"
    },
    {
      "x": -38,
      "y": 3,
      "z": 6,
      "name": "Soil_Dirt_Dry"
    },
    {
      "x": -38,
      "y": 0,
      "z": 7,
      "name": "Rock_Sandstone_Cobble"
    },
    {
      "x": -38,
      "y": 1,
      "z": 7,
      "name": "Rock_Sandstone_Cobble"
    },
    {
      "x": -38,
      "y": 2,
      "z": 7,
      "name": "Rock_Sandstone_Cobble"
    },
    {
      "x": -38,
      "y": 0,
      "z": 8,
      "name": "Rock_Sandstone_Cobble"
    },
    {
      "x": -38,
      "y": 1,
      "z": 8,
      "name": "Rock_Sandstone_Cobble"
    },
    {
      "x": -38,
      "y": 2,
      "z": 8,
      "name": "Rock_Sandstone_Cobble"
    },
    {
      "x": -38,
      "y": 3,
      "z": 8,
      "name": "Soil_Dirt_Dry"
    },
    {
      "x": -38,
      "y": 0,
      "z": 9,
      "name": "Rock_Sandstone_Cobble"
    },
    {
      "x": -38,
      "y": 1,
      "z": 9,
      "name": "Rock_Sandstone_Cobble"
    },
    {
      "x": -38,
      "y": 2,
      "z": 9,
      "name": "Rock_Sandstone_Cobble"
    },
    {
      "x": -38,
      "y": 3,
      "z": 9,
      "name": "Soil_Dirt_Dry"
    },
    {
      "x": -38,
      "y": 0,
      "z": 10,
      "name": "Rock_Sandstone_Cobble"
    },
    {
      "x": -38,
      "y": 1,
      "z": 10,
      "name": "Rock_Sandstone_Cobble"
    },
    {
      "x": -38,
      "y": 2,
      "z": 10,
      "name": "Rock_Sandstone_Cobble"
    },
    {
      "x": -38,
      "y": 3,
      "z": 10,
      "name": "Soil_Dirt_Dry"
    },
    {
      "x": -38,
      "y": 0,
      "z": 11,
      "name": "Rock_Sandstone_Cobble"
    },
    {
      "x": -38,
      "y": 1,
      "z": 11,
      "name": "Rock_Sandstone_Cobble"
    },
    {
      "x": -38,
      "y": 2,
      "z": 11,
      "name": "Rock_Sandstone_Cobble"
    },
    {
      "x": -38,
      "y": 3,
      "z": 11,
      "name": "Soil_Dirt_Dry"
    },
    {
      "x": -38,
      "y": 4,
      "z": 11,
      "name": "Soil_Dirt_Dry"
    },
    {
      "x": -38,
      "y": 0,
      "z": 12,
      "name": "Rock_Sandstone_Cobble"
    },
    {
      "x": -38,
      "y": 1,
      "z": 12,
      "name": "Rock_Sandstone_Cobble"
    },
    {
      "x": -38,
      "y": 2,
      "z": 12,
      "name": "Rock_Sandstone_Cobble"
    },
    {
      "x": -38,
      "y": 3,
      "z": 12,
      "name": "Soil_Dirt_Dry"
    },
    {
      "x": -38,
      "y": 0,
      "z": 13,
      "name": "Rock_Sandstone_Cobble"
    },
    {
      "x": -38,
      "y": 1,
      "z": 13,
      "name": "Rock_Sandstone_Cobble"
    },
    {
      "x": -38,
      "y": 2,
      "z": 13,
      "name": "Rock_Sandstone_Cobble"
    },
    {
      "x": -38,
      "y": 3,
      "z": 13,
      "name": "Soil_Dirt_Dry"
    },
    {
      "x": -38,
      "y": 0,
      "z": 14,
      "name": "Rock_Sandstone_Cobble"
    },
    {
      "x": -38,
      "y": 1,
      "z": 14,
      "name": "Rock_Sandstone_Cobble"
    },
    {
      "x": -38,
      "y": 2,
      "z": 14,
      "name": "Rock_Sandstone_Cobble"
    },
    {
      "x": -38,
      "y": 3,
      "z": 14,
      "name": "Soil_Dirt_Dry"
    },
    {
      "x": -38,
      "y": 0,
      "z": 15,
      "name": "Rock_Sandstone_Cobble"
    },
    {
      "x": -38,
      "y": 1,
      "z": 15,
      "name": "Rock_Sandstone_Cobble"
    },
    {
      "x": -38,
      "y": 2,
      "z": 15,
      "name": "Rock_Sandstone_Cobble"
    },
    {
      "x": -37,
      "y": 0,
      "z": -21,
      "name": "Rock_Sandstone_Cobble"
    },
    {
      "x": -37,
      "y": 1,
      "z": -21,
      "name": "Soil_Dirt_Dry"
    },
    {
      "x": -37,
      "y": 0,
      "z": -20,
      "name": "Rock_Sandstone_Cobble"
    },
    {
      "x": -37,
      "y": 1,
      "z": -20,
      "name": "Rock_Sandstone_Cobble"
    },
    {
      "x": -37,
      "y": 2,
      "z": -20,
      "name": "Soil_Dirt_Dry"
    },
    {
      "x": -37,
      "y": 0,
      "z": -19,
      "name": "Rock_Sandstone_Cobble"
    },
    {
      "x": -37,
      "y": 1,
      "z": -19,
      "name": "Rock_Sandstone_Cobble"
    },
    {
      "x": -37,
      "y": 2,
      "z": -19,
      "name": "Soil_Dirt_Dry"
    },
    {
      "x": -37,
      "y": 0,
      "z": -18,
      "name": "Rock_Sandstone_Cobble"
    },
    {
      "x": -37,
      "y": 1,
      "z": -18,
      "name": "Rock_Sandstone_Cobble"
    },
    {
      "x": -37,
      "y": 2,
      "z": -18,
      "name": "Soil_Dirt_Dry"
    },
    {
      "x": -37,
      "y": 0,
      "z": -17,
      "name": "Rock_Sandstone_Cobble"
    },
    {
      "x": -37,
      "y": 1,
      "z": -17,
      "name": "Rock_Sandstone_Cobble"
    },
    {
      "x": -37,
      "y": 2,
      "z": -17,
      "name": "Soil_Dirt_Dry"
    },
    {
      "x": -37,
      "y": 3,
      "z": -17,
      "name": "Soil_Dirt_Dry"
    },
    {
      "x": -37,
      "y": 0,
      "z": -16,
      "name": "Rock_Sandstone_Cobble"
    },
    {
      "x": -37,
      "y": 1,
      "z": -16,
      "name": "Rock_Sandstone_Cobble"
    },
    {
      "x": -37,
      "y": 2,
      "z": -16,
      "name": "Soil_Dirt_Dry"
    },
    {
      "x": -37,
      "y": 0,
      "z": -15,
      "name": "Rock_Sandstone_Cobble"
    },
    {
      "x": -37,
      "y": 1,
      "z": -15,
      "name": "Rock_Sandstone_Cobble"
    },
    {
      "x": -37,
      "y": 2,
      "z": -15,
      "name": "Soil_Dirt_Dry"
    },
    {
      "x": -37,
      "y": 3,
      "z": -15,
      "name": "Soil_Dirt_Dry"
    },
    {
      "x": -37,
      "y": 0,
      "z": -14,
      "name": "Rock_Sandstone_Cobble"
    },
    {
      "x": -37,
      "y": 1,
      "z": -14,
      "name": "Rock_Sandstone_Cobble"
    },
    {
      "x": -37,
      "y": 2,
      "z": -14,
      "name": "Rock_Sandstone_Cobble"
    },
    {
      "x": -37,
      "y": 3,
      "z": -14,
      "name": "Soil_Dirt_Dry"
    },
    {
      "x": -37,
      "y": 4,
      "z": -14,
      "name": "Soil_Dirt_Dry"
    },
    {
      "x": -37,
      "y": 0,
      "z": -13,
      "name": "Rock_Sandstone_Cobble"
    },
    {
      "x": -37,
      "y": 1,
      "z": -13,
      "name": "Rock_Sandstone_Cobble"
    },
    {
      "x": -37,
      "y": 3,
      "z": -13,
      "name": "Soil_Gravel_Sand"
    },
    {
      "x": -37,
      "y": 4,
      "z": -13,
      "name": "Soil_Dirt_Dry"
    },
    {
      "x": -37,
      "y": 3,
      "z": -12,
      "name": "Soil_Dirt_Dry"
    },
    {
      "x": -37,
      "y": 4,
      "z": -12,
      "name": "Soil_Dirt_Dry"
    },
    {
      "x": -37,
      "y": 3,
      "z": -11,
      "name": "Soil_Dirt_Dry"
    },
    {
      "x": -37,
      "y": 4,
      "z": -11,
      "name": "Soil_Dirt_Dry"
    },
    {
      "x": -37,
      "y": 3,
      "z": -10,
      "name": "Soil_Dirt_Dry"
    },
    {
      "x": -37,
      "y": 4,
      "z": -10,
      "name": "Soil_Dirt_Dry"
    },
    {
      "x": -37,
      "y": 3,
      "z": -9,
      "name": "Soil_Dirt_Dry"
    },
    {
      "x": -37,
      "y": 4,
      "z": -9,
      "name": "Soil_Dirt_Dry"
    },
    {
      "x": -37,
      "y": 3,
      "z": -8,
      "name": "Soil_Dirt_Dry"
    },
    {
      "x": -37,
      "y": 4,
      "z": -8,
      "name": "Soil_Dirt_Dry"
    },
    {
      "x": -37,
      "y": 3,
      "z": -7,
      "name": "Soil_Dirt_Dry"
    },
    {
      "x": -37,
      "y": 4,
      "z": -7,
      "name": "Soil_Dirt_Dry"
    },
    {
      "x": -37,
      "y": 0,
      "z": -6,
      "name": "Rock_Sandstone_Cobble"
    },
    {
      "x": -37,
      "y": 1,
      "z": -6,
      "name": "Rock_Sandstone_Cobble"
    },
    {
      "x": -37,
      "y": 2,
      "z": -6,
      "name": "Rock_Sandstone_Cobble"
    },
    {
      "x": -37,
      "y": 3,
      "z": -6,
      "name": "Soil_Dirt_Dry"
    },
    {
      "x": -37,
      "y": 4,
      "z": -6,
      "name": "Soil_Dirt_Dry"
    },
    {
      "x": -37,
      "y": 0,
      "z": -5,
      "name": "Rock_Sandstone_Cobble"
    },
    {
      "x": -37,
      "y": 1,
      "z": -5,
      "name": "Rock_Sandstone_Cobble"
    },
    {
      "x": -37,
      "y": 2,
      "z": -5,
      "name": "Rock_Sandstone_Cobble"
    },
    {
      "x": -37,
      "y": 3,
      "z": -5,
      "name": "Soil_Dirt_Dry"
    },
    {
      "x": -37,
      "y": 0,
      "z": -4,
      "name": "Rock_Sandstone_Cobble"
    },
    {
      "x": -37,
      "y": 1,
      "z": -4,
      "name": "Rock_Sandstone_Cobble"
    },
    {
      "x": -37,
      "y": 2,
      "z": -4,
      "name": "Rock_Sandstone_Cobble"
    },
    {
      "x": -37,
      "y": 3,
      "z": -4,
      "name": "Soil_Dirt_Dry"
    },
    {
      "x": -37,
      "y": 3,
      "z": -3,
      "name": "Soil_Dirt_Dry"
    },
    {
      "x": -37,
      "y": 4,
      "z": -3,
      "name": "Soil_Dirt_Dry"
    },
    {
      "x": -37,
      "y": 3,
      "z": -2,
      "name": "Soil_Dirt_Dry"
    },
    {
      "x": -37,
      "y": 4,
      "z": -2,
      "name": "Soil_Dirt_Dry"
    },
    {
      "x": -37,
      "y": 3,
      "z": -1,
      "name": "Soil_Dirt_Dry"
    },
    {
      "x": -37,
      "y": 4,
      "z": -1,
      "name": "Soil_Dirt_Dry"
    },
    {
      "x": -37,
      "y": 3,
      "z": 0,
      "name": "Soil_Dirt_Dry"
    },
    {
      "x": -37,
      "y": 4,
      "z": 0,
      "name": "Soil_Dirt_Dry"
    },
    {
      "x": -37,
      "y": 3,
      "z": 1,
      "name": "Soil_Dirt_Dry"
    },
    {
      "x": -37,
      "y": 4,
      "z": 1,
      "name": "Soil_Dirt_Dry"
    },
    {
      "x": -37,
      "y": 3,
      "z": 2,
      "name": "Soil_Dirt_Dry"
    },
    {
      "x": -37,
      "y": 4,
      "z": 2,
      "name": "Soil_Dirt_Dry"
    },
    {
      "x": -37,
      "y": 3,
      "z": 3,
      "name": "Soil_Dirt_Dry"
    },
    {
      "x": -37,
      "y": 4,
      "z": 3,
      "name": "Soil_Dirt_Dry"
    },
    {
      "x": -37,
      "y": 3,
      "z": 4,
      "name": "Soil_Dirt_Dry"
    },
    {
      "x": -37,
      "y": 4,
      "z": 4,
      "name": "Soil_Dirt_Dry"
    },
    {
      "x": -37,
      "y": 3,
      "z": 5,
      "name": "Soil_Dirt_Dry"
    },
    {
      "x": -37,
      "y": 4,
      "z": 5,
      "name": "Soil_Dirt_Dry"
    },
    {
      "x": -37,
      "y": 3,
      "z": 6,
      "name": "Soil_Dirt_Dry"
    },
    {
      "x": -37,
      "y": 3,
      "z": 7,
      "name": "Soil_Dirt_Dry"
    },
    {
      "x": -37,
      "y": 0,
      "z": 8,
      "name": "Rock_Sandstone_Cobble"
    },
    {
      "x": -37,
      "y": 1,
      "z": 8,
      "name": "Rock_Sandstone_Cobble"
    },
    {
      "x": -37,
      "y": 2,
      "z": 8,
      "name": "Rock_Sandstone_Cobble"
    },
    {
      "x": -37,
      "y": 3,
      "z": 8,
      "name": "Soil_Dirt_Dry"
    },
    {
      "x": -37,
      "y": 4,
      "z": 8,
      "name": "Soil_Dirt_Dry"
    },
    {
      "x": -37,
      "y": 3,
      "z": 9,
      "name": "Soil_Dirt_Dry"
    },
    {
      "x": -37,
      "y": 4,
      "z": 9,
      "name": "Soil_Dirt_Dry"
    },
    {
      "x": -37,
      "y": 3,
      "z": 10,
      "name": "Soil_Dirt_Dry"
    },
    {
      "x": -37,
      "y": 4,
      "z": 10,
      "name": "Soil_Pathway"
    },
    {
      "x": -37,
      "y": 3,
      "z": 11,
      "name": "Soil_Dirt_Dry"
    },
    {
      "x": -37,
      "y": 4,
      "z": 11,
      "name": "Soil_Pathway"
    },
    {
      "x": -37,
      "y": 3,
      "z": 12,
      "name": "Soil_Dirt_Dry"
    },
    {
      "x": -37,
      "y": 4,
      "z": 12,
      "name": "Soil_Pathway"
    },
    {
      "x": -37,
      "y": 3,
      "z": 13,
      "name": "Soil_Dirt_Dry"
    },
    {
      "x": -37,
      "y": 4,
      "z": 13,
      "name": "Soil_Pathway"
    },
    {
      "x": -37,
      "y": 0,
      "z": 14,
      "name": "Rock_Sandstone_Cobble"
    },
    {
      "x": -37,
      "y": 1,
      "z": 14,
      "name": "Rock_Sandstone_Cobble"
    },
    {
      "x": -37,
      "y": 2,
      "z": 14,
      "name": "Rock_Sandstone_Cobble"
    },
    {
      "x": -37,
      "y": 3,
      "z": 14,
      "name": "Soil_Dirt_Dry"
    },
    {
      "x": -37,
      "y": 4,
      "z": 14,
      "name": "Soil_Dirt_Dry"
    },
    {
      "x": -37,
      "y": 0,
      "z": 15,
      "name": "Rock_Sandstone_Cobble"
    },
    {
      "x": -37,
      "y": 1,
      "z": 15,
      "name": "Rock_Sandstone_Cobble"
    },
    {
      "x": -37,
      "y": 2,
      "z": 15,
      "name": "Rock_Sandstone_Cobble"
    },
    {
      "x": -37,
      "y": 3,
      "z": 15,
      "name": "Soil_Dirt_Dry"
    },
    {
      "x": -37,
      "y": 0,
      "z": 16,
      "name": "Rock_Sandstone_Cobble"
    },
    {
      "x": -37,
      "y": 1,
      "z": 16,
      "name": "Rock_Sandstone_Cobble"
    },
    {
      "x": -37,
      "y": 2,
      "z": 16,
      "name": "Rock_Sandstone_Cobble"
    },
    {
      "x": -37,
      "y": 3,
      "z": 16,
      "name": "Soil_Dirt_Dry"
    },
    {
      "x": -36,
      "y": 0,
      "z": -22,
      "name": "Rock_Sandstone_Cobble"
    },
    {
      "x": -36,
      "y": 1,
      "z": -22,
      "name": "Rock_Sandstone_Cobble"
    },
    {
      "x": -36,
      "y": 2,
      "z": -22,
      "name": "Rock_Sandstone_Cobble"
    },
    {
      "x": -36,
      "y": 0,
      "z": -21,
      "name": "Rock_Sandstone_Cobble"
    },
    {
      "x": -36,
      "y": 1,
      "z": -21,
      "name": "Rock_Sandstone_Cobble"
    },
    {
      "x": -36,
      "y": 2,
      "z": -21,
      "name": "Rock_Sandstone_Cobble"
    },
    {
      "x": -36,
      "y": 0,
      "z": -20,
      "name": "Rock_Sandstone_Cobble"
    },
    {
      "x": -36,
      "y": 1,
      "z": -20,
      "name": "Rock_Sandstone_Cobble"
    },
    {
      "x": -36,
      "y": 2,
      "z": -20,
      "name": "Soil_Dirt_Dry"
    },
    {
      "x": -36,
      "y": 3,
      "z": -20,
      "name": "Soil_Dirt_Dry"
    },
    {
      "x": -36,
      "y": 0,
      "z": -19,
      "name": "Rock_Sandstone_Cobble"
    },
    {
      "x": -36,
      "y": 1,
      "z": -19,
      "name": "Rock_Sandstone_Cobble"
    },
    {
      "x": -36,
      "y": 2,
      "z": -19,
      "name": "Soil_Dirt_Dry"
    },
    {
      "x": -36,
      "y": 3,
      "z": -19,
      "name": "Soil_Dirt_Dry"
    },
    {
      "x": -36,
      "y": 2,
      "z": -18,
      "name": "Soil_Dirt_Dry"
    },
    {
      "x": -36,
      "y": 3,
      "z": -18,
      "name": "Soil_Dirt_Dry"
    },
    {
      "x": -36,
      "y": 2,
      "z": -17,
      "name": "Soil_Dirt_Dry"
    },
    {
      "x": -36,
      "y": 3,
      "z": -17,
      "name": "Soil_Pathway"
    },
    {
      "x": -36,
      "y": 2,
      "z": -16,
      "name": "Rock_Sandstone_Cobble"
    },
    {
      "x": -36,
      "y": 3,
      "z": -16,
      "name": "Soil_Dirt_Dry"
    },
    {
      "x": -36,
      "y": 4,
      "z": -16,
      "name": "Soil_Pathway"
    },
    {
      "x": -36,
      "y": 2,
      "z": -15,
      "name": "Rock_Sandstone_Cobble"
    },
    {
      "x": -36,
      "y": 3,
      "z": -15,
      "name": "Soil_Pathway"
    },
    {
      "x": -36,
      "y": 4,
      "z": -15,
      "name": "Soil_Pathway"
    },
    {
      "x": -36,
      "y": 1,
      "z": -14,
      "name": "Rock_Sandstone_Cobble"
    },
    {
      "x": -36,
      "y": 2,
      "z": -14,
      "name": "Rock_Sandstone_Cobble"
    },
    {
      "x": -36,
      "y": 3,
      "z": -14,
      "name": "Soil_Dirt_Dry"
    },
    {
      "x": -36,
      "y": 4,
      "z": -14,
      "name": "Soil_Pathway"
    },
    {
      "x": -36,
      "y": 1,
      "z": -13,
      "name": "Rock_Sandstone_Cobble"
    },
    {
      "x": -36,
      "y": 2,
      "z": -13,
      "name": "Rock_Sandstone_Cobble"
    },
    {
      "x": -36,
      "y": 3,
      "z": -13,
      "name": "Soil_Dirt_Dry"
    },
    {
      "x": -36,
      "y": 4,
      "z": -13,
      "name": "Soil_Pathway"
    },
    {
      "x": -36,
      "y": 1,
      "z": -12,
      "name": "Rock_Sandstone_Cobble"
    },
    {
      "x": -36,
      "y": 2,
      "z": -12,
      "name": "Rock_Sandstone_Cobble"
    },
    {
      "x": -36,
      "y": 4,
      "z": -12,
      "name": "Soil_Pathway"
    },
    {
      "x": -36,
      "y": 4,
      "z": -11,
      "name": "Soil_Pathway"
    },
    {
      "x": -36,
      "y": 5,
      "z": -11,
      "name": "Soil_Dirt_Dry"
    },
    {
      "x": -36,
      "y": 4,
      "z": -10,
      "name": "Soil_Pathway"
    },
    {
      "x": -36,
      "y": 5,
      "z": -10,
      "name": "Soil_Mud_Dry"
    },
    {
      "x": -36,
      "y": 4,
      "z": -9,
      "name": "Soil_Pathway"
    },
    {
      "x": -36,
      "y": 5,
      "z": -9,
      "name": "Soil_Dirt_Dry"
    },
    {
      "x": -36,
      "y": 4,
      "z": -8,
      "name": "Soil_Pathway"
    },
    {
      "x": -36,
      "y": 3,
      "z": -7,
      "name": "Soil_Pathway"
    },
    {
      "x": -36,
      "y": 4,
      "z": -7,
      "name": "Soil_Pathway"
    },
    {
      "x": -36,
      "y": 3,
      "z": -6,
      "name": "Soil_Dirt_Dry"
    },
    {
      "x": -36,
      "y": 4,
      "z": -6,
      "name": "Soil_Pathway"
    },
    {
      "x": -36,
      "y": 3,
      "z": -5,
      "name": "Soil_Dirt_Dry"
    },
    {
      "x": -36,
      "y": 4,
      "z": -5,
      "name": "Soil_Pathway"
    },
    {
      "x": -36,
      "y": 3,
      "z": -4,
      "name": "Soil_Dirt_Dry"
    },
    {
      "x": -36,
      "y": 4,
      "z": -4,
      "name": "Soil_Pathway"
    },
    {
      "x": -36,
      "y": 3,
      "z": -3,
      "name": "Soil_Dirt_Dry"
    },
    {
      "x": -36,
      "y": 4,
      "z": -3,
      "name": "Soil_Pathway"
    },
    {
      "x": -36,
      "y": 3,
      "z": -2,
      "name": "Soil_Dirt_Dry"
    },
    {
      "x": -36,
      "y": 4,
      "z": -2,
      "name": "Soil_Pathway"
    },
    {
      "x": -36,
      "y": 4,
      "z": -1,
      "name": "Soil_Pathway"
    },
    {
      "x": -36,
      "y": 4,
      "z": 0,
      "name": "Soil_Pathway"
    },
    {
      "x": -36,
      "y": 5,
      "z": 0,
      "name": "Soil_Dirt_Dry"
    },
    {
      "x": -36,
      "y": 4,
      "z": 1,
      "name": "Soil_Pathway"
    },
    {
      "x": -36,
      "y": 5,
      "z": 1,
      "name": "Soil_Dirt_Dry"
    },
    {
      "x": -36,
      "y": 4,
      "z": 2,
      "name": "Soil_Pathway"
    },
    {
      "x": -36,
      "y": 5,
      "z": 2,
      "name": "Soil_Dirt_Dry"
    },
    {
      "x": -36,
      "y": 4,
      "z": 3,
      "name": "Soil_Pathway"
    },
    {
      "x": -36,
      "y": 3,
      "z": 4,
      "name": "Soil_Dirt_Dry"
    },
    {
      "x": -36,
      "y": 4,
      "z": 4,
      "name": "Soil_Pathway"
    },
    {
      "x": -36,
      "y": 3,
      "z": 5,
      "name": "Soil_Dirt_Dry"
    },
    {
      "x": -36,
      "y": 4,
      "z": 5,
      "name": "Soil_Pathway"
    },
    {
      "x": -36,
      "y": 3,
      "z": 6,
      "name": "Soil_Dirt_Dry"
    },
    {
      "x": -36,
      "y": 4,
      "z": 6,
      "name": "Soil_Pathway"
    },
    {
      "x": -36,
      "y": 3,
      "z": 7,
      "name": "Soil_Dirt_Dry"
    },
    {
      "x": -36,
      "y": 4,
      "z": 7,
      "name": "Soil_Pathway"
    },
    {
      "x": -36,
      "y": 3,
      "z": 8,
      "name": "Soil_Dirt_Dry"
    },
    {
      "x": -36,
      "y": 4,
      "z": 8,
      "name": "Soil_Pathway"
    },
    {
      "x": -36,
      "y": 3,
      "z": 9,
      "name": "Soil_Dirt_Dry"
    },
    {
      "x": -36,
      "y": 4,
      "z": 9,
      "name": "Soil_Pathway"
    },
    {
      "x": -36,
      "y": 3,
      "z": 10,
      "name": "Soil_Dirt_Dry"
    },
    {
      "x": -36,
      "y": 4,
      "z": 10,
      "name": "Soil_Pathway"
    },
    {
      "x": -36,
      "y": 3,
      "z": 11,
      "name": "Soil_Dirt_Dry"
    },
    {
      "x": -36,
      "y": 4,
      "z": 11,
      "name": "Soil_Pathway"
    },
    {
      "x": -36,
      "y": 3,
      "z": 12,
      "name": "Soil_Dirt_Dry"
    },
    {
      "x": -36,
      "y": 4,
      "z": 12,
      "name": "Soil_Pathway"
    },
    {
      "x": -36,
      "y": 3,
      "z": 13,
      "name": "Soil_Dirt_Dry"
    },
    {
      "x": -36,
      "y": 4,
      "z": 13,
      "name": "Soil_Pathway"
    },
    {
      "x": -36,
      "y": 3,
      "z": 14,
      "name": "Soil_Dirt_Dry"
    },
    {
      "x": -36,
      "y": 4,
      "z": 14,
      "name": "Soil_Pathway"
    },
    {
      "x": -36,
      "y": 0,
      "z": 15,
      "name": "Rock_Sandstone_Cobble"
    },
    {
      "x": -36,
      "y": 1,
      "z": 15,
      "name": "Rock_Sandstone_Cobble"
    },
    {
      "x": -36,
      "y": 2,
      "z": 15,
      "name": "Rock_Sandstone_Cobble"
    },
    {
      "x": -36,
      "y": 3,
      "z": 15,
      "name": "Soil_Dirt_Dry"
    },
    {
      "x": -36,
      "y": 4,
      "z": 15,
      "name": "Soil_Dirt_Dry"
    },
    {
      "x": -36,
      "y": 0,
      "z": 16,
      "name": "Rock_Sandstone_Cobble"
    },
    {
      "x": -36,
      "y": 1,
      "z": 16,
      "name": "Rock_Sandstone_Cobble"
    },
    {
      "x": -36,
      "y": 2,
      "z": 16,
      "name": "Rock_Sandstone_Cobble"
    },
    {
      "x": -36,
      "y": 3,
      "z": 16,
      "name": "Soil_Dirt_Dry"
    },
    {
      "x": -36,
      "y": 0,
      "z": 17,
      "name": "Rock_Sandstone_Cobble"
    },
    {
      "x": -36,
      "y": 1,
      "z": 17,
      "name": "Rock_Sandstone_Cobble"
    },
    {
      "x": -36,
      "y": 2,
      "z": 17,
      "name": "Rock_Sandstone_Cobble"
    },
    {
      "x": -35,
      "y": 0,
      "z": -23,
      "name": "Rock_Sandstone_Cobble"
    },
    {
      "x": -35,
      "y": 1,
      "z": -23,
      "name": "Rock_Sandstone_Cobble"
    },
    {
      "x": -35,
      "y": 0,
      "z": -22,
      "name": "Rock_Sandstone_Cobble"
    },
    {
      "x": -35,
      "y": 1,
      "z": -22,
      "name": "Rock_Sandstone_Cobble"
    },
    {
      "x": -35,
      "y": 2,
      "z": -22,
      "name": "Rock_Sandstone_Cobble"
    },
    {
      "x": -35,
      "y": 0,
      "z": -21,
      "name": "Rock_Sandstone_Cobble"
    },
    {
      "x": -35,
      "y": 1,
      "z": -21,
      "name": "Rock_Sandstone_Cobble"
    },
    {
      "x": -35,
      "y": 2,
      "z": -21,
      "name": "Rock_Sandstone_Cobble"
    },
    {
      "x": -35,
      "y": 3,
      "z": -21,
      "name": "Soil_Dirt_Dry"
    },
    {
      "x": -35,
      "y": 2,
      "z": -20,
      "name": "Rock_Sandstone_Cobble"
    },
    {
      "x": -35,
      "y": 3,
      "z": -20,
      "name": "Soil_Dirt_Dry"
    },
    {
      "x": -35,
      "y": 2,
      "z": -19,
      "name": "Soil_Pathway"
    },
    {
      "x": -35,
      "y": 3,
      "z": -19,
      "name": "Soil_Dirt_Dry"
    },
    {
      "x": -35,
      "y": 2,
      "z": -18,
      "name": "Soil_Dirt_Dry"
    },
    {
      "x": -35,
      "y": 3,
      "z": -18,
      "name": "Soil_Dirt_Dry"
    },
    {
      "x": -35,
      "y": 4,
      "z": -18,
      "name": "Soil_Pathway"
    },
    {
      "x": -35,
      "y": 2,
      "z": -17,
      "name": "Rock_Sandstone_Cobble"
    },
    {
      "x": -35,
      "y": 3,
      "z": -17,
      "name": "Soil_Dirt_Dry"
    },
    {
      "x": -35,
      "y": 4,
      "z": -17,
      "name": "Soil_Pathway"
    },
    {
      "x": -35,
      "y": 2,
      "z": -16,
      "name": "Rock_Sandstone_Cobble"
    },
    {
      "x": -35,
      "y": 3,
      "z": -16,
      "name": "Soil_Dirt_Dry"
    },
    {
      "x": -35,
      "y": 4,
      "z": -16,
      "name": "Soil_Pathway"
    },
    {
      "x": -35,
      "y": 2,
      "z": -15,
      "name": "Rock_Sandstone_Cobble"
    },
    {
      "x": -35,
      "y": 3,
      "z": -15,
      "name": "Soil_Dirt_Dry"
    },
    {
      "x": -35,
      "y": 4,
      "z": -15,
      "name": "Soil_Pathway"
    },
    {
      "x": -35,
      "y": 2,
      "z": -14,
      "name": "Rock_Sandstone_Cobble"
    },
    {
      "x": -35,
      "y": 3,
      "z": -14,
      "name": "Soil_Dirt_Dry"
    },
    {
      "x": -35,
      "y": 4,
      "z": -14,
      "name": "Soil_Pathway"
    },
    {
      "x": -35,
      "y": 1,
      "z": -13,
      "name": "Rock_Sandstone_Cobble"
    },
    {
      "x": -35,
      "y": 2,
      "z": -13,
      "name": "Rock_Sandstone_Cobble"
    },
    {
      "x": -35,
      "y": 3,
      "z": -13,
      "name": "Soil_Dirt_Dry"
    },
    {
      "x": -35,
      "y": 4,
      "z": -13,
      "name": "Soil_Pathway"
    },
    {
      "x": -35,
      "y": 5,
      "z": -13,
      "name": "Soil_Dirt_Dry"
    },
    {
      "x": -35,
      "y": 1,
      "z": -12,
      "name": "Rock_Sandstone_Cobble"
    },
    {
      "x": -35,
      "y": 2,
      "z": -12,
      "name": "Rock_Sandstone_Cobble"
    },
    {
      "x": -35,
      "y": 4,
      "z": -12,
      "name": "Soil_Pathway"
    },
    {
      "x": -35,
      "y": 5,
      "z": -12,
      "name": "Soil_Dirt_Dry"
    },
    {
      "x": -35,
      "y": 1,
      "z": -11,
      "name": "Rock_Sandstone_Cobble"
    },
    {
      "x": -35,
      "y": 4,
      "z": -11,
      "name": "Soil_Pathway"
    },
    {
      "x": -35,
      "y": 5,
      "z": -11,
      "name": "Soil_Dirt_Dry"
    },
    {
      "x": -35,
      "y": 4,
      "z": -10,
      "name": "Soil_Pathway"
    },
    {
      "x": -35,
      "y": 5,
      "z": -10,
      "name": "Soil_Dirt_Dry"
    },
    {
      "x": -35,
      "y": 4,
      "z": -9,
      "name": "Soil_Pathway"
    },
    {
      "x": -35,
      "y": 5,
      "z": -9,
      "name": "Soil_Dirt_Dry"
    },
    {
      "x": -35,
      "y": 4,
      "z": -8,
      "name": "Soil_Pathway"
    },
    {
      "x": -35,
      "y": 5,
      "z": -8,
      "name": "Soil_Pathway"
    },
    {
      "x": -35,
      "y": 4,
      "z": -7,
      "name": "Soil_Pathway"
    },
    {
      "x": -35,
      "y": 5,
      "z": -7,
      "name": "Soil_Dirt_Dry"
    },
    {
      "x": -35,
      "y": 3,
      "z": -6,
      "name": "Soil_Dirt_Dry"
    },
    {
      "x": -35,
      "y": 4,
      "z": -6,
      "name": "Soil_Pathway"
    },
    {
      "x": -35,
      "y": 3,
      "z": -5,
      "name": "Soil_Dirt_Dry"
    },
    {
      "x": -35,
      "y": 4,
      "z": -5,
      "name": "Soil_Pathway"
    },
    {
      "x": -35,
      "y": 3,
      "z": -4,
      "name": "Soil_Dirt_Dry"
    },
    {
      "x": -35,
      "y": 4,
      "z": -4,
      "name": "Soil_Pathway"
    },
    {
      "x": -35,
      "y": 3,
      "z": -3,
      "name": "Soil_Dirt_Dry"
    },
    {
      "x": -35,
      "y": 4,
      "z": -3,
      "name": "Soil_Pathway"
    },
    {
      "x": -35,
      "y": 4,
      "z": -2,
      "name": "Soil_Pathway"
    },
    {
      "x": -35,
      "y": 4,
      "z": -1,
      "name": "Soil_Pathway"
    },
    {
      "x": -35,
      "y": 5,
      "z": -1,
      "name": "Soil_Dirt_Dry"
    },
    {
      "x": -35,
      "y": 4,
      "z": 0,
      "name": "Soil_Pathway"
    },
    {
      "x": -35,
      "y": 5,
      "z": 0,
      "name": "Soil_Dirt_Dry"
    },
    {
      "x": -35,
      "y": 4,
      "z": 1,
      "name": "Soil_Pathway"
    },
    {
      "x": -35,
      "y": 5,
      "z": 1,
      "name": "Soil_Dirt_Dry"
    },
    {
      "x": -35,
      "y": 4,
      "z": 2,
      "name": "Soil_Pathway"
    },
    {
      "x": -35,
      "y": 5,
      "z": 2,
      "name": "Soil_Dirt_Dry"
    },
    {
      "x": -35,
      "y": 4,
      "z": 3,
      "name": "Soil_Pathway"
    },
    {
      "x": -35,
      "y": 5,
      "z": 3,
      "name": "Soil_Mud_Dry"
    },
    {
      "x": -35,
      "y": 4,
      "z": 4,
      "name": "Soil_Pathway"
    },
    {
      "x": -35,
      "y": 3,
      "z": 5,
      "name": "Soil_Dirt_Dry"
    },
    {
      "x": -35,
      "y": 4,
      "z": 5,
      "name": "Soil_Pathway"
    },
    {
      "x": -35,
      "y": 3,
      "z": 6,
      "name": "Soil_Dirt_Dry"
    },
    {
      "x": -35,
      "y": 4,
      "z": 6,
      "name": "Soil_Pathway"
    },
    {
      "x": -35,
      "y": 3,
      "z": 7,
      "name": "Soil_Dirt_Dry"
    },
    {
      "x": -35,
      "y": 4,
      "z": 7,
      "name": "Soil_Pathway"
    },
    {
      "x": -35,
      "y": 3,
      "z": 8,
      "name": "Soil_Dirt_Dry"
    },
    {
      "x": -35,
      "y": 4,
      "z": 8,
      "name": "Soil_Pathway"
    },
    {
      "x": -35,
      "y": 4,
      "z": 9,
      "name": "Soil_Pathway"
    },
    {
      "x": -35,
      "y": 4,
      "z": 10,
      "name": "Soil_Pathway"
    },
    {
      "x": -35,
      "y": 5,
      "z": 10,
      "name": "Soil_Pathway"
    },
    {
      "x": -35,
      "y": 4,
      "z": 11,
      "name": "Soil_Pathway"
    },
    {
      "x": -35,
      "y": 5,
      "z": 11,
      "name": "Soil_Pathway"
    },
    {
      "x": -35,
      "y": 4,
      "z": 12,
      "name": "Soil_Pathway"
    },
    {
      "x": -35,
      "y": 5,
      "z": 12,
      "name": "Soil_Pathway"
    },
    {
      "x": -35,
      "y": 4,
      "z": 13,
      "name": "Soil_Pathway"
    },
    {
      "x": -35,
      "y": 3,
      "z": 14,
      "name": "Soil_Dirt_Dry"
    },
    {
      "x": -35,
      "y": 4,
      "z": 14,
      "name": "Soil_Pathway"
    },
    {
      "x": -35,
      "y": 3,
      "z": 15,
      "name": "Soil_Dirt_Dry"
    },
    {
      "x": -35,
      "y": 4,
      "z": 15,
      "name": "Soil_Pathway"
    },
    {
      "x": -35,
      "y": 0,
      "z": 16,
      "name": "Rock_Sandstone_Cobble"
    },
    {
      "x": -35,
      "y": 1,
      "z": 16,
      "name": "Rock_Sandstone_Cobble"
    },
    {
      "x": -35,
      "y": 2,
      "z": 16,
      "name": "Rock_Sandstone_Cobble"
    },
    {
      "x": -35,
      "y": 3,
      "z": 16,
      "name": "Soil_Dirt_Dry"
    },
    {
      "x": -35,
      "y": 4,
      "z": 16,
      "name": "Soil_Dirt_Dry"
    },
    {
      "x": -35,
      "y": 0,
      "z": 17,
      "name": "Rock_Sandstone_Cobble"
    },
    {
      "x": -35,
      "y": 1,
      "z": 17,
      "name": "Rock_Sandstone_Cobble"
    },
    {
      "x": -35,
      "y": 2,
      "z": 17,
      "name": "Rock_Sandstone_Cobble"
    },
    {
      "x": -35,
      "y": 3,
      "z": 17,
      "name": "Soil_Dirt_Dry"
    },
    {
      "x": -34,
      "y": 0,
      "z": -23,
      "name": "Rock_Sandstone_Cobble"
    },
    {
      "x": -34,
      "y": 1,
      "z": -23,
      "name": "Rock_Sandstone_Cobble"
    },
    {
      "x": -34,
      "y": 2,
      "z": -23,
      "name": "Rock_Sandstone_Cobble"
    },
    {
      "x": -34,
      "y": 1,
      "z": -22,
      "name": "Rock_Sandstone_Cobble"
    },
    {
      "x": -34,
      "y": 2,
      "z": -22,
      "name": "Rock_Sandstone_Cobble"
    },
    {
      "x": -34,
      "y": 3,
      "z": -22,
      "name": "Soil_Dirt_Dry"
    },
    {
      "x": -34,
      "y": 2,
      "z": -21,
      "name": "Rock_Sandstone_Cobble"
    },
    {
      "x": -34,
      "y": 3,
      "z": -21,
      "name": "Soil_Pathway"
    },
    {
      "x": -34,
      "y": 2,
      "z": -20,
      "name": "Rock_Sandstone_Cobble"
    },
    {
      "x": -34,
      "y": 3,
      "z": -20,
      "name": "Soil_Dirt_Dry"
    },
    {
      "x": -34,
      "y": 3,
      "z": -19,
      "name": "Soil_Dirt_Dry"
    },
    {
      "x": -34,
      "y": 4,
      "z": -19,
      "name": "Soil_Pathway"
    },
    {
      "x": -34,
      "y": 3,
      "z": -18,
      "name": "Soil_Dirt_Dry"
    },
    {
      "x": -34,
      "y": 4,
      "z": -18,
      "name": "Soil_Dirt_Dry"
    },
    {
      "x": -34,
      "y": 2,
      "z": -17,
      "name": "Rock_Sandstone_Cobble"
    },
    {
      "x": -34,
      "y": 3,
      "z": -17,
      "name": "Soil_Dirt_Dry"
    },
    {
      "x": -34,
      "y": 4,
      "z": -17,
      "name": "Soil_Dirt_Dry"
    },
    {
      "x": -34,
      "y": 5,
      "z": -17,
      "name": "Soil_Dirt_Dry"
    },
    {
      "x": -34,
      "y": 2,
      "z": -16,
      "name": "Rock_Sandstone_Cobble"
    },
    {
      "x": -34,
      "y": 3,
      "z": -16,
      "name": "Soil_Dirt_Dry"
    },
    {
      "x": -34,
      "y": 4,
      "z": -16,
      "name": "Soil_Dirt_Dry"
    },
    {
      "x": -34,
      "y": 5,
      "z": -16,
      "name": "Soil_Dirt_Dry"
    },
    {
      "x": -34,
      "y": 3,
      "z": -15,
      "name": "Soil_Mud_Dry"
    },
    {
      "x": -34,
      "y": 4,
      "z": -15,
      "name": "Soil_Dirt_Dry"
    },
    {
      "x": -34,
      "y": 5,
      "z": -15,
      "name": "Soil_Dirt_Dry"
    },
    {
      "x": -34,
      "y": 2,
      "z": -14,
      "name": "Rock_Sandstone_Cobble"
    },
    {
      "x": -34,
      "y": 3,
      "z": -14,
      "name": "Soil_Dirt_Dry"
    },
    {
      "x": -34,
      "y": 4,
      "z": -14,
      "name": "Soil_Dirt_Dry"
    },
    {
      "x": -34,
      "y": 5,
      "z": -14,
      "name": "Soil_Dirt_Dry"
    },
    {
      "x": -34,
      "y": 2,
      "z": -13,
      "name": "Rock_Sandstone_Cobble"
    },
    {
      "x": -34,
      "y": 3,
      "z": -13,
      "name": "Soil_Dirt_Dry"
    },
    {
      "x": -34,
      "y": 4,
      "z": -13,
      "name": "Soil_Pathway"
    },
    {
      "x": -34,
      "y": 5,
      "z": -13,
      "name": "Soil_Dirt_Dry"
    },
    {
      "x": -34,
      "y": 1,
      "z": -12,
      "name": "Rock_Sandstone_Cobble"
    },
    {
      "x": -34,
      "y": 2,
      "z": -12,
      "name": "Rock_Sandstone_Cobble"
    },
    {
      "x": -34,
      "y": 3,
      "z": -12,
      "name": "Soil_Dirt_Dry"
    },
    {
      "x": -34,
      "y": 4,
      "z": -12,
      "name": "Soil_Pathway"
    },
    {
      "x": -34,
      "y": 5,
      "z": -12,
      "name": "Soil_Dirt_Dry"
    },
    {
      "x": -34,
      "y": 1,
      "z": -11,
      "name": "Rock_Sandstone_Cobble"
    },
    {
      "x": -34,
      "y": 2,
      "z": -11,
      "name": "Rock_Sandstone_Cobble"
    },
    {
      "x": -34,
      "y": 4,
      "z": -11,
      "name": "Soil_Dirt_Dry"
    },
    {
      "x": -34,
      "y": 5,
      "z": -11,
      "name": "Soil_Gravel_Sand"
    },
    {
      "x": -34,
      "y": 4,
      "z": -10,
      "name": "Soil_Gravel_Sand"
    },
    {
      "x": -34,
      "y": 5,
      "z": -10,
      "name": "Soil_Dirt_Dry"
    },
    {
      "x": -34,
      "y": 4,
      "z": -9,
      "name": "Soil_Dirt_Dry"
    },
    {
      "x": -34,
      "y": 5,
      "z": -9,
      "name": "Soil_Dirt_Dry"
    },
    {
      "x": -34,
      "y": 4,
      "z": -8,
      "name": "Soil_Pathway"
    },
    {
      "x": -34,
      "y": 5,
      "z": -8,
      "name": "Soil_Dirt_Dry"
    },
    {
      "x": -34,
      "y": 4,
      "z": -7,
      "name": "Soil_Pathway"
    },
    {
      "x": -34,
      "y": 5,
      "z": -7,
      "name": "Soil_Dirt_Dry"
    },
    {
      "x": -34,
      "y": 3,
      "z": -6,
      "name": "Soil_Dirt_Dry"
    },
    {
      "x": -34,
      "y": 4,
      "z": -6,
      "name": "Soil_Pathway"
    },
    {
      "x": -34,
      "y": 5,
      "z": -6,
      "name": "Soil_Pathway"
    },
    {
      "x": -34,
      "y": 3,
      "z": -5,
      "name": "Soil_Dirt_Dry"
    },
    {
      "x": -34,
      "y": 4,
      "z": -5,
      "name": "Soil_Pathway"
    },
    {
      "x": -34,
      "y": 3,
      "z": -4,
      "name": "Soil_Dirt_Dry"
    },
    {
      "x": -34,
      "y": 4,
      "z": -4,
      "name": "Soil_Pathway"
    },
    {
      "x": -34,
      "y": 3,
      "z": -3,
      "name": "Soil_Dirt_Dry"
    },
    {
      "x": -34,
      "y": 4,
      "z": -3,
      "name": "Soil_Pathway"
    },
    {
      "x": -34,
      "y": 4,
      "z": -2,
      "name": "Soil_Pathway"
    },
    {
      "x": -34,
      "y": 5,
      "z": -2,
      "name": "Soil_Dirt_Dry"
    },
    {
      "x": -34,
      "y": 4,
      "z": -1,
      "name": "Soil_Pathway"
    },
    {
      "x": -34,
      "y": 5,
      "z": -1,
      "name": "Soil_Dirt_Dry"
    },
    {
      "x": -34,
      "y": 4,
      "z": 0,
      "name": "Soil_Pathway"
    },
    {
      "x": -34,
      "y": 5,
      "z": 0,
      "name": "Soil_Dirt_Dry"
    },
    {
      "x": -34,
      "y": 4,
      "z": 1,
      "name": "Soil_Pathway"
    },
    {
      "x": -34,
      "y": 5,
      "z": 1,
      "name": "Soil_Dirt_Dry"
    },
    {
      "x": -34,
      "y": 4,
      "z": 2,
      "name": "Soil_Pathway"
    },
    {
      "x": -34,
      "y": 5,
      "z": 2,
      "name": "Soil_Mud_Dry"
    },
    {
      "x": -34,
      "y": 4,
      "z": 3,
      "name": "Soil_Pathway"
    },
    {
      "x": -34,
      "y": 5,
      "z": 3,
      "name": "Soil_Pathway"
    },
    {
      "x": -34,
      "y": 4,
      "z": 4,
      "name": "Soil_Pathway"
    },
    {
      "x": -34,
      "y": 5,
      "z": 4,
      "name": "Soil_Dirt_Dry"
    },
    {
      "x": -34,
      "y": 3,
      "z": 5,
      "name": "Soil_Dirt_Dry"
    },
    {
      "x": -34,
      "y": 4,
      "z": 5,
      "name": "Soil_Pathway"
    },
    {
      "x": -34,
      "y": 3,
      "z": 6,
      "name": "Soil_Dirt_Dry"
    },
    {
      "x": -34,
      "y": 4,
      "z": 6,
      "name": "Soil_Pathway"
    },
    {
      "x": -34,
      "y": 3,
      "z": 7,
      "name": "Soil_Dirt_Dry"
    },
    {
      "x": -34,
      "y": 4,
      "z": 7,
      "name": "Soil_Pathway"
    },
    {
      "x": -34,
      "y": 3,
      "z": 8,
      "name": "Soil_Dirt_Dry"
    },
    {
      "x": -34,
      "y": 4,
      "z": 8,
      "name": "Soil_Pathway"
    },
    {
      "x": -34,
      "y": 4,
      "z": 9,
      "name": "Soil_Pathway"
    },
    {
      "x": -34,
      "y": 5,
      "z": 9,
      "name": "Soil_Pathway"
    },
    {
      "x": -34,
      "y": 4,
      "z": 10,
      "name": "Soil_Pathway"
    },
    {
      "x": -34,
      "y": 5,
      "z": 10,
      "name": "Soil_Pathway"
    },
    {
      "x": -34,
      "y": 4,
      "z": 11,
      "name": "Soil_Pathway"
    },
    {
      "x": -34,
      "y": 5,
      "z": 11,
      "name": "Soil_Pathway"
    },
    {
      "x": -34,
      "y": 4,
      "z": 12,
      "name": "Soil_Pathway"
    },
    {
      "x": -34,
      "y": 5,
      "z": 12,
      "name": "Soil_Pathway"
    },
    {
      "x": -34,
      "y": 4,
      "z": 13,
      "name": "Soil_Pathway"
    },
    {
      "x": -34,
      "y": 5,
      "z": 13,
      "name": "Soil_Pathway"
    },
    {
      "x": -34,
      "y": 4,
      "z": 14,
      "name": "Soil_Pathway"
    },
    {
      "x": -34,
      "y": 3,
      "z": 15,
      "name": "Soil_Dirt_Dry"
    },
    {
      "x": -34,
      "y": 4,
      "z": 15,
      "name": "Soil_Pathway"
    },
    {
      "x": -34,
      "y": 3,
      "z": 16,
      "name": "Soil_Dirt_Dry"
    },
    {
      "x": -34,
      "y": 4,
      "z": 16,
      "name": "Soil_Pathway"
    },
    {
      "x": -34,
      "y": 0,
      "z": 17,
      "name": "Rock_Sandstone_Cobble"
    },
    {
      "x": -34,
      "y": 1,
      "z": 17,
      "name": "Rock_Sandstone_Cobble"
    },
    {
      "x": -34,
      "y": 2,
      "z": 17,
      "name": "Rock_Sandstone_Cobble"
    },
    {
      "x": -34,
      "y": 3,
      "z": 17,
      "name": "Soil_Dirt_Dry"
    },
    {
      "x": -34,
      "y": 0,
      "z": 18,
      "name": "Rock_Sandstone_Cobble"
    },
    {
      "x": -34,
      "y": 1,
      "z": 18,
      "name": "Rock_Sandstone_Cobble"
    },
    {
      "x": -34,
      "y": 2,
      "z": 18,
      "name": "Rock_Sandstone_Cobble"
    },
    {
      "x": -33,
      "y": 0,
      "z": -24,
      "name": "Rock_Sandstone_Cobble"
    },
    {
      "x": -33,
      "y": 1,
      "z": -24,
      "name": "Rock_Sandstone_Cobble"
    },
    {
      "x": -33,
      "y": 2,
      "z": -24,
      "name": "Rock_Sandstone_Cobble"
    },
    {
      "x": -33,
      "y": 1,
      "z": -23,
      "name": "Rock_Sandstone_Cobble"
    },
    {
      "x": -33,
      "y": 2,
      "z": -23,
      "name": "Rock_Sandstone_Cobble"
    },
    {
      "x": -33,
      "y": 3,
      "z": -23,
      "name": "Soil_Mud_Dry"
    },
    {
      "x": -33,
      "y": 2,
      "z": -22,
      "name": "Rock_Sandstone_Cobble"
    },
    {
      "x": -33,
      "y": 3,
      "z": -22,
      "name": "Soil_Dirt_Dry"
    },
    {
      "x": -33,
      "y": 2,
      "z": -21,
      "name": "Rock_Sandstone_Cobble"
    },
    {
      "x": -33,
      "y": 3,
      "z": -21,
      "name": "Soil_Dirt_Dry"
    },
    {
      "x": -33,
      "y": 2,
      "z": -20,
      "name": "Rock_Sandstone_Cobble"
    },
    {
      "x": -33,
      "y": 3,
      "z": -20,
      "name": "Soil_Dirt_Dry"
    },
    {
      "x": -33,
      "y": 4,
      "z": -20,
      "name": "Soil_Pathway"
    },
    {
      "x": -33,
      "y": 3,
      "z": -19,
      "name": "Soil_Gravel_Sand"
    },
    {
      "x": -33,
      "y": 4,
      "z": -19,
      "name": "Soil_Dirt_Dry"
    },
    {
      "x": -33,
      "y": 3,
      "z": -18,
      "name": "Soil_Dirt_Dry"
    },
    {
      "x": -33,
      "y": 4,
      "z": -18,
      "name": "Soil_Dirt_Dry"
    },
    {
      "x": -33,
      "y": 2,
      "z": -17,
      "name": "Rock_Sandstone_Cobble"
    },
    {
      "x": -33,
      "y": 3,
      "z": -17,
      "name": "Soil_Dirt_Dry"
    },
    {
      "x": -33,
      "y": 4,
      "z": -17,
      "name": "Soil_Dirt_Dry"
    },
    {
      "x": -33,
      "y": 5,
      "z": -17,
      "name": "Soil_Dirt_Dry"
    },
    {
      "x": -33,
      "y": 2,
      "z": -16,
      "name": "Rock_Sandstone_Cobble"
    },
    {
      "x": -33,
      "y": 3,
      "z": -16,
      "name": "Soil_Dirt_Dry"
    },
    {
      "x": -33,
      "y": 4,
      "z": -16,
      "name": "Soil_Dirt_Dry"
    },
    {
      "x": -33,
      "y": 5,
      "z": -16,
      "name": "Soil_Pathway"
    },
    {
      "x": -33,
      "y": 3,
      "z": -15,
      "name": "Soil_Dirt_Dry"
    },
    {
      "x": -33,
      "y": 4,
      "z": -15,
      "name": "Soil_Dirt_Dry"
    },
    {
      "x": -33,
      "y": 5,
      "z": -15,
      "name": "Soil_Dirt_Dry"
    },
    {
      "x": -33,
      "y": 12,
      "z": -15,
      "name": "*Cloth_Roof_Leather_State_Definitions_Corner_Left",
      "rotation": 2
    },
    {
      "x": -33,
      "y": 3,
      "z": -14,
      "name": "Soil_Dirt_Dry"
    },
    {
      "x": -33,
      "y": 4,
      "z": -14,
      "name": "Soil_Pathway"
    },
    {
      "x": -33,
      "y": 6,
      "z": -14,
      "name": "Soil_Dirt_Dry"
    },
    {
      "x": -33,
      "y": 12,
      "z": -14,
      "name": "Cloth_Roof_Leather",
      "rotation": 3
    },
    {
      "x": -33,
      "y": 2,
      "z": -13,
      "name": "Rock_Sandstone_Cobble"
    },
    {
      "x": -33,
      "y": 3,
      "z": -13,
      "name": "Soil_Dirt_Dry"
    },
    {
      "x": -33,
      "y": 4,
      "z": -13,
      "name": "Soil_Dirt_Dry"
    },
    {
      "x": -33,
      "y": 5,
      "z": -13,
      "name": "Soil_Dirt_Dry"
    },
    {
      "x": -33,
      "y": 6,
      "z": -13,
      "name": "Soil_Dirt_Dry"
    },
    {
      "x": -33,
      "y": 12,
      "z": -13,
      "name": "Cloth_Roof_Leather",
      "rotation": 3
    },
    {
      "x": -33,
      "y": 2,
      "z": -12,
      "name": "Rock_Sandstone_Cobble"
    },
    {
      "x": -33,
      "y": 3,
      "z": -12,
      "name": "Soil_Dirt_Dry"
    },
    {
      "x": -33,
      "y": 4,
      "z": -12,
      "name": "Soil_Pathway"
    },
    {
      "x": -33,
      "y": 5,
      "z": -12,
      "name": "Soil_Dirt_Dry"
    },
    {
      "x": -33,
      "y": 6,
      "z": -12,
      "name": "Soil_Dirt_Dry"
    },
    {
      "x": -33,
      "y": 12,
      "z": -12,
      "name": "Cloth_Roof_Leather",
      "rotation": 3
    },
    {
      "x": -33,
      "y": 1,
      "z": -11,
      "name": "Rock_Sandstone_Cobble"
    },
    {
      "x": -33,
      "y": 2,
      "z": -11,
      "name": "Rock_Sandstone_Cobble"
    },
    {
      "x": -33,
      "y": 4,
      "z": -11,
      "name": "Soil_Dirt_Dry"
    },
    {
      "x": -33,
      "y": 5,
      "z": -11,
      "name": "Soil_Dirt_Dry"
    },
    {
      "x": -33,
      "y": 12,
      "z": -11,
      "name": "Cloth_Roof_Leather",
      "rotation": 3
    },
    {
      "x": -33,
      "y": 1,
      "z": -10,
      "name": "Rock_Sandstone_Cobble"
    },
    {
      "x": -33,
      "y": 4,
      "z": -10,
      "name": "Soil_Pathway"
    },
    {
      "x": -33,
      "y": 5,
      "z": -10,
      "name": "Soil_Gravel_Sand"
    },
    {
      "x": -33,
      "y": 12,
      "z": -10,
      "name": "Cloth_Roof_Leather",
      "rotation": 3
    },
    {
      "x": -33,
      "y": 4,
      "z": -9,
      "name": "Soil_Dirt_Dry"
    },
    {
      "x": -33,
      "y": 5,
      "z": -9,
      "name": "Soil_Dirt_Dry"
    },
    {
      "x": -33,
      "y": 12,
      "z": -9,
      "name": "Cloth_Roof_Leather",
      "rotation": 3
    },
    {
      "x": -33,
      "y": 4,
      "z": -8,
      "name": "Soil_Dirt_Dry"
    },
    {
      "x": -33,
      "y": 5,
      "z": -8,
      "name": "Soil_Dirt_Dry"
    },
    {
      "x": -33,
      "y": 12,
      "z": -8,
      "name": "Cloth_Roof_Leather",
      "rotation": 3
    },
    {
      "x": -33,
      "y": 4,
      "z": -7,
      "name": "Soil_Dirt_Dry"
    },
    {
      "x": -33,
      "y": 5,
      "z": -7,
      "name": "Soil_Dirt_Dry"
    },
    {
      "x": -33,
      "y": 12,
      "z": -7,
      "name": "Cloth_Roof_Leather",
      "rotation": 3
    },
    {
      "x": -33,
      "y": 3,
      "z": -6,
      "name": "Soil_Dirt_Dry"
    },
    {
      "x": -33,
      "y": 4,
      "z": -6,
      "name": "Soil_Pathway"
    },
    {
      "x": -33,
      "y": 5,
      "z": -6,
      "name": "Soil_Dirt_Dry"
    },
    {
      "x": -33,
      "y": 12,
      "z": -6,
      "name": "Cloth_Roof_Leather",
      "rotation": 3
    },
    {
      "x": -33,
      "y": 3,
      "z": -5,
      "name": "Soil_Dirt_Dry"
    },
    {
      "x": -33,
      "y": 4,
      "z": -5,
      "name": "Soil_Pathway"
    },
    {
      "x": -33,
      "y": 5,
      "z": -5,
      "name": "Soil_Dirt_Dry"
    },
    {
      "x": -33,
      "y": 12,
      "z": -5,
      "name": "*Cloth_Roof_Leather_State_Definitions_Corner_Left",
      "rotation": 3
    },
    {
      "x": -33,
      "y": 3,
      "z": -4,
      "name": "Soil_Dirt_Dry"
    },
    {
      "x": -33,
      "y": 4,
      "z": -4,
      "name": "Soil_Pathway"
    },
    {
      "x": -33,
      "y": 3,
      "z": -3,
      "name": "Soil_Dirt_Dry"
    },
    {
      "x": -33,
      "y": 4,
      "z": -3,
      "name": "Soil_Pathway"
    },
    {
      "x": -33,
      "y": 4,
      "z": -2,
      "name": "Soil_Pathway"
    },
    {
      "x": -33,
      "y": 5,
      "z": -2,
      "name": "Soil_Dirt_Dry"
    },
    {
      "x": -33,
      "y": 4,
      "z": -1,
      "name": "Soil_Pathway"
    },
    {
      "x": -33,
      "y": 5,
      "z": -1,
      "name": "Soil_Dirt_Dry"
    },
    {
      "x": -33,
      "y": 4,
      "z": 0,
      "name": "Soil_Pathway"
    },
    {
      "x": -33,
      "y": 5,
      "z": 0,
      "name": "Soil_Dirt_Dry"
    },
    {
      "x": -33,
      "y": 4,
      "z": 1,
      "name": "Soil_Pathway"
    },
    {
      "x": -33,
      "y": 5,
      "z": 1,
      "name": "Soil_Dirt_Dry"
    },
    {
      "x": -33,
      "y": 4,
      "z": 2,
      "name": "Soil_Pathway"
    },
    {
      "x": -33,
      "y": 5,
      "z": 2,
      "name": "Soil_Dirt_Dry"
    },
    {
      "x": -33,
      "y": 4,
      "z": 3,
      "name": "Soil_Pathway"
    },
    {
      "x": -33,
      "y": 5,
      "z": 3,
      "name": "Soil_Dirt_Dry"
    },
    {
      "x": -33,
      "y": 3,
      "z": 4,
      "name": "Soil_Dirt_Dry"
    },
    {
      "x": -33,
      "y": 4,
      "z": 4,
      "name": "Soil_Pathway"
    },
    {
      "x": -33,
      "y": 5,
      "z": 4,
      "name": "Soil_Dirt_Dry"
    },
    {
      "x": -33,
      "y": 3,
      "z": 5,
      "name": "Soil_Dirt_Dry"
    },
    {
      "x": -33,
      "y": 4,
      "z": 5,
      "name": "Soil_Pathway"
    },
    {
      "x": -33,
      "y": 3,
      "z": 6,
      "name": "Soil_Dirt_Dry"
    },
    {
      "x": -33,
      "y": 4,
      "z": 6,
      "name": "Soil_Pathway"
    },
    {
      "x": -33,
      "y": 3,
      "z": 7,
      "name": "Soil_Dirt_Dry"
    },
    {
      "x": -33,
      "y": 4,
      "z": 7,
      "name": "Soil_Pathway"
    },
    {
      "x": -33,
      "y": 3,
      "z": 8,
      "name": "Soil_Dirt_Dry"
    },
    {
      "x": -33,
      "y": 4,
      "z": 8,
      "name": "Soil_Pathway"
    },
    {
      "x": -33,
      "y": 5,
      "z": 8,
      "name": "Soil_Pathway"
    },
    {
      "x": -33,
      "y": 4,
      "z": 9,
      "name": "Soil_Pathway"
    },
    {
      "x": -33,
      "y": 5,
      "z": 9,
      "name": "Soil_Pathway"
    },
    {
      "x": -33,
      "y": 4,
      "z": 10,
      "name": "Soil_Pathway"
    },
    {
      "x": -33,
      "y": 5,
      "z": 10,
      "name": "Soil_Pathway"
    },
    {
      "x": -33,
      "y": 4,
      "z": 11,
      "name": "Soil_Pathway"
    },
    {
      "x": -33,
      "y": 5,
      "z": 11,
      "name": "Soil_Pathway"
    },
    {
      "x": -33,
      "y": 4,
      "z": 12,
      "name": "Soil_Pathway"
    },
    {
      "x": -33,
      "y": 5,
      "z": 12,
      "name": "Soil_Pathway"
    },
    {
      "x": -33,
      "y": 4,
      "z": 13,
      "name": "Soil_Pathway"
    },
    {
      "x": -33,
      "y": 5,
      "z": 13,
      "name": "Soil_Pathway"
    },
    {
      "x": -33,
      "y": 4,
      "z": 14,
      "name": "Soil_Pathway"
    },
    {
      "x": -33,
      "y": 5,
      "z": 14,
      "name": "Soil_Pathway"
    },
    {
      "x": -33,
      "y": 0,
      "z": 15,
      "name": "Rock_Sandstone_Cobble"
    },
    {
      "x": -33,
      "y": 1,
      "z": 15,
      "name": "Rock_Sandstone_Cobble"
    },
    {
      "x": -33,
      "y": 2,
      "z": 15,
      "name": "Rock_Sandstone_Cobble"
    },
    {
      "x": -33,
      "y": 3,
      "z": 15,
      "name": "Soil_Pathway"
    },
    {
      "x": -33,
      "y": 4,
      "z": 15,
      "name": "Soil_Pathway"
    },
    {
      "x": -33,
      "y": 0,
      "z": 16,
      "name": "Rock_Sandstone_Cobble"
    },
    {
      "x": -33,
      "y": 1,
      "z": 16,
      "name": "Rock_Sandstone_Cobble"
    },
    {
      "x": -33,
      "y": 2,
      "z": 16,
      "name": "Rock_Sandstone_Cobble"
    },
    {
      "x": -33,
      "y": 3,
      "z": 16,
      "name": "Soil_Pathway"
    },
    {
      "x": -33,
      "y": 4,
      "z": 16,
      "name": "Soil_Pathway"
    },
    {
      "x": -33,
      "y": 0,
      "z": 17,
      "name": "Rock_Sandstone_Cobble"
    },
    {
      "x": -33,
      "y": 1,
      "z": 17,
      "name": "Rock_Sandstone_Cobble"
    },
    {
      "x": -33,
      "y": 2,
      "z": 17,
      "name": "Rock_Sandstone_Cobble"
    },
    {
      "x": -33,
      "y": 3,
      "z": 17,
      "name": "Soil_Pathway"
    },
    {
      "x": -33,
      "y": 0,
      "z": 18,
      "name": "Rock_Sandstone_Cobble"
    },
    {
      "x": -33,
      "y": 1,
      "z": 18,
      "name": "Rock_Sandstone_Cobble"
    },
    {
      "x": -33,
      "y": 2,
      "z": 18,
      "name": "Rock_Sandstone_Cobble"
    },
    {
      "x": -33,
      "y": 3,
      "z": 18,
      "name": "Soil_Dirt_Dry"
    },
    {
      "x": -33,
      "y": 0,
      "z": 19,
      "name": "Rock_Sandstone_Cobble"
    },
    {
      "x": -33,
      "y": 1,
      "z": 19,
      "name": "Rock_Sandstone_Cobble"
    },
    {
      "x": -33,
      "y": 2,
      "z": 19,
      "name": "Rock_Sandstone_Cobble"
    },
    {
      "x": -32,
      "y": 0,
      "z": -26,
      "name": "Rock_Sandstone_Cobble"
    },
    {
      "x": -32,
      "y": 1,
      "z": -26,
      "name": "Rock_Sandstone_Cobble"
    },
    {
      "x": -32,
      "y": 2,
      "z": -26,
      "name": "Rock_Sandstone_Cobble"
    },
    {
      "x": -32,
      "y": 0,
      "z": -25,
      "name": "Rock_Sandstone_Cobble"
    },
    {
      "x": -32,
      "y": 1,
      "z": -25,
      "name": "Rock_Sandstone_Cobble"
    },
    {
      "x": -32,
      "y": 2,
      "z": -25,
      "name": "Rock_Sandstone_Cobble"
    },
    {
      "x": -32,
      "y": 3,
      "z": -25,
      "name": "Soil_Gravel_Sand"
    },
    {
      "x": -32,
      "y": 1,
      "z": -24,
      "name": "Rock_Sandstone_Cobble"
    },
    {
      "x": -32,
      "y": 2,
      "z": -24,
      "name": "Rock_Sandstone_Cobble"
    },
    {
      "x": -32,
      "y": 3,
      "z": -24,
      "name": "Soil_Dirt_Dry"
    },
    {
      "x": -32,
      "y": 1,
      "z": -23,
      "name": "Rock_Sandstone_Cobble"
    },
    {
      "x": -32,
      "y": 2,
      "z": -23,
      "name": "Rock_Sandstone_Cobble"
    },
    {
      "x": -32,
      "y": 3,
      "z": -23,
      "name": "Soil_Dirt_Dry"
    },
    {
      "x": -32,
      "y": 2,
      "z": -22,
      "name": "Rock_Sandstone_Cobble"
    },
    {
      "x": -32,
      "y": 3,
      "z": -22,
      "name": "Soil_Dirt_Dry"
    },
    {
      "x": -32,
      "y": 4,
      "z": -22,
      "name": "Soil_Dirt_Dry"
    },
    {
      "x": -32,
      "y": 2,
      "z": -21,
      "name": "Rock_Sandstone_Cobble"
    },
    {
      "x": -32,
      "y": 3,
      "z": -21,
      "name": "Soil_Dirt_Dry"
    },
    {
      "x": -32,
      "y": 4,
      "z": -21,
      "name": "Soil_Pathway"
    },
    {
      "x": -32,
      "y": 2,
      "z": -20,
      "name": "Rock_Sandstone_Cobble"
    },
    {
      "x": -32,
      "y": 3,
      "z": -20,
      "name": "Soil_Dirt_Dry"
    },
    {
      "x": -32,
      "y": 4,
      "z": -20,
      "name": "Soil_Dirt_Dry"
    },
    {
      "x": -32,
      "y": 5,
      "z": -20,
      "name": "Soil_Dirt_Dry"
    },
    {
      "x": -32,
      "y": 2,
      "z": -19,
      "name": "Rock_Sandstone_Cobble"
    },
    {
      "x": -32,
      "y": 3,
      "z": -19,
      "name": "Soil_Dirt_Dry"
    },
    {
      "x": -32,
      "y": 4,
      "z": -19,
      "name": "Soil_Dirt_Dry"
    },
    {
      "x": -32,
      "y": 5,
      "z": -19,
      "name": "Soil_Mud_Dry"
    },
    {
      "x": -32,
      "y": 2,
      "z": -18,
      "name": "Rock_Sandstone_Cobble"
    },
    {
      "x": -32,
      "y": 3,
      "z": -18,
      "name": "Soil_Gravel_Sand"
    },
    {
      "x": -32,
      "y": 4,
      "z": -18,
      "name": "Soil_Dirt_Dry"
    },
    {
      "x": -32,
      "y": 5,
      "z": -18,
      "name": "Soil_Pathway"
    },
    {
      "x": -32,
      "y": 2,
      "z": -17,
      "name": "Rock_Sandstone_Cobble"
    },
    {
      "x": -32,
      "y": 3,
      "z": -17,
      "name": "Soil_Dirt_Dry"
    },
    {
      "x": -32,
      "y": 4,
      "z": -17,
      "name": "Soil_Dirt_Dry"
    },
    {
      "x": -32,
      "y": 5,
      "z": -17,
      "name": "Soil_Dirt_Dry"
    },
    {
      "x": -32,
      "y": 6,
      "z": -17,
      "name": "Soil_Dirt_Dry"
    },
    {
      "x": -32,
      "y": 2,
      "z": -16,
      "name": "Rock_Sandstone_Cobble"
    },
    {
      "x": -32,
      "y": 3,
      "z": -16,
      "name": "Soil_Dirt_Dry"
    },
    {
      "x": -32,
      "y": 4,
      "z": -16,
      "name": "Soil_Dirt_Dry"
    },
    {
      "x": -32,
      "y": 5,
      "z": -16,
      "name": "Soil_Dirt_Dry"
    },
    {
      "x": -32,
      "y": 6,
      "z": -16,
      "name": "Soil_Dirt_Dry"
    },
    {
      "x": -32,
      "y": 3,
      "z": -15,
      "name": "Soil_Dirt_Dry"
    },
    {
      "x": -32,
      "y": 4,
      "z": -15,
      "name": "Soil_Dirt_Dry"
    },
    {
      "x": -32,
      "y": 6,
      "z": -15,
      "name": "Soil_Dirt_Dry"
    },
    {
      "x": -32,
      "y": 12,
      "z": -15,
      "name": "Cloth_Roof_Leather",
      "rotation": 2
    },
    {
      "x": -32,
      "y": 3,
      "z": -14,
      "name": "Soil_Dirt_Dry"
    },
    {
      "x": -32,
      "y": 4,
      "z": -14,
      "name": "Soil_Dirt_Dry"
    },
    {
      "x": -32,
      "y": 5,
      "z": -14,
      "name": "Soil_Dirt_Dry"
    },
    {
      "x": -32,
      "y": 6,
      "z": -14,
      "name": "Soil_Dirt_Dry"
    },
    {
      "x": -32,
      "y": 7,
      "z": -14,
      "name": "Wood_Gumboab_Trunk",
      "rotation": 3
    },
    {
      "x": -32,
      "y": 8,
      "z": -14,
      "name": "Wood_Gumboab_Trunk",
      "rotation": 3
    },
    {
      "x": -32,
      "y": 9,
      "z": -14,
      "name": "Wood_Gumboab_Trunk",
      "rotation": 3
    },
    {
      "x": -32,
      "y": 10,
      "z": -14,
      "name": "Wood_Gumboab_Trunk",
      "rotation": 3
    },
    {
      "x": -32,
      "y": 11,
      "z": -14,
      "name": "Wood_Gumboab_Trunk",
      "rotation": 3
    },
    {
      "x": -32,
      "y": 12,
      "z": -14,
      "name": "Wood_Gumboab_Trunk",
      "rotation": 7
    },
    {
      "x": -32,
      "y": 13,
      "z": -14,
      "name": "Wood_Gumboab_Trunk",
      "rotation": 3
    },
    {
      "x": -32,
      "y": 14,
      "z": -14,
      "name": "Wood_Gumboab_Branch_Long",
      "rotation": 3
    },
    {
      "x": -32,
      "y": 15,
      "z": -14,
      "name": "Survival_Trap_Spike_Wood_Large",
      "rotation": 3
    },
    {
      "x": -32,
      "y": 2,
      "z": -13,
      "name": "Rock_Sandstone_Cobble"
    },
    {
      "x": -32,
      "y": 3,
      "z": -13,
      "name": "Soil_Pathway"
    },
    {
      "x": -32,
      "y": 4,
      "z": -13,
      "name": "Soil_Dirt_Dry"
    },
    {
      "x": -32,
      "y": 5,
      "z": -13,
      "name": "Soil_Dirt_Dry"
    },
    {
      "x": -32,
      "y": 6,
      "z": -13,
      "name": "Soil_Dirt_Dry"
    },
    {
      "x": -32,
      "y": 12,
      "z": -13,
      "name": "Wood_Gumboab_Trunk",
      "rotation": 4
    },
    {
      "x": -32,
      "y": 13,
      "z": -13,
      "name": "Cloth_Roof_Leather",
      "rotation": 3
    },
    {
      "x": -32,
      "y": 2,
      "z": -12,
      "name": "Rock_Sandstone_Cobble"
    },
    {
      "x": -32,
      "y": 3,
      "z": -12,
      "name": "Soil_Dirt_Dry"
    },
    {
      "x": -32,
      "y": 4,
      "z": -12,
      "name": "Soil_Dirt_Dry"
    },
    {
      "x": -32,
      "y": 5,
      "z": -12,
      "name": "Soil_Gravel_Sand"
    },
    {
      "x": -32,
      "y": 6,
      "z": -12,
      "name": "Soil_Pathway"
    },
    {
      "x": -32,
      "y": 12,
      "z": -12,
      "name": "Wood_Gumboab_Trunk",
      "rotation": 4
    },
    {
      "x": -32,
      "y": 13,
      "z": -12,
      "name": "Cloth_Roof_Leather",
      "rotation": 3
    },
    {
      "x": -32,
      "y": 1,
      "z": -11,
      "name": "Rock_Sandstone_Cobble"
    },
    {
      "x": -32,
      "y": 2,
      "z": -11,
      "name": "Rock_Sandstone_Cobble"
    },
    {
      "x": -32,
      "y": 4,
      "z": -11,
      "name": "Soil_Pathway"
    },
    {
      "x": -32,
      "y": 5,
      "z": -11,
      "name": "Soil_Pathway"
    },
    {
      "x": -32,
      "y": 6,
      "z": -11,
      "name": "Soil_Pathway"
    },
    {
      "x": -32,
      "y": 12,
      "z": -11,
      "name": "Wood_Gumboab_Trunk",
      "rotation": 4
    },
    {
      "x": -32,
      "y": 13,
      "z": -11,
      "name": "Cloth_Roof_Leather",
      "rotation": 3
    },
    {
      "x": -32,
      "y": 1,
      "z": -10,
      "name": "Rock_Sandstone_Cobble"
    },
    {
      "x": -32,
      "y": 2,
      "z": -10,
      "name": "Rock_Sandstone_Cobble"
    },
    {
      "x": -32,
      "y": 4,
      "z": -10,
      "name": "Soil_Pathway"
    },
    {
      "x": -32,
      "y": 5,
      "z": -10,
      "name": "Soil_Pathway"
    },
    {
      "x": -32,
      "y": 6,
      "z": -10,
      "name": "Soil_Pathway"
    },
    {
      "x": -32,
      "y": 12,
      "z": -10,
      "name": "Wood_Gumboab_Trunk",
      "rotation": 4
    },
    {
      "x": -32,
      "y": 13,
      "z": -10,
      "name": "Cloth_Roof_Leather",
      "rotation": 3
    },
    {
      "x": -32,
      "y": 4,
      "z": -9,
      "name": "Soil_Dirt_Dry"
    },
    {
      "x": -32,
      "y": 5,
      "z": -9,
      "name": "Soil_Pathway"
    },
    {
      "x": -32,
      "y": 6,
      "z": -9,
      "name": "Soil_Pathway"
    },
    {
      "x": -32,
      "y": 12,
      "z": -9,
      "name": "Wood_Gumboab_Trunk",
      "rotation": 4
    },
    {
      "x": -32,
      "y": 13,
      "z": -9,
      "name": "Cloth_Roof_Leather",
      "rotation": 3
    },
    {
      "x": -32,
      "y": 4,
      "z": -8,
      "name": "Soil_Dirt_Dry"
    },
    {
      "x": -32,
      "y": 5,
      "z": -8,
      "name": "Soil_Dirt_Dry"
    },
    {
      "x": -32,
      "y": 12,
      "z": -8,
      "name": "Wood_Gumboab_Trunk",
      "rotation": 4
    },
    {
      "x": -32,
      "y": 13,
      "z": -8,
      "name": "Cloth_Roof_Leather",
      "rotation": 3
    },
    {
      "x": -32,
      "y": 4,
      "z": -7,
      "name": "Soil_Dirt_Dry"
    },
    {
      "x": -32,
      "y": 5,
      "z": -7,
      "name": "Soil_Dirt_Dry"
    },
    {
      "x": -32,
      "y": 12,
      "z": -7,
      "name": "Wood_Gumboab_Trunk",
      "rotation": 4
    },
    {
      "x": -32,
      "y": 13,
      "z": -7,
      "name": "Cloth_Roof_Leather",
      "rotation": 3
    },
    {
      "x": -32,
      "y": 3,
      "z": -6,
      "name": "Soil_Dirt_Dry"
    },
    {
      "x": -32,
      "y": 4,
      "z": -6,
      "name": "Soil_Dirt_Dry"
    },
    {
      "x": -32,
      "y": 5,
      "z": -6,
      "name": "Soil_Dirt_Dry"
    },
    {
      "x": -32,
      "y": 6,
      "z": -6,
      "name": "Wood_Gumboab_Trunk",
      "support": 15
    },
    {
      "x": -32,
      "y": 7,
      "z": -6,
      "name": "Wood_Gumboab_Trunk",
      "rotation": 3
    },
    {
      "x": -32,
      "y": 8,
      "z": -6,
      "name": "Wood_Gumboab_Trunk",
      "rotation": 3
    },
    {
      "x": -32,
      "y": 9,
      "z": -6,
      "name": "Wood_Gumboab_Trunk",
      "rotation": 3
    },
    {
      "x": -32,
      "y": 10,
      "z": -6,
      "name": "Wood_Gumboab_Trunk",
      "rotation": 3
    },
    {
      "x": -32,
      "y": 11,
      "z": -6,
      "name": "Wood_Gumboab_Trunk",
      "rotation": 3
    },
    {
      "x": -32,
      "y": 12,
      "z": -6,
      "name": "Wood_Gumboab_Trunk",
      "rotation": 7
    },
    {
      "x": -32,
      "y": 13,
      "z": -6,
      "name": "Wood_Gumboab_Trunk",
      "rotation": 3
    },
    {
      "x": -32,
      "y": 14,
      "z": -6,
      "name": "Wood_Gumboab_Branch_Long",
      "rotation": 3
    },
    {
      "x": -32,
      "y": 15,
      "z": -6,
      "name": "Survival_Trap_Spike_Wood_Large",
      "rotation": 3
    },
    {
      "x": -32,
      "y": 3,
      "z": -5,
      "name": "Soil_Pathway"
    },
    {
      "x": -32,
      "y": 4,
      "z": -5,
      "name": "Soil_Pathway"
    },
    {
      "x": -32,
      "y": 5,
      "z": -5,
      "name": "Soil_Dirt_Dry"
    },
    {
      "x": -32,
      "y": 12,
      "z": -5,
      "name": "Cloth_Roof_Leather"
    },
    {
      "x": -32,
      "y": 3,
      "z": -4,
      "name": "Soil_Dirt_Dry"
    },
    {
      "x": -32,
      "y": 4,
      "z": -4,
      "name": "Soil_Pathway"
    },
    {
      "x": -32,
      "y": 5,
      "z": -4,
      "name": "Soil_Dirt_Dry"
    },
    {
      "x": -32,
      "y": 3,
      "z": -3,
      "name": "Soil_Dirt_Dry"
    },
    {
      "x": -32,
      "y": 4,
      "z": -3,
      "name": "Soil_Pathway"
    },
    {
      "x": -32,
      "y": 4,
      "z": -2,
      "name": "Soil_Pathway"
    },
    {
      "x": -32,
      "y": 5,
      "z": -2,
      "name": "Soil_Dirt_Dry"
    },
    {
      "x": -32,
      "y": 4,
      "z": -1,
      "name": "Soil_Pathway"
    },
    {
      "x": -32,
      "y": 5,
      "z": -1,
      "name": "Soil_Dirt_Dry"
    },
    {
      "x": -32,
      "y": 4,
      "z": 0,
      "name": "Soil_Pathway"
    },
    {
      "x": -32,
      "y": 5,
      "z": 0,
      "name": "Soil_Dirt_Dry"
    },
    {
      "x": -32,
      "y": 4,
      "z": 1,
      "name": "Soil_Pathway"
    },
    {
      "x": -32,
      "y": 5,
      "z": 1,
      "name": "Soil_Dirt_Dry"
    },
    {
      "x": -32,
      "y": 4,
      "z": 2,
      "name": "Soil_Pathway"
    },
    {
      "x": -32,
      "y": 5,
      "z": 2,
      "name": "Soil_Dirt_Dry"
    },
    {
      "x": -32,
      "y": 4,
      "z": 3,
      "name": "Soil_Pathway"
    },
    {
      "x": -32,
      "y": 5,
      "z": 3,
      "name": "Soil_Dirt_Dry"
    },
    {
      "x": -32,
      "y": 3,
      "z": 4,
      "name": "Soil_Dirt_Dry"
    },
    {
      "x": -32,
      "y": 4,
      "z": 4,
      "name": "Soil_Pathway"
    },
    {
      "x": -32,
      "y": 5,
      "z": 4,
      "name": "Soil_Dirt_Dry"
    },
    {
      "x": -32,
      "y": 3,
      "z": 5,
      "name": "Soil_Dirt_Dry"
    },
    {
      "x": -32,
      "y": 4,
      "z": 5,
      "name": "Soil_Pathway"
    },
    {
      "x": -32,
      "y": 3,
      "z": 6,
      "name": "Soil_Dirt_Dry"
    },
    {
      "x": -32,
      "y": 4,
      "z": 6,
      "name": "Soil_Pathway"
    },
    {
      "x": -32,
      "y": 3,
      "z": 7,
      "name": "Soil_Dirt_Dry"
    },
    {
      "x": -32,
      "y": 4,
      "z": 7,
      "name": "Soil_Pathway"
    },
    {
      "x": -32,
      "y": 3,
      "z": 8,
      "name": "Soil_Dirt_Dry"
    },
    {
      "x": -32,
      "y": 4,
      "z": 8,
      "name": "Soil_Pathway"
    },
    {
      "x": -32,
      "y": 5,
      "z": 8,
      "name": "Soil_Pathway"
    },
    {
      "x": -32,
      "y": 4,
      "z": 9,
      "name": "Soil_Pathway"
    },
    {
      "x": -32,
      "y": 5,
      "z": 9,
      "name": "Soil_Pathway"
    },
    {
      "x": -32,
      "y": 4,
      "z": 10,
      "name": "Soil_Pathway"
    },
    {
      "x": -32,
      "y": 5,
      "z": 10,
      "name": "Soil_Pathway"
    },
    {
      "x": -32,
      "y": 4,
      "z": 11,
      "name": "Soil_Pathway"
    },
    {
      "x": -32,
      "y": 5,
      "z": 11,
      "name": "Soil_Pathway"
    },
    {
      "x": -32,
      "y": 4,
      "z": 12,
      "name": "Soil_Pathway"
    },
    {
      "x": -32,
      "y": 5,
      "z": 12,
      "name": "Soil_Pathway"
    },
    {
      "x": -32,
      "y": 0,
      "z": 13,
      "name": "Rock_Sandstone_Cobble"
    },
    {
      "x": -32,
      "y": 1,
      "z": 13,
      "name": "Rock_Sandstone_Cobble"
    },
    {
      "x": -32,
      "y": 2,
      "z": 13,
      "name": "Rock_Sandstone_Cobble"
    },
    {
      "x": -32,
      "y": 4,
      "z": 13,
      "name": "Soil_Pathway"
    },
    {
      "x": -32,
      "y": 5,
      "z": 13,
      "name": "Soil_Pathway"
    },
    {
      "x": -32,
      "y": 0,
      "z": 14,
      "name": "Rock_Sandstone_Cobble"
    },
    {
      "x": -32,
      "y": 1,
      "z": 14,
      "name": "Rock_Sandstone_Cobble"
    },
    {
      "x": -32,
      "y": 2,
      "z": 14,
      "name": "Rock_Sandstone_Cobble"
    },
    {
      "x": -32,
      "y": 3,
      "z": 14,
      "name": "Soil_Pathway"
    },
    {
      "x": -32,
      "y": 4,
      "z": 14,
      "name": "Soil_Pathway"
    },
    {
      "x": -32,
      "y": 5,
      "z": 14,
      "name": "Soil_Dirt_Dry"
    },
    {
      "x": -32,
      "y": 0,
      "z": 15,
      "name": "Rock_Sandstone_Cobble"
    },
    {
      "x": -32,
      "y": 1,
      "z": 15,
      "name": "Rock_Sandstone_Cobble"
    },
    {
      "x": -32,
      "y": 2,
      "z": 15,
      "name": "Rock_Sandstone_Cobble"
    },
    {
      "x": -32,
      "y": 3,
      "z": 15,
      "name": "Soil_Pathway"
    },
    {
      "x": -32,
      "y": 4,
      "z": 15,
      "name": "Soil_Pathway"
    },
    {
      "x": -32,
      "y": 0,
      "z": 16,
      "name": "Rock_Sandstone_Cobble"
    },
    {
      "x": -32,
      "y": 1,
      "z": 16,
      "name": "Rock_Sandstone_Cobble"
    },
    {
      "x": -32,
      "y": 2,
      "z": 16,
      "name": "Rock_Sandstone_Cobble"
    },
    {
      "x": -32,
      "y": 3,
      "z": 16,
      "name": "Soil_Pathway"
    },
    {
      "x": -32,
      "y": 4,
      "z": 16,
      "name": "Soil_Pathway"
    },
    {
      "x": -32,
      "y": 0,
      "z": 17,
      "name": "Rock_Sandstone_Cobble"
    },
    {
      "x": -32,
      "y": 1,
      "z": 17,
      "name": "Rock_Sandstone_Cobble"
    },
    {
      "x": -32,
      "y": 2,
      "z": 17,
      "name": "Rock_Sandstone_Cobble"
    },
    {
      "x": -32,
      "y": 3,
      "z": 17,
      "name": "Soil_Pathway"
    },
    {
      "x": -32,
      "y": 4,
      "z": 17,
      "name": "Soil_Pathway"
    },
    {
      "x": -32,
      "y": 0,
      "z": 18,
      "name": "Rock_Sandstone_Cobble"
    },
    {
      "x": -32,
      "y": 1,
      "z": 18,
      "name": "Rock_Sandstone_Cobble"
    },
    {
      "x": -32,
      "y": 2,
      "z": 18,
      "name": "Rock_Sandstone_Cobble"
    },
    {
      "x": -32,
      "y": 3,
      "z": 18,
      "name": "Soil_Pathway"
    },
    {
      "x": -32,
      "y": 0,
      "z": 19,
      "name": "Rock_Sandstone_Cobble"
    },
    {
      "x": -32,
      "y": 1,
      "z": 19,
      "name": "Rock_Sandstone_Cobble"
    },
    {
      "x": -32,
      "y": 2,
      "z": 19,
      "name": "Rock_Sandstone_Cobble"
    },
    {
      "x": -32,
      "y": 3,
      "z": 19,
      "name": "Soil_Dirt_Dry"
    },
    {
      "x": -32,
      "y": 0,
      "z": 20,
      "name": "Rock_Sandstone_Cobble"
    },
    {
      "x": -32,
      "y": 1,
      "z": 20,
      "name": "Rock_Sandstone_Cobble"
    },
    {
      "x": -32,
      "y": 2,
      "z": 20,
      "name": "Soil_Dirt_Dry"
    },
    {
      "x": -32,
      "y": 3,
      "z": 20,
      "name": "Soil_Dirt_Dry"
    },
    {
      "x": -32,
      "y": 0,
      "z": 21,
      "name": "Rock_Sandstone_Cobble"
    },
    {
      "x": -32,
      "y": 1,
      "z": 21,
      "name": "Rock_Sandstone_Cobble"
    },
    {
      "x": -32,
      "y": 2,
      "z": 21,
      "name": "Soil_Dirt_Dry"
    },
    {
      "x": -31,
      "y": 0,
      "z": -27,
      "name": "Rock_Sandstone_Cobble"
    },
    {
      "x": -31,
      "y": 1,
      "z": -27,
      "name": "Rock_Sandstone_Cobble"
    },
    {
      "x": -31,
      "y": 2,
      "z": -27,
      "name": "Rock_Sandstone_Cobble"
    },
    {
      "x": -31,
      "y": 3,
      "z": -27,
      "name": "Soil_Dirt_Dry"
    },
    {
      "x": -31,
      "y": 0,
      "z": -26,
      "name": "Rock_Sandstone_Cobble"
    },
    {
      "x": -31,
      "y": 1,
      "z": -26,
      "name": "Rock_Sandstone_Cobble"
    },
    {
      "x": -31,
      "y": 2,
      "z": -26,
      "name": "Rock_Sandstone_Cobble"
    },
    {
      "x": -31,
      "y": 3,
      "z": -26,
      "name": "Soil_Dirt_Dry"
    },
    {
      "x": -31,
      "y": 2,
      "z": -25,
      "name": "Rock_Sandstone_Cobble"
    },
    {
      "x": -31,
      "y": 3,
      "z": -25,
      "name": "Soil_Dirt_Dry"
    },
    {
      "x": -31,
      "y": 4,
      "z": -25,
      "name": "Soil_Dirt_Dry"
    },
    {
      "x": -31,
      "y": 1,
      "z": -24,
      "name": "Rock_Sandstone_Cobble"
    },
    {
      "x": -31,
      "y": 2,
      "z": -24,
      "name": "Rock_Sandstone_Cobble"
    },
    {
      "x": -31,
      "y": 3,
      "z": -24,
      "name": "Soil_Pathway"
    },
    {
      "x": -31,
      "y": 4,
      "z": -24,
      "name": "Soil_Pathway"
    },
    {
      "x": -31,
      "y": 1,
      "z": -23,
      "name": "Rock_Sandstone_Cobble"
    },
    {
      "x": -31,
      "y": 2,
      "z": -23,
      "name": "Rock_Sandstone_Cobble"
    },
    {
      "x": -31,
      "y": 3,
      "z": -23,
      "name": "Soil_Dirt_Dry"
    },
    {
      "x": -31,
      "y": 4,
      "z": -23,
      "name": "Soil_Dirt_Dry"
    },
    {
      "x": -31,
      "y": 2,
      "z": -22,
      "name": "Rock_Sandstone_Cobble"
    },
    {
      "x": -31,
      "y": 3,
      "z": -22,
      "name": "Soil_Dirt_Dry"
    },
    {
      "x": -31,
      "y": 4,
      "z": -22,
      "name": "Soil_Dirt_Dry"
    },
    {
      "x": -31,
      "y": 2,
      "z": -21,
      "name": "Rock_Sandstone_Cobble"
    },
    {
      "x": -31,
      "y": 3,
      "z": -21,
      "name": "Soil_Dirt_Dry"
    },
    {
      "x": -31,
      "y": 4,
      "z": -21,
      "name": "Soil_Dirt_Dry"
    },
    {
      "x": -31,
      "y": 5,
      "z": -21,
      "name": "Soil_Dirt_Dry"
    },
    {
      "x": -31,
      "y": 3,
      "z": -20,
      "name": "Soil_Dirt_Dry"
    },
    {
      "x": -31,
      "y": 4,
      "z": -20,
      "name": "Soil_Dirt_Dry"
    },
    {
      "x": -31,
      "y": 5,
      "z": -20,
      "name": "Soil_Dirt_Dry"
    },
    {
      "x": -31,
      "y": 2,
      "z": -19,
      "name": "Rock_Sandstone_Cobble"
    },
    {
      "x": -31,
      "y": 3,
      "z": -19,
      "name": "Soil_Dirt_Dry"
    },
    {
      "x": -31,
      "y": 4,
      "z": -19,
      "name": "Soil_Dirt_Dry"
    },
    {
      "x": -31,
      "y": 5,
      "z": -19,
      "name": "Soil_Dirt_Dry"
    },
    {
      "x": -31,
      "y": 6,
      "z": -19,
      "name": "Soil_Dirt_Dry"
    },
    {
      "x": -31,
      "y": 2,
      "z": -18,
      "name": "Rock_Sandstone_Cobble"
    },
    {
      "x": -31,
      "y": 3,
      "z": -18,
      "name": "Soil_Dirt_Dry"
    },
    {
      "x": -31,
      "y": 4,
      "z": -18,
      "name": "Soil_Dirt_Dry"
    },
    {
      "x": -31,
      "y": 5,
      "z": -18,
      "name": "Soil_Dirt_Dry"
    },
    {
      "x": -31,
      "y": 6,
      "z": -18,
      "name": "Soil_Dirt_Dry"
    },
    {
      "x": -31,
      "y": 2,
      "z": -17,
      "name": "Rock_Sandstone_Cobble"
    },
    {
      "x": -31,
      "y": 3,
      "z": -17,
      "name": "Soil_Dirt_Dry"
    },
    {
      "x": -31,
      "y": 4,
      "z": -17,
      "name": "Soil_Dirt_Dry"
    },
    {
      "x": -31,
      "y": 5,
      "z": -17,
      "name": "Soil_Dirt_Dry"
    },
    {
      "x": -31,
      "y": 6,
      "z": -17,
      "name": "Soil_Dirt_Dry"
    },
    {
      "x": -31,
      "y": 2,
      "z": -16,
      "name": "Rock_Sandstone_Cobble"
    },
    {
      "x": -31,
      "y": 3,
      "z": -16,
      "name": "Soil_Dirt_Dry"
    },
    {
      "x": -31,
      "y": 4,
      "z": -16,
      "name": "Soil_Dirt_Dry"
    },
    {
      "x": -31,
      "y": 5,
      "z": -16,
      "name": "Soil_Dirt_Dry"
    },
    {
      "x": -31,
      "y": 6,
      "z": -16,
      "name": "Soil_Dirt_Dry"
    },
    {
      "x": -31,
      "y": 3,
      "z": -15,
      "name": "Soil_Dirt_Dry"
    },
    {
      "x": -31,
      "y": 4,
      "z": -15,
      "name": "Soil_Dirt_Dry"
    },
    {
      "x": -31,
      "y": 5,
      "z": -15,
      "name": "Plant_Grass_Arid_Short"
    },
    {
      "x": -31,
      "y": 6,
      "z": -15,
      "name": "Soil_Dirt_Dry"
    },
    {
      "x": -31,
      "y": 12,
      "z": -15,
      "name": "Cloth_Roof_Leather",
      "rotation": 2
    },
    {
      "x": -31,
      "y": 3,
      "z": -14,
      "name": "Soil_Dirt_Dry"
    },
    {
      "x": -31,
      "y": 4,
      "z": -14,
      "name": "Soil_Dirt_Dry"
    },
    {
      "x": -31,
      "y": 5,
      "z": -14,
      "name": "Soil_Dirt_Dry"
    },
    {
      "x": -31,
      "y": 6,
      "z": -14,
      "name": "Soil_Dirt_Dry"
    },
    {
      "x": -31,
      "y": 12,
      "z": -14,
      "name": "Wood_Gumboab_Trunk",
      "rotation": 7
    },
    {
      "x": -31,
      "y": 13,
      "z": -14,
      "name": "Cloth_Roof_Leather",
      "support": 15,
      "rotation": 2
    },
    {
      "x": -31,
      "y": 2,
      "z": -13,
      "name": "Rock_Sandstone_Cobble"
    },
    {
      "x": -31,
      "y": 3,
      "z": -13,
      "name": "Soil_Dirt_Dry"
    },
    {
      "x": -31,
      "y": 4,
      "z": -13,
      "name": "Soil_Dirt_Dry"
    },
    {
      "x": -31,
      "y": 5,
      "z": -13,
      "name": "Soil_Dirt_Dry"
    },
    {
      "x": -31,
      "y": 6,
      "z": -13,
      "name": "Soil_Dirt_Dry"
    },
    {
      "x": -31,
      "y": 14,
      "z": -13,
      "name": "Cloth_Roof_Leather_Flat",
      "rotation": 3
    },
    {
      "x": -31,
      "y": 2,
      "z": -12,
      "name": "Rock_Sandstone_Cobble"
    },
    {
      "x": -31,
      "y": 3,
      "z": -12,
      "name": "Soil_Pathway"
    },
    {
      "x": -31,
      "y": 4,
      "z": -12,
      "name": "Soil_Dirt_Dry"
    },
    {
      "x": -31,
      "y": 5,
      "z": -12,
      "name": "Soil_Pathway"
    },
    {
      "x": -31,
      "y": 6,
      "z": -12,
      "name": "Soil_Pathway"
    },
    {
      "x": -31,
      "y": 14,
      "z": -12,
      "name": "Cloth_Roof_Leather_Flat",
      "rotation": 3
    },
    {
      "x": -31,
      "y": 1,
      "z": -11,
      "name": "Rock_Sandstone_Cobble"
    },
    {
      "x": -31,
      "y": 2,
      "z": -11,
      "name": "Rock_Sandstone_Cobble"
    },
    {
      "x": -31,
      "y": 3,
      "z": -11,
      "name": "Soil_Dirt_Dry"
    },
    {
      "x": -31,
      "y": 4,
      "z": -11,
      "name": "Soil_Pathway"
    },
    {
      "x": -31,
      "y": 5,
      "z": -11,
      "name": "Soil_Pathway"
    },
    {
      "x": -31,
      "y": 6,
      "z": -11,
      "name": "Soil_Pathway"
    },
    {
      "x": -31,
      "y": 14,
      "z": -11,
      "name": "Cloth_Roof_Leather_Flat",
      "rotation": 3
    },
    {
      "x": -31,
      "y": 1,
      "z": -10,
      "name": "Rock_Sandstone_Cobble"
    },
    {
      "x": -31,
      "y": 2,
      "z": -10,
      "name": "Rock_Sandstone_Cobble"
    },
    {
      "x": -31,
      "y": 4,
      "z": -10,
      "name": "Soil_Pathway"
    },
    {
      "x": -31,
      "y": 5,
      "z": -10,
      "name": "Soil_Pathway"
    },
    {
      "x": -31,
      "y": 6,
      "z": -10,
      "name": "Soil_Pathway"
    },
    {
      "x": -31,
      "y": 12,
      "z": -10,
      "name": "Wood_Gumboab_Trunk",
      "rotation": 7
    },
    {
      "x": -31,
      "y": 13,
      "z": -10,
      "name": "Wood_Gumboab_Trunk",
      "rotation": 7
    },
    {
      "x": -31,
      "y": 14,
      "z": -10,
      "name": "Cloth_Roof_Leather_Flat",
      "rotation": 3
    },
    {
      "x": -31,
      "y": 4,
      "z": -9,
      "name": "Soil_Pathway"
    },
    {
      "x": -31,
      "y": 5,
      "z": -9,
      "name": "Soil_Pathway"
    },
    {
      "x": -31,
      "y": 6,
      "z": -9,
      "name": "Soil_Pathway"
    },
    {
      "x": -31,
      "y": 14,
      "z": -9,
      "name": "Cloth_Roof_Leather_Flat",
      "rotation": 3
    },
    {
      "x": -31,
      "y": 4,
      "z": -8,
      "name": "Soil_Pathway"
    },
    {
      "x": -31,
      "y": 5,
      "z": -8,
      "name": "Soil_Pathway"
    },
    {
      "x": -31,
      "y": 6,
      "z": -8,
      "name": "Soil_Pathway"
    },
    {
      "x": -31,
      "y": 14,
      "z": -8,
      "name": "Cloth_Roof_Leather_Flat",
      "rotation": 3
    },
    {
      "x": -31,
      "y": 4,
      "z": -7,
      "name": "Soil_Gravel_Sand"
    },
    {
      "x": -31,
      "y": 5,
      "z": -7,
      "name": "Soil_Dirt_Dry"
    },
    {
      "x": -31,
      "y": 6,
      "z": -7,
      "name": "Soil_Dirt_Dry"
    },
    {
      "x": -31,
      "y": 14,
      "z": -7,
      "name": "Cloth_Roof_Leather_Flat",
      "rotation": 3
    },
    {
      "x": -31,
      "y": 3,
      "z": -6,
      "name": "Soil_Dirt_Dry"
    },
    {
      "x": -31,
      "y": 4,
      "z": -6,
      "name": "Soil_Dirt_Dry"
    },
    {
      "x": -31,
      "y": 5,
      "z": -6,
      "name": "Soil_Dirt_Dry"
    },
    {
      "x": -31,
      "y": 12,
      "z": -6,
      "name": "Wood_Gumboab_Trunk",
      "rotation": 7
    },
    {
      "x": -31,
      "y": 13,
      "z": -6,
      "name": "Cloth_Roof_Leather"
    },
    {
      "x": -31,
      "y": 3,
      "z": -5,
      "name": "Soil_Dirt_Dry"
    },
    {
      "x": -31,
      "y": 4,
      "z": -5,
      "name": "Soil_Dirt_Dry"
    },
    {
      "x": -31,
      "y": 5,
      "z": -5,
      "name": "Soil_Dirt_Dry"
    },
    {
      "x": -31,
      "y": 12,
      "z": -5,
      "name": "Cloth_Roof_Leather"
    },
    {
      "x": -31,
      "y": 3,
      "z": -4,
      "name": "Soil_Dirt_Dry"
    },
    {
      "x": -31,
      "y": 4,
      "z": -4,
      "name": "Soil_Pathway"
    },
    {
      "x": -31,
      "y": 5,
      "z": -4,
      "name": "Soil_Dirt_Dry"
    },
    {
      "x": -31,
      "y": 3,
      "z": -3,
      "name": "Soil_Dirt_Dry"
    },
    {
      "x": -31,
      "y": 4,
      "z": -3,
      "name": "Soil_Pathway"
    },
    {
      "x": -31,
      "y": 4,
      "z": -2,
      "name": "Soil_Pathway"
    },
    {
      "x": -31,
      "y": 4,
      "z": -1,
      "name": "Soil_Pathway"
    },
    {
      "x": -31,
      "y": 5,
      "z": -1,
      "name": "Soil_Dirt_Dry"
    },
    {
      "x": -31,
      "y": 4,
      "z": 0,
      "name": "Soil_Pathway"
    },
    {
      "x": -31,
      "y": 5,
      "z": 0,
      "name": "Soil_Dirt_Dry"
    },
    {
      "x": -31,
      "y": 4,
      "z": 1,
      "name": "Soil_Pathway"
    },
    {
      "x": -31,
      "y": 5,
      "z": 1,
      "name": "Soil_Dirt_Dry"
    },
    {
