{
  "version": 8,
  "blockIdVersion": 11,
  "anchorX": 0,
  "anchorY": 0,
  "anchorZ": 0,
  "blocks": [
    {
      "x": -29,
      "y": -3,
      "z": 0,
      "name": "Soil_Dirt"
    },
    {
      "x": -29,
      "y": -2,
      "z": 0,
      "name": "Soil_Dirt"
    },
    {
      "x": -29,
      "y": -1,
      "z": 0,
      "name": "Soil_Dirt"
    },
    {
      "x": -29,
      "y": -3,
      "z": 1,
      "name": "Soil_Dirt"
    },
    {
      "x": -29,
      "y": -2,
      "z": 1,
      "name": "Soil_Dirt"
    },
    {
      "x": -29,
      "y": -1,
      "z": 1,
      "name": "Soil_Dirt"
    },
    {
      "x": -29,
      "y": 0,
      "z": 1,
      "name": "Soil_Dirt"
    },
    {
      "x": -29,
      "y": -3,
      "z": 2,
      "name": "Soil_Dirt"
    },
    {
      "x": -29,
      "y": -2,
      "z": 2,
      "name": "Soil_Dirt"
    },
    {
      "x": -29,
      "y": -1,
      "z": 2,
      "name": "Soil_Dirt"
    },
    {
      "x": -28,
      "y": -3,
      "z": -4,
      "name": "Soil_Dirt"
    },
    {
      "x": -28,
      "y": -2,
      "z": -4,
      "name": "Soil_Dirt"
    },
    {
      "x": -28,
      "y": -1,
      "z": -4,
      "name": "Soil_Dirt"
    },
    {
      "x": -28,
      "y": -3,
      "z": -3,
      "name": "Soil_Dirt"
    },
    {
      "x": -28,
      "y": -2,
      "z": -3,
      "name": "Soil_Dirt"
    },
    {
      "x": -28,
      "y": -1,
      "z": -3,
      "name": "Soil_Dirt"
    },
    {
      "x": -28,
      "y": 0,
      "z": -3,
      "name": "Soil_Dirt"
    },
    {
      "x": -28,
      "y": -3,
      "z": -2,
      "name": "Soil_Dirt"
    },
    {
      "x": -28,
      "y": -2,
      "z": -2,
      "name": "Soil_Dirt"
    },
    {
      "x": -28,
      "y": -1,
      "z": -2,
      "name": "Soil_Dirt"
    },
    {
      "x": -28,
      "y": -3,
      "z": -1,
      "name": "Soil_Dirt"
    },
    {
      "x": -28,
      "y": -2,
      "z": -1,
      "name": "Soil_Dirt"
    },
    {
      "x": -28,
      "y": -1,
      "z": -1,
      "name": "Soil_Dirt"
    },
    {
      "x": -28,
      "y": -3,
      "z": 0,
      "name": "Soil_Dirt"
    },
    {
      "x": -28,
      "y": -2,
      "z": 0,
      "name": "Soil_Dirt"
    },
    {
      "x": -28,
      "y": -1,
      "z": 0,
      "name": "Soil_Dirt"
    },
    {
      "x": -28,
      "y": 0,
      "z": 0,
      "name": "Soil_Dirt"
    },
    {
      "x": -28,
      "y": 1,
      "z": 0,
      "name": "Soil_Dirt"
    },
    {
      "x": -28,
      "y": -1,
      "z": 1,
      "name": "Soil_Dirt"
    },
    {
      "x": -28,
      "y": 0,
      "z": 1,
      "name": "Soil_Dirt"
    },
    {
      "x": -28,
      "y": 1,
      "z": 1,
      "name": "Soil_Dirt"
    },
    {
      "x": -28,
      "y": -3,
      "z": 2,
      "name": "Soil_Dirt"
    },
    {
      "x": -28,
      "y": -2,
      "z": 2,
      "name": "Soil_Dirt"
    },
    {
      "x": -28,
      "y": -1,
      "z": 2,
      "name": "Soil_Dirt"
    },
    {
      "x": -28,
      "y": 0,
      "z": 2,
      "name": "Soil_Dirt"
    },
    {
      "x": -28,
      "y": 1,
      "z": 2,
      "name": "Soil_Dirt"
    },
    {
      "x": -28,
      "y": -3,
      "z": 3,
      "name": "Soil_Dirt"
    },
    {
      "x": -28,
      "y": -2,
      "z": 3,
      "name": "Soil_Dirt"
    },
    {
      "x": -28,
      "y": -1,
      "z": 3,
      "name": "Soil_Dirt"
    },
    {
      "x": -27,
      "y": -3,
      "z": -7,
      "name": "Soil_Dirt"
    },
    {
      "x": -27,
      "y": -2,
      "z": -7,
      "name": "Soil_Dirt"
    },
    {
      "x": -27,
      "y": -1,
      "z": -7,
      "name": "Soil_Dirt"
    },
    {
      "x": -27,
      "y": -3,
      "z": -6,
      "name": "Soil_Dirt"
    },
    {
      "x": -27,
      "y": -2,
      "z": -6,
      "name": "Soil_Dirt"
    },
    {
      "x": -27,
      "y": -1,
      "z": -6,
      "name": "Soil_Dirt"
    },
    {
      "x": -27,
      "y": 0,
      "z": -6,
      "name": "Soil_Dirt"
    },
    {
      "x": -27,
      "y": -3,
      "z": -5,
      "name": "Soil_Dirt"
    },
    {
      "x": -27,
      "y": -2,
      "z": -5,
      "name": "Soil_Dirt"
    },
    {
      "x": -27,
      "y": -1,
      "z": -5,
      "name": "Soil_Dirt"
    },
    {
      "x": -27,
      "y": -3,
      "z": -4,
      "name": "Soil_Dirt"
    },
    {
      "x": -27,
      "y": -2,
      "z": -4,
      "name": "Soil_Dirt"
    },
    {
      "x": -27,
      "y": -1,
      "z": -4,
      "name": "Soil_Dirt"
    },
    {
      "x": -27,
      "y": 0,
      "z": -4,
      "name": "Soil_Dirt"
    },
    {
      "x": -27,
      "y": 1,
      "z": -4,
      "name": "Soil_Dirt"
    },
    {
      "x": -27,
      "y": -1,
      "z": -3,
      "name": "Soil_Dirt"
    },
    {
      "x": -27,
      "y": 0,
      "z": -3,
      "name": "Soil_Dirt"
    },
    {
      "x": -27,
      "y": 1,
      "z": -3,
      "name": "Soil_Dirt"
    },
    {
      "x": -27,
      "y": -3,
      "z": -2,
      "name": "Soil_Dirt"
    },
    {
      "x": -27,
      "y": -2,
      "z": -2,
      "name": "Soil_Dirt"
    },
    {
      "x": -27,
      "y": -1,
      "z": -2,
      "name": "Soil_Dirt"
    },
    {
      "x": -27,
      "y": 0,
      "z": -2,
      "name": "Soil_Dirt"
    },
    {
      "x": -27,
      "y": 1,
      "z": -2,
      "name": "Soil_Dirt"
    },
    {
      "x": -27,
      "y": -3,
      "z": -1,
      "name": "Soil_Dirt"
    },
    {
      "x": -27,
      "y": -2,
      "z": -1,
      "name": "Soil_Dirt"
    },
    {
      "x": -27,
      "y": -1,
      "z": -1,
      "name": "Soil_Dirt"
    },
    {
      "x": -27,
      "y": 0,
      "z": -1,
      "name": "Soil_Dirt"
    },
    {
      "x": -27,
      "y": 1,
      "z": -1,
      "name": "Soil_Dirt"
    },
    {
      "x": -27,
      "y": -1,
      "z": 0,
      "name": "Soil_Dirt"
    },
    {
      "x": -27,
      "y": 0,
      "z": 0,
      "name": "Soil_Dirt"
    },
    {
      "x": -27,
      "y": 1,
      "z": 0,
      "name": "Soil_Dirt"
    },
    {
      "x": -27,
      "y": 1,
      "z": 1,
      "name": "Soil_Dirt"
    },
    {
      "x": -27,
      "y": -1,
      "z": 2,
      "name": "Soil_Dirt"
    },
    {
      "x": -27,
      "y": 0,
      "z": 2,
      "name": "Soil_Dirt"
    },
    {
      "x": -27,
      "y": 1,
      "z": 2,
      "name": "Soil_Dirt"
    },
    {
      "x": -27,
      "y": -3,
      "z": 3,
      "name": "Soil_Dirt"
    },
    {
      "x": -27,
      "y": -2,
      "z": 3,
      "name": "Soil_Dirt"
    },
    {
      "x": -27,
      "y": -1,
      "z": 3,
      "name": "Soil_Dirt"
    },
    {
      "x": -27,
      "y": 0,
      "z": 3,
      "name": "Soil_Dirt"
    },
    {
      "x": -27,
      "y": -3,
      "z": 4,
      "name": "Soil_Dirt"
    },
    {
      "x": -27,
      "y": -2,
      "z": 4,
      "name": "Soil_Dirt"
    },
    {
      "x": -27,
      "y": -1,
      "z": 4,
      "name": "Soil_Dirt"
    },
    {
      "x": -27,
      "y": 0,
      "z": 4,
      "name": "Soil_Dirt"
    },
    {
      "x": -27,
      "y": -3,
      "z": 5,
      "name": "Soil_Dirt"
    },
    {
      "x": -27,
      "y": -2,
      "z": 5,
      "name": "Soil_Dirt"
    },
    {
      "x": -27,
      "y": -1,
      "z": 5,
      "name": "Soil_Dirt"
    },
    {
      "x": -26,
      "y": -3,
      "z": -11,
      "name": "Soil_Dirt"
    },
    {
      "x": -26,
      "y": -2,
      "z": -11,
      "name": "Soil_Dirt"
    },
    {
      "x": -26,
      "y": -1,
      "z": -11,
      "name": "Soil_Dirt"
    },
    {
      "x": -26,
      "y": -3,
      "z": -10,
      "name": "Soil_Dirt"
    },
    {
      "x": -26,
      "y": -2,
      "z": -10,
      "name": "Soil_Dirt"
    },
    {
      "x": -26,
      "y": -1,
      "z": -10,
      "name": "Soil_Dirt"
    },
    {
      "x": -26,
      "y": 0,
      "z": -10,
      "name": "Soil_Dirt"
    },
    {
      "x": -26,
      "y": -3,
      "z": -9,
      "name": "Soil_Dirt"
    },
    {
      "x": -26,
      "y": -2,
      "z": -9,
      "name": "Soil_Dirt"
    },
    {
      "x": -26,
      "y": -1,
      "z": -9,
      "name": "Soil_Dirt"
    },
    {
      "x": -26,
      "y": -3,
      "z": -8,
      "name": "Soil_Dirt"
    },
    {
      "x": -26,
      "y": -2,
      "z": -8,
      "name": "Soil_Dirt"
    },
    {
      "x": -26,
      "y": -1,
      "z": -8,
      "name": "Soil_Dirt"
    },
    {
      "x": -26,
      "y": -3,
      "z": -7,
      "name": "Soil_Dirt"
    },
    {
      "x": -26,
      "y": -2,
      "z": -7,
      "name": "Soil_Dirt"
    },
    {
      "x": -26,
      "y": -1,
      "z": -7,
      "name": "Soil_Dirt"
    },
    {
      "x": -26,
      "y": 0,
      "z": -7,
      "name": "Soil_Dirt"
    },
    {
      "x": -26,
      "y": 1,
      "z": -7,
      "name": "Soil_Dirt"
    },
    {
      "x": -26,
      "y": -1,
      "z": -6,
      "name": "Soil_Dirt"
    },
    {
      "x": -26,
      "y": 0,
      "z": -6,
      "name": "Soil_Dirt"
    },
    {
      "x": -26,
      "y": 1,
      "z": -6,
      "name": "Soil_Dirt"
    },
    {
      "x": -26,
      "y": -3,
      "z": -5,
      "name": "Soil_Dirt"
    },
    {
      "x": -26,
      "y": -2,
      "z": -5,
      "name": "Soil_Dirt"
    },
    {
      "x": -26,
      "y": -1,
      "z": -5,
      "name": "Soil_Dirt"
    },
    {
      "x": -26,
      "y": 0,
      "z": -5,
      "name": "Soil_Dirt"
    },
    {
      "x": -26,
      "y": 1,
      "z": -5,
      "name": "Soil_Dirt"
    },
    {
      "x": -26,
      "y": -3,
      "z": -4,
      "name": "Soil_Dirt"
    },
    {
      "x": -26,
      "y": -2,
      "z": -4,
      "name": "Soil_Dirt"
    },
    {
      "x": -26,
      "y": -1,
      "z": -4,
      "name": "Soil_Dirt"
    },
    {
      "x": -26,
      "y": 0,
      "z": -4,
      "name": "Soil_Dirt"
    },
    {
      "x": -26,
      "y": 1,
      "z": -4,
      "name": "Soil_Dirt"
    },
    {
      "x": -26,
      "y": 1,
      "z": -3,
      "name": "Soil_Dirt"
    },
    {
      "x": -26,
      "y": -1,
      "z": -2,
      "name": "Soil_Dirt"
    },
    {
      "x": -26,
      "y": 0,
      "z": -2,
      "name": "Soil_Dirt"
    },
    {
      "x": -26,
      "y": 1,
      "z": -2,
      "name": "Soil_Dirt"
    },
    {
      "x": -26,
      "y": -3,
      "z": -1,
      "name": "Soil_Dirt"
    },
    {
      "x": -26,
      "y": -2,
      "z": -1,
      "name": "Soil_Dirt"
    },
    {
      "x": -26,
      "y": -1,
      "z": -1,
      "name": "Soil_Dirt"
    },
    {
      "x": -26,
      "y": 0,
      "z": -1,
      "name": "Soil_Dirt"
    },
    {
      "x": -26,
      "y": 1,
      "z": -1,
      "name": "Soil_Dirt"
    },
    {
      "x": -26,
      "y": -3,
      "z": 0,
      "name": "Soil_Dirt"
    },
    {
      "x": -26,
      "y": -2,
      "z": 0,
      "name": "Soil_Dirt"
    },
    {
      "x": -26,
      "y": -1,
      "z": 0,
      "name": "Soil_Dirt"
    },
    {
      "x": -26,
      "y": 0,
      "z": 0,
      "name": "Soil_Dirt"
    },
    {
      "x": -26,
      "y": 1,
      "z": 0,
      "name": "Soil_Dirt"
    },
    {
      "x": -26,
      "y": -1,
      "z": 1,
      "name": "Soil_Dirt"
    },
    {
      "x": -26,
      "y": 0,
      "z": 1,
      "name": "Soil_Dirt"
    },
    {
      "x": -26,
      "y": 1,
      "z": 1,
      "name": "Soil_Dirt"
    },
    {
      "x": -26,
      "y": -3,
      "z": 2,
      "name": "Soil_Dirt"
    },
    {
      "x": -26,
      "y": -2,
      "z": 2,
      "name": "Soil_Dirt"
    },
    {
      "x": -26,
      "y": -1,
      "z": 2,
      "name": "Soil_Dirt"
    },
    {
      "x": -26,
      "y": 0,
      "z": 2,
      "name": "Soil_Dirt"
    },
    {
      "x": -26,
      "y": 1,
      "z": 2,
      "name": "Soil_Dirt"
    },
    {
      "x": -26,
      "y": -3,
      "z": 3,
      "name": "Soil_Dirt"
    },
    {
      "x": -26,
      "y": -2,
      "z": 3,
      "name": "Soil_Dirt"
    },
    {
      "x": -26,
      "y": -1,
      "z": 3,
      "name": "Soil_Dirt"
    },
    {
      "x": -26,
      "y": 0,
      "z": 3,
      "name": "Soil_Dirt"
    },
    {
      "x": -26,
      "y": 1,
      "z": 3,
      "name": "Soil_Dirt"
    },
    {
      "x": -26,
      "y": -1,
      "z": 4,
      "name": "Soil_Dirt"
    },
    {
      "x": -26,
      "y": 0,
      "z": 4,
      "name": "Soil_Dirt"
    },
    {
      "x": -26,
      "y": 1,
      "z": 4,
      "name": "Soil_Dirt"
    },
    {
      "x": -26,
      "y": -3,
      "z": 5,
      "name": "Soil_Dirt"
    },
    {
      "x": -26,
      "y": -2,
      "z": 5,
      "name": "Soil_Dirt"
    },
    {
      "x": -26,
      "y": -1,
      "z": 5,
      "name": "Soil_Dirt"
    },
    {
      "x": -26,
      "y": 0,
      "z": 5,
      "name": "Soil_Dirt"
    },
    {
      "x": -26,
      "y": 1,
      "z": 5,
      "name": "Soil_Dirt"
    },
    {
      "x": -26,
      "y": -3,
      "z": 6,
      "name": "Soil_Dirt"
    },
    {
      "x": -26,
      "y": -2,
      "z": 6,
      "name": "Soil_Dirt"
    },
    {
      "x": -26,
      "y": -1,
      "z": 6,
      "name": "Soil_Dirt"
    },
    {
      "x": -26,
      "y": -3,
      "z": 7,
      "name": "Soil_Dirt"
    },
    {
      "x": -26,
      "y": -2,
      "z": 7,
      "name": "Soil_Dirt"
    },
    {
      "x": -26,
      "y": -1,
      "z": 7,
      "name": "Soil_Dirt"
    },
    {
      "x": -26,
      "y": -3,
      "z": 8,
      "name": "Soil_Dirt"
    },
    {
      "x": -26,
      "y": -2,
      "z": 8,
      "name": "Soil_Dirt"
    },
    {
      "x": -26,
      "y": -1,
      "z": 8,
      "name": "Soil_Dirt"
    },
    {
      "x": -26,
      "y": 0,
      "z": 8,
      "name": "Soil_Dirt"
    },
    {
      "x": -26,
      "y": -3,
      "z": 9,
      "name": "Soil_Dirt"
    },
    {
      "x": -26,
      "y": -2,
      "z": 9,
      "name": "Soil_Dirt"
    },
    {
      "x": -26,
      "y": -1,
      "z": 9,
      "name": "Soil_Dirt"
    },
    {
      "x": -26,
      "y": -3,
      "z": 11,
      "name": "Soil_Dirt"
    },
    {
      "x": -26,
      "y": -2,
      "z": 11,
      "name": "Soil_Dirt"
    },
    {
      "x": -26,
      "y": -1,
      "z": 11,
      "name": "Soil_Dirt"
    },
    {
      "x": -26,
      "y": -3,
      "z": 12,
      "name": "Soil_Dirt"
    },
    {
      "x": -26,
      "y": -2,
      "z": 12,
      "name": "Soil_Dirt"
    },
    {
      "x": -26,
      "y": -1,
      "z": 12,
      "name": "Soil_Dirt"
    },
    {
      "x": -26,
      "y": 0,
      "z": 12,
      "name": "Soil_Dirt"
    },
    {
      "x": -26,
      "y": -3,
      "z": 13,
      "name": "Soil_Dirt"
    },
    {
      "x": -26,
      "y": -2,
      "z": 13,
      "name": "Soil_Dirt"
    },
    {
      "x": -26,
      "y": -1,
      "z": 13,
      "name": "Soil_Dirt"
    },
    {
      "x": -25,
      "y": -3,
      "z": -12,
      "name": "Soil_Dirt"
    },
    {
      "x": -25,
      "y": -2,
      "z": -12,
      "name": "Soil_Dirt"
    },
    {
      "x": -25,
      "y": -1,
      "z": -12,
      "name": "Soil_Dirt"
    },
    {
      "x": -25,
      "y": -3,
      "z": -11,
      "name": "Soil_Dirt"
    },
    {
      "x": -25,
      "y": -2,
      "z": -11,
      "name": "Soil_Dirt"
    },
    {
      "x": -25,
      "y": -1,
      "z": -11,
      "name": "Soil_Dirt"
    },
    {
      "x": -25,
      "y": 0,
      "z": -11,
      "name": "Soil_Dirt"
    },
    {
      "x": -25,
      "y": 1,
      "z": -11,
      "name": "Soil_Dirt"
    },
    {
      "x": -25,
      "y": -1,
      "z": -10,
      "name": "Soil_Dirt"
    },
    {
      "x": -25,
      "y": 0,
      "z": -10,
      "name": "Soil_Dirt"
    },
    {
      "x": -25,
      "y": 1,
      "z": -10,
      "name": "Soil_Dirt"
    },
    {
      "x": -25,
      "y": -3,
      "z": -9,
      "name": "Soil_Dirt"
    },
    {
      "x": -25,
      "y": -2,
      "z": -9,
      "name": "Soil_Dirt"
    },
    {
      "x": -25,
      "y": -1,
      "z": -9,
      "name": "Soil_Dirt"
    },
    {
      "x": -25,
      "y": 0,
      "z": -9,
      "name": "Soil_Dirt"
    },
    {
      "x": -25,
      "y": 1,
      "z": -9,
      "name": "Soil_Dirt"
    },
    {
      "x": -25,
      "y": -3,
      "z": -8,
      "name": "Soil_Dirt"
    },
    {
      "x": -25,
      "y": -2,
      "z": -8,
      "name": "Soil_Dirt"
    },
    {
      "x": -25,
      "y": -1,
      "z": -8,
      "name": "Soil_Dirt"
    },
    {
      "x": -25,
      "y": 0,
      "z": -8,
      "name": "Soil_Dirt"
    },
    {
      "x": -25,
      "y": 1,
      "z": -8,
      "name": "Soil_Dirt"
    },
    {
      "x": -25,
      "y": -1,
      "z": -7,
      "name": "Soil_Dirt"
    },
    {
      "x": -25,
      "y": 0,
      "z": -7,
      "name": "Soil_Dirt"
    },
    {
      "x": -25,
      "y": 1,
      "z": -7,
      "name": "Soil_Dirt"
    },
    {
      "x": -25,
      "y": 1,
      "z": -6,
      "name": "Soil_Dirt"
    },
    {
      "x": -25,
      "y": -3,
      "z": -5,
      "name": "Soil_Dirt"
    },
    {
      "x": -25,
      "y": -2,
      "z": -5,
      "name": "Soil_Dirt"
    },
    {
      "x": -25,
      "y": -1,
      "z": -5,
      "name": "Soil_Dirt"
    },
    {
      "x": -25,
      "y": 0,
      "z": -5,
      "name": "Soil_Dirt"
    },
    {
      "x": -25,
      "y": 1,
      "z": -5,
      "name": "Soil_Dirt"
    },
    {
      "x": -25,
      "y": -3,
      "z": -4,
      "name": "Soil_Dirt"
    },
    {
      "x": -25,
      "y": -2,
      "z": -4,
      "name": "Soil_Dirt"
    },
    {
      "x": -25,
      "y": -1,
      "z": -4,
      "name": "Soil_Dirt"
    },
    {
      "x": -25,
      "y": 0,
      "z": -4,
      "name": "Soil_Dirt"
    },
    {
      "x": -25,
      "y": 1,
      "z": -4,
      "name": "Soil_Dirt"
    },
    {
      "x": -25,
      "y": -1,
      "z": -3,
      "name": "Soil_Dirt"
    },
    {
      "x": -25,
      "y": 0,
      "z": -3,
      "name": "Soil_Dirt"
    },
    {
      "x": -25,
      "y": 1,
      "z": -3,
      "name": "Soil_Dirt"
    },
    {
      "x": -25,
      "y": -3,
      "z": -2,
      "name": "Soil_Dirt"
    },
    {
      "x": -25,
      "y": -2,
      "z": -2,
      "name": "Soil_Dirt"
    },
    {
      "x": -25,
      "y": -1,
      "z": -2,
      "name": "Soil_Dirt"
    },
    {
      "x": -25,
      "y": 0,
      "z": -2,
      "name": "Soil_Dirt"
    },
    {
      "x": -25,
      "y": 1,
      "z": -2,
      "name": "Soil_Dirt"
    },
    {
      "x": -25,
      "y": -3,
      "z": -1,
      "name": "Soil_Dirt"
    },
    {
      "x": -25,
      "y": -2,
      "z": -1,
      "name": "Soil_Dirt"
    },
    {
      "x": -25,
      "y": -1,
      "z": -1,
      "name": "Soil_Dirt"
    },
    {
      "x": -25,
      "y": 1,
      "z": -1,
      "name": "Soil_Dirt"
    },
    {
      "x": -25,
      "y": -3,
      "z": 0,
      "name": "Soil_Dirt"
    },
    {
      "x": -25,
      "y": -2,
      "z": 0,
      "name": "Soil_Dirt"
    },
    {
      "x": -25,
      "y": -1,
      "z": 0,
      "name": "Soil_Dirt"
    },
    {
      "x": -25,
      "y": 1,
      "z": 0,
      "name": "Soil_Dirt"
    },
    {
      "x": -25,
      "y": -3,
      "z": 1,
      "name": "Soil_Dirt"
    },
    {
      "x": -25,
      "y": -2,
      "z": 1,
      "name": "Soil_Dirt"
    },
    {
      "x": -25,
      "y": -1,
      "z": 1,
      "name": "Soil_Dirt"
    },
    {
      "x": -25,
      "y": 0,
      "z": 1,
      "name": "Soil_Dirt"
    },
    {
      "x": -25,
      "y": 1,
      "z": 1,
      "name": "Soil_Dirt"
    },
    {
      "x": -25,
      "y": -3,
      "z": 2,
      "name": "Soil_Dirt"
    },
    {
      "x": -25,
      "y": -2,
      "z": 2,
      "name": "Soil_Dirt"
    },
    {
      "x": -25,
      "y": -1,
      "z": 2,
      "name": "Soil_Dirt"
    },
    {
      "x": -25,
      "y": 0,
      "z": 2,
      "name": "Soil_Dirt"
    },
    {
      "x": -25,
      "y": 1,
      "z": 2,
      "name": "Soil_Dirt"
    },
    {
      "x": -25,
      "y": -1,
      "z": 3,
      "name": "Soil_Dirt"
    },
    {
      "x": -25,
      "y": 0,
      "z": 3,
      "name": "Soil_Dirt"
    },
    {
      "x": -25,
      "y": 1,
      "z": 3,
      "name": "Soil_Dirt"
    },
    {
      "x": -25,
      "y": 1,
      "z": 4,
      "name": "Soil_Dirt"
    },
    {
      "x": -25,
      "y": -1,
      "z": 5,
      "name": "Soil_Dirt"
    },
    {
      "x": -25,
      "y": 0,
      "z": 5,
      "name": "Soil_Dirt"
    },
    {
      "x": -25,
      "y": 1,
      "z": 5,
      "name": "Soil_Dirt"
    },
    {
      "x": -25,
      "y": -3,
      "z": 6,
      "name": "Soil_Dirt"
    },
    {
      "x": -25,
      "y": -2,
      "z": 6,
      "name": "Soil_Dirt"
    },
    {
      "x": -25,
      "y": -1,
      "z": 6,
      "name": "Soil_Dirt"
    },
    {
      "x": -25,
      "y": 0,
      "z": 6,
      "name": "Soil_Dirt"
    },
    {
      "x": -25,
      "y": -3,
      "z": 7,
      "name": "Soil_Dirt"
    },
    {
      "x": -25,
      "y": -2,
      "z": 7,
      "name": "Soil_Dirt"
    },
    {
      "x": -25,
      "y": -1,
      "z": 7,
      "name": "Soil_Dirt"
    },
    {
      "x": -25,
      "y": 0,
      "z": 7,
      "name": "Soil_Dirt"
    },
    {
      "x": -25,
      "y": 1,
      "z": 7,
      "name": "Soil_Dirt"
    },
    {
      "x": -25,
      "y": -1,
      "z": 8,
      "name": "Soil_Dirt"
    },
    {
      "x": -25,
      "y": 0,
      "z": 8,
      "name": "Soil_Dirt"
    },
    {
      "x": -25,
      "y": 1,
      "z": 8,
      "name": "Soil_Dirt"
    },
    {
      "x": -25,
      "y": -3,
      "z": 9,
      "name": "Soil_Dirt"
    },
    {
      "x": -25,
      "y": -2,
      "z": 9,
      "name": "Soil_Dirt"
    },
    {
      "x": -25,
      "y": -1,
      "z": 9,
      "name": "Soil_Dirt"
    },
    {
      "x": -25,
      "y": 0,
      "z": 9,
      "name": "Soil_Dirt"
    },
    {
      "x": -25,
      "y": 1,
      "z": 9,
      "name": "Soil_Dirt"
    },
    {
      "x": -25,
      "y": -3,
      "z": 10,
      "name": "Soil_Dirt"
    },
    {
      "x": -25,
      "y": -2,
      "z": 10,
      "name": "Soil_Dirt"
    },
    {
      "x": -25,
      "y": -1,
      "z": 10,
      "name": "Soil_Dirt"
    },
    {
      "x": -25,
      "y": -3,
      "z": 11,
      "name": "Soil_Dirt"
    },
    {
      "x": -25,
      "y": -2,
      "z": 11,
      "name": "Soil_Dirt"
    },
    {
      "x": -25,
      "y": -1,
      "z": 11,
      "name": "Soil_Dirt"
    },
    {
      "x": -25,
      "y": 0,
      "z": 11,
      "name": "Soil_Dirt"
    },
    {
      "x": -25,
      "y": 1,
      "z": 11,
      "name": "Soil_Dirt"
    },
    {
      "x": -25,
      "y": -1,
      "z": 12,
      "name": "Soil_Dirt"
    },
    {
      "x": -25,
      "y": 0,
      "z": 12,
      "name": "Soil_Dirt"
    },
    {
      "x": -25,
      "y": 1,
      "z": 12,
      "name": "Soil_Dirt"
    },
    {
      "x": -25,
      "y": -3,
      "z": 13,
      "name": "Soil_Dirt"
    },
    {
      "x": -25,
      "y": -2,
      "z": 13,
      "name": "Soil_Dirt"
    },
    {
      "x": -25,
      "y": -1,
      "z": 13,
      "name": "Soil_Dirt"
    },
    {
      "x": -25,
      "y": 0,
      "z": 13,
      "name": "Soil_Dirt"
    },
    {
      "x": -25,
      "y": 1,
      "z": 13,
      "name": "Soil_Dirt"
    },
    {
      "x": -25,
      "y": -3,
      "z": 14,
      "name": "Soil_Dirt"
    },
    {
      "x": -25,
      "y": -2,
      "z": 14,
      "name": "Soil_Dirt"
    },
    {
      "x": -25,
      "y": -1,
      "z": 14,
      "name": "Soil_Dirt"
    },
    {
      "x": -24,
      "y": -3,
      "z": -12,
      "name": "Soil_Dirt"
    },
    {
      "x": -24,
      "y": -2,
      "z": -12,
      "name": "Soil_Dirt"
    },
    {
      "x": -24,
      "y": -1,
      "z": -12,
      "name": "Soil_Dirt"
    },
    {
      "x": -24,
      "y": 0,
      "z": -12,
      "name": "Soil_Dirt"
    },
    {
      "x": -24,
      "y": -1,
      "z": -11,
      "name": "Soil_Dirt"
    },
    {
      "x": -24,
      "y": 0,
      "z": -11,
      "name": "Soil_Dirt"
    },
    {
      "x": -24,
      "y": 1,
      "z": -11,
      "name": "Soil_Dirt"
    },
    {
      "x": -24,
      "y": 1,
      "z": -10,
      "name": "Soil_Dirt"
    },
    {
      "x": -24,
      "y": -1,
      "z": -9,
      "name": "Soil_Dirt"
    },
    {
      "x": -24,
      "y": 0,
      "z": -9,
      "name": "Soil_Dirt"
    },
    {
      "x": -24,
      "y": 1,
      "z": -9,
      "name": "Soil_Dirt"
    },
    {
      "x": -24,
      "y": -3,
      "z": -8,
      "name": "Soil_Dirt"
    },
    {
      "x": -24,
      "y": -2,
      "z": -8,
      "name": "Soil_Dirt"
    },
    {
      "x": -24,
      "y": -1,
      "z": -8,
      "name": "Soil_Dirt"
    },
    {
      "x": -24,
      "y": 0,
      "z": -8,
      "name": "Soil_Dirt"
    },
    {
      "x": -24,
      "y": 1,
      "z": -8,
      "name": "Soil_Dirt"
    },
    {
      "x": -24,
      "y": -3,
      "z": -7,
      "name": "Soil_Dirt"
    },
    {
      "x": -24,
      "y": -2,
      "z": -7,
      "name": "Soil_Dirt"
    },
    {
      "x": -24,
      "y": -1,
      "z": -7,
      "name": "Soil_Dirt"
    },
    {
      "x": -24,
      "y": 0,
      "z": -7,
      "name": "Soil_Dirt"
    },
    {
      "x": -24,
      "y": 1,
      "z": -7,
      "name": "Soil_Dirt"
    },
    {
      "x": -24,
      "y": -1,
      "z": -6,
      "name": "Soil_Dirt"
    },
    {
      "x": -24,
      "y": 0,
      "z": -6,
      "name": "Soil_Dirt"
    },
    {
      "x": -24,
      "y": 1,
      "z": -6,
      "name": "Soil_Dirt"
    },
    {
      "x": -24,
      "y": -3,
      "z": -5,
      "name": "Soil_Dirt"
    },
    {
      "x": -24,
      "y": -2,
      "z": -5,
      "name": "Soil_Dirt"
    },
    {
      "x": -24,
      "y": -1,
      "z": -5,
      "name": "Soil_Dirt"
    },
    {
      "x": -24,
      "y": 0,
      "z": -5,
      "name": "Soil_Dirt"
    },
    {
      "x": -24,
      "y": 1,
      "z": -5,
      "name": "Soil_Dirt"
    },
    {
      "x": -24,
      "y": -3,
      "z": -4,
      "name": "Soil_Dirt"
    },
    {
      "x": -24,
      "y": -2,
      "z": -4,
      "name": "Soil_Dirt"
    },
    {
      "x": -24,
      "y": -1,
      "z": -4,
      "name": "Soil_Dirt"
    },
    {
      "x": -24,
      "y": 1,
      "z": -4,
      "name": "Soil_Dirt"
    },
    {
      "x": -24,
      "y": -3,
      "z": -3,
      "name": "Soil_Dirt"
    },
    {
      "x": -24,
      "y": -2,
      "z": -3,
      "name": "Soil_Dirt"
    },
    {
      "x": -24,
      "y": -1,
      "z": -3,
      "name": "Soil_Dirt"
    },
    {
      "x": -24,
      "y": 0,
      "z": -3,
      "name": "Soil_Dirt"
    },
    {
      "x": -24,
      "y": 1,
      "z": -3,
      "name": "Soil_Dirt"
    },
    {
      "x": -24,
      "y": -3,
      "z": -2,
      "name": "Soil_Dirt"
    },
    {
      "x": -24,
      "y": -2,
      "z": -2,
      "name": "Soil_Dirt"
    },
    {
      "x": -24,
      "y": -1,
      "z": -2,
      "name": "Soil_Dirt"
    },
    {
      "x": -24,
      "y": 1,
      "z": -2,
      "name": "Soil_Dirt"
    },
    {
      "x": -24,
      "y": 1,
      "z": -1,
      "name": "Soil_Dirt"
    },
    {
      "x": -24,
      "y": 1,
      "z": 0,
      "name": "Soil_Dirt"
    },
    {
      "x": -24,
      "y": 1,
      "z": 1,
      "name": "Soil_Dirt"
    },
    {
      "x": -24,
      "y": -3,
      "z": 2,
      "name": "Soil_Dirt"
    },
    {
      "x": -24,
      "y": -2,
      "z": 2,
      "name": "Soil_Dirt"
    },
    {
      "x": -24,
      "y": -1,
      "z": 2,
      "name": "Soil_Dirt"
    },
    {
      "x": -24,
      "y": 1,
      "z": 2,
      "name": "Soil_Dirt"
    },
    {
      "x": -24,
      "y": -3,
      "z": 3,
      "name": "Soil_Dirt"
    },
    {
      "x": -24,
      "y": -2,
      "z": 3,
      "name": "Soil_Dirt"
    },
    {
      "x": -24,
      "y": -1,
      "z": 3,
      "name": "Soil_Dirt"
    },
    {
      "x": -24,
      "y": 0,
      "z": 3,
      "name": "Soil_Dirt"
    },
    {
      "x": -24,
      "y": 1,
      "z": 3,
      "name": "Soil_Dirt"
    },
    {
      "x": -24,
      "y": -1,
      "z": 4,
      "name": "Soil_Dirt"
    },
    {
      "x": -24,
      "y": 0,
      "z": 4,
      "name": "Soil_Dirt"
    },
    {
      "x": -24,
      "y": 1,
      "z": 4,
      "name": "Soil_Dirt"
    },
    {
      "x": -24,
      "y": -3,
      "z": 5,
      "name": "Soil_Dirt"
    },
    {
      "x": -24,
      "y": -2,
      "z": 5,
      "name": "Soil_Dirt"
    },
    {
      "x": -24,
      "y": -1,
      "z": 5,
      "name": "Soil_Dirt"
    },
    {
      "x": -24,
      "y": 0,
      "z": 5,
      "name": "Soil_Dirt"
    },
    {
      "x": -24,
      "y": 1,
      "z": 5,
      "name": "Soil_Dirt"
    },
    {
      "x": -24,
      "y": -3,
      "z": 6,
      "name": "Soil_Dirt"
    },
    {
      "x": -24,
      "y": -2,
      "z": 6,
      "name": "Soil_Dirt"
    },
    {
      "x": -24,
      "y": -1,
      "z": 6,
      "name": "Soil_Dirt"
    },
    {
      "x": -24,
      "y": 0,
      "z": 6,
      "name": "Soil_Dirt"
    },
    {
      "x": -24,
      "y": 1,
      "z": 6,
      "name": "Soil_Dirt"
    },
    {
      "x": -24,
      "y": -1,
      "z": 7,
      "name": "Soil_Dirt"
    },
    {
      "x": -24,
      "y": 0,
      "z": 7,
      "name": "Soil_Dirt"
    },
    {
      "x": -24,
      "y": 1,
      "z": 7,
      "name": "Soil_Dirt"
    },
    {
      "x": -24,
      "y": 1,
      "z": 8,
      "name": "Soil_Dirt"
    },
    {
      "x": -24,
      "y": -1,
      "z": 9,
      "name": "Soil_Dirt"
    },
    {
      "x": -24,
      "y": 0,
      "z": 9,
      "name": "Soil_Dirt"
    },
    {
      "x": -24,
      "y": 1,
      "z": 9,
      "name": "Soil_Dirt"
    },
    {
      "x": -24,
      "y": -3,
      "z": 10,
      "name": "Soil_Dirt"
    },
    {
      "x": -24,
      "y": -2,
      "z": 10,
      "name": "Soil_Dirt"
    },
    {
      "x": -24,
      "y": -1,
      "z": 10,
      "name": "Soil_Dirt"
    },
    {
      "x": -24,
      "y": 0,
      "z": 10,
      "name": "Soil_Dirt"
    },
    {
      "x": -24,
      "y": 1,
      "z": 10,
      "name": "Soil_Dirt"
    },
    {
      "x": -24,
      "y": -1,
      "z": 11,
      "name": "Soil_Dirt"
    },
    {
      "x": -24,
      "y": 0,
      "z": 11,
      "name": "Soil_Dirt"
    },
    {
      "x": -24,
      "y": 1,
      "z": 11,
      "name": "Soil_Dirt"
    },
    {
      "x": -24,
      "y": 1,
      "z": 12,
      "name": "Soil_Dirt"
    },
    {
      "x": -24,
      "y": -1,
      "z": 13,
      "name": "Soil_Dirt"
    },
    {
      "x": -24,
      "y": 0,
      "z": 13,
      "name": "Soil_Dirt"
    },
    {
      "x": -24,
      "y": 1,
      "z": 13,
      "name": "Soil_Dirt"
    },
    {
      "x": -24,
      "y": -3,
      "z": 14,
      "name": "Soil_Dirt"
    },
    {
      "x": -24,
      "y": -2,
      "z": 14,
      "name": "Soil_Dirt"
    },
    {
      "x": -24,
      "y": -1,
      "z": 14,
      "name": "Soil_Dirt"
    },
    {
      "x": -24,
      "y": 0,
      "z": 14,
      "name": "Soil_Dirt"
    },
    {
      "x": -23,
      "y": -3,
      "z": -18,
      "name": "Soil_Dirt"
    },
    {
      "x": -23,
      "y": -2,
      "z": -18,
      "name": "Soil_Dirt"
    },
    {
      "x": -23,
      "y": -1,
      "z": -18,
      "name": "Soil_Dirt"
    },
    {
      "x": -23,
      "y": -3,
      "z": -17,
      "name": "Soil_Dirt"
    },
    {
      "x": -23,
      "y": -2,
      "z": -17,
      "name": "Soil_Dirt"
    },
    {
      "x": -23,
      "y": -1,
      "z": -17,
      "name": "Soil_Dirt"
    },
    {
      "x": -23,
      "y": 0,
      "z": -17,
      "name": "Soil_Dirt"
    },
    {
      "x": -23,
      "y": -3,
      "z": -16,
      "name": "Soil_Dirt"
    },
    {
      "x": -23,
      "y": -2,
      "z": -16,
      "name": "Soil_Dirt"
    },
    {
      "x": -23,
      "y": -1,
      "z": -16,
      "name": "Soil_Dirt"
    },
    {
      "x": -23,
      "y": -3,
      "z": -14,
      "name": "Soil_Dirt"
    },
    {
      "x": -23,
      "y": -2,
      "z": -14,
      "name": "Soil_Dirt"
    },
    {
      "x": -23,
      "y": -1,
      "z": -14,
      "name": "Soil_Dirt"
    },
    {
      "x": -23,
      "y": -3,
      "z": -13,
      "name": "Soil_Dirt"
    },
    {
      "x": -23,
      "y": -2,
      "z": -13,
      "name": "Soil_Dirt"
    },
    {
      "x": -23,
      "y": -1,
      "z": -13,
      "name": "Soil_Dirt"
    },
    {
      "x": -23,
      "y": 0,
      "z": -13,
      "name": "Soil_Dirt"
    },
    {
      "x": -23,
      "y": -3,
      "z": -12,
      "name": "Soil_Dirt"
    },
    {
      "x": -23,
      "y": -2,
      "z": -12,
      "name": "Soil_Dirt"
    },
    {
      "x": -23,
      "y": -1,
      "z": -12,
      "name": "Soil_Dirt"
    },
    {
      "x": -23,
      "y": 1,
      "z": -12,
      "name": "Soil_Dirt"
    },
    {
      "x": -23,
      "y": -3,
      "z": -11,
      "name": "Soil_Dirt"
    },
    {
      "x": -23,
      "y": -2,
      "z": -11,
      "name": "Soil_Dirt"
    },
    {
      "x": -23,
      "y": -1,
      "z": -11,
      "name": "Soil_Dirt"
    },
    {
      "x": -23,
      "y": 0,
      "z": -11,
      "name": "Soil_Dirt"
    },
    {
      "x": -23,
      "y": 1,
      "z": -11,
      "name": "Soil_Dirt"
    },
    {
      "x": -23,
      "y": -1,
      "z": -10,
      "name": "Soil_Dirt"
    },
    {
      "x": -23,
      "y": 0,
      "z": -10,
      "name": "Soil_Dirt"
    },
    {
      "x": -23,
      "y": 1,
      "z": -10,
      "name": "Soil_Dirt"
    },
    {
      "x": -23,
      "y": -3,
      "z": -9,
      "name": "Soil_Dirt"
    },
    {
      "x": -23,
      "y": -2,
      "z": -9,
      "name": "Soil_Dirt"
    },
    {
      "x": -23,
      "y": -1,
      "z": -9,
      "name": "Soil_Dirt"
    },
    {
      "x": -23,
      "y": 0,
      "z": -9,
      "name": "Soil_Dirt"
    },
    {
      "x": -23,
      "y": 1,
      "z": -9,
      "name": "Soil_Dirt"
    },
    {
      "x": -23,
      "y": -3,
      "z": -8,
      "name": "Soil_Dirt"
    },
    {
      "x": -23,
      "y": -2,
      "z": -8,
      "name": "Soil_Dirt"
    },
    {
      "x": -23,
      "y": -1,
      "z": -8,
      "name": "Soil_Dirt"
    },
    {
      "x": -23,
      "y": 1,
      "z": -8,
      "name": "Soil_Dirt"
    },
    {
      "x": -23,
      "y": -3,
      "z": -7,
      "name": "Soil_Dirt"
    },
    {
      "x": -23,
      "y": -2,
      "z": -7,
      "name": "Soil_Dirt"
    },
    {
      "x": -23,
      "y": -1,
      "z": -7,
      "name": "Soil_Dirt"
    },
    {
      "x": -23,
      "y": 1,
      "z": -7,
      "name": "Soil_Dirt"
    },
    {
      "x": -23,
      "y": -3,
      "z": -6,
      "name": "Soil_Dirt"
    },
    {
      "x": -23,
      "y": -2,
      "z": -6,
      "name": "Soil_Dirt"
    },
    {
      "x": -23,
      "y": -1,
      "z": -6,
      "name": "Soil_Dirt"
    },
    {
      "x": -23,
      "y": 0,
      "z": -6,
      "name": "Soil_Dirt"
    },
    {
      "x": -23,
      "y": 1,
      "z": -6,
      "name": "Soil_Dirt"
    },
    {
      "x": -23,
      "y": -3,
      "z": -5,
      "name": "Soil_Dirt"
    },
    {
      "x": -23,
      "y": -2,
      "z": -5,
      "name": "Soil_Dirt"
    },
    {
      "x": -23,
      "y": -1,
      "z": -5,
      "name": "Soil_Dirt"
    },
    {
      "x": -23,
      "y": 1,
      "z": -5,
      "name": "Soil_Dirt"
    },
    {
      "x": -23,
      "y": 1,
      "z": -4,
      "name": "Soil_Dirt"
    },
    {
      "x": -23,
      "y": 1,
      "z": -3,
      "name": "Soil_Dirt"
    },
    {
      "x": -23,
      "y": 1,
      "z": -2,
      "name": "Soil_Dirt"
    },
    {
      "x": -23,
      "y": 1,
      "z": -1,
      "name": "Soil_Dirt"
    },
    {
      "x": -23,
      "y": 1,
      "z": 0,
      "name": "Soil_Dirt"
    },
    {
      "x": -23,
      "y": 1,
      "z": 1,
      "name": "Soil_Dirt"
    },
    {
      "x": -23,
      "y": 1,
      "z": 2,
      "name": "Soil_Dirt"
    },
    {
      "x": -23,
      "y": -3,
      "z": 3,
      "name": "Soil_Dirt"
    },
    {
      "x": -23,
      "y": -2,
      "z": 3,
      "name": "Soil_Dirt"
    },
    {
      "x": -23,
      "y": -1,
      "z": 3,
      "name": "Soil_Dirt"
    },
    {
      "x": -23,
      "y": 1,
      "z": 3,
      "name": "Soil_Dirt"
    },
    {
      "x": -23,
      "y": -3,
      "z": 4,
      "name": "Soil_Dirt"
    },
    {
      "x": -23,
      "y": -2,
      "z": 4,
      "name": "Soil_Dirt"
    },
    {
      "x": -23,
      "y": -1,
      "z": 4,
      "name": "Soil_Dirt"
    },
    {
      "x": -23,
      "y": 0,
      "z": 4,
      "name": "Soil_Dirt"
    },
    {
      "x": -23,
      "y": 1,
      "z": 4,
      "name": "Soil_Dirt"
    },
    {
      "x": -23,
      "y": -3,
      "z": 5,
      "name": "Soil_Dirt"
    },
    {
      "x": -23,
      "y": -2,
      "z": 5,
      "name": "Soil_Dirt"
    },
    {
      "x": -23,
      "y": -1,
      "z": 5,
      "name": "Soil_Dirt"
    },
    {
      "x": -23,
      "y": 1,
      "z": 5,
      "name": "Soil_Dirt"
    },
    {
      "x": -23,
      "y": -3,
      "z": 6,
      "name": "Soil_Dirt"
    },
    {
      "x": -23,
      "y": -2,
      "z": 6,
      "name": "Soil_Dirt"
    },
    {
      "x": -23,
      "y": -1,
      "z": 6,
      "name": "Soil_Dirt"
    },
    {
      "x": -23,
      "y": 1,
      "z": 6,
      "name": "Soil_Dirt"
    },
    {
      "x": -23,
      "y": -3,
      "z": 7,
      "name": "Soil_Dirt"
    },
    {
      "x": -23,
      "y": -2,
      "z": 7,
      "name": "Soil_Dirt"
    },
    {
      "x": -23,
      "y": -1,
      "z": 7,
      "name": "Soil_Dirt"
    },
    {
      "x": -23,
      "y": 0,
      "z": 7,
      "name": "Soil_Dirt"
    },
    {
      "x": -23,
      "y": 1,
      "z": 7,
      "name": "Soil_Dirt"
    },
    {
      "x": -23,
      "y": -1,
      "z": 8,
      "name": "Soil_Dirt"
    },
    {
      "x": -23,
      "y": 0,
      "z": 8,
      "name": "Soil_Dirt"
    },
    {
      "x": -23,
      "y": 1,
      "z": 8,
      "name": "Soil_Dirt"
    },
    {
      "x": -23,
      "y": -3,
      "z": 9,
      "name": "Soil_Dirt"
    },
    {
      "x": -23,
      "y": -2,
      "z": 9,
      "name": "Soil_Dirt"
    },
    {
      "x": -23,
      "y": -1,
      "z": 9,
      "name": "Soil_Dirt"
    },
    {
      "x": -23,
      "y": 0,
      "z": 9,
      "name": "Soil_Dirt"
    },
    {
      "x": -23,
      "y": 1,
      "z": 9,
      "name": "Soil_Dirt"
    },
    {
      "x": -23,
      "y": -3,
      "z": 10,
      "name": "Soil_Dirt"
    },
    {
      "x": -23,
      "y": -2,
      "z": 10,
      "name": "Soil_Dirt"
    },
    {
      "x": -23,
      "y": -1,
      "z": 10,
      "name": "Soil_Dirt"
    },
    {
      "x": -23,
      "y": 1,
      "z": 10,
      "name": "Soil_Dirt"
    },
    {
      "x": -23,
      "y": -3,
      "z": 11,
      "name": "Soil_Dirt"
    },
    {
      "x": -23,
      "y": -2,
      "z": 11,
      "name": "Soil_Dirt"
    },
    {
      "x": -23,
      "y": -1,
      "z": 11,
      "name": "Soil_Dirt"
    },
    {
      "x": -23,
      "y": 0,
      "z": 11,
      "name": "Soil_Dirt"
    },
    {
      "x": -23,
      "y": 1,
      "z": 11,
      "name": "Soil_Dirt"
    },
    {
      "x": -23,
      "y": -1,
      "z": 12,
      "name": "Soil_Dirt"
    },
    {
      "x": -23,
      "y": 0,
      "z": 12,
      "name": "Soil_Dirt"
    },
    {
      "x": -23,
      "y": 1,
      "z": 12,
      "name": "Soil_Dirt"
    },
    {
      "x": -23,
      "y": -3,
      "z": 13,
      "name": "Soil_Dirt"
    },
    {
      "x": -23,
      "y": -2,
      "z": 13,
      "name": "Soil_Dirt"
    },
    {
      "x": -23,
      "y": -1,
      "z": 13,
      "name": "Soil_Dirt"
    },
    {
      "x": -23,
      "y": 0,
      "z": 13,
      "name": "Soil_Dirt"
    },
    {
      "x": -23,
      "y": 1,
      "z": 13,
      "name": "Soil_Dirt"
    },
    {
      "x": -23,
      "y": -3,
      "z": 14,
      "name": "Soil_Dirt"
    },
    {
      "x": -23,
      "y": -2,
      "z": 14,
      "name": "Soil_Dirt"
    },
    {
      "x": -23,
      "y": -1,
      "z": 14,
      "name": "Soil_Dirt"
    },
    {
      "x": -23,
      "y": -3,
      "z": 15,
      "name": "Soil_Dirt"
    },
    {
      "x": -23,
      "y": -2,
      "z": 15,
      "name": "Soil_Dirt"
    },
    {
      "x": -23,
      "y": -1,
      "z": 15,
      "name": "Soil_Dirt"
    },
    {
      "x": -23,
      "y": 0,
      "z": 15,
      "name": "Soil_Dirt"
    },
    {
      "x": -23,
      "y": -3,
      "z": 16,
      "name": "Soil_Dirt"
    },
    {
      "x": -23,
      "y": -2,
      "z": 16,
      "name": "Soil_Dirt"
    },
    {
      "x": -23,
      "y": -1,
      "z": 16,
      "name": "Soil_Dirt"
    },
    {
      "x": -22,
      "y": -3,
      "z": -19,
      "name": "Soil_Dirt"
    },
    {
      "x": -22,
      "y": -2,
      "z": -19,
      "name": "Soil_Dirt"
    },
    {
      "x": -22,
      "y": -1,
      "z": -19,
      "name": "Soil_Dirt"
    },
    {
      "x": -22,
      "y": -3,
      "z": -18,
      "name": "Soil_Dirt"
    },
    {
      "x": -22,
      "y": -2,
      "z": -18,
      "name": "Soil_Dirt"
    },
    {
      "x": -22,
      "y": -1,
      "z": -18,
      "name": "Soil_Dirt"
    },
    {
      "x": -22,
      "y": 0,
      "z": -18,
      "name": "Soil_Dirt"
    },
    {
      "x": -22,
      "y": 1,
      "z": -18,
      "name": "Soil_Dirt"
    },
    {
      "x": -22,
      "y": -1,
      "z": -17,
      "name": "Soil_Dirt"
    },
    {
      "x": -22,
      "y": 0,
      "z": -17,
      "name": "Soil_Dirt"
    },
    {
      "x": -22,
      "y": 1,
      "z": -17,
      "name": "Soil_Dirt"
    },
    {
      "x": -22,
      "y": -3,
      "z": -16,
      "name": "Soil_Dirt"
    },
    {
      "x": -22,
      "y": -2,
      "z": -16,
      "name": "Soil_Dirt"
    },
    {
      "x": -22,
      "y": -1,
      "z": -16,
      "name": "Soil_Dirt"
    },
    {
      "x": -22,
      "y": 0,
      "z": -16,
      "name": "Soil_Dirt"
    },
    {
      "x": -22,
      "y": 1,
      "z": -16,
      "name": "Soil_Dirt"
    },
    {
      "x": -22,
      "y": -3,
      "z": -15,
      "name": "Soil_Dirt"
    },
    {
      "x": -22,
      "y": -2,
      "z": -15,
      "name": "Soil_Dirt"
    },
    {
      "x": -22,
      "y": -1,
      "z": -15,
      "name": "Soil_Dirt"
    },
    {
      "x": -22,
      "y": -3,
      "z": -14,
      "name": "Soil_Dirt"
    },
    {
      "x": -22,
      "y": -2,
      "z": -14,
      "name": "Soil_Dirt"
    },
    {
      "x": -22,
      "y": -1,
      "z": -14,
      "name": "Soil_Dirt"
    },
    {
      "x": -22,
      "y": 0,
      "z": -14,
      "name": "Soil_Dirt"
    },
    {
      "x": -22,
      "y": 1,
      "z": -14,
      "name": "Soil_Dirt"
    },
    {
      "x": -22,
      "y": -1,
      "z": -13,
      "name": "Soil_Dirt"
    },
    {
      "x": -22,
      "y": 0,
      "z": -13,
      "name": "Soil_Dirt"
    },
    {
      "x": -22,
      "y": 1,
      "z": -13,
      "name": "Soil_Dirt"
    },
    {
      "x": -22,
      "y": -3,
      "z": -12,
      "name": "Soil_Dirt"
    },
    {
      "x": -22,
      "y": -2,
      "z": -12,
      "name": "Soil_Dirt"
    },
    {
      "x": -22,
      "y": -1,
      "z": -12,
      "name": "Soil_Dirt"
    },
    {
      "x": -22,
      "y": 0,
      "z": -12,
      "name": "Soil_Dirt"
    },
    {
      "x": -22,
      "y": 1,
      "z": -12,
      "name": "Soil_Dirt"
    },
    {
      "x": -22,
      "y": -3,
      "z": -11,
      "name": "Soil_Dirt"
    },
    {
      "x": -22,
      "y": -2,
      "z": -11,
      "name": "Soil_Dirt"
    },
    {
      "x": -22,
      "y": -1,
      "z": -11,
      "name": "Soil_Dirt"
    },
    {
      "x": -22,
      "y": 1,
      "z": -11,
      "name": "Soil_Dirt"
    },
    {
      "x": -22,
      "y": -3,
      "z": -10,
      "name": "Soil_Dirt"
    },
    {
      "x": -22,
      "y": -2,
      "z": -10,
      "name": "Soil_Dirt"
    },
    {
      "x": -22,
      "y": -1,
      "z": -10,
      "name": "Soil_Dirt"
    },
    {
      "x": -22,
      "y": 0,
      "z": -10,
      "name": "Soil_Dirt"
    },
    {
      "x": -22,
      "y": 1,
      "z": -10,
      "name": "Soil_Dirt"
    },
    {
      "x": -22,
      "y": -3,
      "z": -9,
      "name": "Soil_Dirt"
    },
    {
      "x": -22,
      "y": -2,
      "z": -9,
      "name": "Soil_Dirt"
    },
    {
      "x": -22,
      "y": -1,
      "z": -9,
      "name": "Soil_Dirt"
    },
    {
      "x": -22,
      "y": 1,
      "z": -9,
      "name": "Soil_Dirt"
    },
    {
      "x": -22,
      "y": 1,
      "z": -8,
      "name": "Soil_Dirt"
    },
    {
      "x": -22,
      "y": 1,
      "z": -7,
      "name": "Soil_Dirt"
    },
    {
      "x": -22,
      "y": 1,
      "z": -6,
      "name": "Soil_Dirt"
    },
    {
      "x": -22,
      "y": 1,
      "z": -5,
      "name": "Soil_Dirt"
    },
    {
      "x": -22,
      "y": 1,
      "z": -4,
      "name": "Soil_Dirt"
    },
    {
      "x": -22,
      "y": 2,
      "z": -4,
      "name": "Soil_Pathway"
    },
    {
      "x": -22,
      "y": 1,
      "z": -3,
      "name": "Soil_Dirt"
    },
    {
      "x": -22,
      "y": 2,
      "z": -3,
      "name": "Soil_Pathway"
    },
    {
      "x": -22,
      "y": 1,
      "z": -2,
      "name": "Rock_Stone"
    },
    {
      "x": -22,
      "y": 2,
      "z": -2,
      "name": "Soil_Pathway"
    },
    {
      "x": -22,
      "y": 1,
      "z": -1,
      "name": "Rock_Stone"
    },
    {
      "x": -22,
      "y": 2,
      "z": -1,
      "name": "Soil_Pathway"
    },
    {
      "x": -22,
      "y": 1,
      "z": 0,
      "name": "Rock_Stone"
    },
    {
      "x": -22,
      "y": 2,
      "z": 0,
      "name": "Soil_Pathway"
    },
    {
      "x": -22,
      "y": 1,
      "z": 1,
      "name": "Rock_Stone"
    },
    {
      "x": -22,
      "y": 2,
      "z": 1,
      "name": "Soil_Pathway"
    },
    {
      "x": -22,
      "y": 1,
      "z": 2,
      "name": "Rock_Stone"
    },
    {
      "x": -22,
      "y": 2,
      "z": 2,
      "name": "Soil_Pathway"
    },
    {
      "x": -22,
      "y": 1,
      "z": 3,
      "name": "Soil_Dirt"
    },
    {
      "x": -22,
      "y": 2,
      "z": 3,
      "name": "Soil_Pathway"
    },
    {
      "x": -22,
      "y": 1,
      "z": 4,
      "name": "Soil_Dirt"
    },
    {
      "x": -22,
      "y": 2,
      "z": 4,
      "name": "Soil_Pathway"
    },
    {
      "x": -22,
      "y": 1,
      "z": 5,
      "name": "Soil_Dirt"
    },
    {
      "x": -22,
      "y": 1,
      "z": 6,
      "name": "Soil_Dirt"
    },
    {
      "x": -22,
      "y": -3,
      "z": 7,
      "name": "Soil_Dirt"
    },
    {
      "x": -22,
      "y": -2,
      "z": 7,
      "name": "Soil_Dirt"
    },
    {
      "x": -22,
      "y": -1,
      "z": 7,
      "name": "Soil_Dirt"
    },
    {
      "x": -22,
      "y": 1,
      "z": 7,
      "name": "Soil_Dirt"
    },
    {
      "x": -22,
      "y": -3,
      "z": 8,
      "name": "Soil_Dirt"
    },
    {
      "x": -22,
      "y": -2,
      "z": 8,
      "name": "Soil_Dirt"
    },
    {
      "x": -22,
      "y": -1,
      "z": 8,
      "name": "Soil_Dirt"
    },
    {
      "x": -22,
      "y": 0,
      "z": 8,
      "name": "Soil_Dirt"
    },
    {
      "x": -22,
      "y": 1,
      "z": 8,
      "name": "Soil_Dirt"
    },
    {
      "x": -22,
      "y": -3,
      "z": 9,
      "name": "Soil_Dirt"
    },
    {
      "x": -22,
      "y": -2,
      "z": 9,
      "name": "Soil_Dirt"
    },
    {
      "x": -22,
      "y": -1,
      "z": 9,
      "name": "Soil_Dirt"
    },
    {
      "x": -22,
      "y": 1,
      "z": 9,
      "name": "Soil_Dirt"
    },
    {
      "x": -22,
      "y": 1,
      "z": 10,
      "name": "Soil_Dirt"
    },
    {
      "x": -22,
      "y": -3,
      "z": 11,
      "name": "Soil_Dirt"
    },
    {
      "x": -22,
      "y": -2,
      "z": 11,
      "name": "Soil_Dirt"
    },
    {
      "x": -22,
      "y": -1,
      "z": 11,
      "name": "Soil_Dirt"
    },
    {
      "x": -22,
      "y": 1,
      "z": 11,
      "name": "Soil_Dirt"
    },
    {
      "x": -22,
      "y": -3,
      "z": 12,
      "name": "Soil_Dirt"
    },
    {
      "x": -22,
      "y": -2,
      "z": 12,
      "name": "Soil_Dirt"
    },
    {
      "x": -22,
      "y": -1,
      "z": 12,
      "name": "Soil_Dirt"
    },
    {
      "x": -22,
      "y": 0,
      "z": 12,
      "name": "Soil_Dirt"
    },
    {
      "x": -22,
      "y": 1,
      "z": 12,
      "name": "Soil_Dirt"
    },
    {
      "x": -22,
      "y": -3,
      "z": 13,
      "name": "Soil_Dirt"
    },
    {
      "x": -22,
      "y": -2,
      "z": 13,
      "name": "Soil_Dirt"
    },
    {
      "x": -22,
      "y": -1,
      "z": 13,
      "name": "Soil_Dirt"
    },
    {
      "x": -22,
      "y": 1,
      "z": 13,
      "name": "Soil_Dirt"
    },
    {
      "x": -22,
      "y": -3,
      "z": 14,
      "name": "Soil_Dirt"
    },
    {
      "x": -22,
      "y": -2,
      "z": 14,
      "name": "Soil_Dirt"
    },
    {
      "x": -22,
      "y": -1,
      "z": 14,
      "name": "Soil_Dirt"
    },
    {
      "x": -22,
      "y": 0,
      "z": 14,
      "name": "Soil_Dirt"
    },
    {
      "x": -22,
      "y": 1,
      "z": 14,
      "name": "Soil_Dirt"
    },
    {
      "x": -22,
      "y": -1,
      "z": 15,
      "name": "Soil_Dirt"
    },
    {
      "x": -22,
      "y": 0,
      "z": 15,
      "name": "Soil_Dirt"
    },
    {
      "x": -22,
      "y": 1,
      "z": 15,
      "name": "Soil_Dirt"
    },
    {
      "x": -22,
      "y": -3,
      "z": 16,
      "name": "Soil_Dirt"
    },
    {
      "x": -22,
      "y": -2,
      "z": 16,
      "name": "Soil_Dirt"
    },
    {
      "x": -22,
      "y": -1,
      "z": 16,
      "name": "Soil_Dirt"
    },
    {
      "x": -22,
      "y": 0,
      "z": 16,
      "name": "Soil_Dirt"
    },
    {
      "x": -22,
      "y": 1,
      "z": 16,
      "name": "Soil_Dirt"
    },
    {
      "x": -22,
      "y": -3,
      "z": 17,
      "name": "Soil_Dirt"
    },
    {
      "x": -22,
      "y": -2,
      "z": 17,
      "name": "Soil_Dirt"
    },
    {
      "x": -22,
      "y": -1,
      "z": 17,
      "name": "Soil_Dirt"
    },
    {
      "x": -21,
      "y": -3,
      "z": -19,
      "name": "Soil_Dirt"
    },
    {
      "x": -21,
      "y": -2,
      "z": -19,
      "name": "Soil_Dirt"
    },
    {
      "x": -21,
      "y": -1,
      "z": -19,
      "name": "Soil_Dirt"
    },
    {
      "x": -21,
      "y": 0,
      "z": -19,
      "name": "Soil_Dirt"
    },
    {
      "x": -21,
      "y": -1,
      "z": -18,
      "name": "Soil_Dirt"
    },
    {
      "x": -21,
      "y": 0,
      "z": -18,
      "name": "Soil_Dirt"
    },
    {
      "x": -21,
      "y": 1,
      "z": -18,
      "name": "Soil_Dirt"
    },
    {
      "x": -21,
      "y": 1,
      "z": -17,
      "name": "Soil_Dirt"
    },
    {
      "x": -21,
      "y": -1,
      "z": -16,
      "name": "Soil_Dirt"
    },
    {
      "x": -21,
      "y": 0,
      "z": -16,
      "name": "Soil_Dirt"
    },
    {
      "x": -21,
      "y": 1,
      "z": -16,
      "name": "Soil_Dirt"
    },
    {
      "x": -21,
      "y": -3,
      "z": -15,
      "name": "Soil_Dirt"
    },
    {
      "x": -21,
      "y": -2,
      "z": -15,
      "name": "Soil_Dirt"
    },
    {
      "x": -21,
      "y": -1,
      "z": -15,
      "name": "Soil_Dirt"
    },
    {
      "x": -21,
      "y": 0,
      "z": -15,
      "name": "Soil_Dirt"
    },
    {
      "x": -21,
      "y": 1,
      "z": -15,
      "name": "Soil_Dirt"
    },
    {
      "x": -21,
      "y": -1,
      "z": -14,
      "name": "Soil_Dirt"
    },
    {
      "x": -21,
      "y": 0,
      "z": -14,
      "name": "Soil_Dirt"
    },
    {
      "x": -21,
      "y": 1,
      "z": -14,
      "name": "Soil_Dirt"
    },
    {
      "x": -21,
      "y": 1,
      "z": -13,
      "name": "Soil_Dirt"
    },
    {
      "x": -21,
      "y": -1,
      "z": -12,
      "name": "Soil_Dirt"
    },
    {
      "x": -21,
      "y": 0,
      "z": -12,
      "name": "Soil_Dirt"
    },
    {
      "x": -21,
      "y": 1,
      "z": -12,
      "name": "Soil_Dirt"
    },
    {
      "x": -21,
      "y": -3,
      "z": -11,
      "name": "Soil_Dirt"
    },
    {
      "x": -21,
      "y": -2,
      "z": -11,
      "name": "Soil_Dirt"
    },
    {
      "x": -21,
      "y": -1,
      "z": -11,
      "name": "Soil_Dirt"
    },
    {
      "x": -21,
      "y": 0,
      "z": -11,
      "name": "Soil_Dirt"
    },
    {
      "x": -21,
      "y": 1,
      "z": -11,
      "name": "Soil_Dirt"
    },
    {
      "x": -21,
      "y": 1,
      "z": -10,
      "name": "Soil_Dirt"
    },
    {
      "x": -21,
      "y": 1,
      "z": -9,
      "name": "Soil_Dirt"
    },
    {
      "x": -21,
      "y": 1,
      "z": -8,
      "name": "Soil_Dirt"
    },
    {
      "x": -21,
      "y": 1,
      "z": -7,
      "name": "Soil_Dirt"
    },
    {
      "x": -21,
      "y": 2,
      "z": -7,
      "name": "Soil_Pathway"
    },
    {
      "x": -21,
      "y": 1,
      "z": -6,
      "name": "Rock_Stone"
    },
    {
      "x": -21,
      "y": 2,
      "z": -6,
      "name": "Soil_Pathway"
    },
    {
      "x": -21,
      "y": 1,
      "z": -5,
      "name": "Rock_Stone"
    },
    {
      "x": -21,
      "y": 2,
      "z": -5,
      "name": "Soil_Pathway"
    },
    {
      "x": -21,
      "y": 1,
      "z": -4,
      "name": "Rock_Stone"
    },
    {
      "x": -21,
      "y": 2,
      "z": -4,
      "name": "Soil_Pathway"
    },
    {
      "x": -21,
      "y": 0,
      "z": -3,
      "name": "Rock_Stone"
    },
    {
      "x": -21,
      "y": 1,
      "z": -3,
      "name": "Rock_Stone"
    },
    {
      "x": -21,
      "y": 2,
      "z": -3,
      "name": "Soil_Pathway"
    },
    {
      "x": -21,
      "y": 0,
      "z": -2,
      "name": "Rock_Stone"
    },
    {
      "x": -21,
      "y": 1,
      "z": -2,
      "name": "Rock_Stone"
    },
    {
      "x": -21,
      "y": 2,
      "z": -2,
      "name": "Soil_Pathway"
    },
    {
      "x": -21,
      "y": 0,
      "z": -1,
      "name": "Rock_Stone"
    },
    {
      "x": -21,
      "y": 1,
      "z": -1,
      "name": "Rock_Stone"
    },
    {
      "x": -21,
      "y": 2,
      "z": -1,
      "name": "Soil_Pathway"
    },
    {
      "x": -21,
      "y": 0,
      "z": 0,
      "name": "Rock_Stone"
    },
    {
      "x": -21,
      "y": 1,
      "z": 0,
      "name": "Rock_Stone"
    },
    {
      "x": -21,
      "y": 2,
      "z": 0,
      "name": "Soil_Pathway"
    },
    {
      "x": -21,
      "y": 0,
      "z": 1,
      "name": "Rock_Stone"
    },
    {
      "x": -21,
      "y": 1,
      "z": 1,
      "name": "Rock_Stone"
    },
    {
      "x": -21,
      "y": 2,
      "z": 1,
      "name": "Soil_Pathway"
    },
    {
      "x": -21,
      "y": 0,
      "z": 2,
      "name": "Rock_Stone"
    },
    {
      "x": -21,
      "y": 1,
      "z": 2,
      "name": "Rock_Stone"
    },
    {
      "x": -21,
      "y": 2,
      "z": 2,
      "name": "Soil_Pathway"
    },
    {
      "x": -21,
      "y": 0,
      "z": 3,
      "name": "Rock_Stone"
    },
    {
      "x": -21,
      "y": 1,
      "z": 3,
      "name": "Rock_Stone"
    },
    {
      "x": -21,
      "y": 2,
      "z": 3,
      "name": "Soil_Pathway"
    },
    {
      "x": -21,
      "y": 1,
      "z": 4,
      "name": "Rock_Stone"
    },
    {
      "x": -21,
      "y": 2,
      "z": 4,
      "name": "Soil_Pathway"
    },
    {
      "x": -21,
      "y": 1,
      "z": 5,
      "name": "Rock_Stone"
    },
    {
      "x": -21,
      "y": 2,
      "z": 5,
      "name": "Soil_Pathway"
    },
    {
      "x": -21,
      "y": 1,
      "z": 6,
      "name": "Rock_Stone"
    },
    {
      "x": -21,
      "y": 2,
      "z": 6,
      "name": "Soil_Pathway"
    },
    {
      "x": -21,
      "y": 1,
      "z": 7,
      "name": "Soil_Dirt"
    },
    {
      "x": -21,
      "y": 2,
      "z": 7,
      "name": "Soil_Pathway"
    },
    {
      "x": -21,
      "y": 1,
      "z": 8,
      "name": "Soil_Dirt"
    },
    {
      "x": -21,
      "y": 1,
      "z": 9,
      "name": "Soil_Dirt"
    },
    {
      "x": -21,
      "y": 1,
      "z": 10,
      "name": "Soil_Dirt"
    },
    {
      "x": -21,
      "y": 1,
      "z": 11,
      "name": "Soil_Dirt"
    },
    {
      "x": -21,
      "y": 1,
      "z": 12,
      "name": "Soil_Dirt"
    },
    {
      "x": -21,
      "y": -3,
      "z": 13,
      "name": "Soil_Dirt"
    },
    {
      "x": -21,
      "y": -2,
      "z": 13,
      "name": "Soil_Dirt"
    },
    {
      "x": -21,
      "y": -1,
      "z": 13,
      "name": "Soil_Dirt"
    },
    {
      "x": -21,
      "y": 0,
      "z": 13,
      "name": "Soil_Dirt"
    },
    {
      "x": -21,
      "y": 1,
      "z": 13,
      "name": "Soil_Dirt"
    },
    {
      "x": -21,
      "y": -1,
      "z": 14,
      "name": "Soil_Dirt"
    },
    {
      "x": -21,
      "y": 0,
      "z": 14,
      "name": "Soil_Dirt"
    },
    {
      "x": -21,
      "y": 1,
      "z": 14,
      "name": "Soil_Dirt"
    },
    {
      "x": -21,
      "y": 1,
      "z": 15,
      "name": "Soil_Dirt"
    },
    {
      "x": -21,
      "y": -1,
      "z": 16,
      "name": "Soil_Dirt"
    },
    {
      "x": -21,
      "y": 0,
      "z": 16,
      "name": "Soil_Dirt"
    },
    {
      "x": -21,
      "y": 1,
      "z": 16,
      "name": "Soil_Dirt"
    },
    {
      "x": -21,
      "y": -3,
      "z": 17,
      "name": "Soil_Dirt"
    },
    {
      "x": -21,
      "y": -2,
      "z": 17,
      "name": "Soil_Dirt"
    },
    {
      "x": -21,
      "y": -1,
      "z": 17,
      "name": "Soil_Dirt"
    },
    {
      "x": -21,
      "y": 0,
      "z": 17,
      "name": "Soil_Dirt"
    },
    {
      "x": -20,
      "y": -3,
      "z": -20,
      "name": "Soil_Dirt"
    },
    {
      "x": -20,
      "y": -2,
      "z": -20,
      "name": "Soil_Dirt"
    },
    {
      "x": -20,
      "y": -1,
      "z": -20,
      "name": "Soil_Dirt"
    },
    {
      "x": -20,
      "y": -3,
      "z": -19,
      "name": "Soil_Dirt"
    },
    {
      "x": -20,
      "y": -2,
      "z": -19,
      "name": "Soil_Dirt"
    },
    {
      "x": -20,
      "y": -1,
      "z": -19,
      "name": "Soil_Dirt"
    },
    {
      "x": -20,
      "y": 0,
      "z": -19,
      "name": "Soil_Dirt"
    },
    {
      "x": -20,
      "y": -3,
      "z": -18,
      "name": "Soil_Dirt"
    },
    {
      "x": -20,
      "y": -2,
      "z": -18,
      "name": "Soil_Dirt"
    },
    {
      "x": -20,
      "y": -1,
      "z": -18,
      "name": "Soil_Dirt"
    },
    {
      "x": -20,
      "y": 0,
      "z": -18,
      "name": "Soil_Dirt"
    },
    {
      "x": -20,
      "y": 1,
      "z": -18,
      "name": "Soil_Dirt"
    },
    {
      "x": -20,
      "y": -1,
      "z": -17,
      "name": "Soil_Dirt"
    },
    {
      "x": -20,
      "y": 0,
      "z": -17,
      "name": "Soil_Dirt"
    },
    {
      "x": -20,
      "y": 1,
      "z": -17,
      "name": "Soil_Dirt"
    },
    {
      "x": -20,
      "y": -3,
      "z": -16,
      "name": "Soil_Dirt"
    },
    {
      "x": -20,
      "y": -2,
      "z": -16,
      "name": "Soil_Dirt"
    },
    {
      "x": -20,
      "y": -1,
      "z": -16,
      "name": "Soil_Dirt"
    },
    {
      "x": -20,
      "y": 0,
      "z": -16,
      "name": "Soil_Dirt"
    },
    {
      "x": -20,
      "y": 1,
      "z": -16,
      "name": "Soil_Dirt"
    },
    {
      "x": -20,
      "y": -3,
      "z": -15,
      "name": "Soil_Dirt"
    },
    {
      "x": -20,
      "y": -2,
      "z": -15,
      "name": "Soil_Dirt"
    },
    {
      "x": -20,
      "y": -1,
      "z": -15,
      "name": "Soil_Dirt"
    },
    {
      "x": -20,
      "y": 1,
      "z": -15,
      "name": "Soil_Dirt"
    },
    {
      "x": -20,
      "y": -3,
      "z": -14,
      "name": "Soil_Dirt"
    },
    {
      "x": -20,
      "y": -2,
      "z": -14,
      "name": "Soil_Dirt"
    },
    {
      "x": -20,
      "y": -1,
      "z": -14,
      "name": "Soil_Dirt"
    },
    {
      "x": -20,
      "y": 0,
      "z": -14,
      "name": "Soil_Dirt"
    },
    {
      "x": -20,
      "y": 1,
      "z": -14,
      "name": "Soil_Dirt"
    },
    {
      "x": -20,
      "y": -1,
      "z": -13,
      "name": "Soil_Dirt"
    },
    {
      "x": -20,
      "y": 0,
      "z": -13,
      "name": "Soil_Dirt"
    },
    {
      "x": -20,
      "y": 1,
      "z": -13,
      "name": "Soil_Dirt"
    },
    {
      "x": -20,
      "y": -3,
      "z": -12,
      "name": "Soil_Dirt"
    },
    {
      "x": -20,
      "y": -2,
      "z": -12,
      "name": "Soil_Dirt"
    },
    {
      "x": -20,
      "y": -1,
      "z": -12,
      "name": "Soil_Dirt"
    },
    {
      "x": -20,
      "y": 0,
      "z": -12,
      "name": "Soil_Dirt"
    },
    {
      "x": -20,
      "y": 1,
      "z": -12,
      "name": "Soil_Dirt"
    },
    {
      "x": -20,
      "y": -3,
      "z": -11,
      "name": "Soil_Dirt"
    },
    {
      "x": -20,
      "y": -2,
      "z": -11,
      "name": "Soil_Dirt"
    },
    {
      "x": -20,
      "y": -1,
      "z": -11,
      "name": "Soil_Dirt"
    },
    {
      "x": -20,
      "y": 1,
      "z": -11,
      "name": "Soil_Dirt"
    },
    {
      "x": -20,
      "y": 1,
      "z": -10,
      "name": "Soil_Dirt"
    },
    {
      "x": -20,
      "y": 2,
      "z": -10,
      "name": "Soil_Pathway"
    },
    {
      "x": -20,
      "y": 1,
      "z": -9,
      "name": "Rock_Stone"
    },
    {
      "x": -20,
      "y": 2,
      "z": -9,
      "name": "Soil_Pathway"
    },
    {
      "x": -20,
      "y": 1,
      "z": -8,
      "name": "Rock_Stone"
    },
    {
      "x": -20,
      "y": 2,
      "z": -8,
      "name": "Soil_Pathway"
    },
    {
      "x": -20,
      "y": 0,
      "z": -7,
      "name": "Rock_Stone"
    },
    {
      "x": -20,
      "y": 1,
      "z": -7,
      "name": "Rock_Stone"
    },
    {
      "x": -20,
      "y": 2,
      "z": -7,
      "name": "Soil_Pathway"
    },
    {
      "x": -20,
      "y": 7,
      "z": -7,
      "name": "Wood_Torch_Wall",
      "rotation": 3
    },
    {
      "x": -20,
      "y": 10,
      "z": -7,
      "name": "Wood_Oak_Branch_Long",
      "support": 15,
      "rotation": 5
    },
    {
      "x": -20,
      "y": 0,
      "z": -6,
      "name": "Rock_Stone"
    },
    {
      "x": -20,
      "y": 1,
      "z": -6,
      "name": "Rock_Stone"
    },
    {
      "x": -20,
      "y": 2,
      "z": -6,
      "name": "Soil_Pathway"
    },
    {
      "x": -20,
      "y": 0,
      "z": -5,
      "name": "Rock_Stone"
    },
    {
      "x": -20,
      "y": 1,
      "z": -5,
      "name": "Rock_Stone"
    },
    {
      "x": -20,
      "y": 2,
      "z": -5,
      "name": "Soil_Pathway"
    },
    {
      "x": -20,
      "y": 0,
      "z": -4,
      "name": "Rock_Stone"
    },
    {
      "x": -20,
      "y": 1,
      "z": -4,
      "name": "Rock_Stone"
    },
    {
      "x": -20,
      "y": 2,
      "z": -4,
      "name": "Rock_Stone"
    },
    {
      "x": -20,
      "y": 3,
      "z": -4,
      "name": "Soil_Pathway"
    },
    {
      "x": -20,
      "y": 5,
      "z": -4,
      "name": "Empty"
    },
    {
      "x": -20,
      "y": 6,
      "z": -4,
      "name": "Empty"
    },
    {
      "x": -20,
      "y": 7,
      "z": -4,
      "name": "Empty"
    },
    {
      "x": -20,
      "y": 8,
      "z": -4,
      "name": "Empty"
    },
    {
      "x": -20,
      "y": 9,
      "z": -4,
      "name": "Empty"
    },
    {
      "x": -20,
      "y": 10,
      "z": -4,
      "name": "Empty"
    },
    {
      "x": -20,
      "y": 11,
      "z": -4,
      "name": "Empty"
    },
    {
      "x": -20,
      "y": 12,
      "z": -4,
      "name": "Empty"
    },
    {
      "x": -20,
      "y": 13,
      "z": -4,
      "name": "Empty"
    },
    {
      "x": -20,
      "y": 14,
      "z": -4,
      "name": "Empty"
    },
    {
      "x": -20,
      "y": 15,
      "z": -4,
      "name": "Empty"
    },
    {
      "x": -20,
      "y": 16,
      "z": -4,
      "name": "Empty"
    },
    {
      "x": -20,
      "y": 17,
      "z": -4,
      "name": "Empty"
    },
    {
      "x": -20,
      "y": 18,
      "z": -4,
      "name": "Empty"
    },
    {
      "x": -20,
      "y": 0,
      "z": -3,
      "name": "Rock_Stone"
    },
    {
      "x": -20,
      "y": 1,
      "z": -3,
      "name": "Rock_Stone"
    },
    {
      "x": -20,
      "y": 2,
      "z": -3,
      "name": "Rock_Stone"
    },
    {
      "x": -20,
      "y": 3,
      "z": -3,
      "name": "Soil_Pathway"
    },
    {
      "x": -20,
      "y": 5,
      "z": -3,
      "name": "Empty"
    },
    {
      "x": -20,
      "y": 6,
      "z": -3,
      "name": "Empty"
    },
    {
      "x": -20,
      "y": 7,
      "z": -3,
      "name": "Empty"
    },
    {
      "x": -20,
      "y": 8,
      "z": -3,
      "name": "Empty"
    },
    {
      "x": -20,
      "y": 9,
      "z": -3,
      "name": "Empty"
    },
    {
      "x": -20,
      "y": 10,
      "z": -3,
      "name": "Empty"
    },
    {
      "x": -20,
      "y": 11,
      "z": -3,
      "name": "Empty"
    },
    {
      "x": -20,
      "y": 12,
      "z": -3,
      "name": "Empty"
    },
    {
      "x": -20,
      "y": 13,
      "z": -3,
      "name": "Empty"
    },
    {
      "x": -20,
      "y": 14,
      "z": -3,
      "name": "Empty"
    },
    {
      "x": -20,
      "y": 15,
      "z": -3,
      "name": "Empty"
    },
    {
      "x": -20,
      "y": 16,
      "z": -3,
      "name": "Empty"
    },
    {
      "x": -20,
      "y": 17,
      "z": -3,
      "name": "Empty"
    },
    {
      "x": -20,
      "y": 18,
      "z": -3,
      "name": "Empty"
    },
    {
      "x": -20,
      "y": 0,
      "z": -2,
      "name": "Rock_Stone"
    },
    {
      "x": -20,
      "y": 1,
      "z": -2,
      "name": "Rock_Stone"
    },
    {
      "x": -20,
      "y": 2,
      "z": -2,
      "name": "Rock_Stone"
    },
    {
      "x": -20,
      "y": 3,
      "z": -2,
      "name": "Soil_Pathway"
    },
    {
      "x": -20,
      "y": 5,
      "z": -2,
      "name": "Empty"
    },
    {
      "x": -20,
      "y": 6,
      "z": -2,
      "name": "Empty"
    },
    {
      "x": -20,
      "y": 7,
      "z": -2,
      "name": "Empty"
    },
    {
      "x": -20,
      "y": 8,
      "z": -2,
      "name": "Empty"
    },
    {
      "x": -20,
      "y": 9,
      "z": -2,
      "name": "Empty"
    },
    {
      "x": -20,
      "y": 10,
      "z": -2,
      "name": "Empty"
    },
    {
      "x": -20,
      "y": 11,
      "z": -2,
      "name": "Empty"
    },
    {
      "x": -20,
      "y": 12,
      "z": -2,
      "name": "Empty"
    },
    {
      "x": -20,
      "y": 13,
      "z": -2,
      "name": "Empty"
    },
    {
      "x": -20,
      "y": 14,
      "z": -2,
      "name": "Empty"
    },
    {
      "x": -20,
      "y": 15,
      "z": -2,
      "name": "Empty"
    },
    {
      "x": -20,
      "y": 16,
      "z": -2,
      "name": "Empty"
    },
    {
      "x": -20,
      "y": 17,
      "z": -2,
      "name": "Empty"
    },
    {
      "x": -20,
      "y": 18,
      "z": -2,
      "name": "Empty"
    },
    {
      "x": -20,
      "y": 0,
      "z": -1,
      "name": "Rock_Stone"
    },
    {
      "x": -20,
      "y": 1,
      "z": -1,
      "name": "Rock_Stone"
    },
    {
      "x": -20,
      "y": 2,
      "z": -1,
      "name": "Rock_Stone"
    },
    {
      "x": -20,
      "y": 3,
      "z": -1,
      "name": "Soil_Pathway"
    },
    {
      "x": -20,
      "y": 5,
      "z": -1,
      "name": "Empty"
    },
    {
      "x": -20,
      "y": 6,
      "z": -1,
      "name": "Empty"
    },
    {
      "x": -20,
      "y": 7,
      "z": -1,
      "name": "Empty"
    },
    {
      "x": -20,
      "y": 8,
      "z": -1,
      "name": "Empty"
    },
    {
      "x": -20,
      "y": 9,
      "z": -1,
      "name": "Empty"
    },
    {
      "x": -20,
      "y": 10,
      "z": -1,
      "name": "Empty"
    },
    {
      "x": -20,
      "y": 11,
      "z": -1,
      "name": "Empty"
    },
    {
      "x": -20,
      "y": 12,
      "z": -1,
      "name": "Empty"
    },
    {
      "x": -20,
      "y": 13,
      "z": -1,
      "name": "Empty"
    },
    {
      "x": -20,
      "y": 14,
      "z": -1,
      "name": "Empty"
    },
    {
      "x": -20,
      "y": 15,
      "z": -1,
      "name": "Empty"
    },
    {
      "x": -20,
      "y": 16,
      "z": -1,
      "name": "Empty"
    },
    {
      "x": -20,
      "y": 17,
      "z": -1,
      "name": "Empty"
    },
    {
      "x": -20,
      "y": 18,
      "z": -1,
      "name": "Empty"
    },
    {
      "x": -20,
      "y": 0,
      "z": 0,
      "name": "Rock_Stone"
    },
    {
      "x": -20,
      "y": 1,
      "z": 0,
      "name": "Rock_Stone"
    },
    {
      "x": -20,
      "y": 2,
      "z": 0,
      "name": "Rock_Stone"
    },
    {
      "x": -20,
      "y": 3,
      "z": 0,
      "name": "Soil_Pathway"
    },
    {
      "x": -20,
      "y": 5,
      "z": 0,
      "name": "Empty"
    },
    {
      "x": -20,
      "y": 6,
      "z": 0,
      "name": "Empty"
    },
    {
      "x": -20,
      "y": 7,
      "z": 0,
      "name": "Empty"
    },
    {
      "x": -20,
      "y": 8,
      "z": 0,
      "name": "Empty"
    },
    {
      "x": -20,
      "y": 9,
      "z": 0,
      "name": "Empty"
    },
    {
      "x": -20,
      "y": 10,
      "z": 0,
      "name": "Wood_Oak_Branch_Long",
      "support": 15,
      "rotation": 5
    },
    {
      "x": -20,
      "y": 11,
      "z": 0,
      "name": "Empty"
    },
    {
      "x": -20,
      "y": 12,
      "z": 0,
      "name": "Empty"
    },
    {
      "x": -20,
      "y": 13,
      "z": 0,
      "name": "Empty"
    },
    {
      "x": -20,
      "y": 14,
      "z": 0,
      "name": "Empty"
    },
    {
      "x": -20,
      "y": 15,
      "z": 0,
      "name": "Empty"
    },
    {
      "x": -20,
      "y": 16,
      "z": 0,
      "name": "Empty"
    },
    {
      "x": -20,
      "y": 17,
      "z": 0,
      "name": "Empty"
    },
    {
      "x": -20,
      "y": 18,
      "z": 0,
      "name": "Empty"
    },
    {
      "x": -20,
      "y": 0,
      "z": 1,
      "name": "Rock_Stone"
    },
    {
      "x": -20,
      "y": 1,
      "z": 1,
      "name": "Rock_Stone"
    },
    {
      "x": -20,
      "y": 2,
      "z": 1,
      "name": "Rock_Stone"
    },
    {
      "x": -20,
      "y": 3,
      "z": 1,
      "name": "Soil_Pathway"
    },
    {
      "x": -20,
      "y": 5,
      "z": 1,
      "name": "Empty"
    },
    {
      "x": -20,
      "y": 6,
      "z": 1,
      "name": "Empty"
    },
    {
      "x": -20,
      "y": 7,
      "z": 1,
      "name": "Empty"
    },
    {
      "x": -20,
      "y": 8,
      "z": 1,
      "name": "Empty"
    },
    {
      "x": -20,
      "y": 9,
      "z": 1,
      "name": "Empty"
    },
    {
      "x": -20,
      "y": 10,
      "z": 1,
      "name": "Empty"
    },
    {
      "x": -20,
      "y": 11,
      "z": 1,
      "name": "Empty"
    },
    {
      "x": -20,
      "y": 12,
      "z": 1,
      "name": "Empty"
    },
    {
      "x": -20,
      "y": 13,
      "z": 1,
      "name": "Empty"
    },
    {
      "x": -20,
      "y": 14,
      "z": 1,
      "name": "Empty"
    },
    {
      "x": -20,
      "y": 15,
      "z": 1,
      "name": "Empty"
    },
    {
      "x": -20,
      "y": 16,
      "z": 1,
      "name": "Empty"
    },
    {
      "x": -20,
      "y": 17,
      "z": 1,
      "name": "Empty"
    },
    {
      "x": -20,
      "y": 18,
      "z": 1,
      "name": "Empty"
    },
    {
      "x": -20,
      "y": 0,
      "z": 2,
      "name": "Rock_Stone"
    },
    {
      "x": -20,
      "y": 1,
      "z": 2,
      "name": "Rock_Stone"
    },
    {
      "x": -20,
      "y": 2,
      "z": 2,
      "name": "Rock_Stone"
    },
    {
      "x": -20,
      "y": 3,
      "z": 2,
      "name": "Soil_Pathway"
    },
    {
      "x": -20,
      "y": 5,
      "z": 2,
      "name": "Empty"
    },
    {
      "x": -20,
      "y": 6,
      "z": 2,
      "name": "Empty"
    },
    {
      "x": -20,
      "y": 7,
      "z": 2,
      "name": "Empty"
    },
    {
      "x": -20,
      "y": 8,
      "z": 2,
      "name": "Empty"
    },
    {
      "x": -20,
      "y": 9,
      "z": 2,
      "name": "Empty"
    },
    {
      "x": -20,
      "y": 10,
      "z": 2,
      "name": "Empty"
    },
    {
      "x": -20,
      "y": 11,
      "z": 2,
      "name": "Empty"
    },
    {
      "x": -20,
      "y": 12,
      "z": 2,
      "name": "Empty"
    },
    {
      "x": -20,
      "y": 13,
      "z": 2,
      "name": "Empty"
    },
    {
      "x": -20,
      "y": 14,
      "z": 2,
      "name": "Empty"
    },
    {
      "x": -20,
      "y": 15,
      "z": 2,
      "name": "Empty"
    },
    {
      "x": -20,
      "y": 16,
      "z": 2,
      "name": "Empty"
    },
    {
      "x": -20,
      "y": 17,
      "z": 2,
      "name": "Empty"
    },
    {
      "x": -20,
      "y": 18,
      "z": 2,
      "name": "Empty"
    },
    {
      "x": -20,
      "y": 0,
      "z": 3,
      "name": "Rock_Stone"
    },
    {
      "x": -20,
      "y": 1,
      "z": 3,
      "name": "Rock_Stone"
    },
    {
      "x": -20,
      "y": 2,
      "z": 3,
      "name": "Rock_Stone"
    },
    {
      "x": -20,
      "y": 3,
      "z": 3,
      "name": "Soil_Pathway"
    },
    {
      "x": -20,
      "y": 5,
      "z": 3,
      "name": "Empty"
    },
    {
      "x": -20,
      "y": 6,
      "z": 3,
      "name": "Empty"
    },
    {
      "x": -20,
      "y": 7,
      "z": 3,
      "name": "Empty"
    },
    {
      "x": -20,
      "y": 8,
      "z": 3,
      "name": "Empty"
    },
    {
      "x": -20,
      "y": 9,
      "z": 3,
      "name": "Empty"
    },
    {
      "x": -20,
      "y": 10,
      "z": 3,
      "name": "Empty"
    },
    {
      "x": -20,
      "y": 11,
      "z": 3,
      "name": "Empty"
    },
    {
      "x": -20,
      "y": 12,
      "z": 3,
      "name": "Empty"
    },
    {
      "x": -20,
      "y": 13,
      "z": 3,
      "name": "Empty"
    },
    {
      "x": -20,
      "y": 14,
      "z": 3,
      "name": "Empty"
    },
    {
      "x": -20,
      "y": 15,
      "z": 3,
      "name": "Empty"
    },
    {
      "x": -20,
      "y": 16,
      "z": 3,
      "name": "Empty"
    },
    {
      "x": -20,
      "y": 17,
      "z": 3,
      "name": "Empty"
    },
    {
      "x": -20,
      "y": 18,
      "z": 3,
      "name": "Empty"
    },
    {
      "x": -20,
      "y": 0,
      "z": 4,
      "name": "Rock_Stone"
    },
    {
      "x": -20,
      "y": 1,
      "z": 4,
      "name": "Rock_Stone"
    },
    {
      "x": -20,
      "y": 2,
      "z": 4,
      "name": "Rock_Stone"
    },
    {
      "x": -20,
      "y": 3,
      "z": 4,
      "name": "Soil_Pathway"
    },
    {
      "x": -20,
      "y": 5,
      "z": 4,
      "name": "Empty"
    },
    {
      "x": -20,
      "y": 6,
      "z": 4,
      "name": "Empty"
    },
    {
      "x": -20,
      "y": 7,
      "z": 4,
      "name": "Empty"
    },
    {
      "x": -20,
      "y": 8,
      "z": 4,
      "name": "Empty"
    },
    {
      "x": -20,
      "y": 9,
      "z": 4,
      "name": "Empty"
    },
    {
      "x": -20,
      "y": 10,
      "z": 4,
      "name": "Empty"
    },
    {
      "x": -20,
      "y": 11,
      "z": 4,
      "name": "Empty"
    },
    {
      "x": -20,
      "y": 12,
      "z": 4,
      "name": "Empty"
    },
    {
      "x": -20,
      "y": 13,
      "z": 4,
      "name": "Empty"
    },
    {
      "x": -20,
      "y": 14,
      "z": 4,
      "name": "Empty"
    },
    {
      "x": -20,
      "y": 15,
      "z": 4,
      "name": "Empty"
    },
    {
      "x": -20,
      "y": 16,
      "z": 4,
      "name": "Empty"
    },
    {
      "x": -20,
      "y": 17,
      "z": 4,
      "name": "Empty"
    },
    {
      "x": -20,
      "y": 18,
      "z": 4,
      "name": "Empty"
    },
    {
      "x": -20,
      "y": 0,
      "z": 5,
      "name": "Rock_Stone"
    },
    {
      "x": -20,
      "y": 1,
      "z": 5,
      "name": "Rock_Stone"
    },
    {
      "x": -20,
      "y": 2,
      "z": 5,
      "name": "Soil_Pathway"
    },
    {
      "x": -20,
      "y": 0,
      "z": 6,
      "name": "Rock_Stone"
    },
    {
      "x": -20,
      "y": 1,
      "z": 6,
      "name": "Rock_Stone"
    },
    {
      "x": -20,
      "y": 2,
      "z": 6,
      "name": "Soil_Pathway"
    },
    {
      "x": -20,
      "y": 0,
      "z": 7,
      "name": "Rock_Stone"
    },
    {
      "x": -20,
      "y": 1,
      "z": 7,
      "name": "Rock_Stone"
    },
    {
      "x": -20,
      "y": 2,
      "z": 7,
      "name": "Soil_Pathway"
    },
    {
      "x": -20,
      "y": 7,
      "z": 7,
      "name": "Wood_Torch_Wall",
      "rotation": 3
    },
    {
      "x": -20,
      "y": 10,
      "z": 7,
      "name": "Wood_Oak_Branch_Long",
      "support": 15,
      "rotation": 5
    },
    {
      "x": -20,
      "y": 1,
      "z": 8,
      "name": "Rock_Stone"
    },
    {
      "x": -20,
      "y": 2,
      "z": 8,
      "name": "Soil_Pathway"
    },
    {
      "x": -20,
      "y": 1,
      "z": 9,
      "name": "Rock_Stone"
    },
    {
      "x": -20,
      "y": 2,
      "z": 9,
      "name": "Soil_Pathway"
    },
    {
      "x": -20,
      "y": 1,
      "z": 10,
      "name": "Soil_Dirt"
    },
    {
      "x": -20,
      "y": 2,
      "z": 10,
      "name": "Soil_Pathway"
    },
    {
      "x": -20,
      "y": 1,
      "z": 11,
      "name": "Soil_Dirt"
    },
    {
      "x": -20,
      "y": 1,
      "z": 12,
      "name": "Soil_Dirt"
    },
    {
      "x": -20,
      "y": -3,
      "z": 13,
      "name": "Soil_Dirt"
    },
    {
      "x": -20,
      "y": -2,
      "z": 13,
      "name": "Soil_Dirt"
    },
    {
      "x": -20,
      "y": -1,
      "z": 13,
      "name": "Soil_Dirt"
    },
    {
      "x": -20,
      "y": 1,
      "z": 13,
      "name": "Soil_Dirt"
    },
    {
      "x": -20,
      "y": -3,
      "z": 14,
      "name": "Soil_Dirt"
    },
    {
      "x": -20,
      "y": -2,
      "z": 14,
      "name": "Soil_Dirt"
    },
    {
      "x": -20,
      "y": -1,
      "z": 14,
      "name": "Soil_Dirt"
    },
    {
      "x": -20,
      "y": 0,
      "z": 14,
      "name": "Soil_Dirt"
    },
    {
      "x": -20,
      "y": 1,
      "z": 14,
      "name": "Soil_Dirt"
    },
    {
      "x": -20,
      "y": -1,
      "z": 15,
      "name": "Soil_Dirt"
    },
    {
      "x": -20,
      "y": 0,
      "z": 15,
      "name": "Soil_Dirt"
    },
    {
      "x": -20,
      "y": 1,
      "z": 15,
      "name": "Soil_Dirt"
    },
    {
      "x": -20,
      "y": -3,
      "z": 16,
      "name": "Soil_Dirt"
    },
    {
      "x": -20,
      "y": -2,
      "z": 16,
      "name": "Soil_Dirt"
    },
    {
      "x": -20,
      "y": -1,
      "z": 16,
      "name": "Soil_Dirt"
    },
    {
      "x": -20,
      "y": 0,
      "z": 16,
      "name": "Soil_Dirt"
    },
    {
      "x": -20,
      "y": 1,
      "z": 16,
      "name": "Soil_Dirt"
    },
    {
      "x": -20,
      "y": -3,
      "z": 17,
      "name": "Soil_Dirt"
    },
    {
      "x": -20,
      "y": -2,
      "z": 17,
      "name": "Soil_Dirt"
    },
    {
      "x": -20,
      "y": -1,
      "z": 17,
      "name": "Soil_Dirt"
    },
    {
      "x": -19,
      "y": -3,
      "z": -21,
      "name": "Soil_Dirt"
    },
    {
      "x": -19,
      "y": -2,
      "z": -21,
      "name": "Soil_Dirt"
    },
    {
      "x": -19,
      "y": -1,
      "z": -21,
      "name": "Soil_Dirt"
    },
    {
      "x": -19,
      "y": -3,
      "z": -20,
      "name": "Soil_Dirt"
    },
    {
      "x": -19,
      "y": -2,
      "z": -20,
      "name": "Soil_Dirt"
    },
    {
      "x": -19,
      "y": -1,
      "z": -20,
      "name": "Soil_Dirt"
    },
    {
      "x": -19,
      "y": 0,
      "z": -20,
      "name": "Soil_Dirt"
    },
    {
      "x": -19,
      "y": 1,
      "z": -20,
      "name": "Soil_Dirt"
    },
    {
      "x": -19,
      "y": -1,
      "z": -19,
      "name": "Soil_Dirt"
    },
    {
      "x": -19,
      "y": 0,
      "z": -19,
      "name": "Soil_Dirt"
    },
    {
      "x": -19,
      "y": 1,
      "z": -19,
      "name": "Soil_Dirt"
    },
    {
      "x": -19,
      "y": -3,
      "z": -18,
      "name": "Soil_Dirt"
    },
    {
      "x": -19,
      "y": -2,
      "z": -18,
      "name": "Soil_Dirt"
    },
    {
      "x": -19,
      "y": -1,
      "z": -18,
      "name": "Soil_Dirt"
    },
    {
      "x": -19,
      "y": 0,
      "z": -18,
      "name": "Soil_Dirt"
    },
    {
      "x": -19,
      "y": 1,
      "z": -18,
      "name": "Soil_Dirt"
    },
    {
      "x": -19,
      "y": -3,
      "z": -17,
      "name": "Soil_Dirt"
    },
    {
      "x": -19,
      "y": -2,
      "z": -17,
      "name": "Soil_Dirt"
    },
    {
      "x": -19,
      "y": -1,
      "z": -17,
      "name": "Soil_Dirt"
    },
    {
      "x": -19,
      "y": 0,
      "z": -17,
      "name": "Soil_Dirt"
    },
    {
      "x": -19,
      "y": 1,
      "z": -17,
      "name": "Soil_Dirt"
    },
    {
      "x": -19,
      "y": -3,
      "z": -16,
      "name": "Soil_Dirt"
    },
    {
      "x": -19,
      "y": -2,
      "z": -16,
      "name": "Soil_Dirt"
    },
    {
      "x": -19,
      "y": -1,
      "z": -16,
      "name": "Soil_Dirt"
    },
    {
      "x": -19,
      "y": 1,
      "z": -16,
      "name": "Soil_Dirt"
    },
    {
      "x": -19,
      "y": 1,
      "z": -15,
      "name": "Soil_Dirt"
    },
    {
      "x": -19,
      "y": -3,
      "z": -14,
      "name": "Soil_Dirt"
    },
    {
      "x": -19,
      "y": -2,
      "z": -14,
      "name": "Soil_Dirt"
    },
    {
      "x": -19,
      "y": -1,
      "z": -14,
      "name": "Soil_Dirt"
    },
    {
      "x": -19,
      "y": 1,
      "z": -14,
      "name": "Soil_Dirt"
    },
    {
      "x": -19,
      "y": -3,
      "z": -13,
      "name": "Soil_Dirt"
    },
    {
      "x": -19,
      "y": -2,
      "z": -13,
      "name": "Soil_Dirt"
    },
    {
      "x": -19,
      "y": -1,
      "z": -13,
      "name": "Soil_Dirt"
    },
    {
      "x": -19,
      "y": 0,
      "z": -13,
      "name": "Soil_Dirt"
    },
    {
      "x": -19,
      "y": 1,
      "z": -13,
      "name": "Soil_Dirt"
    },
    {
      "x": -19,
      "y": -3,
      "z": -12,
      "name": "Soil_Dirt"
    },
    {
      "x": -19,
      "y": -2,
      "z": -12,
      "name": "Soil_Dirt"
    },
    {
      "x": -19,
      "y": -1,
      "z": -12,
      "name": "Soil_Dirt"
    },
    {
      "x": -19,
      "y": 1,
      "z": -12,
      "name": "Soil_Dirt"
    },
    {
      "x": -19,
      "y": 1,
      "z": -11,
      "name": "Rock_Stone"
    },
    {
      "x": -19,
      "y": 2,
      "z": -11,
      "name": "Soil_Pathway"
    },
    {
      "x": -19,
      "y": 1,
      "z": -10,
      "name": "Rock_Stone"
    },
    {
      "x": -19,
      "y": 2,
      "z": -10,
      "name": "Soil_Pathway"
    },
    {
      "x": -19,
      "y": 0,
      "z": -9,
      "name": "Rock_Stone"
    },
    {
      "x": -19,
      "y": 1,
      "z": -9,
      "name": "Rock_Stone"
    },
    {
      "x": -19,
      "y": 2,
      "z": -9,
      "name": "Soil_Pathway"
    },
    {
      "x": -19,
      "y": 0,
      "z": -8,
      "name": "Rock_Stone"
    },
    {
      "x": -19,
      "y": 1,
      "z": -8,
      "name": "Rock_Stone"
    },
    {
      "x": -19,
      "y": 2,
      "z": -8,
      "name": "Soil_Pathway"
    },
    {
      "x": -19,
      "y": 7,
      "z": -8,
      "name": "Deco_Bone_Ribs",
      "rotation": 2
    },
    {
      "x": -19,
      "y": 0,
      "z": -7,
      "name": "Rock_Stone"
    },
    {
      "x": -19,
      "y": 1,
      "z": -7,
      "name": "Rock_Stone"
    },
    {
      "x": -19,
      "y": 2,
      "z": -7,
      "name": "Rock_Stone"
    },
    {
      "x": -19,
      "y": 3,
      "z": -7,
      "name": "Soil_Pathway"
    },
    {
      "x": -19,
      "y": 5,
      "z": -7,
      "name": "Empty"
    },
    {
      "x": -19,
      "y": 6,
      "z": -7,
      "name": "Deco_Bone_Spine"
    },
    {
      "x": -19,
      "y": 7,
      "z": -7,
      "name": "Deco_Bone_Full"
    },
    {
      "x": -19,
      "y": 8,
      "z": -7,
      "name": "Deco_Iron_Chain_Small"
    },
    {
      "x": -19,
      "y": 9,
      "z": -7,
      "name": "Deco_Iron_Chain_Small"
    },
    {
      "x": -19,
      "y": 10,
      "z": -7,
      "name": "Wood_Oak_Trunk",
      "support": 15,
      "rotation": 5
    },
    {
      "x": -19,
      "y": 11,
      "z": -7,
      "name": "Cloth_Roof_Leather_Flat"
    },
    {
      "x": -19,
      "y": 12,
      "z": -7,
      "name": "Empty"
    },
    {
      "x": -19,
      "y": 13,
      "z": -7,
      "name": "Empty"
    },
    {
      "x": -19,
      "y": 14,
      "z": -7,
      "name": "Empty"
    },
    {
      "x": -19,
      "y": 15,
      "z": -7,
      "name": "Empty"
    },
    {
      "x": -19,
      "y": 16,
      "z": -7,
      "name": "Empty"
    },
    {
      "x": -19,
      "y": 17,
      "z": -7,
      "name": "Empty"
    },
    {
      "x": -19,
      "y": 18,
      "z": -7,
      "name": "Empty"
    },
    {
      "x": -19,
      "y": 0,
      "z": -6,
      "name": "Rock_Stone"
    },
    {
      "x": -19,
      "y": 1,
      "z": -6,
      "name": "Rock_Stone"
    },
    {
      "x": -19,
      "y": 2,
      "z": -6,
      "name": "Rock_Stone"
    },
    {
      "x": -19,
      "y": 3,
      "z": -6,
      "name": "Soil_Pathway"
    },
    {
      "x": -19,
      "y": 5,
      "z": -6,
      "name": "Empty"
    },
    {
      "x": -19,
      "y": 6,
      "z": -6,
      "name": "Empty"
    },
    {
      "x": -19,
      "y": 7,
      "z": -6,
      "name": "Deco_Bone_Ribs"
    },
    {
      "x": -19,
      "y": 8,
      "z": -6,
      "name": "Empty"
    },
    {
      "x": -19,
      "y": 9,
      "z": -6,
      "name": "Empty"
    },
    {
      "x": -19,
      "y": 10,
      "z": -6,
      "name": "Empty"
    },
    {
      "x": -19,
      "y": 11,
      "z": -6,
      "name": "Empty"
    },
    {
      "x": -19,
      "y": 12,
      "z": -6,
      "name": "Empty"
    },
    {
      "x": -19,
      "y": 13,
      "z": -6,
      "name": "Empty"
    },
    {
      "x": -19,
      "y": 14,
      "z": -6,
      "name": "Empty"
    },
    {
      "x": -19,
      "y": 15,
      "z": -6,
      "name": "Empty"
    },
    {
      "x": -19,
      "y": 16,
      "z": -6,
      "name": "Empty"
    },
    {
      "x": -19,
      "y": 17,
      "z": -6,
      "name": "Empty"
    },
    {
      "x": -19,
      "y": 18,
      "z": -6,
      "name": "Empty"
    },
    {
      "x": -19,
      "y": -1,
      "z": -5,
      "name": "Rock_Stone"
    },
    {
      "x": -19,
      "y": 0,
      "z": -5,
      "name": "Rock_Stone"
    },
    {
      "x": -19,
      "y": 1,
      "z": -5,
      "name": "Rock_Stone"
    },
    {
      "x": -19,
      "y": 2,
      "z": -5,
      "name": "Rock_Stone"
    },
    {
      "x": -19,
      "y": 3,
      "z": -5,
      "name": "Soil_Pathway"
    },
    {
      "x": -19,
      "y": 4,
      "z": -5,
      "name": "Halloween_Wagon",
      "filler": 992,
      "rotation": 1
    },
    {
      "x": -19,
      "y": 5,
      "z": -5,
      "name": "Ore_Copper_Stone"
    },
    {
      "x": -19,
      "y": 6,
      "z": -5,
      "name": "Empty"
    },
    {
      "x": -19,
      "y": 7,
      "z": -5,
      "name": "Empty"
    },
    {
      "x": -19,
      "y": 8,
      "z": -5,
      "name": "Empty"
    },
    {
      "x": -19,
      "y": 9,
      "z": -5,
      "name": "Empty"
    },
    {
      "x": -19,
      "y": 10,
      "z": -5,
      "name": "Empty"
    },
    {
      "x": -19,
      "y": 11,
      "z": -5,
      "name": "Empty"
    },
    {
      "x": -19,
      "y": 12,
      "z": -5,
      "name": "Empty"
    },
    {
      "x": -19,
      "y": 13,
      "z": -5,
      "name": "Empty"
    },
    {
      "x": -19,
      "y": 14,
      "z": -5,
      "name": "Empty"
    },
    {
      "x": -19,
      "y": 15,
      "z": -5,
      "name": "Empty"
    },
    {
      "x": -19,
      "y": 16,
      "z": -5,
      "name": "Empty"
    },
    {
      "x": -19,
      "y": 17,
      "z": -5,
      "name": "Empty"
    },
    {
      "x": -19,
      "y": 18,
      "z": -5,
      "name": "Empty"
    },
    {
      "x": -19,
      "y": -1,
      "z": -4,
      "name": "Rock_Stone"
    },
    {
      "x": -19,
      "y": 0,
      "z": -4,
      "name": "Rock_Stone"
    },
    {
      "x": -19,
      "y": 1,
      "z": -4,
      "name": "Rock_Stone"
    },
    {
      "x": -19,
      "y": 2,
      "z": -4,
      "name": "Rock_Stone"
    },
    {
      "x": -19,
      "y": 3,
      "z": -4,
      "name": "Soil_Pathway"
    },
    {
      "x": -19,
      "y": 4,
      "z": -4,
      "name": "Halloween_Wagon",
      "rotation": 1
    },
    {
      "x": -19,
      "y": 5,
      "z": -4,
      "name": "Ore_Iron_Stone"
    },
    {
      "x": -19,
      "y": 6,
      "z": -4,
      "name": "Empty"
    },
    {
      "x": -19,
      "y": 7,
      "z": -4,
      "name": "Empty"
    },
    {
      "x": -19,
      "y": 8,
      "z": -4,
      "name": "Empty"
    },
    {
      "x": -19,
      "y": 9,
      "z": -4,
      "name": "Empty"
    },
    {
      "x": -19,
      "y": 10,
      "z": -4,
      "name": "Empty"
    },
    {
      "x": -19,
      "y": 11,
      "z": -4,
      "name": "Empty"
    },
    {
      "x": -19,
      "y": 12,
      "z": -4,
      "name": "Empty"
    },
    {
      "x": -19,
      "y": 13,
      "z": -4,
      "name": "Empty"
    },
    {
      "x": -19,
      "y": 14,
      "z": -4,
      "name": "Empty"
    },
    {
      "x": -19,
      "y": 15,
      "z": -4,
      "name": "Empty"
    },
    {
      "x": -19,
      "y": 16,
      "z": -4,
      "name": "Empty"
    },
    {
      "x": -19,
      "y": 17,
      "z": -4,
      "name": "Empty"
    },
    {
      "x": -19,
      "y": 18,
      "z": -4,
      "name": "Empty"
    },
    {
      "x": -19,
      "y": -1,
      "z": -3,
      "name": "Rock_Stone"
    },
    {
      "x": -19,
      "y": 0,
      "z": -3,
      "name": "Rock_Stone"
    },
    {
      "x": -19,
      "y": 1,
      "z": -3,
      "name": "Rock_Stone"
    },
    {
      "x": -19,
      "y": 2,
      "z": -3,
      "name": "Rock_Stone"
    },
    {
      "x": -19,
      "y": 3,
      "z": -3,
      "name": "Soil_Pathway"
    },
    {
      "x": -19,
      "y": 4,
      "z": -3,
      "name": "Empty"
    },
    {
      "x": -19,
      "y": 5,
      "z": -3,
      "name": "Empty"
    },
    {
      "x": -19,
      "y": 6,
      "z": -3,
      "name": "Empty"
    },
    {
      "x": -19,
      "y": 7,
      "z": -3,
      "name": "Empty"
    },
    {
      "x": -19,
      "y": 8,
      "z": -3,
      "name": "Empty"
    },
    {
      "x": -19,
      "y": 9,
      "z": -3,
      "name": "Empty"
    },
    {
      "x": -19,
      "y": 10,
      "z": -3,
      "name": "Empty"
    },
    {
      "x": -19,
      "y": 11,
      "z": -3,
      "name": "Empty"
    },
    {
      "x": -19,
      "y": 12,
      "z": -3,
      "name": "Empty"
    },
    {
      "x": -19,
      "y": 13,
      "z": -3,
      "name": "Empty"
    },
    {
      "x": -19,
      "y": 14,
      "z": -3,
      "name": "Empty"
    },
    {
      "x": -19,
      "y": 15,
      "z": -3,
      "name": "Empty"
    },
    {
      "x": -19,
      "y": 16,
      "z": -3,
      "name": "Empty"
    },
    {
      "x": -19,
      "y": 17,
      "z": -3,
      "name": "Empty"
    },
    {
      "x": -19,
      "y": 18,
      "z": -3,
      "name": "Empty"
    },
    {
      "x": -19,
      "y": -1,
      "z": -2,
      "name": "Rock_Stone"
    },
    {
      "x": -19,
      "y": 0,
      "z": -2,
      "name": "Rock_Stone"
    },
    {
      "x": -19,
      "y": 1,
      "z": -2,
      "name": "Rock_Stone"
    },
    {
      "x": -19,
      "y": 2,
      "z": -2,
      "name": "Rock_Stone"
    },
    {
      "x": -19,
      "y": 3,
      "z": -2,
      "name": "Soil_Pathway"
    },
    {
      "x": -19,
      "y": 4,
      "z": -2,
      "name": "Empty"
    },
    {
      "x": -19,
      "y": 5,
      "z": -2,
      "name": "Empty"
    },
    {
      "x": -19,
      "y": 6,
      "z": -2,
      "name": "Empty"
    },
    {
      "x": -19,
      "y": 7,
      "z": -2,
      "name": "Empty"
    },
    {
      "x": -19,
      "y": 8,
      "z": -2,
      "name": "Empty"
    },
    {
      "x": -19,
      "y": 9,
      "z": -2,
      "name": "Empty"
    },
    {
      "x": -19,
      "y": 10,
      "z": -2,
      "name": "Empty"
    },
    {
      "x": -19,
      "y": 11,
      "z": -2,
      "name": "Empty"
    },
    {
      "x": -19,
      "y": 12,
      "z": -2,
      "name": "Empty"
    },
    {
      "x": -19,
      "y": 13,
      "z": -2,
      "name": "Empty"
    },
    {
      "x": -19,
      "y": 14,
      "z": -2,
      "name": "Empty"
    },
    {
      "x": -19,
      "y": 15,
      "z": -2,
      "name": "Empty"
    },
    {
      "x": -19,
      "y": 16,
      "z": -2,
      "name": "Empty"
    },
    {
      "x": -19,
      "y": 17,
      "z": -2,
      "name": "Empty"
    },
    {
      "x": -19,
      "y": 18,
      "z": -2,
      "name": "Empty"
    },
    {
      "x": -19,
      "y": -1,
      "z": -1,
      "name": "Rock_Stone"
    },
    {
      "x": -19,
      "y": 0,
      "z": -1,
      "name": "Rock_Stone"
    },
    {
      "x": -19,
      "y": 1,
      "z": -1,
      "name": "Rock_Stone"
    },
    {
      "x": -19,
      "y": 2,
      "z": -1,
      "name": "Rock_Stone"
    },
    {
      "x": -19,
      "y": 3,
      "z": -1,
      "name": "Soil_Pathway"
    },
    {
      "x": -19,
      "y": 4,
      "z": -1,
      "name": "Empty"
    },
    {
      "x": -19,
      "y": 5,
      "z": -1,
      "name": "Empty"
    },
    {
      "x": -19,
      "y": 6,
      "z": -1,
      "name": "Empty"
    },
    {
      "x": -19,
      "y": 7,
      "z": -1,
      "name": "Empty"
    },
    {
      "x": -19,
      "y": 8,
      "z": -1,
      "name": "Empty"
    },
    {
      "x": -19,
      "y": 9,
      "z": -1,
      "name": "Empty"
    },
    {
      "x": -19,
      "y": 10,
      "z": -1,
      "name": "Empty"
    },
    {
      "x": -19,
      "y": 11,
      "z": -1,
      "name": "Empty"
    },
    {
      "x": -19,
      "y": 12,
      "z": -1,
      "name": "Empty"
    },
    {
      "x": -19,
      "y": 13,
      "z": -1,
      "name": "Empty"
    },
    {
      "x": -19,
      "y": 14,
      "z": -1,
      "name": "Empty"
    },
    {
      "x": -19,
      "y": 15,
      "z": -1,
      "name": "Empty"
    },
    {
      "x": -19,
      "y": 16,
      "z": -1,
      "name": "Empty"
    },
    {
      "x": -19,
      "y": 17,
      "z": -1,
      "name": "Empty"
    },
    {
      "x": -19,
      "y": 18,
      "z": -1,
      "name": "Empty"
    },
    {
      "x": -19,
      "y": -1,
      "z": 0,
      "name": "Rock_Stone"
    },
    {
      "x": -19,
      "y": 0,
      "z": 0,
      "name": "Rock_Stone"
    },
    {
      "x": -19,
      "y": 1,
      "z": 0,
      "name": "Rock_Stone"
    },
    {
      "x": -19,
      "y": 2,
      "z": 0,
      "name": "Rock_Stone"
    },
    {
      "x": -19,
      "y": 3,
      "z": 0,
      "name": "Soil_Pathway"
    },
    {
      "x": -19,
      "y": 4,
      "z": 0,
      "name": "Empty"
    },
    {
      "x": -19,
      "y": 5,
      "z": 0,
      "name": "Empty"
    },
    {
      "x": -19,
      "y": 6,
      "z": 0,
      "name": "Empty"
    },
    {
      "x": -19,
      "y": 7,
      "z": 0,
      "name": "Empty"
    },
    {
      "x": -19,
      "y": 8,
      "z": 0,
      "name": "Empty"
    },
    {
      "x": -19,
      "y": 9,
      "z": 0,
      "name": "Empty"
    },
    {
      "x": -19,
      "y": 10,
      "z": 0,
      "name": "Wood_Oak_Trunk",
      "support": 15,
      "rotation": 5
    },
    {
      "x": -19,
      "y": 11,
      "z": 0,
      "name": "Cloth_Roof_Leather_Flat"
    },
    {
      "x": -19,
      "y": 12,
      "z": 0,
      "name": "Empty"
    },
    {
      "x": -19,
      "y": 13,
      "z": 0,
      "name": "Empty"
    },
    {
      "x": -19,
      "y": 14,
      "z": 0,
      "name": "Empty"
    },
    {
      "x": -19,
      "y": 15,
      "z": 0,
      "name": "Empty"
    },
    {
      "x": -19,
      "y": 16,
      "z": 0,
      "name": "Empty"
    },
    {
      "x": -19,
      "y": 17,
      "z": 0,
      "name": "Empty"
    },
    {
      "x": -19,
      "y": 18,
      "z": 0,
      "name": "Empty"
    },
    {
      "x": -19,
      "y": -1,
      "z": 1,
      "name": "Rock_Stone"
    },
    {
      "x": -19,
      "y": 0,
      "z": 1,
      "name": "Rock_Stone"
    },
    {
      "x": -19,
      "y": 1,
      "z": 1,
      "name": "Rock_Stone"
    },
    {
      "x": -19,
      "y": 2,
      "z": 1,
      "name": "Rock_Stone"
    },
    {
      "x": -19,
      "y": 3,
      "z": 1,
      "name": "Soil_Pathway"
    },
    {
      "x": -19,
      "y": 4,
      "z": 1,
      "name": "Empty"
    },
    {
      "x": -19,
      "y": 5,
      "z": 1,
      "name": "Empty"
    },
    {
      "x": -19,
      "y": 6,
      "z": 1,
      "name": "Empty"
    },
    {
      "x": -19,
      "y": 7,
      "z": 1,
      "name": "Empty"
    },
    {
      "x": -19,
      "y": 8,
      "z": 1,
      "name": "Empty"
    },
    {
      "x": -19,
      "y": 9,
      "z": 1,
      "name": "Empty"
    },
    {
      "x": -19,
      "y": 10,
      "z": 1,
      "name": "Empty"
    },
    {
      "x": -19,
      "y": 11,
      "z": 1,
      "name": "Empty"
    },
    {
      "x": -19,
      "y": 12,
      "z": 1,
      "name": "Empty"
    },
    {
      "x": -19,
      "y": 13,
      "z": 1,
      "name": "Empty"
    },
    {
      "x": -19,
      "y": 14,
      "z": 1,
      "name": "Empty"
    },
    {
      "x": -19,
      "y": 15,
      "z": 1,
      "name": "Empty"
    },
    {
      "x": -19,
      "y": 16,
      "z": 1,
      "name": "Empty"
    },
    {
      "x": -19,
      "y": 17,
      "z": 1,
      "name": "Empty"
    },
    {
      "x": -19,
      "y": 18,
      "z": 1,
      "name": "Empty"
    },
    {
      "x": -19,
      "y": -1,
      "z": 2,
      "name": "Rock_Stone"
    },
    {
      "x": -19,
      "y": 0,
      "z": 2,
      "name": "Rock_Stone"
    },
    {
      "x": -19,
      "y": 1,
      "z": 2,
      "name": "Rock_Stone"
    },
    {
      "x": -19,
      "y": 2,
      "z": 2,
      "name": "Rock_Stone"
    },
    {
      "x": -19,
      "y": 3,
      "z": 2,
      "name": "Soil_Pathway"
    },
    {
      "x": -19,
      "y": 4,
      "z": 2,
      "name": "Empty"
    },
    {
      "x": -19,
      "y": 5,
      "z": 2,
      "name": "Empty"
    },
    {
      "x": -19,
      "y": 6,
      "z": 2,
      "name": "Empty"
    },
    {
      "x": -19,
      "y": 7,
      "z": 2,
      "name": "Empty"
    },
    {
      "x": -19,
      "y": 8,
      "z": 2,
      "name": "Empty"
    },
    {
      "x": -19,
      "y": 9,
      "z": 2,
      "name": "Empty"
    },
    {
      "x": -19,
      "y": 10,
      "z": 2,
      "name": "Empty"
    },
    {
      "x": -19,
      "y": 11,
      "z": 2,
      "name": "Empty"
    },
    {
      "x": -19,
      "y": 12,
      "z": 2,
      "name": "Empty"
    },
    {
      "x": -19,
      "y": 13,
      "z": 2,
      "name": "Empty"
    },
    {
      "x": -19,
      "y": 14,
      "z": 2,
      "name": "Empty"
    },
    {
      "x": -19,
      "y": 15,
      "z": 2,
      "name": "Empty"
    },
    {
      "x": -19,
      "y": 16,
      "z": 2,
      "name": "Empty"
    },
