{
  "version": 8,
  "blockIdVersion": 11,
  "anchorX": 0,
  "anchorY": 0,
  "anchorZ": 0,
  "blocks": [
    {
      "x": -39,
      "y": 1,
      "z": -7,
      "name": "Soil_Dirt"
    },
    {
      "x": -39,
      "y": 1,
      "z": -6,
      "name": "Soil_Dirt"
    },
    {
      "x": -39,
      "y": 1,
      "z": -5,
      "name": "Soil_Dirt"
    },
    {
      "x": -39,
      "y": 1,
      "z": -4,
      "name": "Soil_Dirt"
    },
    {
      "x": -39,
      "y": 1,
      "z": -3,
      "name": "Soil_Dirt"
    },
    {
      "x": -39,
      "y": 1,
      "z": 11,
      "name": "Soil_Dirt"
    },
    {
      "x": -39,
      "y": 1,
      "z": 12,
      "name": "Soil_Dirt"
    },
    {
      "x": -39,
      "y": 1,
      "z": 13,
      "name": "Soil_Dirt"
    },
    {
      "x": -39,
      "y": 1,
      "z": 14,
      "name": "Soil_Dirt"
    },
    {
      "x": -39,
      "y": 1,
      "z": 15,
      "name": "Soil_Dirt"
    },
    {
      "x": -38,
      "y": 1,
      "z": -10,
      "name": "Soil_Dirt"
    },
    {
      "x": -38,
      "y": 1,
      "z": -9,
      "name": "Soil_Dirt"
    },
    {
      "x": -38,
      "y": 1,
      "z": -8,
      "name": "Soil_Dirt"
    },
    {
      "x": -38,
      "y": 1,
      "z": -7,
      "name": "Soil_Dirt"
    },
    {
      "x": -38,
      "y": 1,
      "z": -6,
      "name": "Soil_Dirt"
    },
    {
      "x": -38,
      "y": 1,
      "z": -5,
      "name": "Soil_Dirt"
    },
    {
      "x": -38,
      "y": 1,
      "z": -4,
      "name": "Soil_Dirt"
    },
    {
      "x": -38,
      "y": 1,
      "z": -3,
      "name": "Soil_Dirt"
    },
    {
      "x": -38,
      "y": 1,
      "z": -2,
      "name": "Soil_Dirt"
    },
    {
      "x": -38,
      "y": 1,
      "z": -1,
      "name": "Soil_Dirt"
    },
    {
      "x": -38,
      "y": 1,
      "z": 0,
      "name": "Soil_Dirt"
    },
    {
      "x": -38,
      "y": 1,
      "z": 8,
      "name": "Soil_Dirt"
    },
    {
      "x": -38,
      "y": 1,
      "z": 9,
      "name": "Soil_Dirt"
    },
    {
      "x": -38,
      "y": 1,
      "z": 10,
      "name": "Soil_Dirt"
    },
    {
      "x": -38,
      "y": 1,
      "z": 11,
      "name": "Soil_Dirt"
    },
    {
      "x": -38,
      "y": 1,
      "z": 12,
      "name": "Soil_Dirt"
    },
    {
      "x": -38,
      "y": 1,
      "z": 13,
      "name": "Soil_Dirt"
    },
    {
      "x": -38,
      "y": 1,
      "z": 14,
      "name": "Soil_Dirt"
    },
    {
      "x": -38,
      "y": 1,
      "z": 15,
      "name": "Soil_Dirt"
    },
    {
      "x": -38,
      "y": 1,
      "z": 16,
      "name": "Soil_Dirt"
    },
    {
      "x": -38,
      "y": 1,
      "z": 17,
      "name": "Soil_Dirt"
    },
    {
      "x": -38,
      "y": 1,
      "z": 18,
      "name": "Soil_Dirt"
    },
    {
      "x": -37,
      "y": 1,
      "z": -11,
      "name": "Soil_Dirt"
    },
    {
      "x": -37,
      "y": 1,
      "z": -10,
      "name": "Soil_Dirt"
    },
    {
      "x": -37,
      "y": 1,
      "z": -9,
      "name": "Soil_Dirt"
    },
    {
      "x": -37,
      "y": 1,
      "z": -8,
      "name": "Soil_Dirt"
    },
    {
      "x": -37,
      "y": 1,
      "z": -7,
      "name": "Soil_Dirt"
    },
    {
      "x": -37,
      "y": 1,
      "z": -6,
      "name": "Soil_Dirt"
    },
    {
      "x": -37,
      "y": 1,
      "z": -5,
      "name": "Soil_Dirt"
    },
    {
      "x": -37,
      "y": 1,
      "z": -4,
      "name": "Soil_Dirt"
    },
    {
      "x": -37,
      "y": 1,
      "z": -3,
      "name": "Soil_Dirt"
    },
    {
      "x": -37,
      "y": 1,
      "z": -2,
      "name": "Soil_Dirt"
    },
    {
      "x": -37,
      "y": 1,
      "z": -1,
      "name": "Soil_Dirt"
    },
    {
      "x": -37,
      "y": 1,
      "z": 0,
      "name": "Soil_Dirt"
    },
    {
      "x": -37,
      "y": 1,
      "z": 1,
      "name": "Soil_Dirt"
    },
    {
      "x": -37,
      "y": 1,
      "z": 7,
      "name": "Soil_Dirt"
    },
    {
      "x": -37,
      "y": 1,
      "z": 8,
      "name": "Soil_Dirt"
    },
    {
      "x": -37,
      "y": 1,
      "z": 9,
      "name": "Soil_Dirt"
    },
    {
      "x": -37,
      "y": 1,
      "z": 10,
      "name": "Soil_Dirt"
    },
    {
      "x": -37,
      "y": 1,
      "z": 11,
      "name": "Soil_Dirt"
    },
    {
      "x": -37,
      "y": 1,
      "z": 12,
      "name": "Soil_Dirt"
    },
    {
      "x": -37,
      "y": 1,
      "z": 13,
      "name": "Soil_Dirt"
    },
    {
      "x": -37,
      "y": 1,
      "z": 14,
      "name": "Soil_Dirt"
    },
    {
      "x": -37,
      "y": 1,
      "z": 15,
      "name": "Soil_Dirt"
    },
    {
      "x": -37,
      "y": 1,
      "z": 16,
      "name": "Soil_Dirt"
    },
    {
      "x": -37,
      "y": 1,
      "z": 17,
      "name": "Soil_Dirt"
    },
    {
      "x": -37,
      "y": 1,
      "z": 18,
      "name": "Soil_Dirt"
    },
    {
      "x": -37,
      "y": 1,
      "z": 19,
      "name": "Soil_Dirt"
    },
    {
      "x": -36,
      "y": 1,
      "z": -12,
      "name": "Soil_Dirt"
    },
    {
      "x": -36,
      "y": 1,
      "z": -11,
      "name": "Soil_Dirt"
    },
    {
      "x": -36,
      "y": 1,
      "z": -10,
      "name": "Soil_Dirt"
    },
    {
      "x": -36,
      "y": 1,
      "z": -9,
      "name": "Soil_Dirt"
    },
    {
      "x": -36,
      "y": 1,
      "z": -8,
      "name": "Soil_Dirt"
    },
    {
      "x": -36,
      "y": 1,
      "z": -7,
      "name": "Soil_Dirt"
    },
    {
      "x": -36,
      "y": 1,
      "z": -6,
      "name": "Soil_Dirt"
    },
    {
      "x": -36,
      "y": 1,
      "z": -5,
      "name": "Soil_Dirt"
    },
    {
      "x": -36,
      "y": 1,
      "z": -4,
      "name": "Soil_Dirt"
    },
    {
      "x": -36,
      "y": 1,
      "z": -3,
      "name": "Soil_Dirt"
    },
    {
      "x": -36,
      "y": 1,
      "z": -2,
      "name": "Soil_Dirt"
    },
    {
      "x": -36,
      "y": 1,
      "z": -1,
      "name": "Soil_Dirt"
    },
    {
      "x": -36,
      "y": 1,
      "z": 0,
      "name": "Soil_Dirt"
    },
    {
      "x": -36,
      "y": 1,
      "z": 1,
      "name": "Soil_Dirt"
    },
    {
      "x": -36,
      "y": 1,
      "z": 2,
      "name": "Soil_Dirt"
    },
    {
      "x": -36,
      "y": 1,
      "z": 6,
      "name": "Soil_Dirt"
    },
    {
      "x": -36,
      "y": 1,
      "z": 7,
      "name": "Soil_Dirt"
    },
    {
      "x": -36,
      "y": 1,
      "z": 8,
      "name": "Soil_Dirt"
    },
    {
      "x": -36,
      "y": 1,
      "z": 9,
      "name": "Soil_Dirt"
    },
    {
      "x": -36,
      "y": 1,
      "z": 10,
      "name": "Soil_Dirt"
    },
    {
      "x": -36,
      "y": 1,
      "z": 11,
      "name": "Soil_Dirt"
    },
    {
      "x": -36,
      "y": 1,
      "z": 12,
      "name": "Soil_Dirt"
    },
    {
      "x": -36,
      "y": 1,
      "z": 13,
      "name": "Soil_Dirt"
    },
    {
      "x": -36,
      "y": 1,
      "z": 14,
      "name": "Soil_Dirt"
    },
    {
      "x": -36,
      "y": 1,
      "z": 15,
      "name": "Soil_Dirt"
    },
    {
      "x": -36,
      "y": 1,
      "z": 16,
      "name": "Soil_Dirt"
    },
    {
      "x": -36,
      "y": 1,
      "z": 17,
      "name": "Soil_Dirt"
    },
    {
      "x": -36,
      "y": 1,
      "z": 18,
      "name": "Soil_Dirt"
    },
    {
      "x": -36,
      "y": 1,
      "z": 19,
      "name": "Soil_Dirt"
    },
    {
      "x": -36,
      "y": 1,
      "z": 20,
      "name": "Soil_Dirt"
    },
    {
      "x": -35,
      "y": 1,
      "z": -13,
      "name": "Soil_Dirt"
    },
    {
      "x": -35,
      "y": 1,
      "z": -12,
      "name": "Soil_Dirt"
    },
    {
      "x": -35,
      "y": 1,
      "z": -11,
      "name": "Soil_Dirt"
    },
    {
      "x": -35,
      "y": 1,
      "z": -10,
      "name": "Soil_Dirt"
    },
    {
      "x": -35,
      "y": 1,
      "z": -9,
      "name": "Soil_Dirt"
    },
    {
      "x": -35,
      "y": 1,
      "z": -8,
      "name": "Soil_Dirt"
    },
    {
      "x": -35,
      "y": 1,
      "z": -7,
      "name": "Soil_Dirt"
    },
    {
      "x": -35,
      "y": 1,
      "z": -6,
      "name": "Soil_Dirt"
    },
    {
      "x": -35,
      "y": 1,
      "z": -5,
      "name": "Soil_Dirt"
    },
    {
      "x": -35,
      "y": 1,
      "z": -4,
      "name": "Soil_Dirt"
    },
    {
      "x": -35,
      "y": 1,
      "z": -3,
      "name": "Soil_Dirt"
    },
    {
      "x": -35,
      "y": 1,
      "z": -2,
      "name": "Soil_Dirt"
    },
    {
      "x": -35,
      "y": 1,
      "z": -1,
      "name": "Soil_Dirt"
    },
    {
      "x": -35,
      "y": 1,
      "z": 0,
      "name": "Soil_Dirt"
    },
    {
      "x": -35,
      "y": 1,
      "z": 1,
      "name": "Soil_Dirt"
    },
    {
      "x": -35,
      "y": 1,
      "z": 2,
      "name": "Soil_Dirt"
    },
    {
      "x": -35,
      "y": 1,
      "z": 3,
      "name": "Soil_Dirt"
    },
    {
      "x": -35,
      "y": 1,
      "z": 5,
      "name": "Soil_Dirt"
    },
    {
      "x": -35,
      "y": 1,
      "z": 6,
      "name": "Soil_Dirt"
    },
    {
      "x": -35,
      "y": 1,
      "z": 7,
      "name": "Soil_Dirt"
    },
    {
      "x": -35,
      "y": 1,
      "z": 8,
      "name": "Soil_Dirt"
    },
    {
      "x": -35,
      "y": 1,
      "z": 9,
      "name": "Soil_Dirt"
    },
    {
      "x": -35,
      "y": 1,
      "z": 10,
      "name": "Soil_Dirt"
    },
    {
      "x": -35,
      "y": 1,
      "z": 11,
      "name": "Soil_Dirt"
    },
    {
      "x": -35,
      "y": 1,
      "z": 12,
      "name": "Soil_Dirt"
    },
    {
      "x": -35,
      "y": 1,
      "z": 13,
      "name": "Soil_Dirt"
    },
    {
      "x": -35,
      "y": 1,
      "z": 14,
      "name": "Soil_Dirt"
    },
    {
      "x": -35,
      "y": 1,
      "z": 15,
      "name": "Soil_Dirt"
    },
    {
      "x": -35,
      "y": 1,
      "z": 16,
      "name": "Soil_Dirt"
    },
    {
      "x": -35,
      "y": 1,
      "z": 17,
      "name": "Soil_Dirt"
    },
    {
      "x": -35,
      "y": 1,
      "z": 18,
      "name": "Soil_Dirt"
    },
    {
      "x": -35,
      "y": 1,
      "z": 19,
      "name": "Soil_Dirt"
    },
    {
      "x": -35,
      "y": 1,
      "z": 20,
      "name": "Soil_Dirt"
    },
    {
      "x": -35,
      "y": 1,
      "z": 21,
      "name": "Soil_Dirt"
    },
    {
      "x": -34,
      "y": 1,
      "z": -14,
      "name": "Soil_Dirt"
    },
    {
      "x": -34,
      "y": 1,
      "z": -13,
      "name": "Soil_Dirt"
    },
    {
      "x": -34,
      "y": 1,
      "z": -12,
      "name": "Soil_Dirt"
    },
    {
      "x": -34,
      "y": 1,
      "z": -11,
      "name": "Soil_Dirt"
    },
    {
      "x": -34,
      "y": 1,
      "z": -10,
      "name": "Soil_Dirt"
    },
    {
      "x": -34,
      "y": 1,
      "z": -9,
      "name": "Soil_Dirt"
    },
    {
      "x": -34,
      "y": 1,
      "z": -8,
      "name": "Soil_Dirt"
    },
    {
      "x": -34,
      "y": 1,
      "z": -7,
      "name": "Soil_Dirt"
    },
    {
      "x": -34,
      "y": 1,
      "z": -6,
      "name": "Soil_Dirt"
    },
    {
      "x": -34,
      "y": 1,
      "z": -5,
      "name": "Soil_Dirt"
    },
    {
      "x": -34,
      "y": 1,
      "z": -4,
      "name": "Soil_Dirt"
    },
    {
      "x": -34,
      "y": 1,
      "z": -3,
      "name": "Soil_Dirt"
    },
    {
      "x": -34,
      "y": 1,
      "z": -2,
      "name": "Soil_Dirt"
    },
    {
      "x": -34,
      "y": 1,
      "z": -1,
      "name": "Soil_Dirt"
    },
    {
      "x": -34,
      "y": 1,
      "z": 0,
      "name": "Soil_Dirt"
    },
    {
      "x": -34,
      "y": 1,
      "z": 1,
      "name": "Soil_Dirt"
    },
    {
      "x": -34,
      "y": 1,
      "z": 2,
      "name": "Soil_Dirt"
    },
    {
      "x": -34,
      "y": 1,
      "z": 3,
      "name": "Soil_Dirt"
    },
    {
      "x": -34,
      "y": 1,
      "z": 4,
      "name": "Soil_Dirt"
    },
    {
      "x": -34,
      "y": 1,
      "z": 5,
      "name": "Soil_Dirt"
    },
    {
      "x": -34,
      "y": 1,
      "z": 6,
      "name": "Soil_Dirt"
    },
    {
      "x": -34,
      "y": 1,
      "z": 7,
      "name": "Soil_Dirt"
    },
    {
      "x": -34,
      "y": 1,
      "z": 8,
      "name": "Soil_Dirt"
    },
    {
      "x": -34,
      "y": 1,
      "z": 9,
      "name": "Soil_Dirt"
    },
    {
      "x": -34,
      "y": 1,
      "z": 10,
      "name": "Soil_Dirt"
    },
    {
      "x": -34,
      "y": 1,
      "z": 11,
      "name": "Soil_Dirt"
    },
    {
      "x": -34,
      "y": 1,
      "z": 12,
      "name": "Soil_Dirt"
    },
    {
      "x": -34,
      "y": 1,
      "z": 13,
      "name": "Soil_Dirt"
    },
    {
      "x": -34,
      "y": 1,
      "z": 14,
      "name": "Soil_Dirt"
    },
    {
      "x": -34,
      "y": 1,
      "z": 15,
      "name": "Soil_Dirt"
    },
    {
      "x": -34,
      "y": 1,
      "z": 16,
      "name": "Soil_Dirt"
    },
    {
      "x": -34,
      "y": 1,
      "z": 17,
      "name": "Soil_Dirt"
    },
    {
      "x": -34,
      "y": 1,
      "z": 18,
      "name": "Soil_Dirt"
    },
    {
      "x": -34,
      "y": 1,
      "z": 19,
      "name": "Soil_Dirt"
    },
    {
      "x": -34,
      "y": 1,
      "z": 20,
      "name": "Soil_Dirt"
    },
    {
      "x": -34,
      "y": 1,
      "z": 21,
      "name": "Soil_Dirt"
    },
    {
      "x": -34,
      "y": 1,
      "z": 22,
      "name": "Soil_Dirt"
    },
    {
      "x": -33,
      "y": 1,
      "z": -14,
      "name": "Soil_Dirt"
    },
    {
      "x": -33,
      "y": 1,
      "z": -13,
      "name": "Soil_Dirt"
    },
    {
      "x": -33,
      "y": 1,
      "z": -12,
      "name": "Soil_Dirt"
    },
    {
      "x": -33,
      "y": 1,
      "z": -11,
      "name": "Soil_Dirt"
    },
    {
      "x": -33,
      "y": 1,
      "z": -10,
      "name": "Soil_Dirt"
    },
    {
      "x": -33,
      "y": 1,
      "z": -9,
      "name": "Soil_Dirt"
    },
    {
      "x": -33,
      "y": 1,
      "z": -8,
      "name": "Soil_Dirt"
    },
    {
      "x": -33,
      "y": 1,
      "z": -7,
      "name": "Soil_Dirt"
    },
    {
      "x": -33,
      "y": 2,
      "z": -7,
      "name": "Soil_Dirt"
    },
    {
      "x": -33,
      "y": 1,
      "z": -6,
      "name": "Soil_Dirt"
    },
    {
      "x": -33,
      "y": 2,
      "z": -6,
      "name": "Soil_Dirt"
    },
    {
      "x": -33,
      "y": 1,
      "z": -5,
      "name": "Soil_Dirt"
    },
    {
      "x": -33,
      "y": 2,
      "z": -5,
      "name": "Soil_Dirt"
    },
    {
      "x": -33,
      "y": 1,
      "z": -4,
      "name": "Soil_Dirt"
    },
    {
      "x": -33,
      "y": 1,
      "z": -3,
      "name": "Soil_Dirt"
    },
    {
      "x": -33,
      "y": 1,
      "z": -2,
      "name": "Soil_Dirt"
    },
    {
      "x": -33,
      "y": 1,
      "z": -1,
      "name": "Soil_Dirt"
    },
    {
      "x": -33,
      "y": 1,
      "z": 0,
      "name": "Soil_Dirt"
    },
    {
      "x": -33,
      "y": 2,
      "z": 0,
      "name": "Soil_Dirt"
    },
    {
      "x": -33,
      "y": 1,
      "z": 1,
      "name": "Soil_Dirt"
    },
    {
      "x": -33,
      "y": 2,
      "z": 1,
      "name": "Soil_Dirt"
    },
    {
      "x": -33,
      "y": 1,
      "z": 2,
      "name": "Soil_Dirt"
    },
    {
      "x": -33,
      "y": 2,
      "z": 2,
      "name": "Soil_Dirt"
    },
    {
      "x": -33,
      "y": 1,
      "z": 3,
      "name": "Soil_Dirt"
    },
    {
      "x": -33,
      "y": 1,
      "z": 4,
      "name": "Soil_Dirt"
    },
    {
      "x": -33,
      "y": 1,
      "z": 5,
      "name": "Soil_Dirt"
    },
    {
      "x": -33,
      "y": 1,
      "z": 6,
      "name": "Soil_Dirt"
    },
    {
      "x": -33,
      "y": 1,
      "z": 7,
      "name": "Soil_Dirt"
    },
    {
      "x": -33,
      "y": 1,
      "z": 8,
      "name": "Soil_Dirt"
    },
    {
      "x": -33,
      "y": 2,
      "z": 8,
      "name": "Soil_Dirt"
    },
    {
      "x": -33,
      "y": 1,
      "z": 9,
      "name": "Soil_Dirt"
    },
    {
      "x": -33,
      "y": 2,
      "z": 9,
      "name": "Soil_Dirt"
    },
    {
      "x": -33,
      "y": 1,
      "z": 10,
      "name": "Soil_Dirt"
    },
    {
      "x": -33,
      "y": 2,
      "z": 10,
      "name": "Soil_Dirt"
    },
    {
      "x": -33,
      "y": 1,
      "z": 11,
      "name": "Soil_Dirt"
    },
    {
      "x": -33,
      "y": 1,
      "z": 12,
      "name": "Soil_Dirt"
    },
    {
      "x": -33,
      "y": 1,
      "z": 13,
      "name": "Soil_Dirt"
    },
    {
      "x": -33,
      "y": 1,
      "z": 14,
      "name": "Soil_Dirt"
    },
    {
      "x": -33,
      "y": 1,
      "z": 15,
      "name": "Soil_Dirt"
    },
    {
      "x": -33,
      "y": 1,
      "z": 16,
      "name": "Soil_Dirt"
    },
    {
      "x": -33,
      "y": 1,
      "z": 17,
      "name": "Soil_Dirt"
    },
    {
      "x": -33,
      "y": 2,
      "z": 17,
      "name": "Soil_Dirt"
    },
    {
      "x": -33,
      "y": 1,
      "z": 18,
      "name": "Soil_Dirt"
    },
    {
      "x": -33,
      "y": 2,
      "z": 18,
      "name": "Soil_Dirt"
    },
    {
      "x": -33,
      "y": 1,
      "z": 19,
      "name": "Soil_Dirt"
    },
    {
      "x": -33,
      "y": 2,
      "z": 19,
      "name": "Soil_Dirt"
    },
    {
      "x": -33,
      "y": 1,
      "z": 20,
      "name": "Soil_Dirt"
    },
    {
      "x": -33,
      "y": 1,
      "z": 21,
      "name": "Soil_Dirt"
    },
    {
      "x": -33,
      "y": 1,
      "z": 22,
      "name": "Soil_Dirt"
    },
    {
      "x": -32,
      "y": 1,
      "z": -22,
      "name": "Soil_Dirt"
    },
    {
      "x": -32,
      "y": 1,
      "z": -21,
      "name": "Soil_Dirt"
    },
    {
      "x": -32,
      "y": 1,
      "z": -20,
      "name": "Soil_Dirt"
    },
    {
      "x": -32,
      "y": 1,
      "z": -19,
      "name": "Soil_Dirt"
    },
    {
      "x": -32,
      "y": 1,
      "z": -18,
      "name": "Soil_Dirt"
    },
    {
      "x": -32,
      "y": 1,
      "z": -14,
      "name": "Soil_Dirt"
    },
    {
      "x": -32,
      "y": 2,
      "z": -14,
      "name": "Soil_Dirt"
    },
    {
      "x": -32,
      "y": 1,
      "z": -13,
      "name": "Soil_Dirt"
    },
    {
      "x": -32,
      "y": 2,
      "z": -13,
      "name": "Soil_Dirt"
    },
    {
      "x": -32,
      "y": 1,
      "z": -12,
      "name": "Soil_Dirt"
    },
    {
      "x": -32,
      "y": 2,
      "z": -12,
      "name": "Soil_Dirt"
    },
    {
      "x": -32,
      "y": 1,
      "z": -11,
      "name": "Soil_Dirt"
    },
    {
      "x": -32,
      "y": 1,
      "z": -10,
      "name": "Soil_Dirt"
    },
    {
      "x": -32,
      "y": 1,
      "z": -9,
      "name": "Soil_Dirt"
    },
    {
      "x": -32,
      "y": 2,
      "z": -9,
      "name": "Soil_Dirt"
    },
    {
      "x": -32,
      "y": 1,
      "z": -8,
      "name": "Soil_Dirt"
    },
    {
      "x": -32,
      "y": 2,
      "z": -8,
      "name": "Soil_Dirt"
    },
    {
      "x": -32,
      "y": 1,
      "z": -7,
      "name": "Soil_Dirt"
    },
    {
      "x": -32,
      "y": 2,
      "z": -7,
      "name": "Soil_Dirt"
    },
    {
      "x": -32,
      "y": 1,
      "z": -6,
      "name": "Soil_Dirt"
    },
    {
      "x": -32,
      "y": 2,
      "z": -6,
      "name": "Soil_Dirt"
    },
    {
      "x": -32,
      "y": 1,
      "z": -5,
      "name": "Soil_Dirt"
    },
    {
      "x": -32,
      "y": 2,
      "z": -5,
      "name": "Soil_Dirt"
    },
    {
      "x": -32,
      "y": 1,
      "z": -4,
      "name": "Soil_Dirt"
    },
    {
      "x": -32,
      "y": 2,
      "z": -4,
      "name": "Soil_Dirt"
    },
    {
      "x": -32,
      "y": 1,
      "z": -3,
      "name": "Soil_Dirt"
    },
    {
      "x": -32,
      "y": 2,
      "z": -3,
      "name": "Soil_Dirt"
    },
    {
      "x": -32,
      "y": 1,
      "z": -2,
      "name": "Soil_Dirt"
    },
    {
      "x": -32,
      "y": 2,
      "z": -2,
      "name": "Soil_Dirt"
    },
    {
      "x": -32,
      "y": 1,
      "z": -1,
      "name": "Soil_Dirt"
    },
    {
      "x": -32,
      "y": 2,
      "z": -1,
      "name": "Soil_Dirt"
    },
    {
      "x": -32,
      "y": 1,
      "z": 0,
      "name": "Soil_Dirt"
    },
    {
      "x": -32,
      "y": 2,
      "z": 0,
      "name": "Soil_Dirt"
    },
    {
      "x": -32,
      "y": 1,
      "z": 1,
      "name": "Soil_Dirt"
    },
    {
      "x": -32,
      "y": 2,
      "z": 1,
      "name": "Soil_Dirt"
    },
    {
      "x": -32,
      "y": 1,
      "z": 2,
      "name": "Soil_Dirt"
    },
    {
      "x": -32,
      "y": 2,
      "z": 2,
      "name": "Soil_Dirt"
    },
    {
      "x": -32,
      "y": 1,
      "z": 3,
      "name": "Soil_Dirt"
    },
    {
      "x": -32,
      "y": 2,
      "z": 3,
      "name": "Soil_Dirt"
    },
    {
      "x": -32,
      "y": 1,
      "z": 4,
      "name": "Soil_Dirt"
    },
    {
      "x": -32,
      "y": 2,
      "z": 4,
      "name": "Soil_Dirt"
    },
    {
      "x": -32,
      "y": 1,
      "z": 5,
      "name": "Soil_Dirt"
    },
    {
      "x": -32,
      "y": 1,
      "z": 6,
      "name": "Soil_Dirt"
    },
    {
      "x": -32,
      "y": 2,
      "z": 6,
      "name": "Soil_Dirt"
    },
    {
      "x": -32,
      "y": 1,
      "z": 7,
      "name": "Soil_Dirt"
    },
    {
      "x": -32,
      "y": 2,
      "z": 7,
      "name": "Soil_Dirt"
    },
    {
      "x": -32,
      "y": 1,
      "z": 8,
      "name": "Soil_Dirt"
    },
    {
      "x": -32,
      "y": 2,
      "z": 8,
      "name": "Soil_Dirt"
    },
    {
      "x": -32,
      "y": 1,
      "z": 9,
      "name": "Soil_Dirt"
    },
    {
      "x": -32,
      "y": 2,
      "z": 9,
      "name": "Soil_Dirt"
    },
    {
      "x": -32,
      "y": 1,
      "z": 10,
      "name": "Soil_Dirt"
    },
    {
      "x": -32,
      "y": 2,
      "z": 10,
      "name": "Soil_Dirt"
    },
    {
      "x": -32,
      "y": 1,
      "z": 11,
      "name": "Soil_Dirt"
    },
    {
      "x": -32,
      "y": 2,
      "z": 11,
      "name": "Soil_Dirt"
    },
    {
      "x": -32,
      "y": 1,
      "z": 12,
      "name": "Soil_Dirt"
    },
    {
      "x": -32,
      "y": 2,
      "z": 12,
      "name": "Soil_Dirt"
    },
    {
      "x": -32,
      "y": 1,
      "z": 13,
      "name": "Soil_Dirt"
    },
    {
      "x": -32,
      "y": 1,
      "z": 14,
      "name": "Soil_Dirt"
    },
    {
      "x": -32,
      "y": 1,
      "z": 15,
      "name": "Soil_Dirt"
    },
    {
      "x": -32,
      "y": 2,
      "z": 15,
      "name": "Soil_Dirt"
    },
    {
      "x": -32,
      "y": 1,
      "z": 16,
      "name": "Soil_Dirt"
    },
    {
      "x": -32,
      "y": 2,
      "z": 16,
      "name": "Soil_Dirt"
    },
    {
      "x": -32,
      "y": 1,
      "z": 17,
      "name": "Soil_Dirt"
    },
    {
      "x": -32,
      "y": 2,
      "z": 17,
      "name": "Soil_Dirt"
    },
    {
      "x": -32,
      "y": 1,
      "z": 18,
      "name": "Soil_Dirt"
    },
    {
      "x": -32,
      "y": 2,
      "z": 18,
      "name": "Soil_Dirt"
    },
    {
      "x": -32,
      "y": 1,
      "z": 19,
      "name": "Soil_Dirt"
    },
    {
      "x": -32,
      "y": 2,
      "z": 19,
      "name": "Soil_Dirt"
    },
    {
      "x": -32,
      "y": 1,
      "z": 20,
      "name": "Soil_Dirt"
    },
    {
      "x": -32,
      "y": 2,
      "z": 20,
      "name": "Soil_Dirt"
    },
    {
      "x": -32,
      "y": 1,
      "z": 21,
      "name": "Soil_Dirt"
    },
    {
      "x": -32,
      "y": 2,
      "z": 21,
      "name": "Soil_Dirt"
    },
    {
      "x": -32,
      "y": 1,
      "z": 22,
      "name": "Soil_Dirt"
    },
    {
      "x": -32,
      "y": 1,
      "z": 24,
      "name": "Soil_Dirt"
    },
    {
      "x": -32,
      "y": 1,
      "z": 25,
      "name": "Soil_Dirt"
    },
    {
      "x": -32,
      "y": 1,
      "z": 26,
      "name": "Soil_Dirt"
    },
    {
      "x": -32,
      "y": 1,
      "z": 27,
      "name": "Soil_Dirt"
    },
    {
      "x": -32,
      "y": 1,
      "z": 28,
      "name": "Soil_Dirt"
    },
    {
      "x": -31,
      "y": 1,
      "z": -25,
      "name": "Soil_Dirt"
    },
    {
      "x": -31,
      "y": 1,
      "z": -24,
      "name": "Soil_Dirt"
    },
    {
      "x": -31,
      "y": 1,
      "z": -23,
      "name": "Soil_Dirt"
    },
    {
      "x": -31,
      "y": 1,
      "z": -22,
      "name": "Soil_Dirt"
    },
    {
      "x": -31,
      "y": 1,
      "z": -21,
      "name": "Soil_Dirt"
    },
    {
      "x": -31,
      "y": 1,
      "z": -20,
      "name": "Soil_Dirt"
    },
    {
      "x": -31,
      "y": 1,
      "z": -19,
      "name": "Soil_Dirt"
    },
    {
      "x": -31,
      "y": 1,
      "z": -18,
      "name": "Soil_Dirt"
    },
    {
      "x": -31,
      "y": 1,
      "z": -17,
      "name": "Soil_Dirt"
    },
    {
      "x": -31,
      "y": 1,
      "z": -16,
      "name": "Soil_Dirt"
    },
    {
      "x": -31,
      "y": 2,
      "z": -16,
      "name": "Soil_Dirt"
    },
    {
      "x": -31,
      "y": 1,
      "z": -15,
      "name": "Soil_Dirt"
    },
    {
      "x": -31,
      "y": 2,
      "z": -15,
      "name": "Soil_Dirt"
    },
    {
      "x": -31,
      "y": 1,
      "z": -14,
      "name": "Soil_Dirt"
    },
    {
      "x": -31,
      "y": 2,
      "z": -14,
      "name": "Soil_Dirt"
    },
    {
      "x": -31,
      "y": 1,
      "z": -13,
      "name": "Soil_Dirt"
    },
    {
      "x": -31,
      "y": 2,
      "z": -13,
      "name": "Soil_Dirt"
    },
    {
      "x": -31,
      "y": 1,
      "z": -12,
      "name": "Soil_Dirt"
    },
    {
      "x": -31,
      "y": 2,
      "z": -12,
      "name": "Soil_Dirt"
    },
    {
      "x": -31,
      "y": 1,
      "z": -11,
      "name": "Soil_Dirt"
    },
    {
      "x": -31,
      "y": 2,
      "z": -11,
      "name": "Soil_Dirt"
    },
    {
      "x": -31,
      "y": 1,
      "z": -10,
      "name": "Soil_Dirt"
    },
    {
      "x": -31,
      "y": 2,
      "z": -10,
      "name": "Soil_Dirt"
    },
    {
      "x": -31,
      "y": 1,
      "z": -9,
      "name": "Soil_Dirt"
    },
    {
      "x": -31,
      "y": 2,
      "z": -9,
      "name": "Soil_Dirt"
    },
    {
      "x": -31,
      "y": 1,
      "z": -8,
      "name": "Soil_Dirt"
    },
    {
      "x": -31,
      "y": 2,
      "z": -8,
      "name": "Soil_Dirt"
    },
    {
      "x": -31,
      "y": 1,
      "z": -7,
      "name": "Soil_Dirt"
    },
    {
      "x": -31,
      "y": 2,
      "z": -7,
      "name": "Soil_Dirt"
    },
    {
      "x": -31,
      "y": 1,
      "z": -6,
      "name": "Soil_Dirt"
    },
    {
      "x": -31,
      "y": 2,
      "z": -6,
      "name": "Soil_Dirt"
    },
    {
      "x": -31,
      "y": 1,
      "z": -5,
      "name": "Soil_Dirt"
    },
    {
      "x": -31,
      "y": 2,
      "z": -5,
      "name": "Soil_Dirt"
    },
    {
      "x": -31,
      "y": 1,
      "z": -4,
      "name": "Soil_Dirt"
    },
    {
      "x": -31,
      "y": 2,
      "z": -4,
      "name": "Soil_Dirt"
    },
    {
      "x": -31,
      "y": 1,
      "z": -3,
      "name": "Soil_Dirt"
    },
    {
      "x": -31,
      "y": 2,
      "z": -3,
      "name": "Soil_Dirt"
    },
    {
      "x": -31,
      "y": 1,
      "z": -2,
      "name": "Soil_Dirt"
    },
    {
      "x": -31,
      "y": 2,
      "z": -2,
      "name": "Soil_Dirt"
    },
    {
      "x": -31,
      "y": 1,
      "z": -1,
      "name": "Soil_Dirt"
    },
    {
      "x": -31,
      "y": 2,
      "z": -1,
      "name": "Soil_Dirt"
    },
    {
      "x": -31,
      "y": 1,
      "z": 0,
      "name": "Soil_Dirt"
    },
    {
      "x": -31,
      "y": 2,
      "z": 0,
      "name": "Soil_Dirt"
    },
    {
      "x": -31,
      "y": 1,
      "z": 1,
      "name": "Soil_Dirt"
    },
    {
      "x": -31,
      "y": 2,
      "z": 1,
      "name": "Soil_Dirt"
    },
    {
      "x": -31,
      "y": 1,
      "z": 2,
      "name": "Soil_Dirt"
    },
    {
      "x": -31,
      "y": 2,
      "z": 2,
      "name": "Soil_Dirt"
    },
    {
      "x": -31,
      "y": 1,
      "z": 3,
      "name": "Soil_Dirt"
    },
    {
      "x": -31,
      "y": 2,
      "z": 3,
      "name": "Soil_Dirt"
    },
    {
      "x": -31,
      "y": 1,
      "z": 4,
      "name": "Soil_Dirt"
    },
    {
      "x": -31,
      "y": 2,
      "z": 4,
      "name": "Soil_Dirt"
    },
    {
      "x": -31,
      "y": 1,
      "z": 5,
      "name": "Soil_Dirt"
    },
    {
      "x": -31,
      "y": 1,
      "z": 6,
      "name": "Soil_Dirt"
    },
    {
      "x": -31,
      "y": 2,
      "z": 6,
      "name": "Soil_Dirt"
    },
    {
      "x": -31,
      "y": 1,
      "z": 7,
      "name": "Soil_Dirt"
    },
    {
      "x": -31,
      "y": 2,
      "z": 7,
      "name": "Soil_Dirt"
    },
    {
      "x": -31,
      "y": 1,
      "z": 8,
      "name": "Soil_Dirt"
    },
    {
      "x": -31,
      "y": 2,
      "z": 8,
      "name": "Soil_Dirt"
    },
    {
      "x": -31,
      "y": 1,
      "z": 9,
      "name": "Soil_Dirt"
    },
    {
      "x": -31,
      "y": 2,
      "z": 9,
      "name": "Soil_Dirt"
    },
    {
      "x": -31,
      "y": 1,
      "z": 10,
      "name": "Soil_Dirt"
    },
    {
      "x": -31,
      "y": 2,
      "z": 10,
      "name": "Soil_Dirt"
    },
    {
      "x": -31,
      "y": 1,
      "z": 11,
      "name": "Soil_Dirt"
    },
    {
      "x": -31,
      "y": 2,
      "z": 11,
      "name": "Soil_Dirt"
    },
    {
      "x": -31,
      "y": 1,
      "z": 12,
      "name": "Soil_Dirt"
    },
    {
      "x": -31,
      "y": 2,
      "z": 12,
      "name": "Soil_Dirt"
    },
    {
      "x": -31,
      "y": 1,
      "z": 13,
      "name": "Soil_Dirt"
    },
    {
      "x": -31,
      "y": 1,
      "z": 14,
      "name": "Soil_Dirt"
    },
    {
      "x": -31,
      "y": 1,
      "z": 15,
      "name": "Soil_Dirt"
    },
    {
      "x": -31,
      "y": 2,
      "z": 15,
      "name": "Soil_Dirt"
    },
    {
      "x": -31,
      "y": 1,
      "z": 16,
      "name": "Soil_Dirt"
    },
    {
      "x": -31,
      "y": 2,
      "z": 16,
      "name": "Soil_Dirt"
    },
    {
      "x": -31,
      "y": 1,
      "z": 17,
      "name": "Soil_Dirt"
    },
    {
      "x": -31,
      "y": 2,
      "z": 17,
      "name": "Soil_Dirt"
    },
    {
      "x": -31,
      "y": 1,
      "z": 18,
      "name": "Soil_Dirt"
    },
    {
      "x": -31,
      "y": 2,
      "z": 18,
      "name": "Soil_Dirt"
    },
    {
      "x": -31,
      "y": 1,
      "z": 19,
      "name": "Soil_Dirt"
    },
    {
      "x": -31,
      "y": 2,
      "z": 19,
      "name": "Soil_Dirt"
    },
    {
      "x": -31,
      "y": 1,
      "z": 20,
      "name": "Soil_Dirt"
    },
    {
      "x": -31,
      "y": 2,
      "z": 20,
      "name": "Soil_Dirt"
    },
    {
      "x": -31,
      "y": 1,
      "z": 21,
      "name": "Soil_Dirt"
    },
    {
      "x": -31,
      "y": 2,
      "z": 21,
      "name": "Soil_Dirt"
    },
    {
      "x": -31,
      "y": 1,
      "z": 22,
      "name": "Soil_Dirt"
    },
    {
      "x": -31,
      "y": 1,
      "z": 23,
      "name": "Soil_Dirt"
    },
    {
      "x": -31,
      "y": 1,
      "z": 24,
      "name": "Soil_Dirt"
    },
    {
      "x": -31,
      "y": 1,
      "z": 25,
      "name": "Soil_Dirt"
    },
    {
      "x": -31,
      "y": 1,
      "z": 26,
      "name": "Soil_Dirt"
    },
    {
      "x": -31,
      "y": 1,
      "z": 27,
      "name": "Soil_Dirt"
    },
    {
      "x": -31,
      "y": 1,
      "z": 28,
      "name": "Soil_Dirt"
    },
    {
      "x": -31,
      "y": 1,
      "z": 29,
      "name": "Soil_Dirt"
    },
    {
      "x": -31,
      "y": 1,
      "z": 30,
      "name": "Soil_Dirt"
    },
    {
      "x": -31,
      "y": 1,
      "z": 31,
      "name": "Soil_Dirt"
    },
    {
      "x": -30,
      "y": 1,
      "z": -26,
      "name": "Soil_Dirt"
    },
    {
      "x": -30,
      "y": 1,
      "z": -25,
      "name": "Soil_Dirt"
    },
    {
      "x": -30,
      "y": 1,
      "z": -24,
      "name": "Soil_Dirt"
    },
    {
      "x": -30,
      "y": 1,
      "z": -23,
      "name": "Soil_Dirt"
    },
    {
      "x": -30,
      "y": 1,
      "z": -22,
      "name": "Soil_Dirt"
    },
    {
      "x": -30,
      "y": 1,
      "z": -21,
      "name": "Soil_Dirt"
    },
    {
      "x": -30,
      "y": 1,
      "z": -20,
      "name": "Soil_Dirt"
    },
    {
      "x": -30,
      "y": 1,
      "z": -19,
      "name": "Soil_Dirt"
    },
    {
      "x": -30,
      "y": 1,
      "z": -18,
      "name": "Soil_Dirt"
    },
    {
      "x": -30,
      "y": 1,
      "z": -17,
      "name": "Soil_Dirt"
    },
    {
      "x": -30,
      "y": 1,
      "z": -16,
      "name": "Soil_Dirt"
    },
    {
      "x": -30,
      "y": 2,
      "z": -16,
      "name": "Soil_Dirt"
    },
    {
      "x": -30,
      "y": 1,
      "z": -15,
      "name": "Soil_Dirt"
    },
    {
      "x": -30,
      "y": 2,
      "z": -15,
      "name": "Soil_Dirt"
    },
    {
      "x": -30,
      "y": 1,
      "z": -14,
      "name": "Soil_Dirt"
    },
    {
      "x": -30,
      "y": 2,
      "z": -14,
      "name": "Soil_Dirt"
    },
    {
      "x": -30,
      "y": 1,
      "z": -13,
      "name": "Soil_Dirt"
    },
    {
      "x": -30,
      "y": 2,
      "z": -13,
      "name": "Soil_Dirt"
    },
    {
      "x": -30,
      "y": 1,
      "z": -12,
      "name": "Soil_Dirt"
    },
    {
      "x": -30,
      "y": 2,
      "z": -12,
      "name": "Soil_Dirt"
    },
    {
      "x": -30,
      "y": 1,
      "z": -11,
      "name": "Soil_Dirt"
    },
    {
      "x": -30,
      "y": 2,
      "z": -11,
      "name": "Soil_Dirt"
    },
    {
      "x": -30,
      "y": 1,
      "z": -10,
      "name": "Soil_Dirt"
    },
    {
      "x": -30,
      "y": 2,
      "z": -10,
      "name": "Soil_Dirt"
    },
    {
      "x": -30,
      "y": 1,
      "z": -9,
      "name": "Soil_Dirt"
    },
    {
      "x": -30,
      "y": 2,
      "z": -9,
      "name": "Soil_Dirt"
    },
    {
      "x": -30,
      "y": 1,
      "z": -8,
      "name": "Soil_Dirt"
    },
    {
      "x": -30,
      "y": 2,
      "z": -8,
      "name": "Soil_Dirt"
    },
    {
      "x": -30,
      "y": 1,
      "z": -7,
      "name": "Soil_Dirt"
    },
    {
      "x": -30,
      "y": 2,
      "z": -7,
      "name": "Soil_Dirt"
    },
    {
      "x": -30,
      "y": 1,
      "z": -6,
      "name": "Soil_Dirt"
    },
    {
      "x": -30,
      "y": 2,
      "z": -6,
      "name": "Soil_Dirt"
    },
    {
      "x": -30,
      "y": 1,
      "z": -5,
      "name": "Soil_Dirt"
    },
    {
      "x": -30,
      "y": 2,
      "z": -5,
      "name": "Soil_Dirt"
    },
    {
      "x": -30,
      "y": 1,
      "z": -4,
      "name": "Soil_Dirt"
    },
    {
      "x": -30,
      "y": 2,
      "z": -4,
      "name": "Soil_Dirt"
    },
    {
      "x": -30,
      "y": 1,
      "z": -3,
      "name": "Soil_Dirt"
    },
    {
      "x": -30,
      "y": 2,
      "z": -3,
      "name": "Soil_Dirt"
    },
    {
      "x": -30,
      "y": 1,
      "z": -2,
      "name": "Soil_Dirt"
    },
    {
      "x": -30,
      "y": 2,
      "z": -2,
      "name": "Soil_Dirt"
    },
    {
      "x": -30,
      "y": 1,
      "z": -1,
      "name": "Soil_Dirt"
    },
    {
      "x": -30,
      "y": 2,
      "z": -1,
      "name": "Soil_Dirt"
    },
    {
      "x": -30,
      "y": 1,
      "z": 0,
      "name": "Soil_Dirt"
    },
    {
      "x": -30,
      "y": 2,
      "z": 0,
      "name": "Soil_Dirt"
    },
    {
      "x": -30,
      "y": 1,
      "z": 1,
      "name": "Soil_Dirt"
    },
    {
      "x": -30,
      "y": 2,
      "z": 1,
      "name": "Soil_Dirt"
    },
    {
      "x": -30,
      "y": 1,
      "z": 2,
      "name": "Soil_Dirt"
    },
    {
      "x": -30,
      "y": 2,
      "z": 2,
      "name": "Soil_Dirt"
    },
    {
      "x": -30,
      "y": 1,
      "z": 3,
      "name": "Soil_Dirt"
    },
    {
      "x": -30,
      "y": 2,
      "z": 3,
      "name": "Soil_Dirt"
    },
    {
      "x": -30,
      "y": 1,
      "z": 4,
      "name": "Soil_Dirt"
    },
    {
      "x": -30,
      "y": 2,
      "z": 4,
      "name": "Soil_Dirt"
    },
    {
      "x": -30,
      "y": 1,
      "z": 5,
      "name": "Soil_Dirt"
    },
    {
      "x": -30,
      "y": 2,
      "z": 5,
      "name": "Soil_Dirt"
    },
    {
      "x": -30,
      "y": 1,
      "z": 6,
      "name": "Soil_Dirt"
    },
    {
      "x": -30,
      "y": 2,
      "z": 6,
      "name": "Soil_Dirt"
    },
    {
      "x": -30,
      "y": 1,
      "z": 7,
      "name": "Soil_Dirt"
    },
    {
      "x": -30,
      "y": 2,
      "z": 7,
      "name": "Soil_Dirt"
    },
    {
      "x": -30,
      "y": 1,
      "z": 8,
      "name": "Soil_Dirt"
    },
    {
      "x": -30,
      "y": 2,
      "z": 8,
      "name": "Soil_Dirt"
    },
    {
      "x": -30,
      "y": 1,
      "z": 9,
      "name": "Soil_Dirt"
    },
    {
      "x": -30,
      "y": 2,
      "z": 9,
      "name": "Soil_Dirt"
    },
    {
      "x": -30,
      "y": 1,
      "z": 10,
      "name": "Soil_Dirt"
    },
    {
      "x": -30,
      "y": 2,
      "z": 10,
      "name": "Soil_Dirt"
    },
    {
      "x": -30,
      "y": 1,
      "z": 11,
      "name": "Soil_Dirt"
    },
    {
      "x": -30,
      "y": 2,
      "z": 11,
      "name": "Soil_Dirt"
    },
    {
      "x": -30,
      "y": 1,
      "z": 12,
      "name": "Soil_Dirt"
    },
    {
      "x": -30,
      "y": 2,
      "z": 12,
      "name": "Soil_Dirt"
    },
    {
      "x": -30,
      "y": 1,
      "z": 13,
      "name": "Soil_Dirt"
    },
    {
      "x": -30,
      "y": 2,
      "z": 13,
      "name": "Soil_Dirt"
    },
    {
      "x": -30,
      "y": 1,
      "z": 14,
      "name": "Soil_Dirt"
    },
    {
      "x": -30,
      "y": 2,
      "z": 14,
      "name": "Soil_Dirt"
    },
    {
      "x": -30,
      "y": 1,
      "z": 15,
      "name": "Soil_Dirt"
    },
    {
      "x": -30,
      "y": 2,
      "z": 15,
      "name": "Soil_Dirt"
    },
    {
      "x": -30,
      "y": 1,
      "z": 16,
      "name": "Soil_Dirt"
    },
    {
      "x": -30,
      "y": 2,
      "z": 16,
      "name": "Soil_Dirt"
    },
    {
      "x": -30,
      "y": 1,
      "z": 17,
      "name": "Soil_Dirt"
    },
    {
      "x": -30,
      "y": 2,
      "z": 17,
      "name": "Soil_Dirt"
    },
    {
      "x": -30,
      "y": 1,
      "z": 18,
      "name": "Soil_Dirt"
    },
    {
      "x": -30,
      "y": 2,
      "z": 18,
      "name": "Soil_Dirt"
    },
    {
      "x": -30,
      "y": 1,
      "z": 19,
      "name": "Soil_Dirt"
    },
    {
      "x": -30,
      "y": 2,
      "z": 19,
      "name": "Soil_Dirt"
    },
    {
      "x": -30,
      "y": 1,
      "z": 20,
      "name": "Soil_Dirt"
    },
    {
      "x": -30,
      "y": 2,
      "z": 20,
      "name": "Soil_Dirt"
    },
    {
      "x": -30,
      "y": 1,
      "z": 21,
      "name": "Soil_Dirt"
    },
    {
      "x": -30,
      "y": 2,
      "z": 21,
      "name": "Soil_Dirt"
    },
    {
      "x": -30,
      "y": 1,
      "z": 22,
      "name": "Soil_Dirt"
    },
    {
      "x": -30,
      "y": 2,
      "z": 22,
      "name": "Soil_Dirt"
    },
    {
      "x": -30,
      "y": 1,
      "z": 23,
      "name": "Soil_Dirt"
    },
    {
      "x": -30,
      "y": 1,
      "z": 24,
      "name": "Soil_Dirt"
    },
    {
      "x": -30,
      "y": 2,
      "z": 24,
      "name": "Soil_Dirt"
    },
    {
      "x": -30,
      "y": 1,
      "z": 25,
      "name": "Soil_Dirt"
    },
    {
      "x": -30,
      "y": 2,
      "z": 25,
      "name": "Soil_Dirt"
    },
    {
      "x": -30,
      "y": 1,
      "z": 26,
      "name": "Soil_Dirt"
    },
    {
      "x": -30,
      "y": 2,
      "z": 26,
      "name": "Soil_Dirt"
    },
    {
      "x": -30,
      "y": 1,
      "z": 27,
      "name": "Soil_Dirt"
    },
    {
      "x": -30,
      "y": 1,
      "z": 28,
      "name": "Soil_Dirt"
    },
    {
      "x": -30,
      "y": 1,
      "z": 29,
      "name": "Soil_Dirt"
    },
    {
      "x": -30,
      "y": 1,
      "z": 30,
      "name": "Soil_Dirt"
    },
    {
      "x": -30,
      "y": 1,
      "z": 31,
      "name": "Soil_Dirt"
    },
    {
      "x": -30,
      "y": 1,
      "z": 32,
      "name": "Soil_Dirt"
    },
    {
      "x": -29,
      "y": 1,
      "z": -27,
      "name": "Soil_Dirt"
    },
    {
      "x": -29,
      "y": 1,
      "z": -26,
      "name": "Soil_Dirt"
    },
    {
      "x": -29,
      "y": 1,
      "z": -25,
      "name": "Soil_Dirt"
    },
    {
      "x": -29,
      "y": 1,
      "z": -24,
      "name": "Soil_Dirt"
    },
    {
      "x": -29,
      "y": 1,
      "z": -23,
      "name": "Soil_Dirt"
    },
    {
      "x": -29,
      "y": 1,
      "z": -22,
      "name": "Soil_Dirt"
    },
    {
      "x": -29,
      "y": 1,
      "z": -21,
      "name": "Soil_Dirt"
    },
    {
      "x": -29,
      "y": 1,
      "z": -20,
      "name": "Soil_Dirt"
    },
    {
      "x": -29,
      "y": 1,
      "z": -19,
      "name": "Soil_Dirt"
    },
    {
      "x": -29,
      "y": 2,
      "z": -19,
      "name": "Soil_Dirt"
    },
    {
      "x": -29,
      "y": 1,
      "z": -18,
      "name": "Soil_Dirt"
    },
    {
      "x": -29,
      "y": 2,
      "z": -18,
      "name": "Soil_Dirt"
    },
    {
      "x": -29,
      "y": 1,
      "z": -17,
      "name": "Soil_Dirt"
    },
    {
      "x": -29,
      "y": 2,
      "z": -17,
      "name": "Soil_Dirt"
    },
    {
      "x": -29,
      "y": 1,
      "z": -16,
      "name": "Soil_Dirt"
    },
    {
      "x": -29,
      "y": 2,
      "z": -16,
      "name": "Soil_Dirt"
    },
    {
      "x": -29,
      "y": 1,
      "z": -15,
      "name": "Soil_Dirt"
    },
    {
      "x": -29,
      "y": 2,
      "z": -15,
      "name": "Soil_Dirt"
    },
    {
      "x": -29,
      "y": 1,
      "z": -14,
      "name": "Soil_Dirt"
    },
    {
      "x": -29,
      "y": 2,
      "z": -14,
      "name": "Soil_Dirt"
    },
    {
      "x": -29,
      "y": 1,
      "z": -13,
      "name": "Soil_Dirt"
    },
    {
      "x": -29,
      "y": 2,
      "z": -13,
      "name": "Soil_Dirt"
    },
    {
      "x": -29,
      "y": 1,
      "z": -12,
      "name": "Rock_Stone"
    },
    {
      "x": -29,
      "y": 2,
      "z": -12,
      "name": "Soil_Dirt"
    },
    {
      "x": -29,
      "y": 3,
      "z": -12,
      "name": "Soil_Dirt"
    },
    {
      "x": -29,
      "y": 1,
      "z": -11,
      "name": "Rock_Stone"
    },
    {
      "x": -29,
      "y": 2,
      "z": -11,
      "name": "Soil_Dirt"
    },
    {
      "x": -29,
      "y": 3,
      "z": -11,
      "name": "Soil_Dirt"
    },
    {
      "x": -29,
      "y": 0,
      "z": -10,
      "name": "Rock_Stone"
    },
    {
      "x": -29,
      "y": 1,
      "z": -10,
      "name": "Rock_Stone"
    },
    {
      "x": -29,
      "y": 2,
      "z": -10,
      "name": "Soil_Dirt"
    },
    {
      "x": -29,
      "y": 3,
      "z": -10,
      "name": "Soil_Dirt"
    },
    {
      "x": -29,
      "y": 0,
      "z": -9,
      "name": "Rock_Stone"
    },
    {
      "x": -29,
      "y": 1,
      "z": -9,
      "name": "Rock_Stone"
    },
    {
      "x": -29,
      "y": 2,
      "z": -9,
      "name": "Soil_Dirt"
    },
    {
      "x": -29,
      "y": 3,
      "z": -9,
      "name": "Soil_Dirt"
    },
    {
      "x": -29,
      "y": 0,
      "z": -8,
      "name": "Rock_Stone"
    },
    {
      "x": -29,
      "y": 1,
      "z": -8,
      "name": "Rock_Stone"
    },
    {
      "x": -29,
      "y": 2,
      "z": -8,
      "name": "Soil_Dirt"
    },
    {
      "x": -29,
      "y": 3,
      "z": -8,
      "name": "Soil_Dirt"
    },
    {
      "x": -29,
      "y": 0,
      "z": -7,
      "name": "Rock_Stone"
    },
    {
      "x": -29,
      "y": 1,
      "z": -7,
      "name": "Rock_Stone"
    },
    {
      "x": -29,
      "y": 2,
      "z": -7,
      "name": "Soil_Dirt"
    },
    {
      "x": -29,
      "y": 3,
      "z": -7,
      "name": "Soil_Dirt"
    },
    {
      "x": -29,
      "y": 0,
      "z": -6,
      "name": "Rock_Stone"
    },
    {
      "x": -29,
      "y": 1,
      "z": -6,
      "name": "Rock_Stone"
    },
    {
      "x": -29,
      "y": 2,
      "z": -6,
      "name": "Soil_Dirt"
    },
    {
      "x": -29,
      "y": 3,
      "z": -6,
      "name": "Soil_Dirt"
    },
    {
      "x": -29,
      "y": 0,
      "z": -5,
      "name": "Rock_Stone"
    },
    {
      "x": -29,
      "y": 1,
      "z": -5,
      "name": "Rock_Stone"
    },
    {
      "x": -29,
      "y": 2,
      "z": -5,
      "name": "Soil_Dirt"
    },
    {
      "x": -29,
      "y": 3,
      "z": -5,
      "name": "Soil_Dirt"
    },
    {
      "x": -29,
      "y": 0,
      "z": -4,
      "name": "Rock_Stone"
    },
    {
      "x": -29,
      "y": 1,
      "z": -4,
      "name": "Rock_Stone"
    },
    {
      "x": -29,
      "y": 2,
      "z": -4,
      "name": "Soil_Dirt"
    },
    {
      "x": -29,
      "y": 3,
      "z": -4,
      "name": "Soil_Dirt"
    },
    {
      "x": -29,
      "y": 0,
      "z": -3,
      "name": "Rock_Stone"
    },
    {
      "x": -29,
      "y": 1,
      "z": -3,
      "name": "Rock_Stone"
    },
    {
      "x": -29,
      "y": 2,
      "z": -3,
      "name": "Soil_Dirt"
    },
    {
      "x": -29,
      "y": 3,
      "z": -3,
      "name": "Soil_Dirt"
    },
    {
      "x": -29,
      "y": 0,
      "z": -2,
      "name": "Rock_Stone"
    },
    {
      "x": -29,
      "y": 1,
      "z": -2,
      "name": "Rock_Stone"
    },
    {
      "x": -29,
      "y": 2,
      "z": -2,
      "name": "Soil_Dirt"
    },
    {
      "x": -29,
      "y": 3,
      "z": -2,
      "name": "Soil_Dirt"
    },
    {
      "x": -29,
      "y": 1,
      "z": -1,
      "name": "Rock_Stone"
    },
    {
      "x": -29,
      "y": 2,
      "z": -1,
      "name": "Soil_Dirt"
    },
    {
      "x": -29,
      "y": 3,
      "z": -1,
      "name": "Soil_Dirt"
    },
    {
      "x": -29,
      "y": 1,
      "z": 0,
      "name": "Rock_Stone"
    },
    {
      "x": -29,
      "y": 2,
      "z": 0,
      "name": "Soil_Dirt"
    },
    {
      "x": -29,
      "y": 3,
      "z": 0,
      "name": "Soil_Dirt"
    },
    {
      "x": -29,
      "y": 1,
      "z": 1,
      "name": "Soil_Dirt"
    },
    {
      "x": -29,
      "y": 2,
      "z": 1,
      "name": "Soil_Pathway"
    },
    {
      "x": -29,
      "y": 3,
      "z": 1,
      "name": "Soil_Dirt"
    },
    {
      "x": -29,
      "y": 1,
      "z": 2,
      "name": "Soil_Dirt"
    },
    {
      "x": -29,
      "y": 2,
      "z": 2,
      "name": "Soil_Pathway"
    },
    {
      "x": -29,
      "y": 3,
      "z": 2,
      "name": "Soil_Dirt"
    },
    {
      "x": -29,
      "y": 1,
      "z": 3,
      "name": "Soil_Dirt"
    },
    {
      "x": -29,
      "y": 2,
      "z": 3,
      "name": "Soil_Pathway"
    },
    {
      "x": -29,
      "y": 3,
      "z": 3,
      "name": "Soil_Dirt"
    },
    {
      "x": -29,
      "y": 1,
      "z": 4,
      "name": "Soil_Dirt"
    },
    {
      "x": -29,
      "y": 2,
      "z": 4,
      "name": "Soil_Pathway"
    },
    {
      "x": -29,
      "y": 3,
      "z": 4,
      "name": "Soil_Dirt"
    },
    {
      "x": -29,
      "y": 9,
      "z": 4,
      "name": "Wood_Beech_Branch_Corner",
      "support": 15,
      "rotation": 3
    },
    {
      "x": -29,
      "y": 1,
      "z": 5,
      "name": "Soil_Dirt"
    },
    {
      "x": -29,
      "y": 2,
      "z": 5,
      "name": "Soil_Pathway"
    },
    {
      "x": -29,
      "y": 3,
      "z": 5,
      "name": "Soil_Dirt"
    },
    {
      "x": -29,
      "y": 1,
      "z": 6,
      "name": "Soil_Dirt"
    },
    {
      "x": -29,
      "y": 2,
      "z": 6,
      "name": "Soil_Pathway"
    },
    {
      "x": -29,
      "y": 3,
      "z": 6,
      "name": "Soil_Dirt"
    },
    {
      "x": -29,
      "y": 1,
      "z": 7,
      "name": "Soil_Dirt"
    },
    {
      "x": -29,
      "y": 2,
      "z": 7,
      "name": "Soil_Pathway"
    },
    {
      "x": -29,
      "y": 3,
      "z": 7,
      "name": "Soil_Dirt"
    },
    {
      "x": -29,
      "y": 1,
      "z": 8,
      "name": "Rock_Stone"
    },
    {
      "x": -29,
      "y": 2,
      "z": 8,
      "name": "Soil_Dirt"
    },
    {
      "x": -29,
      "y": 3,
      "z": 8,
      "name": "Soil_Dirt"
    },
    {
      "x": -29,
      "y": 1,
      "z": 9,
      "name": "Rock_Stone"
    },
    {
      "x": -29,
      "y": 2,
      "z": 9,
      "name": "Soil_Dirt"
    },
    {
      "x": -29,
      "y": 3,
      "z": 9,
      "name": "Soil_Dirt"
    },
    {
      "x": -29,
      "y": 0,
      "z": 10,
      "name": "Rock_Stone"
    },
    {
      "x": -29,
      "y": 1,
      "z": 10,
      "name": "Rock_Stone"
    },
    {
      "x": -29,
      "y": 2,
      "z": 10,
      "name": "Soil_Dirt"
    },
    {
      "x": -29,
      "y": 3,
      "z": 10,
      "name": "Soil_Dirt"
    },
    {
      "x": -29,
      "y": 0,
      "z": 11,
      "name": "Rock_Stone"
    },
    {
      "x": -29,
      "y": 1,
      "z": 11,
      "name": "Rock_Stone"
    },
    {
      "x": -29,
      "y": 2,
      "z": 11,
      "name": "Soil_Dirt"
    },
    {
      "x": -29,
      "y": 3,
      "z": 11,
      "name": "Soil_Dirt"
    },
    {
      "x": -29,
      "y": 0,
      "z": 12,
      "name": "Rock_Stone"
    },
    {
      "x": -29,
      "y": 1,
      "z": 12,
      "name": "Rock_Stone"
    },
    {
      "x": -29,
      "y": 2,
      "z": 12,
      "name": "Soil_Dirt"
    },
    {
      "x": -29,
      "y": 3,
      "z": 12,
      "name": "Soil_Dirt"
    },
    {
      "x": -29,
      "y": 0,
      "z": 13,
      "name": "Rock_Stone"
    },
    {
      "x": -29,
      "y": 1,
      "z": 13,
      "name": "Rock_Stone"
    },
    {
      "x": -29,
      "y": 2,
      "z": 13,
      "name": "Soil_Dirt"
    },
    {
      "x": -29,
      "y": 3,
      "z": 13,
      "name": "Soil_Dirt"
    },
    {
      "x": -29,
      "y": 0,
      "z": 14,
      "name": "Rock_Stone"
    },
    {
      "x": -29,
      "y": 1,
      "z": 14,
      "name": "Rock_Stone"
    },
    {
      "x": -29,
      "y": 2,
      "z": 14,
      "name": "Soil_Dirt"
    },
    {
      "x": -29,
      "y": 3,
      "z": 14,
      "name": "Soil_Dirt"
    },
    {
      "x": -29,
      "y": 0,
      "z": 15,
      "name": "Rock_Stone"
    },
    {
      "x": -29,
      "y": 1,
      "z": 15,
      "name": "Rock_Stone"
    },
    {
      "x": -29,
      "y": 2,
      "z": 15,
      "name": "Soil_Dirt"
    },
    {
      "x": -29,
      "y": 3,
      "z": 15,
      "name": "Soil_Dirt"
    },
    {
      "x": -29,
      "y": 0,
      "z": 16,
      "name": "Rock_Stone"
    },
    {
      "x": -29,
      "y": 1,
      "z": 16,
      "name": "Rock_Stone"
    },
    {
      "x": -29,
      "y": 2,
      "z": 16,
      "name": "Soil_Dirt"
    },
    {
      "x": -29,
      "y": 3,
      "z": 16,
      "name": "Soil_Dirt"
    },
    {
      "x": -29,
      "y": 0,
      "z": 17,
      "name": "Rock_Stone"
    },
    {
      "x": -29,
      "y": 1,
      "z": 17,
      "name": "Rock_Stone"
    },
    {
      "x": -29,
      "y": 2,
      "z": 17,
      "name": "Soil_Dirt"
    },
    {
      "x": -29,
      "y": 3,
      "z": 17,
      "name": "Soil_Dirt"
    },
    {
      "x": -29,
      "y": 0,
      "z": 18,
      "name": "Rock_Stone"
    },
    {
      "x": -29,
      "y": 1,
      "z": 18,
      "name": "Rock_Stone"
    },
    {
      "x": -29,
      "y": 2,
      "z": 18,
      "name": "Soil_Dirt"
    },
    {
      "x": -29,
      "y": 3,
      "z": 18,
      "name": "Soil_Dirt"
    },
    {
      "x": -29,
      "y": 1,
      "z": 19,
      "name": "Rock_Stone"
    },
    {
      "x": -29,
      "y": 2,
      "z": 19,
      "name": "Soil_Dirt"
    },
    {
      "x": -29,
      "y": 3,
      "z": 19,
      "name": "Soil_Dirt"
    },
    {
      "x": -29,
      "y": 1,
      "z": 20,
      "name": "Rock_Stone"
    },
    {
      "x": -29,
      "y": 2,
      "z": 20,
      "name": "Soil_Dirt"
    },
    {
      "x": -29,
      "y": 3,
      "z": 20,
      "name": "Soil_Dirt"
    },
    {
      "x": -29,
      "y": 1,
      "z": 21,
      "name": "Soil_Dirt"
    },
    {
      "x": -29,
      "y": 2,
      "z": 21,
      "name": "Soil_Dirt"
    },
    {
      "x": -29,
      "y": 1,
      "z": 22,
      "name": "Soil_Dirt"
    },
    {
      "x": -29,
      "y": 2,
      "z": 22,
      "name": "Soil_Dirt"
    },
    {
      "x": -29,
      "y": 1,
      "z": 23,
      "name": "Soil_Dirt"
    },
    {
      "x": -29,
      "y": 2,
      "z": 23,
      "name": "Soil_Dirt"
    },
    {
      "x": -29,
      "y": 1,
      "z": 24,
      "name": "Soil_Dirt"
    },
    {
      "x": -29,
      "y": 2,
      "z": 24,
      "name": "Soil_Dirt"
    },
    {
      "x": -29,
      "y": 1,
      "z": 25,
      "name": "Soil_Dirt"
    },
    {
      "x": -29,
      "y": 2,
      "z": 25,
      "name": "Soil_Dirt"
    },
    {
      "x": -29,
      "y": 1,
      "z": 26,
      "name": "Soil_Dirt"
    },
    {
      "x": -29,
      "y": 2,
      "z": 26,
      "name": "Soil_Dirt"
    },
    {
      "x": -29,
      "y": 1,
      "z": 27,
      "name": "Soil_Dirt"
    },
    {
      "x": -29,
      "y": 2,
      "z": 27,
      "name": "Soil_Dirt"
    },
    {
      "x": -29,
      "y": 1,
      "z": 28,
      "name": "Soil_Dirt"
    },
    {
      "x": -29,
      "y": 2,
      "z": 28,
      "name": "Soil_Dirt"
    },
    {
      "x": -29,
      "y": 1,
      "z": 29,
      "name": "Soil_Dirt"
    },
    {
      "x": -29,
      "y": 1,
      "z": 30,
      "name": "Soil_Dirt"
    },
    {
      "x": -29,
      "y": 1,
      "z": 31,
      "name": "Soil_Dirt"
    },
    {
      "x": -29,
      "y": 1,
      "z": 32,
      "name": "Soil_Dirt"
    },
    {
      "x": -29,
      "y": 1,
      "z": 33,
      "name": "Soil_Dirt"
    },
    {
      "x": -28,
      "y": 1,
      "z": -28,
      "name": "Soil_Dirt"
    },
    {
      "x": -28,
      "y": 1,
      "z": -27,
      "name": "Soil_Dirt"
    },
    {
      "x": -28,
      "y": 1,
      "z": -26,
      "name": "Soil_Dirt"
    },
    {
      "x": -28,
      "y": 1,
      "z": -25,
      "name": "Soil_Dirt"
    },
    {
      "x": -28,
      "y": 1,
      "z": -24,
      "name": "Soil_Dirt"
    },
    {
      "x": -28,
      "y": 1,
      "z": -23,
      "name": "Soil_Dirt"
    },
    {
      "x": -28,
      "y": 1,
      "z": -22,
      "name": "Soil_Dirt"
    },
    {
      "x": -28,
      "y": 1,
      "z": -21,
      "name": "Soil_Dirt"
    },
    {
      "x": -28,
      "y": 2,
      "z": -21,
      "name": "Soil_Dirt"
    },
    {
      "x": -28,
      "y": 1,
      "z": -20,
      "name": "Soil_Dirt"
    },
    {
      "x": -28,
      "y": 2,
      "z": -20,
      "name": "Soil_Dirt"
    },
    {
      "x": -28,
      "y": 1,
      "z": -19,
      "name": "Soil_Dirt"
    },
    {
      "x": -28,
      "y": 2,
      "z": -19,
      "name": "Soil_Dirt"
    },
    {
      "x": -28,
      "y": 1,
      "z": -18,
      "name": "Soil_Dirt"
    },
    {
      "x": -28,
      "y": 2,
      "z": -18,
      "name": "Soil_Dirt"
    },
    {
      "x": -28,
      "y": 1,
      "z": -17,
      "name": "Soil_Dirt"
    },
    {
      "x": -28,
      "y": 2,
      "z": -17,
      "name": "Soil_Dirt"
    },
    {
      "x": -28,
      "y": 1,
      "z": -16,
      "name": "Soil_Dirt"
    },
    {
      "x": -28,
      "y": 2,
      "z": -16,
      "name": "Soil_Dirt"
    },
    {
      "x": -28,
      "y": 1,
      "z": -15,
      "name": "Soil_Dirt"
    },
    {
      "x": -28,
      "y": 2,
      "z": -15,
      "name": "Soil_Dirt"
    },
    {
      "x": -28,
      "y": 1,
      "z": -14,
      "name": "Rock_Stone"
    },
    {
      "x": -28,
      "y": 2,
      "z": -14,
      "name": "Soil_Dirt"
    },
    {
      "x": -28,
      "y": 3,
      "z": -14,
      "name": "Soil_Dirt"
    },
    {
      "x": -28,
      "y": 0,
      "z": -13,
      "name": "Rock_Stone"
    },
    {
      "x": -28,
      "y": 1,
      "z": -13,
      "name": "Rock_Stone"
    },
    {
      "x": -28,
      "y": 2,
      "z": -13,
      "name": "Soil_Dirt"
    },
    {
      "x": -28,
      "y": 3,
      "z": -13,
      "name": "Soil_Dirt"
    },
    {
      "x": -28,
      "y": 0,
      "z": -12,
      "name": "Rock_Stone"
    },
    {
      "x": -28,
      "y": 1,
      "z": -12,
      "name": "Rock_Stone"
    },
    {
      "x": -28,
      "y": 2,
      "z": -12,
      "name": "Soil_Dirt"
    },
    {
      "x": -28,
      "y": 3,
      "z": -12,
      "name": "Soil_Dirt"
    },
    {
      "x": -28,
      "y": 0,
      "z": -11,
      "name": "Rock_Stone"
    },
    {
      "x": -28,
      "y": 1,
      "z": -11,
      "name": "Rock_Stone"
    },
    {
      "x": -28,
      "y": 2,
      "z": -11,
      "name": "Soil_Dirt"
    },
    {
      "x": -28,
      "y": 3,
      "z": -11,
      "name": "Soil_Dirt"
    },
    {
      "x": -28,
      "y": 0,
      "z": -10,
      "name": "Rock_Stone"
    },
    {
      "x": -28,
      "y": 1,
      "z": -10,
      "name": "Rock_Stone"
    },
    {
      "x": -28,
      "y": 2,
      "z": -10,
      "name": "Soil_Dirt"
    },
    {
      "x": -28,
      "y": 3,
      "z": -10,
      "name": "Soil_Dirt"
    },
    {
      "x": -28,
      "y": 0,
      "z": -9,
      "name": "Rock_Stone"
    },
    {
      "x": -28,
      "y": 1,
      "z": -9,
      "name": "Rock_Stone"
    },
    {
      "x": -28,
      "y": 2,
      "z": -9,
      "name": "Soil_Dirt"
    },
    {
      "x": -28,
      "y": 3,
      "z": -9,
      "name": "Soil_Dirt"
    },
    {
      "x": -28,
      "y": 0,
      "z": -8,
      "name": "Rock_Stone"
    },
    {
      "x": -28,
      "y": 1,
      "z": -8,
      "name": "Rock_Stone"
    },
    {
      "x": -28,
      "y": 2,
      "z": -8,
      "name": "Soil_Dirt"
    },
    {
      "x": -28,
      "y": 3,
      "z": -8,
      "name": "Soil_Dirt"
    },
    {
      "x": -28,
      "y": 0,
      "z": -7,
      "name": "Rock_Stone"
    },
    {
      "x": -28,
      "y": 1,
      "z": -7,
      "name": "Rock_Stone"
    },
    {
      "x": -28,
      "y": 2,
      "z": -7,
      "name": "Soil_Dirt"
    },
    {
      "x": -28,
      "y": 3,
      "z": -7,
      "name": "Soil_Dirt"
    },
    {
      "x": -28,
      "y": 0,
      "z": -6,
      "name": "Rock_Stone"
    },
    {
      "x": -28,
      "y": 1,
      "z": -6,
      "name": "Rock_Stone"
    },
    {
      "x": -28,
      "y": 2,
      "z": -6,
      "name": "Soil_Dirt"
    },
    {
      "x": -28,
      "y": 3,
      "z": -6,
      "name": "Soil_Dirt"
    },
    {
      "x": -28,
      "y": 0,
      "z": -5,
      "name": "Rock_Stone"
    },
    {
      "x": -28,
      "y": 1,
      "z": -5,
      "name": "Rock_Stone"
    },
    {
      "x": -28,
      "y": 2,
      "z": -5,
      "name": "Soil_Dirt"
    },
    {
      "x": -28,
      "y": 3,
      "z": -5,
      "name": "Soil_Dirt"
    },
    {
      "x": -28,
      "y": 0,
      "z": -4,
      "name": "Rock_Stone"
    },
    {
      "x": -28,
      "y": 1,
      "z": -4,
      "name": "Rock_Stone"
    },
    {
      "x": -28,
      "y": 2,
      "z": -4,
      "name": "Soil_Dirt"
    },
    {
      "x": -28,
      "y": 3,
      "z": -4,
      "name": "Soil_Dirt"
    },
    {
      "x": -28,
      "y": 0,
      "z": -3,
      "name": "Rock_Stone"
    },
    {
      "x": -28,
      "y": 1,
      "z": -3,
      "name": "Rock_Stone"
    },
    {
      "x": -28,
      "y": 2,
      "z": -3,
      "name": "Soil_Dirt"
    },
    {
      "x": -28,
      "y": 3,
      "z": -3,
      "name": "Soil_Dirt"
    },
    {
      "x": -28,
      "y": 0,
      "z": -2,
      "name": "Rock_Stone"
    },
    {
      "x": -28,
      "y": 1,
      "z": -2,
      "name": "Rock_Stone"
    },
    {
      "x": -28,
      "y": 2,
      "z": -2,
      "name": "Soil_Dirt"
    },
    {
      "x": -28,
      "y": 3,
      "z": -2,
      "name": "Soil_Dirt"
    },
    {
      "x": -28,
      "y": 0,
      "z": -1,
      "name": "Rock_Stone"
    },
    {
      "x": -28,
      "y": 1,
      "z": -1,
      "name": "Rock_Stone"
    },
    {
      "x": -28,
      "y": 2,
      "z": -1,
      "name": "Soil_Dirt"
    },
    {
      "x": -28,
      "y": 3,
      "z": -1,
      "name": "Soil_Dirt"
    },
    {
      "x": -28,
      "y": 0,
      "z": 0,
      "name": "Rock_Stone"
    },
    {
      "x": -28,
      "y": 1,
      "z": 0,
      "name": "Rock_Stone"
    },
    {
      "x": -28,
      "y": 2,
      "z": 0,
      "name": "Soil_Dirt"
    },
    {
      "x": -28,
      "y": 3,
      "z": 0,
      "name": "Rock_Chalk"
    },
    {
      "x": -28,
      "y": 4,
      "z": 0,
      "name": "Rock_Chalk"
    },
    {
      "x": -28,
      "y": 0,
      "z": 1,
      "name": "Rock_Stone"
    },
    {
      "x": -28,
      "y": 1,
      "z": 1,
      "name": "Rock_Stone"
    },
    {
      "x": -28,
      "y": 2,
      "z": 1,
      "name": "Soil_Dirt"
    },
    {
      "x": -28,
      "y": 3,
      "z": 1,
      "name": "Rock_Chalk"
    },
    {
      "x": -28,
      "y": 4,
      "z": 1,
      "name": "Rock_Chalk"
    },
    {
      "x": -28,
      "y": 1,
      "z": 2,
      "name": "Rock_Stone"
    },
    {
      "x": -28,
      "y": 2,
      "z": 2,
      "name": "Soil_Dirt"
    },
    {
      "x": -28,
      "y": 3,
      "z": 2,
      "name": "Rock_Chalk"
    },
    {
      "x": -28,
      "y": 4,
      "z": 2,
      "name": "Rock_Chalk"
    },
    {
      "x": -28,
      "y": 5,
      "z": 2,
      "name": "Rock_Chalk"
    },
    {
      "x": -28,
      "y": 1,
      "z": 3,
      "name": "Soil_Dirt"
    },
    {
      "x": -28,
      "y": 2,
      "z": 3,
      "name": "Soil_Pathway"
    },
    {
      "x": -28,
      "y": 3,
      "z": 3,
      "name": "Rock_Chalk"
    },
    {
      "x": -28,
      "y": 4,
      "z": 3,
      "name": "Rock_Chalk"
    },
    {
      "x": -28,
      "y": 5,
      "z": 3,
      "name": "Rock_Chalk"
    },
    {
      "x": -28,
      "y": 6,
      "z": 3,
      "name": "Rock_Chalk"
    },
    {
      "x": -28,
      "y": 7,
      "z": 3,
      "name": "Wood_Beech_Trunk",
      "support": 15
    },
    {
      "x": -28,
      "y": 8,
      "z": 3,
      "name": "Wood_Beech_Trunk",
      "support": 15
    },
    {
      "x": -28,
      "y": 9,
      "z": 3,
      "name": "Wood_Beech_Trunk",
      "support": 15
    },
    {
      "x": -28,
      "y": 10,
      "z": 3,
      "name": "Wood_Beech_Trunk",
      "support": 15
    },
    {
      "x": -28,
      "y": 11,
      "z": 3,
      "name": "Plant_Leaves_Bramble",
      "support": 15
    },
    {
      "x": -28,
      "y": 1,
      "z": 4,
      "name": "Soil_Dirt"
    },
    {
      "x": -28,
      "y": 2,
      "z": 4,
      "name": "Soil_Pathway"
    },
    {
      "x": -28,
      "y": 3,
      "z": 4,
      "name": "Rock_Chalk"
    },
    {
      "x": -28,
      "y": 4,
      "z": 4,
      "name": "Rock_Chalk"
    },
    {
      "x": -28,
      "y": 5,
      "z": 4,
      "name": "Rock_Chalk"
    },
    {
      "x": -28,
      "y": 6,
      "z": 4,
      "name": "Rock_Chalk"
    },
    {
      "x": -28,
      "y": 7,
      "z": 4,
      "name": "Wood_Beech_Trunk",
      "support": 15
    },
    {
      "x": -28,
      "y": 8,
      "z": 4,
      "name": "Wood_Beech_Trunk",
      "support": 15
    },
    {
      "x": -28,
      "y": 9,
      "z": 4,
      "name": "Wood_Beech_Trunk",
      "support": 15
    },
    {
      "x": -28,
      "y": 1,
      "z": 5,
      "name": "Soil_Dirt"
    },
    {
      "x": -28,
      "y": 2,
      "z": 5,
      "name": "Soil_Pathway"
    },
    {
      "x": -28,
      "y": 3,
      "z": 5,
      "name": "Rock_Chalk"
    },
    {
      "x": -28,
      "y": 4,
      "z": 5,
      "name": "Rock_Chalk"
    },
    {
      "x": -28,
      "y": 5,
      "z": 5,
      "name": "Rock_Chalk"
    },
    {
      "x": -28,
      "y": 6,
      "z": 5,
      "name": "Rock_Chalk"
    },
    {
      "x": -28,
      "y": 1,
      "z": 6,
      "name": "Rock_Stone"
    },
    {
      "x": -28,
      "y": 2,
      "z": 6,
      "name": "Soil_Dirt"
    },
    {
      "x": -28,
      "y": 3,
      "z": 6,
      "name": "Rock_Chalk"
    },
    {
      "x": -28,
      "y": 4,
      "z": 6,
      "name": "Rock_Chalk"
    },
    {
      "x": -28,
      "y": 5,
      "z": 6,
      "name": "Rock_Chalk"
    },
    {
      "x": -28,
      "y": 0,
      "z": 7,
      "name": "Rock_Stone"
    },
    {
      "x": -28,
      "y": 1,
      "z": 7,
      "name": "Rock_Stone"
    },
    {
      "x": -28,
      "y": 2,
      "z": 7,
      "name": "Soil_Dirt"
    },
    {
      "x": -28,
      "y": 3,
      "z": 7,
      "name": "Rock_Chalk"
    },
    {
      "x": -28,
      "y": 4,
      "z": 7,
      "name": "Rock_Chalk"
    },
    {
      "x": -28,
      "y": 0,
      "z": 8,
      "name": "Rock_Stone"
    },
    {
      "x": -28,
      "y": 1,
      "z": 8,
      "name": "Rock_Stone"
    },
    {
      "x": -28,
      "y": 2,
      "z": 8,
      "name": "Soil_Dirt"
    },
    {
      "x": -28,
      "y": 3,
      "z": 8,
      "name": "Rock_Chalk"
    },
    {
      "x": -28,
      "y": 0,
      "z": 9,
      "name": "Rock_Stone"
    },
    {
      "x": -28,
      "y": 1,
      "z": 9,
      "name": "Rock_Stone"
    },
    {
      "x": -28,
      "y": 2,
      "z": 9,
      "name": "Soil_Dirt"
    },
    {
      "x": -28,
      "y": 3,
      "z": 9,
      "name": "Soil_Dirt"
    },
    {
      "x": -28,
      "y": 0,
      "z": 10,
      "name": "Rock_Stone"
    },
    {
      "x": -28,
      "y": 1,
      "z": 10,
      "name": "Rock_Stone"
    },
    {
      "x": -28,
      "y": 2,
      "z": 10,
      "name": "Soil_Dirt"
    },
    {
      "x": -28,
      "y": 3,
      "z": 10,
      "name": "Soil_Dirt"
    },
    {
      "x": -28,
      "y": 0,
      "z": 11,
      "name": "Rock_Stone"
    },
    {
      "x": -28,
      "y": 1,
      "z": 11,
      "name": "Rock_Stone"
    },
    {
      "x": -28,
      "y": 2,
      "z": 11,
      "name": "Soil_Dirt"
    },
    {
      "x": -28,
      "y": 3,
      "z": 11,
      "name": "Soil_Dirt"
    },
    {
      "x": -28,
      "y": 0,
      "z": 12,
      "name": "Rock_Stone"
    },
    {
      "x": -28,
      "y": 1,
      "z": 12,
      "name": "Rock_Stone"
    },
    {
      "x": -28,
      "y": 2,
      "z": 12,
      "name": "Soil_Dirt"
    },
    {
      "x": -28,
      "y": 3,
      "z": 12,
      "name": "Soil_Dirt"
    },
    {
      "x": -28,
      "y": 0,
      "z": 13,
      "name": "Rock_Stone"
    },
    {
      "x": -28,
      "y": 1,
      "z": 13,
      "name": "Rock_Stone"
    },
    {
      "x": -28,
      "y": 2,
      "z": 13,
      "name": "Soil_Dirt"
    },
    {
      "x": -28,
      "y": 3,
      "z": 13,
      "name": "Soil_Dirt"
    },
    {
      "x": -28,
      "y": 4,
      "z": 13,
      "name": "Wood_Beech_Trunk",
      "support": 15
    },
    {
      "x": -28,
      "y": 5,
      "z": 13,
      "name": "Wood_Beech_Trunk",
      "support": 15
    },
    {
      "x": -28,
      "y": 6,
      "z": 13,
      "name": "Wood_Beech_Trunk",
      "support": 15
    },
    {
      "x": -28,
      "y": 0,
      "z": 14,
      "name": "Rock_Stone"
    },
    {
      "x": -28,
      "y": 1,
      "z": 14,
      "name": "Rock_Stone"
    },
    {
      "x": -28,
      "y": 2,
      "z": 14,
      "name": "Soil_Dirt"
    },
    {
      "x": -28,
      "y": 3,
      "z": 14,
      "name": "Soil_Dirt"
    },
    {
      "x": -28,
      "y": 4,
      "z": 14,
      "name": "Wood_Beech_Trunk",
      "support": 15
    },
    {
      "x": -28,
      "y": 5,
      "z": 14,
      "name": "Wood_Beech_Trunk",
      "support": 15
    },
    {
      "x": -28,
      "y": 6,
      "z": 14,
      "name": "Wood_Beech_Trunk",
      "support": 15
    },
    {
      "x": -28,
      "y": 7,
      "z": 14,
      "name": "Wood_Beech_Trunk",
      "support": 15
    },
    {
      "x": -28,
      "y": 0,
      "z": 15,
      "name": "Rock_Stone"
    },
    {
      "x": -28,
      "y": 1,
      "z": 15,
      "name": "Rock_Stone"
    },
    {
      "x": -28,
      "y": 2,
      "z": 15,
      "name": "Soil_Dirt"
    },
    {
      "x": -28,
      "y": 3,
      "z": 15,
      "name": "Soil_Dirt"
    },
    {
      "x": -28,
      "y": 0,
      "z": 16,
      "name": "Rock_Stone"
    },
    {
      "x": -28,
      "y": 1,
      "z": 16,
      "name": "Rock_Stone"
    },
    {
      "x": -28,
      "y": 2,
      "z": 16,
      "name": "Soil_Dirt"
    },
    {
      "x": -28,
      "y": 3,
      "z": 16,
      "name": "Soil_Dirt"
    },
    {
      "x": -28,
      "y": 0,
      "z": 17,
      "name": "Rock_Stone"
    },
    {
      "x": -28,
      "y": 1,
      "z": 17,
      "name": "Rock_Stone"
    },
    {
      "x": -28,
      "y": 2,
      "z": 17,
      "name": "Soil_Dirt"
    },
    {
      "x": -28,
      "y": 3,
      "z": 17,
      "name": "Soil_Dirt"
    },
    {
      "x": -28,
      "y": 0,
      "z": 18,
      "name": "Rock_Stone"
    },
    {
      "x": -28,
      "y": 1,
      "z": 18,
      "name": "Rock_Stone"
    },
    {
      "x": -28,
      "y": 2,
      "z": 18,
      "name": "Soil_Dirt"
    },
    {
      "x": -28,
      "y": 3,
      "z": 18,
      "name": "Soil_Dirt"
    },
    {
      "x": -28,
      "y": 10,
      "z": 18,
      "name": "Wood_Beech_Branch_Corner",
      "support": 15,
      "rotation": 3
    },
    {
      "x": -28,
      "y": 0,
      "z": 19,
      "name": "Rock_Stone"
    },
    {
      "x": -28,
      "y": 1,
      "z": 19,
      "name": "Rock_Stone"
    },
    {
      "x": -28,
      "y": 2,
      "z": 19,
      "name": "Soil_Dirt"
    },
    {
      "x": -28,
      "y": 3,
      "z": 19,
      "name": "Soil_Dirt"
    },
    {
      "x": -28,
      "y": 0,
      "z": 20,
      "name": "Rock_Stone"
    },
    {
      "x": -28,
      "y": 1,
      "z": 20,
      "name": "Rock_Stone"
    },
    {
      "x": -28,
      "y": 2,
      "z": 20,
      "name": "Soil_Dirt"
    },
    {
      "x": -28,
      "y": 3,
      "z": 20,
      "name": "Soil_Dirt"
    },
    {
      "x": -28,
      "y": 0,
      "z": 21,
      "name": "Rock_Stone"
    },
    {
      "x": -28,
      "y": 1,
      "z": 21,
      "name": "Rock_Stone"
    },
    {
      "x": -28,
      "y": 2,
      "z": 21,
      "name": "Soil_Dirt"
    },
    {
      "x": -28,
      "y": 3,
      "z": 21,
      "name": "Soil_Dirt"
    },
    {
      "x": -28,
      "y": 1,
      "z": 22,
      "name": "Rock_Stone"
    },
    {
      "x": -28,
      "y": 2,
      "z": 22,
      "name": "Soil_Dirt"
    },
    {
      "x": -28,
      "y": 3,
      "z": 22,
      "name": "Soil_Dirt"
    },
    {
      "x": -28,
      "y": 1,
      "z": 23,
      "name": "Soil_Dirt"
    },
    {
      "x": -28,
      "y": 2,
      "z": 23,
      "name": "Soil_Dirt"
    },
    {
      "x": -28,
      "y": 1,
      "z": 24,
      "name": "Soil_Dirt"
    },
    {
      "x": -28,
      "y": 2,
      "z": 24,
      "name": "Soil_Dirt"
    },
    {
      "x": -28,
      "y": 1,
      "z": 25,
      "name": "Soil_Dirt"
    },
    {
      "x": -28,
      "y": 2,
      "z": 25,
      "name": "Soil_Dirt"
    },
    {
      "x": -28,
      "y": 1,
      "z": 26,
      "name": "Soil_Dirt"
    },
    {
      "x": -28,
      "y": 2,
      "z": 26,
      "name": "Soil_Dirt"
    },
    {
      "x": -28,
      "y": 1,
      "z": 27,
      "name": "Soil_Dirt"
    },
    {
      "x": -28,
      "y": 2,
      "z": 27,
      "name": "Soil_Dirt"
    },
    {
      "x": -28,
      "y": 1,
      "z": 28,
      "name": "Soil_Dirt"
    },
    {
      "x": -28,
      "y": 2,
      "z": 28,
      "name": "Soil_Dirt"
    },
    {
      "x": -28,
      "y": 1,
      "z": 29,
      "name": "Soil_Dirt"
    },
    {
      "x": -28,
      "y": 1,
      "z": 30,
      "name": "Soil_Dirt"
    },
    {
      "x": -28,
      "y": 1,
      "z": 31,
      "name": "Soil_Dirt"
    },
    {
      "x": -28,
      "y": 1,
      "z": 32,
      "name": "Soil_Dirt"
    },
    {
      "x": -28,
      "y": 1,
      "z": 33,
      "name": "Soil_Dirt"
    },
    {
      "x": -28,
      "y": 1,
      "z": 34,
      "name": "Soil_Dirt"
    },
    {
      "x": -27,
      "y": 1,
      "z": -29,
      "name": "Soil_Dirt"
    },
    {
      "x": -27,
      "y": 1,
      "z": -28,
      "name": "Soil_Dirt"
    },
    {
      "x": -27,
      "y": 1,
      "z": -27,
      "name": "Soil_Dirt"
    },
    {
      "x": -27,
      "y": 1,
      "z": -26,
      "name": "Soil_Dirt"
    },
    {
      "x": -27,
      "y": 1,
      "z": -25,
      "name": "Soil_Dirt"
    },
    {
      "x": -27,
      "y": 1,
      "z": -24,
      "name": "Soil_Dirt"
    },
    {
      "x": -27,
      "y": 1,
      "z": -23,
      "name": "Soil_Dirt"
    },
    {
      "x": -27,
      "y": 1,
      "z": -22,
      "name": "Soil_Dirt"
    },
    {
      "x": -27,
      "y": 1,
      "z": -21,
      "name": "Soil_Dirt"
    },
    {
      "x": -27,
      "y": 2,
      "z": -21,
      "name": "Soil_Dirt"
    },
    {
      "x": -27,
      "y": 1,
      "z": -20,
      "name": "Soil_Dirt"
    },
    {
      "x": -27,
      "y": 2,
      "z": -20,
      "name": "Soil_Dirt"
    },
    {
      "x": -27,
      "y": 1,
      "z": -19,
      "name": "Soil_Dirt"
    },
    {
      "x": -27,
      "y": 2,
      "z": -19,
      "name": "Soil_Dirt"
    },
    {
      "x": -27,
      "y": 1,
      "z": -18,
      "name": "Soil_Dirt"
    },
    {
      "x": -27,
      "y": 2,
      "z": -18,
      "name": "Soil_Dirt"
    },
    {
      "x": -27,
      "y": 4,
      "z": -18,
      "name": "Empty"
    },
    {
      "x": -27,
      "y": 5,
      "z": -18,
      "name": "Empty"
    },
    {
      "x": -27,
      "y": 6,
      "z": -18,
      "name": "Empty"
    },
    {
      "x": -27,
      "y": 7,
      "z": -18,
      "name": "Empty"
    },
    {
      "x": -27,
      "y": 8,
      "z": -18,
      "name": "Empty"
    },
    {
      "x": -27,
      "y": 9,
      "z": -18,
      "name": "Empty"
    },
    {
      "x": -27,
      "y": 1,
      "z": -17,
      "name": "Soil_Dirt"
    },
    {
      "x": -27,
      "y": 2,
      "z": -17,
      "name": "Soil_Dirt"
    },
    {
      "x": -27,
      "y": 4,
      "z": -17,
      "name": "Empty"
    },
    {
      "x": -27,
      "y": 5,
      "z": -17,
      "name": "Empty"
    },
    {
      "x": -27,
      "y": 6,
      "z": -17,
      "name": "Empty"
    },
    {
      "x": -27,
      "y": 7,
      "z": -17,
      "name": "Empty"
    },
    {
      "x": -27,
      "y": 8,
      "z": -17,
      "name": "Empty"
    },
    {
      "x": -27,
      "y": 9,
      "z": -17,
      "name": "Empty"
    },
    {
      "x": -27,
      "y": 1,
      "z": -16,
      "name": "Rock_Stone"
    },
    {
      "x": -27,
      "y": 2,
      "z": -16,
      "name": "Soil_Dirt"
    },
    {
      "x": -27,
      "y": 3,
      "z": -16,
      "name": "Soil_Dirt"
    },
    {
      "x": -27,
      "y": 4,
      "z": -16,
      "name": "Empty"
    },
    {
      "x": -27,
      "y": 5,
      "z": -16,
      "name": "Empty"
    },
    {
      "x": -27,
      "y": 6,
      "z": -16,
      "name": "Empty"
    },
    {
      "x": -27,
      "y": 7,
      "z": -16,
      "name": "Empty"
    },
    {
      "x": -27,
      "y": 8,
      "z": -16,
      "name": "Empty"
    },
    {
      "x": -27,
      "y": 9,
      "z": -16,
      "name": "Empty"
    },
    {
      "x": -27,
      "y": 0,
      "z": -15,
      "name": "Rock_Stone"
    },
    {
      "x": -27,
      "y": 1,
      "z": -15,
      "name": "Rock_Stone"
    },
    {
      "x": -27,
      "y": 2,
      "z": -15,
      "name": "Soil_Dirt"
    },
    {
      "x": -27,
      "y": 3,
      "z": -15,
      "name": "Soil_Dirt"
    },
    {
      "x": -27,
      "y": 4,
      "z": -15,
      "name": "Empty"
    },
    {
      "x": -27,
      "y": 5,
      "z": -15,
      "name": "Empty"
    },
    {
      "x": -27,
      "y": 6,
      "z": -15,
      "name": "Empty"
    },
    {
      "x": -27,
      "y": 7,
      "z": -15,
      "name": "Empty"
    },
    {
      "x": -27,
      "y": 0,
      "z": -14,
      "name": "Rock_Stone"
    },
    {
      "x": -27,
      "y": 1,
      "z": -14,
      "name": "Rock_Stone"
    },
    {
      "x": -27,
      "y": 2,
      "z": -14,
      "name": "Soil_Dirt"
    },
    {
      "x": -27,
      "y": 3,
      "z": -14,
      "name": "Soil_Dirt"
    },
    {
      "x": -27,
      "y": 4,
      "z": -14,
      "name": "Empty"
    },
    {
      "x": -27,
      "y": 5,
      "z": -14,
      "name": "Empty"
    },
    {
      "x": -27,
      "y": 6,
      "z": -14,
      "name": "Empty"
    },
    {
      "x": -27,
      "y": 7,
      "z": -14,
      "name": "Empty"
    },
    {
      "x": -27,
      "y": 0,
      "z": -13,
      "name": "Rock_Stone"
    },
    {
      "x": -27,
      "y": 1,
      "z": -13,
      "name": "Rock_Stone"
    },
    {
      "x": -27,
      "y": 2,
      "z": -13,
      "name": "Soil_Dirt"
    },
    {
      "x": -27,
      "y": 3,
      "z": -13,
      "name": "Soil_Dirt"
    },
    {
      "x": -27,
      "y": 4,
      "z": -13,
      "name": "Empty"
    },
    {
      "x": -27,
      "y": 5,
      "z": -13,
      "name": "Empty"
    },
    {
      "x": -27,
      "y": 6,
      "z": -13,
      "name": "Empty"
    },
    {
      "x": -27,
      "y": 7,
      "z": -13,
      "name": "Empty"
    },
    {
      "x": -27,
      "y": 8,
      "z": -13,
      "name": "Empty"
    },
    {
      "x": -27,
      "y": 9,
      "z": -13,
      "name": "Empty"
    },
    {
      "x": -27,
      "y": 10,
      "z": -13,
      "name": "Empty"
    },
    {
      "x": -27,
      "y": 11,
      "z": -13,
      "name": "Empty"
    },
    {
      "x": -27,
      "y": 12,
      "z": -13,
      "name": "Empty"
    },
    {
      "x": -27,
      "y": 0,
      "z": -12,
      "name": "Rock_Stone"
    },
    {
      "x": -27,
      "y": 1,
      "z": -12,
      "name": "Rock_Stone"
    },
    {
      "x": -27,
      "y": 2,
      "z": -12,
      "name": "Soil_Dirt"
    },
    {
      "x": -27,
      "y": 3,
      "z": -12,
      "name": "Soil_Dirt"
    },
    {
      "x": -27,
      "y": 7,
      "z": -12,
      "name": "Empty"
    },
    {
      "x": -27,
      "y": 8,
      "z": -12,
      "name": "Empty"
    },
    {
      "x": -27,
      "y": 9,
      "z": -12,
      "name": "Empty"
    },
    {
      "x": -27,
      "y": 10,
      "z": -12,
      "name": "Empty"
    },
    {
      "x": -27,
      "y": 11,
      "z": -12,
      "name": "Empty"
    },
    {
      "x": -27,
      "y": 12,
      "z": -12,
      "name": "Empty"
    },
    {
      "x": -27,
      "y": 0,
      "z": -11,
      "name": "Rock_Stone"
    },
    {
      "x": -27,
      "y": 1,
      "z": -11,
      "name": "Rock_Stone"
    },
    {
      "x": -27,
      "y": 2,
      "z": -11,
      "name": "Soil_Dirt"
    },
    {
      "x": -27,
      "y": 3,
      "z": -11,
      "name": "Soil_Dirt"
    },
    {
      "x": -27,
      "y": 7,
      "z": -11,
      "name": "Empty"
    },
    {
      "x": -27,
      "y": 8,
      "z": -11,
      "name": "Empty"
    },
    {
      "x": -27,
      "y": 9,
      "z": -11,
      "name": "Empty"
    },
    {
      "x": -27,
      "y": 10,
      "z": -11,
      "name": "Empty"
    },
    {
      "x": -27,
      "y": 11,
      "z": -11,
      "name": "Empty"
    },
    {
      "x": -27,
      "y": 12,
      "z": -11,
      "name": "Empty"
    },
    {
      "x": -27,
      "y": 0,
      "z": -10,
      "name": "Rock_Stone"
    },
    {
      "x": -27,
      "y": 1,
      "z": -10,
      "name": "Rock_Stone"
    },
    {
      "x": -27,
      "y": 2,
      "z": -10,
      "name": "Soil_Dirt"
    },
    {
      "x": -27,
      "y": 3,
      "z": -10,
      "name": "Soil_Dirt"
    },
    {
      "x": -27,
      "y": 0,
      "z": -9,
      "name": "Rock_Stone"
    },
    {
      "x": -27,
      "y": 1,
      "z": -9,
      "name": "Rock_Stone"
    },
    {
      "x": -27,
      "y": 2,
      "z": -9,
      "name": "Soil_Dirt"
    },
    {
      "x": -27,
      "y": 3,
      "z": -9,
      "name": "Soil_Dirt"
    },
    {
      "x": -27,
      "y": 0,
      "z": -8,
      "name": "Rock_Stone"
    },
    {
      "x": -27,
      "y": 1,
      "z": -8,
      "name": "Rock_Stone"
    },
    {
      "x": -27,
      "y": 2,
      "z": -8,
      "name": "Soil_Dirt"
    },
    {
      "x": -27,
      "y": 3,
      "z": -8,
      "name": "Soil_Dirt"
    },
    {
      "x": -27,
      "y": 0,
      "z": -7,
      "name": "Rock_Stone"
    },
    {
      "x": -27,
      "y": 1,
      "z": -7,
      "name": "Rock_Stone"
    },
    {
      "x": -27,
      "y": 2,
      "z": -7,
      "name": "Soil_Dirt"
    },
    {
      "x": -27,
      "y": 3,
      "z": -7,
      "name": "Soil_Dirt"
    },
    {
      "x": -27,
      "y": 0,
      "z": -6,
      "name": "Rock_Stone"
    },
    {
      "x": -27,
      "y": 1,
      "z": -6,
      "name": "Rock_Stone"
    },
    {
      "x": -27,
      "y": 2,
      "z": -6,
      "name": "Soil_Dirt"
    },
    {
      "x": -27,
      "y": 3,
      "z": -6,
      "name": "Soil_Dirt"
    },
    {
      "x": -27,
      "y": 0,
      "z": -5,
      "name": "Rock_Stone"
    },
    {
      "x": -27,
      "y": 1,
      "z": -5,
      "name": "Rock_Stone"
    },
    {
      "x": -27,
      "y": 2,
      "z": -5,
      "name": "Soil_Dirt"
    },
    {
      "x": -27,
      "y": 3,
      "z": -5,
      "name": "Soil_Dirt"
    },
    {
      "x": -27,
      "y": 0,
      "z": -4,
      "name": "Rock_Stone"
    },
    {
      "x": -27,
      "y": 1,
      "z": -4,
      "name": "Rock_Stone"
    },
    {
      "x": -27,
      "y": 2,
      "z": -4,
      "name": "Soil_Dirt"
    },
    {
      "x": -27,
      "y": 3,
      "z": -4,
      "name": "Soil_Dirt"
    },
    {
      "x": -27,
      "y": 0,
      "z": -3,
      "name": "Rock_Stone"
    },
    {
      "x": -27,
      "y": 1,
      "z": -3,
      "name": "Rock_Stone"
    },
    {
      "x": -27,
      "y": 2,
      "z": -3,
      "name": "Soil_Dirt"
    },
    {
      "x": -27,
      "y": 3,
      "z": -3,
      "name": "Soil_Dirt"
    },
    {
      "x": -27,
      "y": 0,
      "z": -2,
      "name": "Rock_Stone"
    },
    {
      "x": -27,
      "y": 1,
      "z": -2,
      "name": "Rock_Stone"
    },
    {
      "x": -27,
      "y": 2,
      "z": -2,
      "name": "Soil_Dirt"
    },
    {
      "x": -27,
      "y": 3,
      "z": -2,
      "name": "Soil_Dirt"
    },
    {
      "x": -27,
      "y": 8,
      "z": -2,
      "name": "Wood_Beech_Branch_Long",
      "support": 15,
      "rotation": 5
    },
    {
      "x": -27,
      "y": 0,
      "z": -1,
      "name": "Rock_Stone"
    },
    {
      "x": -27,
      "y": 1,
      "z": -1,
      "name": "Rock_Stone"
    },
    {
      "x": -27,
      "y": 2,
      "z": -1,
      "name": "Soil_Dirt"
    },
    {
      "x": -27,
      "y": 3,
      "z": -1,
      "name": "Soil_Dirt"
    },
    {
      "x": -27,
      "y": 0,
      "z": 0,
      "name": "Rock_Stone"
    },
    {
      "x": -27,
      "y": 1,
      "z": 0,
      "name": "Rock_Stone"
    },
    {
      "x": -27,
      "y": 2,
      "z": 0,
      "name": "Soil_Dirt"
    },
    {
      "x": -27,
      "y": 3,
      "z": 0,
      "name": "Rock_Chalk"
    },
    {
      "x": -27,
      "y": 4,
      "z": 0,
      "name": "Rock_Chalk"
    },
    {
      "x": -27,
      "y": 5,
      "z": 0,
      "name": "Rock_Chalk"
    },
    {
      "x": -27,
      "y": 0,
      "z": 1,
      "name": "Rock_Stone"
    },
    {
      "x": -27,
      "y": 1,
      "z": 1,
      "name": "Rock_Stone"
    },
    {
      "x": -27,
      "y": 2,
      "z": 1,
      "name": "Soil_Dirt"
    },
    {
      "x": -27,
      "y": 3,
      "z": 1,
      "name": "Rock_Chalk"
    },
    {
      "x": -27,
      "y": 4,
      "z": 1,
      "name": "Rock_Chalk"
    },
    {
      "x": -27,
      "y": 5,
      "z": 1,
      "name": "Rock_Chalk"
    },
    {
      "x": -27,
      "y": 6,
      "z": 1,
      "name": "Rock_Chalk"
    },
    {
      "x": -27,
      "y": 7,
      "z": 1,
      "name": "Rock_Chalk"
    },
    {
      "x": -27,
      "y": 0,
      "z": 2,
      "name": "Rock_Stone"
    },
    {
      "x": -27,
      "y": 1,
      "z": 2,
      "name": "Rock_Stone"
    },
    {
      "x": -27,
      "y": 2,
      "z": 2,
      "name": "Soil_Dirt"
    },
    {
      "x": -27,
      "y": 3,
      "z": 2,
      "name": "Rock_Chalk"
    },
    {
      "x": -27,
      "y": 4,
      "z": 2,
      "name": "Rock_Chalk"
    },
    {
      "x": -27,
      "y": 5,
      "z": 2,
      "name": "Rock_Chalk"
    },
    {
      "x": -27,
      "y": 6,
      "z": 2,
      "name": "Rock_Chalk"
    },
    {
      "x": -27,
      "y": 7,
      "z": 2,
      "name": "Rock_Chalk"
    },
    {
      "x": -27,
      "y": 8,
      "z": 2,
      "name": "Rock_Chalk"
    },
    {
      "x": -27,
      "y": 0,
      "z": 3,
      "name": "Rock_Stone"
    },
    {
      "x": -27,
      "y": 1,
      "z": 3,
      "name": "Rock_Stone"
    },
    {
      "x": -27,
      "y": 2,
      "z": 3,
      "name": "Soil_Dirt"
    },
    {
      "x": -27,
      "y": 3,
      "z": 3,
      "name": "Rock_Chalk"
    },
    {
      "x": -27,
      "y": 4,
      "z": 3,
      "name": "Rock_Chalk"
    },
    {
      "x": -27,
      "y": 5,
      "z": 3,
      "name": "Rock_Chalk"
    },
    {
      "x": -27,
      "y": 6,
      "z": 3,
      "name": "Rock_Chalk"
    },
    {
      "x": -27,
      "y": 7,
      "z": 3,
      "name": "Rock_Chalk"
    },
    {
      "x": -27,
      "y": 8,
      "z": 3,
      "name": "Rock_Chalk"
    },
    {
      "x": -27,
      "y": 9,
      "z": 3,
      "name": "Wood_Beech_Trunk",
      "support": 15
    },
    {
      "x": -27,
      "y": 10,
      "z": 3,
      "name": "Wood_Beech_Trunk",
      "support": 15
    },
    {
      "x": -27,
      "y": 11,
      "z": 3,
      "name": "Wood_Beech_Trunk",
      "support": 15
    },
    {
      "x": -27,
      "y": 1,
      "z": 4,
      "name": "Rock_Stone"
    },
    {
      "x": -27,
      "y": 2,
      "z": 4,
      "name": "Soil_Dirt"
    },
    {
      "x": -27,
      "y": 3,
      "z": 4,
      "name": "Rock_Chalk"
    },
    {
      "x": -27,
      "y": 4,
      "z": 4,
      "name": "Rock_Chalk"
    },
    {
      "x": -27,
      "y": 5,
      "z": 4,
      "name": "Rock_Chalk"
    },
    {
      "x": -27,
      "y": 6,
      "z": 4,
      "name": "Rock_Chalk"
    },
    {
      "x": -27,
      "y": 7,
      "z": 4,
      "name": "Rock_Chalk"
    },
    {
      "x": -27,
      "y": 8,
      "z": 4,
      "name": "Rock_Chalk"
    },
    {
      "x": -27,
      "y": 9,
      "z": 4,
      "name": "Wood_Beech_Trunk",
      "support": 15
    },
    {
      "x": -27,
      "y": 10,
      "z": 4,
      "name": "Wood_Beech_Trunk",
      "support": 15
    },
    {
      "x": -27,
      "y": 11,
      "z": 4,
      "name": "Wood_Beech_Trunk",
      "support": 15
    },
    {
      "x": -27,
      "y": 12,
      "z": 4,
      "name": "Wood_Beech_Trunk",
      "support": 15
    },
    {
      "x": -27,
      "y": 13,
      "z": 4,
      "name": "Wood_Beech_Branch_Long",
      "support": 15
    },
    {
      "x": -27,
      "y": 14,
      "z": 4,
      "name": "Furniture_Crude_Torch",
      "rotation": 2
    },
    {
      "x": -27,
      "y": 0,
      "z": 5,
      "name": "Rock_Stone"
    },
    {
      "x": -27,
      "y": 1,
      "z": 5,
      "name": "Rock_Stone"
    },
    {
      "x": -27,
      "y": 2,
      "z": 5,
      "name": "Soil_Dirt"
    },
    {
      "x": -27,
      "y": 3,
      "z": 5,
      "name": "Rock_Chalk"
    },
    {
      "x": -27,
      "y": 4,
      "z": 5,
      "name": "Rock_Chalk"
    },
    {
      "x": -27,
      "y": 5,
      "z": 5,
      "name": "Rock_Chalk"
    },
    {
      "x": -27,
      "y": 6,
      "z": 5,
      "name": "Rock_Chalk"
    },
    {
      "x": -27,
      "y": 7,
      "z": 5,
      "name": "Rock_Chalk"
    },
    {
      "x": -27,
      "y": 8,
      "z": 5,
      "name": "Rock_Chalk"
    },
    {
      "x": -27,
      "y": 0,
      "z": 6,
      "name": "Rock_Stone"
    },
    {
      "x": -27,
      "y": 1,
      "z": 6,
      "name": "Rock_Stone"
    },
    {
      "x": -27,
      "y": 2,
      "z": 6,
      "name": "Soil_Dirt"
    },
    {
      "x": -27,
      "y": 3,
      "z": 6,
      "name": "Rock_Chalk"
    },
    {
      "x": -27,
      "y": 4,
      "z": 6,
      "name": "Rock_Chalk"
    },
    {
      "x": -27,
      "y": 5,
      "z": 6,
      "name": "Rock_Chalk"
    },
    {
      "x": -27,
      "y": 6,
      "z": 6,
      "name": "Rock_Chalk"
    },
    {
      "x": -27,
      "y": 7,
      "z": 6,
      "name": "Rock_Chalk"
    },
    {
      "x": -27,
      "y": 8,
      "z": 6,
      "name": "Deco_Bone_Skulls"
    },
    {
      "x": -27,
      "y": 0,
      "z": 7,
      "name": "Rock_Stone"
    },
    {
      "x": -27,
      "y": 1,
      "z": 7,
      "name": "Rock_Stone"
    },
    {
      "x": -27,
      "y": 2,
      "z": 7,
      "name": "Soil_Dirt"
    },
    {
      "x": -27,
      "y": 3,
      "z": 7,
      "name": "Rock_Chalk"
    },
    {
      "x": -27,
      "y": 4,
      "z": 7,
      "name": "Rock_Chalk"
    },
    {
      "x": -27,
      "y": 5,
      "z": 7,
      "name": "Rock_Chalk"
    },
    {
      "x": -27,
      "y": 6,
      "z": 7,
      "name": "Rock_Chalk"
    },
    {
      "x": -27,
      "y": 0,
      "z": 8,
      "name": "Rock_Stone"
    },
    {
      "x": -27,
      "y": 1,
      "z": 8,
      "name": "Rock_Stone"
    },
    {
      "x": -27,
      "y": 2,
      "z": 8,
      "name": "Soil_Dirt"
    },
    {
      "x": -27,
      "y": 3,
      "z": 8,
      "name": "Rock_Chalk"
    },
    {
      "x": -27,
      "y": 4,
      "z": 8,
      "name": "Rock_Chalk"
    },
    {
      "x": -27,
      "y": 5,
      "z": 8,
      "name": "Rock_Chalk"
    },
    {
      "x": -27,
      "y": 0,
      "z": 9,
      "name": "Rock_Stone"
    },
    {
      "x": -27,
      "y": 1,
      "z": 9,
      "name": "Rock_Stone"
    },
    {
      "x": -27,
      "y": 2,
      "z": 9,
      "name": "Soil_Dirt"
    },
    {
      "x": -27,
      "y": 3,
      "z": 9,
      "name": "Rock_Chalk"
    },
    {
      "x": -27,
      "y": 4,
      "z": 9,
      "name": "Rock_Chalk"
    },
    {
      "x": -27,
      "y": 0,
      "z": 10,
      "name": "Rock_Stone"
    },
    {
      "x": -27,
      "y": 1,
      "z": 10,
      "name": "Rock_Stone"
    },
    {
      "x": -27,
      "y": 2,
      "z": 10,
      "name": "Soil_Dirt"
    },
    {
      "x": -27,
      "y": 3,
      "z": 10,
      "name": "Soil_Dirt"
    },
    {
      "x": -27,
      "y": 0,
      "z": 11,
      "name": "Rock_Stone"
    },
    {
      "x": -27,
      "y": 1,
      "z": 11,
      "name": "Rock_Stone"
    },
    {
      "x": -27,
      "y": 2,
      "z": 11,
      "name": "Soil_Dirt"
    },
    {
      "x": -27,
      "y": 3,
      "z": 11,
      "name": "Soil_Dirt"
    },
    {
      "x": -27,
      "y": 4,
      "z": 11,
      "name": "Rock_Chalk"
    },
    {
      "x": -27,
      "y": 5,
      "z": 11,
      "name": "Rock_Chalk"
    },
    {
      "x": -27,
      "y": 0,
      "z": 12,
      "name": "Rock_Stone"
    },
    {
      "x": -27,
      "y": 1,
      "z": 12,
      "name": "Rock_Stone"
    },
    {
      "x": -27,
      "y": 2,
      "z": 12,
      "name": "Soil_Dirt"
    },
    {
      "x": -27,
      "y": 3,
      "z": 12,
      "name": "Soil_Dirt"
    },
    {
      "x": -27,
      "y": 4,
      "z": 12,
      "name": "Rock_Chalk"
    },
    {
      "x": -27,
      "y": 5,
      "z": 12,
      "name": "Rock_Chalk"
    },
    {
      "x": -27,
      "y": 0,
      "z": 13,
      "name": "Rock_Stone"
    },
    {
      "x": -27,
      "y": 1,
      "z": 13,
      "name": "Rock_Stone"
    },
    {
      "x": -27,
      "y": 2,
      "z": 13,
      "name": "Soil_Dirt"
    },
    {
      "x": -27,
      "y": 3,
      "z": 13,
      "name": "Soil_Dirt"
    },
    {
      "x": -27,
      "y": 4,
      "z": 13,
      "name": "Wood_Beech_Trunk",
      "support": 15
    },
    {
      "x": -27,
      "y": 5,
      "z": 13,
      "name": "Wood_Beech_Trunk",
      "support": 15
    },
    {
      "x": -27,
      "y": 6,
      "z": 13,
      "name": "Wood_Beech_Trunk",
      "support": 15
    },
    {
      "x": -27,
      "y": 7,
      "z": 13,
      "name": "Wood_Beech_Trunk",
      "support": 15
    },
    {
      "x": -27,
      "y": 8,
      "z": 13,
      "name": "Wood_Beech_Trunk",
      "support": 15
    },
    {
      "x": -27,
      "y": 9,
      "z": 13,
      "name": "Wood_Beech_Trunk",
      "support": 15
    },
    {
      "x": -27,
      "y": 0,
      "z": 14,
      "name": "Rock_Stone"
    },
    {
      "x": -27,
      "y": 1,
      "z": 14,
      "name": "Rock_Stone"
    },
    {
      "x": -27,
      "y": 2,
      "z": 14,
      "name": "Soil_Dirt"
    },
    {
      "x": -27,
      "y": 3,
      "z": 14,
      "name": "Soil_Dirt"
    },
    {
      "x": -27,
      "y": 4,
      "z": 14,
      "name": "Wood_Beech_Trunk",
      "support": 15
    },
    {
      "x": -27,
      "y": 5,
      "z": 14,
      "name": "Wood_Beech_Trunk",
      "support": 15
    },
    {
      "x": -27,
      "y": 6,
      "z": 14,
      "name": "Wood_Beech_Trunk",
      "support": 15
    },
    {
      "x": -27,
      "y": 7,
      "z": 14,
      "name": "Wood_Beech_Trunk",
      "support": 15
    },
    {
      "x": -27,
      "y": 8,
      "z": 14,
      "name": "Wood_Beech_Trunk",
      "support": 15
    },
    {
      "x": -27,
      "y": 9,
      "z": 14,
      "name": "Plant_Leaves_Bramble",
      "support": 15
    },
    {
      "x": -27,
      "y": 0,
      "z": 15,
      "name": "Rock_Stone"
    },
    {
      "x": -27,
      "y": 1,
      "z": 15,
      "name": "Rock_Stone"
    },
    {
      "x": -27,
      "y": 2,
      "z": 15,
      "name": "Soil_Dirt"
    },
    {
      "x": -27,
      "y": 3,
      "z": 15,
      "name": "Soil_Dirt"
    },
    {
      "x": -27,
      "y": 4,
      "z": 15,
      "name": "Rock_Chalk"
    },
    {
      "x": -27,
      "y": 5,
      "z": 15,
      "name": "Rock_Chalk"
    },
    {
      "x": -27,
      "y": 6,
      "z": 15,
      "name": "Rock_Chalk"
    },
    {
      "x": -27,
      "y": 7,
      "z": 15,
      "name": "Rock_Chalk"
    },
    {
      "x": -27,
      "y": 0,
      "z": 16,
      "name": "Rock_Stone"
    },
    {
      "x": -27,
      "y": 1,
      "z": 16,
      "name": "Rock_Stone"
    },
    {
      "x": -27,
      "y": 2,
      "z": 16,
      "name": "Soil_Dirt"
    },
    {
      "x": -27,
      "y": 3,
      "z": 16,
      "name": "Soil_Dirt"
    },
    {
      "x": -27,
      "y": 4,
      "z": 16,
      "name": "Rock_Chalk"
    },
    {
      "x": -27,
      "y": 5,
      "z": 16,
      "name": "Rock_Chalk"
    },
    {
      "x": -27,
      "y": 6,
      "z": 16,
      "name": "Deco_Bone_Skulls"
    },
    {
      "x": -27,
      "y": 7,
      "z": 16,
      "name": "Rock_Chalk"
    },
    {
      "x": -27,
      "y": 0,
      "z": 17,
      "name": "Rock_Stone"
    },
    {
      "x": -27,
      "y": 1,
      "z": 17,
      "name": "Rock_Stone"
    },
    {
      "x": -27,
      "y": 2,
      "z": 17,
      "name": "Soil_Dirt"
    },
    {
      "x": -27,
      "y": 3,
      "z": 17,
      "name": "Soil_Dirt"
    },
    {
      "x": -27,
      "y": 0,
      "z": 18,
      "name": "Rock_Stone"
    },
    {
      "x": -27,
      "y": 1,
      "z": 18,
      "name": "Rock_Stone"
    },
    {
      "x": -27,
      "y": 2,
      "z": 18,
      "name": "Soil_Dirt"
    },
    {
      "x": -27,
      "y": 3,
      "z": 18,
      "name": "Soil_Dirt"
    },
    {
      "x": -27,
      "y": 4,
      "z": 18,
      "name": "Wood_Beech_Trunk",
      "support": 15
    },
    {
      "x": -27,
      "y": 5,
      "z": 18,
      "name": "Wood_Beech_Trunk",
      "support": 15
    },
    {
      "x": -27,
      "y": 6,
      "z": 18,
      "name": "Wood_Beech_Trunk",
      "support": 15
    },
    {
      "x": -27,
      "y": 7,
      "z": 18,
      "name": "Wood_Beech_Trunk",
      "support": 15
    },
    {
      "x": -27,
      "y": 8,
      "z": 18,
      "name": "Wood_Beech_Trunk",
      "support": 15
    },
    {
      "x": -27,
      "y": 9,
      "z": 18,
      "name": "Wood_Beech_Trunk",
      "support": 15
    },
    {
      "x": -27,
      "y": 10,
      "z": 18,
      "name": "Wood_Beech_Trunk",
      "support": 15
    },
    {
      "x": -27,
      "y": 11,
      "z": 18,
      "name": "Wood_Beech_Trunk",
      "support": 15
    },
    {
      "x": -27,
      "y": 0,
      "z": 19,
      "name": "Rock_Stone"
    },
    {
      "x": -27,
      "y": 1,
      "z": 19,
      "name": "Rock_Stone"
    },
    {
      "x": -27,
      "y": 2,
      "z": 19,
      "name": "Soil_Dirt"
    },
    {
      "x": -27,
      "y": 3,
      "z": 19,
      "name": "Soil_Dirt"
    },
    {
      "x": -27,
      "y": 4,
      "z": 19,
      "name": "Wood_Beech_Trunk",
      "support": 15
    },
    {
      "x": -27,
      "y": 5,
      "z": 19,
      "name": "Wood_Beech_Trunk",
      "support": 15
    },
    {
      "x": -27,
      "y": 6,
      "z": 19,
      "name": "Wood_Beech_Trunk",
      "support": 15
    },
    {
      "x": -27,
      "y": 7,
      "z": 19,
      "name": "Wood_Beech_Trunk",
      "support": 15
    },
    {
      "x": -27,
      "y": 8,
      "z": 19,
      "name": "Wood_Beech_Trunk",
      "support": 15
    },
    {
      "x": -27,
      "y": 9,
      "z": 19,
      "name": "Wood_Beech_Trunk",
      "support": 15
    },
    {
      "x": -27,
      "y": 0,
      "z": 20,
      "name": "Rock_Stone"
    },
    {
      "x": -27,
      "y": 1,
      "z": 20,
      "name": "Rock_Stone"
    },
    {
      "x": -27,
      "y": 2,
      "z": 20,
      "name": "Soil_Dirt"
    },
    {
      "x": -27,
      "y": 3,
      "z": 20,
      "name": "Soil_Dirt"
    },
    {
      "x": -27,
      "y": 9,
      "z": 20,
      "name": "Plant_Leaves_Bramble",
      "support": 15
    },
    {
      "x": -27,
      "y": 0,
      "z": 21,
      "name": "Rock_Stone"
    },
    {
      "x": -27,
      "y": 1,
      "z": 21,
      "name": "Rock_Stone"
    },
    {
      "x": -27,
      "y": 2,
      "z": 21,
      "name": "Soil_Dirt"
    },
    {
      "x": -27,
      "y": 3,
      "z": 21,
      "name": "Soil_Dirt"
    },
    {
      "x": -27,
      "y": 0,
      "z": 22,
      "name": "Rock_Stone"
    },
    {
      "x": -27,
      "y": 1,
      "z": 22,
      "name": "Rock_Stone"
    },
    {
      "x": -27,
      "y": 2,
      "z": 22,
      "name": "Soil_Dirt"
    },
    {
      "x": -27,
      "y": 3,
      "z": 22,
      "name": "Soil_Dirt"
    },
    {
      "x": -27,
      "y": 0,
      "z": 23,
      "name": "Rock_Stone"
    },
    {
      "x": -27,
      "y": 1,
      "z": 23,
      "name": "Rock_Stone"
    },
    {
      "x": -27,
      "y": 2,
      "z": 23,
      "name": "Soil_Dirt"
    },
    {
      "x": -27,
      "y": 3,
      "z": 23,
      "name": "Soil_Dirt"
    },
    {
      "x": -27,
      "y": 1,
      "z": 24,
      "name": "Rock_Stone"
    },
    {
      "x": -27,
      "y": 2,
      "z": 24,
      "name": "Soil_Dirt"
    },
    {
      "x": -27,
      "y": 3,
      "z": 24,
      "name": "Soil_Dirt"
    },
    {
      "x": -27,
      "y": 1,
      "z": 25,
      "name": "Soil_Dirt"
    },
    {
      "x": -27,
      "y": 2,
      "z": 25,
      "name": "Soil_Dirt"
    },
    {
      "x": -27,
      "y": 1,
      "z": 26,
      "name": "Soil_Dirt"
    },
    {
      "x": -27,
      "y": 2,
      "z": 26,
      "name": "Soil_Dirt"
    },
    {
      "x": -27,
      "y": 1,
      "z": 27,
