{
  "version": 8,
  "blockIdVersion": 11,
  "anchorX": 0,
  "anchorY": 4,
  "anchorZ": 0,
  "blocks": [
    {
      "x": -3,
      "y": 2,
      "z": -3,
      "name": "Rock_Sandstone"
    },
    {
      "x": -3,
      "y": 3,
      "z": -3,
      "name": "Soil_Dirt_Dry"
    },
    {
      "x": -3,
      "y": 4,
      "z": -3,
      "name": "Soil_Dirt_Dry"
    },
    {
      "x": -3,
      "y": 2,
      "z": -2,
      "name": "Rock_Sandstone"
    },
    {
      "x": -3,
      "y": 3,
      "z": -2,
      "name": "Soil_Dirt_Dry"
    },
    {
      "x": -3,
      "y": 4,
      "z": -2,
      "name": "Soil_Dirt_Dry"
    },
    {
      "x": -3,
      "y": 2,
      "z": -1,
      "name": "Rock_Sandstone"
    },
    {
      "x": -3,
      "y": 3,
      "z": -1,
      "name": "Soil_Dirt_Dry"
    },
    {
      "x": -3,
      "y": 4,
      "z": -1,
      "name": "Soil_Dirt_Dry"
    },
    {
      "x": -3,
      "y": 5,
      "z": -1,
      "name": "Wood_Drywood_Beam"
    },
    {
      "x": -3,
      "y": 2,
      "z": 0,
      "name": "Rock_Sandstone"
    },
    {
      "x": -3,
      "y": 3,
      "z": 0,
      "name": "Soil_Dirt_Dry"
    },
    {
      "x": -3,
      "y": 4,
      "z": 0,
      "name": "Soil_Dirt_Dry"
    },
    {
      "x": -3,
      "y": 2,
      "z": 1,
      "name": "Rock_Sandstone"
    },
    {
      "x": -3,
      "y": 3,
      "z": 1,
      "name": "Soil_Dirt_Dry"
    },
    {
      "x": -3,
      "y": 4,
      "z": 1,
      "name": "Soil_Dirt_Dry"
    },
    {
      "x": -3,
      "y": 5,
      "z": 1,
      "name": "Wood_Drywood_Beam"
    },
    {
      "x": -3,
      "y": 6,
      "z": 1,
      "name": "Furniture_Crude_Torch",
      "rotation": 2
    },
    {
      "x": -3,
      "y": 2,
      "z": 2,
      "name": "Rock_Sandstone"
    },
    {
      "x": -3,
      "y": 3,
      "z": 2,
      "name": "Soil_Dirt_Dry"
    },
    {
      "x": -3,
      "y": 4,
      "z": 2,
      "name": "Soil_Dirt_Dry"
    },
    {
      "x": -3,
      "y": 2,
      "z": 3,
      "name": "Rock_Sandstone"
    },
    {
      "x": -3,
      "y": 3,
      "z": 3,
      "name": "Soil_Dirt_Dry"
    },
    {
      "x": -3,
      "y": 4,
      "z": 3,
      "name": "Soil_Dirt_Dry"
    },
    {
      "x": -3,
      "y": 5,
      "z": 3,
      "name": "Wood_Drywood_Beam"
    },
    {
      "x": -3,
      "y": 6,
      "z": 3,
      "name": "Wood_Drywood_Planks_Half"
    },
    {
      "x": -2,
      "y": 2,
      "z": -3,
      "name": "Rock_Sandstone"
    },
    {
      "x": -2,
      "y": 3,
      "z": -3,
      "name": "Soil_Dirt_Dry"
    },
    {
      "x": -2,
      "y": 4,
      "z": -3,
      "name": "Soil_Dirt_Dry"
    },
    {
      "x": -2,
      "y": 1,
      "z": -2,
      "name": "Rock_Sandstone"
    },
    {
      "x": -2,
      "y": 2,
      "z": -2,
      "name": "Rock_Sandstone"
    },
    {
      "x": -2,
      "y": 3,
      "z": -2,
      "name": "Soil_Dirt_Dry"
    },
    {
      "x": -2,
      "y": 4,
      "z": -2,
      "name": "Soil_Dirt_Dry"
    },
    {
      "x": -2,
      "y": 1,
      "z": -1,
      "name": "Rock_Sandstone"
    },
    {
      "x": -2,
      "y": 2,
      "z": -1,
      "name": "Rock_Sandstone"
    },
    {
      "x": -2,
      "y": 3,
      "z": -1,
      "name": "Soil_Dirt_Dry"
    },
    {
      "x": -2,
      "y": 4,
      "z": -1,
      "name": "Soil_Dirt_Dry"
    },
    {
      "x": -2,
      "y": 1,
      "z": 0,
      "name": "Rock_Sandstone"
    },
    {
      "x": -2,
      "y": 2,
      "z": 0,
      "name": "Rock_Sandstone"
    },
    {
      "x": -2,
      "y": 3,
      "z": 0,
      "name": "Soil_Dirt_Dry"
    },
    {
      "x": -2,
      "y": 4,
      "z": 0,
      "name": "Soil_Dirt_Dry"
    },
    {
      "x": -2,
      "y": 1,
      "z": 1,
      "name": "Rock_Sandstone"
    },
    {
      "x": -2,
      "y": 2,
      "z": 1,
      "name": "Rock_Sandstone"
    },
    {
      "x": -2,
      "y": 3,
      "z": 1,
      "name": "Soil_Dirt_Dry"
    },
    {
      "x": -2,
      "y": 4,
      "z": 1,
      "name": "Soil_Dirt_Dry"
    },
    {
      "x": -2,
      "y": 5,
      "z": 1,
      "name": "Halloween_Wagon",
      "filler": 31,
      "rotation": 3
    },
    {
      "x": -2,
      "y": 6,
      "z": 1,
      "name": "Ore_Iron_Sandstone"
    },
    {
      "x": -2,
      "y": 1,
      "z": 2,
      "name": "Rock_Sandstone"
    },
    {
      "x": -2,
      "y": 2,
      "z": 2,
      "name": "Rock_Sandstone"
    },
    {
      "x": -2,
      "y": 3,
      "z": 2,
      "name": "Soil_Dirt_Dry"
    },
    {
      "x": -2,
      "y": 4,
      "z": 2,
      "name": "Soil_Dirt_Dry"
    },
    {
      "x": -2,
      "y": 5,
      "z": 2,
      "name": "Halloween_Wagon",
      "filler": 63,
      "rotation": 3
    },
    {
      "x": -2,
      "y": 6,
      "z": 2,
      "name": "Ore_Iron_Sandstone"
    },
    {
      "x": -2,
      "y": 2,
      "z": 3,
      "name": "Rock_Sandstone"
    },
    {
      "x": -2,
      "y": 3,
      "z": 3,
      "name": "Soil_Dirt_Dry"
    },
    {
      "x": -2,
      "y": 4,
      "z": 3,
      "name": "Soil_Dirt_Dry"
    },
    {
      "x": -2,
      "y": 5,
      "z": 3,
      "name": "Wood_Drywood_Planks"
    },
    {
      "x": -2,
      "y": 6,
      "z": 3,
      "name": "Wood_Drywood_Planks"
    },
    {
      "x": -1,
      "y": 2,
      "z": -3,
      "name": "Rock_Sandstone"
    },
    {
      "x": -1,
      "y": 3,
      "z": -3,
      "name": "Soil_Dirt_Dry"
    },
    {
      "x": -1,
      "y": 4,
      "z": -3,
      "name": "Soil_Dirt_Dry"
    },
    {
      "x": -1,
      "y": 1,
      "z": -2,
      "name": "Rock_Sandstone"
    },
    {
      "x": -1,
      "y": 2,
      "z": -2,
      "name": "Rock_Sandstone"
    },
    {
      "x": -1,
      "y": 3,
      "z": -2,
      "name": "Soil_Dirt_Dry"
    },
    {
      "x": -1,
      "y": 4,
      "z": -2,
      "name": "Soil_Dirt_Dry"
    },
    {
      "x": -1,
      "y": 0,
      "z": -1,
      "name": "Rock_Sandstone"
    },
    {
      "x": -1,
      "y": 1,
      "z": -1,
      "name": "Rock_Sandstone"
    },
    {
      "x": -1,
      "y": 2,
      "z": -1,
      "name": "Rock_Sandstone"
    },
    {
      "x": -1,
      "y": 3,
      "z": -1,
      "name": "Soil_Dirt_Dry"
    },
    {
      "x": -1,
      "y": 4,
      "z": -1,
      "name": "Soil_Dirt_Dry"
    },
    {
      "x": -1,
      "y": 0,
      "z": 0,
      "name": "Rock_Sandstone"
    },
    {
      "x": -1,
      "y": 1,
      "z": 0,
      "name": "Rock_Sandstone"
    },
    {
      "x": -1,
      "y": 2,
      "z": 0,
      "name": "Rock_Sandstone"
    },
    {
      "x": -1,
      "y": 3,
      "z": 0,
      "name": "Soil_Dirt_Dry"
    },
    {
      "x": -1,
      "y": 4,
      "z": 0,
      "name": "Soil_Dirt_Dry"
    },
    {
      "x": -1,
      "y": 0,
      "z": 1,
      "name": "Rock_Sandstone"
    },
    {
      "x": -1,
      "y": 1,
      "z": 1,
      "name": "Rock_Sandstone"
    },
    {
      "x": -1,
      "y": 2,
      "z": 1,
      "name": "Rock_Sandstone"
    },
    {
      "x": -1,
      "y": 3,
      "z": 1,
      "name": "Soil_Dirt_Dry"
    },
    {
      "x": -1,
      "y": 4,
      "z": 1,
      "name": "Soil_Dirt_Dry"
    },
    {
      "x": -1,
      "y": 5,
      "z": 1,
      "name": "Halloween_Wagon",
      "rotation": 3
    },
    {
      "x": -1,
      "y": 6,
      "z": 1,
      "name": "Ore_Iron_Sandstone"
    },
    {
      "x": -1,
      "y": 1,
      "z": 2,
      "name": "Rock_Sandstone"
    },
    {
      "x": -1,
      "y": 2,
      "z": 2,
      "name": "Rock_Sandstone"
    },
    {
      "x": -1,
      "y": 3,
      "z": 2,
      "name": "Soil_Dirt_Dry"
    },
    {
      "x": -1,
      "y": 4,
      "z": 2,
      "name": "Soil_Dirt_Dry"
    },
    {
      "x": -1,
      "y": 5,
      "z": 2,
      "name": "Halloween_Wagon",
      "filler": 32,
      "rotation": 3
    },
    {
      "x": -1,
      "y": 6,
      "z": 2,
      "name": "Ore_Iron_Sandstone"
    },
    {
      "x": -1,
      "y": 2,
      "z": 3,
      "name": "Rock_Sandstone"
    },
    {
      "x": -1,
      "y": 3,
      "z": 3,
      "name": "Soil_Dirt_Dry"
    },
    {
      "x": -1,
      "y": 4,
      "z": 3,
      "name": "Soil_Dirt_Dry"
    },
    {
      "x": -1,
      "y": 5,
      "z": 3,
      "name": "Wood_Drywood_Planks"
    },
    {
      "x": -1,
      "y": 6,
      "z": 3,
      "name": "Wood_Drywood_Planks"
    },
    {
      "x": 0,
      "y": 2,
      "z": -3,
      "name": "Rock_Sandstone"
    },
    {
      "x": 0,
      "y": 3,
      "z": -3,
      "name": "Soil_Dirt_Dry"
    },
    {
      "x": 0,
      "y": 4,
      "z": -3,
      "name": "Soil_Dirt_Dry"
    },
    {
      "x": 0,
      "y": 1,
      "z": -2,
      "name": "Rock_Sandstone"
    },
    {
      "x": 0,
      "y": 2,
      "z": -2,
      "name": "Rock_Sandstone"
    },
    {
      "x": 0,
      "y": 3,
      "z": -2,
      "name": "Soil_Dirt_Dry"
    },
    {
      "x": 0,
      "y": 4,
      "z": -2,
      "name": "Soil_Dirt_Dry"
    },
    {
      "x": 0,
      "y": 0,
      "z": -1,
      "name": "Rock_Sandstone"
    },
    {
      "x": 0,
      "y": 1,
      "z": -1,
      "name": "Rock_Sandstone"
    },
    {
      "x": 0,
      "y": 2,
      "z": -1,
      "name": "Rock_Sandstone"
    },
    {
      "x": 0,
      "y": 3,
      "z": -1,
      "name": "Soil_Dirt_Dry"
    },
    {
      "x": 0,
      "y": 4,
      "z": -1,
      "name": "Soil_Dirt_Dry"
    },
    {
      "x": 0,
      "y": 5,
      "z": -1,
      "name": "Wood_Drywood_Beam"
    },
    {
      "x": 0,
      "y": 0,
      "z": 0,
      "name": "Rock_Sandstone"
    },
    {
      "x": 0,
      "y": 1,
      "z": 0,
      "name": "Rock_Sandstone"
    },
    {
      "x": 0,
      "y": 2,
      "z": 0,
      "name": "Rock_Sandstone"
    },
    {
      "x": 0,
      "y": 3,
      "z": 0,
      "name": "Soil_Dirt_Dry"
    },
    {
      "x": 0,
      "y": 4,
      "z": 0,
      "name": "Soil_Dirt_Dry"
    },
    {
      "x": 0,
      "y": 0,
      "z": 1,
      "name": "Rock_Sandstone"
    },
    {
      "x": 0,
      "y": 1,
      "z": 1,
      "name": "Rock_Sandstone"
    },
    {
      "x": 0,
      "y": 2,
      "z": 1,
      "name": "Rock_Sandstone"
    },
    {
      "x": 0,
      "y": 3,
      "z": 1,
      "name": "Soil_Dirt_Dry"
    },
    {
      "x": 0,
      "y": 4,
      "z": 1,
      "name": "Soil_Dirt_Dry"
    },
    {
      "x": 0,
      "y": 5,
      "z": 1,
      "name": "Wood_Drywood_Beam"
    },
    {
      "x": 0,
      "y": 1,
      "z": 2,
      "name": "Rock_Sandstone"
    },
    {
      "x": 0,
      "y": 2,
      "z": 2,
      "name": "Rock_Sandstone"
    },
    {
      "x": 0,
      "y": 3,
      "z": 2,
      "name": "Soil_Dirt_Dry"
    },
    {
      "x": 0,
      "y": 4,
      "z": 2,
      "name": "Soil_Dirt_Dry"
    },
    {
      "x": 0,
      "y": 2,
      "z": 3,
      "name": "Rock_Sandstone"
    },
    {
      "x": 0,
      "y": 3,
      "z": 3,
      "name": "Soil_Dirt_Dry"
    },
    {
      "x": 0,
      "y": 4,
      "z": 3,
      "name": "Soil_Dirt_Dry"
    },
    {
      "x": 0,
      "y": 5,
      "z": 3,
      "name": "Wood_Drywood_Beam"
    },
    {
      "x": 0,
      "y": 6,
      "z": 3,
      "name": "Wood_Drywood_Planks_Half"
    },
    {
      "x": 1,
      "y": 2,
      "z": -3,
      "name": "Rock_Sandstone"
    },
    {
      "x": 1,
      "y": 3,
      "z": -3,
      "name": "Soil_Dirt_Dry"
    },
    {
      "x": 1,
      "y": 4,
      "z": -3,
      "name": "Soil_Dirt_Dry"
    },
    {
      "x": 1,
      "y": 1,
      "z": -2,
      "name": "Rock_Sandstone"
    },
    {
      "x": 1,
      "y": 2,
      "z": -2,
      "name": "Rock_Sandstone"
    },
    {
      "x": 1,
      "y": 3,
      "z": -2,
      "name": "Soil_Dirt_Dry"
    },
    {
      "x": 1,
      "y": 4,
      "z": -2,
      "name": "Soil_Dirt_Dry"
    },
    {
      "x": 1,
      "y": 0,
      "z": -1,
      "name": "Rock_Sandstone"
    },
    {
      "x": 1,
      "y": 1,
      "z": -1,
      "name": "Rock_Sandstone"
    },
    {
      "x": 1,
      "y": 2,
      "z": -1,
      "name": "Rock_Sandstone"
    },
    {
      "x": 1,
      "y": 3,
      "z": -1,
      "name": "Soil_Dirt_Dry"
    },
    {
      "x": 1,
      "y": 4,
      "z": -1,
      "name": "Soil_Dirt_Dry"
    },
    {
      "x": 1,
      "y": 0,
      "z": 0,
      "name": "Rock_Sandstone"
    },
    {
      "x": 1,
      "y": 1,
      "z": 0,
      "name": "Rock_Sandstone"
    },
    {
      "x": 1,
      "y": 2,
      "z": 0,
      "name": "Rock_Sandstone"
    },
    {
      "x": 1,
      "y": 3,
      "z": 0,
      "name": "Soil_Dirt_Dry"
    },
    {
      "x": 1,
      "y": 4,
      "z": 0,
      "name": "Soil_Dirt_Dry"
    },
    {
      "x": 1,
      "y": 0,
      "z": 1,
      "name": "Rock_Sandstone"
    },
    {
      "x": 1,
      "y": 1,
      "z": 1,
      "name": "Rock_Sandstone"
    },
    {
      "x": 1,
      "y": 2,
      "z": 1,
      "name": "Rock_Sandstone"
    },
    {
      "x": 1,
      "y": 3,
      "z": 1,
      "name": "Soil_Dirt_Dry"
    },
    {
      "x": 1,
      "y": 4,
      "z": 1,
      "name": "Soil_Dirt_Dry"
    },
    {
      "x": 1,
      "y": 5,
      "z": 1,
      "name": "Halloween_Wagon",
      "filler": 31,
      "rotation": 3
    },
    {
      "x": 1,
      "y": 6,
      "z": 1,
      "name": "Ore_Copper_Sandstone"
    },
    {
      "x": 1,
      "y": 1,
      "z": 2,
      "name": "Rock_Sandstone"
    },
    {
      "x": 1,
      "y": 2,
      "z": 2,
      "name": "Rock_Sandstone"
    },
    {
      "x": 1,
      "y": 3,
      "z": 2,
      "name": "Soil_Dirt_Dry"
    },
    {
      "x": 1,
      "y": 4,
      "z": 2,
      "name": "Soil_Dirt_Dry"
    },
    {
      "x": 1,
      "y": 5,
      "z": 2,
      "name": "Halloween_Wagon",
      "filler": 63,
      "rotation": 3
    },
    {
      "x": 1,
      "y": 6,
      "z": 2,
      "name": "Ore_Copper_Sandstone"
    },
    {
      "x": 1,
      "y": 2,
      "z": 3,
      "name": "Rock_Sandstone"
    },
    {
      "x": 1,
      "y": 3,
      "z": 3,
      "name": "Soil_Dirt_Dry"
    },
    {
      "x": 1,
      "y": 4,
      "z": 3,
      "name": "Soil_Dirt_Dry"
    },
    {
      "x": 1,
      "y": 5,
      "z": 3,
      "name": "Wood_Drywood_Planks"
    },
    {
      "x": 1,
      "y": 6,
      "z": 3,
      "name": "Wood_Drywood_Planks"
    },
    {
      "x": 2,
      "y": 2,
      "z": -3,
      "name": "Rock_Sandstone"
    },
    {
      "x": 2,
      "y": 3,
      "z": -3,
      "name": "Soil_Dirt_Dry"
    },
    {
      "x": 2,
      "y": 4,
      "z": -3,
      "name": "Soil_Dirt_Dry"
    },
    {
      "x": 2,
      "y": 1,
      "z": -2,
      "name": "Rock_Sandstone"
    },
    {
      "x": 2,
      "y": 2,
      "z": -2,
      "name": "Rock_Sandstone"
    },
    {
      "x": 2,
      "y": 3,
      "z": -2,
      "name": "Soil_Dirt_Dry"
    },
    {
      "x": 2,
      "y": 4,
      "z": -2,
      "name": "Soil_Dirt_Dry"
    },
    {
      "x": 2,
      "y": 1,
      "z": -1,
      "name": "Rock_Sandstone"
    },
    {
      "x": 2,
      "y": 2,
      "z": -1,
      "name": "Rock_Sandstone"
    },
    {
      "x": 2,
      "y": 3,
      "z": -1,
      "name": "Soil_Dirt_Dry"
    },
    {
      "x": 2,
      "y": 4,
      "z": -1,
      "name": "Soil_Dirt_Dry"
    },
    {
      "x": 2,
      "y": 1,
      "z": 0,
      "name": "Rock_Sandstone"
    },
    {
      "x": 2,
      "y": 2,
      "z": 0,
      "name": "Rock_Sandstone"
    },
    {
      "x": 2,
      "y": 3,
      "z": 0,
      "name": "Soil_Dirt_Dry"
    },
    {
      "x": 2,
      "y": 4,
      "z": 0,
      "name": "Soil_Dirt_Dry"
    },
    {
      "x": 2,
      "y": 1,
      "z": 1,
      "name": "Rock_Sandstone"
    },
    {
      "x": 2,
      "y": 2,
      "z": 1,
      "name": "Rock_Sandstone"
    },
    {
      "x": 2,
      "y": 3,
      "z": 1,
      "name": "Soil_Dirt_Dry"
    },
    {
      "x": 2,
      "y": 4,
      "z": 1,
      "name": "Soil_Dirt_Dry"
    },
    {
      "x": 2,
      "y": 5,
      "z": 1,
      "name": "Halloween_Wagon",
      "rotation": 3
    },
    {
      "x": 2,
      "y": 6,
      "z": 1,
      "name": "Ore_Copper_Sandstone"
    },
    {
      "x": 2,
      "y": 1,
      "z": 2,
      "name": "Rock_Sandstone"
    },
    {
      "x": 2,
      "y": 2,
      "z": 2,
      "name": "Rock_Sandstone"
    },
    {
      "x": 2,
      "y": 3,
      "z": 2,
      "name": "Soil_Dirt_Dry"
    },
    {
      "x": 2,
      "y": 4,
      "z": 2,
      "name": "Soil_Dirt_Dry"
    },
    {
      "x": 2,
      "y": 5,
      "z": 2,
      "name": "Halloween_Wagon",
      "filler": 32,
      "rotation": 3
    },
    {
      "x": 2,
      "y": 6,
      "z": 2,
      "name": "Ore_Copper_Sandstone"
    },
    {
      "x": 2,
      "y": 2,
      "z": 3,
      "name": "Rock_Sandstone"
    },
    {
      "x": 2,
      "y": 3,
      "z": 3,
      "name": "Soil_Dirt_Dry"
    },
    {
      "x": 2,
      "y": 4,
      "z": 3,
      "name": "Soil_Dirt_Dry"
    },
    {
      "x": 2,
      "y": 5,
      "z": 3,
      "name": "Wood_Drywood_Planks"
    },
    {
      "x": 2,
      "y": 6,
      "z": 3,
      "name": "Wood_Drywood_Planks"
    },
    {
      "x": 3,
      "y": 2,
      "z": -3,
      "name": "Rock_Sandstone"
    },
    {
      "x": 3,
      "y": 3,
      "z": -3,
      "name": "Soil_Dirt_Dry"
    },
    {
      "x": 3,
      "y": 4,
      "z": -3,
      "name": "Soil_Dirt_Dry"
    },
    {
      "x": 3,
      "y": 2,
      "z": -2,
      "name": "Rock_Sandstone"
    },
    {
      "x": 3,
      "y": 3,
      "z": -2,
      "name": "Soil_Dirt_Dry"
    },
    {
      "x": 3,
      "y": 4,
      "z": -2,
      "name": "Soil_Dirt_Dry"
    },
    {
      "x": 3,
      "y": 2,
      "z": -1,
      "name": "Rock_Sandstone"
    },
    {
      "x": 3,
      "y": 3,
      "z": -1,
      "name": "Soil_Dirt_Dry"
    },
    {
      "x": 3,
      "y": 4,
      "z": -1,
      "name": "Soil_Dirt_Dry"
    },
    {
      "x": 3,
      "y": 5,
      "z": -1,
      "name": "Wood_Drywood_Beam"
    },
    {
      "x": 3,
      "y": 2,
      "z": 0,
      "name": "Rock_Sandstone"
    },
    {
      "x": 3,
      "y": 3,
      "z": 0,
      "name": "Soil_Dirt_Dry"
    },
    {
      "x": 3,
      "y": 4,
      "z": 0,
      "name": "Soil_Dirt_Dry"
    },
    {
      "x": 3,
      "y": 2,
      "z": 1,
      "name": "Rock_Sandstone"
    },
    {
      "x": 3,
      "y": 3,
      "z": 1,
      "name": "Soil_Dirt_Dry"
    },
    {
      "x": 3,
      "y": 4,
      "z": 1,
      "name": "Soil_Dirt_Dry"
    },
    {
      "x": 3,
      "y": 5,
      "z": 1,
      "name": "Wood_Drywood_Beam"
    },
    {
      "x": 3,
      "y": 6,
      "z": 1,
      "name": "Furniture_Crude_Torch",
      "rotation": 2
    },
    {
      "x": 3,
      "y": 2,
      "z": 2,
      "name": "Rock_Sandstone"
    },
    {
      "x": 3,
      "y": 3,
      "z": 2,
      "name": "Soil_Dirt_Dry"
    },
    {
      "x": 3,
      "y": 4,
      "z": 2,
      "name": "Soil_Dirt_Dry"
    },
    {
      "x": 3,
      "y": 2,
      "z": 3,
      "name": "Rock_Sandstone"
    },
    {
      "x": 3,
      "y": 3,
      "z": 3,
      "name": "Soil_Dirt_Dry"
    },
    {
      "x": 3,
      "y": 4,
      "z": 3,
      "name": "Soil_Dirt_Dry"
    },
    {
      "x": 3,
      "y": 5,
      "z": 3,
      "name": "Wood_Drywood_Beam"
    },
    {
      "x": 3,
      "y": 6,
      "z": 3,
      "name": "Wood_Drywood_Planks_Half"
    }
  ]
}