{
  "version": 8,
  "blockIdVersion": 11,
  "anchorX": 0,
  "anchorY": 0,
  "anchorZ": 0,
  "blocks": [
    {
      "x": -42,
      "y": 0,
      "z": -6,
      "name": "Soil_Dirt_Dry"
    },
    {
      "x": -42,
      "y": 0,
      "z": -5,
      "name": "Soil_Dirt_Dry"
    },
    {
      "x": -42,
      "y": 0,
      "z": -4,
      "name": "Soil_Dirt_Dry"
    },
    {
      "x": -42,
      "y": 0,
      "z": -3,
      "name": "Soil_Gravel_Sand_Red"
    },
    {
      "x": -42,
      "y": 0,
      "z": -2,
      "name": "Soil_Gravel_Sand_Red"
    },
    {
      "x": -42,
      "y": 0,
      "z": -1,
      "name": "Soil_Gravel_Sand_Red"
    },
    {
      "x": -42,
      "y": 0,
      "z": 0,
      "name": "Soil_Gravel_Sand_Red"
    },
    {
      "x": -42,
      "y": 0,
      "z": 1,
      "name": "Soil_Gravel_Sand_Red"
    },
    {
      "x": -42,
      "y": 0,
      "z": 2,
      "name": "Soil_Gravel_Sand_Red"
    },
    {
      "x": -42,
      "y": 0,
      "z": 3,
      "name": "Soil_Gravel_Sand_Red"
    },
    {
      "x": -42,
      "y": 0,
      "z": 4,
      "name": "Soil_Dirt_Dry"
    },
    {
      "x": -42,
      "y": 0,
      "z": 5,
      "name": "Soil_Dirt_Dry"
    },
    {
      "x": -42,
      "y": 0,
      "z": 6,
      "name": "Soil_Dirt_Dry"
    },
    {
      "x": -41,
      "y": 0,
      "z": -8,
      "name": "Soil_Dirt_Dry"
    },
    {
      "x": -41,
      "y": 0,
      "z": -7,
      "name": "Soil_Dirt_Dry"
    },
    {
      "x": -41,
      "y": 0,
      "z": -6,
      "name": "Soil_Dirt_Dry"
    },
    {
      "x": -41,
      "y": 0,
      "z": -5,
      "name": "Soil_Dirt_Dry"
    },
    {
      "x": -41,
      "y": 0,
      "z": -4,
      "name": "Soil_Dirt_Dry"
    },
    {
      "x": -41,
      "y": 0,
      "z": -3,
      "name": "Soil_Gravel_Sand_Red"
    },
    {
      "x": -41,
      "y": 0,
      "z": -2,
      "name": "Soil_Dirt_Dry"
    },
    {
      "x": -41,
      "y": 1,
      "z": -2,
      "name": "Soil_Gravel_Sand_Red"
    },
    {
      "x": -41,
      "y": 0,
      "z": -1,
      "name": "Soil_Dirt_Dry"
    },
    {
      "x": -41,
      "y": 1,
      "z": -1,
      "name": "Soil_Gravel_Sand_Red"
    },
    {
      "x": -41,
      "y": 0,
      "z": 0,
      "name": "Soil_Dirt_Dry"
    },
    {
      "x": -41,
      "y": 1,
      "z": 0,
      "name": "Soil_Gravel_Sand_Red"
    },
    {
      "x": -41,
      "y": 0,
      "z": 1,
      "name": "Soil_Dirt_Dry"
    },
    {
      "x": -41,
      "y": 1,
      "z": 1,
      "name": "Soil_Gravel_Sand_Red"
    },
    {
      "x": -41,
      "y": 0,
      "z": 2,
      "name": "Soil_Dirt_Dry"
    },
    {
      "x": -41,
      "y": 1,
      "z": 2,
      "name": "Soil_Gravel_Sand_Red"
    },
    {
      "x": -41,
      "y": 0,
      "z": 3,
      "name": "Soil_Gravel_Sand_Red"
    },
    {
      "x": -41,
      "y": 0,
      "z": 4,
      "name": "Soil_Dirt_Dry"
    },
    {
      "x": -41,
      "y": 0,
      "z": 5,
      "name": "Soil_Dirt_Dry"
    },
    {
      "x": -41,
      "y": 0,
      "z": 6,
      "name": "Soil_Dirt_Dry"
    },
    {
      "x": -41,
      "y": 0,
      "z": 7,
      "name": "Soil_Dirt_Dry"
    },
    {
      "x": -41,
      "y": 0,
      "z": 8,
      "name": "Soil_Dirt_Dry"
    },
    {
      "x": -40,
      "y": 0,
      "z": -9,
      "name": "Soil_Dirt_Dry"
    },
    {
      "x": -40,
      "y": 0,
      "z": -8,
      "name": "Soil_Dirt_Dry"
    },
    {
      "x": -40,
      "y": 0,
      "z": -7,
      "name": "Soil_Dirt_Dry"
    },
    {
      "x": -40,
      "y": 0,
      "z": -6,
      "name": "Soil_Dirt_Dry"
    },
    {
      "x": -40,
      "y": 0,
      "z": -5,
      "name": "Soil_Dirt_Dry"
    },
    {
      "x": -40,
      "y": 1,
      "z": -5,
      "name": "Soil_Dirt_Dry"
    },
    {
      "x": -40,
      "y": 0,
      "z": -4,
      "name": "Soil_Dirt_Dry"
    },
    {
      "x": -40,
      "y": 1,
      "z": -4,
      "name": "Soil_Dirt_Dry"
    },
    {
      "x": -40,
      "y": 0,
      "z": -3,
      "name": "Soil_Dirt_Dry"
    },
    {
      "x": -40,
      "y": 1,
      "z": -3,
      "name": "Soil_Gravel_Sand_Red"
    },
    {
      "x": -40,
      "y": 0,
      "z": -2,
      "name": "Soil_Dirt_Dry"
    },
    {
      "x": -40,
      "y": 1,
      "z": -2,
      "name": "Soil_Gravel_Sand_Red"
    },
    {
      "x": -40,
      "y": 0,
      "z": -1,
      "name": "Soil_Dirt_Dry"
    },
    {
      "x": -40,
      "y": 1,
      "z": -1,
      "name": "Soil_Gravel_Sand_Red"
    },
    {
      "x": -40,
      "y": 0,
      "z": 0,
      "name": "Soil_Dirt_Dry"
    },
    {
      "x": -40,
      "y": 1,
      "z": 0,
      "name": "Soil_Gravel_Sand_Red"
    },
    {
      "x": -40,
      "y": 0,
      "z": 1,
      "name": "Soil_Dirt_Dry"
    },
    {
      "x": -40,
      "y": 1,
      "z": 1,
      "name": "Soil_Gravel_Sand_Red"
    },
    {
      "x": -40,
      "y": 0,
      "z": 2,
      "name": "Soil_Dirt_Dry"
    },
    {
      "x": -40,
      "y": 1,
      "z": 2,
      "name": "Soil_Gravel_Sand_Red"
    },
    {
      "x": -40,
      "y": 0,
      "z": 3,
      "name": "Soil_Dirt_Dry"
    },
    {
      "x": -40,
      "y": 1,
      "z": 3,
      "name": "Soil_Gravel_Sand_Red"
    },
    {
      "x": -40,
      "y": 0,
      "z": 4,
      "name": "Soil_Dirt_Dry"
    },
    {
      "x": -40,
      "y": 1,
      "z": 4,
      "name": "Soil_Dirt_Dry"
    },
    {
      "x": -40,
      "y": 0,
      "z": 5,
      "name": "Soil_Dirt_Dry"
    },
    {
      "x": -40,
      "y": 1,
      "z": 5,
      "name": "Soil_Dirt_Dry"
    },
    {
      "x": -40,
      "y": 0,
      "z": 6,
      "name": "Soil_Dirt_Dry"
    },
    {
      "x": -40,
      "y": 0,
      "z": 7,
      "name": "Soil_Dirt_Dry"
    },
    {
      "x": -40,
      "y": 0,
      "z": 8,
      "name": "Soil_Dirt_Dry"
    },
    {
      "x": -40,
      "y": 0,
      "z": 9,
      "name": "Soil_Dirt_Dry"
    },
    {
      "x": -39,
      "y": 0,
      "z": -10,
      "name": "Soil_Dirt_Dry"
    },
    {
      "x": -39,
      "y": 0,
      "z": -9,
      "name": "Soil_Dirt_Dry"
    },
    {
      "x": -39,
      "y": 0,
      "z": -8,
      "name": "Soil_Dirt_Dry"
    },
    {
      "x": -39,
      "y": 0,
      "z": -7,
      "name": "Soil_Dirt_Dry"
    },
    {
      "x": -39,
      "y": 0,
      "z": -6,
      "name": "Soil_Dirt_Dry"
    },
    {
      "x": -39,
      "y": 1,
      "z": -6,
      "name": "Soil_Dirt_Dry"
    },
    {
      "x": -39,
      "y": 0,
      "z": -5,
      "name": "Soil_Dirt_Dry"
    },
    {
      "x": -39,
      "y": 1,
      "z": -5,
      "name": "Soil_Dirt_Dry"
    },
    {
      "x": -39,
      "y": 0,
      "z": -4,
      "name": "Soil_Dirt_Dry"
    },
    {
      "x": -39,
      "y": 1,
      "z": -4,
      "name": "Soil_Dirt_Dry"
    },
    {
      "x": -39,
      "y": 0,
      "z": -3,
      "name": "Soil_Dirt_Dry"
    },
    {
      "x": -39,
      "y": 1,
      "z": -3,
      "name": "Soil_Gravel_Sand_Red"
    },
    {
      "x": -39,
      "y": 0,
      "z": -2,
      "name": "Soil_Dirt_Dry"
    },
    {
      "x": -39,
      "y": 1,
      "z": -2,
      "name": "Soil_Gravel_Sand_Red"
    },
    {
      "x": -39,
      "y": 0,
      "z": -1,
      "name": "Soil_Dirt_Dry"
    },
    {
      "x": -39,
      "y": 1,
      "z": -1,
      "name": "Soil_Gravel_Sand_Red"
    },
    {
      "x": -39,
      "y": 0,
      "z": 0,
      "name": "Soil_Dirt_Dry"
    },
    {
      "x": -39,
      "y": 1,
      "z": 0,
      "name": "Soil_Gravel_Sand_Red"
    },
    {
      "x": -39,
      "y": 0,
      "z": 1,
      "name": "Soil_Dirt_Dry"
    },
    {
      "x": -39,
      "y": 1,
      "z": 1,
      "name": "Soil_Gravel_Sand_Red"
    },
    {
      "x": -39,
      "y": 0,
      "z": 2,
      "name": "Soil_Dirt_Dry"
    },
    {
      "x": -39,
      "y": 1,
      "z": 2,
      "name": "Soil_Gravel_Sand_Red"
    },
    {
      "x": -39,
      "y": 0,
      "z": 3,
      "name": "Soil_Dirt_Dry"
    },
    {
      "x": -39,
      "y": 1,
      "z": 3,
      "name": "Soil_Gravel_Sand_Red"
    },
    {
      "x": -39,
      "y": 0,
      "z": 4,
      "name": "Soil_Dirt_Dry"
    },
    {
      "x": -39,
      "y": 1,
      "z": 4,
      "name": "Soil_Dirt_Dry"
    },
    {
      "x": -39,
      "y": 0,
      "z": 5,
      "name": "Soil_Dirt_Dry"
    },
    {
      "x": -39,
      "y": 1,
      "z": 5,
      "name": "Soil_Dirt_Dry"
    },
    {
      "x": -39,
      "y": 0,
      "z": 6,
      "name": "Soil_Dirt_Dry"
    },
    {
      "x": -39,
      "y": 1,
      "z": 6,
      "name": "Soil_Dirt_Dry"
    },
    {
      "x": -39,
      "y": 0,
      "z": 7,
      "name": "Soil_Dirt_Dry"
    },
    {
      "x": -39,
      "y": 0,
      "z": 8,
      "name": "Soil_Dirt_Dry"
    },
    {
      "x": -39,
      "y": 0,
      "z": 9,
      "name": "Soil_Dirt_Dry"
    },
    {
      "x": -39,
      "y": 0,
      "z": 10,
      "name": "Soil_Dirt_Dry"
    },
    {
      "x": -38,
      "y": 0,
      "z": -11,
      "name": "Soil_Dirt_Dry"
    },
    {
      "x": -38,
      "y": 0,
      "z": -10,
      "name": "Soil_Dirt_Dry"
    },
    {
      "x": -38,
      "y": 0,
      "z": -9,
      "name": "Soil_Dirt_Dry"
    },
    {
      "x": -38,
      "y": 0,
      "z": -8,
      "name": "Soil_Dirt_Dry"
    },
    {
      "x": -38,
      "y": 0,
      "z": -7,
      "name": "Soil_Dirt_Dry"
    },
    {
      "x": -38,
      "y": 1,
      "z": -7,
      "name": "Soil_Dirt_Dry"
    },
    {
      "x": -38,
      "y": 0,
      "z": -6,
      "name": "Soil_Dirt_Dry"
    },
    {
      "x": -38,
      "y": 1,
      "z": -6,
      "name": "Soil_Dirt_Dry"
    },
    {
      "x": -38,
      "y": 0,
      "z": -5,
      "name": "Soil_Dirt_Dry"
    },
    {
      "x": -38,
      "y": 1,
      "z": -5,
      "name": "Soil_Dirt_Dry"
    },
    {
      "x": -38,
      "y": 0,
      "z": -4,
      "name": "Soil_Dirt_Dry"
    },
    {
      "x": -38,
      "y": 1,
      "z": -4,
      "name": "Soil_Dirt_Dry"
    },
    {
      "x": -38,
      "y": 0,
      "z": -3,
      "name": "Soil_Dirt_Dry"
    },
    {
      "x": -38,
      "y": 1,
      "z": -3,
      "name": "Soil_Gravel_Sand_Red"
    },
    {
      "x": -38,
      "y": 0,
      "z": -2,
      "name": "Soil_Dirt_Dry"
    },
    {
      "x": -38,
      "y": 1,
      "z": -2,
      "name": "Soil_Gravel_Sand_Red"
    },
    {
      "x": -38,
      "y": 0,
      "z": -1,
      "name": "Soil_Dirt_Dry"
    },
    {
      "x": -38,
      "y": 1,
      "z": -1,
      "name": "Soil_Gravel_Sand_Red"
    },
    {
      "x": -38,
      "y": 0,
      "z": 0,
      "name": "Soil_Dirt_Dry"
    },
    {
      "x": -38,
      "y": 1,
      "z": 0,
      "name": "Soil_Gravel_Sand_Red"
    },
    {
      "x": -38,
      "y": 0,
      "z": 1,
      "name": "Soil_Dirt_Dry"
    },
    {
      "x": -38,
      "y": 1,
      "z": 1,
      "name": "Soil_Gravel_Sand_Red"
    },
    {
      "x": -38,
      "y": 0,
      "z": 2,
      "name": "Soil_Dirt_Dry"
    },
    {
      "x": -38,
      "y": 1,
      "z": 2,
      "name": "Soil_Gravel_Sand_Red"
    },
    {
      "x": -38,
      "y": 0,
      "z": 3,
      "name": "Soil_Dirt_Dry"
    },
    {
      "x": -38,
      "y": 1,
      "z": 3,
      "name": "Soil_Gravel_Sand_Red"
    },
    {
      "x": -38,
      "y": 0,
      "z": 4,
      "name": "Soil_Dirt_Dry"
    },
    {
      "x": -38,
      "y": 1,
      "z": 4,
      "name": "Soil_Dirt_Dry"
    },
    {
      "x": -38,
      "y": 0,
      "z": 5,
      "name": "Soil_Dirt_Dry"
    },
    {
      "x": -38,
      "y": 1,
      "z": 5,
      "name": "Soil_Dirt_Dry"
    },
    {
      "x": -38,
      "y": 0,
      "z": 6,
      "name": "Soil_Dirt_Dry"
    },
    {
      "x": -38,
      "y": 1,
      "z": 6,
      "name": "Soil_Dirt_Dry"
    },
    {
      "x": -38,
      "y": 0,
      "z": 7,
      "name": "Soil_Dirt_Dry"
    },
    {
      "x": -38,
      "y": 1,
      "z": 7,
      "name": "Soil_Dirt_Dry"
    },
    {
      "x": -38,
      "y": 0,
      "z": 8,
      "name": "Soil_Dirt_Dry"
    },
    {
      "x": -38,
      "y": 0,
      "z": 9,
      "name": "Soil_Dirt_Dry"
    },
    {
      "x": -38,
      "y": 0,
      "z": 10,
      "name": "Soil_Dirt_Dry"
    },
    {
      "x": -38,
      "y": 0,
      "z": 11,
      "name": "Soil_Dirt_Dry"
    },
    {
      "x": -37,
      "y": 0,
      "z": -22,
      "name": "Soil_Dirt_Dry"
    },
    {
      "x": -37,
      "y": 0,
      "z": -21,
      "name": "Soil_Dirt_Dry"
    },
    {
      "x": -37,
      "y": 0,
      "z": -20,
      "name": "Soil_Dirt_Dry"
    },
    {
      "x": -37,
      "y": 0,
      "z": -19,
      "name": "Soil_Dirt_Dry"
    },
    {
      "x": -37,
      "y": 0,
      "z": -18,
      "name": "Soil_Dirt_Dry"
    },
    {
      "x": -37,
      "y": 0,
      "z": -17,
      "name": "Soil_Dirt_Dry"
    },
    {
      "x": -37,
      "y": 0,
      "z": -16,
      "name": "Soil_Dirt_Dry"
    },
    {
      "x": -37,
      "y": 0,
      "z": -15,
      "name": "Soil_Dirt_Dry"
    },
    {
      "x": -37,
      "y": 0,
      "z": -14,
      "name": "Soil_Dirt_Dry"
    },
    {
      "x": -37,
      "y": 0,
      "z": -11,
      "name": "Soil_Dirt_Dry"
    },
    {
      "x": -37,
      "y": 0,
      "z": -10,
      "name": "Soil_Dirt_Dry"
    },
    {
      "x": -37,
      "y": 0,
      "z": -9,
      "name": "Soil_Dirt_Dry"
    },
    {
      "x": -37,
      "y": 0,
      "z": -8,
      "name": "Soil_Dirt_Dry"
    },
    {
      "x": -37,
      "y": 1,
      "z": -8,
      "name": "Soil_Dirt_Dry"
    },
    {
      "x": -37,
      "y": 0,
      "z": -7,
      "name": "Soil_Dirt_Dry"
    },
    {
      "x": -37,
      "y": 1,
      "z": -7,
      "name": "Soil_Dirt_Dry"
    },
    {
      "x": -37,
      "y": 0,
      "z": -6,
      "name": "Soil_Dirt_Dry"
    },
    {
      "x": -37,
      "y": 1,
      "z": -6,
      "name": "Soil_Dirt_Dry"
    },
    {
      "x": -37,
      "y": 0,
      "z": -5,
      "name": "Soil_Dirt_Dry"
    },
    {
      "x": -37,
      "y": 1,
      "z": -5,
      "name": "Soil_Dirt_Dry"
    },
    {
      "x": -37,
      "y": 0,
      "z": -4,
      "name": "Soil_Dirt_Dry"
    },
    {
      "x": -37,
      "y": 1,
      "z": -4,
      "name": "Soil_Dirt_Dry"
    },
    {
      "x": -37,
      "y": 0,
      "z": -3,
      "name": "Soil_Dirt_Dry"
    },
    {
      "x": -37,
      "y": 1,
      "z": -3,
      "name": "Soil_Gravel_Sand_Red"
    },
    {
      "x": -37,
      "y": 0,
      "z": -2,
      "name": "Soil_Dirt_Dry"
    },
    {
      "x": -37,
      "y": 1,
      "z": -2,
      "name": "Soil_Gravel_Sand_Red"
    },
    {
      "x": -37,
      "y": 0,
      "z": -1,
      "name": "Soil_Dirt_Dry"
    },
    {
      "x": -37,
      "y": 1,
      "z": -1,
      "name": "Soil_Gravel_Sand_Red"
    },
    {
      "x": -37,
      "y": 0,
      "z": 0,
      "name": "Soil_Dirt_Dry"
    },
    {
      "x": -37,
      "y": 1,
      "z": 0,
      "name": "Soil_Gravel_Sand_Red"
    },
    {
      "x": -37,
      "y": 0,
      "z": 1,
      "name": "Soil_Dirt_Dry"
    },
    {
      "x": -37,
      "y": 1,
      "z": 1,
      "name": "Soil_Gravel_Sand_Red"
    },
    {
      "x": -37,
      "y": 0,
      "z": 2,
      "name": "Soil_Dirt_Dry"
    },
    {
      "x": -37,
      "y": 1,
      "z": 2,
      "name": "Soil_Gravel_Sand_Red"
    },
    {
      "x": -37,
      "y": 0,
      "z": 3,
      "name": "Soil_Dirt_Dry"
    },
    {
      "x": -37,
      "y": 1,
      "z": 3,
      "name": "Soil_Gravel_Sand_Red"
    },
    {
      "x": -37,
      "y": 0,
      "z": 4,
      "name": "Soil_Dirt_Dry"
    },
    {
      "x": -37,
      "y": 1,
      "z": 4,
      "name": "Soil_Dirt_Dry"
    },
    {
      "x": -37,
      "y": 0,
      "z": 5,
      "name": "Soil_Dirt_Dry"
    },
    {
      "x": -37,
      "y": 1,
      "z": 5,
      "name": "Soil_Dirt_Dry"
    },
    {
      "x": -37,
      "y": 0,
      "z": 6,
      "name": "Soil_Dirt_Dry"
    },
    {
      "x": -37,
      "y": 1,
      "z": 6,
      "name": "Soil_Dirt_Dry"
    },
    {
      "x": -37,
      "y": 0,
      "z": 7,
      "name": "Soil_Dirt_Dry"
    },
    {
      "x": -37,
      "y": 1,
      "z": 7,
      "name": "Soil_Dirt_Dry"
    },
    {
      "x": -37,
      "y": 0,
      "z": 8,
      "name": "Soil_Dirt_Dry"
    },
    {
      "x": -37,
      "y": 1,
      "z": 8,
      "name": "Soil_Dirt_Dry"
    },
    {
      "x": -37,
      "y": 0,
      "z": 9,
      "name": "Soil_Dirt_Dry"
    },
    {
      "x": -37,
      "y": 0,
      "z": 10,
      "name": "Soil_Dirt_Dry"
    },
    {
      "x": -37,
      "y": 0,
      "z": 11,
      "name": "Soil_Dirt_Dry"
    },
    {
      "x": -37,
      "y": 0,
      "z": 14,
      "name": "Soil_Dirt_Dry"
    },
    {
      "x": -37,
      "y": 0,
      "z": 15,
      "name": "Soil_Dirt_Dry"
    },
    {
      "x": -37,
      "y": 0,
      "z": 16,
      "name": "Soil_Dirt_Dry"
    },
    {
      "x": -37,
      "y": 0,
      "z": 17,
      "name": "Soil_Dirt_Dry"
    },
    {
      "x": -37,
      "y": 0,
      "z": 18,
      "name": "Soil_Dirt_Dry"
    },
    {
      "x": -37,
      "y": 0,
      "z": 19,
      "name": "Soil_Dirt_Dry"
    },
    {
      "x": -37,
      "y": 0,
      "z": 20,
      "name": "Soil_Dirt_Dry"
    },
    {
      "x": -37,
      "y": 0,
      "z": 21,
      "name": "Soil_Dirt_Dry"
    },
    {
      "x": -37,
      "y": 0,
      "z": 22,
      "name": "Soil_Dirt_Dry"
    },
    {
      "x": -36,
      "y": 0,
      "z": -24,
      "name": "Soil_Dirt_Dry"
    },
    {
      "x": -36,
      "y": 0,
      "z": -23,
      "name": "Soil_Dirt_Dry"
    },
    {
      "x": -36,
      "y": 0,
      "z": -22,
      "name": "Soil_Dirt_Dry"
    },
    {
      "x": -36,
      "y": 0,
      "z": -21,
      "name": "Soil_Dirt_Dry"
    },
    {
      "x": -36,
      "y": 0,
      "z": -20,
      "name": "Soil_Dirt_Dry"
    },
    {
      "x": -36,
      "y": 0,
      "z": -19,
      "name": "Soil_Dirt_Dry"
    },
    {
      "x": -36,
      "y": 0,
      "z": -18,
      "name": "Soil_Dirt_Dry"
    },
    {
      "x": -36,
      "y": 0,
      "z": -17,
      "name": "Soil_Dirt_Dry"
    },
    {
      "x": -36,
      "y": 0,
      "z": -16,
      "name": "Soil_Dirt_Dry"
    },
    {
      "x": -36,
      "y": 0,
      "z": -15,
      "name": "Soil_Dirt_Dry"
    },
    {
      "x": -36,
      "y": 0,
      "z": -14,
      "name": "Soil_Dirt_Dry"
    },
    {
      "x": -36,
      "y": 0,
      "z": -13,
      "name": "Soil_Dirt_Dry"
    },
    {
      "x": -36,
      "y": 0,
      "z": -12,
      "name": "Soil_Dirt_Dry"
    },
    {
      "x": -36,
      "y": 0,
      "z": -11,
      "name": "Soil_Dirt_Dry"
    },
    {
      "x": -36,
      "y": 0,
      "z": -10,
      "name": "Soil_Dirt_Dry"
    },
    {
      "x": -36,
      "y": 0,
      "z": -9,
      "name": "Soil_Dirt_Dry"
    },
    {
      "x": -36,
      "y": 1,
      "z": -9,
      "name": "Soil_Dirt_Dry"
    },
    {
      "x": -36,
      "y": 0,
      "z": -8,
      "name": "Soil_Dirt_Dry"
    },
    {
      "x": -36,
      "y": 1,
      "z": -8,
      "name": "Soil_Dirt_Dry"
    },
    {
      "x": -36,
      "y": 0,
      "z": -7,
      "name": "Soil_Dirt_Dry"
    },
    {
      "x": -36,
      "y": 1,
      "z": -7,
      "name": "Soil_Dirt_Dry"
    },
    {
      "x": -36,
      "y": 0,
      "z": -6,
      "name": "Soil_Dirt_Dry"
    },
    {
      "x": -36,
      "y": 1,
      "z": -6,
      "name": "Soil_Dirt_Dry"
    },
    {
      "x": -36,
      "y": 0,
      "z": -5,
      "name": "Soil_Dirt_Dry"
    },
    {
      "x": -36,
      "y": 1,
      "z": -5,
      "name": "Soil_Dirt_Dry"
    },
    {
      "x": -36,
      "y": 11,
      "z": -5,
      "name": "Wood_Dry_Branch_Short",
      "support": 15,
      "rotation": 3
    },
    {
      "x": -36,
      "y": 0,
      "z": -4,
      "name": "Soil_Dirt_Dry"
    },
    {
      "x": -36,
      "y": 1,
      "z": -4,
      "name": "Soil_Dirt_Dry"
    },
    {
      "x": -36,
      "y": 11,
      "z": -4,
      "name": "Cloth_Roof_Leather",
      "rotation": 3
    },
    {
      "x": -36,
      "y": 0,
      "z": -3,
      "name": "Soil_Dirt_Dry"
    },
    {
      "x": -36,
      "y": 1,
      "z": -3,
      "name": "Soil_Gravel_Sand_Red"
    },
    {
      "x": -36,
      "y": 11,
      "z": -3,
      "name": "Cloth_Roof_Leather",
      "rotation": 3
    },
    {
      "x": -36,
      "y": 0,
      "z": -2,
      "name": "Soil_Dirt_Dry"
    },
    {
      "x": -36,
      "y": 1,
      "z": -2,
      "name": "Soil_Dirt_Dry"
    },
    {
      "x": -36,
      "y": 2,
      "z": -2,
      "name": "Soil_Gravel_Sand_Red"
    },
    {
      "x": -36,
      "y": 11,
      "z": -2,
      "name": "Cloth_Roof_Leather",
      "rotation": 3
    },
    {
      "x": -36,
      "y": 0,
      "z": -1,
      "name": "Soil_Dirt_Dry"
    },
    {
      "x": -36,
      "y": 1,
      "z": -1,
      "name": "Soil_Dirt_Dry"
    },
    {
      "x": -36,
      "y": 2,
      "z": -1,
      "name": "Soil_Gravel_Sand_Red"
    },
    {
      "x": -36,
      "y": 11,
      "z": -1,
      "name": "Cloth_Roof_Leather",
      "rotation": 3
    },
    {
      "x": -36,
      "y": 0,
      "z": 0,
      "name": "Soil_Dirt_Dry"
    },
    {
      "x": -36,
      "y": 1,
      "z": 0,
      "name": "Soil_Dirt_Dry"
    },
    {
      "x": -36,
      "y": 2,
      "z": 0,
      "name": "Soil_Gravel_Sand_Red"
    },
    {
      "x": -36,
      "y": 11,
      "z": 0,
      "name": "Cloth_Roof_Leather",
      "rotation": 3
    },
    {
      "x": -36,
      "y": 0,
      "z": 1,
      "name": "Soil_Dirt_Dry"
    },
    {
      "x": -36,
      "y": 1,
      "z": 1,
      "name": "Soil_Dirt_Dry"
    },
    {
      "x": -36,
      "y": 2,
      "z": 1,
      "name": "Soil_Gravel_Sand_Red"
    },
    {
      "x": -36,
      "y": 11,
      "z": 1,
      "name": "Cloth_Roof_Leather",
      "rotation": 3
    },
    {
      "x": -36,
      "y": 0,
      "z": 2,
      "name": "Soil_Dirt_Dry"
    },
    {
      "x": -36,
      "y": 1,
      "z": 2,
      "name": "Soil_Dirt_Dry"
    },
    {
      "x": -36,
      "y": 2,
      "z": 2,
      "name": "Soil_Gravel_Sand_Red"
    },
    {
      "x": -36,
      "y": 11,
      "z": 2,
      "name": "Cloth_Roof_Leather",
      "rotation": 3
    },
    {
      "x": -36,
      "y": 0,
      "z": 3,
      "name": "Soil_Dirt_Dry"
    },
    {
      "x": -36,
      "y": 1,
      "z": 3,
      "name": "Soil_Gravel_Sand_Red"
    },
    {
      "x": -36,
      "y": 11,
      "z": 3,
      "name": "Cloth_Roof_Leather",
      "rotation": 3
    },
    {
      "x": -36,
      "y": 0,
      "z": 4,
      "name": "Soil_Dirt_Dry"
    },
    {
      "x": -36,
      "y": 1,
      "z": 4,
      "name": "Soil_Dirt_Dry"
    },
    {
      "x": -36,
      "y": 11,
      "z": 4,
      "name": "Cloth_Roof_Leather",
      "rotation": 3
    },
    {
      "x": -36,
      "y": 0,
      "z": 5,
      "name": "Soil_Dirt_Dry"
    },
    {
      "x": -36,
      "y": 1,
      "z": 5,
      "name": "Soil_Dirt_Dry"
    },
    {
      "x": -36,
      "y": 11,
      "z": 5,
      "name": "Wood_Dry_Branch_Short",
      "support": 15,
      "rotation": 3
    },
    {
      "x": -36,
      "y": 0,
      "z": 6,
      "name": "Soil_Dirt_Dry"
    },
    {
      "x": -36,
      "y": 1,
      "z": 6,
      "name": "Soil_Dirt_Dry"
    },
    {
      "x": -36,
      "y": 0,
      "z": 7,
      "name": "Soil_Dirt_Dry"
    },
    {
      "x": -36,
      "y": 1,
      "z": 7,
      "name": "Soil_Dirt_Dry"
    },
    {
      "x": -36,
      "y": 0,
      "z": 8,
      "name": "Soil_Dirt_Dry"
    },
    {
      "x": -36,
      "y": 1,
      "z": 8,
      "name": "Soil_Dirt_Dry"
    },
    {
      "x": -36,
      "y": 0,
      "z": 9,
      "name": "Soil_Dirt_Dry"
    },
    {
      "x": -36,
      "y": 1,
      "z": 9,
      "name": "Soil_Dirt_Dry"
    },
    {
      "x": -36,
      "y": 0,
      "z": 10,
      "name": "Soil_Dirt_Dry"
    },
    {
      "x": -36,
      "y": 0,
      "z": 11,
      "name": "Soil_Dirt_Dry"
    },
    {
      "x": -36,
      "y": 0,
      "z": 12,
      "name": "Soil_Dirt_Dry"
    },
    {
      "x": -36,
      "y": 0,
      "z": 13,
      "name": "Soil_Dirt_Dry"
    },
    {
      "x": -36,
      "y": 0,
      "z": 14,
      "name": "Soil_Dirt_Dry"
    },
    {
      "x": -36,
      "y": 0,
      "z": 15,
      "name": "Soil_Dirt_Dry"
    },
    {
      "x": -36,
      "y": 0,
      "z": 16,
      "name": "Soil_Dirt_Dry"
    },
    {
      "x": -36,
      "y": 0,
      "z": 17,
      "name": "Soil_Dirt_Dry"
    },
    {
      "x": -36,
      "y": 0,
      "z": 18,
      "name": "Soil_Dirt_Dry"
    },
    {
      "x": -36,
      "y": 0,
      "z": 19,
      "name": "Soil_Dirt_Dry"
    },
    {
      "x": -36,
      "y": 0,
      "z": 20,
      "name": "Soil_Dirt_Dry"
    },
    {
      "x": -36,
      "y": 0,
      "z": 21,
      "name": "Soil_Dirt_Dry"
    },
    {
      "x": -36,
      "y": 0,
      "z": 22,
      "name": "Soil_Dirt_Dry"
    },
    {
      "x": -36,
      "y": 0,
      "z": 23,
      "name": "Soil_Dirt_Dry"
    },
    {
      "x": -36,
      "y": 0,
      "z": 24,
      "name": "Soil_Dirt_Dry"
    },
    {
      "x": -35,
      "y": 0,
      "z": -26,
      "name": "Soil_Dirt_Dry"
    },
    {
      "x": -35,
      "y": 0,
      "z": -25,
      "name": "Soil_Dirt_Dry"
    },
    {
      "x": -35,
      "y": 0,
      "z": -24,
      "name": "Soil_Dirt_Dry"
    },
    {
      "x": -35,
      "y": 0,
      "z": -23,
      "name": "Soil_Dirt_Dry"
    },
    {
      "x": -35,
      "y": 0,
      "z": -22,
      "name": "Soil_Dirt_Dry"
    },
    {
      "x": -35,
      "y": 0,
      "z": -21,
      "name": "Soil_Dirt_Dry"
    },
    {
      "x": -35,
      "y": 0,
      "z": -20,
      "name": "Soil_Dirt_Dry"
    },
    {
      "x": -35,
      "y": 1,
      "z": -20,
      "name": "Soil_Dirt_Dry"
    },
    {
      "x": -35,
      "y": 0,
      "z": -19,
      "name": "Soil_Dirt_Dry"
    },
    {
      "x": -35,
      "y": 1,
      "z": -19,
      "name": "Soil_Dirt_Dry"
    },
    {
      "x": -35,
      "y": 0,
      "z": -18,
      "name": "Soil_Dirt_Dry"
    },
    {
      "x": -35,
      "y": 1,
      "z": -18,
      "name": "Soil_Dirt_Dry"
    },
    {
      "x": -35,
      "y": 0,
      "z": -17,
      "name": "Soil_Dirt_Dry"
    },
    {
      "x": -35,
      "y": 1,
      "z": -17,
      "name": "Soil_Dirt_Dry"
    },
    {
      "x": -35,
      "y": 0,
      "z": -16,
      "name": "Soil_Dirt_Dry"
    },
    {
      "x": -35,
      "y": 1,
      "z": -16,
      "name": "Soil_Dirt_Dry"
    },
    {
      "x": -35,
      "y": 0,
      "z": -15,
      "name": "Soil_Dirt_Dry"
    },
    {
      "x": -35,
      "y": 0,
      "z": -14,
      "name": "Soil_Dirt_Dry"
    },
    {
      "x": -35,
      "y": 0,
      "z": -13,
      "name": "Soil_Dirt_Dry"
    },
    {
      "x": -35,
      "y": 0,
      "z": -12,
      "name": "Soil_Dirt_Dry"
    },
    {
      "x": -35,
      "y": 0,
      "z": -11,
      "name": "Soil_Dirt_Dry"
    },
    {
      "x": -35,
      "y": 0,
      "z": -10,
      "name": "Soil_Dirt_Dry"
    },
    {
      "x": -35,
      "y": 1,
      "z": -10,
      "name": "Soil_Dirt_Dry"
    },
    {
      "x": -35,
      "y": 0,
      "z": -9,
      "name": "Soil_Dirt_Dry"
    },
    {
      "x": -35,
      "y": 1,
      "z": -9,
      "name": "Soil_Dirt_Dry"
    },
    {
      "x": -35,
      "y": 0,
      "z": -8,
      "name": "Soil_Dirt_Dry"
    },
    {
      "x": -35,
      "y": 1,
      "z": -8,
      "name": "Soil_Dirt_Dry"
    },
    {
      "x": -35,
      "y": 0,
      "z": -7,
      "name": "Soil_Dirt_Dry"
    },
    {
      "x": -35,
      "y": 1,
      "z": -7,
      "name": "Soil_Dirt_Dry"
    },
    {
      "x": -35,
      "y": 0,
      "z": -6,
      "name": "Soil_Dirt_Dry"
    },
    {
      "x": -35,
      "y": 1,
      "z": -6,
      "name": "Soil_Dirt_Dry"
    },
    {
      "x": -35,
      "y": 11,
      "z": -6,
      "name": "Wood_Dry_Branch_Short",
      "support": 15,
      "rotation": 2
    },
    {
      "x": -35,
      "y": 0,
      "z": -5,
      "name": "Soil_Dirt_Dry"
    },
    {
      "x": -35,
      "y": 1,
      "z": -5,
      "name": "Soil_Dirt_Dry"
    },
    {
      "x": -35,
      "y": 2,
      "z": -5,
      "name": "Wood_Dry_Trunk",
      "support": 15
    },
    {
      "x": -35,
      "y": 3,
      "z": -5,
      "name": "Wood_Dry_Trunk",
      "support": 15
    },
    {
      "x": -35,
      "y": 4,
      "z": -5,
      "name": "Wood_Dry_Trunk",
      "support": 15
    },
    {
      "x": -35,
      "y": 5,
      "z": -5,
      "name": "Wood_Dry_Trunk",
      "support": 15
    },
    {
      "x": -35,
      "y": 6,
      "z": -5,
      "name": "Wood_Dry_Trunk",
      "support": 15
    },
    {
      "x": -35,
      "y": 7,
      "z": -5,
      "name": "Wood_Dry_Trunk",
      "support": 15
    },
    {
      "x": -35,
      "y": 8,
      "z": -5,
      "name": "Wood_Dry_Trunk",
      "support": 15
    },
    {
      "x": -35,
      "y": 9,
      "z": -5,
      "name": "Wood_Dry_Trunk",
      "support": 15
    },
    {
      "x": -35,
      "y": 10,
      "z": -5,
      "name": "Wood_Dry_Trunk",
      "support": 15
    },
    {
      "x": -35,
      "y": 11,
      "z": -5,
      "name": "Wood_Dry_Trunk",
      "support": 15
    },
    {
      "x": -35,
      "y": 12,
      "z": -5,
      "name": "Wood_Dry_Trunk",
      "support": 15
    },
    {
      "x": -35,
      "y": 0,
      "z": -4,
      "name": "Soil_Dirt_Dry"
    },
    {
      "x": -35,
      "y": 1,
      "z": -4,
      "name": "Soil_Dirt_Dry"
    },
    {
      "x": -35,
      "y": 2,
      "z": -4,
      "name": "Soil_Dirt_Dry"
    },
    {
      "x": -35,
      "y": 11,
      "z": -4,
      "name": "Wood_Dry_Trunk",
      "support": 15,
      "rotation": 4
    },
    {
      "x": -35,
      "y": 12,
      "z": -4,
      "name": "Cloth_Roof_Leather_Shallow",
      "rotation": 3
    },
    {
      "x": -35,
      "y": 0,
      "z": -3,
      "name": "Soil_Dirt_Dry"
    },
    {
      "x": -35,
      "y": 1,
      "z": -3,
      "name": "Soil_Dirt_Dry"
    },
    {
      "x": -35,
      "y": 2,
      "z": -3,
      "name": "Soil_Gravel_Sand_Red"
    },
    {
      "x": -35,
      "y": 11,
      "z": -3,
      "name": "Wood_Dry_Trunk",
      "support": 15,
      "rotation": 4
    },
    {
      "x": -35,
      "y": 12,
      "z": -3,
      "name": "Cloth_Roof_Leather_Shallow",
      "rotation": 3
    },
    {
      "x": -35,
      "y": 0,
      "z": -2,
      "name": "Soil_Dirt_Dry"
    },
    {
      "x": -35,
      "y": 1,
      "z": -2,
      "name": "Soil_Dirt_Dry"
    },
    {
      "x": -35,
      "y": 2,
      "z": -2,
      "name": "Soil_Gravel_Sand_Red"
    },
    {
      "x": -35,
      "y": 11,
      "z": -2,
      "name": "Wood_Dry_Trunk",
      "support": 15,
      "rotation": 4
    },
    {
      "x": -35,
      "y": 12,
      "z": -2,
      "name": "Cloth_Roof_Leather_Shallow",
      "rotation": 3
    },
    {
      "x": -35,
      "y": 0,
      "z": -1,
      "name": "Soil_Dirt_Dry"
    },
    {
      "x": -35,
      "y": 1,
      "z": -1,
      "name": "Soil_Dirt_Dry"
    },
    {
      "x": -35,
      "y": 2,
      "z": -1,
      "name": "Soil_Gravel_Sand_Red"
    },
    {
      "x": -35,
      "y": 11,
      "z": -1,
      "name": "Wood_Dry_Trunk",
      "support": 15,
      "rotation": 4
    },
    {
      "x": -35,
      "y": 12,
      "z": -1,
      "name": "Cloth_Roof_Leather_Shallow",
      "rotation": 3
    },
    {
      "x": -35,
      "y": 0,
      "z": 0,
      "name": "Soil_Dirt_Dry"
    },
    {
      "x": -35,
      "y": 1,
      "z": 0,
      "name": "Soil_Dirt_Dry"
    },
    {
      "x": -35,
      "y": 2,
      "z": 0,
      "name": "Soil_Gravel_Sand_Red"
    },
    {
      "x": -35,
      "y": 11,
      "z": 0,
      "name": "Wood_Dry_Trunk",
      "support": 15,
      "rotation": 4
    },
    {
      "x": -35,
      "y": 12,
      "z": 0,
      "name": "Cloth_Roof_Leather_Shallow",
      "rotation": 3
    },
    {
      "x": -35,
      "y": 0,
      "z": 1,
      "name": "Soil_Dirt_Dry"
    },
    {
      "x": -35,
      "y": 1,
      "z": 1,
      "name": "Soil_Dirt_Dry"
    },
    {
      "x": -35,
      "y": 2,
      "z": 1,
      "name": "Soil_Gravel_Sand_Red"
    },
    {
      "x": -35,
      "y": 11,
      "z": 1,
      "name": "Wood_Dry_Trunk",
      "support": 15,
      "rotation": 4
    },
    {
      "x": -35,
      "y": 12,
      "z": 1,
      "name": "Cloth_Roof_Leather_Shallow",
      "rotation": 3
    },
    {
      "x": -35,
      "y": 0,
      "z": 2,
      "name": "Soil_Dirt_Dry"
    },
    {
      "x": -35,
      "y": 1,
      "z": 2,
      "name": "Soil_Dirt_Dry"
    },
    {
      "x": -35,
      "y": 2,
      "z": 2,
      "name": "Soil_Gravel_Sand_Red"
    },
    {
      "x": -35,
      "y": 11,
      "z": 2,
      "name": "Wood_Dry_Trunk",
      "support": 15,
      "rotation": 4
    },
    {
      "x": -35,
      "y": 12,
      "z": 2,
      "name": "Cloth_Roof_Leather_Shallow",
      "rotation": 3
    },
    {
      "x": -35,
      "y": 0,
      "z": 3,
      "name": "Soil_Dirt_Dry"
    },
    {
      "x": -35,
      "y": 1,
      "z": 3,
      "name": "Soil_Dirt_Dry"
    },
    {
      "x": -35,
      "y": 2,
      "z": 3,
      "name": "Soil_Gravel_Sand_Red"
    },
    {
      "x": -35,
      "y": 11,
      "z": 3,
      "name": "Wood_Dry_Trunk",
      "support": 15,
      "rotation": 4
    },
    {
      "x": -35,
      "y": 12,
      "z": 3,
      "name": "Cloth_Roof_Leather_Shallow",
      "rotation": 3
    },
    {
      "x": -35,
      "y": 0,
      "z": 4,
      "name": "Soil_Dirt_Dry"
    },
    {
      "x": -35,
      "y": 1,
      "z": 4,
      "name": "Soil_Dirt_Dry"
    },
    {
      "x": -35,
      "y": 2,
      "z": 4,
      "name": "Soil_Dirt_Dry"
    },
    {
      "x": -35,
      "y": 11,
      "z": 4,
      "name": "Wood_Dry_Trunk",
      "support": 15,
      "rotation": 4
    },
    {
      "x": -35,
      "y": 12,
      "z": 4,
      "name": "Cloth_Roof_Leather_Shallow",
      "rotation": 3
    },
    {
      "x": -35,
      "y": 0,
      "z": 5,
      "name": "Soil_Dirt_Dry"
    },
    {
      "x": -35,
      "y": 1,
      "z": 5,
      "name": "Soil_Dirt_Dry"
    },
    {
      "x": -35,
      "y": 2,
      "z": 5,
      "name": "Wood_Dry_Trunk",
      "support": 15
    },
    {
      "x": -35,
      "y": 3,
      "z": 5,
      "name": "Wood_Dry_Trunk",
      "support": 15
    },
    {
      "x": -35,
      "y": 4,
      "z": 5,
      "name": "Wood_Dry_Trunk",
      "support": 15
    },
    {
      "x": -35,
      "y": 5,
      "z": 5,
      "name": "Wood_Dry_Trunk",
      "support": 15
    },
    {
      "x": -35,
      "y": 6,
      "z": 5,
      "name": "Wood_Dry_Trunk",
      "support": 15
    },
    {
      "x": -35,
      "y": 7,
      "z": 5,
      "name": "Wood_Dry_Trunk",
      "support": 15
    },
    {
      "x": -35,
      "y": 8,
      "z": 5,
      "name": "Wood_Dry_Trunk",
      "support": 15
    },
    {
      "x": -35,
      "y": 9,
      "z": 5,
      "name": "Wood_Dry_Trunk",
      "support": 15
    },
    {
      "x": -35,
      "y": 10,
      "z": 5,
      "name": "Wood_Dry_Trunk",
      "support": 15
    },
    {
      "x": -35,
      "y": 11,
      "z": 5,
      "name": "Wood_Dry_Trunk",
      "support": 15
    },
    {
      "x": -35,
      "y": 12,
      "z": 5,
      "name": "Wood_Dry_Trunk",
      "support": 15
    },
    {
      "x": -35,
      "y": 0,
      "z": 6,
      "name": "Soil_Dirt_Dry"
    },
    {
      "x": -35,
      "y": 1,
      "z": 6,
      "name": "Soil_Dirt_Dry"
    },
    {
      "x": -35,
      "y": 11,
      "z": 6,
      "name": "Wood_Dry_Branch_Short",
      "support": 15
    },
    {
      "x": -35,
      "y": 0,
      "z": 7,
      "name": "Soil_Dirt_Dry"
    },
    {
      "x": -35,
      "y": 1,
      "z": 7,
      "name": "Soil_Dirt_Dry"
    },
    {
      "x": -35,
      "y": 0,
      "z": 8,
      "name": "Soil_Dirt_Dry"
    },
    {
      "x": -35,
      "y": 1,
      "z": 8,
      "name": "Soil_Dirt_Dry"
    },
    {
      "x": -35,
      "y": 0,
      "z": 9,
      "name": "Soil_Dirt_Dry"
    },
    {
      "x": -35,
      "y": 1,
      "z": 9,
      "name": "Soil_Dirt_Dry"
    },
    {
      "x": -35,
      "y": 0,
      "z": 10,
      "name": "Soil_Dirt_Dry"
    },
    {
      "x": -35,
      "y": 1,
      "z": 10,
      "name": "Soil_Dirt_Dry"
    },
    {
      "x": -35,
      "y": 0,
      "z": 11,
      "name": "Soil_Dirt_Dry"
    },
    {
      "x": -35,
      "y": 0,
      "z": 12,
      "name": "Soil_Dirt_Dry"
    },
    {
      "x": -35,
      "y": 0,
      "z": 13,
      "name": "Soil_Dirt_Dry"
    },
    {
      "x": -35,
      "y": 0,
      "z": 14,
      "name": "Soil_Dirt_Dry"
    },
    {
      "x": -35,
      "y": 0,
      "z": 15,
      "name": "Soil_Dirt_Dry"
    },
    {
      "x": -35,
      "y": 0,
      "z": 16,
      "name": "Soil_Dirt_Dry"
    },
    {
      "x": -35,
      "y": 1,
      "z": 16,
      "name": "Soil_Dirt_Dry"
    },
    {
      "x": -35,
      "y": 0,
      "z": 17,
      "name": "Soil_Dirt_Dry"
    },
    {
      "x": -35,
      "y": 1,
      "z": 17,
      "name": "Soil_Dirt_Dry"
    },
    {
      "x": -35,
      "y": 0,
      "z": 18,
      "name": "Soil_Dirt_Dry"
    },
    {
      "x": -35,
      "y": 1,
      "z": 18,
      "name": "Soil_Dirt_Dry"
    },
    {
      "x": -35,
      "y": 0,
      "z": 19,
      "name": "Soil_Dirt_Dry"
    },
    {
      "x": -35,
      "y": 1,
      "z": 19,
      "name": "Soil_Dirt_Dry"
    },
    {
      "x": -35,
      "y": 0,
      "z": 20,
      "name": "Soil_Dirt_Dry"
    },
    {
      "x": -35,
      "y": 1,
      "z": 20,
      "name": "Soil_Dirt_Dry"
    },
    {
      "x": -35,
      "y": 0,
      "z": 21,
      "name": "Soil_Dirt_Dry"
    },
    {
      "x": -35,
      "y": 0,
      "z": 22,
      "name": "Soil_Dirt_Dry"
    },
    {
      "x": -35,
      "y": 0,
      "z": 23,
      "name": "Soil_Dirt_Dry"
    },
    {
      "x": -35,
      "y": 0,
      "z": 24,
      "name": "Soil_Dirt_Dry"
    },
    {
      "x": -35,
      "y": 0,
      "z": 25,
      "name": "Soil_Dirt_Dry"
    },
    {
      "x": -35,
      "y": 0,
      "z": 26,
      "name": "Soil_Dirt_Dry"
    },
    {
      "x": -34,
      "y": 0,
      "z": -27,
      "name": "Soil_Dirt_Dry"
    },
    {
      "x": -34,
      "y": 0,
      "z": -26,
      "name": "Soil_Dirt_Dry"
    },
    {
      "x": -34,
      "y": 0,
      "z": -25,
      "name": "Soil_Dirt_Dry"
    },
    {
      "x": -34,
      "y": 0,
      "z": -24,
      "name": "Soil_Dirt_Dry"
    },
    {
      "x": -34,
      "y": 0,
      "z": -23,
      "name": "Soil_Dirt_Dry"
    },
    {
      "x": -34,
      "y": 1,
      "z": -23,
      "name": "Soil_Dirt_Dry"
    },
    {
      "x": -34,
      "y": 0,
      "z": -22,
      "name": "Soil_Dirt_Dry"
    },
    {
      "x": -34,
      "y": 1,
      "z": -22,
      "name": "Soil_Dirt_Dry"
    },
    {
      "x": -34,
      "y": 0,
      "z": -21,
      "name": "Soil_Dirt_Dry"
    },
    {
      "x": -34,
      "y": 1,
      "z": -21,
      "name": "Soil_Dirt_Dry"
    },
    {
      "x": -34,
      "y": 0,
      "z": -20,
      "name": "Soil_Dirt_Dry"
    },
    {
      "x": -34,
      "y": 1,
      "z": -20,
      "name": "Soil_Dirt_Dry"
    },
    {
      "x": -34,
      "y": 0,
      "z": -19,
      "name": "Soil_Dirt_Dry"
    },
    {
      "x": -34,
      "y": 1,
      "z": -19,
      "name": "Soil_Dirt_Dry"
    },
    {
      "x": -34,
      "y": 0,
      "z": -18,
      "name": "Soil_Dirt_Dry"
    },
    {
      "x": -34,
      "y": 1,
      "z": -18,
      "name": "Soil_Dirt_Dry"
    },
    {
      "x": -34,
      "y": 0,
      "z": -17,
      "name": "Soil_Dirt_Dry"
    },
    {
      "x": -34,
      "y": 1,
      "z": -17,
      "name": "Soil_Dirt_Dry"
    },
    {
      "x": -34,
      "y": 0,
      "z": -16,
      "name": "Soil_Dirt_Dry"
    },
    {
      "x": -34,
      "y": 1,
      "z": -16,
      "name": "Soil_Dirt_Dry"
    },
    {
      "x": -34,
      "y": 0,
      "z": -15,
      "name": "Soil_Dirt_Dry"
    },
    {
      "x": -34,
      "y": 1,
      "z": -15,
      "name": "Soil_Dirt_Dry"
    },
    {
      "x": -34,
      "y": 0,
      "z": -14,
      "name": "Soil_Dirt_Dry"
    },
    {
      "x": -34,
      "y": 1,
      "z": -14,
      "name": "Soil_Dirt_Dry"
    },
    {
      "x": -34,
      "y": 0,
      "z": -13,
      "name": "Soil_Dirt_Dry"
    },
    {
      "x": -34,
      "y": 1,
      "z": -13,
      "name": "Soil_Dirt_Dry"
    },
    {
      "x": -34,
      "y": 0,
      "z": -12,
      "name": "Soil_Dirt_Dry"
    },
    {
      "x": -34,
      "y": 0,
      "z": -11,
      "name": "Soil_Dirt_Dry"
    },
    {
      "x": -34,
      "y": 0,
      "z": -10,
      "name": "Soil_Dirt_Dry"
    },
    {
      "x": -34,
      "y": 1,
      "z": -10,
      "name": "Soil_Dirt_Dry"
    },
    {
      "x": -34,
      "y": 0,
      "z": -9,
      "name": "Soil_Dirt_Dry"
    },
    {
      "x": -34,
      "y": 1,
      "z": -9,
      "name": "Soil_Dirt_Dry"
    },
    {
      "x": -34,
      "y": 0,
      "z": -8,
      "name": "Soil_Dirt_Dry"
    },
    {
      "x": -34,
      "y": 1,
      "z": -8,
      "name": "Soil_Dirt_Dry"
    },
    {
      "x": -34,
      "y": 0,
      "z": -7,
      "name": "Soil_Dirt_Dry"
    },
    {
      "x": -34,
      "y": 1,
      "z": -7,
      "name": "Soil_Dirt_Dry"
    },
    {
      "x": -34,
      "y": 0,
      "z": -6,
      "name": "Soil_Dirt_Dry"
    },
    {
      "x": -34,
      "y": 1,
      "z": -6,
      "name": "Soil_Dirt_Dry"
    },
    {
      "x": -34,
      "y": 0,
      "z": -5,
      "name": "Soil_Dirt_Dry"
    },
    {
      "x": -34,
      "y": 1,
      "z": -5,
      "name": "Soil_Dirt_Dry"
    },
    {
      "x": -34,
      "y": 2,
      "z": -5,
      "name": "Soil_Dirt_Dry"
    },
    {
      "x": -34,
      "y": 11,
      "z": -5,
      "name": "Wood_Dry_Trunk",
      "support": 15,
      "rotation": 5
    },
    {
      "x": -34,
      "y": 12,
      "z": -5,
      "name": "Cloth_Roof_Leather",
      "rotation": 2
    },
    {
      "x": -34,
      "y": 0,
      "z": -4,
      "name": "Soil_Dirt_Dry"
    },
    {
      "x": -34,
      "y": 1,
      "z": -4,
      "name": "Soil_Dirt_Dry"
    },
    {
      "x": -34,
      "y": 2,
      "z": -4,
      "name": "Soil_Dirt_Dry"
    },
    {
      "x": -34,
      "y": 12,
      "z": -4,
      "name": "Cloth_Roof_Leather_Shallow",
      "filler": 1,
      "rotation": 3
    },
    {
      "x": -34,
      "y": 0,
      "z": -3,
      "name": "Soil_Dirt_Dry"
    },
    {
      "x": -34,
      "y": 1,
      "z": -3,
      "name": "Soil_Dirt_Dry"
    },
    {
      "x": -34,
      "y": 2,
      "z": -3,
      "name": "Soil_Gravel_Sand_Red"
    },
    {
      "x": -34,
      "y": 12,
      "z": -3,
      "name": "Cloth_Roof_Leather_Shallow",
      "filler": 1,
      "rotation": 3
    },
    {
      "x": -34,
      "y": 0,
      "z": -2,
      "name": "Soil_Dirt_Dry"
    },
    {
      "x": -34,
      "y": 1,
      "z": -2,
      "name": "Soil_Dirt_Dry"
    },
    {
      "x": -34,
      "y": 2,
      "z": -2,
      "name": "Soil_Gravel_Sand_Red"
    },
    {
      "x": -34,
      "y": 12,
      "z": -2,
      "name": "Cloth_Roof_Leather_Shallow",
      "filler": 1,
      "rotation": 3
    },
    {
      "x": -34,
      "y": 0,
      "z": -1,
      "name": "Soil_Dirt_Dry"
    },
    {
      "x": -34,
      "y": 1,
      "z": -1,
      "name": "Soil_Dirt_Dry"
    },
    {
      "x": -34,
      "y": 2,
      "z": -1,
      "name": "Soil_Gravel_Sand_Red"
    },
    {
      "x": -34,
      "y": 12,
      "z": -1,
      "name": "Cloth_Roof_Leather_Shallow",
      "filler": 1,
      "rotation": 3
    },
    {
      "x": -34,
      "y": 0,
      "z": 0,
      "name": "Soil_Dirt_Dry"
    },
    {
      "x": -34,
      "y": 1,
      "z": 0,
      "name": "Soil_Dirt_Dry"
    },
    {
      "x": -34,
      "y": 2,
      "z": 0,
      "name": "Soil_Gravel_Sand_Red"
    },
    {
      "x": -34,
      "y": 12,
      "z": 0,
      "name": "Cloth_Roof_Leather_Shallow",
      "filler": 1,
      "rotation": 3
    },
    {
      "x": -34,
      "y": 0,
      "z": 1,
      "name": "Soil_Dirt_Dry"
    },
    {
      "x": -34,
      "y": 1,
      "z": 1,
      "name": "Soil_Dirt_Dry"
    },
    {
      "x": -34,
      "y": 2,
      "z": 1,
      "name": "Soil_Gravel_Sand_Red"
    },
    {
      "x": -34,
      "y": 12,
      "z": 1,
      "name": "Cloth_Roof_Leather_Shallow",
      "filler": 1,
      "rotation": 3
    },
    {
      "x": -34,
      "y": 0,
      "z": 2,
      "name": "Soil_Dirt_Dry"
    },
    {
      "x": -34,
      "y": 1,
      "z": 2,
      "name": "Soil_Dirt_Dry"
    },
    {
      "x": -34,
      "y": 2,
      "z": 2,
      "name": "Soil_Gravel_Sand_Red"
    },
    {
      "x": -34,
      "y": 12,
      "z": 2,
      "name": "Cloth_Roof_Leather_Shallow",
      "filler": 1,
      "rotation": 3
    },
    {
      "x": -34,
      "y": 0,
      "z": 3,
      "name": "Soil_Dirt_Dry"
    },
    {
      "x": -34,
      "y": 1,
      "z": 3,
      "name": "Soil_Dirt_Dry"
    },
    {
      "x": -34,
      "y": 2,
      "z": 3,
      "name": "Soil_Gravel_Sand_Red"
    },
    {
      "x": -34,
      "y": 12,
      "z": 3,
      "name": "Cloth_Roof_Leather_Shallow",
      "filler": 1,
      "rotation": 3
    },
    {
      "x": -34,
      "y": 0,
      "z": 4,
      "name": "Soil_Dirt_Dry"
    },
    {
      "x": -34,
      "y": 1,
      "z": 4,
      "name": "Soil_Dirt_Dry"
    },
    {
      "x": -34,
      "y": 2,
      "z": 4,
      "name": "Soil_Dirt_Dry"
    },
    {
      "x": -34,
      "y": 12,
      "z": 4,
      "name": "Cloth_Roof_Leather_Shallow",
      "filler": 1,
      "rotation": 3
    },
    {
      "x": -34,
      "y": 0,
      "z": 5,
      "name": "Soil_Dirt_Dry"
    },
    {
      "x": -34,
      "y": 1,
      "z": 5,
      "name": "Soil_Dirt_Dry"
    },
    {
      "x": -34,
      "y": 2,
      "z": 5,
      "name": "Soil_Dirt_Dry"
    },
    {
      "x": -34,
      "y": 11,
      "z": 5,
      "name": "Wood_Dry_Trunk",
      "support": 15,
      "rotation": 5
    },
    {
      "x": -34,
      "y": 12,
      "z": 5,
      "name": "Cloth_Roof_Leather"
    },
    {
      "x": -34,
      "y": 0,
      "z": 6,
      "name": "Soil_Dirt_Dry"
    },
    {
      "x": -34,
      "y": 1,
      "z": 6,
      "name": "Soil_Dirt_Dry"
    },
    {
      "x": -34,
      "y": 0,
      "z": 7,
      "name": "Soil_Dirt_Dry"
    },
    {
      "x": -34,
      "y": 1,
      "z": 7,
      "name": "Soil_Dirt_Dry"
    },
    {
      "x": -34,
      "y": 0,
      "z": 8,
      "name": "Soil_Dirt_Dry"
    },
    {
      "x": -34,
      "y": 1,
      "z": 8,
      "name": "Soil_Dirt_Dry"
    },
    {
      "x": -34,
      "y": 0,
      "z": 9,
      "name": "Soil_Dirt_Dry"
    },
    {
      "x": -34,
      "y": 1,
      "z": 9,
      "name": "Soil_Dirt_Dry"
    },
    {
      "x": -34,
      "y": 0,
      "z": 10,
      "name": "Soil_Dirt_Dry"
    },
    {
      "x": -34,
      "y": 1,
      "z": 10,
      "name": "Soil_Dirt_Dry"
    },
    {
      "x": -34,
      "y": 0,
      "z": 11,
      "name": "Soil_Dirt_Dry"
    },
    {
      "x": -34,
      "y": 0,
      "z": 12,
      "name": "Soil_Dirt_Dry"
    },
    {
      "x": -34,
      "y": 0,
      "z": 13,
      "name": "Soil_Dirt_Dry"
    },
    {
      "x": -34,
      "y": 1,
      "z": 13,
      "name": "Soil_Dirt_Dry"
    },
    {
      "x": -34,
      "y": 0,
      "z": 14,
      "name": "Soil_Dirt_Dry"
    },
    {
      "x": -34,
      "y": 1,
      "z": 14,
      "name": "Soil_Dirt_Dry"
    },
    {
      "x": -34,
      "y": 0,
      "z": 15,
      "name": "Soil_Dirt_Dry"
    },
    {
      "x": -34,
      "y": 1,
      "z": 15,
      "name": "Soil_Dirt_Dry"
    },
    {
      "x": -34,
      "y": 0,
      "z": 16,
      "name": "Soil_Dirt_Dry"
    },
    {
      "x": -34,
      "y": 1,
      "z": 16,
      "name": "Soil_Dirt_Dry"
    },
    {
      "x": -34,
      "y": 0,
      "z": 17,
      "name": "Soil_Dirt_Dry"
    },
    {
      "x": -34,
      "y": 1,
      "z": 17,
      "name": "Soil_Dirt_Dry"
    },
    {
      "x": -34,
      "y": 0,
      "z": 18,
      "name": "Soil_Dirt_Dry"
    },
    {
      "x": -34,
      "y": 1,
      "z": 18,
      "name": "Soil_Dirt_Dry"
    },
    {
      "x": -34,
      "y": 0,
      "z": 19,
      "name": "Soil_Dirt_Dry"
    },
    {
      "x": -34,
      "y": 1,
      "z": 19,
      "name": "Soil_Dirt_Dry"
    },
    {
      "x": -34,
      "y": 0,
      "z": 20,
      "name": "Soil_Dirt_Dry"
    },
    {
      "x": -34,
      "y": 1,
      "z": 20,
      "name": "Soil_Dirt_Dry"
    },
    {
      "x": -34,
      "y": 0,
      "z": 21,
      "name": "Soil_Dirt_Dry"
    },
    {
      "x": -34,
      "y": 1,
      "z": 21,
      "name": "Soil_Dirt_Dry"
    },
    {
      "x": -34,
      "y": 0,
      "z": 22,
      "name": "Soil_Dirt_Dry"
    },
    {
      "x": -34,
      "y": 1,
      "z": 22,
      "name": "Soil_Dirt_Dry"
    },
    {
      "x": -34,
      "y": 0,
      "z": 23,
      "name": "Soil_Dirt_Dry"
    },
    {
      "x": -34,
      "y": 1,
      "z": 23,
      "name": "Soil_Dirt_Dry"
    },
    {
      "x": -34,
      "y": 0,
      "z": 24,
      "name": "Soil_Dirt_Dry"
    },
    {
      "x": -34,
      "y": 0,
      "z": 25,
      "name": "Soil_Dirt_Dry"
    },
    {
      "x": -34,
      "y": 0,
      "z": 26,
      "name": "Soil_Dirt_Dry"
    },
    {
      "x": -34,
      "y": 0,
      "z": 27,
      "name": "Soil_Dirt_Dry"
    },
    {
      "x": -33,
      "y": 0,
      "z": -28,
      "name": "Soil_Dirt_Dry"
    },
    {
      "x": -33,
      "y": 0,
      "z": -27,
      "name": "Soil_Dirt_Dry"
    },
    {
      "x": -33,
      "y": 0,
      "z": -26,
      "name": "Soil_Dirt_Dry"
    },
    {
      "x": -33,
      "y": 0,
      "z": -25,
      "name": "Soil_Dirt_Dry"
    },
    {
      "x": -33,
      "y": 0,
      "z": -24,
      "name": "Soil_Dirt_Dry"
    },
    {
      "x": -33,
      "y": 1,
      "z": -24,
      "name": "Soil_Dirt_Dry"
    },
    {
      "x": -33,
      "y": 0,
      "z": -23,
      "name": "Soil_Dirt_Dry"
    },
    {
      "x": -33,
      "y": 1,
      "z": -23,
      "name": "Soil_Dirt_Dry"
    },
    {
      "x": -33,
      "y": 0,
      "z": -22,
      "name": "Soil_Dirt_Dry"
    },
    {
      "x": -33,
      "y": 1,
      "z": -22,
      "name": "Soil_Dirt_Dry"
    },
    {
      "x": -33,
      "y": 0,
      "z": -21,
      "name": "Soil_Dirt_Dry"
    },
    {
      "x": -33,
      "y": 1,
      "z": -21,
      "name": "Soil_Dirt_Dry"
    },
    {
      "x": -33,
      "y": 0,
      "z": -20,
      "name": "Soil_Dirt_Dry"
    },
    {
      "x": -33,
      "y": 1,
      "z": -20,
      "name": "Soil_Dirt_Dry"
    },
    {
      "x": -33,
      "y": 0,
      "z": -19,
      "name": "Soil_Dirt_Dry"
    },
    {
      "x": -33,
      "y": 1,
      "z": -19,
      "name": "Soil_Dirt_Dry"
    },
    {
      "x": -33,
      "y": 0,
      "z": -18,
      "name": "Soil_Dirt_Dry"
    },
    {
      "x": -33,
      "y": 1,
      "z": -18,
      "name": "Soil_Dirt_Dry"
    },
    {
      "x": -33,
      "y": 0,
      "z": -17,
      "name": "Soil_Dirt_Dry"
    },
    {
      "x": -33,
      "y": 1,
      "z": -17,
      "name": "Soil_Dirt_Dry"
    },
    {
      "x": -33,
      "y": 0,
      "z": -16,
      "name": "Soil_Dirt_Dry"
    },
    {
      "x": -33,
      "y": 1,
      "z": -16,
      "name": "Soil_Dirt_Dry"
    },
    {
      "x": -33,
      "y": 0,
      "z": -15,
      "name": "Soil_Dirt_Dry"
    },
    {
      "x": -33,
      "y": 1,
      "z": -15,
      "name": "Soil_Dirt_Dry"
    },
    {
      "x": -33,
      "y": 0,
      "z": -14,
      "name": "Soil_Dirt_Dry"
    },
    {
      "x": -33,
      "y": 1,
      "z": -14,
      "name": "Soil_Dirt_Dry"
    },
    {
      "x": -33,
      "y": 0,
      "z": -13,
      "name": "Soil_Dirt_Dry"
    },
    {
      "x": -33,
      "y": 1,
      "z": -13,
      "name": "Soil_Dirt_Dry"
    },
    {
      "x": -33,
      "y": 0,
      "z": -12,
      "name": "Soil_Dirt_Dry"
    },
    {
      "x": -33,
      "y": 1,
      "z": -12,
      "name": "Soil_Dirt_Dry"
    },
    {
      "x": -33,
      "y": 0,
      "z": -11,
      "name": "Soil_Dirt_Dry"
    },
    {
      "x": -33,
      "y": 0,
      "z": -10,
      "name": "Soil_Dirt_Dry"
    },
    {
      "x": -33,
      "y": 1,
      "z": -10,
      "name": "Soil_Dirt_Dry"
    },
    {
      "x": -33,
      "y": 0,
      "z": -9,
      "name": "Soil_Dirt_Dry"
    },
    {
      "x": -33,
      "y": 1,
      "z": -9,
      "name": "Soil_Dirt_Dry"
    },
    {
      "x": -33,
      "y": 2,
      "z": -9,
      "name": "Soil_Dirt_Dry"
    },
    {
      "x": -33,
      "y": 0,
      "z": -8,
      "name": "Soil_Dirt_Dry"
    },
    {
      "x": -33,
      "y": 1,
      "z": -8,
      "name": "Soil_Dirt_Dry"
    },
    {
      "x": -33,
      "y": 2,
      "z": -8,
      "name": "Soil_Dirt_Dry"
    },
    {
      "x": -33,
      "y": 0,
      "z": -7,
      "name": "Soil_Dirt_Dry"
    },
    {
      "x": -33,
      "y": 1,
      "z": -7,
      "name": "Soil_Dirt_Dry"
    },
    {
      "x": -33,
      "y": 2,
      "z": -7,
      "name": "Soil_Dirt_Dry"
    },
    {
      "x": -33,
      "y": 0,
      "z": -6,
      "name": "Soil_Dirt_Dry"
    },
    {
      "x": -33,
      "y": 1,
      "z": -6,
      "name": "Soil_Dirt_Dry"
    },
    {
      "x": -33,
      "y": 2,
      "z": -6,
      "name": "Soil_Dirt_Dry"
    },
    {
      "x": -33,
      "y": 12,
      "z": -6,
      "name": "Wood_Dry_Trunk",
      "support": 15,
      "rotation": 4
    },
    {
      "x": -33,
      "y": 0,
      "z": -5,
      "name": "Soil_Dirt_Dry"
    },
    {
      "x": -33,
      "y": 1,
      "z": -5,
      "name": "Soil_Dirt_Dry"
    },
    {
      "x": -33,
      "y": 2,
      "z": -5,
      "name": "Soil_Dirt_Dry"
    },
    {
      "x": -33,
      "y": 11,
      "z": -5,
      "name": "Wood_Dry_Trunk",
      "support": 15,
      "rotation": 5
    },
    {
      "x": -33,
      "y": 12,
      "z": -5,
      "name": "Wood_Dry_Trunk",
      "support": 15,
      "rotation": 4
    },
    {
      "x": -33,
      "y": 0,
      "z": -4,
      "name": "Soil_Dirt_Dry"
    },
    {
      "x": -33,
      "y": 1,
      "z": -4,
      "name": "Soil_Dirt_Dry"
    },
    {
      "x": -33,
      "y": 2,
      "z": -4,
      "name": "Soil_Dirt_Dry"
    },
    {
      "x": -33,
      "y": 12,
      "z": -4,
      "name": "Wood_Dry_Trunk",
      "support": 15,
      "rotation": 4
    },
    {
      "x": -33,
      "y": 13,
      "z": -4,
      "name": "Cloth_Roof_Leather_Flat"
    },
    {
      "x": -33,
      "y": 0,
      "z": -3,
      "name": "Soil_Dirt_Dry"
    },
    {
      "x": -33,
      "y": 1,
      "z": -3,
      "name": "Soil_Dirt_Dry"
    },
    {
      "x": -33,
      "y": 2,
      "z": -3,
      "name": "Soil_Gravel_Sand_Red"
    },
    {
      "x": -33,
      "y": 12,
      "z": -3,
      "name": "Wood_Dry_Trunk",
      "support": 15,
      "rotation": 4
    },
    {
      "x": -33,
      "y": 13,
      "z": -3,
      "name": "Cloth_Roof_Leather_Flat"
    },
    {
      "x": -33,
      "y": 0,
      "z": -2,
      "name": "Soil_Dirt_Dry"
    },
    {
      "x": -33,
      "y": 1,
      "z": -2,
      "name": "Soil_Dirt_Dry"
    },
    {
      "x": -33,
      "y": 2,
      "z": -2,
      "name": "Soil_Gravel_Sand_Red"
    },
    {
      "x": -33,
      "y": 12,
      "z": -2,
      "name": "Wood_Dry_Trunk",
      "support": 15,
      "rotation": 4
    },
    {
      "x": -33,
      "y": 13,
      "z": -2,
      "name": "Cloth_Roof_Leather_Flat"
    },
    {
      "x": -33,
      "y": 0,
      "z": -1,
      "name": "Soil_Dirt_Dry"
    },
    {
      "x": -33,
      "y": 1,
      "z": -1,
      "name": "Soil_Dirt_Dry"
    },
    {
      "x": -33,
      "y": 2,
      "z": -1,
      "name": "Soil_Gravel_Sand_Red"
    },
    {
      "x": -33,
      "y": 12,
      "z": -1,
      "name": "Wood_Dry_Trunk",
      "support": 15,
      "rotation": 4
    },
    {
      "x": -33,
      "y": 13,
      "z": -1,
      "name": "Cloth_Roof_Leather_Flat"
    },
    {
      "x": -33,
      "y": 0,
      "z": 0,
      "name": "Soil_Dirt_Dry"
    },
    {
      "x": -33,
      "y": 1,
      "z": 0,
      "name": "Soil_Dirt_Dry"
    },
    {
      "x": -33,
      "y": 2,
      "z": 0,
      "name": "Soil_Gravel_Sand_Red"
    },
    {
      "x": -33,
      "y": 12,
      "z": 0,
      "name": "Wood_Dry_Trunk",
      "support": 15,
      "rotation": 4
    },
    {
      "x": -33,
      "y": 13,
      "z": 0,
      "name": "Cloth_Roof_Leather_Flat"
    },
    {
      "x": -33,
      "y": 0,
      "z": 1,
      "name": "Soil_Dirt_Dry"
    },
    {
      "x": -33,
      "y": 1,
      "z": 1,
      "name": "Soil_Dirt_Dry"
    },
    {
      "x": -33,
      "y": 2,
      "z": 1,
      "name": "Soil_Gravel_Sand_Red"
    },
    {
      "x": -33,
      "y": 12,
      "z": 1,
      "name": "Wood_Dry_Trunk",
      "support": 15,
      "rotation": 4
    },
    {
      "x": -33,
      "y": 13,
      "z": 1,
      "name": "Cloth_Roof_Leather_Flat"
    },
    {
      "x": -33,
      "y": 0,
      "z": 2,
      "name": "Soil_Dirt_Dry"
    },
    {
      "x": -33,
      "y": 1,
      "z": 2,
      "name": "Soil_Dirt_Dry"
    },
    {
      "x": -33,
      "y": 2,
      "z": 2,
      "name": "Soil_Gravel_Sand_Red"
    },
    {
      "x": -33,
      "y": 12,
      "z": 2,
      "name": "Wood_Dry_Trunk",
      "support": 15,
      "rotation": 4
    },
    {
      "x": -33,
      "y": 13,
      "z": 2,
      "name": "Cloth_Roof_Leather_Flat"
    },
    {
      "x": -33,
      "y": 0,
      "z": 3,
      "name": "Soil_Dirt_Dry"
    },
    {
      "x": -33,
      "y": 1,
      "z": 3,
      "name": "Soil_Dirt_Dry"
    },
    {
      "x": -33,
      "y": 2,
      "z": 3,
      "name": "Soil_Gravel_Sand_Red"
    },
    {
      "x": -33,
      "y": 12,
      "z": 3,
      "name": "Wood_Dry_Trunk",
      "support": 15,
      "rotation": 4
    },
    {
      "x": -33,
      "y": 13,
      "z": 3,
      "name": "Cloth_Roof_Leather_Flat"
    },
    {
      "x": -33,
      "y": 0,
      "z": 4,
      "name": "Soil_Dirt_Dry"
    },
    {
      "x": -33,
      "y": 1,
      "z": 4,
      "name": "Soil_Dirt_Dry"
    },
    {
      "x": -33,
      "y": 2,
      "z": 4,
      "name": "Soil_Dirt_Dry"
    },
    {
      "x": -33,
      "y": 12,
      "z": 4,
      "name": "Wood_Dry_Trunk",
      "support": 15,
      "rotation": 4
    },
    {
      "x": -33,
      "y": 13,
      "z": 4,
      "name": "Cloth_Roof_Leather_Flat"
    },
    {
      "x": -33,
      "y": 0,
      "z": 5,
      "name": "Soil_Dirt_Dry"
    },
    {
      "x": -33,
      "y": 1,
      "z": 5,
      "name": "Soil_Dirt_Dry"
    },
    {
      "x": -33,
      "y": 2,
      "z": 5,
      "name": "Soil_Dirt_Dry"
    },
    {
      "x": -33,
      "y": 11,
      "z": 5,
      "name": "Wood_Dry_Trunk",
      "support": 15,
      "rotation": 5
    },
    {
      "x": -33,
      "y": 12,
      "z": 5,
      "name": "Wood_Dry_Trunk",
      "support": 15,
      "rotation": 4
    },
    {
      "x": -33,
      "y": 0,
      "z": 6,
      "name": "Soil_Dirt_Dry"
    },
    {
      "x": -33,
      "y": 1,
      "z": 6,
      "name": "Soil_Dirt_Dry"
    },
    {
      "x": -33,
      "y": 12,
      "z": 6,
      "name": "Wood_Dry_Trunk",
      "support": 15,
      "rotation": 4
    },
    {
      "x": -33,
      "y": 0,
      "z": 7,
      "name": "Soil_Dirt_Dry"
    },
    {
      "x": -33,
      "y": 1,
      "z": 7,
      "name": "Soil_Dirt_Dry"
    },
    {
      "x": -33,
      "y": 0,
      "z": 8,
      "name": "Soil_Dirt_Dry"
    },
    {
      "x": -33,
      "y": 1,
      "z": 8,
      "name": "Soil_Dirt_Dry"
    },
    {
      "x": -33,
      "y": 0,
      "z": 9,
      "name": "Soil_Dirt_Dry"
    },
    {
      "x": -33,
      "y": 1,
      "z": 9,
      "name": "Soil_Dirt_Dry"
    },
    {
      "x": -33,
      "y": 0,
      "z": 10,
      "name": "Soil_Dirt_Dry"
    },
    {
      "x": -33,
      "y": 1,
      "z": 10,
      "name": "Soil_Dirt_Dry"
    },
    {
      "x": -33,
      "y": 0,
      "z": 11,
      "name": "Soil_Dirt_Dry"
    },
    {
      "x": -33,
      "y": 0,
      "z": 12,
      "name": "Soil_Dirt_Dry"
    },
    {
      "x": -33,
      "y": 1,
      "z": 12,
      "name": "Soil_Dirt_Dry"
    },
    {
      "x": -33,
      "y": 0,
      "z": 13,
      "name": "Soil_Dirt_Dry"
    },
    {
      "x": -33,
      "y": 1,
      "z": 13,
      "name": "Soil_Dirt_Dry"
    },
    {
      "x": -33,
      "y": 0,
      "z": 14,
      "name": "Soil_Dirt_Dry"
    },
    {
      "x": -33,
      "y": 1,
      "z": 14,
      "name": "Soil_Dirt_Dry"
    },
    {
      "x": -33,
      "y": 0,
      "z": 15,
      "name": "Soil_Dirt_Dry"
    },
    {
      "x": -33,
      "y": 1,
      "z": 15,
      "name": "Soil_Dirt_Dry"
    },
    {
      "x": -33,
      "y": 0,
      "z": 16,
      "name": "Soil_Dirt_Dry"
    },
    {
      "x": -33,
      "y": 1,
      "z": 16,
      "name": "Soil_Dirt_Dry"
    },
    {
      "x": -33,
      "y": 0,
      "z": 17,
      "name": "Soil_Dirt_Dry"
    },
    {
      "x": -33,
      "y": 1,
      "z": 17,
      "name": "Soil_Dirt_Dry"
    },
    {
      "x": -33,
      "y": 0,
      "z": 18,
      "name": "Soil_Dirt_Dry"
    },
    {
      "x": -33,
      "y": 1,
      "z": 18,
      "name": "Soil_Dirt_Dry"
    },
    {
      "x": -33,
      "y": 0,
      "z": 19,
      "name": "Soil_Dirt_Dry"
    },
    {
      "x": -33,
      "y": 1,
      "z": 19,
      "name": "Soil_Dirt_Dry"
    },
    {
      "x": -33,
      "y": 0,
      "z": 20,
      "name": "Soil_Dirt_Dry"
    },
    {
      "x": -33,
      "y": 1,
      "z": 20,
      "name": "Soil_Dirt_Dry"
    },
    {
      "x": -33,
      "y": 0,
      "z": 21,
      "name": "Soil_Dirt_Dry"
    },
    {
      "x": -33,
      "y": 1,
      "z": 21,
      "name": "Soil_Dirt_Dry"
    },
    {
      "x": -33,
      "y": 0,
      "z": 22,
      "name": "Soil_Dirt_Dry"
    },
    {
      "x": -33,
      "y": 1,
      "z": 22,
      "name": "Soil_Dirt_Dry"
    },
    {
      "x": -33,
      "y": 0,
      "z": 23,
      "name": "Soil_Dirt_Dry"
    },
    {
      "x": -33,
      "y": 1,
      "z": 23,
      "name": "Soil_Dirt_Dry"
    },
    {
      "x": -33,
      "y": 0,
      "z": 24,
      "name": "Soil_Dirt_Dry"
    },
    {
      "x": -33,
      "y": 1,
      "z": 24,
      "name": "Soil_Dirt_Dry"
    },
    {
      "x": -33,
      "y": 0,
      "z": 25,
      "name": "Soil_Dirt_Dry"
    },
    {
      "x": -33,
      "y": 0,
      "z": 26,
      "name": "Soil_Dirt_Dry"
    },
    {
      "x": -33,
      "y": 0,
      "z": 27,
      "name": "Soil_Dirt_Dry"
    },
    {
      "x": -33,
      "y": 0,
      "z": 28,
      "name": "Soil_Dirt_Dry"
    },
    {
      "x": -32,
      "y": 0,
      "z": -29,
      "name": "Soil_Dirt_Dry"
    },
    {
      "x": -32,
      "y": 0,
      "z": -28,
      "name": "Soil_Dirt_Dry"
    },
    {
      "x": -32,
      "y": 0,
      "z": -27,
      "name": "Soil_Dirt_Dry"
    },
    {
      "x": -32,
      "y": 0,
      "z": -26,
      "name": "Soil_Dirt_Dry"
    },
    {
      "x": -32,
      "y": 0,
      "z": -25,
      "name": "Soil_Dirt_Dry"
    },
    {
      "x": -32,
      "y": 1,
      "z": -25,
      "name": "Soil_Dirt_Dry"
    },
    {
      "x": -32,
      "y": 0,
      "z": -24,
      "name": "Soil_Dirt_Dry"
    },
    {
      "x": -32,
      "y": 1,
      "z": -24,
      "name": "Soil_Dirt_Dry"
    },
    {
      "x": -32,
      "y": 0,
      "z": -23,
      "name": "Soil_Dirt_Dry"
    },
    {
      "x": -32,
      "y": 1,
      "z": -23,
      "name": "Soil_Dirt_Dry"
    },
    {
      "x": -32,
      "y": 0,
      "z": -22,
      "name": "Soil_Dirt_Dry"
    },
    {
      "x": -32,
      "y": 1,
      "z": -22,
      "name": "Soil_Dirt_Dry"
    },
    {
      "x": -32,
      "y": 0,
      "z": -21,
      "name": "Soil_Dirt_Dry"
    },
    {
      "x": -32,
      "y": 1,
      "z": -21,
      "name": "Soil_Dirt_Dry"
    },
    {
      "x": -32,
      "y": 0,
      "z": -20,
      "name": "Soil_Dirt_Dry"
    },
    {
      "x": -32,
      "y": 1,
      "z": -20,
      "name": "Soil_Dirt_Dry"
    },
    {
      "x": -32,
      "y": 0,
      "z": -19,
      "name": "Soil_Dirt_Dry"
    },
    {
      "x": -32,
      "y": 1,
      "z": -19,
      "name": "Soil_Dirt_Dry"
    },
    {
      "x": -32,
      "y": 0,
      "z": -18,
      "name": "Soil_Dirt_Dry"
    },
    {
      "x": -32,
      "y": 1,
      "z": -18,
      "name": "Soil_Dirt_Dry"
    },
    {
      "x": -32,
      "y": 0,
      "z": -17,
      "name": "Soil_Dirt_Dry"
    },
    {
      "x": -32,
      "y": 1,
      "z": -17,
      "name": "Soil_Dirt_Dry"
    },
    {
      "x": -32,
      "y": 0,
      "z": -16,
      "name": "Soil_Dirt_Dry"
    },
    {
      "x": -32,
      "y": 1,
      "z": -16,
      "name": "Soil_Dirt_Dry"
    },
    {
      "x": -32,
      "y": 0,
      "z": -15,
      "name": "Soil_Dirt_Dry"
    },
    {
      "x": -32,
      "y": 1,
      "z": -15,
      "name": "Soil_Dirt_Dry"
    },
    {
      "x": -32,
      "y": 0,
      "z": -14,
      "name": "Soil_Dirt_Dry"
    },
    {
      "x": -32,
      "y": 1,
      "z": -14,
      "name": "Soil_Dirt_Dry"
    },
    {
      "x": -32,
      "y": 0,
      "z": -13,
      "name": "Soil_Dirt_Dry"
    },
    {
      "x": -32,
      "y": 1,
      "z": -13,
      "name": "Soil_Dirt_Dry"
    },
    {
      "x": -32,
      "y": 0,
      "z": -12,
      "name": "Soil_Dirt_Dry"
    },
    {
      "x": -32,
      "y": 1,
      "z": -12,
      "name": "Soil_Dirt_Dry"
    },
    {
      "x": -32,
      "y": 2,
      "z": -12,
      "name": "Soil_Dirt_Dry"
    },
    {
      "x": -32,
      "y": 0,
      "z": -11,
      "name": "Soil_Dirt_Dry"
    },
    {
      "x": -32,
      "y": 1,
      "z": -11,
      "name": "Soil_Dirt_Dry"
    },
    {
      "x": -32,
      "y": 2,
      "z": -11,
      "name": "Soil_Dirt_Dry"
    },
    {
      "x": -32,
      "y": 0,
      "z": -10,
      "name": "Soil_Dirt_Dry"
    },
    {
      "x": -32,
      "y": 1,
      "z": -10,
      "name": "Soil_Dirt_Dry"
    },
    {
      "x": -32,
      "y": 2,
      "z": -10,
      "name": "Soil_Dirt_Dry"
    },
    {
      "x": -32,
      "y": 0,
      "z": -9,
      "name": "Soil_Dirt_Dry"
    },
    {
      "x": -32,
      "y": 1,
      "z": -9,
      "name": "Soil_Dirt_Dry"
    },
    {
      "x": -32,
      "y": 2,
      "z": -9,
      "name": "Soil_Dirt_Dry"
    },
    {
      "x": -32,
      "y": 0,
      "z": -8,
      "name": "Soil_Dirt_Dry"
    },
    {
      "x": -32,
      "y": 1,
      "z": -8,
      "name": "Soil_Dirt_Dry"
    },
    {
      "x": -32,
      "y": 2,
      "z": -8,
      "name": "Soil_Dirt_Dry"
    },
    {
      "x": -32,
      "y": 0,
      "z": -7,
      "name": "Soil_Dirt_Dry"
    },
    {
      "x": -32,
      "y": 1,
      "z": -7,
      "name": "Soil_Dirt_Dry"
    },
    {
      "x": -32,
      "y": 2,
      "z": -7,
      "name": "Soil_Dirt_Dry"
    },
    {
      "x": -32,
      "y": 0,
      "z": -6,
      "name": "Soil_Dirt_Dry"
    },
    {
      "x": -32,
      "y": 1,
      "z": -6,
      "name": "Soil_Dirt_Dry"
    },
    {
      "x": -32,
      "y": 2,
      "z": -6,
      "name": "Soil_Dirt_Dry"
    },
    {
      "x": -32,
      "y": 0,
      "z": -5,
      "name": "Soil_Dirt_Dry"
    },
    {
      "x": -32,
      "y": 1,
      "z": -5,
      "name": "Soil_Dirt_Dry"
    },
    {
      "x": -32,
      "y": 2,
      "z": -5,
      "name": "Soil_Dirt_Dry"
    },
    {
      "x": -32,
      "y": 11,
      "z": -5,
      "name": "Wood_Dry_Trunk",
      "support": 15,
      "rotation": 5
    },
    {
      "x": -32,
      "y": 12,
      "z": -5,
      "name": "Cloth_Roof_Leather",
      "rotation": 2
    },
    {
      "x": -32,
      "y": 0,
      "z": -4,
      "name": "Soil_Dirt_Dry"
    },
    {
      "x": -32,
      "y": 1,
      "z": -4,
      "name": "Soil_Dirt_Dry"
    },
    {
      "x": -32,
      "y": 2,
      "z": -4,
      "name": "Soil_Dirt_Dry"
    },
    {
      "x": -32,
      "y": 12,
      "z": -4,
      "name": "Cloth_Roof_Leather_Shallow",
      "filler": 31,
      "rotation": 1
    },
    {
      "x": -32,
      "y": 0,
      "z": -3,
      "name": "Soil_Dirt_Dry"
    },
    {
      "x": -32,
      "y": 1,
      "z": -3,
      "name": "Soil_Dirt_Dry"
    },
    {
      "x": -32,
      "y": 2,
      "z": -3,
      "name": "Soil_Gravel_Sand_Red"
    },
    {
      "x": -32,
      "y": 12,
      "z": -3,
      "name": "Cloth_Roof_Leather_Shallow",
      "filler": 31,
      "rotation": 1
    },
    {
      "x": -32,
      "y": 0,
      "z": -2,
      "name": "Soil_Dirt_Dry"
    },
    {
      "x": -32,
      "y": 1,
      "z": -2,
      "name": "Soil_Dirt_Dry"
    },
    {
      "x": -32,
      "y": 2,
      "z": -2,
      "name": "Soil_Gravel_Sand_Red"
    },
    {
      "x": -32,
      "y": 12,
      "z": -2,
      "name": "Cloth_Roof_Leather_Shallow",
      "filler": 31,
      "rotation": 1
    },
    {
      "x": -32,
      "y": 0,
      "z": -1,
      "name": "Soil_Dirt_Dry"
    },
    {
      "x": -32,
      "y": 1,
      "z": -1,
      "name": "Soil_Dirt_Dry"
    },
    {
      "x": -32,
      "y": 2,
      "z": -1,
      "name": "Soil_Gravel_Sand_Red"
    },
    {
      "x": -32,
      "y": 12,
      "z": -1,
      "name": "Cloth_Roof_Leather_Shallow",
      "filler": 31,
      "rotation": 1
    },
    {
      "x": -32,
      "y": 0,
      "z": 0,
      "name": "Soil_Dirt_Dry"
    },
    {
      "x": -32,
      "y": 1,
      "z": 0,
      "name": "Soil_Dirt_Dry"
    },
    {
      "x": -32,
      "y": 2,
      "z": 0,
      "name": "Soil_Gravel_Sand_Red"
    },
    {
      "x": -32,
      "y": 12,
      "z": 0,
      "name": "Cloth_Roof_Leather_Shallow",
      "filler": 31,
      "rotation": 1
    },
    {
      "x": -32,
      "y": 0,
      "z": 1,
      "name": "Soil_Dirt_Dry"
    },
    {
      "x": -32,
      "y": 1,
      "z": 1,
      "name": "Soil_Dirt_Dry"
    },
    {
      "x": -32,
      "y": 2,
      "z": 1,
      "name": "Soil_Gravel_Sand_Red"
    },
    {
      "x": -32,
      "y": 12,
      "z": 1,
      "name": "Cloth_Roof_Leather_Shallow",
      "filler": 31,
      "rotation": 1
    },
    {
      "x": -32,
      "y": 0,
      "z": 2,
      "name": "Soil_Dirt_Dry"
    },
    {
      "x": -32,
      "y": 1,
      "z": 2,
      "name": "Soil_Dirt_Dry"
    },
    {
      "x": -32,
      "y": 2,
      "z": 2,
      "name": "Soil_Gravel_Sand_Red"
    },
    {
      "x": -32,
      "y": 12,
      "z": 2,
      "name": "Cloth_Roof_Leather_Shallow",
      "filler": 31,
      "rotation": 1
    },
    {
      "x": -32,
      "y": 0,
      "z": 3,
      "name": "Soil_Dirt_Dry"
    },
    {
      "x": -32,
      "y": 1,
      "z": 3,
      "name": "Soil_Dirt_Dry"
    },
    {
      "x": -32,
      "y": 2,
      "z": 3,
      "name": "Soil_Gravel_Sand_Red"
    },
    {
      "x": -32,
      "y": 12,
      "z": 3,
      "name": "Cloth_Roof_Leather_Shallow",
      "filler": 31,
      "rotation": 1
    },
    {
      "x": -32,
      "y": 0,
      "z": 4,
      "name": "Soil_Dirt_Dry"
    },
    {
      "x": -32,
      "y": 1,
      "z": 4,
      "name": "Soil_Dirt_Dry"
    },
    {
      "x": -32,
      "y": 2,
      "z": 4,
      "name": "Soil_Dirt_Dry"
    },
    {
      "x": -32,
      "y": 12,
      "z": 4,
      "name": "Cloth_Roof_Leather_Shallow",
      "filler": 31,
      "rotation": 1
    },
    {
      "x": -32,
      "y": 0,
      "z": 5,
      "name": "Soil_Dirt_Dry"
    },
    {
      "x": -32,
      "y": 1,
      "z": 5,
      "name": "Soil_Dirt_Dry"
    },
    {
      "x": -32,
      "y": 2,
      "z": 5,
      "name": "Soil_Dirt_Dry"
    },
    {
      "x": -32,
      "y": 11,
      "z": 5,
      "name": "Wood_Dry_Trunk",
      "support": 15,
      "rotation": 5
    },
    {
      "x": -32,
      "y": 12,
      "z": 5,
      "name": "Cloth_Roof_Leather"
    },
    {
      "x": -32,
      "y": 0,
      "z": 6,
      "name": "Soil_Dirt_Dry"
    },
    {
      "x": -32,
      "y": 1,
      "z": 6,
      "name": "Soil_Dirt_Dry"
    },
    {
      "x": -32,
      "y": 2,
      "z": 6,
      "name": "Soil_Dirt_Dry"
    },
    {
      "x": -32,
      "y": 0,
      "z": 7,
      "name": "Soil_Dirt_Dry"
    },
    {
      "x": -32,
      "y": 1,
      "z": 7,
      "name": "Soil_Dirt_Dry"
    },
    {
      "x": -32,
      "y": 2,
      "z": 7,
      "name": "Soil_Dirt_Dry"
    },
    {
      "x": -32,
      "y": 0,
      "z": 8,
      "name": "Soil_Dirt_Dry"
    },
    {
      "x": -32,
      "y": 1,
      "z": 8,
      "name": "Soil_Dirt_Dry"
    },
    {
      "x": -32,
      "y": 2,
      "z": 8,
      "name": "Soil_Dirt_Dry"
    },
    {
      "x": -32,
      "y": 0,
      "z": 9,
      "name": "Soil_Dirt_Dry"
    },
    {
      "x": -32,
      "y": 1,
      "z": 9,
      "name": "Soil_Dirt_Dry"
    },
    {
      "x": -32,
      "y": 2,
      "z": 9,
      "name": "Soil_Dirt_Dry"
    },
    {
      "x": -32,
      "y": 3,
      "z": 9,
      "name": "Wood_Dry_Trunk",
      "support": 15
    },
    {
      "x": -32,
      "y": 4,
      "z": 9,
      "name": "Wood_Dry_Trunk",
      "support": 15
    },
    {
      "x": -32,
      "y": 5,
      "z": 9,
      "name": "Wood_Dry_Trunk",
      "support": 15
    },
    {
      "x": -32,
      "y": 6,
      "z": 9,
      "name": "Wood_Dry_Trunk",
      "support": 15
    },
    {
      "x": -32,
      "y": 7,
      "z": 9,
      "name": "Wood_Dry_Trunk",
      "support": 15
    },
    {
      "x": -32,
      "y": 8,
      "z": 9,
      "name": "Wood_Dry_Trunk",
      "support": 15
    },
    {
      "x": -32,
      "y": 9,
      "z": 9,
      "name": "Wood_Dry_Branch_Long",
      "support": 15
    },
    {
      "x": -32,
      "y": 10,
      "z": 9,
      "name": "Survival_Trap_Spike_Wood_Large"
    },
    {
      "x": -32,
      "y": 0,
      "z": 10,
      "name": "Soil_Dirt_Dry"
    },
    {
      "x": -32,
      "y": 1,
      "z": 10,
      "name": "Soil_Dirt_Dry"
    },
    {
      "x": -32,
      "y": 2,
      "z": 10,
      "name": "Soil_Dirt_Dry"
    },
    {
      "x": -32,
      "y": 0,
      "z": 11,
      "name": "Soil_Dirt_Dry"
    },
    {
      "x": -32,
      "y": 1,
      "z": 11,
      "name": "Soil_Dirt_Dry"
    },
    {
      "x": -32,
      "y": 2,
      "z": 11,
      "name": "Soil_Dirt_Dry"
    },
    {
      "x": -32,
      "y": 0,
      "z": 12,
      "name": "Soil_Dirt_Dry"
    },
    {
      "x": -32,
      "y": 1,
      "z": 12,
      "name": "Soil_Dirt_Dry"
    },
    {
      "x": -32,
      "y": 2,
      "z": 12,
      "name": "Soil_Dirt_Dry"
    },
    {
      "x": -32,
      "y": 0,
      "z": 13,
      "name": "Soil_Dirt_Dry"
    },
    {
      "x": -32,
      "y": 1,
      "z": 13,
      "name": "Soil_Dirt_Dry"
    },
    {
      "x": -32,
      "y": 0,
      "z": 14,
      "name": "Soil_Dirt_Dry"
    },
    {
      "x": -32,
      "y": 1,
      "z": 14,
      "name": "Soil_Dirt_Dry"
    },
    {
      "x": -32,
      "y": 0,
      "z": 15,
      "name": "Soil_Dirt_Dry"
    },
    {
      "x": -32,
      "y": 1,
      "z": 15,
      "name": "Soil_Dirt_Dry"
    },
    {
      "x": -32,
      "y": 0,
      "z": 16,
      "name": "Soil_Dirt_Dry"
    },
    {
      "x": -32,
      "y": 1,
      "z": 16,
      "name": "Soil_Dirt_Dry"
    },
    {
      "x": -32,
      "y": 0,
      "z": 17,
      "name": "Soil_Dirt_Dry"
    },
    {
      "x": -32,
      "y": 1,
      "z": 17,
      "name": "Soil_Dirt_Dry"
    },
    {
      "x": -32,
      "y": 0,
      "z": 18,
      "name": "Soil_Dirt_Dry"
    },
    {
      "x": -32,
      "y": 1,
      "z": 18,
      "name": "Soil_Dirt_Dry"
    },
    {
      "x": -32,
      "y": 0,
      "z": 19,
      "name": "Soil_Dirt_Dry"
    },
    {
      "x": -32,
      "y": 1,
      "z": 19,
      "name": "Soil_Dirt_Dry"
    },
    {
      "x": -32,
      "y": 0,
      "z": 20,
      "name": "Soil_Dirt_Dry"
    },
    {
      "x": -32,
      "y": 1,
      "z": 20,
      "name": "Soil_Dirt_Dry"
    },
    {
      "x": -32,
      "y": 0,
      "z": 21,
      "name": "Soil_Dirt_Dry"
    },
    {
      "x": -32,
      "y": 1,
      "z": 21,
      "name": "Soil_Dirt_Dry"
    },
    {
      "x": -32,
      "y": 0,
      "z": 22,
      "name": "Soil_Dirt_Dry"
    },
    {
      "x": -32,
      "y": 1,
      "z": 22,
      "name": "Soil_Dirt_Dry"
    },
    {
      "x": -32,
      "y": 0,
      "z": 23,
      "name": "Soil_Dirt_Dry"
    },
    {
      "x": -32,
      "y": 1,
      "z": 23,
      "name": "Soil_Dirt_Dry"
    },
    {
      "x": -32,
      "y": 0,
      "z": 24,
      "name": "Soil_Dirt_Dry"
    },
    {
      "x": -32,
      "y": 1,
      "z": 24,
      "name": "Soil_Dirt_Dry"
    },
    {
      "x": -32,
      "y": 0,
      "z": 25,
      "name": "Soil_Dirt_Dry"
    },
    {
      "x": -32,
      "y": 1,
      "z": 25,
      "name": "Soil_Dirt_Dry"
    },
    {
      "x": -32,
      "y": 0,
      "z": 26,
      "name": "Soil_Dirt_Dry"
    },
    {
      "x": -32,
      "y": 0,
      "z": 27,
      "name": "Soil_Dirt_Dry"
    },
    {
      "x": -32,
      "y": 0,
      "z": 28,
      "name": "Soil_Dirt_Dry"
    },
    {
      "x": -32,
      "y": 0,
      "z": 29,
      "name": "Soil_Dirt_Dry"
    },
    {
      "x": -31,
      "y": 0,
      "z": -29,
      "name": "Soil_Dirt_Dry"
    },
    {
      "x": -31,
      "y": 0,
      "z": -28,
      "name": "Soil_Dirt_Dry"
    },
    {
      "x": -31,
      "y": 0,
      "z": -27,
      "name": "Soil_Dirt_Dry"
    },
    {
      "x": -31,
      "y": 0,
      "z": -26,
      "name": "Soil_Dirt_Dry"
    },
    {
      "x": -31,
      "y": 1,
      "z": -26,
      "name": "Soil_Dirt_Dry"
    },
    {
      "x": -31,
      "y": 0,
      "z": -25,
      "name": "Soil_Dirt_Dry"
    },
    {
      "x": -31,
      "y": 1,
      "z": -25,
      "name": "Soil_Dirt_Dry"
    },
    {
      "x": -31,
      "y": 0,
      "z": -24,
      "name": "Soil_Dirt_Dry"
    },
    {
      "x": -31,
      "y": 1,
      "z": -24,
      "name": "Soil_Dirt_Dry"
    },
    {
      "x": -31,
      "y": 0,
      "z": -23,
      "name": "Soil_Dirt_Dry"
    },
    {
      "x": -31,
      "y": 1,
      "z": -23,
      "name": "Soil_Dirt_Dry"
    },
    {
      "x": -31,
      "y": 0,
      "z": -22,
      "name": "Soil_Dirt_Dry"
    },
    {
      "x": -31,
      "y": 1,
      "z": -22,
      "name": "Soil_Dirt_Dry"
    },
    {
      "x": -31,
      "y": 0,
      "z": -21,
      "name": "Soil_Dirt_Dry"
    },
    {
      "x": -31,
      "y": 1,
      "z": -21,
      "name": "Soil_Dirt_Dry"
    },
    {
      "x": -31,
      "y": 0,
      "z": -20,
      "name": "Soil_Dirt_Dry"
    },
    {
      "x": -31,
      "y": 1,
      "z": -20,
      "name": "Soil_Dirt_Dry"
    },
    {
      "x": -31,
      "y": 0,
      "z": -19,
      "name": "Soil_Dirt_Dry"
    },
    {
      "x": -31,
      "y": 1,
      "z": -19,
      "name": "Soil_Dirt_Dry"
    },
    {
      "x": -31,
      "y": 0,
      "z": -18,
      "name": "Soil_Dirt_Dry"
    },
    {
      "x": -31,
      "y": 1,
      "z": -18,
      "name": "Soil_Dirt_Dry"
    },
    {
      "x": -31,
      "y": 0,
      "z": -17,
      "name": "Soil_Dirt_Dry"
    },
    {
      "x": -31,
      "y": 1,
      "z": -17,
      "name": "Soil_Dirt_Dry"
    },
    {
      "x": -31,
      "y": 0,
      "z": -16,
      "name": "Soil_Dirt_Dry"
    },
    {
      "x": -31,
      "y": 1,
      "z": -16,
      "name": "Soil_Dirt_Dry"
    },
    {
      "x": -31,
      "y": 0,
      "z": -15,
      "name": "Soil_Dirt_Dry"
    },
    {
      "x": -31,
      "y": 1,
      "z": -15,
      "name": "Soil_Dirt_Dry"
    },
    {
      "x": -31,
      "y": 0,
      "z": -14,
      "name": "Soil_Dirt_Dry"
    },
    {
      "x": -31,
      "y": 1,
      "z": -14,
      "name": "Soil_Dirt_Dry"
    },
    {
      "x": -31,
      "y": 2,
      "z": -14,
      "name": "Soil_Dirt_Dry"
    },
    {
      "x": -31,
      "y": 0,
      "z": -13,
      "name": "Soil_Dirt_Dry"
    },
    {
      "x": -31,
      "y": 1,
      "z": -13,
      "name": "Soil_Dirt_Dry"
    },
    {
      "x": -31,
      "y": 2,
      "z": -13,
      "name": "Soil_Dirt_Dry"
    },
    {
      "x": -31,
      "y": 0,
      "z": -12,
      "name": "Soil_Dirt_Dry"
    },
    {
      "x": -31,
      "y": 1,
      "z": -12,
      "name": "Soil_Dirt_Dry"
    },
    {
      "x": -31,
      "y": 2,
      "z": -12,
      "name": "Soil_Dirt_Dry"
    },
    {
      "x": -31,
      "y": 0,
      "z": -11,
      "name": "Soil_Dirt_Dry"
    },
    {
      "x": -31,
      "y": 1,
      "z": -11,
      "name": "Soil_Dirt_Dry"
    },
    {
      "x": -31,
      "y": 2,
      "z": -11,
      "name": "Soil_Dirt_Dry"
    },
    {
      "x": -31,
      "y": 3,
      "z": -11,
      "name": "Soil_Dirt_Dry"
    },
    {
      "x": -31,
      "y": 0,
      "z": -10,
      "name": "Soil_Dirt_Dry"
    },
    {
      "x": -31,
      "y": 1,
      "z": -10,
      "name": "Soil_Dirt_Dry"
    },
    {
      "x": -31,
      "y": 2,
      "z": -10,
      "name": "Soil_Dirt_Dry"
    },
    {
      "x": -31,
      "y": 3,
      "z": -10,
      "name": "Soil_Dirt_Dry"
    },
    {
      "x": -31,
      "y": 0,
      "z": -9,
      "name": "Soil_Dirt_Dry"
    },
    {
      "x": -31,
      "y": 1,
      "z": -9,
      "name": "Soil_Dirt_Dry"
    },
    {
      "x": -31,
      "y": 2,
      "z": -9,
      "name": "Soil_Dirt_Dry"
    },
    {
      "x": -31,
      "y": 3,
      "z": -9,
      "name": "Soil_Dirt_Dry"
    },
    {
      "x": -31,
      "y": 0,
      "z": -8,
      "name": "Soil_Dirt_Dry"
    },
    {
      "x": -31,
      "y": 1,
      "z": -8,
      "name": "Soil_Dirt_Dry"
    },
    {
      "x": -31,
      "y": 2,
      "z": -8,
      "name": "Soil_Dirt_Dry"
    },
    {
      "x": -31,
      "y": 3,
      "z": -8,
      "name": "Soil_Dirt_Dry"
    },
    {
      "x": -31,
      "y": 0,
      "z": -7,
      "name": "Soil_Dirt_Dry"
    },
    {
      "x": -31,
      "y": 1,
      "z": -7,
      "name": "Soil_Dirt_Dry"
    },
    {
      "x": -31,
      "y": 2,
      "z": -7,
      "name": "Soil_Dirt_Dry"
    },
    {
      "x": -31,
      "y": 3,
      "z": -7,
      "name": "Soil_Dirt_Dry"
    },
    {
      "x": -31,
      "y": 0,
      "z": -6,
      "name": "Soil_Dirt_Dry"
    },
    {
      "x": -31,
      "y": 1,
      "z": -6,
      "name": "Soil_Dirt_Dry"
    },
    {
      "x": -31,
      "y": 2,
      "z": -6,
      "name": "Soil_Dirt_Dry"
    },
    {
      "x": -31,
      "y": 3,
      "z": -6,
      "name": "Soil_Dirt_Dry"
    },
    {
      "x": -31,
      "y": 11,
      "z": -6,
      "name": "Wood_Dry_Branch_Short",
      "support": 15,
      "rotation": 2
    },
    {
      "x": -31,
      "y": 0,
      "z": -5,
      "name": "Soil_Dirt_Dry"
    },
    {
      "x": -31,
      "y": 1,
      "z": -5,
      "name": "Soil_Dirt_Dry"
    },
    {
      "x": -31,
      "y": 2,
      "z": -5,
      "name": "Soil_Dirt_Dry"
    },
    {
      "x": -31,
      "y": 3,
      "z": -5,
      "name": "Wood_Dry_Trunk",
      "support": 15
    },
    {
      "x": -31,
      "y": 4,
      "z": -5,
      "name": "Wood_Dry_Trunk",
      "support": 15
    },
    {
      "x": -31,
      "y": 5,
      "z": -5,
      "name": "Wood_Dry_Trunk",
      "support": 15
    },
    {
      "x": -31,
      "y": 6,
      "z": -5,
      "name": "Wood_Dry_Trunk",
      "support": 15
    },
    {
      "x": -31,
      "y": 7,
      "z": -5,
      "name": "Wood_Dry_Trunk",
      "support": 15
    },
    {
      "x": -31,
      "y": 8,
      "z": -5,
      "name": "Wood_Dry_Trunk",
      "support": 15
    },
    {
      "x": -31,
      "y": 9,
      "z": -5,
      "name": "Wood_Dry_Trunk",
      "support": 15
    },
    {
      "x": -31,
      "y": 10,
      "z": -5,
      "name": "Wood_Dry_Trunk",
      "support": 15
    },
    {
      "x": -31,
      "y": 11,
      "z": -5,
      "name": "Wood_Dry_Trunk",
      "support": 15
    },
    {
      "x": -31,
      "y": 12,
      "z": -5,
      "name": "Wood_Dry_Trunk",
      "support": 15
    },
    {
      "x": -31,
      "y": 0,
      "z": -4,
      "name": "Soil_Dirt_Dry"
    },
    {
      "x": -31,
      "y": 1,
      "z": -4,
      "name": "Soil_Dirt_Dry"
    },
    {
      "x": -31,
      "y": 2,
      "z": -4,
      "name": "Soil_Dirt_Dry"
    },
    {
      "x": -31,
      "y": 3,
      "z": -4,
      "name": "Soil_Dirt_Dry"
    },
    {
      "x": -31,
      "y": 11,
      "z": -4,
      "name": "Wood_Dry_Trunk",
      "support": 15,
      "rotation": 4
    },
    {
      "x": -31,
      "y": 12,
      "z": -4,
      "name": "Cloth_Roof_Leather_Shallow",
      "rotation": 1
    },
    {
      "x": -31,
      "y": 0,
      "z": -3,
      "name": "Soil_Dirt_Dry"
    },
    {
      "x": -31,
      "y": 1,
      "z": -3,
      "name": "Soil_Dirt_Dry"
    },
    {
      "x": -31,
      "y": 2,
      "z": -3,
      "name": "Soil_Dirt_Dry"
    },
    {
      "x": -31,
      "y": 3,
      "z": -3,
      "name": "Soil_Gravel_Sand_Red"
    },
    {
      "x": -31,
      "y": 11,
      "z": -3,
      "name": "Wood_Dry_Trunk",
      "support": 15,
      "rotation": 4
    },
    {
      "x": -31,
      "y": 12,
      "z": -3,
      "name": "Cloth_Roof_Leather_Shallow",
      "rotation": 1
    },
    {
      "x": -31,
      "y": 0,
      "z": -2,
      "name": "Soil_Dirt_Dry"
    },
    {
      "x": -31,
      "y": 1,
      "z": -2,
      "name": "Soil_Dirt_Dry"
    },
    {
      "x": -31,
      "y": 2,
      "z": -2,
      "name": "Soil_Gravel_Sand_Red"
    },
    {
      "x": -31,
      "y": 11,
      "z": -2,
      "name": "Wood_Dry_Trunk",
      "support": 15,
      "rotation": 4
    },
    {
      "x": -31,
      "y": 12,
      "z": -2,
      "name": "Cloth_Roof_Leather_Shallow",
      "rotation": 1
    },
    {
      "x": -31,
      "y": 0,
      "z": -1,
      "name": "Soil_Dirt_Dry"
    },
    {
      "x": -31,
      "y": 1,
      "z": -1,
      "name": "Soil_Dirt_Dry"
    },
    {
      "x": -31,
      "y": 2,
      "z": -1,
      "name": "Soil_Gravel_Sand_Red"
    },
    {
      "x": -31,
      "y": 11,
      "z": -1,
      "name": "Wood_Dry_Trunk",
      "support": 15,
      "rotation": 4
    },
    {
      "x": -31,
      "y": 12,
      "z": -1,
      "name": "Cloth_Roof_Leather_Shallow",
      "rotation": 1
    },
    {
      "x": -31,
      "y": 0,
      "z": 0,
      "name": "Soil_Dirt_Dry"
    },
    {
      "x": -31,
      "y": 1,
      "z": 0,
      "name": "Soil_Dirt_Dry"
    },
    {
      "x": -31,
      "y": 2,
      "z": 0,
      "name": "Soil_Gravel_Sand_Red"
    },
    {
      "x": -31,
      "y": 11,
      "z": 0,
      "name": "Wood_Dry_Trunk",
      "support": 15,
      "rotation": 4
    },
    {
      "x": -31,
      "y": 12,
      "z": 0,
      "name": "Cloth_Roof_Leather_Shallow",
      "rotation": 1
    },
    {
      "x": -31,
      "y": 0,
      "z": 1,
      "name": "Soil_Dirt_Dry"
    },
    {
      "x": -31,
      "y": 1,
      "z": 1,
      "name": "Soil_Dirt_Dry"
    },
    {
      "x": -31,
      "y": 2,
      "z": 1,
      "name": "Soil_Gravel_Sand_Red"
    },
    {
      "x": -31,
      "y": 11,
      "z": 1,
      "name": "Wood_Dry_Trunk",
      "support": 15,
      "rotation": 4
    },
    {
      "x": -31,
      "y": 12,
      "z": 1,
      "name": "Cloth_Roof_Leather_Shallow",
      "rotation": 1
    },
    {
      "x": -31,
      "y": 0,
      "z": 2,
      "name": "Soil_Dirt_Dry"
    },
    {
      "x": -31,
      "y": 1,
      "z": 2,
      "name": "Soil_Dirt_Dry"
    },
    {
      "x": -31,
      "y": 2,
      "z": 2,
      "name": "Soil_Gravel_Sand_Red"
    },
    {
      "x": -31,
      "y": 11,
      "z": 2,
      "name": "Wood_Dry_Trunk",
      "support": 15,
      "rotation": 4
    },
    {
      "x": -31,
      "y": 12,
      "z": 2,
      "name": "Cloth_Roof_Leather_Shallow",
      "rotation": 1
    },
    {
      "x": -31,
      "y": 0,
      "z": 3,
      "name": "Soil_Dirt_Dry"
    },
    {
      "x": -31,
      "y": 1,
      "z": 3,
      "name": "Soil_Dirt_Dry"
    },
    {
      "x": -31,
      "y": 2,
      "z": 3,
      "name": "Soil_Gravel_Sand_Red"
    },
    {
      "x": -31,
      "y": 11,
      "z": 3,
      "name": "Wood_Dry_Trunk",
      "support": 15,
      "rotation": 4
    },
    {
      "x": -31,
      "y": 12,
      "z": 3,
      "name": "Cloth_Roof_Leather_Shallow",
      "rotation": 1
    },
    {
      "x": -31,
      "y": 0,
      "z": 4,
      "name": "Soil_Dirt_Dry"
    },
    {
      "x": -31,
      "y": 1,
      "z": 4,
      "name": "Soil_Dirt_Dry"
    },
    {
      "x": -31,
      "y": 2,
      "z": 4,
      "name": "Soil_Dirt_Dry"
    },
    {
      "x": -31,
      "y": 11,
      "z": 4,
      "name": "Wood_Dry_Trunk",
      "support": 15,
      "rotation": 4
    },
    {
      "x": -31,
      "y": 12,
      "z": 4,
      "name": "Cloth_Roof_Leather_Shallow",
      "rotation": 1
    },
    {
      "x": -31,
      "y": 0,
      "z": 5,
      "name": "Soil_Dirt_Dry"
    },
    {
      "x": -31,
      "y": 1,
      "z": 5,
      "name": "Soil_Dirt_Dry"
    },
    {
      "x": -31,
      "y": 2,
      "z": 5,
      "name": "Soil_Dirt_Dry"
    },
    {
      "x": -31,
      "y": 3,
      "z": 5,
      "name": "Wood_Dry_Trunk",
      "support": 15
    },
    {
      "x": -31,
      "y": 4,
      "z": 5,
      "name": "Wood_Dry_Trunk",
      "support": 15
    },
    {
      "x": -31,
      "y": 5,
      "z": 5,
      "name": "Wood_Dry_Trunk",
      "support": 15
    },
    {
      "x": -31,
      "y": 6,
      "z": 5,
      "name": "Wood_Dry_Trunk",
      "support": 15
    },
    {
      "x": -31,
      "y": 7,
      "z": 5,
      "name": "Wood_Dry_Trunk",
      "support": 15
    },
    {
      "x": -31,
      "y": 8,
      "z": 5,
      "name": "Wood_Dry_Trunk",
      "support": 15
    },
    {
      "x": -31,
      "y": 9,
      "z": 5,
      "name": "Wood_Dry_Trunk",
      "support": 15
    },
    {
      "x": -31,
      "y": 10,
      "z": 5,
      "name": "Wood_Dry_Trunk",
      "support": 15
    },
    {
      "x": -31,
      "y": 11,
      "z": 5,
      "name": "Wood_Dry_Trunk",
      "support": 15
    },
    {
      "x": -31,
      "y": 12,
      "z": 5,
      "name": "Wood_Dry_Trunk",
      "support": 15
    },
    {
      "x": -31,
      "y": 0,
      "z": 6,
      "name": "Soil_Dirt_Dry"
    },
    {
      "x": -31,
      "y": 1,
      "z": 6,
      "name": "Soil_Dirt_Dry"
    },
    {
      "x": -31,
      "y": 2,
      "z": 6,
      "name": "Soil_Dirt_Dry"
    },
    {
      "x": -31,
      "y": 3,
      "z": 6,
      "name": "Soil_Dirt_Dry"
    },
    {
      "x": -31,
      "y": 11,
      "z": 6,
      "name": "Wood_Dry_Branch_Short",
      "support": 15
    },
    {
      "x": -31,
      "y": 0,
      "z": 7,
      "name": "Soil_Dirt_Dry"
    },
    {
      "x": -31,
      "y": 1,
      "z": 7,
      "name": "Soil_Dirt_Dry"
    },
    {
      "x": -31,
      "y": 2,
      "z": 7,
      "name": "Soil_Dirt_Dry"
    },
    {
      "x": -31,
      "y": 3,
      "z": 7,
      "name": "Soil_Dirt_Dry"
    },
    {
      "x": -31,
      "y": 0,
      "z": 8,
      "name": "Soil_Dirt_Dry"
    },
    {
      "x": -31,
      "y": 1,
      "z": 8,
      "name": "Soil_Dirt_Dry"
    },
    {
      "x": -31,
      "y": 2,
      "z": 8,
      "name": "Soil_Dirt_Dry"
    },
    {
      "x": -31,
      "y": 3,
      "z": 8,
      "name": "Soil_Dirt_Dry"
    },
    {
      "x": -31,
      "y": 0,
      "z": 9,
      "name": "Soil_Dirt_Dry"
    },
    {
      "x": -31,
      "y": 1,
      "z": 9,
      "name": "Soil_Dirt_Dry"
    },
    {
      "x": -31,
      "y": 2,
      "z": 9,
      "name": "Soil_Dirt_Dry"
    },
    {
      "x": -31,
      "y": 3,
      "z": 9,
      "name": "Soil_Dirt_Dry"
    },
    {
      "x": -31,
      "y": 0,
      "z": 10,
      "name": "Soil_Dirt_Dry"
    },
    {
      "x": -31,
      "y": 1,
      "z": 10,
      "name": "Soil_Dirt_Dry"
    },
    {
      "x": -31,
      "y": 2,
      "z": 10,
      "name": "Soil_Dirt_Dry"
    },
    {
      "x": -31,
      "y": 3,
      "z": 10,
      "name": "Soil_Dirt_Dry"
    },
    {
      "x": -31,
      "y": 0,
      "z": 11,
      "name": "Soil_Dirt_Dry"
    },
    {
      "x": -31,
      "y": 1,
      "z": 11,
      "name": "Soil_Dirt_Dry"
    },
    {
      "x": -31,
      "y": 2,
      "z": 11,
      "name": "Soil_Dirt_Dry"
    },
    {
      "x": -31,
      "y": 3,
      "z": 11,
      "name": "Soil_Dirt_Dry"
    },
    {
      "x": -31,
      "y": 0,
      "z": 12,
      "name": "Soil_Dirt_Dry"
    },
    {
      "x": -31,
      "y": 1,
      "z": 12,
      "name": "Soil_Dirt_Dry"
    },
    {
      "x": -31,
      "y": 2,
      "z": 12,
      "name": "Soil_Dirt_Dry"
    },
    {
      "x": -31,
      "y": 3,
      "z": 12,
      "name": "Soil_Dirt_Dry"
    },
    {
      "x": -31,
      "y": 0,
      "z": 13,
      "name": "Soil_Dirt_Dry"
    },
    {
      "x": -31,
      "y": 1,
      "z": 13,
      "name": "Soil_Dirt_Dry"
    },
    {
      "x": -31,
      "y": 2,
      "z": 13,
      "name": "Soil_Dirt_Dry"
    },
    {
      "x": -31,
      "y": 3,
      "z": 13,
      "name": "Wood_Dry_Trunk",
      "support": 15
    },
    {
      "x": -31,
      "y": 4,
      "z": 13,
      "name": "Wood_Dry_Trunk",
      "support": 15
    },
    {
      "x": -31,
      "y": 5,
      "z": 13,
      "name": "Wood_Dry_Trunk",
      "support": 15
    },
    {
      "x": -31,
      "y": 6,
      "z": 13,
      "name": "Wood_Dry_Trunk",
      "support": 15
    },
    {
      "x": -31,
      "y": 7,
      "z": 13,
      "name": "Wood_Dry_Trunk",
      "support": 15
    },
    {
      "x": -31,
      "y": 8,
      "z": 13,
      "name": "Wood_Dry_Trunk",
      "support": 15
    },
    {
      "x": -31,
      "y": 9,
      "z": 13,
      "name": "Wood_Dry_Branch_Long",
      "support": 15
    },
    {
      "x": -31,
      "y": 10,
      "z": 13,
      "name": "Survival_Trap_Spike_Wood_Large"
    },
    {
      "x": -31,
      "y": 0,
      "z": 14,
      "name": "Soil_Dirt_Dry"
    },
    {
      "x": -31,
      "y": 1,
      "z": 14,
      "name": "Soil_Dirt_Dry"
    },
    {
      "x": -31,
      "y": 2,
      "z": 14,
      "name": "Soil_Dirt_Dry"
    },
    {
      "x": -31,
      "y": 0,
      "z": 15,
      "name": "Soil_Dirt_Dry"
    },
    {
      "x": -31,
      "y": 1,
      "z": 15,
      "name": "Soil_Dirt_Dry"
    },
    {
      "x": -31,
      "y": 0,
      "z": 16,
      "name": "Soil_Dirt_Dry"
    },
    {
      "x": -31,
      "y": 1,
      "z": 16,
      "name": "Soil_Dirt_Dry"
    },
    {
      "x": -31,
      "y": 0,
      "z": 17,
      "name": "Soil_Dirt_Dry"
    },
    {
      "x": -31,
      "y": 1,
      "z": 17,
      "name": "Soil_Dirt_Dry"
    },
    {
      "x": -31,
      "y": 0,
      "z": 18,
      "name": "Soil_Dirt_Dry"
    },
    {
      "x": -31,
      "y": 1,
      "z": 18,
      "name": "Soil_Dirt_Dry"
    },
    {
      "x": -31,
      "y": 0,
      "z": 19,
      "name": "Soil_Dirt_Dry"
    },
    {
      "x": -31,
      "y": 1,
      "z": 19,
      "name": "Soil_Dirt_Dry"
    },
    {
      "x": -31,
      "y": 0,
      "z": 20,
      "name": "Soil_Dirt_Dry"
    },
    {
      "x": -31,
      "y": 1,
      "z": 20,
      "name": "Soil_Dirt_Dry"
    },
    {
      "x": -31,
      "y": 0,
      "z": 21,
      "name": "Soil_Dirt_Dry"
    },
    {
      "x": -31,
      "y": 1,
      "z": 21,
      "name": "Soil_Dirt_Dry"
    },
    {
      "x": -31,
      "y": 0,
      "z": 22,
      "name": "Soil_Dirt_Dry"
    },
    {
      "x": -31,
      "y": 1,
      "z": 22,
      "name": "Soil_Dirt_Dry"
    },
    {
      "x": -31,
      "y": 0,
      "z": 23,
      "name": "Soil_Dirt_Dry"
    },
    {
      "x": -31,
      "y": 1,
      "z": 23,
      "name": "Soil_Dirt_Dry"
    },
    {
      "x": -31,
      "y": 0,
      "z": 24,
      "name": "Soil_Dirt_Dry"
    },
    {
      "x": -31,
      "y": 1,
      "z": 24,
      "name": "Soil_Dirt_Dry"
    },
    {
      "x": -31,
      "y": 0,
      "z": 25,
      "name": "Soil_Dirt_Dry"
    },
    {
      "x": -31,
      "y": 1,
      "z": 25,
      "name": "Soil_Dirt_Dry"
    },
    {
      "x": -31,
      "y": 0,
      "z": 26,
      "name": "Soil_Dirt_Dry"
    },
    {
      "x": -31,
      "y": 1,
      "z": 26,
      "name": "Soil_Dirt_Dry"
    },
    {
      "x": -31,
      "y": 0,
      "z": 27,
      "name": "Soil_Dirt_Dry"
    },
    {
      "x": -31,
      "y": 0,
      "z": 28,
      "name": "Soil_Dirt_Dry"
    },
    {
      "x": -31,
      "y": 0,
      "z": 29,
      "name": "Soil_Dirt_Dry"
    },
    {
      "x": -30,
      "y": 0,
      "z": -30,
      "name": "Soil_Dirt_Dry"
    },
    {
      "x": -30,
      "y": 0,
      "z": -29,
      "name": "Soil_Dirt_Dry"
    },
    {
      "x": -30,
      "y": 0,
      "z": -28,
      "name": "Soil_Dirt_Dry"
    },
    {
      "x": -30,
      "y": 0,
      "z": -27,
      "name": "Soil_Dirt_Dry"
    },
    {
      "x": -30,
      "y": 1,
      "z": -27,
      "name": "Soil_Dirt_Dry"
    },
    {
      "x": -30,
      "y": 0,
      "z": -26,
      "name": "Soil_Dirt_Dry"
    },
    {
      "x": -30,
      "y": 1,
      "z": -26,
      "name": "Soil_Dirt_Dry"
    },
    {
      "x": -30,
      "y": 0,
      "z": -25,
      "name": "Soil_Dirt_Dry"
    },
    {
      "x": -30,
      "y": 1,
      "z": -25,
      "name": "Soil_Dirt_Dry"
    },
    {
      "x": -30,
      "y": 0,
      "z": -24,
      "name": "Soil_Dirt_Dry"
    },
    {
      "x": -30,
      "y": 1,
      "z": -24,
      "name": "Soil_Dirt_Dry"
    },
    {
      "x": -30,
      "y": 0,
      "z": -23,
      "name": "Soil_Dirt_Dry"
    },
    {
      "x": -30,
      "y": 1,
      "z": -23,
      "name": "Soil_Dirt_Dry"
    },
    {
      "x": -30,
      "y": 0,
      "z": -22,
      "name": "Soil_Dirt_Dry"
    },
    {
      "x": -30,
      "y": 1,
      "z": -22,
      "name": "Soil_Dirt_Dry"
    },
    {
      "x": -30,
      "y": 0,
      "z": -21,
      "name": "Soil_Dirt_Dry"
    },
    {
      "x": -30,
      "y": 1,
      "z": -21,
      "name": "Soil_Dirt_Dry"
    },
    {
      "x": -30,
      "y": 0,
      "z": -20,
      "name": "Soil_Dirt_Dry"
    },
    {
      "x": -30,
      "y": 1,
      "z": -20,
      "name": "Soil_Dirt_Dry"
    },
    {
      "x": -30,
      "y": 2,
      "z": -20,
      "name": "Soil_Dirt_Dry"
    },
    {
      "x": -30,
      "y": 0,
      "z": -19,
      "name": "Soil_Dirt_Dry"
    },
    {
      "x": -30,
      "y": 1,
      "z": -19,
      "name": "Soil_Dirt_Dry"
    },
    {
      "x": -30,
      "y": 2,
      "z": -19,
      "name": "Soil_Dirt_Dry"
    },
    {
      "x": -30,
      "y": 0,
      "z": -18,
      "name": "Soil_Dirt_Dry"
    },
    {
      "x": -30,
      "y": 1,
      "z": -18,
      "name": "Soil_Dirt_Dry"
    },
    {
      "x": -30,
      "y": 2,
      "z": -18,
      "name": "Soil_Dirt_Dry"
    },
    {
      "x": -30,
      "y": 0,
      "z": -17,
      "name": "Soil_Dirt_Dry"
    },
    {
      "x": -30,
      "y": 1,
      "z": -17,
      "name": "Soil_Dirt_Dry"
    },
    {
      "x": -30,
      "y": 2,
      "z": -17,
      "name": "Soil_Dirt_Dry"
    },
    {
      "x": -30,
      "y": 0,
      "z": -16,
      "name": "Soil_Dirt_Dry"
    },
    {
      "x": -30,
      "y": 1,
      "z": -16,
      "name": "Soil_Dirt_Dry"
    },
    {
      "x": -30,
      "y": 2,
      "z": -16,
