{
  "version": 8,
  "blockIdVersion": 11,
  "anchorX": 0,
  "anchorY": 0,
  "anchorZ": 0,
  "blocks": [
    {
      "x": -23,
      "y": 0,
      "z": -20,
      "name": "Soil_Clay"
    },
    {
      "x": -23,
      "y": 1,
      "z": -20,
      "name": "Soil_Clay"
    },
    {
      "x": -23,
      "y": 2,
      "z": -20,
      "name": "Soil_Grass"
    },
    {
      "x": -23,
      "y": 0,
      "z": -19,
      "name": "Soil_Clay"
    },
    {
      "x": -23,
      "y": 1,
      "z": -19,
      "name": "Soil_Clay"
    },
    {
      "x": -23,
      "y": 2,
      "z": -19,
      "name": "Soil_Grass"
    },
    {
      "x": -23,
      "y": 0,
      "z": -18,
      "name": "Soil_Clay"
    },
    {
      "x": -23,
      "y": 1,
      "z": -18,
      "name": "Soil_Clay"
    },
    {
      "x": -23,
      "y": 2,
      "z": -18,
      "name": "Soil_Grass"
    },
    {
      "x": -23,
      "y": 0,
      "z": -17,
      "name": "Soil_Clay"
    },
    {
      "x": -23,
      "y": 1,
      "z": -17,
      "name": "Soil_Clay"
    },
    {
      "x": -23,
      "y": 2,
      "z": -17,
      "name": "Soil_Grass"
    },
    {
      "x": -23,
      "y": 0,
      "z": -16,
      "name": "Soil_Clay"
    },
    {
      "x": -23,
      "y": 1,
      "z": -16,
      "name": "Soil_Clay"
    },
    {
      "x": -23,
      "y": 2,
      "z": -16,
      "name": "Soil_Grass"
    },
    {
      "x": -23,
      "y": 0,
      "z": -15,
      "name": "Soil_Clay"
    },
    {
      "x": -23,
      "y": 1,
      "z": -15,
      "name": "Soil_Clay"
    },
    {
      "x": -23,
      "y": 2,
      "z": -15,
      "name": "Soil_Grass"
    },
    {
      "x": -23,
      "y": 0,
      "z": -14,
      "name": "Soil_Clay"
    },
    {
      "x": -23,
      "y": 1,
      "z": -14,
      "name": "Soil_Clay"
    },
    {
      "x": -23,
      "y": 2,
      "z": -14,
      "name": "Soil_Grass"
    },
    {
      "x": -23,
      "y": 0,
      "z": -13,
      "name": "Soil_Clay"
    },
    {
      "x": -23,
      "y": 1,
      "z": -13,
      "name": "Soil_Clay"
    },
    {
      "x": -23,
      "y": 2,
      "z": -13,
      "name": "Soil_Grass"
    },
    {
      "x": -23,
      "y": 0,
      "z": -12,
      "name": "Soil_Clay"
    },
    {
      "x": -23,
      "y": 1,
      "z": -12,
      "name": "Soil_Clay"
    },
    {
      "x": -23,
      "y": 2,
      "z": -12,
      "name": "Soil_Grass"
    },
    {
      "x": -23,
      "y": 0,
      "z": -11,
      "name": "Soil_Clay"
    },
    {
      "x": -23,
      "y": 1,
      "z": -11,
      "name": "Soil_Clay"
    },
    {
      "x": -23,
      "y": 2,
      "z": -11,
      "name": "Soil_Grass"
    },
    {
      "x": -23,
      "y": 0,
      "z": -10,
      "name": "Soil_Clay"
    },
    {
      "x": -23,
      "y": 1,
      "z": -10,
      "name": "Soil_Clay"
    },
    {
      "x": -23,
      "y": 2,
      "z": -10,
      "name": "Soil_Grass"
    },
    {
      "x": -23,
      "y": 0,
      "z": -9,
      "name": "Soil_Clay"
    },
    {
      "x": -23,
      "y": 1,
      "z": -9,
      "name": "Soil_Clay"
    },
    {
      "x": -23,
      "y": 2,
      "z": -9,
      "name": "Soil_Grass"
    },
    {
      "x": -23,
      "y": 0,
      "z": -8,
      "name": "Soil_Clay"
    },
    {
      "x": -23,
      "y": 1,
      "z": -8,
      "name": "Soil_Clay"
    },
    {
      "x": -23,
      "y": 2,
      "z": -8,
      "name": "Soil_Grass"
    },
    {
      "x": -23,
      "y": 0,
      "z": -7,
      "name": "Soil_Clay"
    },
    {
      "x": -23,
      "y": 1,
      "z": -7,
      "name": "Soil_Clay"
    },
    {
      "x": -23,
      "y": 2,
      "z": -7,
      "name": "Soil_Grass"
    },
    {
      "x": -23,
      "y": 0,
      "z": -6,
      "name": "Soil_Clay"
    },
    {
      "x": -23,
      "y": 1,
      "z": -6,
      "name": "Soil_Clay"
    },
    {
      "x": -23,
      "y": 2,
      "z": -6,
      "name": "Soil_Grass"
    },
    {
      "x": -23,
      "y": 0,
      "z": -5,
      "name": "Soil_Clay"
    },
    {
      "x": -23,
      "y": 1,
      "z": -5,
      "name": "Soil_Clay"
    },
    {
      "x": -23,
      "y": 2,
      "z": -5,
      "name": "Soil_Grass"
    },
    {
      "x": -23,
      "y": 0,
      "z": -4,
      "name": "Soil_Clay"
    },
    {
      "x": -23,
      "y": 1,
      "z": -4,
      "name": "Soil_Clay"
    },
    {
      "x": -23,
      "y": 2,
      "z": -4,
      "name": "Soil_Grass"
    },
    {
      "x": -23,
      "y": 0,
      "z": -3,
      "name": "Soil_Clay"
    },
    {
      "x": -23,
      "y": 1,
      "z": -3,
      "name": "Soil_Clay"
    },
    {
      "x": -23,
      "y": 2,
      "z": -3,
      "name": "Soil_Grass"
    },
    {
      "x": -23,
      "y": 0,
      "z": -2,
      "name": "Soil_Clay"
    },
    {
      "x": -23,
      "y": 1,
      "z": -2,
      "name": "Soil_Clay"
    },
    {
      "x": -23,
      "y": 2,
      "z": -2,
      "name": "Soil_Grass"
    },
    {
      "x": -23,
      "y": 0,
      "z": -1,
      "name": "Soil_Clay"
    },
    {
      "x": -23,
      "y": 1,
      "z": -1,
      "name": "Soil_Clay"
    },
    {
      "x": -23,
      "y": 2,
      "z": -1,
      "name": "Soil_Grass"
    },
    {
      "x": -23,
      "y": 0,
      "z": 0,
      "name": "Soil_Clay"
    },
    {
      "x": -23,
      "y": 1,
      "z": 0,
      "name": "Soil_Clay"
    },
    {
      "x": -23,
      "y": 2,
      "z": 0,
      "name": "Soil_Grass"
    },
    {
      "x": -23,
      "y": 0,
      "z": 1,
      "name": "Soil_Clay"
    },
    {
      "x": -23,
      "y": 1,
      "z": 1,
      "name": "Soil_Clay"
    },
    {
      "x": -23,
      "y": 2,
      "z": 1,
      "name": "Soil_Grass"
    },
    {
      "x": -23,
      "y": 0,
      "z": 2,
      "name": "Soil_Clay"
    },
    {
      "x": -23,
      "y": 1,
      "z": 2,
      "name": "Soil_Clay"
    },
    {
      "x": -23,
      "y": 2,
      "z": 2,
      "name": "Soil_Grass"
    },
    {
      "x": -23,
      "y": 0,
      "z": 3,
      "name": "Soil_Clay"
    },
    {
      "x": -23,
      "y": 1,
      "z": 3,
      "name": "Soil_Clay"
    },
    {
      "x": -23,
      "y": 2,
      "z": 3,
      "name": "Soil_Grass"
    },
    {
      "x": -23,
      "y": 0,
      "z": 4,
      "name": "Soil_Clay"
    },
    {
      "x": -23,
      "y": 1,
      "z": 4,
      "name": "Soil_Clay"
    },
    {
      "x": -23,
      "y": 2,
      "z": 4,
      "name": "Soil_Grass"
    },
    {
      "x": -23,
      "y": 0,
      "z": 5,
      "name": "Soil_Clay"
    },
    {
      "x": -23,
      "y": 1,
      "z": 5,
      "name": "Soil_Clay"
    },
    {
      "x": -23,
      "y": 2,
      "z": 5,
      "name": "Soil_Grass"
    },
    {
      "x": -23,
      "y": 0,
      "z": 6,
      "name": "Soil_Clay"
    },
    {
      "x": -23,
      "y": 1,
      "z": 6,
      "name": "Soil_Clay"
    },
    {
      "x": -23,
      "y": 2,
      "z": 6,
      "name": "Soil_Grass"
    },
    {
      "x": -23,
      "y": 0,
      "z": 7,
      "name": "Soil_Clay"
    },
    {
      "x": -23,
      "y": 1,
      "z": 7,
      "name": "Soil_Clay"
    },
    {
      "x": -23,
      "y": 2,
      "z": 7,
      "name": "Soil_Grass"
    },
    {
      "x": -23,
      "y": 0,
      "z": 8,
      "name": "Soil_Clay"
    },
    {
      "x": -23,
      "y": 1,
      "z": 8,
      "name": "Soil_Clay"
    },
    {
      "x": -23,
      "y": 2,
      "z": 8,
      "name": "Soil_Grass"
    },
    {
      "x": -23,
      "y": 0,
      "z": 9,
      "name": "Soil_Clay"
    },
    {
      "x": -23,
      "y": 1,
      "z": 9,
      "name": "Soil_Clay"
    },
    {
      "x": -23,
      "y": 2,
      "z": 9,
      "name": "Soil_Grass"
    },
    {
      "x": -23,
      "y": 0,
      "z": 10,
      "name": "Soil_Clay"
    },
    {
      "x": -23,
      "y": 1,
      "z": 10,
      "name": "Soil_Clay"
    },
    {
      "x": -23,
      "y": 2,
      "z": 10,
      "name": "Soil_Grass"
    },
    {
      "x": -23,
      "y": 0,
      "z": 11,
      "name": "Soil_Clay"
    },
    {
      "x": -23,
      "y": 1,
      "z": 11,
      "name": "Soil_Clay"
    },
    {
      "x": -23,
      "y": 2,
      "z": 11,
      "name": "Soil_Grass"
    },
    {
      "x": -23,
      "y": 0,
      "z": 12,
      "name": "Soil_Clay"
    },
    {
      "x": -23,
      "y": 1,
      "z": 12,
      "name": "Soil_Clay"
    },
    {
      "x": -23,
      "y": 2,
      "z": 12,
      "name": "Soil_Grass"
    },
    {
      "x": -23,
      "y": 0,
      "z": 13,
      "name": "Soil_Clay"
    },
    {
      "x": -23,
      "y": 1,
      "z": 13,
      "name": "Soil_Clay"
    },
    {
      "x": -23,
      "y": 2,
      "z": 13,
      "name": "Soil_Grass"
    },
    {
      "x": -23,
      "y": 0,
      "z": 14,
      "name": "Soil_Clay"
    },
    {
      "x": -23,
      "y": 1,
      "z": 14,
      "name": "Soil_Clay"
    },
    {
      "x": -23,
      "y": 2,
      "z": 14,
      "name": "Soil_Grass"
    },
    {
      "x": -23,
      "y": 0,
      "z": 15,
      "name": "Soil_Clay"
    },
    {
      "x": -23,
      "y": 1,
      "z": 15,
      "name": "Soil_Clay"
    },
    {
      "x": -23,
      "y": 2,
      "z": 15,
      "name": "Soil_Grass"
    },
    {
      "x": -23,
      "y": 0,
      "z": 16,
      "name": "Soil_Clay"
    },
    {
      "x": -23,
      "y": 1,
      "z": 16,
      "name": "Soil_Clay"
    },
    {
      "x": -23,
      "y": 2,
      "z": 16,
      "name": "Soil_Grass"
    },
    {
      "x": -23,
      "y": 0,
      "z": 17,
      "name": "Soil_Clay"
    },
    {
      "x": -23,
      "y": 1,
      "z": 17,
      "name": "Soil_Clay"
    },
    {
      "x": -23,
      "y": 2,
      "z": 17,
      "name": "Soil_Grass"
    },
    {
      "x": -23,
      "y": 0,
      "z": 18,
      "name": "Soil_Clay"
    },
    {
      "x": -23,
      "y": 1,
      "z": 18,
      "name": "Soil_Clay"
    },
    {
      "x": -23,
      "y": 2,
      "z": 18,
      "name": "Soil_Grass"
    },
    {
      "x": -23,
      "y": 0,
      "z": 19,
      "name": "Soil_Clay"
    },
    {
      "x": -23,
      "y": 1,
      "z": 19,
      "name": "Soil_Clay"
    },
    {
      "x": -23,
      "y": 2,
      "z": 19,
      "name": "Soil_Grass"
    },
    {
      "x": -23,
      "y": 0,
      "z": 20,
      "name": "Soil_Clay"
    },
    {
      "x": -23,
      "y": 1,
      "z": 20,
      "name": "Soil_Clay"
    },
    {
      "x": -23,
      "y": 2,
      "z": 20,
      "name": "Soil_Grass"
    },
    {
      "x": -22,
      "y": 0,
      "z": -20,
      "name": "Soil_Clay"
    },
    {
      "x": -22,
      "y": 1,
      "z": -20,
      "name": "Soil_Clay"
    },
    {
      "x": -22,
      "y": 2,
      "z": -20,
      "name": "Soil_Grass"
    },
    {
      "x": -22,
      "y": 0,
      "z": -19,
      "name": "Soil_Clay"
    },
    {
      "x": -22,
      "y": 1,
      "z": -19,
      "name": "Soil_Clay"
    },
    {
      "x": -22,
      "y": 2,
      "z": -19,
      "name": "Soil_Grass"
    },
    {
      "x": -22,
      "y": 0,
      "z": -18,
      "name": "Soil_Clay"
    },
    {
      "x": -22,
      "y": 1,
      "z": -18,
      "name": "Soil_Clay"
    },
    {
      "x": -22,
      "y": 2,
      "z": -18,
      "name": "Soil_Grass"
    },
    {
      "x": -22,
      "y": 0,
      "z": -17,
      "name": "Soil_Clay"
    },
    {
      "x": -22,
      "y": 1,
      "z": -17,
      "name": "Soil_Clay"
    },
    {
      "x": -22,
      "y": 2,
      "z": -17,
      "name": "Soil_Grass"
    },
    {
      "x": -22,
      "y": 0,
      "z": -16,
      "name": "Soil_Clay"
    },
    {
      "x": -22,
      "y": 1,
      "z": -16,
      "name": "Soil_Clay"
    },
    {
      "x": -22,
      "y": 2,
      "z": -16,
      "name": "Soil_Grass"
    },
    {
      "x": -22,
      "y": 0,
      "z": -15,
      "name": "Soil_Clay"
    },
    {
      "x": -22,
      "y": 1,
      "z": -15,
      "name": "Soil_Clay"
    },
    {
      "x": -22,
      "y": 2,
      "z": -15,
      "name": "Soil_Grass"
    },
    {
      "x": -22,
      "y": 0,
      "z": -14,
      "name": "Soil_Clay"
    },
    {
      "x": -22,
      "y": 1,
      "z": -14,
      "name": "Soil_Clay"
    },
    {
      "x": -22,
      "y": 2,
      "z": -14,
      "name": "Soil_Grass"
    },
    {
      "x": -22,
      "y": 0,
      "z": -13,
      "name": "Soil_Clay"
    },
    {
      "x": -22,
      "y": 1,
      "z": -13,
      "name": "Soil_Clay"
    },
    {
      "x": -22,
      "y": 2,
      "z": -13,
      "name": "Soil_Grass"
    },
    {
      "x": -22,
      "y": 0,
      "z": -12,
      "name": "Soil_Clay"
    },
    {
      "x": -22,
      "y": 1,
      "z": -12,
      "name": "Soil_Clay"
    },
    {
      "x": -22,
      "y": 2,
      "z": -12,
      "name": "Soil_Grass"
    },
    {
      "x": -22,
      "y": 0,
      "z": -11,
      "name": "Soil_Clay"
    },
    {
      "x": -22,
      "y": 1,
      "z": -11,
      "name": "Soil_Clay"
    },
    {
      "x": -22,
      "y": 2,
      "z": -11,
      "name": "Soil_Grass"
    },
    {
      "x": -22,
      "y": 0,
      "z": -10,
      "name": "Soil_Clay"
    },
    {
      "x": -22,
      "y": 1,
      "z": -10,
      "name": "Soil_Clay"
    },
    {
      "x": -22,
      "y": 2,
      "z": -10,
      "name": "Soil_Grass"
    },
    {
      "x": -22,
      "y": 0,
      "z": -9,
      "name": "Soil_Clay"
    },
    {
      "x": -22,
      "y": 1,
      "z": -9,
      "name": "Soil_Clay"
    },
    {
      "x": -22,
      "y": 2,
      "z": -9,
      "name": "Soil_Grass"
    },
    {
      "x": -22,
      "y": 0,
      "z": -8,
      "name": "Soil_Clay"
    },
    {
      "x": -22,
      "y": 1,
      "z": -8,
      "name": "Soil_Clay"
    },
    {
      "x": -22,
      "y": 2,
      "z": -8,
      "name": "Soil_Grass"
    },
    {
      "x": -22,
      "y": 0,
      "z": -7,
      "name": "Soil_Clay"
    },
    {
      "x": -22,
      "y": 1,
      "z": -7,
      "name": "Soil_Clay"
    },
    {
      "x": -22,
      "y": 2,
      "z": -7,
      "name": "Soil_Grass"
    },
    {
      "x": -22,
      "y": 0,
      "z": -6,
      "name": "Soil_Clay"
    },
    {
      "x": -22,
      "y": 1,
      "z": -6,
      "name": "Soil_Clay"
    },
    {
      "x": -22,
      "y": 2,
      "z": -6,
      "name": "Soil_Grass"
    },
    {
      "x": -22,
      "y": 0,
      "z": -5,
      "name": "Soil_Clay"
    },
    {
      "x": -22,
      "y": 1,
      "z": -5,
      "name": "Soil_Clay"
    },
    {
      "x": -22,
      "y": 2,
      "z": -5,
      "name": "Soil_Grass"
    },
    {
      "x": -22,
      "y": 0,
      "z": -4,
      "name": "Soil_Clay"
    },
    {
      "x": -22,
      "y": 1,
      "z": -4,
      "name": "Soil_Clay"
    },
    {
      "x": -22,
      "y": 2,
      "z": -4,
      "name": "Soil_Grass"
    },
    {
      "x": -22,
      "y": 0,
      "z": -3,
      "name": "Soil_Clay"
    },
    {
      "x": -22,
      "y": 1,
      "z": -3,
      "name": "Soil_Clay"
    },
    {
      "x": -22,
      "y": 2,
      "z": -3,
      "name": "Soil_Grass"
    },
    {
      "x": -22,
      "y": 0,
      "z": -2,
      "name": "Soil_Clay"
    },
    {
      "x": -22,
      "y": 1,
      "z": -2,
      "name": "Soil_Clay"
    },
    {
      "x": -22,
      "y": 2,
      "z": -2,
      "name": "Soil_Grass"
    },
    {
      "x": -22,
      "y": 0,
      "z": -1,
      "name": "Soil_Clay"
    },
    {
      "x": -22,
      "y": 1,
      "z": -1,
      "name": "Soil_Clay"
    },
    {
      "x": -22,
      "y": 2,
      "z": -1,
      "name": "Soil_Grass"
    },
    {
      "x": -22,
      "y": 0,
      "z": 0,
      "name": "Soil_Clay"
    },
    {
      "x": -22,
      "y": 1,
      "z": 0,
      "name": "Soil_Clay"
    },
    {
      "x": -22,
      "y": 2,
      "z": 0,
      "name": "Soil_Grass"
    },
    {
      "x": -22,
      "y": 0,
      "z": 1,
      "name": "Soil_Clay"
    },
    {
      "x": -22,
      "y": 1,
      "z": 1,
      "name": "Soil_Clay"
    },
    {
      "x": -22,
      "y": 2,
      "z": 1,
      "name": "Soil_Grass"
    },
    {
      "x": -22,
      "y": 0,
      "z": 2,
      "name": "Soil_Clay"
    },
    {
      "x": -22,
      "y": 1,
      "z": 2,
      "name": "Soil_Clay"
    },
    {
      "x": -22,
      "y": 2,
      "z": 2,
      "name": "Soil_Grass"
    },
    {
      "x": -22,
      "y": 0,
      "z": 3,
      "name": "Soil_Clay"
    },
    {
      "x": -22,
      "y": 1,
      "z": 3,
      "name": "Soil_Clay"
    },
    {
      "x": -22,
      "y": 2,
      "z": 3,
      "name": "Soil_Grass"
    },
    {
      "x": -22,
      "y": 0,
      "z": 4,
      "name": "Soil_Clay"
    },
    {
      "x": -22,
      "y": 1,
      "z": 4,
      "name": "Soil_Clay"
    },
    {
      "x": -22,
      "y": 2,
      "z": 4,
      "name": "Soil_Grass"
    },
    {
      "x": -22,
      "y": 0,
      "z": 5,
      "name": "Soil_Clay"
    },
    {
      "x": -22,
      "y": 1,
      "z": 5,
      "name": "Soil_Clay"
    },
    {
      "x": -22,
      "y": 2,
      "z": 5,
      "name": "Soil_Grass"
    },
    {
      "x": -22,
      "y": 0,
      "z": 6,
      "name": "Soil_Clay"
    },
    {
      "x": -22,
      "y": 1,
      "z": 6,
      "name": "Soil_Clay"
    },
    {
      "x": -22,
      "y": 2,
      "z": 6,
      "name": "Soil_Grass"
    },
    {
      "x": -22,
      "y": 0,
      "z": 7,
      "name": "Soil_Clay"
    },
    {
      "x": -22,
      "y": 1,
      "z": 7,
      "name": "Soil_Clay"
    },
    {
      "x": -22,
      "y": 2,
      "z": 7,
      "name": "Soil_Grass"
    },
    {
      "x": -22,
      "y": 0,
      "z": 8,
      "name": "Soil_Clay"
    },
    {
      "x": -22,
      "y": 1,
      "z": 8,
      "name": "Soil_Clay"
    },
    {
      "x": -22,
      "y": 2,
      "z": 8,
      "name": "Soil_Grass"
    },
    {
      "x": -22,
      "y": 0,
      "z": 9,
      "name": "Soil_Clay"
    },
    {
      "x": -22,
      "y": 1,
      "z": 9,
      "name": "Soil_Clay"
    },
    {
      "x": -22,
      "y": 2,
      "z": 9,
      "name": "Soil_Grass"
    },
    {
      "x": -22,
      "y": 0,
      "z": 10,
      "name": "Soil_Clay"
    },
    {
      "x": -22,
      "y": 1,
      "z": 10,
      "name": "Soil_Clay"
    },
    {
      "x": -22,
      "y": 2,
      "z": 10,
      "name": "Soil_Grass"
    },
    {
      "x": -22,
      "y": 0,
      "z": 11,
      "name": "Soil_Clay"
    },
    {
      "x": -22,
      "y": 1,
      "z": 11,
      "name": "Soil_Clay"
    },
    {
      "x": -22,
      "y": 2,
      "z": 11,
      "name": "Soil_Grass"
    },
    {
      "x": -22,
      "y": 0,
      "z": 12,
      "name": "Soil_Clay"
    },
    {
      "x": -22,
      "y": 1,
      "z": 12,
      "name": "Soil_Clay"
    },
    {
      "x": -22,
      "y": 2,
      "z": 12,
      "name": "Soil_Grass"
    },
    {
      "x": -22,
      "y": 0,
      "z": 13,
      "name": "Soil_Clay"
    },
    {
      "x": -22,
      "y": 1,
      "z": 13,
      "name": "Soil_Clay"
    },
    {
      "x": -22,
      "y": 2,
      "z": 13,
      "name": "Soil_Grass"
    },
    {
      "x": -22,
      "y": 0,
      "z": 14,
      "name": "Soil_Clay"
    },
    {
      "x": -22,
      "y": 1,
      "z": 14,
      "name": "Soil_Clay"
    },
    {
      "x": -22,
      "y": 2,
      "z": 14,
      "name": "Soil_Grass"
    },
    {
      "x": -22,
      "y": 0,
      "z": 15,
      "name": "Soil_Clay"
    },
    {
      "x": -22,
      "y": 1,
      "z": 15,
      "name": "Soil_Clay"
    },
    {
      "x": -22,
      "y": 2,
      "z": 15,
      "name": "Soil_Grass"
    },
    {
      "x": -22,
      "y": 0,
      "z": 16,
      "name": "Soil_Clay"
    },
    {
      "x": -22,
      "y": 1,
      "z": 16,
      "name": "Soil_Clay"
    },
    {
      "x": -22,
      "y": 2,
      "z": 16,
      "name": "Soil_Grass"
    },
    {
      "x": -22,
      "y": 0,
      "z": 17,
      "name": "Soil_Clay"
    },
    {
      "x": -22,
      "y": 1,
      "z": 17,
      "name": "Soil_Clay"
    },
    {
      "x": -22,
      "y": 2,
      "z": 17,
      "name": "Soil_Grass"
    },
    {
      "x": -22,
      "y": 0,
      "z": 18,
      "name": "Soil_Clay"
    },
    {
      "x": -22,
      "y": 1,
      "z": 18,
      "name": "Soil_Clay"
    },
    {
      "x": -22,
      "y": 2,
      "z": 18,
      "name": "Soil_Grass"
    },
    {
      "x": -22,
      "y": 0,
      "z": 19,
      "name": "Soil_Clay"
    },
    {
      "x": -22,
      "y": 1,
      "z": 19,
      "name": "Soil_Clay"
    },
    {
      "x": -22,
      "y": 2,
      "z": 19,
      "name": "Soil_Grass"
    },
    {
      "x": -22,
      "y": 0,
      "z": 20,
      "name": "Soil_Clay"
    },
    {
      "x": -22,
      "y": 1,
      "z": 20,
      "name": "Soil_Clay"
    },
    {
      "x": -22,
      "y": 2,
      "z": 20,
      "name": "Soil_Grass"
    },
    {
      "x": -21,
      "y": 0,
      "z": -20,
      "name": "Soil_Clay"
    },
    {
      "x": -21,
      "y": 1,
      "z": -20,
      "name": "Soil_Clay"
    },
    {
      "x": -21,
      "y": 2,
      "z": -20,
      "name": "Soil_Grass"
    },
    {
      "x": -21,
      "y": 0,
      "z": -19,
      "name": "Soil_Clay"
    },
    {
      "x": -21,
      "y": 1,
      "z": -19,
      "name": "Soil_Clay"
    },
    {
      "x": -21,
      "y": 2,
      "z": -19,
      "name": "Soil_Grass"
    },
    {
      "x": -21,
      "y": 0,
      "z": -18,
      "name": "Soil_Clay"
    },
    {
      "x": -21,
      "y": 1,
      "z": -18,
      "name": "Soil_Clay"
    },
    {
      "x": -21,
      "y": 2,
      "z": -18,
      "name": "Soil_Grass"
    },
    {
      "x": -21,
      "y": 0,
      "z": -17,
      "name": "Soil_Clay"
    },
    {
      "x": -21,
      "y": 1,
      "z": -17,
      "name": "Soil_Clay"
    },
    {
      "x": -21,
      "y": 2,
      "z": -17,
      "name": "Soil_Grass"
    },
    {
      "x": -21,
      "y": 0,
      "z": -16,
      "name": "Soil_Clay"
    },
    {
      "x": -21,
      "y": 1,
      "z": -16,
      "name": "Soil_Clay"
    },
    {
      "x": -21,
      "y": 2,
      "z": -16,
      "name": "Soil_Grass"
    },
    {
      "x": -21,
      "y": 0,
      "z": -15,
      "name": "Soil_Clay"
    },
    {
      "x": -21,
      "y": 1,
      "z": -15,
      "name": "Soil_Clay"
    },
    {
      "x": -21,
      "y": 2,
      "z": -15,
      "name": "Soil_Grass"
    },
    {
      "x": -21,
      "y": 0,
      "z": -14,
      "name": "Soil_Clay"
    },
    {
      "x": -21,
      "y": 1,
      "z": -14,
      "name": "Soil_Clay"
    },
    {
      "x": -21,
      "y": 2,
      "z": -14,
      "name": "Soil_Grass"
    },
    {
      "x": -21,
      "y": 0,
      "z": -13,
      "name": "Soil_Clay"
    },
    {
      "x": -21,
      "y": 1,
      "z": -13,
      "name": "Soil_Clay"
    },
    {
      "x": -21,
      "y": 2,
      "z": -13,
      "name": "Soil_Grass"
    },
    {
      "x": -21,
      "y": 0,
      "z": -12,
      "name": "Soil_Clay"
    },
    {
      "x": -21,
      "y": 1,
      "z": -12,
      "name": "Soil_Clay"
    },
    {
      "x": -21,
      "y": 2,
      "z": -12,
      "name": "Soil_Grass"
    },
    {
      "x": -21,
      "y": 0,
      "z": -11,
      "name": "Soil_Clay"
    },
    {
      "x": -21,
      "y": 1,
      "z": -11,
      "name": "Soil_Clay"
    },
    {
      "x": -21,
      "y": 2,
      "z": -11,
      "name": "Soil_Grass"
    },
    {
      "x": -21,
      "y": 0,
      "z": -10,
      "name": "Soil_Clay"
    },
    {
      "x": -21,
      "y": 1,
      "z": -10,
      "name": "Soil_Clay"
    },
    {
      "x": -21,
      "y": 2,
      "z": -10,
      "name": "Soil_Grass"
    },
    {
      "x": -21,
      "y": 0,
      "z": -9,
      "name": "Soil_Clay"
    },
    {
      "x": -21,
      "y": 1,
      "z": -9,
      "name": "Soil_Clay"
    },
    {
      "x": -21,
      "y": 2,
      "z": -9,
      "name": "Soil_Grass"
    },
    {
      "x": -21,
      "y": 0,
      "z": -8,
      "name": "Soil_Clay"
    },
    {
      "x": -21,
      "y": 1,
      "z": -8,
      "name": "Soil_Clay"
    },
    {
      "x": -21,
      "y": 2,
      "z": -8,
      "name": "Soil_Grass"
    },
    {
      "x": -21,
      "y": 0,
      "z": -7,
      "name": "Soil_Clay"
    },
    {
      "x": -21,
      "y": 1,
      "z": -7,
      "name": "Soil_Clay"
    },
    {
      "x": -21,
      "y": 2,
      "z": -7,
      "name": "Soil_Grass"
    },
    {
      "x": -21,
      "y": 0,
      "z": -6,
      "name": "Soil_Clay"
    },
    {
      "x": -21,
      "y": 1,
      "z": -6,
      "name": "Soil_Clay"
    },
    {
      "x": -21,
      "y": 2,
      "z": -6,
      "name": "Soil_Grass"
    },
    {
      "x": -21,
      "y": 0,
      "z": -5,
      "name": "Soil_Clay"
    },
    {
      "x": -21,
      "y": 1,
      "z": -5,
      "name": "Soil_Clay"
    },
    {
      "x": -21,
      "y": 2,
      "z": -5,
      "name": "Soil_Grass"
    },
    {
      "x": -21,
      "y": 0,
      "z": -4,
      "name": "Soil_Clay"
    },
    {
      "x": -21,
      "y": 1,
      "z": -4,
      "name": "Soil_Clay"
    },
    {
      "x": -21,
      "y": 2,
      "z": -4,
      "name": "Soil_Grass"
    },
    {
      "x": -21,
      "y": 0,
      "z": -3,
      "name": "Soil_Clay"
    },
    {
      "x": -21,
      "y": 1,
      "z": -3,
      "name": "Soil_Clay"
    },
    {
      "x": -21,
      "y": 2,
      "z": -3,
      "name": "Soil_Grass"
    },
    {
      "x": -21,
      "y": 0,
      "z": -2,
      "name": "Soil_Clay"
    },
    {
      "x": -21,
      "y": 1,
      "z": -2,
      "name": "Soil_Clay"
    },
    {
      "x": -21,
      "y": 2,
      "z": -2,
      "name": "Soil_Grass"
    },
    {
      "x": -21,
      "y": 0,
      "z": -1,
      "name": "Soil_Clay"
    },
    {
      "x": -21,
      "y": 1,
      "z": -1,
      "name": "Soil_Clay"
    },
    {
      "x": -21,
      "y": 2,
      "z": -1,
      "name": "Soil_Grass"
    },
    {
      "x": -21,
      "y": 0,
      "z": 0,
      "name": "Soil_Clay"
    },
    {
      "x": -21,
      "y": 1,
      "z": 0,
      "name": "Soil_Clay"
    },
    {
      "x": -21,
      "y": 2,
      "z": 0,
      "name": "Soil_Grass"
    },
    {
      "x": -21,
      "y": 0,
      "z": 1,
      "name": "Soil_Clay"
    },
    {
      "x": -21,
      "y": 1,
      "z": 1,
      "name": "Soil_Clay"
    },
    {
      "x": -21,
      "y": 2,
      "z": 1,
      "name": "Soil_Grass"
    },
    {
      "x": -21,
      "y": 0,
      "z": 2,
      "name": "Soil_Clay"
    },
    {
      "x": -21,
      "y": 1,
      "z": 2,
      "name": "Soil_Clay"
    },
    {
      "x": -21,
      "y": 2,
      "z": 2,
      "name": "Soil_Grass"
    },
    {
      "x": -21,
      "y": 0,
      "z": 3,
      "name": "Soil_Clay"
    },
    {
      "x": -21,
      "y": 1,
      "z": 3,
      "name": "Soil_Clay"
    },
    {
      "x": -21,
      "y": 2,
      "z": 3,
      "name": "Soil_Grass"
    },
    {
      "x": -21,
      "y": 0,
      "z": 4,
      "name": "Soil_Clay"
    },
    {
      "x": -21,
      "y": 1,
      "z": 4,
      "name": "Soil_Clay"
    },
    {
      "x": -21,
      "y": 2,
      "z": 4,
      "name": "Soil_Grass"
    },
    {
      "x": -21,
      "y": 0,
      "z": 5,
      "name": "Soil_Clay"
    },
    {
      "x": -21,
      "y": 1,
      "z": 5,
      "name": "Soil_Clay"
    },
    {
      "x": -21,
      "y": 2,
      "z": 5,
      "name": "Soil_Grass"
    },
    {
      "x": -21,
      "y": 0,
      "z": 6,
      "name": "Soil_Clay"
    },
    {
      "x": -21,
      "y": 1,
      "z": 6,
      "name": "Soil_Clay"
    },
    {
      "x": -21,
      "y": 2,
      "z": 6,
      "name": "Soil_Grass"
    },
    {
      "x": -21,
      "y": 0,
      "z": 7,
      "name": "Soil_Clay"
    },
    {
      "x": -21,
      "y": 1,
      "z": 7,
      "name": "Soil_Clay"
    },
    {
      "x": -21,
      "y": 2,
      "z": 7,
      "name": "Soil_Grass"
    },
    {
      "x": -21,
      "y": 0,
      "z": 8,
      "name": "Soil_Clay"
    },
    {
      "x": -21,
      "y": 1,
      "z": 8,
      "name": "Soil_Clay"
    },
    {
      "x": -21,
      "y": 2,
      "z": 8,
      "name": "Soil_Grass"
    },
    {
      "x": -21,
      "y": 0,
      "z": 9,
      "name": "Soil_Clay"
    },
    {
      "x": -21,
      "y": 1,
      "z": 9,
      "name": "Soil_Clay"
    },
    {
      "x": -21,
      "y": 2,
      "z": 9,
      "name": "Soil_Grass"
    },
    {
      "x": -21,
      "y": 0,
      "z": 10,
      "name": "Soil_Clay"
    },
    {
      "x": -21,
      "y": 1,
      "z": 10,
      "name": "Soil_Clay"
    },
    {
      "x": -21,
      "y": 2,
      "z": 10,
      "name": "Soil_Grass"
    },
    {
      "x": -21,
      "y": 0,
      "z": 11,
      "name": "Soil_Clay"
    },
    {
      "x": -21,
      "y": 1,
      "z": 11,
      "name": "Soil_Clay"
    },
    {
      "x": -21,
      "y": 2,
      "z": 11,
      "name": "Soil_Grass"
    },
    {
      "x": -21,
      "y": 0,
      "z": 12,
      "name": "Soil_Clay"
    },
    {
      "x": -21,
      "y": 1,
      "z": 12,
      "name": "Soil_Clay"
    },
    {
      "x": -21,
      "y": 2,
      "z": 12,
      "name": "Soil_Grass"
    },
    {
      "x": -21,
      "y": 0,
      "z": 13,
      "name": "Soil_Clay"
    },
    {
      "x": -21,
      "y": 1,
      "z": 13,
      "name": "Soil_Clay"
    },
    {
      "x": -21,
      "y": 2,
      "z": 13,
      "name": "Soil_Grass"
    },
    {
      "x": -21,
      "y": 0,
      "z": 14,
      "name": "Soil_Clay"
    },
    {
      "x": -21,
      "y": 1,
      "z": 14,
      "name": "Soil_Clay"
    },
    {
      "x": -21,
      "y": 2,
      "z": 14,
      "name": "Soil_Grass"
    },
    {
      "x": -21,
      "y": 0,
      "z": 15,
      "name": "Soil_Clay"
    },
    {
      "x": -21,
      "y": 1,
      "z": 15,
      "name": "Soil_Clay"
    },
    {
      "x": -21,
      "y": 2,
      "z": 15,
      "name": "Soil_Grass"
    },
    {
      "x": -21,
      "y": 0,
      "z": 16,
      "name": "Soil_Clay"
    },
    {
      "x": -21,
      "y": 1,
      "z": 16,
      "name": "Soil_Clay"
    },
    {
      "x": -21,
      "y": 2,
      "z": 16,
      "name": "Soil_Grass"
    },
    {
      "x": -21,
      "y": 0,
      "z": 17,
      "name": "Soil_Clay"
    },
    {
      "x": -21,
      "y": 1,
      "z": 17,
      "name": "Soil_Clay"
    },
    {
      "x": -21,
      "y": 2,
      "z": 17,
      "name": "Soil_Grass"
    },
    {
      "x": -21,
      "y": 0,
      "z": 18,
      "name": "Soil_Clay"
    },
    {
      "x": -21,
      "y": 1,
      "z": 18,
      "name": "Soil_Clay"
    },
    {
      "x": -21,
      "y": 2,
      "z": 18,
      "name": "Soil_Grass"
    },
    {
      "x": -21,
      "y": 0,
      "z": 19,
      "name": "Soil_Clay"
    },
    {
      "x": -21,
      "y": 1,
      "z": 19,
      "name": "Soil_Clay"
    },
    {
      "x": -21,
      "y": 2,
      "z": 19,
      "name": "Soil_Grass"
    },
    {
      "x": -21,
      "y": 0,
      "z": 20,
      "name": "Soil_Clay"
    },
    {
      "x": -21,
      "y": 1,
      "z": 20,
      "name": "Soil_Clay"
    },
    {
      "x": -21,
      "y": 2,
      "z": 20,
      "name": "Soil_Grass"
    },
    {
      "x": -20,
      "y": 0,
      "z": -20,
      "name": "Soil_Clay"
    },
    {
      "x": -20,
      "y": 1,
      "z": -20,
      "name": "Soil_Clay"
    },
    {
      "x": -20,
      "y": 2,
      "z": -20,
      "name": "Soil_Grass"
    },
    {
      "x": -20,
      "y": 0,
      "z": -19,
      "name": "Soil_Clay"
    },
    {
      "x": -20,
      "y": 1,
      "z": -19,
      "name": "Soil_Clay"
    },
    {
      "x": -20,
      "y": 2,
      "z": -19,
      "name": "Soil_Grass"
    },
    {
      "x": -20,
      "y": 0,
      "z": -18,
      "name": "Soil_Clay"
    },
    {
      "x": -20,
      "y": 1,
      "z": -18,
      "name": "Soil_Clay"
    },
    {
      "x": -20,
      "y": 2,
      "z": -18,
      "name": "Soil_Grass"
    },
    {
      "x": -20,
      "y": 0,
      "z": -17,
      "name": "Soil_Clay"
    },
    {
      "x": -20,
      "y": 1,
      "z": -17,
      "name": "Soil_Clay"
    },
    {
      "x": -20,
      "y": 2,
      "z": -17,
      "name": "Soil_Grass"
    },
    {
      "x": -20,
      "y": 0,
      "z": -16,
      "name": "Soil_Clay"
    },
    {
      "x": -20,
      "y": 1,
      "z": -16,
      "name": "Soil_Clay"
    },
    {
      "x": -20,
      "y": 2,
      "z": -16,
      "name": "Soil_Grass"
    },
    {
      "x": -20,
      "y": 0,
      "z": -15,
      "name": "Soil_Clay"
    },
    {
      "x": -20,
      "y": 1,
      "z": -15,
      "name": "Soil_Clay"
    },
    {
      "x": -20,
      "y": 2,
      "z": -15,
      "name": "Soil_Grass"
    },
    {
      "x": -20,
      "y": 0,
      "z": -14,
      "name": "Soil_Clay"
    },
    {
      "x": -20,
      "y": 1,
      "z": -14,
      "name": "Soil_Clay"
    },
    {
      "x": -20,
      "y": 2,
      "z": -14,
      "name": "Soil_Grass"
    },
    {
      "x": -20,
      "y": 0,
      "z": -13,
      "name": "Soil_Clay"
    },
    {
      "x": -20,
      "y": 1,
      "z": -13,
      "name": "Soil_Clay"
    },
    {
      "x": -20,
      "y": 2,
      "z": -13,
      "name": "Soil_Grass"
    },
    {
      "x": -20,
      "y": 0,
      "z": -12,
      "name": "Soil_Clay"
    },
    {
      "x": -20,
      "y": 1,
      "z": -12,
      "name": "Soil_Clay"
    },
    {
      "x": -20,
      "y": 2,
      "z": -12,
      "name": "Soil_Grass"
    },
    {
      "x": -20,
      "y": 0,
      "z": -11,
      "name": "Soil_Clay"
    },
    {
      "x": -20,
      "y": 1,
      "z": -11,
      "name": "Soil_Clay"
    },
    {
      "x": -20,
      "y": 2,
      "z": -11,
      "name": "Soil_Grass"
    },
    {
      "x": -20,
      "y": 0,
      "z": -10,
      "name": "Soil_Clay"
    },
    {
      "x": -20,
      "y": 1,
      "z": -10,
      "name": "Soil_Clay"
    },
    {
      "x": -20,
      "y": 2,
      "z": -10,
      "name": "Soil_Grass"
    },
    {
      "x": -20,
      "y": 0,
      "z": -9,
      "name": "Soil_Clay"
    },
    {
      "x": -20,
      "y": 1,
      "z": -9,
      "name": "Soil_Clay"
    },
    {
      "x": -20,
      "y": 2,
      "z": -9,
      "name": "Soil_Grass"
    },
    {
      "x": -20,
      "y": 0,
      "z": -8,
      "name": "Soil_Clay"
    },
    {
      "x": -20,
      "y": 1,
      "z": -8,
      "name": "Soil_Clay"
    },
    {
      "x": -20,
      "y": 2,
      "z": -8,
      "name": "Soil_Grass"
    },
    {
      "x": -20,
      "y": 0,
      "z": -7,
      "name": "Soil_Clay"
    },
    {
      "x": -20,
      "y": 1,
      "z": -7,
      "name": "Soil_Clay"
    },
    {
      "x": -20,
      "y": 2,
      "z": -7,
      "name": "Soil_Grass"
    },
    {
      "x": -20,
      "y": 0,
      "z": -6,
      "name": "Soil_Clay"
    },
    {
      "x": -20,
      "y": 1,
      "z": -6,
      "name": "Soil_Clay"
    },
    {
      "x": -20,
      "y": 2,
      "z": -6,
      "name": "Soil_Grass"
    },
    {
      "x": -20,
      "y": 0,
      "z": -5,
      "name": "Soil_Clay"
    },
    {
      "x": -20,
      "y": 1,
      "z": -5,
      "name": "Soil_Clay"
    },
    {
      "x": -20,
      "y": 2,
      "z": -5,
      "name": "Soil_Grass"
    },
    {
      "x": -20,
      "y": 0,
      "z": -4,
      "name": "Soil_Clay"
    },
    {
      "x": -20,
      "y": 1,
      "z": -4,
      "name": "Soil_Clay"
    },
    {
      "x": -20,
      "y": 2,
      "z": -4,
      "name": "Soil_Grass"
    },
    {
      "x": -20,
      "y": 0,
      "z": -3,
      "name": "Soil_Clay"
    },
    {
      "x": -20,
      "y": 1,
      "z": -3,
      "name": "Soil_Clay"
    },
    {
      "x": -20,
      "y": 2,
      "z": -3,
      "name": "Soil_Grass"
    },
    {
      "x": -20,
      "y": 0,
      "z": -2,
      "name": "Soil_Clay"
    },
    {
      "x": -20,
      "y": 1,
      "z": -2,
      "name": "Soil_Clay"
    },
    {
      "x": -20,
      "y": 2,
      "z": -2,
      "name": "Soil_Grass"
    },
    {
      "x": -20,
      "y": 0,
      "z": -1,
      "name": "Soil_Clay"
    },
    {
      "x": -20,
      "y": 1,
      "z": -1,
      "name": "Soil_Clay"
    },
    {
      "x": -20,
      "y": 2,
      "z": -1,
      "name": "Soil_Grass"
    },
    {
      "x": -20,
      "y": 0,
      "z": 0,
      "name": "Soil_Clay"
    },
    {
      "x": -20,
      "y": 1,
      "z": 0,
      "name": "Soil_Clay"
    },
    {
      "x": -20,
      "y": 2,
      "z": 0,
      "name": "Soil_Grass"
    },
    {
      "x": -20,
      "y": 0,
      "z": 1,
      "name": "Soil_Clay"
    },
    {
      "x": -20,
      "y": 1,
      "z": 1,
      "name": "Soil_Clay"
    },
    {
      "x": -20,
      "y": 2,
      "z": 1,
      "name": "Soil_Grass"
    },
    {
      "x": -20,
      "y": 0,
      "z": 2,
      "name": "Soil_Clay"
    },
    {
      "x": -20,
      "y": 1,
      "z": 2,
      "name": "Soil_Clay"
    },
    {
      "x": -20,
      "y": 2,
      "z": 2,
      "name": "Soil_Grass"
    },
    {
      "x": -20,
      "y": 0,
      "z": 3,
      "name": "Soil_Clay"
    },
    {
      "x": -20,
      "y": 1,
      "z": 3,
      "name": "Soil_Clay"
    },
    {
      "x": -20,
      "y": 2,
      "z": 3,
      "name": "Soil_Grass"
    },
    {
      "x": -20,
      "y": 0,
      "z": 4,
      "name": "Soil_Clay"
    },
    {
      "x": -20,
      "y": 1,
      "z": 4,
      "name": "Soil_Clay"
    },
    {
      "x": -20,
      "y": 2,
      "z": 4,
      "name": "Soil_Grass"
    },
    {
      "x": -20,
      "y": 0,
      "z": 5,
      "name": "Soil_Clay"
    },
    {
      "x": -20,
      "y": 1,
      "z": 5,
      "name": "Soil_Clay"
    },
    {
      "x": -20,
      "y": 2,
      "z": 5,
      "name": "Soil_Grass"
    },
    {
      "x": -20,
      "y": 0,
      "z": 6,
      "name": "Soil_Clay"
    },
    {
      "x": -20,
      "y": 1,
      "z": 6,
      "name": "Soil_Clay"
    },
    {
      "x": -20,
      "y": 2,
      "z": 6,
      "name": "Soil_Grass"
    },
    {
      "x": -20,
      "y": 0,
      "z": 7,
      "name": "Soil_Clay"
    },
    {
      "x": -20,
      "y": 1,
      "z": 7,
      "name": "Soil_Clay"
    },
    {
      "x": -20,
      "y": 2,
      "z": 7,
      "name": "Soil_Grass"
    },
    {
      "x": -20,
      "y": 0,
      "z": 8,
      "name": "Soil_Clay"
    },
    {
      "x": -20,
      "y": 1,
      "z": 8,
      "name": "Soil_Clay"
    },
    {
      "x": -20,
      "y": 2,
      "z": 8,
      "name": "Soil_Grass"
    },
    {
      "x": -20,
      "y": 0,
      "z": 9,
      "name": "Soil_Clay"
    },
    {
      "x": -20,
      "y": 1,
      "z": 9,
      "name": "Soil_Clay"
    },
    {
      "x": -20,
      "y": 2,
      "z": 9,
      "name": "Soil_Grass"
    },
    {
      "x": -20,
      "y": 0,
      "z": 10,
      "name": "Soil_Clay"
    },
    {
      "x": -20,
      "y": 1,
      "z": 10,
      "name": "Soil_Clay"
    },
    {
      "x": -20,
      "y": 2,
      "z": 10,
      "name": "Soil_Grass"
    },
    {
      "x": -20,
      "y": 0,
      "z": 11,
      "name": "Soil_Clay"
    },
    {
      "x": -20,
      "y": 1,
      "z": 11,
      "name": "Soil_Clay"
    },
    {
      "x": -20,
      "y": 2,
      "z": 11,
      "name": "Soil_Grass"
    },
    {
      "x": -20,
      "y": 0,
      "z": 12,
      "name": "Soil_Clay"
    },
    {
      "x": -20,
      "y": 1,
      "z": 12,
      "name": "Soil_Clay"
    },
    {
      "x": -20,
      "y": 2,
      "z": 12,
      "name": "Soil_Grass"
    },
    {
      "x": -20,
      "y": 0,
      "z": 13,
      "name": "Soil_Clay"
    },
    {
      "x": -20,
      "y": 1,
      "z": 13,
      "name": "Soil_Clay"
    },
    {
      "x": -20,
      "y": 2,
      "z": 13,
      "name": "Soil_Grass"
    },
    {
      "x": -20,
      "y": 0,
      "z": 14,
      "name": "Soil_Clay"
    },
    {
      "x": -20,
      "y": 1,
      "z": 14,
      "name": "Soil_Clay"
    },
    {
      "x": -20,
      "y": 2,
      "z": 14,
      "name": "Soil_Grass"
    },
    {
      "x": -20,
      "y": 0,
      "z": 15,
      "name": "Soil_Clay"
    },
    {
      "x": -20,
      "y": 1,
      "z": 15,
      "name": "Soil_Clay"
    },
    {
      "x": -20,
      "y": 2,
      "z": 15,
      "name": "Soil_Grass"
    },
    {
      "x": -20,
      "y": 0,
      "z": 16,
      "name": "Soil_Clay"
    },
    {
      "x": -20,
      "y": 1,
      "z": 16,
      "name": "Soil_Clay"
    },
    {
      "x": -20,
      "y": 2,
      "z": 16,
      "name": "Soil_Grass"
    },
    {
      "x": -20,
      "y": 0,
      "z": 17,
      "name": "Soil_Clay"
    },
    {
      "x": -20,
      "y": 1,
      "z": 17,
      "name": "Soil_Clay"
    },
    {
      "x": -20,
      "y": 2,
      "z": 17,
      "name": "Soil_Grass"
    },
    {
      "x": -20,
      "y": 0,
      "z": 18,
      "name": "Soil_Clay"
    },
    {
      "x": -20,
      "y": 1,
      "z": 18,
      "name": "Soil_Clay"
    },
    {
      "x": -20,
      "y": 2,
      "z": 18,
      "name": "Soil_Grass"
    },
    {
      "x": -20,
      "y": 0,
      "z": 19,
      "name": "Soil_Clay"
    },
    {
      "x": -20,
      "y": 1,
      "z": 19,
      "name": "Soil_Clay"
    },
    {
      "x": -20,
      "y": 2,
      "z": 19,
      "name": "Soil_Grass"
    },
    {
      "x": -20,
      "y": 0,
      "z": 20,
      "name": "Soil_Clay"
    },
    {
      "x": -20,
      "y": 1,
      "z": 20,
      "name": "Soil_Clay"
    },
    {
      "x": -20,
      "y": 2,
      "z": 20,
      "name": "Soil_Grass"
    },
    {
      "x": -19,
      "y": 0,
      "z": -20,
      "name": "Soil_Clay"
    },
    {
      "x": -19,
      "y": 1,
      "z": -20,
      "name": "Soil_Clay"
    },
    {
      "x": -19,
      "y": 2,
      "z": -20,
      "name": "Soil_Grass"
    },
    {
      "x": -19,
      "y": 0,
      "z": -19,
      "name": "Soil_Clay"
    },
    {
      "x": -19,
      "y": 1,
      "z": -19,
      "name": "Soil_Clay"
    },
    {
      "x": -19,
      "y": 2,
      "z": -19,
      "name": "Soil_Grass"
    },
    {
      "x": -19,
      "y": 0,
      "z": -18,
      "name": "Soil_Clay"
    },
    {
      "x": -19,
      "y": 1,
      "z": -18,
      "name": "Soil_Clay"
    },
    {
      "x": -19,
      "y": 2,
      "z": -18,
      "name": "Soil_Grass"
    },
    {
      "x": -19,
      "y": 0,
      "z": -17,
      "name": "Soil_Clay"
    },
    {
      "x": -19,
      "y": 1,
      "z": -17,
      "name": "Soil_Clay"
    },
    {
      "x": -19,
      "y": 2,
      "z": -17,
      "name": "Soil_Grass"
    },
    {
      "x": -19,
      "y": 0,
      "z": -16,
      "name": "Soil_Clay"
    },
    {
      "x": -19,
      "y": 1,
      "z": -16,
      "name": "Soil_Clay"
    },
    {
      "x": -19,
      "y": 2,
      "z": -16,
      "name": "Soil_Grass"
    },
    {
      "x": -19,
      "y": 0,
      "z": -15,
      "name": "Soil_Clay"
    },
    {
      "x": -19,
      "y": 1,
      "z": -15,
      "name": "Soil_Clay"
    },
    {
      "x": -19,
      "y": 2,
      "z": -15,
      "name": "Soil_Grass"
    },
    {
      "x": -19,
      "y": 0,
      "z": -14,
      "name": "Soil_Clay"
    },
    {
      "x": -19,
      "y": 1,
      "z": -14,
      "name": "Soil_Clay"
    },
    {
      "x": -19,
      "y": 2,
      "z": -14,
      "name": "Soil_Grass"
    },
    {
      "x": -19,
      "y": 0,
      "z": -13,
      "name": "Soil_Clay"
    },
    {
      "x": -19,
      "y": 1,
      "z": -13,
      "name": "Soil_Clay"
    },
    {
      "x": -19,
      "y": 2,
      "z": -13,
      "name": "Soil_Grass"
    },
    {
      "x": -19,
      "y": 0,
      "z": -12,
      "name": "Soil_Clay"
    },
    {
      "x": -19,
      "y": 1,
      "z": -12,
      "name": "Soil_Clay"
    },
    {
      "x": -19,
      "y": 2,
      "z": -12,
      "name": "Soil_Grass"
    },
    {
      "x": -19,
      "y": 0,
      "z": -11,
      "name": "Soil_Clay"
    },
    {
      "x": -19,
      "y": 1,
      "z": -11,
      "name": "Soil_Clay"
    },
    {
      "x": -19,
      "y": 2,
      "z": -11,
      "name": "Soil_Grass"
    },
    {
      "x": -19,
      "y": 0,
      "z": -10,
      "name": "Soil_Clay"
    },
    {
      "x": -19,
      "y": 1,
      "z": -10,
      "name": "Soil_Clay"
    },
    {
      "x": -19,
      "y": 2,
      "z": -10,
      "name": "Soil_Grass"
    },
    {
      "x": -19,
      "y": 0,
      "z": -9,
      "name": "Soil_Clay"
    },
    {
      "x": -19,
      "y": 1,
      "z": -9,
      "name": "Soil_Clay"
    },
    {
      "x": -19,
      "y": 2,
      "z": -9,
      "name": "Soil_Grass"
    },
    {
      "x": -19,
      "y": 0,
      "z": -8,
      "name": "Soil_Clay"
    },
    {
      "x": -19,
      "y": 1,
      "z": -8,
      "name": "Soil_Clay"
    },
    {
      "x": -19,
      "y": 2,
      "z": -8,
      "name": "Soil_Grass"
    },
    {
      "x": -19,
      "y": 0,
      "z": -7,
      "name": "Soil_Clay"
    },
    {
      "x": -19,
      "y": 1,
      "z": -7,
      "name": "Soil_Clay"
    },
    {
      "x": -19,
      "y": 2,
      "z": -7,
      "name": "Soil_Grass"
    },
    {
      "x": -19,
      "y": 0,
      "z": -6,
      "name": "Soil_Clay"
    },
    {
      "x": -19,
      "y": 1,
      "z": -6,
      "name": "Soil_Clay"
    },
    {
      "x": -19,
      "y": 2,
      "z": -6,
      "name": "Soil_Grass"
    },
    {
      "x": -19,
      "y": 0,
      "z": -5,
      "name": "Soil_Clay"
    },
    {
      "x": -19,
      "y": 1,
      "z": -5,
      "name": "Soil_Clay"
    },
    {
      "x": -19,
      "y": 2,
      "z": -5,
      "name": "Soil_Grass"
    },
    {
      "x": -19,
      "y": 3,
      "z": -5,
      "name": "Soil_Dirt_Half"
    },
    {
      "x": -19,
      "y": 0,
      "z": -4,
      "name": "Soil_Clay"
    },
    {
      "x": -19,
      "y": 1,
      "z": -4,
      "name": "Soil_Clay"
    },
    {
      "x": -19,
      "y": 2,
      "z": -4,
      "name": "Soil_Grass"
    },
    {
      "x": -19,
      "y": 3,
      "z": -4,
      "name": "Soil_Dirt_Half"
    },
    {
      "x": -19,
      "y": 0,
      "z": -3,
      "name": "Soil_Clay"
    },
    {
      "x": -19,
      "y": 1,
      "z": -3,
      "name": "Soil_Clay"
    },
    {
      "x": -19,
      "y": 2,
      "z": -3,
      "name": "Soil_Grass"
    },
    {
      "x": -19,
      "y": 3,
      "z": -3,
      "name": "Soil_Dirt_Half"
    },
    {
      "x": -19,
      "y": 0,
      "z": -2,
      "name": "Soil_Clay"
    },
    {
      "x": -19,
      "y": 1,
      "z": -2,
      "name": "Soil_Clay"
    },
    {
      "x": -19,
      "y": 2,
      "z": -2,
      "name": "Soil_Grass"
    },
    {
      "x": -19,
      "y": 3,
      "z": -2,
      "name": "Soil_Dirt_Half"
    },
    {
      "x": -19,
      "y": 0,
      "z": -1,
      "name": "Soil_Clay"
    },
    {
      "x": -19,
      "y": 1,
      "z": -1,
      "name": "Soil_Clay"
    },
    {
      "x": -19,
      "y": 2,
      "z": -1,
      "name": "Soil_Grass"
    },
    {
      "x": -19,
      "y": 3,
      "z": -1,
      "name": "Soil_Dirt_Half"
    },
    {
      "x": -19,
      "y": 0,
      "z": 0,
      "name": "Soil_Clay"
    },
    {
      "x": -19,
      "y": 1,
      "z": 0,
      "name": "Soil_Clay"
    },
    {
      "x": -19,
      "y": 2,
      "z": 0,
      "name": "Soil_Grass"
    },
    {
      "x": -19,
      "y": 3,
      "z": 0,
      "name": "Soil_Dirt_Half"
    },
    {
      "x": -19,
      "y": 0,
      "z": 1,
      "name": "Soil_Clay"
    },
    {
      "x": -19,
      "y": 1,
      "z": 1,
      "name": "Soil_Clay"
    },
    {
      "x": -19,
      "y": 2,
      "z": 1,
      "name": "Soil_Grass"
    },
    {
      "x": -19,
      "y": 3,
      "z": 1,
      "name": "Soil_Dirt_Half"
    },
    {
      "x": -19,
      "y": 0,
      "z": 2,
      "name": "Soil_Clay"
    },
    {
      "x": -19,
      "y": 1,
      "z": 2,
      "name": "Soil_Clay"
    },
    {
      "x": -19,
      "y": 2,
      "z": 2,
      "name": "Soil_Grass"
    },
    {
      "x": -19,
      "y": 3,
      "z": 2,
      "name": "Soil_Dirt_Half"
    },
    {
      "x": -19,
      "y": 0,
      "z": 3,
      "name": "Soil_Clay"
    },
    {
      "x": -19,
      "y": 1,
      "z": 3,
      "name": "Soil_Clay"
    },
    {
      "x": -19,
      "y": 2,
      "z": 3,
      "name": "Soil_Grass"
    },
    {
      "x": -19,
      "y": 3,
      "z": 3,
      "name": "Soil_Dirt_Half"
    },
    {
      "x": -19,
      "y": 0,
      "z": 4,
      "name": "Soil_Clay"
    },
    {
      "x": -19,
      "y": 1,
      "z": 4,
      "name": "Soil_Clay"
    },
    {
      "x": -19,
      "y": 2,
      "z": 4,
      "name": "Soil_Grass"
    },
    {
      "x": -19,
      "y": 3,
      "z": 4,
      "name": "Soil_Dirt_Half"
    },
    {
      "x": -19,
      "y": 0,
      "z": 5,
      "name": "Soil_Clay"
    },
    {
      "x": -19,
      "y": 1,
      "z": 5,
      "name": "Soil_Clay"
    },
    {
      "x": -19,
      "y": 2,
      "z": 5,
      "name": "Soil_Grass"
    },
    {
      "x": -19,
      "y": 0,
      "z": 6,
      "name": "Soil_Clay"
    },
    {
      "x": -19,
      "y": 1,
      "z": 6,
      "name": "Soil_Clay"
    },
    {
      "x": -19,
      "y": 2,
      "z": 6,
      "name": "Soil_Grass"
    },
    {
      "x": -19,
      "y": 0,
      "z": 7,
      "name": "Soil_Clay"
    },
    {
      "x": -19,
      "y": 1,
      "z": 7,
      "name": "Soil_Clay"
    },
    {
      "x": -19,
      "y": 2,
      "z": 7,
      "name": "Soil_Grass"
    },
    {
      "x": -19,
      "y": 0,
      "z": 8,
      "name": "Soil_Clay"
    },
    {
      "x": -19,
      "y": 1,
      "z": 8,
      "name": "Soil_Clay"
    },
    {
      "x": -19,
      "y": 2,
      "z": 8,
      "name": "Soil_Grass"
    },
    {
      "x": -19,
      "y": 0,
      "z": 9,
      "name": "Soil_Clay"
    },
    {
      "x": -19,
      "y": 1,
      "z": 9,
      "name": "Soil_Clay"
    },
    {
      "x": -19,
      "y": 2,
      "z": 9,
      "name": "Soil_Grass"
    },
    {
      "x": -19,
      "y": 0,
      "z": 10,
      "name": "Soil_Clay"
    },
    {
      "x": -19,
      "y": 1,
      "z": 10,
      "name": "Soil_Clay"
    },
    {
      "x": -19,
      "y": 2,
      "z": 10,
      "name": "Soil_Grass"
    },
    {
      "x": -19,
      "y": 0,
      "z": 11,
      "name": "Soil_Clay"
    },
    {
      "x": -19,
      "y": 1,
      "z": 11,
      "name": "Soil_Clay"
    },
    {
      "x": -19,
      "y": 2,
      "z": 11,
      "name": "Soil_Grass"
    },
    {
      "x": -19,
      "y": 0,
      "z": 12,
      "name": "Soil_Clay"
    },
    {
      "x": -19,
      "y": 1,
      "z": 12,
      "name": "Soil_Clay"
    },
    {
      "x": -19,
      "y": 2,
      "z": 12,
      "name": "Soil_Grass"
    },
    {
      "x": -19,
      "y": 0,
      "z": 13,
      "name": "Soil_Clay"
    },
    {
      "x": -19,
      "y": 1,
      "z": 13,
      "name": "Soil_Clay"
    },
    {
      "x": -19,
      "y": 2,
      "z": 13,
      "name": "Soil_Grass"
    },
    {
      "x": -19,
      "y": 0,
      "z": 14,
      "name": "Soil_Clay"
    },
    {
      "x": -19,
      "y": 1,
      "z": 14,
      "name": "Soil_Clay"
    },
    {
      "x": -19,
      "y": 2,
      "z": 14,
      "name": "Soil_Grass"
    },
    {
      "x": -19,
      "y": 0,
      "z": 15,
      "name": "Soil_Clay"
    },
    {
      "x": -19,
      "y": 1,
      "z": 15,
      "name": "Soil_Clay"
    },
    {
      "x": -19,
      "y": 2,
      "z": 15,
      "name": "Soil_Grass"
    },
    {
      "x": -19,
      "y": 0,
      "z": 16,
      "name": "Soil_Clay"
    },
    {
      "x": -19,
      "y": 1,
      "z": 16,
      "name": "Soil_Clay"
    },
    {
      "x": -19,
      "y": 2,
      "z": 16,
      "name": "Soil_Grass"
    },
    {
      "x": -19,
      "y": 0,
      "z": 17,
      "name": "Soil_Clay"
    },
    {
      "x": -19,
      "y": 1,
      "z": 17,
      "name": "Soil_Clay"
    },
    {
      "x": -19,
      "y": 2,
      "z": 17,
      "name": "Soil_Grass"
    },
    {
      "x": -19,
      "y": 0,
      "z": 18,
      "name": "Soil_Clay"
    },
    {
      "x": -19,
      "y": 1,
      "z": 18,
      "name": "Soil_Clay"
    },
    {
      "x": -19,
      "y": 2,
      "z": 18,
      "name": "Soil_Grass"
    },
    {
      "x": -19,
      "y": 0,
      "z": 19,
      "name": "Soil_Clay"
    },
    {
      "x": -19,
      "y": 1,
      "z": 19,
      "name": "Soil_Clay"
    },
    {
      "x": -19,
      "y": 2,
      "z": 19,
      "name": "Soil_Grass"
    },
    {
      "x": -19,
      "y": 0,
      "z": 20,
      "name": "Soil_Clay"
    },
    {
      "x": -19,
      "y": 1,
      "z": 20,
      "name": "Soil_Clay"
    },
    {
      "x": -19,
      "y": 2,
      "z": 20,
      "name": "Soil_Grass"
    },
    {
      "x": -18,
      "y": 0,
      "z": -20,
      "name": "Soil_Clay"
    },
    {
      "x": -18,
      "y": 1,
      "z": -20,
      "name": "Soil_Clay"
    },
    {
      "x": -18,
      "y": 2,
      "z": -20,
      "name": "Soil_Grass"
    },
    {
      "x": -18,
      "y": 0,
      "z": -19,
      "name": "Soil_Clay"
    },
    {
      "x": -18,
      "y": 1,
      "z": -19,
      "name": "Soil_Clay"
    },
    {
      "x": -18,
      "y": 2,
      "z": -19,
      "name": "Soil_Grass"
    },
    {
      "x": -18,
      "y": 0,
      "z": -18,
      "name": "Soil_Clay"
    },
    {
      "x": -18,
      "y": 1,
      "z": -18,
      "name": "Soil_Clay"
    },
    {
      "x": -18,
      "y": 2,
      "z": -18,
      "name": "Soil_Grass"
    },
    {
      "x": -18,
      "y": 0,
      "z": -17,
      "name": "Soil_Clay"
    },
    {
      "x": -18,
      "y": 1,
      "z": -17,
      "name": "Soil_Clay"
    },
    {
      "x": -18,
      "y": 2,
      "z": -17,
      "name": "Soil_Grass"
    },
    {
      "x": -18,
      "y": 0,
      "z": -16,
      "name": "Soil_Clay"
    },
    {
      "x": -18,
      "y": 1,
      "z": -16,
      "name": "Soil_Clay"
    },
    {
      "x": -18,
      "y": 2,
      "z": -16,
      "name": "Soil_Grass"
    },
    {
      "x": -18,
      "y": 0,
      "z": -15,
      "name": "Soil_Clay"
    },
    {
      "x": -18,
      "y": 1,
      "z": -15,
      "name": "Soil_Clay"
    },
    {
      "x": -18,
      "y": 2,
      "z": -15,
      "name": "Soil_Grass"
    },
    {
      "x": -18,
      "y": 0,
      "z": -14,
      "name": "Soil_Clay"
    },
    {
      "x": -18,
      "y": 1,
      "z": -14,
      "name": "Soil_Clay"
    },
    {
      "x": -18,
      "y": 2,
      "z": -14,
      "name": "Soil_Grass"
    },
    {
      "x": -18,
      "y": 0,
      "z": -13,
      "name": "Soil_Clay"
    },
    {
      "x": -18,
      "y": 1,
      "z": -13,
      "name": "Soil_Clay"
    },
    {
      "x": -18,
      "y": 2,
      "z": -13,
      "name": "Soil_Grass"
    },
    {
      "x": -18,
      "y": 0,
      "z": -12,
      "name": "Soil_Clay"
    },
    {
      "x": -18,
      "y": 1,
      "z": -12,
      "name": "Soil_Clay"
    },
    {
      "x": -18,
      "y": 2,
      "z": -12,
      "name": "Soil_Grass"
    },
    {
      "x": -18,
      "y": 0,
      "z": -11,
      "name": "Soil_Clay"
    },
    {
      "x": -18,
      "y": 1,
      "z": -11,
      "name": "Soil_Clay"
    },
    {
      "x": -18,
      "y": 2,
      "z": -11,
      "name": "Soil_Grass"
    },
    {
      "x": -18,
      "y": 0,
      "z": -10,
      "name": "Soil_Clay"
    },
    {
      "x": -18,
      "y": 1,
      "z": -10,
      "name": "Soil_Clay"
    },
    {
      "x": -18,
      "y": 2,
      "z": -10,
      "name": "Soil_Grass"
    },
    {
      "x": -18,
      "y": 0,
      "z": -9,
      "name": "Soil_Clay"
    },
    {
      "x": -18,
      "y": 1,
      "z": -9,
      "name": "Soil_Clay"
    },
    {
      "x": -18,
      "y": 2,
      "z": -9,
      "name": "Soil_Grass"
    },
    {
      "x": -18,
      "y": 0,
      "z": -8,
      "name": "Soil_Clay"
    },
    {
      "x": -18,
      "y": 1,
      "z": -8,
      "name": "Soil_Clay"
    },
    {
      "x": -18,
      "y": 2,
      "z": -8,
      "name": "Soil_Grass"
    },
    {
      "x": -18,
      "y": 0,
      "z": -7,
      "name": "Soil_Clay"
    },
    {
      "x": -18,
      "y": 1,
      "z": -7,
      "name": "Soil_Clay"
    },
    {
      "x": -18,
      "y": 2,
      "z": -7,
      "name": "Soil_Grass"
    },
    {
      "x": -18,
      "y": 0,
      "z": -6,
      "name": "Soil_Clay"
    },
    {
      "x": -18,
      "y": 1,
      "z": -6,
      "name": "Soil_Clay"
    },
    {
      "x": -18,
      "y": 2,
      "z": -6,
      "name": "Soil_Grass"
    },
    {
      "x": -18,
      "y": 0,
      "z": -5,
      "name": "Soil_Clay"
    },
    {
      "x": -18,
      "y": 1,
      "z": -5,
      "name": "Soil_Clay"
    },
    {
      "x": -18,
      "y": 2,
      "z": -5,
      "name": "Soil_Grass"
    },
    {
      "x": -18,
      "y": 3,
      "z": -5,
      "name": "Soil_Dirt"
    },
    {
      "x": -18,
      "y": 0,
      "z": -4,
      "name": "Soil_Clay"
    },
    {
      "x": -18,
      "y": 1,
      "z": -4,
      "name": "Soil_Clay"
    },
    {
      "x": -18,
      "y": 2,
      "z": -4,
      "name": "Soil_Grass"
    },
    {
      "x": -18,
      "y": 3,
      "z": -4,
      "name": "Soil_Dirt"
    },
    {
      "x": -18,
      "y": 0,
      "z": -3,
      "name": "Soil_Clay"
    },
    {
      "x": -18,
      "y": 1,
      "z": -3,
      "name": "Soil_Clay"
    },
    {
      "x": -18,
      "y": 2,
      "z": -3,
      "name": "Soil_Grass"
    },
    {
      "x": -18,
      "y": 3,
      "z": -3,
      "name": "Soil_Dirt"
    },
    {
      "x": -18,
      "y": 0,
      "z": -2,
      "name": "Soil_Clay"
    },
    {
      "x": -18,
      "y": 1,
      "z": -2,
      "name": "Soil_Clay"
    },
    {
      "x": -18,
      "y": 2,
      "z": -2,
      "name": "Soil_Grass"
    },
    {
      "x": -18,
      "y": 3,
      "z": -2,
      "name": "Soil_Dirt"
    },
    {
      "x": -18,
      "y": 0,
      "z": -1,
      "name": "Soil_Clay"
    },
    {
      "x": -18,
      "y": 1,
      "z": -1,
      "name": "Soil_Clay"
    },
    {
      "x": -18,
      "y": 2,
      "z": -1,
      "name": "Soil_Grass"
    },
    {
      "x": -18,
      "y": 3,
      "z": -1,
      "name": "Soil_Dirt"
    },
    {
      "x": -18,
      "y": 0,
      "z": 0,
      "name": "Soil_Clay"
    },
    {
      "x": -18,
      "y": 1,
      "z": 0,
      "name": "Soil_Clay"
    },
    {
      "x": -18,
      "y": 2,
      "z": 0,
      "name": "Soil_Grass"
    },
    {
      "x": -18,
      "y": 3,
      "z": 0,
      "name": "Soil_Dirt"
    },
    {
      "x": -18,
      "y": 0,
      "z": 1,
      "name": "Soil_Clay"
    },
    {
      "x": -18,
      "y": 1,
      "z": 1,
      "name": "Soil_Clay"
    },
    {
      "x": -18,
      "y": 2,
      "z": 1,
      "name": "Soil_Grass"
    },
    {
      "x": -18,
      "y": 3,
      "z": 1,
      "name": "Soil_Dirt"
    },
    {
      "x": -18,
      "y": 0,
      "z": 2,
      "name": "Soil_Clay"
    },
    {
      "x": -18,
      "y": 1,
      "z": 2,
      "name": "Soil_Clay"
    },
    {
      "x": -18,
      "y": 2,
      "z": 2,
      "name": "Soil_Grass"
    },
    {
      "x": -18,
      "y": 3,
      "z": 2,
      "name": "Soil_Dirt"
    },
    {
      "x": -18,
      "y": 0,
      "z": 3,
      "name": "Soil_Clay"
    },
    {
      "x": -18,
      "y": 1,
      "z": 3,
      "name": "Soil_Clay"
    },
    {
      "x": -18,
      "y": 2,
      "z": 3,
      "name": "Soil_Grass"
    },
    {
      "x": -18,
      "y": 3,
      "z": 3,
      "name": "Soil_Dirt"
    },
    {
      "x": -18,
      "y": 0,
      "z": 4,
      "name": "Soil_Clay"
    },
    {
      "x": -18,
      "y": 1,
      "z": 4,
      "name": "Soil_Clay"
    },
    {
      "x": -18,
      "y": 2,
      "z": 4,
      "name": "Soil_Grass"
    },
    {
      "x": -18,
      "y": 3,
      "z": 4,
      "name": "Soil_Dirt"
    },
    {
      "x": -18,
      "y": 0,
      "z": 5,
      "name": "Soil_Clay"
    },
    {
      "x": -18,
      "y": 1,
      "z": 5,
      "name": "Soil_Clay"
    },
    {
      "x": -18,
      "y": 2,
      "z": 5,
      "name": "Soil_Grass"
    },
    {
      "x": -18,
      "y": 0,
      "z": 6,
      "name": "Soil_Clay"
    },
    {
      "x": -18,
      "y": 1,
      "z": 6,
      "name": "Soil_Clay"
    },
    {
      "x": -18,
      "y": 2,
      "z": 6,
      "name": "Soil_Grass"
    },
    {
      "x": -18,
      "y": 0,
      "z": 7,
      "name": "Soil_Clay"
    },
    {
      "x": -18,
      "y": 1,
      "z": 7,
      "name": "Soil_Clay"
    },
    {
      "x": -18,
      "y": 2,
      "z": 7,
      "name": "Soil_Grass"
    },
    {
      "x": -18,
      "y": 0,
      "z": 8,
      "name": "Soil_Clay"
    },
    {
      "x": -18,
      "y": 1,
      "z": 8,
      "name": "Soil_Clay"
    },
    {
      "x": -18,
      "y": 2,
      "z": 8,
      "name": "Soil_Grass"
    },
    {
      "x": -18,
      "y": 0,
      "z": 9,
      "name": "Soil_Clay"
    },
    {
      "x": -18,
      "y": 1,
      "z": 9,
      "name": "Soil_Clay"
    },
    {
      "x": -18,
      "y": 2,
      "z": 9,
      "name": "Soil_Grass"
    },
    {
      "x": -18,
      "y": 0,
      "z": 10,
      "name": "Soil_Clay"
    },
    {
      "x": -18,
      "y": 1,
      "z": 10,
      "name": "Soil_Clay"
    },
    {
      "x": -18,
      "y": 2,
      "z": 10,
      "name": "Soil_Grass"
    },
    {
      "x": -18,
      "y": 0,
      "z": 11,
      "name": "Soil_Clay"
    },
    {
      "x": -18,
      "y": 1,
      "z": 11,
      "name": "Soil_Clay"
    },
    {
      "x": -18,
      "y": 2,
      "z": 11,
      "name": "Soil_Grass"
    },
    {
      "x": -18,
      "y": 0,
      "z": 12,
      "name": "Soil_Clay"
    },
    {
      "x": -18,
      "y": 1,
      "z": 12,
      "name": "Soil_Clay"
    },
    {
      "x": -18,
      "y": 2,
      "z": 12,
      "name": "Soil_Grass"
    },
    {
      "x": -18,
      "y": 0,
      "z": 13,
      "name": "Soil_Clay"
    },
    {
      "x": -18,
      "y": 1,
      "z": 13,
      "name": "Soil_Clay"
    },
    {
      "x": -18,
      "y": 2,
      "z": 13,
      "name": "Soil_Grass"
    },
    {
      "x": -18,
      "y": 0,
      "z": 14,
      "name": "Soil_Clay"
    },
    {
      "x": -18,
      "y": 1,
      "z": 14,
      "name": "Soil_Clay"
    },
    {
      "x": -18,
      "y": 2,
      "z": 14,
      "name": "Soil_Grass"
    },
    {
      "x": -18,
      "y": 0,
      "z": 15,
      "name": "Soil_Clay"
    },
    {
      "x": -18,
      "y": 1,
      "z": 15,
      "name": "Soil_Clay"
    },
    {
      "x": -18,
      "y": 2,
      "z": 15,
      "name": "Soil_Grass"
    },
    {
      "x": -18,
      "y": 0,
      "z": 16,
      "name": "Soil_Clay"
    },
    {
      "x": -18,
      "y": 1,
      "z": 16,
      "name": "Soil_Clay"
    },
    {
      "x": -18,
      "y": 2,
      "z": 16,
      "name": "Soil_Grass"
    },
    {
      "x": -18,
      "y": 0,
      "z": 17,
      "name": "Soil_Clay"
    },
    {
      "x": -18,
      "y": 1,
      "z": 17,
      "name": "Soil_Clay"
    },
    {
      "x": -18,
      "y": 2,
      "z": 17,
      "name": "Soil_Grass"
    },
    {
      "x": -18,
      "y": 0,
      "z": 18,
      "name": "Soil_Clay"
    },
    {
      "x": -18,
      "y": 1,
      "z": 18,
      "name": "Soil_Clay"
    },
    {
      "x": -18,
      "y": 2,
      "z": 18,
      "name": "Soil_Grass"
    },
    {
      "x": -18,
      "y": 0,
      "z": 19,
      "name": "Soil_Clay"
    },
    {
      "x": -18,
      "y": 1,
      "z": 19,
      "name": "Soil_Clay"
    },
    {
      "x": -18,
      "y": 2,
      "z": 19,
      "name": "Soil_Grass"
    },
    {
      "x": -18,
      "y": 0,
      "z": 20,
      "name": "Soil_Clay"
    },
    {
      "x": -18,
      "y": 1,
      "z": 20,
      "name": "Soil_Clay"
    },
    {
      "x": -18,
      "y": 2,
      "z": 20,
      "name": "Soil_Grass"
    },
    {
      "x": -17,
      "y": 0,
      "z": -20,
      "name": "Soil_Clay"
    },
    {
      "x": -17,
      "y": 1,
      "z": -20,
      "name": "Soil_Clay"
    },
    {
      "x": -17,
      "y": 2,
      "z": -20,
      "name": "Soil_Grass"
    },
    {
      "x": -17,
      "y": 0,
      "z": -19,
      "name": "Soil_Clay"
    },
    {
      "x": -17,
      "y": 1,
      "z": -19,
      "name": "Soil_Clay"
    },
    {
      "x": -17,
      "y": 2,
      "z": -19,
      "name": "Soil_Grass"
    },
    {
      "x": -17,
      "y": 0,
      "z": -18,
      "name": "Soil_Clay"
    },
    {
      "x": -17,
      "y": 1,
      "z": -18,
      "name": "Soil_Clay"
    },
    {
      "x": -17,
      "y": 2,
      "z": -18,
      "name": "Soil_Grass"
    },
    {
      "x": -17,
      "y": 0,
      "z": -17,
      "name": "Soil_Clay"
    },
    {
      "x": -17,
      "y": 1,
      "z": -17,
      "name": "Soil_Clay"
    },
    {
      "x": -17,
      "y": 2,
      "z": -17,
      "name": "Soil_Grass"
    },
    {
      "x": -17,
      "y": 0,
      "z": -16,
      "name": "Soil_Clay"
    },
    {
      "x": -17,
      "y": 1,
      "z": -16,
      "name": "Soil_Clay"
    },
    {
      "x": -17,
      "y": 2,
      "z": -16,
      "name": "Soil_Grass"
    },
    {
      "x": -17,
      "y": 0,
      "z": -15,
      "name": "Soil_Clay"
    },
    {
      "x": -17,
      "y": 1,
      "z": -15,
      "name": "Soil_Clay"
    },
    {
      "x": -17,
      "y": 2,
      "z": -15,
      "name": "Soil_Grass"
    },
    {
      "x": -17,
      "y": 0,
      "z": -14,
      "name": "Soil_Clay"
    },
    {
      "x": -17,
      "y": 1,
      "z": -14,
      "name": "Soil_Clay"
    },
    {
      "x": -17,
      "y": 2,
      "z": -14,
      "name": "Soil_Grass"
    },
    {
      "x": -17,
      "y": 0,
      "z": -13,
      "name": "Soil_Clay"
    },
    {
      "x": -17,
      "y": 1,
      "z": -13,
      "name": "Soil_Clay"
    },
    {
      "x": -17,
      "y": 2,
      "z": -13,
      "name": "Soil_Grass"
    },
    {
      "x": -17,
      "y": 0,
      "z": -12,
      "name": "Soil_Clay"
    },
    {
      "x": -17,
      "y": 1,
      "z": -12,
      "name": "Soil_Clay"
    },
    {
      "x": -17,
      "y": 2,
      "z": -12,
      "name": "Soil_Grass"
    },
    {
      "x": -17,
      "y": 0,
      "z": -11,
      "name": "Soil_Clay"
    },
    {
      "x": -17,
      "y": 1,
      "z": -11,
      "name": "Soil_Clay"
    },
    {
      "x": -17,
      "y": 2,
      "z": -11,
      "name": "Soil_Grass"
    },
    {
      "x": -17,
      "y": 0,
      "z": -10,
      "name": "Soil_Clay"
    },
    {
      "x": -17,
      "y": 1,
      "z": -10,
      "name": "Soil_Clay"
    },
    {
      "x": -17,
      "y": 2,
      "z": -10,
      "name": "Soil_Grass"
    },
    {
      "x": -17,
      "y": 0,
      "z": -9,
      "name": "Soil_Clay"
    },
    {
      "x": -17,
      "y": 1,
      "z": -9,
      "name": "Soil_Clay"
    },
    {
      "x": -17,
      "y": 2,
      "z": -9,
      "name": "Soil_Grass"
    },
    {
      "x": -17,
      "y": 0,
      "z": -8,
      "name": "Soil_Clay"
    },
    {
      "x": -17,
      "y": 1,
      "z": -8,
      "name": "Soil_Clay"
    },
    {
      "x": -17,
      "y": 2,
      "z": -8,
      "name": "Soil_Grass"
    },
    {
      "x": -17,
      "y": 0,
      "z": -7,
      "name": "Soil_Clay"
    },
    {
      "x": -17,
      "y": 1,
      "z": -7,
      "name": "Soil_Clay"
    },
    {
      "x": -17,
      "y": 2,
      "z": -7,
      "name": "Soil_Grass"
    },
    {
      "x": -17,
      "y": 0,
      "z": -6,
      "name": "Soil_Clay"
    },
    {
      "x": -17,
      "y": 1,
      "z": -6,
      "name": "Soil_Clay"
    },
    {
      "x": -17,
      "y": 2,
      "z": -6,
      "name": "Soil_Grass"
    },
    {
      "x": -17,
      "y": 0,
      "z": -5,
      "name": "Soil_Clay"
    },
    {
      "x": -17,
      "y": 1,
      "z": -5,
      "name": "Soil_Clay"
    },
    {
      "x": -17,
      "y": 2,
      "z": -5,
      "name": "Soil_Grass"
    },
    {
      "x": -17,
      "y": 3,
      "z": -5,
      "name": "Soil_Dirt"
    },
    {
      "x": -17,
      "y": 4,
      "z": -5,
      "name": "Soil_Dirt_Half"
    },
    {
      "x": -17,
      "y": 0,
      "z": -4,
      "name": "Soil_Clay"
    },
    {
      "x": -17,
      "y": 1,
      "z": -4,
      "name": "Soil_Clay"
    },
    {
      "x": -17,
      "y": 2,
      "z": -4,
      "name": "Soil_Grass"
    },
    {
      "x": -17,
      "y": 3,
      "z": -4,
      "name": "Soil_Dirt"
    },
    {
      "x": -17,
      "y": 4,
      "z": -4,
      "name": "Soil_Dirt_Half"
    },
    {
      "x": -17,
      "y": 0,
      "z": -3,
      "name": "Soil_Clay"
    },
    {
      "x": -17,
      "y": 1,
      "z": -3,
      "name": "Soil_Clay"
    },
    {
      "x": -17,
      "y": 2,
      "z": -3,
      "name": "Soil_Grass"
    },
    {
      "x": -17,
      "y": 3,
      "z": -3,
      "name": "Soil_Dirt"
    },
    {
      "x": -17,
      "y": 4,
      "z": -3,
      "name": "Soil_Dirt_Half"
    },
    {
      "x": -17,
      "y": 0,
      "z": -2,
      "name": "Soil_Clay"
    },
    {
      "x": -17,
      "y": 1,
      "z": -2,
      "name": "Soil_Clay"
    },
    {
      "x": -17,
      "y": 2,
      "z": -2,
      "name": "Soil_Grass"
    },
    {
      "x": -17,
      "y": 3,
      "z": -2,
      "name": "Soil_Dirt"
    },
    {
      "x": -17,
      "y": 4,
      "z": -2,
      "name": "Soil_Dirt_Half"
    },
    {
      "x": -17,
      "y": 0,
      "z": -1,
      "name": "Soil_Clay"
    },
    {
      "x": -17,
      "y": 1,
      "z": -1,
      "name": "Soil_Clay"
    },
    {
      "x": -17,
      "y": 2,
      "z": -1,
      "name": "Soil_Grass"
    },
    {
      "x": -17,
      "y": 3,
      "z": -1,
      "name": "Soil_Dirt"
    },
    {
      "x": -17,
      "y": 4,
      "z": -1,
      "name": "Soil_Dirt_Half"
    },
    {
      "x": -17,
      "y": 0,
      "z": 0,
      "name": "Soil_Clay"
    },
    {
      "x": -17,
      "y": 1,
      "z": 0,
      "name": "Soil_Clay"
    },
    {
      "x": -17,
      "y": 2,
      "z": 0,
      "name": "Soil_Grass"
    },
    {
      "x": -17,
      "y": 3,
      "z": 0,
      "name": "Soil_Dirt"
    },
    {
      "x": -17,
      "y": 4,
      "z": 0,
      "name": "Soil_Dirt_Half"
    },
    {
      "x": -17,
      "y": 0,
      "z": 1,
      "name": "Soil_Clay"
    },
    {
      "x": -17,
      "y": 1,
      "z": 1,
      "name": "Soil_Clay"
    },
    {
      "x": -17,
      "y": 2,
      "z": 1,
      "name": "Soil_Grass"
    },
    {
      "x": -17,
      "y": 3,
      "z": 1,
      "name": "Soil_Dirt"
    },
    {
      "x": -17,
      "y": 4,
      "z": 1,
      "name": "Soil_Dirt_Half"
    },
    {
      "x": -17,
      "y": 0,
      "z": 2,
      "name": "Soil_Clay"
    },
    {
      "x": -17,
      "y": 1,
      "z": 2,
      "name": "Soil_Clay"
    },
    {
      "x": -17,
      "y": 2,
      "z": 2,
      "name": "Soil_Grass"
    },
    {
      "x": -17,
      "y": 3,
      "z": 2,
      "name": "Soil_Dirt"
    },
    {
      "x": -17,
      "y": 4,
      "z": 2,
      "name": "Soil_Dirt_Half"
    },
    {
      "x": -17,
      "y": 0,
      "z": 3,
      "name": "Soil_Clay"
    },
    {
      "x": -17,
      "y": 1,
      "z": 3,
      "name": "Soil_Clay"
    },
    {
      "x": -17,
      "y": 2,
      "z": 3,
      "name": "Soil_Grass"
    },
    {
      "x": -17,
      "y": 3,
      "z": 3,
      "name": "Soil_Dirt"
    },
    {
      "x": -17,
      "y": 4,
      "z": 3,
      "name": "Soil_Dirt_Half"
    },
    {
      "x": -17,
      "y": 0,
      "z": 4,
      "name": "Soil_Clay"
    },
    {
      "x": -17,
      "y": 1,
      "z": 4,
      "name": "Soil_Clay"
    },
    {
      "x": -17,
      "y": 2,
      "z": 4,
      "name": "Soil_Grass"
    },
    {
      "x": -17,
      "y": 3,
      "z": 4,
      "name": "Soil_Dirt"
    },
    {
      "x": -17,
      "y": 4,
      "z": 4,
      "name": "Soil_Dirt_Half"
    },
    {
      "x": -17,
      "y": 0,
      "z": 5,
      "name": "Soil_Clay"
    },
    {
      "x": -17,
      "y": 1,
      "z": 5,
      "name": "Soil_Clay"
    },
    {
      "x": -17,
      "y": 2,
      "z": 5,
      "name": "Soil_Grass"
    },
    {
      "x": -17,
      "y": 0,
      "z": 6,
      "name": "Soil_Clay"
    },
    {
      "x": -17,
      "y": 1,
      "z": 6,
      "name": "Soil_Clay"
    },
    {
      "x": -17,
      "y": 2,
      "z": 6,
      "name": "Soil_Grass"
    },
    {
      "x": -17,
      "y": 0,
      "z": 7,
      "name": "Soil_Clay"
    },
    {
      "x": -17,
      "y": 1,
      "z": 7,
      "name": "Soil_Clay"
    },
    {
      "x": -17,
      "y": 2,
      "z": 7,
      "name": "Soil_Grass"
    },
    {
      "x": -17,
      "y": 0,
      "z": 8,
      "name": "Soil_Clay"
    },
    {
      "x": -17,
      "y": 1,
      "z": 8,
      "name": "Soil_Clay"
    },
    {
      "x": -17,
      "y": 2,
      "z": 8,
      "name": "Soil_Grass"
    },
    {
      "x": -17,
      "y": 0,
      "z": 9,
      "name": "Soil_Clay"
    },
    {
      "x": -17,
      "y": 1,
      "z": 9,
      "name": "Soil_Clay"
    },
    {
      "x": -17,
      "y": 2,
      "z": 9,
      "name": "Soil_Grass"
    },
    {
      "x": -17,
      "y": 0,
      "z": 10,
      "name": "Soil_Clay"
    },
    {
      "x": -17,
      "y": 1,
      "z": 10,
      "name": "Soil_Clay"
    },
    {
      "x": -17,
      "y": 2,
      "z": 10,
      "name": "Soil_Grass"
    },
    {
      "x": -17,
      "y": 0,
      "z": 11,
      "name": "Soil_Clay"
    },
    {
      "x": -17,
      "y": 1,
      "z": 11,
      "name": "Soil_Clay"
    },
    {
      "x": -17,
      "y": 2,
      "z": 11,
      "name": "Soil_Grass"
    },
    {
      "x": -17,
      "y": 0,
      "z": 12,
      "name": "Soil_Clay"
    },
    {
      "x": -17,
      "y": 1,
      "z": 12,
      "name": "Soil_Clay"
    },
    {
      "x": -17,
      "y": 2,
      "z": 12,
      "name": "Soil_Grass"
    },
    {
      "x": -17,
      "y": 0,
      "z": 13,
      "name": "Soil_Clay"
    },
    {
      "x": -17,
      "y": 1,
      "z": 13,
      "name": "Soil_Clay"
    },
    {
      "x": -17,
      "y": 2,
      "z": 13,
      "name": "Soil_Grass"
    },
    {
      "x": -17,
      "y": 0,
      "z": 14,
      "name": "Soil_Clay"
    },
    {
      "x": -17,
      "y": 1,
      "z": 14,
      "name": "Soil_Clay"
    },
    {
      "x": -17,
      "y": 2,
      "z": 14,
      "name": "Soil_Grass"
    },
    {
      "x": -17,
      "y": 0,
      "z": 15,
      "name": "Soil_Clay"
    },
    {
      "x": -17,
      "y": 1,
      "z": 15,
      "name": "Soil_Clay"
    },
    {
      "x": -17,
      "y": 2,
      "z": 15,
      "name": "Soil_Grass"
    },
    {
      "x": -17,
      "y": 0,
      "z": 16,
      "name": "Soil_Clay"
    },
    {
      "x": -17,
      "y": 1,
      "z": 16,
      "name": "Soil_Clay"
    },
    {
      "x": -17,
      "y": 2,
      "z": 16,
      "name": "Soil_Grass"
    },
    {
      "x": -17,
      "y": 0,
      "z": 17,
      "name": "Soil_Clay"
    },
    {
      "x": -17,
      "y": 1,
      "z": 17,
      "name": "Soil_Clay"
    },
    {
      "x": -17,
      "y": 2,
      "z": 17,
      "name": "Soil_Grass"
    },
    {
      "x": -17,
      "y": 0,
      "z": 18,
      "name": "Soil_Clay"
    },
    {
      "x": -17,
      "y": 1,
      "z": 18,
      "name": "Soil_Clay"
    },
    {
      "x": -17,
      "y": 2,
      "z": 18,
      "name": "Soil_Grass"
    },
    {
      "x": -17,
      "y": 0,
      "z": 19,
      "name": "Soil_Clay"
    },
    {
      "x": -17,
      "y": 1,
      "z": 19,
      "name": "Soil_Clay"
    },
    {
      "x": -17,
      "y": 2,
      "z": 19,
      "name": "Soil_Grass"
    },
    {
      "x": -17,
      "y": 0,
      "z": 20,
      "name": "Soil_Clay"
    },
    {
      "x": -17,
      "y": 1,
      "z": 20,
      "name": "Soil_Clay"
    },
    {
      "x": -17,
      "y": 2,
      "z": 20,
      "name": "Soil_Grass"
    },
    {
      "x": -16,
      "y": 0,
      "z": -20,
      "name": "Soil_Clay"
    },
    {
      "x": -16,
      "y": 1,
      "z": -20,
      "name": "Soil_Clay"
    },
    {
      "x": -16,
      "y": 2,
      "z": -20,
      "name": "Soil_Grass"
    },
    {
      "x": -16,
      "y": 0,
      "z": -19,
      "name": "Soil_Clay"
    },
    {
      "x": -16,
      "y": 1,
      "z": -19,
      "name": "Soil_Clay"
    },
    {
      "x": -16,
      "y": 2,
      "z": -19,
      "name": "Soil_Grass"
    },
    {
      "x": -16,
      "y": 0,
      "z": -18,
      "name": "Soil_Clay"
    },
    {
      "x": -16,
      "y": 1,
      "z": -18,
      "name": "Soil_Clay"
    },
    {
      "x": -16,
      "y": 2,
      "z": -18,
      "name": "Soil_Grass"
    },
    {
      "x": -16,
      "y": 0,
      "z": -17,
      "name": "Soil_Clay"
    },
    {
      "x": -16,
      "y": 1,
      "z": -17,
      "name": "Soil_Clay"
    },
    {
      "x": -16,
      "y": 2,
      "z": -17,
      "name": "Soil_Grass"
    },
    {
      "x": -16,
      "y": 0,
      "z": -16,
      "name": "Soil_Clay"
    },
    {
      "x": -16,
      "y": 1,
      "z": -16,
      "name": "Soil_Clay"
    },
    {
      "x": -16,
      "y": 2,
      "z": -16,
      "name": "Soil_Grass"
    },
    {
      "x": -16,
      "y": 0,
      "z": -15,
      "name": "Soil_Clay"
    },
    {
      "x": -16,
      "y": 1,
      "z": -15,
      "name": "Soil_Clay"
    },
    {
      "x": -16,
      "y": 2,
      "z": -15,
      "name": "Soil_Grass"
    },
    {
      "x": -16,
      "y": 0,
      "z": -14,
      "name": "Soil_Clay"
    },
    {
      "x": -16,
      "y": 1,
      "z": -14,
      "name": "Soil_Clay"
    },
    {
      "x": -16,
      "y": 2,
      "z": -14,
      "name": "Soil_Grass"
    },
    {
      "x": -16,
      "y": 0,
      "z": -13,
      "name": "Soil_Clay"
    },
    {
      "x": -16,
      "y": 1,
      "z": -13,
      "name": "Soil_Clay"
    },
    {
      "x": -16,
      "y": 2,
      "z": -13,
      "name": "Soil_Grass"
    },
    {
      "x": -16,
      "y": 0,
      "z": -12,
      "name": "Soil_Clay"
    },
    {
      "x": -16,
      "y": 1,
      "z": -12,
      "name": "Soil_Clay"
    },
    {
      "x": -16,
      "y": 2,
      "z": -12,
      "name": "Soil_Grass"
    },
    {
      "x": -16,
      "y": 0,
      "z": -11,
      "name": "Soil_Clay"
    },
    {
      "x": -16,
      "y": 1,
      "z": -11,
      "name": "Soil_Clay"
    },
    {
      "x": -16,
      "y": 2,
      "z": -11,
      "name": "Soil_Grass"
    },
    {
      "x": -16,
      "y": 0,
      "z": -10,
      "name": "Soil_Clay"
    },
    {
      "x": -16,
      "y": 1,
      "z": -10,
      "name": "Soil_Clay"
    },
    {
      "x": -16,
      "y": 2,
      "z": -10,
      "name": "Soil_Grass"
    },
    {
      "x": -16,
      "y": 0,
      "z": -9,
      "name": "Soil_Clay"
    },
    {
      "x": -16,
      "y": 1,
      "z": -9,
      "name": "Soil_Clay"
    },
    {
      "x": -16,
      "y": 2,
      "z": -9,
      "name": "Soil_Grass"
    },
    {
      "x": -16,
      "y": 0,
      "z": -8,
      "name": "Soil_Clay"
    },
    {
      "x": -16,
      "y": 1,
      "z": -8,
      "name": "Soil_Clay"
    },
    {
      "x": -16,
      "y": 2,
      "z": -8,
      "name": "Soil_Grass"
    },
    {
      "x": -16,
      "y": 0,
      "z": -7,
      "name": "Soil_Clay"
    },
    {
      "x": -16,
      "y": 1,
      "z": -7,
      "name": "Soil_Clay"
    },
    {
      "x": -16,
      "y": 2,
      "z": -7,
      "name": "Soil_Grass"
    },
    {
      "x": -16,
      "y": 0,
      "z": -6,
      "name": "Soil_Clay"
    },
    {
      "x": -16,
      "y": 1,
      "z": -6,
      "name": "Soil_Clay"
    },
    {
      "x": -16,
      "y": 2,
      "z": -6,
      "name": "Soil_Grass"
    },
    {
      "x": -16,
      "y": 0,
      "z": -5,
      "name": "Soil_Clay"
    },
    {
      "x": -16,
      "y": 1,
      "z": -5,
      "name": "Soil_Clay"
    },
    {
      "x": -16,
      "y": 2,
      "z": -5,
      "name": "Soil_Grass"
    },
    {
      "x": -16,
      "y": 3,
      "z": -5,
      "name": "Soil_Dirt"
    },
    {
      "x": -16,
      "y": 4,
      "z": -5,
      "name": "Soil_Dirt"
    },
    {
      "x": -16,
      "y": 0,
      "z": -4,
      "name": "Soil_Clay"
    },
    {
      "x": -16,
      "y": 1,
      "z": -4,
      "name": "Soil_Clay"
    },
    {
      "x": -16,
      "y": 2,
      "z": -4,
      "name": "Soil_Grass"
    },
    {
      "x": -16,
      "y": 3,
      "z": -4,
      "name": "Soil_Dirt"
    },
    {
      "x": -16,
      "y": 4,
      "z": -4,
      "name": "Soil_Dirt"
    },
    {
      "x": -16,
      "y": 0,
      "z": -3,
      "name": "Soil_Clay"
    },
    {
      "x": -16,
      "y": 1,
      "z": -3,
      "name": "Soil_Clay"
    },
    {
      "x": -16,
      "y": 2,
      "z": -3,
      "name": "Soil_Grass"
    },
    {
      "x": -16,
      "y": 3,
      "z": -3,
      "name": "Soil_Dirt"
    },
    {
      "x": -16,
      "y": 4,
      "z": -3,
      "name": "Soil_Dirt"
    },
    {
      "x": -16,
      "y": 0,
      "z": -2,
      "name": "Soil_Clay"
    },
    {
      "x": -16,
      "y": 1,
      "z": -2,
      "name": "Soil_Clay"
    },
    {
      "x": -16,
      "y": 2,
      "z": -2,
      "name": "Soil_Grass"
    },
    {
      "x": -16,
      "y": 3,
      "z": -2,
      "name": "Soil_Dirt"
    },
    {
      "x": -16,
      "y": 4,
      "z": -2,
      "name": "Soil_Dirt"
    },
    {
      "x": -16,
      "y": 0,
      "z": -1,
      "name": "Soil_Clay"
    },
    {
      "x": -16,
      "y": 1,
      "z": -1,
      "name": "Soil_Clay"
    },
    {
      "x": -16,
      "y": 2,
      "z": -1,
      "name": "Soil_Grass"
    },
    {
      "x": -16,
      "y": 3,
      "z": -1,
      "name": "Soil_Dirt"
    },
    {
      "x": -16,
      "y": 4,
      "z": -1,
      "name": "Soil_Dirt"
    },
    {
      "x": -16,
      "y": 0,
      "z": 0,
      "name": "Soil_Clay"
    },
    {
      "x": -16,
      "y": 1,
      "z": 0,
      "name": "Soil_Clay"
    },
    {
      "x": -16,
      "y": 2,
      "z": 0,
      "name": "Soil_Grass"
    },
    {
      "x": -16,
      "y": 3,
      "z": 0,
      "name": "Soil_Dirt"
    },
    {
      "x": -16,
      "y": 4,
      "z": 0,
      "name": "Soil_Dirt"
    },
    {
      "x": -16,
      "y": 0,
      "z": 1,
      "name": "Soil_Clay"
    },
    {
      "x": -16,
      "y": 1,
      "z": 1,
      "name": "Soil_Clay"
    },
    {
      "x": -16,
      "y": 2,
      "z": 1,
      "name": "Soil_Grass"
    },
    {
      "x": -16,
      "y": 3,
      "z": 1,
      "name": "Soil_Dirt"
    },
    {
      "x": -16,
      "y": 4,
      "z": 1,
      "name": "Soil_Dirt"
    },
    {
      "x": -16,
      "y": 0,
      "z": 2,
      "name": "Soil_Clay"
    },
    {
      "x": -16,
      "y": 1,
      "z": 2,
      "name": "Soil_Clay"
    },
    {
      "x": -16,
      "y": 2,
      "z": 2,
      "name": "Soil_Grass"
    },
    {
      "x": -16,
      "y": 3,
      "z": 2,
      "name": "Soil_Dirt"
    },
    {
      "x": -16,
      "y": 4,
      "z": 2,
      "name": "Soil_Dirt"
    },
    {
      "x": -16,
      "y": 0,
      "z": 3,
      "name": "Soil_Clay"
    },
    {
      "x": -16,
      "y": 1,
      "z": 3,
      "name": "Soil_Clay"
    },
    {
      "x": -16,
      "y": 2,
      "z": 3,
      "name": "Soil_Grass"
    },
    {
      "x": -16,
      "y": 3,
      "z": 3,
      "name": "Soil_Dirt"
    },
    {
      "x": -16,
      "y": 4,
      "z": 3,
      "name": "Soil_Dirt"
    },
    {
      "x": -16,
      "y": 0,
      "z": 4,
      "name": "Soil_Clay"
    },
    {
      "x": -16,
      "y": 1,
      "z": 4,
      "name": "Soil_Clay"
    },
    {
      "x": -16,
      "y": 2,
      "z": 4,
      "name": "Soil_Grass"
    },
    {
      "x": -16,
      "y": 3,
      "z": 4,
      "name": "Soil_Dirt"
    },
    {
      "x": -16,
      "y": 4,
      "z": 4,
      "name": "Soil_Dirt"
    },
    {
      "x": -16,
      "y": 0,
      "z": 5,
      "name": "Soil_Clay"
    },
    {
      "x": -16,
      "y": 1,
      "z": 5,
      "name": "Soil_Clay"
    },
    {
      "x": -16,
      "y": 2,
      "z": 5,
      "name": "Soil_Grass"
    },
    {
      "x": -16,
      "y": 0,
      "z": 6,
      "name": "Soil_Clay"
    },
    {
      "x": -16,
      "y": 1,
      "z": 6,
      "name": "Soil_Clay"
    },
    {
      "x": -16,
      "y": 2,
      "z": 6,
      "name": "Soil_Grass"
    },
    {
      "x": -16,
      "y": 0,
      "z": 7,
      "name": "Soil_Clay"
    },
    {
      "x": -16,
      "y": 1,
      "z": 7,
      "name": "Soil_Clay"
    },
    {
      "x": -16,
      "y": 2,
      "z": 7,
      "name": "Soil_Grass"
    },
    {
      "x": -16,
      "y": 0,
      "z": 8,
      "name": "Soil_Clay"
    },
    {
      "x": -16,
      "y": 1,
      "z": 8,
      "name": "Soil_Clay"
    },
    {
      "x": -16,
      "y": 2,
      "z": 8,
      "name": "Soil_Grass"
    },
    {
      "x": -16,
      "y": 0,
      "z": 9,
      "name": "Soil_Clay"
    },
    {
      "x": -16,
      "y": 1,
      "z": 9,
      "name": "Soil_Clay"
    },
    {
      "x": -16,
      "y": 2,
      "z": 9,
      "name": "Soil_Grass"
    },
    {
      "x": -16,
      "y": 0,
      "z": 10,
      "name": "Soil_Clay"
    },
    {
      "x": -16,
      "y": 1,
      "z": 10,
      "name": "Soil_Clay"
    },
    {
      "x": -16,
      "y": 2,
      "z": 10,
      "name": "Soil_Grass"
    },
    {
      "x": -16,
      "y": 0,
      "z": 11,
      "name": "Soil_Clay"
    },
    {
      "x": -16,
      "y": 1,
      "z": 11,
      "name": "Soil_Clay"
    },
    {
      "x": -16,
      "y": 2,
      "z": 11,
      "name": "Soil_Grass"
    },
    {
      "x": -16,
      "y": 0,
      "z": 12,
      "name": "Soil_Clay"
    },
    {
      "x": -16,
      "y": 1,
      "z": 12,
      "name": "Soil_Clay"
    },
    {
      "x": -16,
      "y": 2,
      "z": 12,
      "name": "Soil_Grass"
    },
    {
      "x": -16,
      "y": 0,
      "z": 13,
      "name": "Soil_Clay"
    },
    {
      "x": -16,
      "y": 1,
      "z": 13,
      "name": "Soil_Clay"
    },
    {
      "x": -16,
      "y": 2,
      "z": 13,
      "name": "Soil_Grass"
    },
    {
      "x": -16,
      "y": 0,
      "z": 14,
      "name": "Soil_Clay"
    },
    {
      "x": -16,
      "y": 1,
      "z": 14,
      "name": "Soil_Clay"
    },
    {
      "x": -16,
      "y": 2,
      "z": 14,
      "name": "Soil_Grass"
    },
    {
      "x": -16,
      "y": 0,
      "z": 15,
      "name": "Soil_Clay"
    },
    {
      "x": -16,
      "y": 1,
      "z": 15,
      "name": "Soil_Clay"
    },
    {
      "x": -16,
      "y": 2,
      "z": 15,
      "name": "Soil_Grass"
    },
    {
      "x": -16,
      "y": 0,
      "z": 16,
      "name": "Soil_Clay"
    },
    {
      "x": -16,
      "y": 1,
      "z": 16,
      "name": "Soil_Clay"
    },
    {
      "x": -16,
      "y": 2,
      "z": 16,
      "name": "Soil_Grass"
    },
    {
      "x": -16,
      "y": 0,
      "z": 17,
      "name": "Soil_Clay"
    },
    {
      "x": -16,
      "y": 1,
      "z": 17,
      "name": "Soil_Clay"
    },
    {
      "x": -16,
      "y": 2,
      "z": 17,
      "name": "Soil_Grass"
    },
    {
      "x": -16,
      "y": 0,
      "z": 18,
      "name": "Soil_Clay"
    },
    {
      "x": -16,
      "y": 1,
      "z": 18,
      "name": "Soil_Clay"
    },
    {
      "x": -16,
      "y": 2,
      "z": 18,
      "name": "Soil_Grass"
    },
    {
      "x": -16,
      "y": 0,
      "z": 19,
      "name": "Soil_Clay"
    },
    {
      "x": -16,
      "y": 1,
      "z": 19,
      "name": "Soil_Clay"
    },
    {
      "x": -16,
      "y": 2,
      "z": 19,
      "name": "Soil_Grass"
    },
    {
      "x": -16,
      "y": 0,
      "z": 20,
      "name": "Soil_Clay"
    },
    {
      "x": -16,
      "y": 1,
      "z": 20,
      "name": "Soil_Clay"
    },
    {
      "x": -16,
      "y": 2,
      "z": 20,
      "name": "Soil_Grass"
    },
    {
      "x": -15,
      "y": 0,
      "z": -20,
      "name": "Soil_Clay"
    },
    {
      "x": -15,
      "y": 1,
      "z": -20,
      "name": "Soil_Clay"
    },
    {
      "x": -15,
      "y": 2,
      "z": -20,
      "name": "Soil_Grass"
    },
    {
      "x": -15,
      "y": 0,
      "z": -19,
      "name": "Soil_Clay"
    },
    {
      "x": -15,
      "y": 1,
      "z": -19,
      "name": "Soil_Clay"
    },
    {
      "x": -15,
      "y": 2,
      "z": -19,
      "name": "Soil_Grass"
    },
    {
      "x": -15,
      "y": 0,
      "z": -18,
      "name": "Soil_Clay"
    },
    {
      "x": -15,
      "y": 1,
      "z": -18,
      "name": "Soil_Clay"
    },
    {
      "x": -15,
      "y": 2,
      "z": -18,
      "name": "Soil_Grass"
    },
    {
      "x": -15,
      "y": 0,
      "z": -17,
      "name": "Soil_Clay"
    },
    {
      "x": -15,
      "y": 1,
      "z": -17,
      "name": "Soil_Clay"
    },
    {
      "x": -15,
      "y": 2,
      "z": -17,
      "name": "Soil_Grass"
    },
    {
      "x": -15,
      "y": 0,
      "z": -16,
      "name": "Soil_Clay"
    },
    {
      "x": -15,
      "y": 1,
      "z": -16,
      "name": "Soil_Clay"
    },
    {
      "x": -15,
      "y": 2,
      "z": -16,
      "name": "Soil_Grass"
    },
    {
      "x": -15,
      "y": 0,
      "z": -15,
      "name": "Soil_Clay"
    },
    {
      "x": -15,
      "y": 1,
      "z": -15,
      "name": "Soil_Clay"
    },
    {
      "x": -15,
      "y": 2,
      "z": -15,
      "name": "Soil_Grass"
    },
    {
      "x": -15,
      "y": 0,
      "z": -14,
      "name": "Soil_Clay"
    },
    {
      "x": -15,
      "y": 1,
      "z": -14,
      "name": "Soil_Clay"
    },
    {
      "x": -15,
      "y": 2,
      "z": -14,
      "name": "Soil_Grass"
    },
    {
      "x": -15,
      "y": 0,
      "z": -13,
      "name": "Soil_Clay"
    },
    {
      "x": -15,
      "y": 1,
      "z": -13,
      "name": "Soil_Clay"
    },
    {
      "x": -15,
      "y": 2,
      "z": -13,
      "name": "Soil_Grass"
    },
    {
      "x": -15,
      "y": 0,
      "z": -12,
      "name": "Soil_Clay"
    },
    {
      "x": -15,
      "y": 1,
      "z": -12,
      "name": "Soil_Clay"
    },
    {
      "x": -15,
      "y": 2,
      "z": -12,
      "name": "Soil_Grass"
    },
    {
      "x": -15,
      "y": 0,
      "z": -11,
      "name": "Soil_Clay"
    },
    {
      "x": -15,
      "y": 1,
      "z": -11,
      "name": "Soil_Clay"
    },
    {
      "x": -15,
      "y": 2,
      "z": -11,
      "name": "Soil_Grass"
    },
    {
      "x": -15,
      "y": 0,
      "z": -10,
      "name": "Soil_Clay"
    },
    {
      "x": -15,
      "y": 1,
      "z": -10,
      "name": "Soil_Clay"
    },
    {
      "x": -15,
      "y": 2,
      "z": -10,
      "name": "Soil_Grass"
    },
    {
      "x": -15,
      "y": 0,
      "z": -9,
      "name": "Soil_Clay"
    },
    {
      "x": -15,
      "y": 1,
      "z": -9,
      "name": "Soil_Clay"
    },
    {
      "x": -15,
      "y": 2,
      "z": -9,
      "name": "Soil_Grass"
    },
    {
      "x": -15,
      "y": 0,
      "z": -8,
      "name": "Soil_Clay"
    },
    {
      "x": -15,
      "y": 1,
      "z": -8,
      "name": "Soil_Clay"
    },
    {
      "x": -15,
      "y": 2,
      "z": -8,
      "name": "Soil_Grass"
    },
    {
      "x": -15,
      "y": 0,
      "z": -7,
      "name": "Soil_Clay"
    },
    {
      "x": -15,
      "y": 1,
      "z": -7,
      "name": "Soil_Clay"
    },
    {
      "x": -15,
      "y": 2,
      "z": -7,
      "name": "Soil_Grass"
    },
    {
      "x": -15,
      "y": 0,
      "z": -6,
      "name": "Soil_Clay"
    },
    {
      "x": -15,
      "y": 1,
      "z": -6,
      "name": "Soil_Clay"
    },
    {
      "x": -15,
      "y": 2,
      "z": -6,
      "name": "Soil_Grass"
    },
    {
      "x": -15,
      "y": 0,
      "z": -5,
      "name": "Soil_Clay"
    },
    {
      "x": -15,
      "y": 1,
      "z": -5,
      "name": "Soil_Clay"
    },
    {
      "x": -15,
      "y": 2,
      "z": -5,
      "name": "Soil_Grass"
    },
    {
      "x": -15,
      "y": 3,
      "z": -5,
      "name": "Soil_Dirt"
    },
    {
      "x": -15,
      "y": 4,
      "z": -5,
      "name": "Soil_Dirt"
    },
    {
      "x": -15,
      "y": 5,
      "z": -5,
      "name": "Soil_Dirt_Half"
    },
    {
      "x": -15,
      "y": 0,
      "z": -4,
      "name": "Soil_Clay"
    },
    {
      "x": -15,
      "y": 1,
      "z": -4,
      "name": "Soil_Clay"
    },
    {
      "x": -15,
      "y": 2,
      "z": -4,
      "name": "Soil_Grass"
    },
    {
      "x": -15,
      "y": 3,
      "z": -4,
      "name": "Soil_Dirt"
    },
    {
      "x": -15,
      "y": 4,
      "z": -4,
      "name": "Soil_Dirt"
    },
    {
      "x": -15,
      "y": 5,
      "z": -4,
      "name": "Soil_Dirt_Half"
    },
    {
      "x": -15,
      "y": 0,
      "z": -3,
      "name": "Soil_Clay"
    },
    {
      "x": -15,
      "y": 1,
      "z": -3,
      "name": "Soil_Clay"
    },
    {
      "x": -15,
      "y": 2,
      "z": -3,
      "name": "Soil_Grass"
    },
    {
      "x": -15,
      "y": 3,
      "z": -3,
      "name": "Soil_Dirt"
    },
    {
      "x": -15,
      "y": 4,
      "z": -3,
      "name": "Soil_Dirt"
    },
    {
      "x": -15,
      "y": 5,
      "z": -3,
      "name": "Soil_Dirt_Half"
    },
    {
      "x": -15,
      "y": 0,
      "z": -2,
      "name": "Soil_Clay"
    },
    {
      "x": -15,
      "y": 1,
      "z": -2,
      "name": "Soil_Clay"
    },
    {
      "x": -15,
      "y": 2,
      "z": -2,
      "name": "Soil_Grass"
    },
    {
      "x": -15,
      "y": 3,
      "z": -2,
      "name": "Soil_Dirt"
    },
    {
      "x": -15,
      "y": 4,
      "z": -2,
      "name": "Soil_Dirt"
    },
    {
      "x": -15,
      "y": 5,
      "z": -2,
      "name": "Soil_Dirt_Half"
    },
    {
      "x": -15,
      "y": 0,
      "z": -1,
      "name": "Soil_Clay"
    },
    {
      "x": -15,
      "y": 1,
      "z": -1,
      "name": "Soil_Clay"
    },
    {
      "x": -15,
      "y": 2,
      "z": -1,
      "name": "Soil_Grass"
    },
    {
      "x": -15,
      "y": 3,
      "z": -1,
      "name": "Soil_Dirt"
    },
    {
      "x": -15,
      "y": 4,
      "z": -1,
      "name": "Soil_Dirt"
    },
    {
      "x": -15,
      "y": 5,
      "z": -1,
      "name": "Soil_Dirt_Half"
    },
    {
      "x": -15,
      "y": 0,
      "z": 0,
      "name": "Soil_Clay"
    },
    {
      "x": -15,
      "y": 1,
      "z": 0,
      "name": "Soil_Clay"
    },
    {
      "x": -15,
      "y": 2,
      "z": 0,
      "name": "Soil_Grass"
    },
    {
      "x": -15,
      "y": 3,
      "z": 0,
      "name": "Soil_Dirt"
    },
    {
      "x": -15,
      "y": 4,
      "z": 0,
      "name": "Soil_Dirt"
    },
    {
      "x": -15,
      "y": 5,
      "z": 0,
      "name": "Soil_Dirt_Half"
    },
    {
      "x": -15,
      "y": 0,
      "z": 1,
      "name": "Soil_Clay"
    },
    {
      "x": -15,
      "y": 1,
      "z": 1,
      "name": "Soil_Clay"
    },
    {
      "x": -15,
      "y": 2,
      "z": 1,
      "name": "Soil_Grass"
    },
    {
      "x": -15,
      "y": 3,
      "z": 1,
      "name": "Soil_Dirt"
    },
    {
      "x": -15,
      "y": 4,
      "z": 1,
      "name": "Soil_Dirt"
    },
    {
      "x": -15,
      "y": 5,
      "z": 1,
      "name": "Soil_Dirt_Half"
    },
    {
      "x": -15,
      "y": 0,
      "z": 2,
      "name": "Soil_Clay"
    },
    {
      "x": -15,
      "y": 1,
      "z": 2,
      "name": "Soil_Clay"
    },
    {
      "x": -15,
      "y": 2,
      "z": 2,
      "name": "Soil_Grass"
    },
    {
      "x": -15,
      "y": 3,
      "z": 2,
      "name": "Soil_Dirt"
    },
    {
      "x": -15,
      "y": 4,
      "z": 2,
      "name": "Soil_Dirt"
    },
    {
      "x": -15,
      "y": 5,
      "z": 2,
      "name": "Soil_Dirt_Half"
    },
    {
      "x": -15,
      "y": 0,
      "z": 3,
      "name": "Soil_Clay"
    },
    {
      "x": -15,
      "y": 1,
      "z": 3,
      "name": "Soil_Clay"
    },
    {
      "x": -15,
      "y": 2,
      "z": 3,
      "name": "Soil_Grass"
    },
    {
      "x": -15,
      "y": 3,
      "z": 3,
      "name": "Soil_Dirt"
    },
    {
      "x": -15,
      "y": 4,
      "z": 3,
      "name": "Soil_Dirt"
    },
    {
      "x": -15,
      "y": 5,
      "z": 3,
      "name": "Soil_Dirt_Half"
    },
    {
      "x": -15,
      "y": 0,
      "z": 4,
      "name": "Soil_Clay"
    },
    {
      "x": -15,
      "y": 1,
      "z": 4,
      "name": "Soil_Clay"
    },
    {
      "x": -15,
      "y": 2,
      "z": 4,
      "name": "Soil_Grass"
    },
    {
      "x": -15,
      "y": 3,
      "z": 4,
      "name": "Soil_Dirt"
    },
    {
      "x": -15,
      "y": 4,
      "z": 4,
      "name": "Soil_Dirt"
    },
    {
      "x": -15,
      "y": 5,
      "z": 4,
      "name": "Soil_Dirt_Half"
    },
    {
      "x": -15,
      "y": 0,
      "z": 5,
      "name": "Soil_Clay"
    },
    {
      "x": -15,
      "y": 1,
      "z": 5,
      "name": "Soil_Clay"
    },
    {
      "x": -15,
      "y": 2,
      "z": 5,
      "name": "Soil_Grass"
    },
    {
      "x": -15,
      "y": 0,
      "z": 6,
      "name": "Soil_Clay"
    },
    {
      "x": -15,
      "y": 1,
      "z": 6,
      "name": "Soil_Clay"
    },
    {
      "x": -15,
      "y": 2,
      "z": 6,
      "name": "Soil_Grass"
    },
    {
      "x": -15,
      "y": 0,
      "z": 7,
      "name": "Soil_Clay"
    },
    {
      "x": -15,
      "y": 1,
      "z": 7,
      "name": "Soil_Clay"
    },
    {
      "x": -15,
      "y": 2,
      "z": 7,
      "name": "Soil_Grass"
    },
    {
      "x": -15,
      "y": 0,
      "z": 8,
      "name": "Soil_Clay"
    },
    {
      "x": -15,
      "y": 1,
      "z": 8,
      "name": "Soil_Clay"
    },
    {
      "x": -15,
      "y": 2,
      "z": 8,
      "name": "Soil_Grass"
    },
    {
      "x": -15,
      "y": 0,
      "z": 9,
      "name": "Soil_Clay"
    },
    {
      "x": -15,
      "y": 1,
      "z": 9,
      "name": "Soil_Clay"
    },
    {
      "x": -15,
      "y": 2,
      "z": 9,
      "name": "Soil_Grass"
    },
    {
      "x": -15,
      "y": 0,
      "z": 10,
      "name": "Soil_Clay"
    },
    {
      "x": -15,
      "y": 1,
      "z": 10,
      "name": "Soil_Clay"
    },
    {
      "x": -15,
      "y": 2,
      "z": 10,
      "name": "Soil_Grass"
    },
    {
      "x": -15,
      "y": 0,
      "z": 11,
      "name": "Soil_Clay"
    },
    {
      "x": -15,
      "y": 1,
      "z": 11,
      "name": "Soil_Clay"
    },
    {
      "x": -15,
      "y": 2,
      "z": 11,
      "name": "Soil_Grass"
    },
    {
      "x": -15,
      "y": 0,
      "z": 12,
      "name": "Soil_Clay"
    },
    {
      "x": -15,
      "y": 1,
      "z": 12,
      "name": "Soil_Clay"
    },
    {
      "x": -15,
      "y": 2,
      "z": 12,
      "name": "Soil_Grass"
    },
    {
      "x": -15,
      "y": 0,
      "z": 13,
      "name": "Soil_Clay"
    },
    {
      "x": -15,
      "y": 1,
      "z": 13,
      "name": "Soil_Clay"
    },
    {
      "x": -15,
      "y": 2,
      "z": 13,
      "name": "Soil_Grass"
    },
    {
      "x": -15,
      "y": 0,
      "z": 14,
      "name": "Soil_Clay"
    },
    {
      "x": -15,
      "y": 1,
      "z": 14,
      "name": "Soil_Clay"
    },
    {
      "x": -15,
      "y": 2,
      "z": 14,
      "name": "Soil_Grass"
    },
    {
      "x": -15,
      "y": 0,
      "z": 15,
      "name": "Soil_Clay"
    },
    {
      "x": -15,
      "y": 1,
      "z": 15,
      "name": "Soil_Clay"
    },
    {
      "x": -15,
      "y": 2,
      "z": 15,
      "name": "Soil_Grass"
    },
    {
      "x": -15,
      "y": 0,
      "z": 16,
      "name": "Soil_Clay"
    },
    {
      "x": -15,
