{
  "version": 8,
  "blockIdVersion": 11,
  "anchorX": 0,
  "anchorY": 0,
  "anchorZ": 0,
  "blocks": [
    {
      "x": -39,
      "y": 1,
      "z": -34,
      "name": "Plant_Leaves_Fir",
      "rotation": 1
    },
    {
      "x": -39,
      "y": 2,
      "z": -34,
      "name": "Plant_Leaves_Fir",
      "rotation": 1
    },
    {
      "x": -39,
      "y": 2,
      "z": -33,
      "name": "Plant_Leaves_Fir",
      "rotation": 1
    },
    {
      "x": -39,
      "y": 6,
      "z": -33,
      "name": "Plant_Leaves_Fir",
      "rotation": 1
    },
    {
      "x": -39,
      "y": 7,
      "z": -33,
      "name": "Plant_Leaves_Fir",
      "rotation": 1
    },
    {
      "x": -39,
      "y": 9,
      "z": -33,
      "name": "Plant_Leaves_Fir",
      "rotation": 1
    },
    {
      "x": -39,
      "y": 2,
      "z": -32,
      "name": "Plant_Leaves_Fir",
      "rotation": 1
    },
    {
      "x": -39,
      "y": 0,
      "z": -24,
      "name": "Plant_Fern_Winter"
    },
    {
      "x": -39,
      "y": 0,
      "z": -16,
      "name": "Rubble_Stone"
    },
    {
      "x": -39,
      "y": 0,
      "z": -1,
      "name": "Rock_Basalt",
      "rotation": 2
    },
    {
      "x": -39,
      "y": 1,
      "z": -1,
      "name": "Rock_Basalt",
      "rotation": 2
    },
    {
      "x": -39,
      "y": 0,
      "z": 0,
      "name": "Rock_Basalt",
      "rotation": 2
    },
    {
      "x": -39,
      "y": 1,
      "z": 0,
      "name": "Rock_Basalt",
      "rotation": 2
    },
    {
      "x": -39,
      "y": 0,
      "z": 1,
      "name": "Rock_Basalt",
      "rotation": 2
    },
    {
      "x": -39,
      "y": 0,
      "z": 14,
      "name": "Plant_Grass_Sharp_Tall"
    },
    {
      "x": -39,
      "y": 0,
      "z": 17,
      "name": "Rock_Basalt"
    },
    {
      "x": -39,
      "y": 0,
      "z": 18,
      "name": "Rock_Basalt"
    },
    {
      "x": -39,
      "y": 1,
      "z": 18,
      "name": "Rock_Basalt"
    },
    {
      "x": -39,
      "y": 0,
      "z": 19,
      "name": "Rock_Basalt"
    },
    {
      "x": -39,
      "y": 1,
      "z": 19,
      "name": "Rock_Basalt"
    },
    {
      "x": -39,
      "y": 0,
      "z": 20,
      "name": "Rock_Basalt"
    },
    {
      "x": -39,
      "y": 0,
      "z": 22,
      "name": "Plant_Fern_Winter"
    },
    {
      "x": -39,
      "y": 0,
      "z": 23,
      "name": "Rubble_Stone"
    },
    {
      "x": -39,
      "y": 0,
      "z": 29,
      "name": "Soil_Dirt"
    },
    {
      "x": -39,
      "y": 0,
      "z": 30,
      "name": "Soil_Dirt"
    },
    {
      "x": -39,
      "y": 0,
      "z": 31,
      "name": "Soil_Dirt"
    },
    {
      "x": -39,
      "y": 1,
      "z": 31,
      "name": "Plant_Crop_Mushroom_Cap_Brown",
      "components": {
        "Components": {
          "FarmingBlock": {
            "LastTickGameTime": "0001-01-01T05:30:00Z",
            "SpreadRate": 0.0
          }
        }
      }
    },
    {
      "x": -39,
      "y": 0,
      "z": 32,
      "name": "Soil_Dirt"
    },
    {
      "x": -39,
      "y": 0,
      "z": 33,
      "name": "Soil_Dirt"
    },
    {
      "x": -39,
      "y": 0,
      "z": 34,
      "name": "Soil_Dirt"
    },
    {
      "x": -39,
      "y": 0,
      "z": 35,
      "name": "Soil_Dirt"
    },
    {
      "x": -39,
      "y": 0,
      "z": 36,
      "name": "Soil_Dirt"
    },
    {
      "x": -39,
      "y": 0,
      "z": 37,
      "name": "Soil_Dirt"
    },
    {
      "x": -39,
      "y": 0,
      "z": 38,
      "name": "Soil_Dirt"
    },
    {
      "x": -39,
      "y": 0,
      "z": 39,
      "name": "Soil_Dirt"
    },
    {
      "x": -39,
      "y": 0,
      "z": 40,
      "name": "Soil_Dirt"
    },
    {
      "x": -38,
      "y": 1,
      "z": -34,
      "name": "Plant_Leaves_Fir",
      "rotation": 1
    },
    {
      "x": -38,
      "y": 1,
      "z": -33,
      "name": "Plant_Leaves_Fir",
      "rotation": 1
    },
    {
      "x": -38,
      "y": 2,
      "z": -33,
      "name": "Plant_Leaves_Fir",
      "rotation": 1
    },
    {
      "x": -38,
      "y": 5,
      "z": -33,
      "name": "Plant_Leaves_Fir",
      "rotation": 1
    },
    {
      "x": -38,
      "y": 6,
      "z": -33,
      "name": "Plant_Leaves_Fir",
      "rotation": 1
    },
    {
      "x": -38,
      "y": 0,
      "z": -22,
      "name": "Rubble_Stone"
    },
    {
      "x": -38,
      "y": 0,
      "z": -1,
      "name": "Rock_Basalt",
      "rotation": 2
    },
    {
      "x": -38,
      "y": 0,
      "z": 7,
      "name": "Rubble_Stone_Medium"
    },
    {
      "x": -38,
      "y": 0,
      "z": 13,
      "name": "Rubble_Stone"
    },
    {
      "x": -38,
      "y": 0,
      "z": 16,
      "name": "Plant_Fern_Winter"
    },
    {
      "x": -38,
      "y": 0,
      "z": 17,
      "name": "Plant_Grass_Sharp_Tall"
    },
    {
      "x": -38,
      "y": 0,
      "z": 18,
      "name": "Rock_Basalt"
    },
    {
      "x": -38,
      "y": 0,
      "z": 19,
      "name": "Rock_Basalt"
    },
    {
      "x": -38,
      "y": 0,
      "z": 20,
      "name": "Plant_Fern_Winter"
    },
    {
      "x": -38,
      "y": 0,
      "z": 22,
      "name": "Plant_Fern_Winter"
    },
    {
      "x": -38,
      "y": 0,
      "z": 23,
      "name": "Plant_Grass_Sharp_Tall"
    },
    {
      "x": -38,
      "y": 0,
      "z": 28,
      "name": "Soil_Dirt"
    },
    {
      "x": -38,
      "y": 0,
      "z": 29,
      "name": "Soil_Dirt"
    },
    {
      "x": -38,
      "y": 0,
      "z": 30,
      "name": "Soil_Dirt"
    },
    {
      "x": -38,
      "y": 1,
      "z": 30,
      "name": "Plant_Crop_Mushroom_Cap_Brown",
      "components": {
        "Components": {
          "FarmingBlock": {
            "LastTickGameTime": "0001-01-01T05:30:00Z",
            "SpreadRate": 0.0
          }
        }
      }
    },
    {
      "x": -38,
      "y": 0,
      "z": 31,
      "name": "Soil_Dirt"
    },
    {
      "x": -38,
      "y": 1,
      "z": 31,
      "name": "Plant_Crop_Mushroom_Cap_Brown",
      "components": {
        "Components": {
          "FarmingBlock": {
            "LastTickGameTime": "0001-01-01T05:30:00Z",
            "SpreadRate": 0.0
          }
        }
      }
    },
    {
      "x": -38,
      "y": 0,
      "z": 32,
      "name": "Soil_Dirt"
    },
    {
      "x": -38,
      "y": 0,
      "z": 33,
      "name": "Soil_Dirt"
    },
    {
      "x": -38,
      "y": 0,
      "z": 34,
      "name": "Soil_Dirt"
    },
    {
      "x": -38,
      "y": 0,
      "z": 35,
      "name": "Soil_Dirt"
    },
    {
      "x": -38,
      "y": 0,
      "z": 36,
      "name": "Soil_Dirt"
    },
    {
      "x": -38,
      "y": 0,
      "z": 37,
      "name": "Soil_Dirt"
    },
    {
      "x": -38,
      "y": 0,
      "z": 38,
      "name": "Soil_Dirt"
    },
    {
      "x": -38,
      "y": 0,
      "z": 39,
      "name": "Soil_Dirt"
    },
    {
      "x": -38,
      "y": 0,
      "z": 40,
      "name": "Soil_Dirt"
    },
    {
      "x": -37,
      "y": 1,
      "z": -33,
      "name": "Plant_Leaves_Fir",
      "rotation": 1
    },
    {
      "x": -37,
      "y": 0,
      "z": -25,
      "name": "Rubble_Stone"
    },
    {
      "x": -37,
      "y": 0,
      "z": 14,
      "name": "Plant_Fern_Winter"
    },
    {
      "x": -37,
      "y": 0,
      "z": 27,
      "name": "Soil_Dirt"
    },
    {
      "x": -37,
      "y": 0,
      "z": 28,
      "name": "Soil_Dirt"
    },
    {
      "x": -37,
      "y": 0,
      "z": 29,
      "name": "Soil_Dirt"
    },
    {
      "x": -37,
      "y": 0,
      "z": 30,
      "name": "Soil_Dirt"
    },
    {
      "x": -37,
      "y": 0,
      "z": 31,
      "name": "Soil_Dirt"
    },
    {
      "x": -37,
      "y": 0,
      "z": 32,
      "name": "Soil_Dirt"
    },
    {
      "x": -37,
      "y": 0,
      "z": 33,
      "name": "Soil_Dirt"
    },
    {
      "x": -37,
      "y": 0,
      "z": 34,
      "name": "Soil_Dirt"
    },
    {
      "x": -37,
      "y": 0,
      "z": 35,
      "name": "Soil_Dirt"
    },
    {
      "x": -37,
      "y": 0,
      "z": 36,
      "name": "Soil_Dirt"
    },
    {
      "x": -37,
      "y": 0,
      "z": 37,
      "name": "Soil_Dirt"
    },
    {
      "x": -37,
      "y": 0,
      "z": 38,
      "name": "Soil_Dirt"
    },
    {
      "x": -37,
      "y": 0,
      "z": 39,
      "name": "Soil_Dirt"
    },
    {
      "x": -37,
      "y": 0,
      "z": 40,
      "name": "Soil_Dirt"
    },
    {
      "x": -36,
      "y": 0,
      "z": 7,
      "name": "Rubble_Stone"
    },
    {
      "x": -36,
      "y": 0,
      "z": 13,
      "name": "Rubble_Stone"
    },
    {
      "x": -36,
      "y": 0,
      "z": 17,
      "name": "Plant_Fern_Winter"
    },
    {
      "x": -36,
      "y": 0,
      "z": 26,
      "name": "Soil_Dirt"
    },
    {
      "x": -36,
      "y": 0,
      "z": 27,
      "name": "Soil_Dirt"
    },
    {
      "x": -36,
      "y": 0,
      "z": 28,
      "name": "Soil_Dirt"
    },
    {
      "x": -36,
      "y": 0,
      "z": 29,
      "name": "Soil_Dirt"
    },
    {
      "x": -36,
      "y": 0,
      "z": 30,
      "name": "Soil_Dirt"
    },
    {
      "x": -36,
      "y": 1,
      "z": 30,
      "name": "Plant_Crop_Mushroom_Common_Brown",
      "components": {
        "Components": {
          "FarmingBlock": {
            "LastTickGameTime": "0001-01-01T05:30:00Z",
            "SpreadRate": 0.0
          }
        }
      }
    },
    {
      "x": -36,
      "y": 0,
      "z": 31,
      "name": "Soil_Dirt"
    },
    {
      "x": -36,
      "y": 0,
      "z": 32,
      "name": "Soil_Dirt"
    },
    {
      "x": -36,
      "y": 1,
      "z": 32,
      "name": "Plant_Crop_Mushroom_Cap_Brown",
      "components": {
        "Components": {
          "FarmingBlock": {
            "LastTickGameTime": "0001-01-01T05:30:00Z",
            "SpreadRate": 0.0
          }
        }
      }
    },
    {
      "x": -36,
      "y": 0,
      "z": 33,
      "name": "Soil_Dirt"
    },
    {
      "x": -36,
      "y": 0,
      "z": 34,
      "name": "Soil_Dirt"
    },
    {
      "x": -36,
      "y": 0,
      "z": 35,
      "name": "Soil_Dirt"
    },
    {
      "x": -36,
      "y": 0,
      "z": 36,
      "name": "Soil_Dirt"
    },
    {
      "x": -36,
      "y": 0,
      "z": 37,
      "name": "Soil_Dirt"
    },
    {
      "x": -36,
      "y": 0,
      "z": 38,
      "name": "Soil_Dirt"
    },
    {
      "x": -36,
      "y": 0,
      "z": 39,
      "name": "Soil_Dirt"
    },
    {
      "x": -36,
      "y": 0,
      "z": 40,
      "name": "Soil_Dirt"
    },
    {
      "x": -35,
      "y": 5,
      "z": -37,
      "name": "Plant_Leaves_Cedar",
      "rotation": 1
    },
    {
      "x": -35,
      "y": 5,
      "z": -36,
      "name": "Plant_Leaves_Cedar",
      "rotation": 1
    },
    {
      "x": -35,
      "y": 6,
      "z": -36,
      "name": "Plant_Leaves_Cedar",
      "rotation": 1
    },
    {
      "x": -35,
      "y": 5,
      "z": -35,
      "name": "Plant_Leaves_Cedar",
      "rotation": 1
    },
    {
      "x": -35,
      "y": 0,
      "z": -16,
      "name": "Rubble_Stone_Medium"
    },
    {
      "x": -35,
      "y": 0,
      "z": -10,
      "name": "Plant_Fern_Winter"
    },
    {
      "x": -35,
      "y": 0,
      "z": -8,
      "name": "Plant_Fern_Winter"
    },
    {
      "x": -35,
      "y": 0,
      "z": 7,
      "name": "Rubble_Stone"
    },
    {
      "x": -35,
      "y": 0,
      "z": 8,
      "name": "Rubble_Stone"
    },
    {
      "x": -35,
      "y": 0,
      "z": 14,
      "name": "Plant_Crop_Mushroom_Common_Brown",
      "components": {
        "Components": {
          "FarmingBlock": {
            "LastTickGameTime": "0001-01-01T05:30:00Z",
            "SpreadRate": 0.0
          }
        }
      }
    },
    {
      "x": -35,
      "y": 0,
      "z": 17,
      "name": "Plant_Crop_Mushroom_Cap_Brown",
      "components": {
        "Components": {
          "FarmingBlock": {
            "LastTickGameTime": "0001-01-01T05:30:00Z",
            "SpreadRate": 0.0
          }
        }
      }
    },
    {
      "x": -35,
      "y": 0,
      "z": 25,
      "name": "Soil_Dirt"
    },
    {
      "x": -35,
      "y": 0,
      "z": 26,
      "name": "Soil_Dirt"
    },
    {
      "x": -35,
      "y": 0,
      "z": 27,
      "name": "Soil_Dirt"
    },
    {
      "x": -35,
      "y": 0,
      "z": 28,
      "name": "Soil_Dirt"
    },
    {
      "x": -35,
      "y": 0,
      "z": 29,
      "name": "Soil_Dirt"
    },
    {
      "x": -35,
      "y": 0,
      "z": 30,
      "name": "Soil_Dirt"
    },
    {
      "x": -35,
      "y": 0,
      "z": 31,
      "name": "Soil_Dirt"
    },
    {
      "x": -35,
      "y": 0,
      "z": 32,
      "name": "Soil_Dirt"
    },
    {
      "x": -35,
      "y": 0,
      "z": 33,
      "name": "Soil_Dirt"
    },
    {
      "x": -35,
      "y": 0,
      "z": 34,
      "name": "Soil_Dirt"
    },
    {
      "x": -35,
      "y": 0,
      "z": 35,
      "name": "Soil_Dirt"
    },
    {
      "x": -35,
      "y": 0,
      "z": 36,
      "name": "Soil_Dirt"
    },
    {
      "x": -35,
      "y": 0,
      "z": 37,
      "name": "Soil_Dirt"
    },
    {
      "x": -35,
      "y": 0,
      "z": 38,
      "name": "Soil_Dirt"
    },
    {
      "x": -35,
      "y": 0,
      "z": 39,
      "name": "Soil_Dirt"
    },
    {
      "x": -35,
      "y": 0,
      "z": 40,
      "name": "Soil_Dirt"
    },
    {
      "x": -34,
      "y": 5,
      "z": -38,
      "name": "Plant_Leaves_Cedar",
      "rotation": 1
    },
    {
      "x": -34,
      "y": 9,
      "z": -38,
      "name": "Plant_Leaves_Cedar",
      "rotation": 1
    },
    {
      "x": -34,
      "y": 6,
      "z": -37,
      "name": "Plant_Leaves_Cedar",
      "rotation": 1
    },
    {
      "x": -34,
      "y": 9,
      "z": -37,
      "name": "Plant_Leaves_Cedar",
      "rotation": 1
    },
    {
      "x": -34,
      "y": 10,
      "z": -37,
      "name": "Plant_Leaves_Cedar",
      "rotation": 1
    },
    {
      "x": -34,
      "y": 6,
      "z": -36,
      "name": "Plant_Leaves_Cedar",
      "rotation": 1
    },
    {
      "x": -34,
      "y": 7,
      "z": -36,
      "name": "Plant_Leaves_Cedar",
      "rotation": 1
    },
    {
      "x": -34,
      "y": 9,
      "z": -36,
      "name": "Plant_Leaves_Cedar",
      "rotation": 1
    },
    {
      "x": -34,
      "y": 10,
      "z": -36,
      "name": "Plant_Leaves_Cedar",
      "rotation": 1
    },
    {
      "x": -34,
      "y": 6,
      "z": -35,
      "name": "Plant_Leaves_Cedar",
      "rotation": 1
    },
    {
      "x": -34,
      "y": 2,
      "z": -34,
      "name": "Plant_Leaves_Fir",
      "rotation": 3
    },
    {
      "x": -34,
      "y": 5,
      "z": -34,
      "name": "Plant_Leaves_Fir",
      "rotation": 3
    },
    {
      "x": -34,
      "y": 6,
      "z": -34,
      "name": "Plant_Leaves_Cedar",
      "rotation": 1
    },
    {
      "x": -34,
      "y": 0,
      "z": -11,
      "name": "Rubble_Stone"
    },
    {
      "x": -34,
      "y": 0,
      "z": -4,
      "name": "Plant_Bramble_Dry_Twisted"
    },
    {
      "x": -34,
      "y": 0,
      "z": 7,
      "name": "Rubble_Stone"
    },
    {
      "x": -34,
      "y": 0,
      "z": 8,
      "name": "Rubble_Stone"
    },
    {
      "x": -34,
      "y": 0,
      "z": 14,
      "name": "Plant_Crop_Mushroom_Common_Brown",
      "components": {
        "Components": {
          "FarmingBlock": {
            "LastTickGameTime": "0001-01-01T05:30:00Z",
            "SpreadRate": 0.0
          }
        }
      }
    },
    {
      "x": -34,
      "y": 0,
      "z": 15,
      "name": "Plant_Crop_Mushroom_Cap_Brown",
      "components": {
        "Components": {
          "FarmingBlock": {
            "LastTickGameTime": "0001-01-01T05:30:00Z",
            "SpreadRate": 0.0
          }
        }
      }
    },
    {
      "x": -34,
      "y": 0,
      "z": 25,
      "name": "Soil_Dirt"
    },
    {
      "x": -34,
      "y": 0,
      "z": 26,
      "name": "Soil_Dirt"
    },
    {
      "x": -34,
      "y": 0,
      "z": 27,
      "name": "Soil_Dirt"
    },
    {
      "x": -34,
      "y": 0,
      "z": 28,
      "name": "Soil_Dirt"
    },
    {
      "x": -34,
      "y": 0,
      "z": 29,
      "name": "Soil_Dirt"
    },
    {
      "x": -34,
      "y": 0,
      "z": 30,
      "name": "Soil_Dirt"
    },
    {
      "x": -34,
      "y": 0,
      "z": 31,
      "name": "Soil_Dirt"
    },
    {
      "x": -34,
      "y": 0,
      "z": 32,
      "name": "Soil_Dirt"
    },
    {
      "x": -34,
      "y": 0,
      "z": 33,
      "name": "Soil_Dirt"
    },
    {
      "x": -34,
      "y": 0,
      "z": 34,
      "name": "Soil_Dirt"
    },
    {
      "x": -34,
      "y": 0,
      "z": 35,
      "name": "Soil_Dirt"
    },
    {
      "x": -34,
      "y": 0,
      "z": 36,
      "name": "Soil_Dirt"
    },
    {
      "x": -34,
      "y": 0,
      "z": 37,
      "name": "Soil_Dirt"
    },
    {
      "x": -34,
      "y": 0,
      "z": 38,
      "name": "Soil_Dirt"
    },
    {
      "x": -34,
      "y": 0,
      "z": 39,
      "name": "Soil_Dirt"
    },
    {
      "x": -34,
      "y": 0,
      "z": 40,
      "name": "Soil_Dirt"
    },
    {
      "x": -33,
      "y": 5,
      "z": -38,
      "name": "Plant_Leaves_Cedar",
      "rotation": 1
    },
    {
      "x": -33,
      "y": 9,
      "z": -38,
      "name": "Plant_Leaves_Cedar",
      "rotation": 1
    },
    {
      "x": -33,
      "y": 7,
      "z": -37,
      "name": "Plant_Leaves_Cedar",
      "rotation": 1
    },
    {
      "x": -33,
      "y": 10,
      "z": -37,
      "name": "Plant_Leaves_Cedar",
      "rotation": 1
    },
    {
      "x": -33,
      "y": 12,
      "z": -37,
      "name": "Plant_Leaves_Cedar",
      "rotation": 1
    },
    {
      "x": -33,
      "y": 13,
      "z": -37,
      "name": "Plant_Leaves_Cedar",
      "rotation": 1
    },
    {
      "x": -33,
      "y": 3,
      "z": -36,
      "name": "Wood_Cedar_Branch_Long",
      "rotation": 5
    },
    {
      "x": -33,
      "y": 6,
      "z": -36,
      "name": "Wood_Cedar_Branch_Long",
      "rotation": 5
    },
    {
      "x": -33,
      "y": 7,
      "z": -36,
      "name": "Wood_Cedar_Branch_Short",
      "rotation": 3
    },
    {
      "x": -33,
      "y": 10,
      "z": -36,
      "name": "Wood_Cedar_Branch_Long",
      "rotation": 5
    },
    {
      "x": -33,
      "y": 11,
      "z": -36,
      "name": "Plant_Leaves_Cedar",
      "rotation": 1
    },
    {
      "x": -33,
      "y": 12,
      "z": -36,
      "name": "Plant_Leaves_Cedar",
      "rotation": 1
    },
    {
      "x": -33,
      "y": 13,
      "z": -36,
      "name": "Plant_Leaves_Cedar",
      "rotation": 1
    },
    {
      "x": -33,
      "y": 14,
      "z": -36,
      "name": "Plant_Leaves_Cedar",
      "rotation": 1
    },
    {
      "x": -33,
      "y": 15,
      "z": -36,
      "name": "Plant_Leaves_Cedar",
      "rotation": 1
    },
    {
      "x": -33,
      "y": 16,
      "z": -36,
      "name": "Plant_Leaves_Cedar",
      "rotation": 1
    },
    {
      "x": -33,
      "y": 7,
      "z": -35,
      "name": "Plant_Leaves_Cedar",
      "rotation": 1
    },
    {
      "x": -33,
      "y": 9,
      "z": -35,
      "name": "Plant_Leaves_Cedar",
      "rotation": 1
    },
    {
      "x": -33,
      "y": 12,
      "z": -35,
      "name": "Plant_Leaves_Cedar",
      "rotation": 1
    },
    {
      "x": -33,
      "y": 13,
      "z": -35,
      "name": "Plant_Leaves_Cedar",
      "rotation": 1
    },
    {
      "x": -33,
      "y": 0,
      "z": -34,
      "name": "Soil_Dirt",
      "rotation": 1
    },
    {
      "x": -33,
      "y": 1,
      "z": -34,
      "name": "Plant_Grass_Sharp_Tall",
      "rotation": 1
    },
    {
      "x": -33,
      "y": 2,
      "z": -34,
      "name": "Plant_Grass_Sharp_Tall",
      "filler": 1024,
      "rotation": 1
    },
    {
      "x": -33,
      "y": 6,
      "z": -34,
      "name": "Plant_Leaves_Cedar",
      "rotation": 1
    },
    {
      "x": -33,
      "y": 7,
      "z": -34,
      "name": "Plant_Leaves_Fir",
      "rotation": 3
    },
    {
      "x": -33,
      "y": 9,
      "z": -34,
      "name": "Plant_Leaves_Cedar",
      "rotation": 1
    },
    {
      "x": -33,
      "y": 12,
      "z": -34,
      "name": "Plant_Leaves_Cedar",
      "rotation": 1
    },
    {
      "x": -33,
      "y": 0,
      "z": -33,
      "name": "Soil_Dirt",
      "rotation": 1
    },
    {
      "x": -33,
      "y": 1,
      "z": -33,
      "name": "Soil_Dirt",
      "rotation": 1
    },
    {
      "x": -33,
      "y": 2,
      "z": -33,
      "name": "Plant_Leaves_Fir"
    },
    {
      "x": -33,
      "y": 5,
      "z": -33,
      "name": "Plant_Leaves_Fir"
    },
    {
      "x": -33,
      "y": 0,
      "z": -32,
      "name": "Soil_Dirt",
      "rotation": 1
    },
    {
      "x": -33,
      "y": 1,
      "z": -32,
      "name": "Soil_Dirt",
      "rotation": 1
    },
    {
      "x": -33,
      "y": 2,
      "z": -32,
      "name": "Plant_Grass_Sharp_Tall",
      "rotation": 1
    },
    {
      "x": -33,
      "y": 3,
      "z": -32,
      "name": "Plant_Grass_Sharp_Tall",
      "filler": 1024,
      "rotation": 1
    },
    {
      "x": -33,
      "y": 0,
      "z": -31,
      "name": "Rock_Basalt",
      "rotation": 1
    },
    {
      "x": -33,
      "y": 1,
      "z": -31,
      "name": "Rock_Basalt",
      "rotation": 1
    },
    {
      "x": -33,
      "y": 0,
      "z": -7,
      "name": "Rubble_Stone"
    },
    {
      "x": -33,
      "y": 0,
      "z": -5,
      "name": "Plant_Bramble_Dry_Twisted"
    },
    {
      "x": -33,
      "y": 0,
      "z": 15,
      "name": "Plant_Crop_Mushroom_Common_Brown",
      "components": {
        "Components": {
          "FarmingBlock": {
            "LastTickGameTime": "0001-01-01T05:30:00Z",
            "SpreadRate": 0.0
          }
        }
      }
    },
    {
      "x": -33,
      "y": 0,
      "z": 24,
      "name": "Soil_Dirt"
    },
    {
      "x": -33,
      "y": 0,
      "z": 25,
      "name": "Soil_Dirt"
    },
    {
      "x": -33,
      "y": 0,
      "z": 26,
      "name": "Soil_Dirt"
    },
    {
      "x": -33,
      "y": 0,
      "z": 27,
      "name": "Soil_Dirt"
    },
    {
      "x": -33,
      "y": 0,
      "z": 28,
      "name": "Soil_Dirt"
    },
    {
      "x": -33,
      "y": 0,
      "z": 29,
      "name": "Soil_Dirt"
    },
    {
      "x": -33,
      "y": 0,
      "z": 30,
      "name": "Soil_Dirt"
    },
    {
      "x": -33,
      "y": 0,
      "z": 31,
      "name": "Soil_Dirt"
    },
    {
      "x": -33,
      "y": 0,
      "z": 32,
      "name": "Soil_Dirt"
    },
    {
      "x": -33,
      "y": 0,
      "z": 33,
      "name": "Soil_Dirt"
    },
    {
      "x": -33,
      "y": 0,
      "z": 34,
      "name": "Soil_Dirt"
    },
    {
      "x": -33,
      "y": 0,
      "z": 35,
      "name": "Soil_Dirt"
    },
    {
      "x": -33,
      "y": 0,
      "z": 36,
      "name": "Soil_Dirt"
    },
    {
      "x": -33,
      "y": 0,
      "z": 37,
      "name": "Soil_Dirt"
    },
    {
      "x": -33,
      "y": 0,
      "z": 38,
      "name": "Soil_Dirt"
    },
    {
      "x": -33,
      "y": 0,
      "z": 39,
      "name": "Soil_Dirt"
    },
    {
      "x": -33,
      "y": 0,
      "z": 40,
      "name": "Soil_Dirt"
    },
    {
      "x": -32,
      "y": 5,
      "z": -38,
      "name": "Plant_Leaves_Cedar",
      "rotation": 1
    },
    {
      "x": -32,
      "y": 6,
      "z": -38,
      "name": "Plant_Leaves_Cedar",
      "rotation": 1
    },
    {
      "x": -32,
      "y": 9,
      "z": -38,
      "name": "Plant_Leaves_Cedar",
      "rotation": 1
    },
    {
      "x": -32,
      "y": 10,
      "z": -38,
      "name": "Plant_Leaves_Cedar",
      "rotation": 1
    },
    {
      "x": -32,
      "y": 1,
      "z": -37,
      "name": "Plant_Leaves_Fir",
      "rotation": 2
    },
    {
      "x": -32,
      "y": 6,
      "z": -37,
      "name": "Wood_Cedar_Branch_Long",
      "rotation": 6
    },
    {
      "x": -32,
      "y": 7,
      "z": -37,
      "name": "Plant_Leaves_Cedar",
      "rotation": 1
    },
    {
      "x": -32,
      "y": 9,
      "z": -37,
      "name": "Plant_Leaves_Cedar",
      "rotation": 1
    },
    {
      "x": -32,
      "y": 10,
      "z": -37,
      "name": "Plant_Leaves_Cedar",
      "rotation": 1
    },
    {
      "x": -32,
      "y": 11,
      "z": -37,
      "name": "Plant_Leaves_Cedar",
      "rotation": 1
    },
    {
      "x": -32,
      "y": 12,
      "z": -37,
      "name": "Plant_Leaves_Cedar",
      "rotation": 1
    },
    {
      "x": -32,
      "y": 13,
      "z": -37,
      "name": "Plant_Leaves_Cedar",
      "rotation": 1
    },
    {
      "x": -32,
      "y": 14,
      "z": -37,
      "name": "Plant_Leaves_Cedar",
      "rotation": 1
    },
    {
      "x": -32,
      "y": 0,
      "z": -36,
      "name": "Wood_Cedar_Trunk",
      "rotation": 1
    },
    {
      "x": -32,
      "y": 1,
      "z": -36,
      "name": "Wood_Cedar_Trunk",
      "rotation": 1
    },
    {
      "x": -32,
      "y": 2,
      "z": -36,
      "name": "Wood_Cedar_Trunk",
      "rotation": 1
    },
    {
      "x": -32,
      "y": 3,
      "z": -36,
      "name": "Wood_Cedar_Trunk",
      "rotation": 1
    },
    {
      "x": -32,
      "y": 4,
      "z": -36,
      "name": "Wood_Cedar_Trunk",
      "rotation": 1
    },
    {
      "x": -32,
      "y": 5,
      "z": -36,
      "name": "Wood_Cedar_Trunk",
      "rotation": 1
    },
    {
      "x": -32,
      "y": 6,
      "z": -36,
      "name": "Wood_Cedar_Trunk",
      "rotation": 1
    },
    {
      "x": -32,
      "y": 7,
      "z": -36,
      "name": "Wood_Cedar_Trunk",
      "rotation": 1
    },
    {
      "x": -32,
      "y": 8,
      "z": -36,
      "name": "Wood_Cedar_Trunk",
      "rotation": 1
    },
    {
      "x": -32,
      "y": 9,
      "z": -36,
      "name": "Wood_Cedar_Trunk",
      "rotation": 1
    },
    {
      "x": -32,
      "y": 10,
      "z": -36,
      "name": "Wood_Cedar_Trunk",
      "rotation": 1
    },
    {
      "x": -32,
      "y": 11,
      "z": -36,
      "name": "Wood_Cedar_Trunk",
      "rotation": 1
    },
    {
      "x": -32,
      "y": 12,
      "z": -36,
      "name": "Wood_Cedar_Branch_Long",
      "rotation": 1
    },
    {
      "x": -32,
      "y": 13,
      "z": -36,
      "name": "Wood_Cedar_Branch_Long",
      "rotation": 1
    },
    {
      "x": -32,
      "y": 14,
      "z": -36,
      "name": "Wood_Cedar_Branch_Long",
      "rotation": 1
    },
    {
      "x": -32,
      "y": 15,
      "z": -36,
      "name": "Plant_Leaves_Cedar",
      "rotation": 1
    },
    {
      "x": -32,
      "y": 16,
      "z": -36,
      "name": "Plant_Leaves_Cedar",
      "rotation": 1
    },
    {
      "x": -32,
      "y": 17,
      "z": -36,
      "name": "Plant_Leaves_Cedar",
      "rotation": 1
    },
    {
      "x": -32,
      "y": 2,
      "z": -35,
      "name": "Plant_Leaves_Fir",
      "rotation": 2
    },
    {
      "x": -32,
      "y": 3,
      "z": -35,
      "name": "Wood_Cedar_Branch_Long",
      "rotation": 6
    },
    {
      "x": -32,
      "y": 5,
      "z": -35,
      "name": "Plant_Leaves_Fir",
      "rotation": 3
    },
    {
      "x": -32,
      "y": 6,
      "z": -35,
      "name": "Wood_Cedar_Branch_Long",
      "rotation": 6
    },
    {
      "x": -32,
      "y": 7,
      "z": -35,
      "name": "Plant_Leaves_Fir",
      "rotation": 2
    },
    {
      "x": -32,
      "y": 9,
      "z": -35,
      "name": "Wood_Cedar_Branch_Long",
      "rotation": 6
    },
    {
      "x": -32,
      "y": 10,
      "z": -35,
      "name": "Plant_Leaves_Cedar",
      "rotation": 1
    },
    {
      "x": -32,
      "y": 11,
      "z": -35,
      "name": "Plant_Leaves_Cedar",
      "rotation": 1
    },
    {
      "x": -32,
      "y": 12,
      "z": -35,
      "name": "Plant_Leaves_Cedar",
      "rotation": 1
    },
    {
      "x": -32,
      "y": 13,
      "z": -35,
      "name": "Plant_Leaves_Cedar",
      "rotation": 1
    },
    {
      "x": -32,
      "y": 15,
      "z": -35,
      "name": "Plant_Leaves_Cedar",
      "rotation": 1
    },
    {
      "x": -32,
      "y": 0,
      "z": -34,
      "name": "Soil_Dirt",
      "rotation": 1
    },
    {
      "x": -32,
      "y": 2,
      "z": -34,
      "name": "Wood_Fir_Branch_Long",
      "rotation": 7
    },
    {
      "x": -32,
      "y": 3,
      "z": -34,
      "name": "Plant_Leaves_Fir",
      "rotation": 3
    },
    {
      "x": -32,
      "y": 5,
      "z": -34,
      "name": "Plant_Leaves_Cedar",
      "rotation": 1
    },
    {
      "x": -32,
      "y": 6,
      "z": -34,
      "name": "Plant_Leaves_Cedar",
      "rotation": 1
    },
    {
      "x": -32,
      "y": 7,
      "z": -34,
      "name": "Plant_Leaves_Cedar",
      "rotation": 1
    },
    {
      "x": -32,
      "y": 9,
      "z": -34,
      "name": "Plant_Leaves_Cedar",
      "rotation": 1
    },
    {
      "x": -32,
      "y": 10,
      "z": -34,
      "name": "Plant_Leaves_Cedar",
      "rotation": 1
    },
    {
      "x": -32,
      "y": 11,
      "z": -34,
      "name": "Plant_Leaves_Fir",
      "rotation": 3
    },
    {
      "x": -32,
      "y": 13,
      "z": -34,
      "name": "Plant_Leaves_Fir",
      "rotation": 3
    },
    {
      "x": -32,
      "y": 14,
      "z": -34,
      "name": "Plant_Leaves_Fir",
      "rotation": 3
    },
    {
      "x": -32,
      "y": 0,
      "z": -33,
      "name": "Soil_Dirt",
      "rotation": 1
    },
    {
      "x": -32,
      "y": 1,
      "z": -33,
      "name": "Soil_Dirt",
      "rotation": 1
    },
    {
      "x": -32,
      "y": 2,
      "z": -33,
      "name": "Soil_Dirt",
      "rotation": 1
    },
    {
      "x": -32,
      "y": 3,
      "z": -33,
      "name": "Soil_Dirt",
      "rotation": 1
    },
    {
      "x": -32,
      "y": 4,
      "z": -33,
      "name": "Plant_Leaves_Fir"
    },
    {
      "x": -32,
      "y": 6,
      "z": -33,
      "name": "Plant_Leaves_Cedar",
      "rotation": 1
    },
    {
      "x": -32,
      "y": 7,
      "z": -33,
      "name": "Plant_Leaves_Fir"
    },
    {
      "x": -32,
      "y": 9,
      "z": -33,
      "name": "Plant_Leaves_Fir",
      "rotation": 3
    },
    {
      "x": -32,
      "y": 0,
      "z": -32,
      "name": "Soil_Dirt",
      "rotation": 1
    },
    {
      "x": -32,
      "y": 1,
      "z": -32,
      "name": "Soil_Dirt",
      "rotation": 1
    },
    {
      "x": -32,
      "y": 2,
      "z": -32,
      "name": "Soil_Dirt",
      "rotation": 1
    },
    {
      "x": -32,
      "y": 3,
      "z": -32,
      "name": "Soil_Dirt",
      "rotation": 1
    },
    {
      "x": -32,
      "y": 4,
      "z": -32,
      "name": "Plant_Grass_Sharp_Tall",
      "rotation": 1
    },
    {
      "x": -32,
      "y": 5,
      "z": -32,
      "name": "Plant_Grass_Sharp_Tall",
      "filler": 1024,
      "rotation": 1
    },
    {
      "x": -32,
      "y": 0,
      "z": -31,
      "name": "Rock_Basalt",
      "rotation": 1
    },
    {
      "x": -32,
      "y": 1,
      "z": -31,
      "name": "Rock_Basalt",
      "rotation": 1
    },
    {
      "x": -32,
      "y": 2,
      "z": -31,
      "name": "Soil_Dirt",
      "rotation": 1
    },
    {
      "x": -32,
      "y": 3,
      "z": -31,
      "name": "Soil_Dirt",
      "rotation": 1
    },
    {
      "x": -32,
      "y": 4,
      "z": -31,
      "name": "Soil_Dirt",
      "rotation": 1
    },
    {
      "x": -32,
      "y": 0,
      "z": -30,
      "name": "Rock_Basalt",
      "rotation": 1
    },
    {
      "x": -32,
      "y": 1,
      "z": -30,
      "name": "Rock_Basalt",
      "rotation": 1
    },
    {
      "x": -32,
      "y": 2,
      "z": -30,
      "name": "Rock_Basalt",
      "rotation": 1
    },
    {
      "x": -32,
      "y": 3,
      "z": -30,
      "name": "Soil_Dirt",
      "rotation": 1
    },
    {
      "x": -32,
      "y": 5,
      "z": -21,
      "name": "Soil_Dirt",
      "rotation": 1
    },
    {
      "x": -32,
      "y": 6,
      "z": -21,
      "name": "Soil_Snow",
      "rotation": 1
    },
    {
      "x": -32,
      "y": 4,
      "z": -20,
      "name": "Soil_Dirt",
      "rotation": 1
    },
    {
      "x": -32,
      "y": 5,
      "z": -20,
      "name": "Rock_Stone",
      "rotation": 1
    },
    {
      "x": -32,
      "y": 6,
      "z": -20,
      "name": "Soil_Snow",
      "rotation": 1
    },
    {
      "x": -32,
      "y": 0,
      "z": -3,
      "name": "Plant_Bramble_Dry_Twisted"
    },
    {
      "x": -32,
      "y": 0,
      "z": 24,
      "name": "Soil_Dirt"
    },
    {
      "x": -32,
      "y": 0,
      "z": 25,
      "name": "Soil_Dirt"
    },
    {
      "x": -32,
      "y": 0,
      "z": 26,
      "name": "Soil_Dirt"
    },
    {
      "x": -32,
      "y": 0,
      "z": 27,
      "name": "Soil_Dirt"
    },
    {
      "x": -32,
      "y": 0,
      "z": 28,
      "name": "Soil_Dirt"
    },
    {
      "x": -32,
      "y": 0,
      "z": 29,
      "name": "Soil_Dirt"
    },
    {
      "x": -32,
      "y": 0,
      "z": 30,
      "name": "Soil_Dirt"
    },
    {
      "x": -32,
      "y": 0,
      "z": 31,
      "name": "Soil_Dirt"
    },
    {
      "x": -32,
      "y": 0,
      "z": 32,
      "name": "Soil_Dirt"
    },
    {
      "x": -32,
      "y": 0,
      "z": 33,
      "name": "Soil_Dirt"
    },
    {
      "x": -32,
      "y": 0,
      "z": 34,
      "name": "Soil_Dirt"
    },
    {
      "x": -32,
      "y": 0,
      "z": 35,
      "name": "Soil_Dirt"
    },
    {
      "x": -32,
      "y": 0,
      "z": 36,
      "name": "Soil_Dirt"
    },
    {
      "x": -32,
      "y": 0,
      "z": 37,
      "name": "Soil_Dirt"
    },
    {
      "x": -32,
      "y": 0,
      "z": 38,
      "name": "Soil_Dirt"
    },
    {
      "x": -32,
      "y": 0,
      "z": 39,
      "name": "Soil_Dirt"
    },
    {
      "x": -32,
      "y": 0,
      "z": 40,
      "name": "Soil_Dirt"
    },
    {
      "x": -31,
      "y": 1,
      "z": -38,
      "name": "Plant_Leaves_Fir",
      "rotation": 2
    },
    {
      "x": -31,
      "y": 6,
      "z": -38,
      "name": "Plant_Leaves_Cedar",
      "rotation": 1
    },
    {
      "x": -31,
      "y": 9,
      "z": -38,
      "name": "Plant_Leaves_Cedar",
      "rotation": 1
    },
    {
      "x": -31,
      "y": 1,
      "z": -37,
      "name": "Plant_Leaves_Fir",
      "rotation": 2
    },
    {
      "x": -31,
      "y": 2,
      "z": -37,
      "name": "Plant_Leaves_Fir",
      "rotation": 2
    },
    {
      "x": -31,
      "y": 5,
      "z": -37,
      "name": "Plant_Leaves_Fir",
      "rotation": 2
    },
    {
      "x": -31,
      "y": 6,
      "z": -37,
      "name": "Plant_Leaves_Cedar",
      "rotation": 1
    },
    {
      "x": -31,
      "y": 7,
      "z": -37,
      "name": "Plant_Leaves_Cedar",
      "rotation": 1
    },
    {
      "x": -31,
      "y": 10,
      "z": -37,
      "name": "Plant_Leaves_Cedar",
      "rotation": 1
    },
    {
      "x": -31,
      "y": 12,
      "z": -37,
      "name": "Plant_Leaves_Cedar",
      "rotation": 1
    },
    {
      "x": -31,
      "y": 2,
      "z": -36,
      "name": "Plant_Leaves_Fir",
      "rotation": 2
    },
    {
      "x": -31,
      "y": 6,
      "z": -36,
      "name": "Plant_Leaves_Cedar",
      "rotation": 1
    },
    {
      "x": -31,
      "y": 7,
      "z": -36,
      "name": "Plant_Leaves_Fir",
      "rotation": 2
    },
    {
      "x": -31,
      "y": 9,
      "z": -36,
      "name": "Wood_Cedar_Branch_Long",
      "rotation": 5
    },
    {
      "x": -31,
      "y": 10,
      "z": -36,
      "name": "Plant_Leaves_Cedar",
      "rotation": 1
    },
    {
      "x": -31,
      "y": 11,
      "z": -36,
      "name": "Plant_Leaves_Cedar",
      "rotation": 1
    },
    {
      "x": -31,
      "y": 12,
      "z": -36,
      "name": "Plant_Leaves_Cedar",
      "rotation": 1
    },
    {
      "x": -31,
      "y": 13,
      "z": -36,
      "name": "Plant_Leaves_Cedar",
      "rotation": 1
    },
    {
      "x": -31,
      "y": 15,
      "z": -36,
      "name": "Plant_Leaves_Cedar",
      "rotation": 1
    },
    {
      "x": -31,
      "y": 0,
      "z": -35,
      "name": "Plant_Grass_Sharp_Tall",
      "rotation": 1
    },
    {
      "x": -31,
      "y": 1,
      "z": -35,
      "name": "Plant_Grass_Sharp_Tall",
      "filler": 1024,
      "rotation": 1
    },
    {
      "x": -31,
      "y": 3,
      "z": -35,
      "name": "Plant_Leaves_Fir",
      "rotation": 2
    },
    {
      "x": -31,
      "y": 4,
      "z": -35,
      "name": "Wood_Fir_Branch_Corner",
      "rotation": 2
    },
    {
      "x": -31,
      "y": 5,
      "z": -35,
      "name": "Plant_Leaves_Fir",
      "rotation": 2
    },
    {
      "x": -31,
      "y": 6,
      "z": -35,
      "name": "Plant_Leaves_Fir",
      "rotation": 2
    },
    {
      "x": -31,
      "y": 7,
      "z": -35,
      "name": "Wood_Fir_Branch_Corner",
      "rotation": 2
    },
    {
      "x": -31,
      "y": 9,
      "z": -35,
      "name": "Plant_Leaves_Cedar",
      "rotation": 1
    },
    {
      "x": -31,
      "y": 10,
      "z": -35,
      "name": "Plant_Leaves_Cedar",
      "rotation": 1
    },
    {
      "x": -31,
      "y": 12,
      "z": -35,
      "name": "Plant_Leaves_Cedar",
      "rotation": 1
    },
    {
      "x": -31,
      "y": 13,
      "z": -35,
      "name": "Plant_Leaves_Cedar",
      "rotation": 1
    },
    {
      "x": -31,
      "y": 14,
      "z": -35,
      "name": "Plant_Leaves_Cedar",
      "rotation": 1
    },
    {
      "x": -31,
      "y": 0,
      "z": -34,
      "name": "Wood_Fir_Trunk",
      "rotation": 3
    },
    {
      "x": -31,
      "y": 1,
      "z": -34,
      "name": "Wood_Fir_Trunk",
      "rotation": 3
    },
    {
      "x": -31,
      "y": 2,
      "z": -34,
      "name": "Wood_Fir_Trunk",
      "rotation": 3
    },
    {
      "x": -31,
      "y": 3,
      "z": -34,
      "name": "Wood_Fir_Trunk",
      "rotation": 3
    },
    {
      "x": -31,
      "y": 4,
      "z": -34,
      "name": "Wood_Fir_Trunk",
      "rotation": 3
    },
    {
      "x": -31,
      "y": 5,
      "z": -34,
      "name": "Wood_Fir_Trunk",
      "rotation": 3
    },
    {
      "x": -31,
      "y": 6,
      "z": -34,
      "name": "Wood_Fir_Trunk",
      "rotation": 3
    },
    {
      "x": -31,
      "y": 7,
      "z": -34,
      "name": "Wood_Fir_Trunk_Full",
      "rotation": 3
    },
    {
      "x": -31,
      "y": 8,
      "z": -34,
      "name": "Wood_Fir_Branch_Long",
      "rotation": 3
    },
    {
      "x": -31,
      "y": 9,
      "z": -34,
      "name": "Wood_Fir_Branch_Long",
      "rotation": 3
    },
    {
      "x": -31,
      "y": 10,
      "z": -34,
      "name": "Wood_Fir_Branch_Long",
      "rotation": 3
    },
    {
      "x": -31,
      "y": 11,
      "z": -34,
      "name": "Plant_Leaves_Fir_Tip",
      "rotation": 3
    },
    {
      "x": -31,
      "y": 12,
      "z": -34,
      "name": "Plant_Leaves_Fir_Tip",
      "rotation": 3
    },
    {
      "x": -31,
      "y": 13,
      "z": -34,
      "name": "Plant_Leaves_Fir_Tip",
      "rotation": 3
    },
    {
      "x": -31,
      "y": 14,
      "z": -34,
      "name": "Plant_Leaves_Fir_Tip",
      "rotation": 3
    },
    {
      "x": -31,
      "y": 15,
      "z": -34,
      "name": "Plant_Leaves_Fir_Tip",
      "rotation": 3
    },
    {
      "x": -31,
      "y": 16,
      "z": -34,
      "name": "Plant_Leaves_Fir_Tip",
      "rotation": 3
    },
    {
      "x": -31,
      "y": 17,
      "z": -34,
      "name": "Plant_Leaves_Fir_Tip",
      "rotation": 3
    },
    {
      "x": -31,
      "y": 0,
      "z": -33,
      "name": "Soil_Dirt",
      "rotation": 1
    },
    {
      "x": -31,
      "y": 1,
      "z": -33,
      "name": "Soil_Dirt",
      "rotation": 1
    },
    {
      "x": -31,
      "y": 2,
      "z": -33,
      "name": "Soil_Dirt",
      "rotation": 1
    },
    {
      "x": -31,
      "y": 3,
      "z": -33,
      "name": "Soil_Dirt",
      "rotation": 1
    },
    {
      "x": -31,
      "y": 4,
      "z": -33,
      "name": "Plant_Leaves_Fir"
    },
    {
      "x": -31,
      "y": 6,
      "z": -33,
      "name": "Plant_Leaves_Fir"
    },
    {
      "x": -31,
      "y": 7,
      "z": -33,
      "name": "Plant_Leaves_Fir"
    },
    {
      "x": -31,
      "y": 9,
      "z": -33,
      "name": "Plant_Leaves_Fir"
    },
    {
      "x": -31,
      "y": 10,
      "z": -33,
      "name": "Plant_Leaves_Fir"
    },
    {
      "x": -31,
      "y": 12,
      "z": -33,
      "name": "Plant_Leaves_Fir"
    },
    {
      "x": -31,
      "y": 13,
      "z": -33,
      "name": "Plant_Leaves_Fir"
    },
    {
      "x": -31,
      "y": 0,
      "z": -32,
      "name": "Soil_Dirt",
      "rotation": 1
    },
    {
      "x": -31,
      "y": 1,
      "z": -32,
      "name": "Soil_Dirt",
      "rotation": 1
    },
    {
      "x": -31,
      "y": 2,
      "z": -32,
      "name": "Soil_Dirt",
      "rotation": 1
    },
    {
      "x": -31,
      "y": 3,
      "z": -32,
      "name": "Soil_Dirt",
      "rotation": 1
    },
    {
      "x": -31,
      "y": 5,
      "z": -32,
      "name": "Plant_Leaves_Fir"
    },
    {
      "x": -31,
      "y": 6,
      "z": -32,
      "name": "Plant_Leaves_Fir"
    },
    {
      "x": -31,
      "y": 9,
      "z": -32,
      "name": "Plant_Leaves_Fir"
    },
    {
      "x": -31,
      "y": 0,
      "z": -31,
      "name": "Rock_Basalt",
      "rotation": 1
    },
    {
      "x": -31,
      "y": 1,
      "z": -31,
      "name": "Soil_Dirt",
      "rotation": 1
    },
    {
      "x": -31,
      "y": 2,
      "z": -31,
      "name": "Soil_Dirt",
      "rotation": 1
    },
    {
      "x": -31,
      "y": 3,
      "z": -31,
      "name": "Soil_Dirt",
      "rotation": 1
    },
    {
      "x": -31,
      "y": 4,
      "z": -31,
      "name": "Soil_Dirt",
      "rotation": 1
    },
    {
      "x": -31,
      "y": 5,
      "z": -31,
      "name": "Soil_Dirt",
      "rotation": 1
    },
    {
      "x": -31,
      "y": 6,
      "z": -31,
      "name": "Plant_Grass_Sharp_Tall",
      "rotation": 1
    },
    {
      "x": -31,
      "y": 7,
      "z": -31,
      "name": "Plant_Grass_Sharp_Tall",
      "filler": 1024,
      "rotation": 1
    },
    {
      "x": -31,
      "y": 0,
      "z": -30,
      "name": "Rock_Basalt",
      "rotation": 1
    },
    {
      "x": -31,
      "y": 1,
      "z": -30,
      "name": "Rock_Basalt",
      "rotation": 1
    },
    {
      "x": -31,
      "y": 2,
      "z": -30,
      "name": "Soil_Dirt",
      "rotation": 1
    },
    {
      "x": -31,
      "y": 3,
      "z": -30,
      "name": "Soil_Dirt",
      "rotation": 1
    },
    {
      "x": -31,
      "y": 4,
      "z": -30,
      "name": "Soil_Dirt",
      "rotation": 1
    },
    {
      "x": -31,
      "y": 5,
      "z": -30,
      "name": "Soil_Dirt",
      "rotation": 1
    },
    {
      "x": -31,
      "y": 6,
      "z": -30,
      "name": "Plant_Fern_Winter",
      "rotation": 1
    },
    {
      "x": -31,
      "y": 1,
      "z": -29,
      "name": "Plant_Leaves_Fir"
    },
    {
      "x": -31,
      "y": 5,
      "z": -29,
      "name": "Soil_Dirt",
      "rotation": 1
    },
    {
      "x": -31,
      "y": 5,
      "z": -28,
      "name": "Soil_Dirt",
      "rotation": 1
    },
    {
      "x": -31,
      "y": 6,
      "z": -28,
      "name": "Soil_Grass",
      "rotation": 1
    },
    {
      "x": -31,
      "y": 6,
      "z": -27,
      "name": "Soil_Dirt",
      "rotation": 1
    },
    {
      "x": -31,
      "y": 7,
      "z": -27,
      "name": "Plant_Grass_Sharp_Tall",
      "rotation": 1
    },
    {
      "x": -31,
      "y": 8,
      "z": -27,
      "name": "Plant_Grass_Sharp_Tall",
      "filler": 1024,
      "rotation": 1
    },
    {
      "x": -31,
      "y": 6,
      "z": -26,
      "name": "Soil_Dirt",
      "rotation": 1
    },
    {
      "x": -31,
      "y": 7,
      "z": -26,
      "name": "Soil_Dirt",
      "rotation": 1
    },
    {
      "x": -31,
      "y": 8,
      "z": -26,
      "name": "Plant_Grass_Sharp_Tall",
      "rotation": 1
    },
    {
      "x": -31,
      "y": 9,
      "z": -26,
      "name": "Plant_Grass_Sharp_Tall",
      "filler": 1024,
      "rotation": 1
    },
    {
      "x": -31,
      "y": 7,
      "z": -25,
      "name": "Soil_Dirt",
      "rotation": 1
    },
    {
      "x": -31,
      "y": 8,
      "z": -25,
      "name": "Soil_Snow",
      "rotation": 1
    },
    {
      "x": -31,
      "y": 7,
      "z": -24,
      "name": "Soil_Dirt",
      "rotation": 1
    },
    {
      "x": -31,
      "y": 8,
      "z": -24,
      "name": "Soil_Snow",
      "rotation": 1
    },
    {
      "x": -31,
      "y": 4,
      "z": -23,
      "name": "Rock_Basalt",
      "rotation": 1
    },
    {
      "x": -31,
      "y": 5,
      "z": -23,
      "name": "Soil_Dirt",
      "rotation": 1
    },
    {
      "x": -31,
      "y": 6,
      "z": -23,
      "name": "Soil_Dirt",
      "rotation": 1
    },
    {
      "x": -31,
      "y": 7,
      "z": -23,
      "name": "Soil_Snow",
      "rotation": 1
    },
    {
      "x": -31,
      "y": 8,
      "z": -23,
      "name": "Soil_Snow",
      "rotation": 1
    },
    {
      "x": -31,
      "y": 3,
      "z": -22,
      "name": "Soil_Dirt",
      "rotation": 1
    },
    {
      "x": -31,
      "y": 4,
      "z": -22,
      "name": "Soil_Dirt",
      "rotation": 1
    },
    {
      "x": -31,
      "y": 5,
      "z": -22,
      "name": "Soil_Dirt",
      "rotation": 1
    },
    {
      "x": -31,
      "y": 6,
      "z": -22,
      "name": "Soil_Dirt",
      "rotation": 1
    },
    {
      "x": -31,
      "y": 7,
      "z": -22,
      "name": "Soil_Snow",
      "rotation": 1
    },
    {
      "x": -31,
      "y": 2,
      "z": -21,
      "name": "Soil_Dirt",
      "rotation": 1
    },
    {
      "x": -31,
      "y": 3,
      "z": -21,
      "name": "Soil_Dirt",
      "rotation": 1
    },
    {
      "x": -31,
      "y": 4,
      "z": -21,
      "name": "Rock_Stone",
      "rotation": 1
    },
    {
      "x": -31,
      "y": 5,
      "z": -21,
      "name": "Rock_Stone",
      "rotation": 1
    },
    {
      "x": -31,
      "y": 6,
      "z": -21,
      "name": "Rock_Stone",
      "rotation": 1
    },
    {
      "x": -31,
      "y": 1,
      "z": -20,
      "name": "Rock_Basalt",
      "rotation": 1
    },
    {
      "x": -31,
      "y": 2,
      "z": -20,
      "name": "Soil_Dirt",
      "rotation": 1
    },
    {
      "x": -31,
      "y": 3,
      "z": -20,
      "name": "Soil_Pathway",
      "rotation": 1
    },
    {
      "x": -31,
      "y": 4,
      "z": -20,
      "name": "Rock_Stone",
      "rotation": 1
    },
    {
      "x": -31,
      "y": 5,
      "z": -20,
      "name": "Rock_Stone",
      "rotation": 1
    },
    {
      "x": -31,
      "y": 6,
      "z": -20,
      "name": "Rock_Stone",
      "rotation": 1
    },
    {
      "x": -31,
      "y": 0,
      "z": -19,
      "name": "Rock_Basalt",
      "rotation": 1
    },
    {
      "x": -31,
      "y": 1,
      "z": -19,
      "name": "Soil_Dirt",
      "rotation": 1
    },
    {
      "x": -31,
      "y": 2,
      "z": -19,
      "name": "Soil_Dirt",
      "rotation": 1
    },
    {
      "x": -31,
      "y": 3,
      "z": -19,
      "name": "Soil_Dirt",
      "rotation": 1
    },
    {
      "x": -31,
      "y": 4,
      "z": -19,
      "name": "Rock_Stone",
      "rotation": 1
    },
    {
      "x": -31,
      "y": 5,
      "z": -19,
      "name": "Rock_Stone",
      "rotation": 1
    },
    {
      "x": -31,
      "y": 6,
      "z": -19,
      "name": "Rubble_Basalt",
      "rotation": 1
    },
    {
      "x": -31,
      "y": 0,
      "z": -18,
      "name": "Rock_Basalt",
      "rotation": 1
    },
    {
      "x": -31,
      "y": 1,
      "z": -18,
      "name": "Soil_Dirt",
      "rotation": 1
    },
    {
      "x": -31,
      "y": 2,
      "z": -18,
      "name": "Soil_Dirt",
      "rotation": 1
    },
    {
      "x": -31,
      "y": 3,
      "z": -18,
      "name": "Soil_Dirt",
      "rotation": 1
    },
    {
      "x": -31,
      "y": 0,
      "z": -17,
      "name": "Rock_Basalt",
      "rotation": 1
    },
    {
      "x": -31,
      "y": 1,
      "z": -17,
      "name": "Soil_Dirt",
      "rotation": 1
    },
    {
      "x": -31,
      "y": 2,
      "z": -17,
      "name": "Plant_Grass_Sharp_Tall",
      "rotation": 1
    },
    {
      "x": -31,
      "y": 3,
      "z": -17,
      "name": "Plant_Grass_Sharp_Tall",
      "filler": 1024,
      "rotation": 1
    },
    {
      "x": -31,
      "y": 0,
      "z": -7,
      "name": "Soil_Dirt_Cold"
    },
    {
      "x": -31,
      "y": 0,
      "z": 23,
      "name": "Soil_Dirt"
    },
    {
      "x": -31,
      "y": 0,
      "z": 24,
      "name": "Soil_Dirt"
    },
    {
      "x": -31,
      "y": 0,
      "z": 25,
      "name": "Soil_Dirt"
    },
    {
      "x": -31,
      "y": 0,
      "z": 26,
      "name": "Soil_Dirt"
    },
    {
      "x": -31,
      "y": 0,
      "z": 27,
      "name": "Soil_Dirt"
    },
    {
      "x": -31,
      "y": 0,
      "z": 28,
      "name": "Soil_Dirt"
    },
    {
      "x": -31,
      "y": 1,
      "z": 28,
      "name": "Plant_Crop_Mushroom_Common_Brown",
      "components": {
        "Components": {
          "FarmingBlock": {
            "LastTickGameTime": "0001-01-01T05:30:00Z",
            "SpreadRate": 0.0
          }
        }
      }
    },
    {
      "x": -31,
      "y": 0,
      "z": 29,
      "name": "Soil_Dirt"
    },
    {
      "x": -31,
      "y": 1,
      "z": 29,
      "name": "Plant_Crop_Mushroom_Cap_Brown",
      "components": {
        "Components": {
          "FarmingBlock": {
            "LastTickGameTime": "0001-01-01T05:30:00Z",
            "SpreadRate": 0.0
          }
        }
      }
    },
    {
      "x": -31,
      "y": 0,
      "z": 30,
      "name": "Soil_Dirt"
    },
    {
      "x": -31,
      "y": 0,
      "z": 31,
      "name": "Soil_Dirt"
    },
    {
      "x": -31,
      "y": 0,
      "z": 32,
      "name": "Soil_Dirt"
    },
    {
      "x": -31,
      "y": 0,
      "z": 33,
      "name": "Soil_Dirt"
    },
    {
      "x": -31,
      "y": 0,
      "z": 34,
      "name": "Soil_Dirt"
    },
    {
      "x": -31,
      "y": 0,
      "z": 35,
      "name": "Soil_Dirt"
    },
    {
      "x": -31,
      "y": 0,
      "z": 36,
      "name": "Soil_Dirt"
    },
    {
      "x": -31,
      "y": 0,
      "z": 37,
      "name": "Soil_Dirt"
    },
    {
      "x": -31,
      "y": 0,
      "z": 38,
      "name": "Soil_Dirt"
    },
    {
      "x": -31,
      "y": 0,
      "z": 39,
      "name": "Soil_Dirt"
    },
    {
      "x": -31,
      "y": 0,
      "z": 40,
      "name": "Soil_Dirt"
    },
    {
      "x": -30,
      "y": 2,
      "z": -36,
      "name": "Plant_Leaves_Fir",
      "rotation": 2
    },
    {
      "x": -30,
      "y": 9,
      "z": -36,
      "name": "Plant_Leaves_Cedar",
      "rotation": 1
    },
    {
      "x": -30,
      "y": 10,
      "z": -36,
      "name": "Plant_Leaves_Cedar",
      "rotation": 1
    },
    {
      "x": -30,
      "y": 2,
      "z": -35,
      "name": "Plant_Leaves_Fir",
      "rotation": 2
    },
    {
      "x": -30,
      "y": 3,
      "z": -35,
      "name": "Plant_Leaves_Fir",
      "rotation": 2
    },
    {
      "x": -30,
      "y": 6,
      "z": -35,
      "name": "Plant_Leaves_Fir",
      "rotation": 2
    },
    {
      "x": -30,
      "y": 7,
      "z": -35,
      "name": "Plant_Leaves_Fir",
      "rotation": 1
    },
    {
      "x": -30,
      "y": 9,
      "z": -35,
      "name": "Plant_Leaves_Cedar",
      "rotation": 1
    },
    {
      "x": -30,
      "y": 0,
      "z": -34,
      "name": "Soil_Dirt",
      "rotation": 1
    },
    {
      "x": -30,
      "y": 1,
      "z": -34,
      "name": "Soil_Dirt",
      "rotation": 1
    },
    {
      "x": -30,
      "y": 2,
      "z": -34,
      "name": "Soil_Dirt",
      "rotation": 1
    },
    {
      "x": -30,
      "y": 3,
      "z": -34,
      "name": "Plant_Leaves_Fir",
      "rotation": 1
    },
    {
      "x": -30,
      "y": 4,
      "z": -34,
      "name": "Plant_Leaves_Fir",
      "rotation": 1
    },
    {
      "x": -30,
      "y": 6,
      "z": -34,
      "name": "Wood_Fir_Branch_Corner",
      "rotation": 1
    },
    {
      "x": -30,
      "y": 7,
      "z": -34,
      "name": "Plant_Leaves_Fir",
      "rotation": 1
    },
    {
      "x": -30,
      "y": 9,
      "z": -34,
      "name": "Plant_Leaves_Fir",
      "rotation": 1
    },
    {
      "x": -30,
      "y": 10,
      "z": -34,
      "name": "Plant_Leaves_Fir",
      "rotation": 1
    },
    {
      "x": -30,
      "y": 12,
      "z": -34,
      "name": "Plant_Leaves_Fir",
      "rotation": 1
    },
    {
      "x": -30,
      "y": 0,
      "z": -33,
      "name": "Soil_Dirt",
      "rotation": 1
    },
    {
      "x": -30,
      "y": 1,
      "z": -33,
      "name": "Soil_Dirt",
      "rotation": 1
    },
    {
      "x": -30,
      "y": 2,
      "z": -33,
      "name": "Soil_Dirt",
      "rotation": 1
    },
    {
      "x": -30,
      "y": 3,
      "z": -33,
      "name": "Soil_Dirt",
      "rotation": 1
    },
    {
      "x": -30,
      "y": 4,
      "z": -33,
      "name": "Plant_Grass_Sharp_Tall",
      "rotation": 1
    },
    {
      "x": -30,
      "y": 5,
      "z": -33,
      "name": "Plant_Grass_Sharp_Tall",
      "filler": 1024,
      "rotation": 1
    },
    {
      "x": -30,
      "y": 6,
      "z": -33,
      "name": "Plant_Leaves_Fir"
    },
    {
      "x": -30,
      "y": 0,
      "z": -32,
      "name": "Soil_Dirt",
      "rotation": 1
    },
    {
      "x": -30,
      "y": 1,
      "z": -32,
      "name": "Soil_Dirt",
      "rotation": 1
    },
    {
      "x": -30,
      "y": 2,
      "z": -32,
      "name": "Soil_Dirt",
      "rotation": 1
    },
    {
      "x": -30,
      "y": 3,
      "z": -32,
      "name": "Soil_Dirt",
      "rotation": 1
    },
    {
      "x": -30,
      "y": 4,
      "z": -32,
      "name": "Soil_Dirt",
      "rotation": 1
    },
    {
      "x": -30,
      "y": 6,
      "z": -32,
      "name": "Plant_Leaves_Fir",
      "rotation": 1
    },
    {
      "x": -30,
      "y": 0,
      "z": -31,
      "name": "Rock_Basalt",
      "rotation": 1
    },
    {
      "x": -30,
      "y": 1,
      "z": -31,
      "name": "Rock_Basalt",
      "rotation": 1
    },
    {
      "x": -30,
      "y": 2,
      "z": -31,
      "name": "Soil_Dirt",
      "rotation": 1
    },
    {
      "x": -30,
      "y": 3,
      "z": -31,
      "name": "Soil_Dirt",
      "rotation": 1
    },
    {
      "x": -30,
      "y": 4,
      "z": -31,
      "name": "Soil_Dirt",
      "rotation": 1
    },
    {
      "x": -30,
      "y": 5,
      "z": -31,
      "name": "Soil_Dirt",
      "rotation": 1
    },
    {
      "x": -30,
      "y": 0,
      "z": -30,
      "name": "Rock_Basalt",
      "rotation": 1
    },
    {
      "x": -30,
      "y": 1,
      "z": -30,
      "name": "Rock_Basalt",
      "rotation": 1
    },
    {
      "x": -30,
      "y": 2,
      "z": -30,
      "name": "Soil_Dirt",
      "rotation": 1
    },
    {
      "x": -30,
      "y": 3,
      "z": -30,
      "name": "Soil_Dirt",
      "rotation": 1
    },
    {
      "x": -30,
      "y": 4,
      "z": -30,
      "name": "Soil_Dirt",
      "rotation": 1
    },
    {
      "x": -30,
      "y": 5,
      "z": -30,
      "name": "Soil_Dirt",
      "rotation": 1
    },
    {
      "x": -30,
      "y": 6,
      "z": -30,
      "name": "Soil_Grass",
      "rotation": 1
    },
    {
      "x": -30,
      "y": 2,
      "z": -29,
      "name": "Soil_Dirt",
      "rotation": 1
    },
    {
      "x": -30,
      "y": 3,
      "z": -29,
      "name": "Soil_Dirt",
      "rotation": 1
    },
    {
      "x": -30,
      "y": 4,
      "z": -29,
      "name": "Soil_Dirt",
      "rotation": 1
    },
    {
      "x": -30,
      "y": 5,
      "z": -29,
      "name": "Soil_Dirt",
      "rotation": 1
    },
    {
      "x": -30,
      "y": 6,
      "z": -29,
      "name": "Soil_Grass",
      "rotation": 1
    },
    {
      "x": -30,
      "y": 4,
      "z": -28,
      "name": "Soil_Dirt",
      "rotation": 1
    },
    {
      "x": -30,
      "y": 5,
      "z": -28,
      "name": "Soil_Dirt",
      "rotation": 1
    },
    {
      "x": -30,
      "y": 6,
      "z": -28,
      "name": "Soil_Grass",
      "rotation": 1
    },
    {
      "x": -30,
      "y": 7,
      "z": -28,
      "name": "Plant_Grass_Sharp_Tall",
      "rotation": 1
    },
    {
      "x": -30,
      "y": 8,
      "z": -28,
      "name": "Plant_Grass_Sharp_Tall",
      "filler": 1024,
      "rotation": 1
    },
    {
      "x": -30,
      "y": 4,
      "z": -27,
      "name": "Soil_Dirt",
      "rotation": 1
    },
    {
      "x": -30,
      "y": 5,
      "z": -27,
      "name": "Soil_Dirt",
      "rotation": 1
    },
    {
      "x": -30,
      "y": 6,
      "z": -27,
      "name": "Soil_Dirt",
      "rotation": 1
    },
    {
      "x": -30,
      "y": 7,
      "z": -27,
      "name": "Soil_Grass",
      "rotation": 1
    },
    {
      "x": -30,
      "y": 4,
      "z": -26,
      "name": "Soil_Dirt",
      "rotation": 1
    },
    {
      "x": -30,
      "y": 5,
      "z": -26,
      "name": "Soil_Dirt",
      "rotation": 1
    },
    {
      "x": -30,
      "y": 6,
      "z": -26,
      "name": "Soil_Dirt",
      "rotation": 1
    },
    {
      "x": -30,
      "y": 7,
      "z": -26,
      "name": "Soil_Dirt",
      "rotation": 1
    },
    {
      "x": -30,
      "y": 5,
      "z": -25,
      "name": "Soil_Dirt",
      "rotation": 1
    },
    {
      "x": -30,
      "y": 6,
      "z": -25,
      "name": "Soil_Dirt",
      "rotation": 1
    },
    {
      "x": -30,
      "y": 7,
      "z": -25,
      "name": "Soil_Dirt",
      "rotation": 1
    },
    {
      "x": -30,
      "y": 8,
      "z": -25,
      "name": "Soil_Snow",
      "rotation": 1
    },
    {
      "x": -30,
      "y": 5,
      "z": -24,
      "name": "Soil_Dirt",
      "rotation": 1
    },
    {
      "x": -30,
      "y": 6,
      "z": -24,
      "name": "Soil_Dirt",
      "rotation": 1
    },
    {
      "x": -30,
      "y": 7,
      "z": -24,
      "name": "Soil_Dirt",
      "rotation": 1
    },
    {
      "x": -30,
      "y": 8,
      "z": -24,
      "name": "Soil_Snow",
      "rotation": 1
    },
    {
      "x": -30,
      "y": 4,
      "z": -23,
      "name": "Soil_Dirt",
      "rotation": 1
    },
    {
      "x": -30,
      "y": 5,
      "z": -23,
      "name": "Soil_Dirt",
      "rotation": 1
    },
    {
      "x": -30,
      "y": 6,
      "z": -23,
      "name": "Soil_Dirt",
      "rotation": 1
    },
    {
      "x": -30,
      "y": 7,
      "z": -23,
      "name": "Soil_Dirt",
      "rotation": 1
    },
    {
      "x": -30,
      "y": 8,
      "z": -23,
      "name": "Soil_Snow",
      "rotation": 1
    },
    {
      "x": -30,
      "y": 3,
      "z": -22,
      "name": "Soil_Dirt",
      "rotation": 1
    },
    {
      "x": -30,
      "y": 4,
      "z": -22,
      "name": "Soil_Dirt",
      "rotation": 1
    },
    {
      "x": -30,
      "y": 5,
      "z": -22,
      "name": "Rock_Stone",
      "rotation": 1
    },
    {
      "x": -30,
      "y": 6,
      "z": -22,
      "name": "Soil_Dirt",
      "rotation": 1
    },
    {
      "x": -30,
      "y": 7,
      "z": -22,
      "name": "Soil_Dirt",
      "rotation": 1
    },
    {
      "x": -30,
      "y": 8,
      "z": -22,
      "name": "Soil_Snow",
      "rotation": 1
    },
    {
      "x": -30,
      "y": 2,
      "z": -21,
      "name": "Soil_Pathway",
      "rotation": 1
    },
    {
      "x": -30,
      "y": 3,
      "z": -21,
      "name": "Soil_Pathway",
      "rotation": 1
    },
    {
      "x": -30,
      "y": 4,
      "z": -21,
      "name": "Rock_Stone",
      "rotation": 1
    },
    {
      "x": -30,
      "y": 5,
      "z": -21,
      "name": "Rock_Stone",
      "rotation": 1
    },
    {
      "x": -30,
      "y": 6,
      "z": -21,
      "name": "Rock_Stone",
      "rotation": 1
    },
    {
      "x": -30,
      "y": 7,
      "z": -21,
      "name": "Soil_Snow",
      "rotation": 1
    },
    {
      "x": -30,
      "y": 0,
      "z": -20,
      "name": "Rock_Basalt",
      "rotation": 1
    },
    {
      "x": -30,
      "y": 1,
      "z": -20,
      "name": "Soil_Dirt",
      "rotation": 1
    },
    {
      "x": -30,
      "y": 2,
      "z": -20,
      "name": "Soil_Pathway",
      "rotation": 1
    },
    {
      "x": -30,
      "y": 3,
      "z": -20,
      "name": "Rock_Stone",
      "rotation": 1
    },
    {
      "x": -30,
      "y": 4,
      "z": -20,
      "name": "Rock_Stone",
      "rotation": 1
    },
    {
      "x": -30,
      "y": 5,
      "z": -20,
      "name": "Rock_Stone",
      "rotation": 1
    },
    {
      "x": -30,
      "y": 6,
      "z": -20,
      "name": "Rock_Stone_Mossy",
      "rotation": 1
    },
    {
      "x": -30,
      "y": 0,
      "z": -19,
      "name": "Rock_Basalt",
      "rotation": 1
    },
    {
      "x": -30,
      "y": 1,
      "z": -19,
      "name": "Soil_Dirt",
      "rotation": 1
    },
    {
      "x": -30,
      "y": 2,
      "z": -19,
      "name": "Soil_Pathway",
      "rotation": 1
    },
    {
      "x": -30,
      "y": 3,
      "z": -19,
      "name": "Soil_Pathway",
      "rotation": 1
    },
    {
      "x": -30,
      "y": 4,
      "z": -19,
      "name": "Rock_Stone",
      "rotation": 1
    },
    {
      "x": -30,
      "y": 5,
      "z": -19,
      "name": "Rock_Stone",
      "rotation": 1
    },
    {
      "x": -30,
      "y": 6,
      "z": -19,
      "name": "Rock_Stone",
      "rotation": 1
    },
    {
      "x": -30,
      "y": 7,
      "z": -19,
      "name": "Rubble_Basalt",
      "rotation": 1
    },
    {
      "x": -30,
      "y": 0,
      "z": -18,
      "name": "Rock_Basalt",
      "rotation": 1
    },
    {
      "x": -30,
      "y": 1,
      "z": -18,
      "name": "Soil_Dirt",
      "rotation": 1
    },
    {
      "x": -30,
      "y": 2,
      "z": -18,
      "name": "Soil_Dirt",
      "rotation": 1
    },
    {
      "x": -30,
      "y": 3,
      "z": -18,
      "name": "Soil_Dirt",
      "rotation": 1
    },
    {
      "x": -30,
      "y": 4,
      "z": -18,
      "name": "Plant_Grass_Sharp_Tall",
      "rotation": 1
    },
    {
      "x": -30,
      "y": 5,
      "z": -18,
      "name": "Plant_Grass_Sharp_Tall",
      "filler": 1024,
      "rotation": 1
    },
    {
      "x": -30,
      "y": 0,
      "z": -17,
      "name": "Rock_Basalt",
      "rotation": 1
    },
    {
      "x": -30,
      "y": 1,
      "z": -17,
      "name": "Soil_Dirt",
      "rotation": 1
    },
    {
      "x": -30,
      "y": 2,
      "z": -17,
      "name": "Soil_Dirt",
      "rotation": 1
    },
    {
      "x": -30,
      "y": 3,
      "z": -17,
      "name": "Plant_Grass_Sharp_Tall",
      "rotation": 1
    },
    {
      "x": -30,
      "y": 4,
      "z": -17,
      "name": "Plant_Grass_Sharp_Tall",
      "filler": 1024,
      "rotation": 1
    },
    {
      "x": -30,
      "y": 0,
      "z": 23,
      "name": "Soil_Dirt_Cold"
    },
    {
      "x": -30,
      "y": 0,
      "z": 24,
      "name": "Soil_Dirt_Cold"
    },
    {
      "x": -30,
      "y": 0,
      "z": 25,
      "name": "Soil_Dirt_Cold"
    },
    {
      "x": -30,
      "y": 0,
      "z": 26,
      "name": "Soil_Dirt_Cold"
    },
    {
      "x": -30,
      "y": 0,
      "z": 27,
      "name": "Soil_Dirt_Cold"
    },
    {
      "x": -30,
      "y": 0,
      "z": 28,
      "name": "Soil_Dirt"
    },
    {
      "x": -30,
      "y": 1,
      "z": 28,
      "name": "Plant_Crop_Mushroom_Cap_Brown",
      "components": {
        "Components": {
          "FarmingBlock": {
            "LastTickGameTime": "0001-01-01T05:30:00Z",
            "SpreadRate": 0.0
          }
        }
      }
    },
    {
      "x": -30,
      "y": 0,
      "z": 29,
      "name": "Soil_Dirt"
    },
    {
      "x": -30,
      "y": 0,
      "z": 30,
      "name": "Soil_Dirt"
    },
    {
      "x": -30,
      "y": 0,
      "z": 31,
      "name": "Soil_Dirt"
    },
    {
      "x": -30,
      "y": 0,
      "z": 32,
      "name": "Soil_Dirt"
    },
    {
      "x": -30,
      "y": 0,
      "z": 33,
      "name": "Soil_Dirt"
    },
    {
      "x": -30,
      "y": 0,
      "z": 34,
      "name": "Soil_Dirt"
    },
    {
      "x": -30,
      "y": 0,
      "z": 35,
      "name": "Soil_Dirt"
    },
    {
      "x": -30,
      "y": 0,
      "z": 36,
      "name": "Soil_Dirt"
    },
    {
      "x": -30,
      "y": 0,
      "z": 37,
      "name": "Soil_Dirt"
    },
    {
      "x": -30,
      "y": 0,
      "z": 38,
      "name": "Soil_Dirt"
    },
    {
      "x": -30,
      "y": 0,
      "z": 39,
      "name": "Soil_Dirt"
    },
    {
      "x": -30,
      "y": 0,
      "z": 40,
      "name": "Soil_Dirt"
    },
    {
      "x": -29,
      "y": 0,
      "z": -34,
      "name": "Soil_Dirt",
      "rotation": 1
    },
    {
      "x": -29,
      "y": 1,
      "z": -34,
      "name": "Plant_Grass_Sharp_Tall",
      "rotation": 1
    },
    {
      "x": -29,
      "y": 2,
      "z": -34,
      "name": "Plant_Grass_Sharp_Tall",
      "filler": 1024,
      "rotation": 1
    },
    {
      "x": -29,
      "y": 4,
      "z": -34,
      "name": "Plant_Leaves_Fir",
      "rotation": 1
    },
    {
      "x": -29,
      "y": 6,
      "z": -34,
      "name": "Plant_Leaves_Fir",
      "rotation": 1
    },
    {
      "x": -29,
      "y": 9,
      "z": -34,
      "name": "Plant_Leaves_Fir",
      "rotation": 1
    },
    {
      "x": -29,
      "y": 0,
      "z": -33,
      "name": "Soil_Dirt",
      "rotation": 1
    },
    {
      "x": -29,
      "y": 1,
      "z": -33,
      "name": "Soil_Dirt",
      "rotation": 1
    },
    {
      "x": -29,
      "y": 2,
      "z": -33,
      "name": "Soil_Dirt",
      "rotation": 1
    },
    {
      "x": -29,
      "y": 3,
      "z": -33,
      "name": "Plant_Leaves_Fir",
      "rotation": 1
    },
    {
      "x": -29,
      "y": 0,
      "z": -32,
      "name": "Soil_Dirt",
      "rotation": 1
    },
    {
      "x": -29,
      "y": 1,
      "z": -32,
      "name": "Soil_Dirt",
      "rotation": 1
    },
    {
      "x": -29,
      "y": 2,
      "z": -32,
      "name": "Soil_Dirt",
      "rotation": 1
    },
    {
      "x": -29,
      "y": 3,
      "z": -32,
      "name": "Soil_Dirt",
      "rotation": 1
    },
    {
      "x": -29,
      "y": 4,
      "z": -32,
      "name": "Soil_Dirt",
      "rotation": 1
    },
    {
      "x": -29,
      "y": 5,
      "z": -32,
      "name": "Plant_Grass_Sharp_Tall",
      "rotation": 1
    },
    {
      "x": -29,
      "y": 6,
      "z": -32,
      "name": "Plant_Grass_Sharp_Tall",
      "filler": 1024,
      "rotation": 1
    },
    {
      "x": -29,
      "y": 0,
      "z": -31,
      "name": "Rock_Basalt",
      "rotation": 1
    },
    {
      "x": -29,
      "y": 1,
      "z": -31,
      "name": "Soil_Dirt",
      "rotation": 1
    },
    {
      "x": -29,
      "y": 2,
      "z": -31,
      "name": "Soil_Dirt",
      "rotation": 1
    },
    {
      "x": -29,
      "y": 3,
      "z": -31,
      "name": "Soil_Dirt",
      "rotation": 1
    },
    {
      "x": -29,
      "y": 4,
      "z": -31,
      "name": "Soil_Dirt",
      "rotation": 1
    },
    {
      "x": -29,
      "y": 0,
      "z": -30,
      "name": "Rock_Basalt",
      "rotation": 1
    },
    {
      "x": -29,
      "y": 1,
      "z": -30,
      "name": "Rock_Basalt",
      "rotation": 1
    },
    {
      "x": -29,
      "y": 2,
      "z": -30,
      "name": "Soil_Dirt",
      "rotation": 1
    },
    {
      "x": -29,
      "y": 3,
      "z": -30,
      "name": "Soil_Dirt",
      "rotation": 1
    },
    {
      "x": -29,
      "y": 4,
      "z": -30,
      "name": "Soil_Dirt",
      "rotation": 1
    },
    {
      "x": -29,
      "y": 5,
      "z": -30,
      "name": "Soil_Dirt",
      "rotation": 1
    },
    {
      "x": -29,
      "y": 6,
      "z": -30,
      "name": "Soil_Grass",
      "rotation": 1
    },
    {
      "x": -29,
      "y": 3,
      "z": -29,
      "name": "Soil_Dirt",
      "rotation": 1
    },
    {
      "x": -29,
      "y": 4,
      "z": -29,
      "name": "Soil_Dirt",
      "rotation": 1
    },
    {
      "x": -29,
      "y": 5,
      "z": -29,
      "name": "Soil_Dirt",
      "rotation": 1
    },
    {
      "x": -29,
      "y": 6,
      "z": -29,
      "name": "Soil_Dirt",
      "rotation": 1
    },
    {
      "x": -29,
      "y": 7,
      "z": -29,
      "name": "Soil_Dirt",
      "rotation": 1
    },
    {
      "x": -29,
      "y": 4,
      "z": -28,
      "name": "Soil_Dirt",
      "rotation": 1
    },
    {
      "x": -29,
      "y": 5,
      "z": -28,
      "name": "Soil_Dirt",
      "rotation": 1
    },
    {
      "x": -29,
      "y": 6,
      "z": -28,
      "name": "Soil_Dirt",
      "rotation": 1
    },
    {
      "x": -29,
      "y": 7,
      "z": -28,
      "name": "Soil_Grass",
      "rotation": 1
    },
    {
      "x": -29,
      "y": 8,
      "z": -28,
      "name": "Plant_Fern_Winter",
      "rotation": 1
    },
    {
      "x": -29,
      "y": 4,
      "z": -27,
      "name": "Rock_Basalt",
      "rotation": 1
    },
    {
      "x": -29,
      "y": 5,
      "z": -27,
      "name": "Soil_Dirt",
      "rotation": 1
    },
    {
      "x": -29,
      "y": 6,
      "z": -27,
      "name": "Soil_Dirt",
      "rotation": 1
    },
    {
      "x": -29,
      "y": 7,
      "z": -27,
      "name": "Soil_Grass",
      "rotation": 1
    },
    {
      "x": -29,
      "y": 8,
      "z": -27,
      "name": "Plant_Grass_Sharp_Tall",
      "rotation": 1
    },
    {
      "x": -29,
      "y": 9,
      "z": -27,
      "name": "Plant_Grass_Sharp_Tall",
      "filler": 1024,
      "rotation": 1
    },
    {
      "x": -29,
      "y": 4,
      "z": -26,
      "name": "Rock_Basalt",
      "rotation": 1
    },
    {
      "x": -29,
      "y": 5,
      "z": -26,
      "name": "Soil_Dirt",
      "rotation": 1
    },
    {
      "x": -29,
      "y": 6,
      "z": -26,
      "name": "Soil_Dirt",
      "rotation": 1
    },
    {
      "x": -29,
      "y": 7,
      "z": -26,
      "name": "Soil_Grass",
      "rotation": 1
    },
    {
      "x": -29,
      "y": 8,
      "z": -26,
      "name": "Plant_Grass_Sharp_Tall",
      "rotation": 1
    },
    {
      "x": -29,
      "y": 9,
      "z": -26,
      "name": "Plant_Grass_Sharp_Tall",
      "filler": 1024,
      "rotation": 1
    },
    {
      "x": -29,
      "y": 4,
      "z": -25,
      "name": "Rock_Basalt",
      "rotation": 1
    },
    {
      "x": -29,
      "y": 5,
      "z": -25,
      "name": "Soil_Dirt",
      "rotation": 1
    },
    {
      "x": -29,
      "y": 6,
      "z": -25,
      "name": "Soil_Dirt",
      "rotation": 1
    },
    {
      "x": -29,
      "y": 7,
      "z": -25,
      "name": "Soil_Dirt",
      "rotation": 1
    },
    {
      "x": -29,
      "y": 8,
      "z": -25,
      "name": "Soil_Snow",
      "rotation": 1
    },
    {
      "x": -29,
      "y": 5,
      "z": -24,
      "name": "Soil_Dirt",
      "rotation": 1
    },
    {
      "x": -29,
      "y": 6,
      "z": -24,
      "name": "Soil_Dirt",
      "rotation": 1
    },
    {
      "x": -29,
      "y": 7,
      "z": -24,
      "name": "Soil_Dirt",
      "rotation": 1
    },
    {
      "x": -29,
      "y": 8,
      "z": -24,
      "name": "Soil_Snow",
      "rotation": 1
    },
    {
      "x": -29,
      "y": 4,
      "z": -23,
      "name": "Soil_Dirt",
      "rotation": 1
    },
    {
      "x": -29,
      "y": 5,
      "z": -23,
      "name": "Soil_Dirt",
      "rotation": 1
    },
    {
      "x": -29,
      "y": 6,
      "z": -23,
      "name": "Soil_Dirt",
      "rotation": 1
    },
    {
      "x": -29,
      "y": 7,
      "z": -23,
      "name": "Soil_Snow",
      "rotation": 1
    },
    {
      "x": -29,
      "y": 8,
      "z": -23,
      "name": "Soil_Snow",
      "rotation": 1
    },
    {
      "x": -29,
      "y": 4,
      "z": -22,
      "name": "Soil_Dirt",
      "rotation": 1
    },
    {
      "x": -29,
      "y": 5,
      "z": -22,
      "name": "Soil_Dirt",
      "rotation": 1
    },
    {
      "x": -29,
      "y": 6,
      "z": -22,
      "name": "Soil_Dirt",
      "rotation": 1
    },
    {
      "x": -29,
      "y": 7,
      "z": -22,
      "name": "Soil_Snow",
      "rotation": 1
    },
    {
      "x": -29,
      "y": 2,
      "z": -21,
      "name": "Soil_Pathway",
      "rotation": 1
    },
    {
      "x": -29,
      "y": 3,
      "z": -21,
      "name": "Soil_Pathway",
      "rotation": 1
    },
    {
      "x": -29,
      "y": 4,
      "z": -21,
      "name": "Rock_Stone",
      "rotation": 1
    },
    {
      "x": -29,
      "y": 5,
      "z": -21,
      "name": "Rock_Stone",
      "rotation": 1
    },
    {
      "x": -29,
      "y": 6,
      "z": -21,
      "name": "Rock_Stone",
      "rotation": 1
    },
    {
      "x": -29,
      "y": 7,
      "z": -21,
      "name": "Soil_Snow",
      "rotation": 1
    },
    {
      "x": -29,
      "y": 0,
      "z": -20,
      "name": "Rock_Basalt",
      "rotation": 1
    },
    {
      "x": -29,
      "y": 1,
      "z": -20,
      "name": "Soil_Pathway",
      "rotation": 1
    },
    {
      "x": -29,
      "y": 2,
      "z": -20,
      "name": "Soil_Pathway",
      "rotation": 1
    },
    {
      "x": -29,
      "y": 3,
      "z": -20,
      "name": "Soil_Pathway",
      "rotation": 1
    },
    {
      "x": -29,
      "y": 4,
      "z": -20,
      "name": "Rock_Stone",
      "rotation": 1
    },
    {
      "x": -29,
      "y": 5,
      "z": -20,
      "name": "Rock_Stone",
      "rotation": 1
    },
    {
      "x": -29,
      "y": 6,
      "z": -20,
      "name": "Rock_Stone_Mossy",
      "rotation": 1
    },
    {
      "x": -29,
      "y": 7,
      "z": -20,
      "name": "Rubble_Basalt",
      "rotation": 1
    },
    {
      "x": -29,
      "y": 0,
      "z": -19,
      "name": "Rock_Basalt",
      "rotation": 1
    },
    {
      "x": -29,
      "y": 1,
      "z": -19,
      "name": "Soil_Dirt",
      "rotation": 1
    },
    {
      "x": -29,
      "y": 2,
      "z": -19,
      "name": "Soil_Pathway",
      "rotation": 1
    },
    {
      "x": -29,
      "y": 3,
      "z": -19,
      "name": "Soil_Pathway",
      "rotation": 1
    },
    {
      "x": -29,
      "y": 4,
      "z": -19,
      "name": "Rock_Stone_Mossy",
      "rotation": 1
    },
    {
      "x": -29,
      "y": 5,
      "z": -19,
      "name": "Rock_Stone_Mossy",
      "rotation": 1
    },
    {
      "x": -29,
      "y": 0,
      "z": -18,
      "name": "Soil_Dirt",
      "rotation": 1
    },
    {
      "x": -29,
      "y": 1,
      "z": -18,
      "name": "Soil_Dirt",
      "rotation": 1
    },
    {
      "x": -29,
      "y": 2,
      "z": -18,
      "name": "Soil_Dirt",
      "rotation": 1
    },
    {
      "x": -29,
      "y": 3,
      "z": -18,
      "name": "Soil_Pathway",
      "rotation": 1
    },
    {
      "x": -29,
      "y": 4,
      "z": -18,
      "name": "Plant_Grass_Sharp_Tall",
      "rotation": 1
    },
    {
      "x": -29,
      "y": 5,
      "z": -18,
      "name": "Plant_Grass_Sharp_Tall",
      "filler": 1024,
      "rotation": 1
    },
    {
      "x": -29,
      "y": 0,
      "z": -17,
      "name": "Rock_Basalt",
      "rotation": 1
    },
    {
      "x": -29,
      "y": 1,
      "z": -17,
      "name": "Soil_Dirt",
      "rotation": 1
    },
    {
      "x": -29,
      "y": 2,
      "z": -17,
      "name": "Soil_Dirt",
      "rotation": 1
    },
    {
      "x": -29,
      "y": 0,
      "z": -14,
      "name": "Rubble_Stone"
    },
    {
      "x": -29,
      "y": 0,
      "z": -10,
      "name": "Soil_Dirt_Cold"
    },
    {
      "x": -29,
      "y": 0,
      "z": 22,
      "name": "Soil_Dirt_Cold"
    },
    {
      "x": -29,
      "y": 0,
      "z": 23,
      "name": "Soil_Dirt_Cold"
    },
    {
      "x": -29,
      "y": 0,
      "z": 24,
      "name": "Soil_Dirt_Cold"
    },
    {
      "x": -29,
      "y": 0,
      "z": 25,
      "name": "Soil_Dirt_Cold"
    },
    {
      "x": -29,
      "y": 0,
      "z": 26,
      "name": "Soil_Dirt_Cold"
    },
    {
      "x": -29,
      "y": 0,
      "z": 27,
      "name": "Soil_Dirt_Cold"
    },
    {
      "x": -29,
      "y": 0,
      "z": 28,
      "name": "Soil_Dirt_Cold"
    },
    {
      "x": -29,
      "y": 0,
      "z": 29,
      "name": "Soil_Dirt_Cold"
    },
    {
      "x": -29,
      "y": 0,
      "z": 30,
      "name": "Soil_Dirt_Cold"
    },
    {
      "x": -29,
      "y": 0,
      "z": 31,
      "name": "Soil_Dirt"
    },
    {
      "x": -29,
      "y": 0,
      "z": 32,
      "name": "Soil_Dirt"
    },
    {
      "x": -29,
      "y": 0,
      "z": 33,
      "name": "Soil_Dirt"
    },
    {
      "x": -29,
      "y": 0,
      "z": 34,
      "name": "Soil_Dirt"
    },
    {
      "x": -29,
      "y": 0,
      "z": 35,
      "name": "Soil_Dirt"
    },
    {
      "x": -29,
      "y": 0,
      "z": 36,
      "name": "Soil_Dirt"
    },
    {
      "x": -29,
      "y": 0,
      "z": 37,
      "name": "Soil_Dirt"
    },
    {
      "x": -29,
      "y": 0,
      "z": 38,
      "name": "Soil_Dirt"
    },
    {
      "x": -29,
      "y": 0,
      "z": 39,
      "name": "Soil_Dirt"
    },
    {
      "x": -29,
      "y": 0,
      "z": 40,
      "name": "Soil_Dirt"
    },
    {
      "x": -28,
      "y": 2,
      "z": -35,
      "name": "Plant_Leaves_Fir",
      "rotation": 1
    },
    {
      "x": -28,
      "y": 2,
      "z": -34,
      "name": "Plant_Leaves_Fir",
      "rotation": 1
    },
    {
      "x": -28,
      "y": 6,
      "z": -34,
      "name": "Plant_Leaves_Fir",
      "rotation": 1
    },
    {
      "x": -28,
      "y": 2,
      "z": -33,
      "name": "Plant_Leaves_Fir",
      "rotation": 1
    },
    {
      "x": -28,
      "y": 3,
      "z": -33,
      "name": "Plant_Leaves_Fir",
      "rotation": 1
    },
    {
      "x": -28,
      "y": 1,
      "z": -32,
      "name": "Soil_Dirt",
      "rotation": 1
    },
    {
      "x": -28,
      "y": 2,
      "z": -32,
      "name": "Soil_Dirt",
      "rotation": 1
    },
    {
      "x": -28,
      "y": 3,
      "z": -32,
      "name": "Soil_Dirt",
      "rotation": 1
    },
    {
      "x": -28,
      "y": 4,
      "z": -32,
      "name": "Plant_Grass_Sharp_Tall",
      "rotation": 1
    },
    {
      "x": -28,
      "y": 5,
      "z": -32,
      "name": "Plant_Grass_Sharp_Tall",
      "filler": 1024,
      "rotation": 1
    },
    {
      "x": -28,
      "y": 0,
      "z": -31,
      "name": "Rock_Basalt",
      "rotation": 1
    },
    {
      "x": -28,
      "y": 1,
      "z": -31,
      "name": "Rock_Basalt",
      "rotation": 1
    },
    {
      "x": -28,
      "y": 2,
      "z": -31,
      "name": "Soil_Dirt",
      "rotation": 1
    },
    {
      "x": -28,
      "y": 3,
      "z": -31,
      "name": "Soil_Dirt",
      "rotation": 1
    },
    {
      "x": -28,
      "y": 4,
      "z": -31,
      "name": "Soil_Dirt",
      "rotation": 1
    },
    {
      "x": -28,
      "y": 5,
      "z": -31,
      "name": "Plant_Fern_Winter",
      "rotation": 1
    },
    {
      "x": -28,
      "y": 0,
      "z": -30,
      "name": "Rock_Basalt",
      "rotation": 1
    },
    {
      "x": -28,
      "y": 1,
      "z": -30,
      "name": "Rock_Basalt",
      "rotation": 1
    },
    {
      "x": -28,
      "y": 2,
      "z": -30,
      "name": "Soil_Dirt",
      "rotation": 1
    },
    {
      "x": -28,
      "y": 3,
      "z": -30,
      "name": "Soil_Dirt",
      "rotation": 1
    },
    {
      "x": -28,
      "y": 4,
      "z": -30,
      "name": "Soil_Dirt",
      "rotation": 1
    },
    {
      "x": -28,
      "y": 5,
      "z": -30,
      "name": "Soil_Dirt",
      "rotation": 1
    },
    {
      "x": -28,
      "y": 6,
      "z": -30,
      "name": "Soil_Grass",
      "rotation": 1
    },
    {
      "x": -28,
      "y": 3,
      "z": -29,
      "name": "Soil_Dirt",
      "rotation": 1
    },
    {
      "x": -28,
      "y": 4,
      "z": -29,
      "name": "Soil_Dirt",
      "rotation": 1
    },
    {
      "x": -28,
      "y": 5,
      "z": -29,
      "name": "Soil_Dirt",
      "rotation": 1
    },
    {
      "x": -28,
      "y": 6,
      "z": -29,
      "name": "Soil_Grass",
      "rotation": 1
    },
    {
      "x": -28,
      "y": 7,
      "z": -29,
      "name": "Plant_Grass_Sharp_Tall",
      "rotation": 1
    },
    {
      "x": -28,
      "y": 8,
      "z": -29,
      "name": "Plant_Grass_Sharp_Tall",
      "filler": 1024,
      "rotation": 1
    },
    {
      "x": -28,
      "y": 3,
      "z": -28,
      "name": "Rock_Basalt",
      "rotation": 1
    },
    {
      "x": -28,
      "y": 4,
      "z": -28,
      "name": "Soil_Dirt",
      "rotation": 1
    },
    {
      "x": -28,
      "y": 5,
      "z": -28,
      "name": "Soil_Dirt",
      "rotation": 1
    },
    {
      "x": -28,
      "y": 6,
      "z": -28,
      "name": "Soil_Dirt",
      "rotation": 1
    },
    {
      "x": -28,
      "y": 7,
      "z": -28,
      "name": "Soil_Grass",
      "rotation": 1
    },
    {
      "x": -28,
      "y": 4,
      "z": -27,
      "name": "Rock_Basalt",
      "rotation": 1
    },
    {
      "x": -28,
      "y": 5,
      "z": -27,
      "name": "Soil_Dirt",
      "rotation": 1
    },
    {
      "x": -28,
      "y": 6,
      "z": -27,
      "name": "Soil_Dirt",
      "rotation": 1
    },
    {
      "x": -28,
      "y": 7,
      "z": -27,
      "name": "Soil_Grass",
      "rotation": 1
    },
    {
      "x": -28,
      "y": 4,
      "z": -26,
      "name": "Rock_Basalt",
      "rotation": 1
    },
    {
      "x": -28,
      "y": 5,
      "z": -26,
      "name": "Soil_Dirt",
      "rotation": 1
    },
    {
      "x": -28,
      "y": 6,
      "z": -26,
      "name": "Soil_Dirt",
      "rotation": 1
    },
    {
      "x": -28,
      "y": 7,
      "z": -26,
      "name": "Soil_Grass",
      "rotation": 1
    },
    {
      "x": -28,
      "y": 8,
      "z": -26,
      "name": "Plant_Grass_Sharp_Tall",
      "rotation": 1
    },
    {
      "x": -28,
      "y": 9,
      "z": -26,
      "name": "Plant_Grass_Sharp_Tall",
      "filler": 1024,
      "rotation": 1
    },
    {
      "x": -28,
      "y": 4,
      "z": -25,
      "name": "Soil_Dirt",
      "rotation": 1
    },
    {
      "x": -28,
      "y": 5,
      "z": -25,
      "name": "Soil_Dirt",
      "rotation": 1
    },
    {
      "x": -28,
      "y": 6,
      "z": -25,
      "name": "Soil_Dirt",
      "rotation": 1
    },
    {
      "x": -28,
      "y": 7,
      "z": -25,
      "name": "Soil_Dirt",
      "rotation": 1
    },
    {
      "x": -28,
      "y": 5,
      "z": -24,
      "name": "Soil_Dirt",
      "rotation": 1
    },
    {
      "x": -28,
      "y": 6,
      "z": -24,
      "name": "Soil_Dirt",
      "rotation": 1
    },
    {
      "x": -28,
      "y": 7,
      "z": -24,
      "name": "Soil_Dirt",
      "rotation": 1
    },
    {
      "x": -28,
      "y": 8,
      "z": -24,
      "name": "Plant_Grass_Sharp_Tall",
      "rotation": 1
    },
    {
      "x": -28,
      "y": 9,
      "z": -24,
      "name": "Plant_Grass_Sharp_Tall",
      "filler": 1024,
      "rotation": 1
    },
    {
      "x": -28,
      "y": 5,
      "z": -23,
      "name": "Soil_Dirt",
      "rotation": 1
    },
    {
      "x": -28,
      "y": 6,
      "z": -23,
      "name": "Soil_Dirt",
      "rotation": 1
    },
    {
      "x": -28,
      "y": 7,
      "z": -23,
      "name": "Plant_Grass_Sharp_Tall",
      "rotation": 1
    },
    {
      "x": -28,
      "y": 8,
      "z": -23,
      "name": "Plant_Grass_Sharp_Tall",
      "filler": 1024,
      "rotation": 1
    },
    {
      "x": -28,
      "y": 0,
      "z": -12,
      "name": "Soil_Dirt_Cold"
    },
    {
      "x": -28,
      "y": 0,
      "z": -11,
      "name": "Soil_Dirt_Cold"
    },
    {
      "x": -28,
      "y": 0,
      "z": 22,
      "name": "Soil_Dirt_Cold"
    },
    {
      "x": -28,
      "y": 0,
      "z": 23,
      "name": "Soil_Dirt_Cold"
    },
    {
      "x": -28,
      "y": 0,
      "z": 24,
      "name": "Soil_Dirt_Cold"
    },
    {
      "x": -28,
      "y": 0,
      "z": 25,
      "name": "Soil_Dirt_Cold"
    },
    {
      "x": -28,
      "y": 0,
      "z": 26,
      "name": "Soil_Dirt_Cold"
    },
    {
      "x": -28,
      "y": 0,
      "z": 27,
      "name": "Soil_Dirt_Cold"
    },
    {
      "x": -28,
      "y": 0,
      "z": 28,
      "name": "Soil_Dirt_Cold"
    },
    {
      "x": -28,
      "y": 0,
      "z": 29,
      "name": "Soil_Dirt_Cold"
    },
    {
      "x": -28,
      "y": 0,
      "z": 30,
      "name": "Soil_Dirt_Cold"
    },
    {
      "x": -28,
      "y": 0,
      "z": 31,
      "name": "Soil_Dirt_Cold"
    },
    {
      "x": -28,
      "y": 0,
      "z": 32,
      "name": "Soil_Dirt"
    },
    {
      "x": -28,
      "y": 0,
      "z": 33,
      "name": "Soil_Dirt"
    },
    {
      "x": -28,
      "y": 0,
      "z": 34,
      "name": "Soil_Dirt"
    },
    {
      "x": -28,
      "y": 0,
      "z": 35,
      "name": "Soil_Dirt"
    },
    {
      "x": -28,
      "y": 0,
      "z": 36,
      "name": "Soil_Dirt"
    },
    {
      "x": -28,
      "y": 0,
      "z": 37,
      "name": "Soil_Dirt"
    },
    {
      "x": -28,
      "y": 0,
      "z": 38,
      "name": "Soil_Dirt"
    },
    {
      "x": -28,
      "y": 1,
      "z": 38,
      "name": "Rubble_Stone"
    },
    {
      "x": -28,
      "y": 0,
      "z": 39,
      "name": "Soil_Dirt"
    },
    {
      "x": -28,
      "y": 0,
      "z": 40,
      "name": "Soil_Dirt"
    },
    {
      "x": -27,
      "y": 2,
      "z": -34,
      "name": "Plant_Leaves_Fir",
      "rotation": 1
    },
    {
      "x": -27,
      "y": 2,
      "z": -33,
      "name": "Plant_Leaves_Fir",
      "rotation": 1
    },
    {
      "x": -27,
      "y": 3,
      "z": -31,
      "name": "Soil_Dirt",
      "rotation": 1
    },
    {
      "x": -27,
      "y": 3,
      "z": -30,
      "name": "Soil_Dirt",
      "rotation": 1
    },
    {
      "x": -27,
      "y": 4,
      "z": -30,
      "name": "Soil_Dirt",
      "rotation": 1
    },
    {
      "x": -27,
      "y": 5,
      "z": -30,
      "name": "Plant_Grass_Sharp_Tall",
      "rotation": 1
    },
    {
      "x": -27,
      "y": 6,
      "z": -30,
      "name": "Plant_Grass_Sharp_Tall",
      "filler": 1024,
      "rotation": 1
    },
    {
      "x": -27,
      "y": 3,
      "z": -29,
      "name": "Soil_Dirt",
      "rotation": 1
    },
    {
      "x": -27,
      "y": 4,
      "z": -29,
      "name": "Soil_Dirt",
      "rotation": 1
    },
    {
      "x": -27,
      "y": 5,
      "z": -29,
      "name": "Soil_Dirt",
      "rotation": 1
    },
    {
      "x": -27,
      "y": 6,
      "z": -29,
      "name": "Soil_Grass",
      "rotation": 1
    },
    {
      "x": -27,
      "y": 4,
      "z": -28,
      "name": "Rock_Basalt",
      "rotation": 1
    },
    {
      "x": -27,
      "y": 5,
      "z": -28,
      "name": "Soil_Dirt",
      "rotation": 1
    },
    {
      "x": -27,
      "y": 6,
      "z": -28,
      "name": "Soil_Grass",
      "rotation": 1
    },
    {
      "x": -27,
      "y": 4,
      "z": -27,
      "name": "Rock_Basalt",
      "rotation": 1
    },
    {
      "x": -27,
      "y": 5,
      "z": -27,
      "name": "Soil_Dirt",
      "rotation": 1
    },
    {
      "x": -27,
      "y": 5,
      "z": -26,
      "name": "Soil_Dirt",
      "rotation": 1
    },
    {
      "x": -27,
      "y": 0,
      "z": 22,
      "name": "Soil_Dirt_Cold"
    },
    {
      "x": -27,
      "y": 0,
      "z": 23,
      "name": "Soil_Dirt_Cold"
    },
    {
      "x": -27,
      "y": 0,
      "z": 24,
      "name": "Soil_Dirt_Cold"
    },
    {
      "x": -27,
      "y": 0,
      "z": 25,
      "name": "Soil_Dirt_Cold"
    },
    {
      "x": -27,
      "y": 0,
      "z": 26,
      "name": "Soil_Dirt_Cold"
    },
    {
      "x": -27,
      "y": 0,
      "z": 27,
      "name": "Soil_Dirt_Cold"
    },
    {
      "x": -27,
      "y": 0,
      "z": 28,
      "name": "Soil_Dirt_Cold"
    },
    {
      "x": -27,
      "y": 0,
      "z": 29,
      "name": "Soil_Dirt_Cold"
    },
    {
      "x": -27,
      "y": 0,
      "z": 30,
      "name": "Soil_Dirt_Cold"
    },
    {
      "x": -27,
      "y": 0,
      "z": 31,
      "name": "Soil_Dirt_Cold"
    },
    {
      "x": -27,
      "y": 0,
      "z": 32,
      "name": "Soil_Dirt_Cold"
    },
    {
      "x": -27,
      "y": 0,
      "z": 33,
      "name": "Soil_Dirt"
    },
    {
      "x": -27,
      "y": 1,
      "z": 33,
      "name": "Rubble_Stone"
    },
    {
      "x": -27,
      "y": 0,
      "z": 34,
      "name": "Soil_Dirt"
    },
    {
      "x": -27,
      "y": 1,
      "z": 34,
      "name": "Rubble_Stone"
    },
    {
      "x": -27,
      "y": 0,
      "z": 35,
      "name": "Soil_Dirt"
    },
    {
      "x": -27,
      "y": 0,
      "z": 36,
      "name": "Soil_Dirt"
    },
    {
      "x": -27,
      "y": 0,
      "z": 37,
      "name": "Soil_Dirt"
    },
    {
      "x": -27,
      "y": 0,
      "z": 38,
      "name": "Soil_Dirt"
    },
    {
      "x": -27,
      "y": 0,
      "z": 39,
      "name": "Soil_Dirt"
    },
    {
      "x": -27,
      "y": 0,
      "z": 40,
      "name": "Soil_Dirt"
    },
    {
      "x": -26,
      "y": 0,
      "z": 15,
      "name": "Rock_Basalt"
    },
    {
      "x": -26,
      "y": 0,
      "z": 16,
      "name": "Rock_Basalt"
    },
    {
      "x": -26,
      "y": 0,
      "z": 17,
      "name": "Rock_Basalt"
    },
    {
      "x": -26,
      "y": 0,
      "z": 22,
      "name": "Soil_Dirt_Cold"
    },
    {
      "x": -26,
      "y": 0,
      "z": 23,
      "name": "Soil_Dirt_Cold"
    },
    {
      "x": -26,
      "y": 0,
      "z": 24,
      "name": "Soil_Dirt_Cold"
    },
    {
      "x": -26,
      "y": 0,
      "z": 25,
      "name": "Soil_Dirt_Cold"
    },
    {
      "x": -26,
      "y": 0,
      "z": 26,
      "name": "Soil_Dirt_Cold"
    },
    {
      "x": -26,
      "y": 0,
      "z": 27,
      "name": "Soil_Dirt_Cold"
    },
    {
      "x": -26,
      "y": 0,
      "z": 28,
      "name": "Soil_Dirt_Cold"
    },
    {
      "x": -26,
      "y": 0,
      "z": 29,
      "name": "Soil_Dirt_Cold"
    },
    {
      "x": -26,
      "y": 0,
      "z": 30,
      "name": "Soil_Dirt_Cold"
    },
    {
      "x": -26,
      "y": 0,
      "z": 31,
      "name": "Soil_Dirt_Cold"
    },
    {
      "x": -26,
      "y": 0,
      "z": 32,
      "name": "Soil_Dirt_Cold"
    },
    {
      "x": -26,
      "y": 0,
      "z": 33,
      "name": "Soil_Dirt"
    },
    {
      "x": -26,
      "y": 0,
      "z": 34,
      "name": "Soil_Dirt"
    },
    {
      "x": -26,
      "y": 0,
      "z": 35,
      "name": "Soil_Dirt"
    },
    {
      "x": -26,
      "y": 0,
      "z": 36,
      "name": "Soil_Dirt"
    },
    {
      "x": -26,
      "y": 0,
      "z": 37,
      "name": "Soil_Dirt"
    },
    {
      "x": -26,
      "y": 0,
      "z": 38,
      "name": "Soil_Dirt"
    },
    {
      "x": -26,
      "y": 0,
      "z": 39,
      "name": "Soil_Dirt"
    },
    {
      "x": -26,
      "y": 0,
      "z": 40,
      "name": "Soil_Dirt"
    },
    {
      "x": -25,
      "y": 0,
      "z": 11,
      "name": "Soil_Dirt_Cold"
    },
    {
      "x": -25,
      "y": 0,
      "z": 12,
      "name": "Soil_Dirt_Cold"
    },
    {
      "x": -25,
      "y": 0,
      "z": 13,
      "name": "Soil_Dirt_Cold"
    },
    {
      "x": -25,
      "y": 0,
      "z": 14,
      "name": "Soil_Dirt_Cold"
    },
    {
      "x": -25,
      "y": 0,
      "z": 15,
      "name": "Rock_Basalt"
    },
    {
      "x": -25,
      "y": 0,
      "z": 16,
      "name": "Rock_Basalt"
    },
    {
      "x": -25,
      "y": 0,
      "z": 17,
      "name": "Rock_Basalt"
    },
    {
      "x": -25,
      "y": 0,
      "z": 18,
      "name": "Soil_Dirt_Cold"
    },
    {
      "x": -25,
      "y": 0,
      "z": 19,
      "name": "Soil_Dirt_Cold"
    },
    {
      "x": -25,
      "y": 0,
      "z": 20,
      "name": "Soil_Dirt_Cold"
    },
    {
      "x": -25,
      "y": 0,
      "z": 21,
      "name": "Soil_Dirt_Cold"
    },
    {
      "x": -25,
      "y": 0,
      "z": 22,
      "name": "Soil_Dirt_Cold"
    },
    {
      "x": -25,
      "y": 0,
      "z": 23,
      "name": "Soil_Dirt_Cold"
    },
    {
      "x": -25,
      "y": 0,
      "z": 24,
      "name": "Soil_Dirt_Cold"
    },
    {
      "x": -25,
      "y": 0,
      "z": 25,
      "name": "Soil_Dirt_Cold"
    },
    {
      "x": -25,
      "y": 0,
      "z": 26,
      "name": "Soil_Dirt_Cold"
    },
    {
      "x": -25,
      "y": 0,
      "z": 27,
      "name": "Soil_Dirt_Cold"
    },
    {
      "x": -25,
      "y": 0,
      "z": 28,
      "name": "Soil_Dirt_Cold"
    },
    {
      "x": -25,
      "y": 0,
      "z": 29,
      "name": "Soil_Dirt_Cold"
    },
    {
      "x": -25,
      "y": 0,
      "z": 30,
      "name": "Soil_Dirt_Cold"
    },
    {
      "x": -25,
      "y": 0,
      "z": 31,
      "name": "Soil_Dirt_Cold"
    },
    {
      "x": -25,
      "y": 0,
      "z": 32,
      "name": "Soil_Dirt_Cold"
    },
    {
      "x": -25,
      "y": 0,
      "z": 33,
      "name": "Soil_Dirt_Cold"
    },
    {
      "x": -25,
      "y": 0,
      "z": 34,
      "name": "Soil_Dirt"
    },
    {
      "x": -25,
      "y": 0,
      "z": 35,
      "name": "Soil_Dirt"
    },
    {
      "x": -25,
      "y": 0,
      "z": 36,
      "name": "Soil_Dirt"
    },
    {
      "x": -25,
      "y": 0,
      "z": 37,
      "name": "Soil_Dirt"
    },
    {
      "x": -25,
      "y": 0,
      "z": 38,
      "name": "Soil_Dirt"
    },
    {
      "x": -25,
      "y": 0,
      "z": 39,
      "name": "Soil_Dirt"
    },
    {
      "x": -25,
      "y": 0,
      "z": 40,
      "name": "Soil_Dirt"
    },
    {
      "x": -24,
      "y": 0,
      "z": 10,
      "name": "Soil_Dirt_Cold"
    },
    {
      "x": -24,
      "y": 0,
      "z": 11,
      "name": "Soil_Dirt_Cold"
    },
    {
      "x": -24,
      "y": 0,
      "z": 12,
      "name": "Soil_Dirt_Cold"
    },
    {
      "x": -24,
      "y": 0,
      "z": 13,
      "name": "Soil_Dirt_Cold"
    },
    {
      "x": -24,
      "y": 0,
      "z": 14,
      "name": "Soil_Dirt_Cold"
    },
    {
      "x": -24,
      "y": 0,
      "z": 15,
      "name": "Soil_Dirt_Cold"
    },
    {
      "x": -24,
      "y": 0,
      "z": 16,
      "name": "Rock_Basalt"
    },
    {
      "x": -24,
      "y": 0,
      "z": 17,
      "name": "Rock_Basalt"
    },
    {
      "x": -24,
      "y": 0,
      "z": 18,
      "name": "Soil_Dirt_Cold"
    },
    {
      "x": -24,
      "y": 0,
      "z": 19,
      "name": "Soil_Dirt_Cold"
    },
    {
      "x": -24,
      "y": 0,
      "z": 20,
      "name": "Soil_Dirt_Cold"
    },
    {
      "x": -24,
      "y": 0,
      "z": 21,
      "name": "Soil_Dirt"
    },
    {
      "x": -24,
      "y": 1,
      "z": 21,
      "name": "Soil_Dirt_Cold"
    },
    {
      "x": -24,
      "y": 0,
      "z": 22,
      "name": "Soil_Dirt"
    },
    {
      "x": -24,
      "y": 1,
      "z": 22,
      "name": "Soil_Dirt_Cold"
    },
    {
      "x": -24,
      "y": 0,
      "z": 23,
      "name": "Soil_Dirt_Cold"
    },
    {
      "x": -24,
      "y": 0,
      "z": 24,
      "name": "Soil_Dirt_Cold"
    },
    {
      "x": -24,
      "y": 0,
      "z": 25,
      "name": "Soil_Dirt_Cold"
    },
    {
      "x": -24,
      "y": 0,
      "z": 26,
      "name": "Soil_Dirt_Cold"
    },
    {
      "x": -24,
      "y": 0,
      "z": 27,
      "name": "Soil_Dirt_Cold"
    },
    {
      "x": -24,
      "y": 0,
      "z": 28,
      "name": "Soil_Dirt_Cold"
    },
    {
      "x": -24,
      "y": 0,
      "z": 29,
      "name": "Soil_Dirt_Cold"
    },
    {
      "x": -24,
      "y": 0,
      "z": 30,
      "name": "Soil_Dirt_Cold"
    },
    {
      "x": -24,
      "y": 0,
      "z": 31,
      "name": "Soil_Dirt_Cold"
    },
    {
      "x": -24,
      "y": 0,
      "z": 32,
      "name": "Soil_Dirt_Cold"
    },
    {
      "x": -24,
      "y": 0,
      "z": 33,
      "name": "Soil_Dirt_Cold"
    },
    {
      "x": -24,
      "y": 0,
      "z": 34,
      "name": "Soil_Dirt"
    },
    {
      "x": -24,
      "y": 0,
      "z": 35,
      "name": "Soil_Dirt"
    },
    {
      "x": -24,
      "y": 0,
      "z": 36,
      "name": "Soil_Dirt"
    },
    {
      "x": -24,
      "y": 0,
      "z": 37,
      "name": "Soil_Dirt"
    },
    {
      "x": -24,
      "y": 0,
      "z": 38,
      "name": "Soil_Dirt"
    },
    {
      "x": -24,
      "y": 1,
      "z": 38,
      "name": "*Plant_Crop_Cauliflower_Block_State_Definitions_StageFinal"
    },
    {
      "x": -24,
      "y": 0,
      "z": 39,
      "name": "Soil_Dirt"
    },
    {
      "x": -24,
      "y": 0,
      "z": 40,
      "name": "Soil_Dirt"
    },
    {
      "x": -24,
      "y": 1,
      "z": 40,
      "name": "Plant_Fern_Winter"
    },
    {
      "x": -23,
      "y": 0,
      "z": 9,
      "name": "Soil_Dirt_Cold"
    },
    {
      "x": -23,
      "y": 0,
      "z": 10,
      "name": "Soil_Dirt_Cold"
    },
    {
      "x": -23,
      "y": 0,
      "z": 11,
      "name": "Soil_Dirt_Cold"
    },
    {
      "x": -23,
      "y": 0,
      "z": 12,
      "name": "Soil_Dirt_Cold"
    },
    {
      "x": -23,
      "y": 0,
      "z": 13,
      "name": "Soil_Dirt_Cold"
    },
    {
      "x": -23,
      "y": 0,
      "z": 14,
      "name": "Rock_Basalt"
    },
    {
      "x": -23,
      "y": 1,
      "z": 14,
      "name": "Soil_Dirt_Cold"
    },
    {
      "x": -23,
      "y": 0,
      "z": 15,
      "name": "Rock_Basalt"
    },
    {
      "x": -23,
      "y": 1,
      "z": 15,
      "name": "Rock_Basalt"
    },
    {
      "x": -23,
      "y": 0,
      "z": 16,
      "name": "Rock_Basalt"
    },
    {
      "x": -23,
      "y": 1,
      "z": 16,
      "name": "Rock_Basalt"
    },
    {
      "x": -23,
      "y": 0,
      "z": 17,
      "name": "Rock_Basalt"
    },
    {
      "x": -23,
      "y": 0,
      "z": 18,
      "name": "Soil_Dirt_Cold"
    },
    {
      "x": -23,
      "y": 0,
      "z": 19,
      "name": "Soil_Dirt_Cold"
    },
    {
      "x": -23,
      "y": 0,
      "z": 20,
      "name": "Soil_Dirt_Cold"
    },
    {
      "x": -23,
      "y": 0,
      "z": 21,
      "name": "Soil_Dirt_Cold"
    },
    {
      "x": -23,
      "y": 0,
      "z": 22,
      "name": "Soil_Dirt_Cold"
    },
    {
      "x": -23,
      "y": 0,
      "z": 23,
      "name": "Soil_Dirt_Cold"
    },
    {
      "x": -23,
      "y": 0,
      "z": 24,
      "name": "Soil_Dirt_Cold"
    },
    {
      "x": -23,
      "y": 0,
      "z": 25,
      "name": "Soil_Dirt_Cold"
    },
    {
      "x": -23,
      "y": 0,
      "z": 26,
      "name": "Soil_Dirt_Cold"
    },
    {
      "x": -23,
      "y": 0,
      "z": 27,
      "name": "Soil_Dirt_Cold"
    },
    {
      "x": -23,
      "y": 0,
      "z": 28,
      "name": "Soil_Dirt_Cold"
    },
    {
      "x": -23,
      "y": 0,
      "z": 29,
      "name": "Soil_Dirt_Cold"
    },
    {
      "x": -23,
      "y": 0,
      "z": 30,
      "name": "Soil_Dirt_Cold"
    },
    {
      "x": -23,
      "y": 0,
      "z": 31,
      "name": "Soil_Dirt_Cold"
    },
    {
      "x": -23,
      "y": 0,
      "z": 32,
      "name": "Soil_Dirt_Cold"
    },
    {
      "x": -23,
      "y": 0,
      "z": 33,
      "name": "Soil_Dirt_Cold"
    },
    {
      "x": -23,
      "y": 0,
      "z": 34,
      "name": "Soil_Dirt_Cold"
    },
    {
      "x": -23,
      "y": 0,
      "z": 35,
      "name": "Soil_Dirt"
    },
    {
      "x": -23,
      "y": 0,
      "z": 36,
      "name": "Soil_Dirt"
    },
    {
      "x": -23,
      "y": 0,
      "z": 37,
      "name": "Soil_Dirt"
    },
    {
      "x": -23,
