{
  "version": 8,
  "blockIdVersion": 11,
  "anchorX": 0,
  "anchorY": 0,
  "anchorZ": 0,
  "blocks": [
    {
      "x": -23,
      "y": 0,
      "z": -8,
      "name": "Rock_Sandstone"
    },
    {
      "x": -23,
      "y": 1,
      "z": -8,
      "name": "Rock_Sandstone"
    },
    {
      "x": -23,
      "y": 2,
      "z": -8,
      "name": "Rock_Sandstone"
    },
    {
      "x": -23,
      "y": 0,
      "z": -7,
      "name": "Rock_Sandstone"
    },
    {
      "x": -23,
      "y": 1,
      "z": -7,
      "name": "Rock_Sandstone"
    },
    {
      "x": -23,
      "y": 2,
      "z": -7,
      "name": "Rock_Sandstone"
    },
    {
      "x": -23,
      "y": 3,
      "z": -7,
      "name": "Soil_Dirt_Dry"
    },
    {
      "x": -23,
      "y": 0,
      "z": -6,
      "name": "Rock_Sandstone"
    },
    {
      "x": -23,
      "y": 1,
      "z": -6,
      "name": "Rock_Sandstone"
    },
    {
      "x": -23,
      "y": 2,
      "z": -6,
      "name": "Rock_Sandstone"
    },
    {
      "x": -23,
      "y": 3,
      "z": -6,
      "name": "Soil_Dirt_Dry"
    },
    {
      "x": -23,
      "y": 0,
      "z": -5,
      "name": "Rock_Sandstone"
    },
    {
      "x": -23,
      "y": 1,
      "z": -5,
      "name": "Rock_Sandstone"
    },
    {
      "x": -23,
      "y": 2,
      "z": -5,
      "name": "Rock_Sandstone"
    },
    {
      "x": -23,
      "y": 3,
      "z": -5,
      "name": "Soil_Dirt_Dry"
    },
    {
      "x": -23,
      "y": 0,
      "z": -4,
      "name": "Rock_Sandstone"
    },
    {
      "x": -23,
      "y": 1,
      "z": -4,
      "name": "Rock_Sandstone"
    },
    {
      "x": -23,
      "y": 2,
      "z": -4,
      "name": "Rock_Sandstone"
    },
    {
      "x": -22,
      "y": 0,
      "z": -10,
      "name": "Rock_Sandstone"
    },
    {
      "x": -22,
      "y": 1,
      "z": -10,
      "name": "Rock_Sandstone"
    },
    {
      "x": -22,
      "y": 2,
      "z": -10,
      "name": "Rock_Sandstone"
    },
    {
      "x": -22,
      "y": 0,
      "z": -9,
      "name": "Rock_Sandstone"
    },
    {
      "x": -22,
      "y": 1,
      "z": -9,
      "name": "Rock_Sandstone"
    },
    {
      "x": -22,
      "y": 2,
      "z": -9,
      "name": "Rock_Sandstone"
    },
    {
      "x": -22,
      "y": 3,
      "z": -9,
      "name": "Soil_Dirt_Dry"
    },
    {
      "x": -22,
      "y": 0,
      "z": -8,
      "name": "Rock_Sandstone"
    },
    {
      "x": -22,
      "y": 1,
      "z": -8,
      "name": "Rock_Sandstone"
    },
    {
      "x": -22,
      "y": 2,
      "z": -8,
      "name": "Rock_Sandstone"
    },
    {
      "x": -22,
      "y": 3,
      "z": -8,
      "name": "Soil_Dirt_Dry"
    },
    {
      "x": -22,
      "y": 0,
      "z": -7,
      "name": "Rock_Sandstone"
    },
    {
      "x": -22,
      "y": 1,
      "z": -7,
      "name": "Rock_Sandstone"
    },
    {
      "x": -22,
      "y": 2,
      "z": -7,
      "name": "Rock_Sandstone"
    },
    {
      "x": -22,
      "y": 3,
      "z": -7,
      "name": "Soil_Dirt_Dry"
    },
    {
      "x": -22,
      "y": 0,
      "z": -6,
      "name": "Rock_Sandstone"
    },
    {
      "x": -22,
      "y": 1,
      "z": -6,
      "name": "Rock_Sandstone"
    },
    {
      "x": -22,
      "y": 2,
      "z": -6,
      "name": "Soil_Dirt_Dry"
    },
    {
      "x": -22,
      "y": 3,
      "z": -6,
      "name": "Soil_Dirt_Dry"
    },
    {
      "x": -22,
      "y": 4,
      "z": -6,
      "name": "Soil_Dirt_Dry"
    },
    {
      "x": -22,
      "y": 0,
      "z": -5,
      "name": "Rock_Sandstone"
    },
    {
      "x": -22,
      "y": 1,
      "z": -5,
      "name": "Rock_Sandstone"
    },
    {
      "x": -22,
      "y": 2,
      "z": -5,
      "name": "Rock_Sandstone"
    },
    {
      "x": -22,
      "y": 3,
      "z": -5,
      "name": "Soil_Dirt_Dry"
    },
    {
      "x": -22,
      "y": 0,
      "z": -4,
      "name": "Rock_Sandstone"
    },
    {
      "x": -22,
      "y": 1,
      "z": -4,
      "name": "Rock_Sandstone"
    },
    {
      "x": -22,
      "y": 2,
      "z": -4,
      "name": "Rock_Sandstone"
    },
    {
      "x": -22,
      "y": 3,
      "z": -4,
      "name": "Soil_Dirt_Dry"
    },
    {
      "x": -22,
      "y": 0,
      "z": -3,
      "name": "Rock_Sandstone"
    },
    {
      "x": -22,
      "y": 1,
      "z": -3,
      "name": "Rock_Sandstone"
    },
    {
      "x": -22,
      "y": 2,
      "z": -3,
      "name": "Rock_Sandstone"
    },
    {
      "x": -22,
      "y": 3,
      "z": -3,
      "name": "Soil_Dirt_Dry"
    },
    {
      "x": -22,
      "y": 0,
      "z": -2,
      "name": "Rock_Sandstone"
    },
    {
      "x": -22,
      "y": 1,
      "z": -2,
      "name": "Rock_Sandstone"
    },
    {
      "x": -22,
      "y": 2,
      "z": -2,
      "name": "Rock_Sandstone"
    },
    {
      "x": -21,
      "y": 0,
      "z": -11,
      "name": "Rock_Sandstone"
    },
    {
      "x": -21,
      "y": 1,
      "z": -11,
      "name": "Rock_Sandstone"
    },
    {
      "x": -21,
      "y": 2,
      "z": -11,
      "name": "Rock_Sandstone"
    },
    {
      "x": -21,
      "y": 3,
      "z": -11,
      "name": "Soil_Gravel_Sand"
    },
    {
      "x": -21,
      "y": 0,
      "z": -10,
      "name": "Rock_Sandstone"
    },
    {
      "x": -21,
      "y": 1,
      "z": -10,
      "name": "Rock_Sandstone"
    },
    {
      "x": -21,
      "y": 2,
      "z": -10,
      "name": "Rock_Sandstone"
    },
    {
      "x": -21,
      "y": 3,
      "z": -10,
      "name": "Soil_Dirt_Dry"
    },
    {
      "x": -21,
      "y": 0,
      "z": -9,
      "name": "Rock_Sandstone"
    },
    {
      "x": -21,
      "y": 1,
      "z": -9,
      "name": "Rock_Sandstone"
    },
    {
      "x": -21,
      "y": 2,
      "z": -9,
      "name": "Soil_Dirt_Dry"
    },
    {
      "x": -21,
      "y": 3,
      "z": -9,
      "name": "Soil_Dirt_Dry"
    },
    {
      "x": -21,
      "y": 4,
      "z": -9,
      "name": "Soil_Dirt_Dry"
    },
    {
      "x": -21,
      "y": 1,
      "z": -8,
      "name": "Rock_Sandstone"
    },
    {
      "x": -21,
      "y": 2,
      "z": -8,
      "name": "Soil_Dirt_Dry"
    },
    {
      "x": -21,
      "y": 3,
      "z": -8,
      "name": "Soil_Dirt_Dry"
    },
    {
      "x": -21,
      "y": 4,
      "z": -8,
      "name": "Soil_Dirt_Dry"
    },
    {
      "x": -21,
      "y": 1,
      "z": -7,
      "name": "Rock_Sandstone"
    },
    {
      "x": -21,
      "y": 2,
      "z": -7,
      "name": "Soil_Dirt_Dry"
    },
    {
      "x": -21,
      "y": 3,
      "z": -7,
      "name": "Soil_Dirt_Dry"
    },
    {
      "x": -21,
      "y": 4,
      "z": -7,
      "name": "Soil_Dirt_Dry"
    },
    {
      "x": -21,
      "y": 1,
      "z": -6,
      "name": "Rock_Sandstone"
    },
    {
      "x": -21,
      "y": 2,
      "z": -6,
      "name": "Soil_Dirt_Dry"
    },
    {
      "x": -21,
      "y": 3,
      "z": -6,
      "name": "Soil_Dirt_Dry"
    },
    {
      "x": -21,
      "y": 4,
      "z": -6,
      "name": "Soil_Dirt_Dry"
    },
    {
      "x": -21,
      "y": 1,
      "z": -5,
      "name": "Rock_Sandstone"
    },
    {
      "x": -21,
      "y": 2,
      "z": -5,
      "name": "Soil_Dirt_Dry"
    },
    {
      "x": -21,
      "y": 3,
      "z": -5,
      "name": "Soil_Dirt_Dry"
    },
    {
      "x": -21,
      "y": 4,
      "z": -5,
      "name": "Soil_Dirt_Dry"
    },
    {
      "x": -21,
      "y": 1,
      "z": -4,
      "name": "Rock_Sandstone"
    },
    {
      "x": -21,
      "y": 2,
      "z": -4,
      "name": "Soil_Dirt_Dry"
    },
    {
      "x": -21,
      "y": 3,
      "z": -4,
      "name": "Soil_Dirt_Dry"
    },
    {
      "x": -21,
      "y": 4,
      "z": -4,
      "name": "Soil_Dirt_Dry"
    },
    {
      "x": -21,
      "y": 0,
      "z": -3,
      "name": "Rock_Sandstone"
    },
    {
      "x": -21,
      "y": 1,
      "z": -3,
      "name": "Rock_Sandstone"
    },
    {
      "x": -21,
      "y": 2,
      "z": -3,
      "name": "Soil_Dirt_Dry"
    },
    {
      "x": -21,
      "y": 3,
      "z": -3,
      "name": "Soil_Dirt_Dry"
    },
    {
      "x": -21,
      "y": 4,
      "z": -3,
      "name": "Soil_Dirt_Dry"
    },
    {
      "x": -21,
      "y": 0,
      "z": -2,
      "name": "Rock_Sandstone"
    },
    {
      "x": -21,
      "y": 1,
      "z": -2,
      "name": "Rock_Sandstone"
    },
    {
      "x": -21,
      "y": 2,
      "z": -2,
      "name": "Rock_Sandstone"
    },
    {
      "x": -21,
      "y": 3,
      "z": -2,
      "name": "Soil_Dirt_Dry"
    },
    {
      "x": -21,
      "y": 0,
      "z": -1,
      "name": "Rock_Sandstone"
    },
    {
      "x": -21,
      "y": 1,
      "z": -1,
      "name": "Rock_Sandstone"
    },
    {
      "x": -21,
      "y": 2,
      "z": -1,
      "name": "Rock_Sandstone"
    },
    {
      "x": -21,
      "y": 3,
      "z": -1,
      "name": "Soil_Dirt_Dry"
    },
    {
      "x": -20,
      "y": 0,
      "z": -12,
      "name": "Rock_Sandstone"
    },
    {
      "x": -20,
      "y": 1,
      "z": -12,
      "name": "Rock_Sandstone"
    },
    {
      "x": -20,
      "y": 2,
      "z": -12,
      "name": "Rock_Sandstone"
    },
    {
      "x": -20,
      "y": 0,
      "z": -11,
      "name": "Rock_Sandstone"
    },
    {
      "x": -20,
      "y": 1,
      "z": -11,
      "name": "Rock_Sandstone"
    },
    {
      "x": -20,
      "y": 2,
      "z": -11,
      "name": "Rock_Sandstone"
    },
    {
      "x": -20,
      "y": 3,
      "z": -11,
      "name": "Soil_Dirt_Dry"
    },
    {
      "x": -20,
      "y": 0,
      "z": -10,
      "name": "Rock_Sandstone"
    },
    {
      "x": -20,
      "y": 1,
      "z": -10,
      "name": "Rock_Sandstone"
    },
    {
      "x": -20,
      "y": 2,
      "z": -10,
      "name": "Soil_Dirt_Dry"
    },
    {
      "x": -20,
      "y": 3,
      "z": -10,
      "name": "Soil_Dirt_Dry"
    },
    {
      "x": -20,
      "y": 4,
      "z": -10,
      "name": "Soil_Dirt_Dry"
    },
    {
      "x": -20,
      "y": 1,
      "z": -9,
      "name": "Rock_Sandstone"
    },
    {
      "x": -20,
      "y": 2,
      "z": -9,
      "name": "Soil_Dirt_Dry"
    },
    {
      "x": -20,
      "y": 3,
      "z": -9,
      "name": "Soil_Dirt_Dry"
    },
    {
      "x": -20,
      "y": 4,
      "z": -9,
      "name": "Soil_Dirt_Dry"
    },
    {
      "x": -20,
      "y": 1,
      "z": -8,
      "name": "Rock_Sandstone"
    },
    {
      "x": -20,
      "y": 2,
      "z": -8,
      "name": "Soil_Dirt_Dry"
    },
    {
      "x": -20,
      "y": 3,
      "z": -8,
      "name": "Soil_Dirt_Dry"
    },
    {
      "x": -20,
      "y": 4,
      "z": -8,
      "name": "Soil_Dirt_Dry"
    },
    {
      "x": -20,
      "y": 1,
      "z": -7,
      "name": "Rock_Sandstone"
    },
    {
      "x": -20,
      "y": 2,
      "z": -7,
      "name": "Soil_Dirt_Dry"
    },
    {
      "x": -20,
      "y": 3,
      "z": -7,
      "name": "Soil_Dirt_Dry"
    },
    {
      "x": -20,
      "y": 4,
      "z": -7,
      "name": "Soil_Dirt_Dry"
    },
    {
      "x": -20,
      "y": 1,
      "z": -6,
      "name": "Rock_Sandstone"
    },
    {
      "x": -20,
      "y": 2,
      "z": -6,
      "name": "Soil_Dirt_Dry"
    },
    {
      "x": -20,
      "y": 3,
      "z": -6,
      "name": "Soil_Dirt_Dry"
    },
    {
      "x": -20,
      "y": 4,
      "z": -6,
      "name": "Soil_Dirt_Dry"
    },
    {
      "x": -20,
      "y": 1,
      "z": -5,
      "name": "Rock_Sandstone"
    },
    {
      "x": -20,
      "y": 2,
      "z": -5,
      "name": "Soil_Dirt_Dry"
    },
    {
      "x": -20,
      "y": 3,
      "z": -5,
      "name": "Soil_Dirt_Dry"
    },
    {
      "x": -20,
      "y": 4,
      "z": -5,
      "name": "Soil_Dirt_Dry"
    },
    {
      "x": -20,
      "y": 1,
      "z": -4,
      "name": "Rock_Sandstone"
    },
    {
      "x": -20,
      "y": 2,
      "z": -4,
      "name": "Soil_Dirt_Dry"
    },
    {
      "x": -20,
      "y": 3,
      "z": -4,
      "name": "Soil_Dirt_Dry"
    },
    {
      "x": -20,
      "y": 4,
      "z": -4,
      "name": "Soil_Dirt_Dry"
    },
    {
      "x": -20,
      "y": 1,
      "z": -3,
      "name": "Rock_Sandstone"
    },
    {
      "x": -20,
      "y": 2,
      "z": -3,
      "name": "Soil_Dirt_Dry"
    },
    {
      "x": -20,
      "y": 3,
      "z": -3,
      "name": "Soil_Dirt_Dry"
    },
    {
      "x": -20,
      "y": 4,
      "z": -3,
      "name": "Soil_Dirt_Dry"
    },
    {
      "x": -20,
      "y": 0,
      "z": -2,
      "name": "Rock_Sandstone"
    },
    {
      "x": -20,
      "y": 1,
      "z": -2,
      "name": "Rock_Sandstone"
    },
    {
      "x": -20,
      "y": 2,
      "z": -2,
      "name": "Soil_Dirt_Dry"
    },
    {
      "x": -20,
      "y": 3,
      "z": -2,
      "name": "Soil_Dirt_Dry"
    },
    {
      "x": -20,
      "y": 4,
      "z": -2,
      "name": "Soil_Dirt_Dry"
    },
    {
      "x": -20,
      "y": 0,
      "z": -1,
      "name": "Rock_Sandstone"
    },
    {
      "x": -20,
      "y": 1,
      "z": -1,
      "name": "Rock_Sandstone"
    },
    {
      "x": -20,
      "y": 2,
      "z": -1,
      "name": "Rock_Sandstone"
    },
    {
      "x": -20,
      "y": 3,
      "z": -1,
      "name": "Soil_Dirt_Dry"
    },
    {
      "x": -20,
      "y": 0,
      "z": 0,
      "name": "Rock_Sandstone"
    },
    {
      "x": -20,
      "y": 1,
      "z": 0,
      "name": "Rock_Sandstone"
    },
    {
      "x": -20,
      "y": 2,
      "z": 0,
      "name": "Rock_Sandstone"
    },
    {
      "x": -19,
      "y": 0,
      "z": -12,
      "name": "Rock_Sandstone"
    },
    {
      "x": -19,
      "y": 1,
      "z": -12,
      "name": "Rock_Sandstone"
    },
    {
      "x": -19,
      "y": 2,
      "z": -12,
      "name": "Rock_Sandstone"
    },
    {
      "x": -19,
      "y": 3,
      "z": -12,
      "name": "Soil_Dirt_Dry"
    },
    {
      "x": -19,
      "y": 0,
      "z": -11,
      "name": "Rock_Sandstone"
    },
    {
      "x": -19,
      "y": 1,
      "z": -11,
      "name": "Rock_Sandstone"
    },
    {
      "x": -19,
      "y": 2,
      "z": -11,
      "name": "Soil_Dirt_Dry"
    },
    {
      "x": -19,
      "y": 3,
      "z": -11,
      "name": "Soil_Dirt_Dry"
    },
    {
      "x": -19,
      "y": 4,
      "z": -11,
      "name": "Soil_Dirt_Dry"
    },
    {
      "x": -19,
      "y": 1,
      "z": -10,
      "name": "Rock_Sandstone"
    },
    {
      "x": -19,
      "y": 2,
      "z": -10,
      "name": "Soil_Dirt_Dry"
    },
    {
      "x": -19,
      "y": 3,
      "z": -10,
      "name": "Soil_Dirt_Dry"
    },
    {
      "x": -19,
      "y": 4,
      "z": -10,
      "name": "Soil_Dirt_Dry"
    },
    {
      "x": -19,
      "y": 1,
      "z": -9,
      "name": "Rock_Sandstone"
    },
    {
      "x": -19,
      "y": 2,
      "z": -9,
      "name": "Soil_Dirt_Dry"
    },
    {
      "x": -19,
      "y": 3,
      "z": -9,
      "name": "Soil_Dirt_Dry"
    },
    {
      "x": -19,
      "y": 4,
      "z": -9,
      "name": "Soil_Dirt_Dry"
    },
    {
      "x": -19,
      "y": 1,
      "z": -8,
      "name": "Rock_Sandstone"
    },
    {
      "x": -19,
      "y": 2,
      "z": -8,
      "name": "Soil_Dirt_Dry"
    },
    {
      "x": -19,
      "y": 3,
      "z": -8,
      "name": "Soil_Dirt_Dry"
    },
    {
      "x": -19,
      "y": 4,
      "z": -8,
      "name": "Soil_Dirt_Dry"
    },
    {
      "x": -19,
      "y": 1,
      "z": -7,
      "name": "Rock_Sandstone"
    },
    {
      "x": -19,
      "y": 2,
      "z": -7,
      "name": "Soil_Dirt_Dry"
    },
    {
      "x": -19,
      "y": 3,
      "z": -7,
      "name": "Soil_Dirt_Dry"
    },
    {
      "x": -19,
      "y": 4,
      "z": -7,
      "name": "Soil_Dirt_Dry"
    },
    {
      "x": -19,
      "y": 5,
      "z": -7,
      "name": "Soil_Dirt_Dry"
    },
    {
      "x": -19,
      "y": 1,
      "z": -6,
      "name": "Rock_Sandstone"
    },
    {
      "x": -19,
      "y": 2,
      "z": -6,
      "name": "Soil_Dirt_Dry"
    },
    {
      "x": -19,
      "y": 3,
      "z": -6,
      "name": "Soil_Dirt_Dry"
    },
    {
      "x": -19,
      "y": 4,
      "z": -6,
      "name": "Soil_Dirt_Dry"
    },
    {
      "x": -19,
      "y": 5,
      "z": -6,
      "name": "Soil_Dirt_Dry"
    },
    {
      "x": -19,
      "y": 1,
      "z": -5,
      "name": "Rock_Sandstone"
    },
    {
      "x": -19,
      "y": 2,
      "z": -5,
      "name": "Soil_Dirt_Dry"
    },
    {
      "x": -19,
      "y": 3,
      "z": -5,
      "name": "Soil_Dirt_Dry"
    },
    {
      "x": -19,
      "y": 4,
      "z": -5,
      "name": "Soil_Dirt_Dry"
    },
    {
      "x": -19,
      "y": 5,
      "z": -5,
      "name": "Soil_Dirt_Dry"
    },
    {
      "x": -19,
      "y": 1,
      "z": -4,
      "name": "Rock_Sandstone"
    },
    {
      "x": -19,
      "y": 2,
      "z": -4,
      "name": "Soil_Dirt_Dry"
    },
    {
      "x": -19,
      "y": 3,
      "z": -4,
      "name": "Soil_Dirt_Dry"
    },
    {
      "x": -19,
      "y": 4,
      "z": -4,
      "name": "Soil_Dirt_Dry"
    },
    {
      "x": -19,
      "y": 1,
      "z": -3,
      "name": "Rock_Sandstone"
    },
    {
      "x": -19,
      "y": 2,
      "z": -3,
      "name": "Soil_Dirt_Dry"
    },
    {
      "x": -19,
      "y": 3,
      "z": -3,
      "name": "Soil_Dirt_Dry"
    },
    {
      "x": -19,
      "y": 4,
      "z": -3,
      "name": "Soil_Dirt_Dry"
    },
    {
      "x": -19,
      "y": 1,
      "z": -2,
      "name": "Rock_Sandstone"
    },
    {
      "x": -19,
      "y": 2,
      "z": -2,
      "name": "Soil_Dirt_Dry"
    },
    {
      "x": -19,
      "y": 3,
      "z": -2,
      "name": "Soil_Dirt_Dry"
    },
    {
      "x": -19,
      "y": 4,
      "z": -2,
      "name": "Soil_Dirt_Dry"
    },
    {
      "x": -19,
      "y": 0,
      "z": -1,
      "name": "Rock_Sandstone"
    },
    {
      "x": -19,
      "y": 1,
      "z": -1,
      "name": "Rock_Sandstone"
    },
    {
      "x": -19,
      "y": 2,
      "z": -1,
      "name": "Soil_Dirt_Dry"
    },
    {
      "x": -19,
      "y": 3,
      "z": -1,
      "name": "Soil_Dirt_Dry"
    },
    {
      "x": -19,
      "y": 4,
      "z": -1,
      "name": "Soil_Dirt_Dry"
    },
    {
      "x": -19,
      "y": 0,
      "z": 0,
      "name": "Rock_Sandstone"
    },
    {
      "x": -19,
      "y": 1,
      "z": 0,
      "name": "Rock_Sandstone"
    },
    {
      "x": -19,
      "y": 2,
      "z": 0,
      "name": "Rock_Sandstone"
    },
    {
      "x": -19,
      "y": 3,
      "z": 0,
      "name": "Soil_Dirt_Dry"
    },
    {
      "x": -18,
      "y": 0,
      "z": -17,
      "name": "Rock_Sandstone"
    },
    {
      "x": -18,
      "y": 1,
      "z": -17,
      "name": "Rock_Sandstone"
    },
    {
      "x": -18,
      "y": 2,
      "z": -17,
      "name": "Rock_Sandstone"
    },
    {
      "x": -18,
      "y": 0,
      "z": -16,
      "name": "Rock_Sandstone"
    },
    {
      "x": -18,
      "y": 1,
      "z": -16,
      "name": "Rock_Sandstone"
    },
    {
      "x": -18,
      "y": 2,
      "z": -16,
      "name": "Rock_Sandstone"
    },
    {
      "x": -18,
      "y": 3,
      "z": -16,
      "name": "Soil_Dirt_Dry"
    },
    {
      "x": -18,
      "y": 0,
      "z": -15,
      "name": "Rock_Sandstone"
    },
    {
      "x": -18,
      "y": 1,
      "z": -15,
      "name": "Rock_Sandstone"
    },
    {
      "x": -18,
      "y": 2,
      "z": -15,
      "name": "Rock_Sandstone"
    },
    {
      "x": -18,
      "y": 3,
      "z": -15,
      "name": "Soil_Dirt_Dry"
    },
    {
      "x": -18,
      "y": 0,
      "z": -14,
      "name": "Rock_Sandstone"
    },
    {
      "x": -18,
      "y": 1,
      "z": -14,
      "name": "Rock_Sandstone"
    },
    {
      "x": -18,
      "y": 2,
      "z": -14,
      "name": "Rock_Sandstone"
    },
    {
      "x": -18,
      "y": 3,
      "z": -14,
      "name": "Soil_Dirt_Dry"
    },
    {
      "x": -18,
      "y": 0,
      "z": -13,
      "name": "Rock_Sandstone"
    },
    {
      "x": -18,
      "y": 1,
      "z": -13,
      "name": "Rock_Sandstone"
    },
    {
      "x": -18,
      "y": 2,
      "z": -13,
      "name": "Rock_Sandstone"
    },
    {
      "x": -18,
      "y": 0,
      "z": -12,
      "name": "Rock_Sandstone"
    },
    {
      "x": -18,
      "y": 1,
      "z": -12,
      "name": "Rock_Sandstone"
    },
    {
      "x": -18,
      "y": 2,
      "z": -12,
      "name": "Rock_Sandstone"
    },
    {
      "x": -18,
      "y": 3,
      "z": -12,
      "name": "Soil_Dirt_Dry"
    },
    {
      "x": -18,
      "y": 1,
      "z": -11,
      "name": "Rock_Sandstone"
    },
    {
      "x": -18,
      "y": 2,
      "z": -11,
      "name": "Soil_Dirt_Dry"
    },
    {
      "x": -18,
      "y": 3,
      "z": -11,
      "name": "Soil_Dirt_Dry"
    },
    {
      "x": -18,
      "y": 4,
      "z": -11,
      "name": "Soil_Dirt_Dry"
    },
    {
      "x": -18,
      "y": 1,
      "z": -10,
      "name": "Rock_Sandstone"
    },
    {
      "x": -18,
      "y": 2,
      "z": -10,
      "name": "Soil_Dirt_Dry"
    },
    {
      "x": -18,
      "y": 3,
      "z": -10,
      "name": "Soil_Dirt_Dry"
    },
    {
      "x": -18,
      "y": 4,
      "z": -10,
      "name": "Soil_Dirt_Dry"
    },
    {
      "x": -18,
      "y": 1,
      "z": -9,
      "name": "Rock_Sandstone"
    },
    {
      "x": -18,
      "y": 2,
      "z": -9,
      "name": "Soil_Dirt_Dry"
    },
    {
      "x": -18,
      "y": 3,
      "z": -9,
      "name": "Soil_Dirt_Dry"
    },
    {
      "x": -18,
      "y": 4,
      "z": -9,
      "name": "Soil_Dirt_Dry"
    },
    {
      "x": -18,
      "y": 1,
      "z": -8,
      "name": "Rock_Sandstone"
    },
    {
      "x": -18,
      "y": 2,
      "z": -8,
      "name": "Soil_Dirt_Dry"
    },
    {
      "x": -18,
      "y": 3,
      "z": -8,
      "name": "Soil_Dirt_Dry"
    },
    {
      "x": -18,
      "y": 4,
      "z": -8,
      "name": "Soil_Dirt_Dry"
    },
    {
      "x": -18,
      "y": 5,
      "z": -8,
      "name": "Soil_Dirt_Dry"
    },
    {
      "x": -18,
      "y": 1,
      "z": -7,
      "name": "Rock_Sandstone"
    },
    {
      "x": -18,
      "y": 2,
      "z": -7,
      "name": "Soil_Dirt_Dry"
    },
    {
      "x": -18,
      "y": 3,
      "z": -7,
      "name": "Soil_Dirt_Dry"
    },
    {
      "x": -18,
      "y": 4,
      "z": -7,
      "name": "Soil_Dirt_Dry"
    },
    {
      "x": -18,
      "y": 5,
      "z": -7,
      "name": "Soil_Dirt_Dry"
    },
    {
      "x": -18,
      "y": 1,
      "z": -6,
      "name": "Rock_Sandstone"
    },
    {
      "x": -18,
      "y": 2,
      "z": -6,
      "name": "Soil_Dirt_Dry"
    },
    {
      "x": -18,
      "y": 3,
      "z": -6,
      "name": "Soil_Dirt_Dry"
    },
    {
      "x": -18,
      "y": 4,
      "z": -6,
      "name": "Soil_Dirt_Dry"
    },
    {
      "x": -18,
      "y": 5,
      "z": -6,
      "name": "Soil_Dirt_Dry"
    },
    {
      "x": -18,
      "y": 1,
      "z": -5,
      "name": "Rock_Sandstone"
    },
    {
      "x": -18,
      "y": 2,
      "z": -5,
      "name": "Soil_Dirt_Dry"
    },
    {
      "x": -18,
      "y": 3,
      "z": -5,
      "name": "Soil_Dirt_Dry"
    },
    {
      "x": -18,
      "y": 4,
      "z": -5,
      "name": "Soil_Dirt_Dry"
    },
    {
      "x": -18,
      "y": 5,
      "z": -5,
      "name": "Soil_Dirt_Dry"
    },
    {
      "x": -18,
      "y": 1,
      "z": -4,
      "name": "Rock_Sandstone"
    },
    {
      "x": -18,
      "y": 2,
      "z": -4,
      "name": "Soil_Dirt_Dry"
    },
    {
      "x": -18,
      "y": 3,
      "z": -4,
      "name": "Soil_Dirt_Dry"
    },
    {
      "x": -18,
      "y": 4,
      "z": -4,
      "name": "Soil_Dirt_Dry"
    },
    {
      "x": -18,
      "y": 5,
      "z": -4,
      "name": "Soil_Dirt_Dry"
    },
    {
      "x": -18,
      "y": 1,
      "z": -3,
      "name": "Rock_Sandstone"
    },
    {
      "x": -18,
      "y": 2,
      "z": -3,
      "name": "Soil_Dirt_Dry"
    },
    {
      "x": -18,
      "y": 3,
      "z": -3,
      "name": "Soil_Dirt_Dry"
    },
    {
      "x": -18,
      "y": 4,
      "z": -3,
      "name": "Soil_Dirt_Dry"
    },
    {
      "x": -18,
      "y": 1,
      "z": -2,
      "name": "Rock_Sandstone"
    },
    {
      "x": -18,
      "y": 2,
      "z": -2,
      "name": "Soil_Dirt_Dry"
    },
    {
      "x": -18,
      "y": 3,
      "z": -2,
      "name": "Soil_Dirt_Dry"
    },
    {
      "x": -18,
      "y": 4,
      "z": -2,
      "name": "Soil_Dirt_Dry"
    },
    {
      "x": -18,
      "y": 1,
      "z": -1,
      "name": "Rock_Sandstone"
    },
    {
      "x": -18,
      "y": 2,
      "z": -1,
      "name": "Soil_Dirt_Dry"
    },
    {
      "x": -18,
      "y": 3,
      "z": -1,
      "name": "Soil_Dirt_Dry"
    },
    {
      "x": -18,
      "y": 4,
      "z": -1,
      "name": "Soil_Dirt_Dry"
    },
    {
      "x": -18,
      "y": 0,
      "z": 0,
      "name": "Rock_Sandstone"
    },
    {
      "x": -18,
      "y": 1,
      "z": 0,
      "name": "Rock_Sandstone"
    },
    {
      "x": -18,
      "y": 2,
      "z": 0,
      "name": "Rock_Sandstone"
    },
    {
      "x": -18,
      "y": 3,
      "z": 0,
      "name": "Soil_Dirt_Dry"
    },
    {
      "x": -18,
      "y": 0,
      "z": 1,
      "name": "Rock_Sandstone"
    },
    {
      "x": -18,
      "y": 1,
      "z": 1,
      "name": "Rock_Sandstone"
    },
    {
      "x": -18,
      "y": 2,
      "z": 1,
      "name": "Rock_Sandstone"
    },
    {
      "x": -18,
      "y": 0,
      "z": 3,
      "name": "Rock_Sandstone"
    },
    {
      "x": -18,
      "y": 1,
      "z": 3,
      "name": "Rock_Sandstone"
    },
    {
      "x": -18,
      "y": 2,
      "z": 3,
      "name": "Rock_Sandstone"
    },
    {
      "x": -18,
      "y": 0,
      "z": 4,
      "name": "Rock_Sandstone"
    },
    {
      "x": -18,
      "y": 1,
      "z": 4,
      "name": "Rock_Sandstone"
    },
    {
      "x": -18,
      "y": 2,
      "z": 4,
      "name": "Rock_Sandstone"
    },
    {
      "x": -18,
      "y": 3,
      "z": 4,
      "name": "Soil_Dirt_Dry"
    },
    {
      "x": -18,
      "y": 0,
      "z": 5,
      "name": "Rock_Sandstone"
    },
    {
      "x": -18,
      "y": 1,
      "z": 5,
      "name": "Rock_Sandstone"
    },
    {
      "x": -18,
      "y": 2,
      "z": 5,
      "name": "Rock_Sandstone"
    },
    {
      "x": -18,
      "y": 3,
      "z": 5,
      "name": "Soil_Dirt_Dry"
    },
    {
      "x": -18,
      "y": 0,
      "z": 6,
      "name": "Rock_Sandstone"
    },
    {
      "x": -18,
      "y": 1,
      "z": 6,
      "name": "Rock_Sandstone"
    },
    {
      "x": -18,
      "y": 2,
      "z": 6,
      "name": "Rock_Sandstone"
    },
    {
      "x": -18,
      "y": 3,
      "z": 6,
      "name": "Soil_Dirt_Dry"
    },
    {
      "x": -18,
      "y": 0,
      "z": 7,
      "name": "Rock_Sandstone"
    },
    {
      "x": -18,
      "y": 1,
      "z": 7,
      "name": "Rock_Sandstone"
    },
    {
      "x": -18,
      "y": 2,
      "z": 7,
      "name": "Rock_Sandstone"
    },
    {
      "x": -17,
      "y": 0,
      "z": -19,
      "name": "Rock_Sandstone"
    },
    {
      "x": -17,
      "y": 1,
      "z": -19,
      "name": "Rock_Sandstone"
    },
    {
      "x": -17,
      "y": 2,
      "z": -19,
      "name": "Rock_Sandstone"
    },
    {
      "x": -17,
      "y": 0,
      "z": -18,
      "name": "Rock_Sandstone"
    },
    {
      "x": -17,
      "y": 1,
      "z": -18,
      "name": "Rock_Sandstone"
    },
    {
      "x": -17,
      "y": 2,
      "z": -18,
      "name": "Rock_Sandstone"
    },
    {
      "x": -17,
      "y": 3,
      "z": -18,
      "name": "Soil_Dirt_Dry"
    },
    {
      "x": -17,
      "y": 0,
      "z": -17,
      "name": "Rock_Sandstone"
    },
    {
      "x": -17,
      "y": 1,
      "z": -17,
      "name": "Rock_Sandstone"
    },
    {
      "x": -17,
      "y": 2,
      "z": -17,
      "name": "Rock_Sandstone"
    },
    {
      "x": -17,
      "y": 3,
      "z": -17,
      "name": "Soil_Dirt_Dry"
    },
    {
      "x": -17,
      "y": 0,
      "z": -16,
      "name": "Rock_Sandstone"
    },
    {
      "x": -17,
      "y": 1,
      "z": -16,
      "name": "Rock_Sandstone"
    },
    {
      "x": -17,
      "y": 2,
      "z": -16,
      "name": "Rock_Sandstone"
    },
    {
      "x": -17,
      "y": 3,
      "z": -16,
      "name": "Soil_Dirt_Dry"
    },
    {
      "x": -17,
      "y": 0,
      "z": -15,
      "name": "Rock_Sandstone"
    },
    {
      "x": -17,
      "y": 1,
      "z": -15,
      "name": "Rock_Sandstone"
    },
    {
      "x": -17,
      "y": 2,
      "z": -15,
      "name": "Soil_Dirt_Dry"
    },
    {
      "x": -17,
      "y": 3,
      "z": -15,
      "name": "Soil_Dirt_Dry"
    },
    {
      "x": -17,
      "y": 4,
      "z": -15,
      "name": "Soil_Dirt_Dry"
    },
    {
      "x": -17,
      "y": 0,
      "z": -14,
      "name": "Rock_Sandstone"
    },
    {
      "x": -17,
      "y": 1,
      "z": -14,
      "name": "Rock_Sandstone"
    },
    {
      "x": -17,
      "y": 2,
      "z": -14,
      "name": "Rock_Sandstone"
    },
    {
      "x": -17,
      "y": 3,
      "z": -14,
      "name": "Soil_Dirt_Dry"
    },
    {
      "x": -17,
      "y": 0,
      "z": -13,
      "name": "Rock_Sandstone"
    },
    {
      "x": -17,
      "y": 1,
      "z": -13,
      "name": "Rock_Sandstone"
    },
    {
      "x": -17,
      "y": 2,
      "z": -13,
      "name": "Rock_Sandstone"
    },
    {
      "x": -17,
      "y": 3,
      "z": -13,
      "name": "Soil_Dirt_Dry"
    },
    {
      "x": -17,
      "y": 0,
      "z": -12,
      "name": "Rock_Sandstone"
    },
    {
      "x": -17,
      "y": 1,
      "z": -12,
      "name": "Rock_Sandstone"
    },
    {
      "x": -17,
      "y": 2,
      "z": -12,
      "name": "Rock_Sandstone"
    },
    {
      "x": -17,
      "y": 3,
      "z": -12,
      "name": "Soil_Dirt_Dry"
    },
    {
      "x": -17,
      "y": 0,
      "z": -11,
      "name": "Rock_Sandstone"
    },
    {
      "x": -17,
      "y": 1,
      "z": -11,
      "name": "Rock_Sandstone"
    },
    {
      "x": -17,
      "y": 2,
      "z": -11,
      "name": "Soil_Dirt_Dry"
    },
    {
      "x": -17,
      "y": 3,
      "z": -11,
      "name": "Soil_Dirt_Dry"
    },
    {
      "x": -17,
      "y": 4,
      "z": -11,
      "name": "Soil_Dirt_Dry"
    },
    {
      "x": -17,
      "y": 1,
      "z": -10,
      "name": "Rock_Sandstone"
    },
    {
      "x": -17,
      "y": 2,
      "z": -10,
      "name": "Soil_Dirt_Dry"
    },
    {
      "x": -17,
      "y": 3,
      "z": -10,
      "name": "Soil_Dirt_Dry"
    },
    {
      "x": -17,
      "y": 4,
      "z": -10,
      "name": "Soil_Dirt_Dry"
    },
    {
      "x": -17,
      "y": 1,
      "z": -9,
      "name": "Rock_Sandstone"
    },
    {
      "x": -17,
      "y": 2,
      "z": -9,
      "name": "Soil_Dirt_Dry"
    },
    {
      "x": -17,
      "y": 3,
      "z": -9,
      "name": "Soil_Dirt_Dry"
    },
    {
      "x": -17,
      "y": 4,
      "z": -9,
      "name": "Soil_Dirt_Dry"
    },
    {
      "x": -17,
      "y": 5,
      "z": -9,
      "name": "Soil_Dirt_Dry"
    },
    {
      "x": -17,
      "y": 1,
      "z": -8,
      "name": "Rock_Sandstone"
    },
    {
      "x": -17,
      "y": 2,
      "z": -8,
      "name": "Soil_Dirt_Dry"
    },
    {
      "x": -17,
      "y": 3,
      "z": -8,
      "name": "Soil_Dirt_Dry"
    },
    {
      "x": -17,
      "y": 4,
      "z": -8,
      "name": "Soil_Dirt_Dry"
    },
    {
      "x": -17,
      "y": 5,
      "z": -8,
      "name": "Soil_Dirt_Dry"
    },
    {
      "x": -17,
      "y": 1,
      "z": -7,
      "name": "Rock_Sandstone"
    },
    {
      "x": -17,
      "y": 2,
      "z": -7,
      "name": "Soil_Dirt_Dry"
    },
    {
      "x": -17,
      "y": 3,
      "z": -7,
      "name": "Soil_Dirt_Dry"
    },
    {
      "x": -17,
      "y": 4,
      "z": -7,
      "name": "Soil_Dirt_Dry"
    },
    {
      "x": -17,
      "y": 5,
      "z": -7,
      "name": "Soil_Dirt_Dry"
    },
    {
      "x": -17,
      "y": 1,
      "z": -6,
      "name": "Rock_Sandstone"
    },
    {
      "x": -17,
      "y": 2,
      "z": -6,
      "name": "Soil_Dirt_Dry"
    },
    {
      "x": -17,
      "y": 3,
      "z": -6,
      "name": "Soil_Dirt_Dry"
    },
    {
      "x": -17,
      "y": 4,
      "z": -6,
      "name": "Soil_Dirt_Dry"
    },
    {
      "x": -17,
      "y": 5,
      "z": -6,
      "name": "Soil_Dirt_Dry"
    },
    {
      "x": -17,
      "y": 1,
      "z": -5,
      "name": "Rock_Sandstone"
    },
    {
      "x": -17,
      "y": 2,
      "z": -5,
      "name": "Soil_Dirt_Dry"
    },
    {
      "x": -17,
      "y": 3,
      "z": -5,
      "name": "Soil_Dirt_Dry"
    },
    {
      "x": -17,
      "y": 4,
      "z": -5,
      "name": "Soil_Dirt_Dry"
    },
    {
      "x": -17,
      "y": 5,
      "z": -5,
      "name": "Soil_Dirt_Dry"
    },
    {
      "x": -17,
      "y": 1,
      "z": -4,
      "name": "Rock_Sandstone"
    },
    {
      "x": -17,
      "y": 2,
      "z": -4,
      "name": "Soil_Dirt_Dry"
    },
    {
      "x": -17,
      "y": 3,
      "z": -4,
      "name": "Soil_Dirt_Dry"
    },
    {
      "x": -17,
      "y": 4,
      "z": -4,
      "name": "Soil_Dirt_Dry"
    },
    {
      "x": -17,
      "y": 5,
      "z": -4,
      "name": "Soil_Dirt_Dry"
    },
    {
      "x": -17,
      "y": 1,
      "z": -3,
      "name": "Rock_Sandstone"
    },
    {
      "x": -17,
      "y": 2,
      "z": -3,
      "name": "Soil_Dirt_Dry"
    },
    {
      "x": -17,
      "y": 3,
      "z": -3,
      "name": "Soil_Dirt_Dry"
    },
    {
      "x": -17,
      "y": 4,
      "z": -3,
      "name": "Soil_Dirt_Dry"
    },
    {
      "x": -17,
      "y": 5,
      "z": -3,
      "name": "Soil_Dirt_Dry"
    },
    {
      "x": -17,
      "y": 1,
      "z": -2,
      "name": "Rock_Sandstone"
    },
    {
      "x": -17,
      "y": 2,
      "z": -2,
      "name": "Soil_Dirt_Dry"
    },
    {
      "x": -17,
      "y": 3,
      "z": -2,
      "name": "Soil_Dirt_Dry"
    },
    {
      "x": -17,
      "y": 4,
      "z": -2,
      "name": "Soil_Dirt_Dry"
    },
    {
      "x": -17,
      "y": 1,
      "z": -1,
      "name": "Rock_Sandstone"
    },
    {
      "x": -17,
      "y": 2,
      "z": -1,
      "name": "Soil_Dirt_Dry"
    },
    {
      "x": -17,
      "y": 3,
      "z": -1,
      "name": "Soil_Dirt_Dry"
    },
    {
      "x": -17,
      "y": 4,
      "z": -1,
      "name": "Soil_Dirt_Dry"
    },
    {
      "x": -17,
      "y": 0,
      "z": 0,
      "name": "Rock_Sandstone"
    },
    {
      "x": -17,
      "y": 1,
      "z": 0,
      "name": "Rock_Sandstone"
    },
    {
      "x": -17,
      "y": 2,
      "z": 0,
      "name": "Rock_Sandstone"
    },
    {
      "x": -17,
      "y": 3,
      "z": 0,
      "name": "Soil_Dirt_Dry"
    },
    {
      "x": -17,
      "y": 0,
      "z": 1,
      "name": "Rock_Sandstone"
    },
    {
      "x": -17,
      "y": 1,
      "z": 1,
      "name": "Rock_Sandstone"
    },
    {
      "x": -17,
      "y": 2,
      "z": 1,
      "name": "Rock_Sandstone"
    },
    {
      "x": -17,
      "y": 3,
      "z": 1,
      "name": "Soil_Dirt_Dry"
    },
    {
      "x": -17,
      "y": 0,
      "z": 2,
      "name": "Rock_Sandstone"
    },
    {
      "x": -17,
      "y": 1,
      "z": 2,
      "name": "Rock_Sandstone"
    },
    {
      "x": -17,
      "y": 2,
      "z": 2,
      "name": "Rock_Sandstone"
    },
    {
      "x": -17,
      "y": 3,
      "z": 2,
      "name": "Soil_Dirt_Dry"
    },
    {
      "x": -17,
      "y": 0,
      "z": 3,
      "name": "Rock_Sandstone"
    },
    {
      "x": -17,
      "y": 1,
      "z": 3,
      "name": "Rock_Sandstone"
    },
    {
      "x": -17,
      "y": 2,
      "z": 3,
      "name": "Rock_Sandstone"
    },
    {
      "x": -17,
      "y": 3,
      "z": 3,
      "name": "Soil_Dirt_Dry"
    },
    {
      "x": -17,
      "y": 0,
      "z": 4,
      "name": "Rock_Sandstone"
    },
    {
      "x": -17,
      "y": 1,
      "z": 4,
      "name": "Rock_Sandstone"
    },
    {
      "x": -17,
      "y": 2,
      "z": 4,
      "name": "Rock_Sandstone"
    },
    {
      "x": -17,
      "y": 3,
      "z": 4,
      "name": "Soil_Dirt_Dry"
    },
    {
      "x": -17,
      "y": 0,
      "z": 5,
      "name": "Rock_Sandstone"
    },
    {
      "x": -17,
      "y": 1,
      "z": 5,
      "name": "Rock_Sandstone"
    },
    {
      "x": -17,
      "y": 2,
      "z": 5,
      "name": "Soil_Dirt_Dry"
    },
    {
      "x": -17,
      "y": 3,
      "z": 5,
      "name": "Soil_Dirt_Dry"
    },
    {
      "x": -17,
      "y": 4,
      "z": 5,
      "name": "Soil_Dirt_Dry"
    },
    {
      "x": -17,
      "y": 0,
      "z": 6,
      "name": "Rock_Sandstone"
    },
    {
      "x": -17,
      "y": 1,
      "z": 6,
      "name": "Rock_Sandstone"
    },
    {
      "x": -17,
      "y": 2,
      "z": 6,
      "name": "Rock_Sandstone"
    },
    {
      "x": -17,
      "y": 3,
      "z": 6,
      "name": "Soil_Dirt_Dry"
    },
    {
      "x": -17,
      "y": 0,
      "z": 7,
      "name": "Rock_Sandstone"
    },
    {
      "x": -17,
      "y": 1,
      "z": 7,
      "name": "Rock_Sandstone"
    },
    {
      "x": -17,
      "y": 2,
      "z": 7,
      "name": "Rock_Sandstone"
    },
    {
      "x": -17,
      "y": 3,
      "z": 7,
      "name": "Soil_Dirt_Dry"
    },
    {
      "x": -17,
      "y": 0,
      "z": 8,
      "name": "Rock_Sandstone"
    },
    {
      "x": -17,
      "y": 1,
      "z": 8,
      "name": "Rock_Sandstone"
    },
    {
      "x": -17,
      "y": 2,
      "z": 8,
      "name": "Rock_Sandstone"
    },
    {
      "x": -17,
      "y": 3,
      "z": 8,
      "name": "Soil_Dirt_Dry"
    },
    {
      "x": -17,
      "y": 0,
      "z": 9,
      "name": "Rock_Sandstone"
    },
    {
      "x": -17,
      "y": 1,
      "z": 9,
      "name": "Rock_Sandstone"
    },
    {
      "x": -17,
      "y": 2,
      "z": 9,
      "name": "Rock_Sandstone"
    },
    {
      "x": -16,
      "y": 0,
      "z": -20,
      "name": "Rock_Sandstone"
    },
    {
      "x": -16,
      "y": 1,
      "z": -20,
      "name": "Rock_Sandstone"
    },
    {
      "x": -16,
      "y": 2,
      "z": -20,
      "name": "Rock_Sandstone"
    },
    {
      "x": -16,
      "y": 3,
      "z": -20,
      "name": "Soil_Gravel_Sand"
    },
    {
      "x": -16,
      "y": 0,
      "z": -19,
      "name": "Rock_Sandstone"
    },
    {
      "x": -16,
      "y": 1,
      "z": -19,
      "name": "Rock_Sandstone"
    },
    {
      "x": -16,
      "y": 2,
      "z": -19,
      "name": "Rock_Sandstone"
    },
    {
      "x": -16,
      "y": 3,
      "z": -19,
      "name": "Soil_Dirt_Dry"
    },
    {
      "x": -16,
      "y": 0,
      "z": -18,
      "name": "Rock_Sandstone"
    },
    {
      "x": -16,
      "y": 1,
      "z": -18,
      "name": "Rock_Sandstone"
    },
    {
      "x": -16,
      "y": 2,
      "z": -18,
      "name": "Soil_Dirt_Dry"
    },
    {
      "x": -16,
      "y": 3,
      "z": -18,
      "name": "Soil_Dirt_Dry"
    },
    {
      "x": -16,
      "y": 4,
      "z": -18,
      "name": "Soil_Dirt_Dry"
    },
    {
      "x": -16,
      "y": 1,
      "z": -17,
      "name": "Rock_Sandstone"
    },
    {
      "x": -16,
      "y": 2,
      "z": -17,
      "name": "Soil_Dirt_Dry"
    },
    {
      "x": -16,
      "y": 3,
      "z": -17,
      "name": "Soil_Dirt_Dry"
    },
    {
      "x": -16,
      "y": 4,
      "z": -17,
      "name": "Soil_Dirt_Dry"
    },
    {
      "x": -16,
      "y": 1,
      "z": -16,
      "name": "Rock_Sandstone"
    },
    {
      "x": -16,
      "y": 2,
      "z": -16,
      "name": "Soil_Dirt_Dry"
    },
    {
      "x": -16,
      "y": 3,
      "z": -16,
      "name": "Soil_Dirt_Dry"
    },
    {
      "x": -16,
      "y": 4,
      "z": -16,
      "name": "Soil_Dirt_Dry"
    },
    {
      "x": -16,
      "y": 1,
      "z": -15,
      "name": "Rock_Sandstone"
    },
    {
      "x": -16,
      "y": 2,
      "z": -15,
      "name": "Soil_Dirt_Dry"
    },
    {
      "x": -16,
      "y": 3,
      "z": -15,
      "name": "Soil_Dirt_Dry"
    },
    {
      "x": -16,
      "y": 4,
      "z": -15,
      "name": "Soil_Dirt_Dry"
    },
    {
      "x": -16,
      "y": 1,
      "z": -14,
      "name": "Rock_Sandstone"
    },
    {
      "x": -16,
      "y": 2,
      "z": -14,
      "name": "Soil_Dirt_Dry"
    },
    {
      "x": -16,
      "y": 3,
      "z": -14,
      "name": "Soil_Dirt_Dry"
    },
    {
      "x": -16,
      "y": 4,
      "z": -14,
      "name": "Soil_Dirt_Dry"
    },
    {
      "x": -16,
      "y": 0,
      "z": -13,
      "name": "Rock_Sandstone"
    },
    {
      "x": -16,
      "y": 1,
      "z": -13,
      "name": "Rock_Sandstone"
    },
    {
      "x": -16,
      "y": 2,
      "z": -13,
      "name": "Soil_Dirt_Dry"
    },
    {
      "x": -16,
      "y": 3,
      "z": -13,
      "name": "Soil_Dirt_Dry"
    },
    {
      "x": -16,
      "y": 4,
      "z": -13,
      "name": "Soil_Dirt_Dry"
    },
    {
      "x": -16,
      "y": 0,
      "z": -12,
      "name": "Rock_Sandstone"
    },
    {
      "x": -16,
      "y": 1,
      "z": -12,
      "name": "Rock_Sandstone"
    },
    {
      "x": -16,
      "y": 2,
      "z": -12,
      "name": "Soil_Dirt_Dry"
    },
    {
      "x": -16,
      "y": 3,
      "z": -12,
      "name": "Soil_Dirt_Dry"
    },
    {
      "x": -16,
      "y": 4,
      "z": -12,
      "name": "Soil_Dirt_Dry"
    },
    {
      "x": -16,
      "y": 0,
      "z": -11,
      "name": "Rock_Sandstone"
    },
    {
      "x": -16,
      "y": 1,
      "z": -11,
      "name": "Rock_Sandstone"
    },
    {
      "x": -16,
      "y": 2,
      "z": -11,
      "name": "Soil_Dirt_Dry"
    },
    {
      "x": -16,
      "y": 3,
      "z": -11,
      "name": "Soil_Dirt_Dry"
    },
    {
      "x": -16,
      "y": 4,
      "z": -11,
      "name": "Soil_Dirt_Dry"
    },
    {
      "x": -16,
      "y": 0,
      "z": -10,
      "name": "Rock_Sandstone"
    },
    {
      "x": -16,
      "y": 1,
      "z": -10,
      "name": "Rock_Sandstone"
    },
    {
      "x": -16,
      "y": 2,
      "z": -10,
      "name": "Soil_Dirt_Dry"
    },
    {
      "x": -16,
      "y": 3,
      "z": -10,
      "name": "Soil_Dirt_Dry"
    },
    {
      "x": -16,
      "y": 4,
      "z": -10,
      "name": "Soil_Dirt_Dry"
    },
    {
      "x": -16,
      "y": 1,
      "z": -9,
      "name": "Rock_Sandstone"
    },
    {
      "x": -16,
      "y": 2,
      "z": -9,
      "name": "Soil_Dirt_Dry"
    },
    {
      "x": -16,
      "y": 3,
      "z": -9,
      "name": "Soil_Dirt_Dry"
    },
    {
      "x": -16,
      "y": 4,
      "z": -9,
      "name": "Soil_Dirt_Dry"
    },
    {
      "x": -16,
      "y": 5,
      "z": -9,
      "name": "Soil_Dirt_Dry"
    },
    {
      "x": -16,
      "y": 1,
      "z": -8,
      "name": "Rock_Sandstone"
    },
    {
      "x": -16,
      "y": 2,
      "z": -8,
      "name": "Soil_Dirt_Dry"
    },
    {
      "x": -16,
      "y": 3,
      "z": -8,
      "name": "Soil_Dirt_Dry"
    },
    {
      "x": -16,
      "y": 4,
      "z": -8,
      "name": "Soil_Dirt_Dry"
    },
    {
      "x": -16,
      "y": 5,
      "z": -8,
      "name": "Soil_Dirt_Dry"
    },
    {
      "x": -16,
      "y": 1,
      "z": -7,
      "name": "Rock_Sandstone"
    },
    {
      "x": -16,
      "y": 2,
      "z": -7,
      "name": "Soil_Dirt_Dry"
    },
    {
      "x": -16,
      "y": 3,
      "z": -7,
      "name": "Soil_Dirt_Dry"
    },
    {
      "x": -16,
      "y": 4,
      "z": -7,
      "name": "Soil_Dirt_Dry"
    },
    {
      "x": -16,
      "y": 5,
      "z": -7,
      "name": "Soil_Dirt_Dry"
    },
    {
      "x": -16,
      "y": 1,
      "z": -6,
      "name": "Rock_Sandstone"
    },
    {
      "x": -16,
      "y": 2,
      "z": -6,
      "name": "Soil_Dirt_Dry"
    },
    {
      "x": -16,
      "y": 3,
      "z": -6,
      "name": "Soil_Dirt_Dry"
    },
    {
      "x": -16,
      "y": 4,
      "z": -6,
      "name": "Soil_Dirt_Dry"
    },
    {
      "x": -16,
      "y": 5,
      "z": -6,
      "name": "Soil_Dirt_Dry"
    },
    {
      "x": -16,
      "y": 1,
      "z": -5,
      "name": "Rock_Sandstone"
    },
    {
      "x": -16,
      "y": 2,
      "z": -5,
      "name": "Soil_Dirt_Dry"
    },
    {
      "x": -16,
      "y": 3,
      "z": -5,
      "name": "Soil_Dirt_Dry"
    },
    {
      "x": -16,
      "y": 4,
      "z": -5,
      "name": "Soil_Dirt_Dry"
    },
    {
      "x": -16,
      "y": 5,
      "z": -5,
      "name": "Soil_Dirt_Dry"
    },
    {
      "x": -16,
      "y": 1,
      "z": -4,
      "name": "Rock_Sandstone"
    },
    {
      "x": -16,
      "y": 2,
      "z": -4,
      "name": "Soil_Dirt_Dry"
    },
    {
      "x": -16,
      "y": 3,
      "z": -4,
      "name": "Soil_Dirt_Dry"
    },
    {
      "x": -16,
      "y": 4,
      "z": -4,
      "name": "Soil_Dirt_Dry"
    },
    {
      "x": -16,
      "y": 5,
      "z": -4,
      "name": "Soil_Dirt_Dry"
    },
    {
      "x": -16,
      "y": 1,
      "z": -3,
      "name": "Rock_Sandstone"
    },
    {
      "x": -16,
      "y": 2,
      "z": -3,
      "name": "Soil_Dirt_Dry"
    },
    {
      "x": -16,
      "y": 3,
      "z": -3,
      "name": "Soil_Dirt_Dry"
    },
    {
      "x": -16,
      "y": 4,
      "z": -3,
      "name": "Soil_Dirt_Dry"
    },
    {
      "x": -16,
      "y": 5,
      "z": -3,
      "name": "Soil_Dirt_Dry"
    },
    {
      "x": -16,
      "y": 1,
      "z": -2,
      "name": "Rock_Sandstone"
    },
    {
      "x": -16,
      "y": 2,
      "z": -2,
      "name": "Soil_Dirt_Dry"
    },
    {
      "x": -16,
      "y": 3,
      "z": -2,
      "name": "Soil_Dirt_Dry"
    },
    {
      "x": -16,
      "y": 4,
      "z": -2,
      "name": "Soil_Dirt_Dry"
    },
    {
      "x": -16,
      "y": 5,
      "z": -2,
      "name": "Soil_Dirt_Dry"
    },
    {
      "x": -16,
      "y": 1,
      "z": -1,
      "name": "Rock_Sandstone"
    },
    {
      "x": -16,
      "y": 2,
      "z": -1,
      "name": "Soil_Dirt_Dry"
    },
    {
      "x": -16,
      "y": 3,
      "z": -1,
      "name": "Soil_Dirt_Dry"
    },
    {
      "x": -16,
      "y": 4,
      "z": -1,
      "name": "Soil_Dirt_Dry"
    },
    {
      "x": -16,
      "y": 5,
      "z": -1,
      "name": "Soil_Dirt_Dry"
    },
    {
      "x": -16,
      "y": 0,
      "z": 0,
      "name": "Rock_Sandstone"
    },
    {
      "x": -16,
      "y": 1,
      "z": 0,
      "name": "Rock_Sandstone"
    },
    {
      "x": -16,
      "y": 2,
      "z": 0,
      "name": "Soil_Dirt_Dry"
    },
    {
      "x": -16,
      "y": 3,
      "z": 0,
      "name": "Soil_Dirt_Dry"
    },
    {
      "x": -16,
      "y": 4,
      "z": 0,
      "name": "Soil_Dirt_Dry"
    },
    {
      "x": -16,
      "y": 5,
      "z": 0,
      "name": "Soil_Dirt_Dry"
    },
    {
      "x": -16,
      "y": 0,
      "z": 1,
      "name": "Rock_Sandstone"
    },
    {
      "x": -16,
      "y": 1,
      "z": 1,
      "name": "Rock_Sandstone"
    },
    {
      "x": -16,
      "y": 2,
      "z": 1,
      "name": "Soil_Dirt_Dry"
    },
    {
      "x": -16,
      "y": 3,
      "z": 1,
      "name": "Soil_Dirt_Dry"
    },
    {
      "x": -16,
      "y": 4,
      "z": 1,
      "name": "Soil_Dirt_Dry"
    },
    {
      "x": -16,
      "y": 0,
      "z": 2,
      "name": "Rock_Sandstone"
    },
    {
      "x": -16,
      "y": 1,
      "z": 2,
      "name": "Rock_Sandstone"
    },
    {
      "x": -16,
      "y": 2,
      "z": 2,
      "name": "Soil_Dirt_Dry"
    },
    {
      "x": -16,
      "y": 3,
      "z": 2,
      "name": "Soil_Dirt_Dry"
    },
    {
      "x": -16,
      "y": 4,
      "z": 2,
      "name": "Soil_Gravel_Sand"
    },
    {
      "x": -16,
      "y": 1,
      "z": 3,
      "name": "Rock_Sandstone"
    },
    {
      "x": -16,
      "y": 2,
      "z": 3,
      "name": "Soil_Dirt_Dry"
    },
    {
      "x": -16,
      "y": 3,
      "z": 3,
      "name": "Soil_Dirt_Dry"
    },
    {
      "x": -16,
      "y": 4,
      "z": 3,
      "name": "Soil_Dirt_Dry"
    },
    {
      "x": -16,
      "y": 1,
      "z": 4,
      "name": "Rock_Sandstone"
    },
    {
      "x": -16,
      "y": 2,
      "z": 4,
      "name": "Soil_Dirt_Dry"
    },
    {
      "x": -16,
      "y": 3,
      "z": 4,
      "name": "Soil_Dirt_Dry"
    },
    {
      "x": -16,
      "y": 4,
      "z": 4,
      "name": "Soil_Dirt_Dry"
    },
    {
      "x": -16,
      "y": 1,
      "z": 5,
      "name": "Rock_Sandstone"
    },
    {
      "x": -16,
      "y": 2,
      "z": 5,
      "name": "Soil_Dirt_Dry"
    },
    {
      "x": -16,
      "y": 3,
      "z": 5,
      "name": "Soil_Dirt_Dry"
    },
    {
      "x": -16,
      "y": 4,
      "z": 5,
      "name": "Soil_Dirt_Dry"
    },
    {
      "x": -16,
      "y": 1,
      "z": 6,
      "name": "Rock_Sandstone"
    },
    {
      "x": -16,
      "y": 2,
      "z": 6,
      "name": "Soil_Dirt_Dry"
    },
    {
      "x": -16,
      "y": 3,
      "z": 6,
      "name": "Soil_Dirt_Dry"
    },
    {
      "x": -16,
      "y": 4,
      "z": 6,
      "name": "Soil_Dirt_Dry"
    },
    {
      "x": -16,
      "y": 1,
      "z": 7,
      "name": "Rock_Sandstone"
    },
    {
      "x": -16,
      "y": 2,
      "z": 7,
      "name": "Soil_Dirt_Dry"
    },
    {
      "x": -16,
      "y": 3,
      "z": 7,
      "name": "Soil_Dirt_Dry"
    },
    {
      "x": -16,
      "y": 4,
      "z": 7,
      "name": "Soil_Dirt_Dry"
    },
    {
      "x": -16,
      "y": 0,
      "z": 8,
      "name": "Rock_Sandstone"
    },
    {
      "x": -16,
      "y": 1,
      "z": 8,
      "name": "Rock_Sandstone"
    },
    {
      "x": -16,
      "y": 2,
      "z": 8,
      "name": "Soil_Dirt_Dry"
    },
    {
      "x": -16,
      "y": 3,
      "z": 8,
      "name": "Soil_Dirt_Dry"
    },
    {
      "x": -16,
      "y": 4,
      "z": 8,
      "name": "Soil_Dirt_Dry"
    },
    {
      "x": -16,
      "y": 0,
      "z": 9,
      "name": "Rock_Sandstone"
    },
    {
      "x": -16,
      "y": 1,
      "z": 9,
      "name": "Rock_Sandstone"
    },
    {
      "x": -16,
      "y": 2,
      "z": 9,
      "name": "Rock_Sandstone"
    },
    {
      "x": -16,
      "y": 3,
      "z": 9,
      "name": "Soil_Dirt_Dry"
    },
    {
      "x": -16,
      "y": 0,
      "z": 10,
      "name": "Rock_Sandstone"
    },
    {
      "x": -16,
      "y": 1,
      "z": 10,
      "name": "Rock_Sandstone"
    },
    {
      "x": -16,
      "y": 2,
      "z": 10,
      "name": "Rock_Sandstone"
    },
    {
      "x": -16,
      "y": 3,
      "z": 10,
      "name": "Soil_Dirt_Dry"
    },
    {
      "x": -15,
      "y": 0,
      "z": -21,
      "name": "Rock_Sandstone"
    },
    {
      "x": -15,
      "y": 1,
      "z": -21,
      "name": "Rock_Sandstone"
    },
    {
      "x": -15,
      "y": 2,
      "z": -21,
      "name": "Rock_Sandstone"
    },
    {
      "x": -15,
      "y": 0,
      "z": -20,
      "name": "Rock_Sandstone"
    },
    {
      "x": -15,
      "y": 1,
      "z": -20,
      "name": "Rock_Sandstone"
    },
    {
      "x": -15,
      "y": 2,
      "z": -20,
      "name": "Rock_Sandstone"
    },
    {
      "x": -15,
      "y": 3,
      "z": -20,
      "name": "Soil_Dirt_Dry"
    },
    {
      "x": -15,
      "y": 0,
      "z": -19,
      "name": "Rock_Sandstone"
    },
    {
      "x": -15,
      "y": 1,
      "z": -19,
      "name": "Rock_Sandstone"
    },
    {
      "x": -15,
      "y": 2,
      "z": -19,
      "name": "Soil_Dirt_Dry"
    },
    {
      "x": -15,
      "y": 3,
      "z": -19,
      "name": "Soil_Dirt_Dry"
    },
    {
      "x": -15,
      "y": 4,
      "z": -19,
      "name": "Soil_Dirt_Dry"
    },
    {
      "x": -15,
      "y": 1,
      "z": -18,
      "name": "Rock_Sandstone"
    },
    {
      "x": -15,
      "y": 2,
      "z": -18,
      "name": "Soil_Dirt_Dry"
    },
    {
      "x": -15,
      "y": 3,
      "z": -18,
      "name": "Soil_Dirt_Dry"
    },
    {
      "x": -15,
      "y": 4,
      "z": -18,
      "name": "Soil_Dirt_Dry"
    },
    {
      "x": -15,
      "y": 1,
      "z": -17,
      "name": "Rock_Sandstone"
    },
    {
      "x": -15,
      "y": 2,
      "z": -17,
      "name": "Soil_Dirt_Dry"
    },
    {
      "x": -15,
      "y": 3,
      "z": -17,
      "name": "Soil_Dirt_Dry"
    },
    {
      "x": -15,
      "y": 4,
      "z": -17,
      "name": "Soil_Dirt_Dry"
    },
    {
      "x": -15,
      "y": 1,
      "z": -16,
      "name": "Rock_Sandstone"
    },
    {
      "x": -15,
      "y": 2,
      "z": -16,
      "name": "Soil_Dirt_Dry"
    },
    {
      "x": -15,
      "y": 3,
      "z": -16,
      "name": "Soil_Dirt_Dry"
    },
    {
      "x": -15,
      "y": 4,
      "z": -16,
      "name": "Soil_Dirt_Dry"
    },
    {
      "x": -15,
      "y": 1,
      "z": -15,
      "name": "Rock_Sandstone"
    },
    {
      "x": -15,
      "y": 2,
      "z": -15,
      "name": "Soil_Dirt_Dry"
    },
    {
      "x": -15,
      "y": 3,
      "z": -15,
      "name": "Soil_Dirt_Dry"
    },
    {
      "x": -15,
      "y": 4,
      "z": -15,
      "name": "Soil_Dirt_Dry"
    },
    {
      "x": -15,
      "y": 5,
      "z": -15,
      "name": "Soil_Dirt_Dry"
    },
    {
      "x": -15,
      "y": 1,
      "z": -14,
      "name": "Rock_Sandstone"
    },
    {
      "x": -15,
      "y": 2,
      "z": -14,
      "name": "Soil_Dirt_Dry"
    },
    {
      "x": -15,
      "y": 3,
      "z": -14,
      "name": "Soil_Dirt_Dry"
    },
    {
      "x": -15,
      "y": 4,
      "z": -14,
      "name": "Soil_Dirt_Dry"
    },
    {
      "x": -15,
      "y": 5,
      "z": -14,
      "name": "Soil_Dirt_Dry"
    },
    {
      "x": -15,
      "y": 0,
      "z": -13,
      "name": "Rock_Sandstone"
    },
    {
      "x": -15,
      "y": 1,
      "z": -13,
      "name": "Rock_Sandstone"
    },
    {
      "x": -15,
      "y": 2,
      "z": -13,
      "name": "Soil_Dirt_Dry"
    },
    {
      "x": -15,
      "y": 3,
      "z": -13,
      "name": "Soil_Dirt_Dry"
    },
    {
      "x": -15,
      "y": 4,
      "z": -13,
      "name": "Soil_Dirt_Dry"
    },
    {
      "x": -15,
      "y": 5,
      "z": -13,
      "name": "Soil_Dirt_Dry"
    },
    {
      "x": -15,
      "y": 0,
      "z": -12,
      "name": "Rock_Sandstone"
    },
    {
      "x": -15,
      "y": 1,
      "z": -12,
      "name": "Rock_Sandstone"
    },
    {
      "x": -15,
      "y": 2,
      "z": -12,
      "name": "Soil_Dirt_Dry"
    },
    {
      "x": -15,
      "y": 3,
      "z": -12,
      "name": "Soil_Dirt_Dry"
    },
    {
      "x": -15,
      "y": 4,
      "z": -12,
      "name": "Soil_Dirt_Dry"
    },
    {
      "x": -15,
      "y": 5,
      "z": -12,
      "name": "Soil_Dirt_Dry"
    },
    {
      "x": -15,
      "y": 0,
      "z": -11,
      "name": "Rock_Sandstone"
    },
    {
      "x": -15,
      "y": 1,
      "z": -11,
      "name": "Rock_Sandstone"
    },
    {
      "x": -15,
      "y": 2,
      "z": -11,
      "name": "Soil_Dirt_Dry"
    },
    {
      "x": -15,
      "y": 3,
      "z": -11,
      "name": "Soil_Dirt_Dry"
    },
    {
      "x": -15,
      "y": 4,
      "z": -11,
      "name": "Soil_Dirt_Dry"
    },
    {
      "x": -15,
      "y": 5,
      "z": -11,
      "name": "Soil_Dirt_Dry"
    },
    {
      "x": -15,
      "y": 0,
      "z": -10,
      "name": "Rock_Sandstone"
    },
    {
      "x": -15,
      "y": 1,
      "z": -10,
      "name": "Rock_Sandstone"
    },
    {
      "x": -15,
      "y": 2,
      "z": -10,
      "name": "Soil_Dirt_Dry"
    },
    {
      "x": -15,
      "y": 3,
      "z": -10,
      "name": "Soil_Dirt_Dry"
    },
    {
      "x": -15,
      "y": 4,
      "z": -10,
      "name": "Soil_Dirt_Dry"
    },
    {
      "x": -15,
      "y": 5,
      "z": -10,
      "name": "Soil_Dirt_Dry"
    },
    {
      "x": -15,
      "y": 0,
      "z": -9,
      "name": "Rock_Sandstone"
    },
    {
      "x": -15,
      "y": 1,
      "z": -9,
      "name": "Rock_Sandstone"
    },
    {
      "x": -15,
      "y": 2,
      "z": -9,
      "name": "Soil_Dirt_Dry"
    },
    {
      "x": -15,
      "y": 3,
      "z": -9,
      "name": "Soil_Dirt_Dry"
    },
    {
      "x": -15,
      "y": 4,
      "z": -9,
      "name": "Soil_Dirt_Dry"
    },
    {
      "x": -15,
      "y": 5,
      "z": -9,
      "name": "Soil_Dirt_Dry"
    },
    {
      "x": -15,
      "y": 1,
      "z": -8,
      "name": "Rock_Sandstone"
    },
    {
      "x": -15,
      "y": 2,
      "z": -8,
      "name": "Soil_Dirt_Dry"
    },
    {
      "x": -15,
      "y": 3,
      "z": -8,
      "name": "Soil_Dirt_Dry"
    },
    {
      "x": -15,
      "y": 4,
      "z": -8,
      "name": "Soil_Dirt_Dry"
    },
    {
      "x": -15,
      "y": 5,
      "z": -8,
      "name": "Soil_Dirt_Dry"
    },
    {
      "x": -15,
      "y": 1,
      "z": -7,
      "name": "Rock_Sandstone"
    },
    {
      "x": -15,
      "y": 2,
      "z": -7,
      "name": "Soil_Dirt_Dry"
    },
    {
      "x": -15,
      "y": 3,
      "z": -7,
      "name": "Soil_Dirt_Dry"
    },
    {
      "x": -15,
      "y": 4,
      "z": -7,
      "name": "Soil_Dirt_Dry"
    },
    {
      "x": -15,
      "y": 5,
      "z": -7,
      "name": "Soil_Dirt_Dry"
    },
    {
      "x": -15,
      "y": 1,
      "z": -6,
      "name": "Rock_Sandstone"
    },
    {
      "x": -15,
      "y": 2,
      "z": -6,
      "name": "Soil_Dirt_Dry"
    },
    {
      "x": -15,
      "y": 3,
      "z": -6,
      "name": "Soil_Dirt_Dry"
    },
    {
      "x": -15,
      "y": 4,
      "z": -6,
      "name": "Soil_Dirt_Dry"
    },
    {
      "x": -15,
      "y": 5,
      "z": -6,
      "name": "Soil_Dirt_Dry"
    },
    {
      "x": -15,
      "y": 1,
      "z": -5,
      "name": "Rock_Sandstone"
    },
    {
      "x": -15,
      "y": 2,
      "z": -5,
      "name": "Soil_Dirt_Dry"
    },
    {
      "x": -15,
      "y": 3,
      "z": -5,
      "name": "Soil_Dirt_Dry"
    },
    {
      "x": -15,
      "y": 4,
      "z": -5,
      "name": "Soil_Dirt_Dry"
    },
    {
      "x": -15,
      "y": 5,
      "z": -5,
      "name": "Soil_Dirt_Dry"
    },
    {
      "x": -15,
      "y": 1,
      "z": -4,
      "name": "Rock_Sandstone"
    },
    {
      "x": -15,
      "y": 2,
      "z": -4,
      "name": "Soil_Dirt_Dry"
    },
    {
      "x": -15,
      "y": 3,
      "z": -4,
      "name": "Soil_Dirt_Dry"
    },
    {
      "x": -15,
      "y": 4,
      "z": -4,
      "name": "Soil_Dirt_Dry"
    },
    {
      "x": -15,
      "y": 5,
      "z": -4,
      "name": "Soil_Dirt_Dry"
    },
    {
      "x": -15,
      "y": 1,
      "z": -3,
      "name": "Rock_Sandstone"
    },
    {
      "x": -15,
      "y": 2,
      "z": -3,
      "name": "Soil_Dirt_Dry"
    },
    {
      "x": -15,
      "y": 3,
      "z": -3,
      "name": "Soil_Dirt_Dry"
    },
    {
      "x": -15,
      "y": 4,
      "z": -3,
      "name": "Soil_Dirt_Dry"
    },
    {
      "x": -15,
      "y": 5,
      "z": -3,
      "name": "Soil_Dirt_Dry"
    },
    {
      "x": -15,
      "y": 1,
      "z": -2,
      "name": "Rock_Sandstone"
    },
    {
      "x": -15,
      "y": 2,
      "z": -2,
      "name": "Soil_Dirt_Dry"
    },
    {
      "x": -15,
      "y": 3,
      "z": -2,
      "name": "Soil_Dirt_Dry"
    },
    {
      "x": -15,
      "y": 4,
      "z": -2,
      "name": "Soil_Dirt_Dry"
    },
    {
      "x": -15,
      "y": 5,
      "z": -2,
      "name": "Soil_Dirt_Dry"
    },
    {
      "x": -15,
      "y": 0,
      "z": -1,
      "name": "Rock_Sandstone"
    },
    {
      "x": -15,
      "y": 1,
      "z": -1,
      "name": "Rock_Sandstone"
    },
    {
      "x": -15,
      "y": 2,
      "z": -1,
      "name": "Soil_Dirt_Dry"
    },
    {
      "x": -15,
      "y": 3,
      "z": -1,
      "name": "Soil_Dirt_Dry"
    },
    {
      "x": -15,
      "y": 4,
      "z": -1,
      "name": "Soil_Dirt_Dry"
    },
    {
      "x": -15,
      "y": 5,
      "z": -1,
      "name": "Soil_Dirt_Dry"
    },
    {
      "x": -15,
      "y": 0,
      "z": 0,
      "name": "Rock_Sandstone"
    },
    {
      "x": -15,
      "y": 1,
      "z": 0,
      "name": "Rock_Sandstone"
    },
    {
      "x": -15,
      "y": 2,
      "z": 0,
      "name": "Soil_Dirt_Dry"
    },
    {
      "x": -15,
      "y": 3,
      "z": 0,
      "name": "Soil_Dirt_Dry"
    },
    {
      "x": -15,
      "y": 4,
      "z": 0,
      "name": "Soil_Dirt_Dry"
    },
    {
      "x": -15,
      "y": 5,
      "z": 0,
      "name": "Soil_Dirt_Dry"
    },
    {
      "x": -15,
      "y": 0,
      "z": 1,
      "name": "Rock_Sandstone"
    },
    {
      "x": -15,
      "y": 1,
      "z": 1,
      "name": "Rock_Sandstone"
    },
    {
      "x": -15,
      "y": 2,
      "z": 1,
      "name": "Soil_Dirt_Dry"
    },
    {
      "x": -15,
      "y": 3,
      "z": 1,
      "name": "Soil_Dirt_Dry"
    },
    {
      "x": -15,
      "y": 4,
      "z": 1,
      "name": "Soil_Dirt_Dry"
    },
    {
      "x": -15,
      "y": 5,
      "z": 1,
      "name": "Soil_Dirt_Dry"
    },
    {
      "x": -15,
      "y": 1,
      "z": 2,
      "name": "Rock_Sandstone"
    },
    {
      "x": -15,
      "y": 2,
      "z": 2,
      "name": "Soil_Dirt_Dry"
    },
    {
      "x": -15,
      "y": 3,
      "z": 2,
      "name": "Soil_Dirt_Dry"
    },
    {
      "x": -15,
      "y": 4,
      "z": 2,
      "name": "Soil_Dirt_Dry"
    },
    {
      "x": -15,
      "y": 5,
      "z": 2,
      "name": "Soil_Dirt_Dry"
    },
    {
      "x": -15,
      "y": 1,
      "z": 3,
      "name": "Rock_Sandstone"
    },
    {
      "x": -15,
      "y": 2,
      "z": 3,
      "name": "Soil_Dirt_Dry"
    },
    {
      "x": -15,
      "y": 3,
      "z": 3,
      "name": "Soil_Dirt_Dry"
    },
    {
      "x": -15,
      "y": 4,
      "z": 3,
      "name": "Soil_Dirt_Dry"
    },
    {
      "x": -15,
      "y": 5,
      "z": 3,
      "name": "Soil_Dirt_Dry"
    },
    {
      "x": -15,
      "y": 1,
      "z": 4,
      "name": "Rock_Sandstone"
    },
    {
      "x": -15,
      "y": 2,
      "z": 4,
      "name": "Soil_Dirt_Dry"
    },
    {
      "x": -15,
      "y": 3,
      "z": 4,
      "name": "Soil_Dirt_Dry"
    },
    {
      "x": -15,
      "y": 4,
      "z": 4,
      "name": "Soil_Dirt_Dry"
    },
    {
      "x": -15,
      "y": 5,
      "z": 4,
      "name": "Soil_Dirt_Dry"
    },
    {
      "x": -15,
      "y": 1,
      "z": 5,
      "name": "Rock_Sandstone"
    },
    {
      "x": -15,
      "y": 2,
      "z": 5,
      "name": "Soil_Dirt_Dry"
    },
    {
      "x": -15,
      "y": 3,
      "z": 5,
      "name": "Soil_Dirt_Dry"
    },
    {
      "x": -15,
      "y": 4,
      "z": 5,
      "name": "Soil_Dirt_Dry"
    },
    {
      "x": -15,
      "y": 5,
      "z": 5,
      "name": "Soil_Dirt_Dry"
    },
    {
      "x": -15,
      "y": 1,
      "z": 6,
      "name": "Rock_Sandstone"
    },
    {
      "x": -15,
      "y": 2,
      "z": 6,
      "name": "Soil_Dirt_Dry"
    },
    {
      "x": -15,
      "y": 3,
      "z": 6,
      "name": "Soil_Dirt_Dry"
    },
    {
      "x": -15,
      "y": 4,
      "z": 6,
      "name": "Soil_Dirt_Dry"
    },
    {
      "x": -15,
      "y": 1,
      "z": 7,
      "name": "Rock_Sandstone"
    },
    {
      "x": -15,
      "y": 2,
      "z": 7,
      "name": "Soil_Dirt_Dry"
    },
    {
      "x": -15,
      "y": 3,
      "z": 7,
      "name": "Soil_Dirt_Dry"
    },
    {
      "x": -15,
      "y": 4,
      "z": 7,
      "name": "Soil_Dirt_Dry"
    },
    {
      "x": -15,
      "y": 1,
      "z": 8,
      "name": "Rock_Sandstone"
    },
    {
      "x": -15,
      "y": 2,
      "z": 8,
      "name": "Soil_Dirt_Dry"
    },
    {
      "x": -15,
      "y": 3,
      "z": 8,
      "name": "Soil_Dirt_Dry"
    },
    {
      "x": -15,
      "y": 4,
      "z": 8,
      "name": "Soil_Dirt_Dry"
    },
    {
      "x": -15,
      "y": 0,
      "z": 9,
      "name": "Rock_Sandstone"
    },
    {
      "x": -15,
      "y": 1,
      "z": 9,
      "name": "Rock_Sandstone"
    },
    {
      "x": -15,
      "y": 2,
      "z": 9,
      "name": "Soil_Dirt_Dry"
    },
    {
      "x": -15,
      "y": 3,
      "z": 9,
      "name": "Soil_Dirt_Dry"
    },
    {
      "x": -15,
      "y": 4,
      "z": 9,
      "name": "Soil_Dirt_Dry"
    },
    {
      "x": -15,
      "y": 0,
      "z": 10,
      "name": "Rock_Sandstone"
    },
    {
      "x": -15,
      "y": 1,
      "z": 10,
      "name": "Rock_Sandstone"
    },
    {
      "x": -15,
      "y": 2,
      "z": 10,
      "name": "Rock_Sandstone"
    },
    {
      "x": -15,
      "y": 3,
      "z": 10,
      "name": "Soil_Dirt_Dry"
    },
    {
      "x": -15,
      "y": 0,
      "z": 11,
      "name": "Rock_Sandstone"
    },
    {
      "x": -15,
      "y": 1,
      "z": 11,
      "name": "Rock_Sandstone"
    },
    {
      "x": -15,
      "y": 2,
      "z": 11,
      "name": "Rock_Sandstone"
    },
    {
      "x": -14,
      "y": 0,
      "z": -21,
      "name": "Rock_Sandstone"
    },
    {
      "x": -14,
      "y": 1,
      "z": -21,
      "name": "Rock_Sandstone"
    },
    {
      "x": -14,
      "y": 2,
      "z": -21,
      "name": "Rock_Sandstone"
    },
    {
      "x": -14,
      "y": 3,
      "z": -21,
      "name": "Soil_Dirt_Dry"
    },
    {
      "x": -14,
      "y": 0,
      "z": -20,
      "name": "Rock_Sandstone"
    },
    {
      "x": -14,
      "y": 1,
      "z": -20,
      "name": "Rock_Sandstone"
    },
    {
      "x": -14,
      "y": 2,
      "z": -20,
      "name": "Soil_Dirt_Dry"
    },
    {
      "x": -14,
      "y": 3,
      "z": -20,
      "name": "Soil_Dirt_Dry"
    },
    {
      "x": -14,
      "y": 4,
      "z": -20,
      "name": "Soil_Dirt_Dry"
    },
    {
      "x": -14,
      "y": 1,
      "z": -19,
      "name": "Rock_Sandstone"
    },
    {
      "x": -14,
      "y": 2,
      "z": -19,
      "name": "Soil_Dirt_Dry"
    },
    {
      "x": -14,
      "y": 3,
      "z": -19,
      "name": "Soil_Dirt_Dry"
    },
    {
      "x": -14,
      "y": 4,
      "z": -19,
      "name": "Soil_Dirt_Dry"
    },
    {
      "x": -14,
      "y": 1,
      "z": -18,
      "name": "Rock_Sandstone"
    },
    {
      "x": -14,
      "y": 2,
      "z": -18,
      "name": "Soil_Dirt_Dry"
    },
    {
      "x": -14,
      "y": 3,
      "z": -18,
      "name": "Soil_Dirt_Dry"
    },
    {
      "x": -14,
      "y": 4,
      "z": -18,
      "name": "Soil_Dirt_Dry"
    },
    {
      "x": -14,
      "y": 1,
      "z": -17,
      "name": "Rock_Sandstone"
    },
    {
      "x": -14,
      "y": 2,
      "z": -17,
      "name": "Soil_Dirt_Dry"
    },
    {
      "x": -14,
      "y": 3,
      "z": -17,
      "name": "Soil_Dirt_Dry"
    },
    {
      "x": -14,
      "y": 4,
      "z": -17,
      "name": "Soil_Dirt_Dry"
    },
    {
      "x": -14,
      "y": 1,
      "z": -16,
      "name": "Rock_Sandstone"
    },
    {
      "x": -14,
      "y": 2,
      "z": -16,
      "name": "Soil_Dirt_Dry"
    },
    {
      "x": -14,
      "y": 3,
      "z": -16,
      "name": "Soil_Dirt_Dry"
    },
    {
      "x": -14,
      "y": 4,
      "z": -16,
      "name": "Soil_Dirt_Dry"
    },
    {
      "x": -14,
      "y": 5,
      "z": -16,
      "name": "Soil_Dirt_Dry"
    },
    {
      "x": -14,
      "y": 1,
      "z": -15,
      "name": "Rock_Sandstone"
    },
    {
      "x": -14,
      "y": 2,
      "z": -15,
      "name": "Soil_Dirt_Dry"
    },
    {
      "x": -14,
      "y": 3,
      "z": -15,
      "name": "Soil_Dirt_Dry"
    },
    {
      "x": -14,
      "y": 4,
      "z": -15,
      "name": "Soil_Dirt_Dry"
    },
    {
      "x": -14,
      "y": 5,
      "z": -15,
      "name": "Soil_Dirt_Dry"
    },
    {
      "x": -14,
      "y": 1,
      "z": -14,
      "name": "Rock_Sandstone"
    },
    {
      "x": -14,
      "y": 2,
      "z": -14,
      "name": "Soil_Dirt_Dry"
    },
    {
      "x": -14,
      "y": 3,
      "z": -14,
      "name": "Soil_Dirt_Dry"
    },
    {
      "x": -14,
      "y": 4,
      "z": -14,
      "name": "Soil_Dirt_Dry"
    },
    {
      "x": -14,
      "y": 5,
      "z": -14,
      "name": "Soil_Dirt_Dry"
    },
    {
      "x": -14,
      "y": 0,
      "z": -13,
      "name": "Rock_Sandstone"
    },
    {
      "x": -14,
      "y": 1,
      "z": -13,
      "name": "Rock_Sandstone"
    },
    {
      "x": -14,
      "y": 2,
      "z": -13,
      "name": "Soil_Dirt_Dry"
    },
    {
      "x": -14,
      "y": 3,
      "z": -13,
      "name": "Soil_Dirt_Dry"
    },
    {
      "x": -14,
      "y": 4,
      "z": -13,
      "name": "Soil_Dirt_Dry"
    },
    {
      "x": -14,
      "y": 5,
      "z": -13,
      "name": "Soil_Dirt_Dry"
    },
    {
      "x": -14,
      "y": 0,
      "z": -12,
      "name": "Rock_Sandstone"
    },
    {
      "x": -14,
      "y": 1,
      "z": -12,
      "name": "Rock_Sandstone"
    },
    {
      "x": -14,
      "y": 2,
      "z": -12,
      "name": "Soil_Dirt_Dry"
    },
    {
      "x": -14,
      "y": 3,
      "z": -12,
      "name": "Soil_Dirt_Dry"
    },
    {
      "x": -14,
      "y": 4,
      "z": -12,
      "name": "Soil_Dirt_Dry"
    },
    {
      "x": -14,
      "y": 5,
      "z": -12,
      "name": "Soil_Dirt_Dry"
    },
    {
      "x": -14,
      "y": 1,
      "z": -11,
      "name": "Rock_Sandstone"
    },
    {
      "x": -14,
      "y": 2,
      "z": -11,
      "name": "Soil_Dirt_Dry"
    },
    {
      "x": -14,
      "y": 3,
      "z": -11,
      "name": "Soil_Dirt_Dry"
    },
    {
      "x": -14,
      "y": 4,
      "z": -11,
      "name": "Soil_Dirt_Dry"
    },
    {
      "x": -14,
      "y": 5,
      "z": -11,
      "name": "Soil_Dirt_Dry"
    },
    {
      "x": -14,
      "y": 0,
      "z": -10,
      "name": "Rock_Sandstone"
    },
    {
      "x": -14,
      "y": 1,
      "z": -10,
      "name": "Rock_Sandstone"
    },
    {
      "x": -14,
      "y": 2,
      "z": -10,
      "name": "Soil_Dirt_Dry"
    },
    {
      "x": -14,
      "y": 3,
      "z": -10,
      "name": "Soil_Dirt_Dry"
    },
    {
      "x": -14,
      "y": 4,
      "z": -10,
      "name": "Soil_Dirt_Dry"
    },
    {
      "x": -14,
      "y": 5,
      "z": -10,
      "name": "Soil_Dirt_Dry"
    },
    {
      "x": -14,
      "y": 0,
      "z": -9,
      "name": "Rock_Sandstone"
    },
    {
      "x": -14,
      "y": 1,
      "z": -9,
      "name": "Rock_Sandstone"
    },
    {
      "x": -14,
      "y": 2,
      "z": -9,
      "name": "Soil_Dirt_Dry"
    },
    {
      "x": -14,
      "y": 3,
      "z": -9,
      "name": "Soil_Dirt_Dry"
    },
    {
      "x": -14,
      "y": 4,
      "z": -9,
      "name": "Soil_Dirt_Dry"
    },
    {
      "x": -14,
      "y": 5,
      "z": -9,
      "name": "Soil_Dirt_Dry"
    },
    {
      "x": -14,
      "y": 1,
      "z": -8,
      "name": "Rock_Sandstone"
    },
    {
      "x": -14,
      "y": 2,
      "z": -8,
      "name": "Soil_Dirt_Dry"
    },
    {
      "x": -14,
      "y": 3,
      "z": -8,
      "name": "Soil_Dirt_Dry"
    },
    {
      "x": -14,
      "y": 4,
      "z": -8,
      "name": "Soil_Dirt_Dry"
    },
    {
      "x": -14,
      "y": 5,
      "z": -8,
      "name": "Soil_Dirt_Dry"
    },
    {
      "x": -14,
      "y": 1,
      "z": -7,
      "name": "Rock_Sandstone"
    },
    {
      "x": -14,
      "y": 2,
      "z": -7,
      "name": "Soil_Dirt_Dry"
    },
    {
      "x": -14,
      "y": 3,
      "z": -7,
      "name": "Soil_Dirt_Dry"
    },
    {
      "x": -14,
      "y": 4,
      "z": -7,
      "name": "Soil_Dirt_Dry"
    },
    {
      "x": -14,
      "y": 5,
      "z": -7,
      "name": "Soil_Dirt_Dry"
    },
    {
      "x": -14,
      "y": 1,
      "z": -6,
      "name": "Rock_Sandstone"
    },
    {
      "x": -14,
      "y": 2,
      "z": -6,
      "name": "Soil_Dirt_Dry"
    },
    {
      "x": -14,
      "y": 3,
      "z": -6,
      "name": "Soil_Dirt_Dry"
    },
    {
      "x": -14,
      "y": 4,
      "z": -6,
      "name": "Soil_Dirt_Dry"
    },
    {
      "x": -14,
      "y": 5,
      "z": -6,
      "name": "Soil_Dirt_Dry"
    },
    {
      "x": -14,
      "y": 1,
      "z": -5,
      "name": "Rock_Sandstone"
    },
    {
      "x": -14,
      "y": 2,
      "z": -5,
      "name": "Soil_Dirt_Dry"
    },
    {
      "x": -14,
      "y": 3,
      "z": -5,
      "name": "Soil_Dirt_Dry"
    },
    {
      "x": -14,
      "y": 4,
      "z": -5,
      "name": "Soil_Dirt_Dry"
    },
    {
      "x": -14,
      "y": 5,
      "z": -5,
      "name": "Soil_Dirt_Dry"
    },
    {
      "x": -14,
      "y": 1,
      "z": -4,
      "name": "Rock_Sandstone"
    },
    {
      "x": -14,
      "y": 2,
      "z": -4,
      "name": "Soil_Dirt_Dry"
    },
    {
      "x": -14,
      "y": 3,
      "z": -4,
      "name": "Soil_Dirt_Dry"
    },
    {
      "x": -14,
      "y": 4,
      "z": -4,
      "name": "Soil_Dirt_Dry"
    },
    {
      "x": -14,
      "y": 5,
      "z": -4,
      "name": "Soil_Dirt_Dry"
    },
    {
      "x": -14,
      "y": 1,
      "z": -3,
      "name": "Rock_Sandstone"
    },
    {
      "x": -14,
      "y": 2,
      "z": -3,
      "name": "Soil_Dirt_Dry"
    },
    {
      "x": -14,
      "y": 3,
      "z": -3,
      "name": "Soil_Dirt_Dry"
    },
    {
      "x": -14,
      "y": 4,
      "z": -3,
      "name": "Soil_Dirt_Dry"
    },
    {
      "x": -14,
      "y": 5,
      "z": -3,
      "name": "Soil_Dirt_Dry"
    },
    {
      "x": -14,
      "y": 1,
      "z": -2,
      "name": "Rock_Sandstone"
    },
    {
      "x": -14,
      "y": 2,
      "z": -2,
      "name": "Soil_Dirt_Dry"
    },
    {
      "x": -14,
      "y": 3,
      "z": -2,
      "name": "Soil_Dirt_Dry"
    },
    {
      "x": -14,
      "y": 4,
      "z": -2,
      "name": "Soil_Dirt_Dry"
    },
    {
      "x": -14,
      "y": 5,
      "z": -2,
      "name": "Soil_Dirt_Dry"
    },
    {
      "x": -14,
      "y": 0,
      "z": -1,
      "name": "Rock_Sandstone"
    },
    {
      "x": -14,
      "y": 1,
      "z": -1,
      "name": "Rock_Sandstone"
    },
    {
      "x": -14,
      "y": 2,
      "z": -1,
      "name": "Soil_Dirt_Dry"
    },
    {
      "x": -14,
      "y": 3,
      "z": -1,
      "name": "Soil_Dirt_Dry"
    },
    {
      "x": -14,
      "y": 4,
      "z": -1,
      "name": "Soil_Dirt_Dry"
    },
    {
      "x": -14,
      "y": 5,
      "z": -1,
      "name": "Soil_Dirt_Dry"
    },
    {
      "x": -14,
      "y": 0,
      "z": 0,
      "name": "Rock_Sandstone"
    },
    {
      "x": -14,
      "y": 1,
      "z": 0,
      "name": "Rock_Sandstone"
    },
    {
      "x": -14,
      "y": 2,
      "z": 0,
      "name": "Soil_Dirt_Dry"
    },
    {
      "x": -14,
      "y": 3,
      "z": 0,
      "name": "Soil_Dirt_Dry"
    },
    {
      "x": -14,
      "y": 4,
      "z": 0,
      "name": "Soil_Dirt_Dry"
    },
    {
      "x": -14,
      "y": 5,
      "z": 0,
      "name": "Soil_Dirt_Dry"
    },
    {
      "x": -14,
      "y": 0,
      "z": 1,
      "name": "Rock_Sandstone"
    },
    {
      "x": -14,
      "y": 1,
      "z": 1,
      "name": "Rock_Sandstone"
    },
    {
      "x": -14,
      "y": 2,
      "z": 1,
      "name": "Soil_Dirt_Dry"
    },
    {
      "x": -14,
      "y": 3,
      "z": 1,
      "name": "Soil_Dirt_Dry"
    },
    {
      "x": -14,
      "y": 4,
      "z": 1,
      "name": "Soil_Dirt_Dry"
    },
    {
      "x": -14,
      "y": 5,
      "z": 1,
      "name": "Soil_Dirt_Dry"
    },
    {
      "x": -14,
      "y": 1,
      "z": 2,
      "name": "Rock_Sandstone"
    },
    {
      "x": -14,
      "y": 2,
      "z": 2,
      "name": "Soil_Dirt_Dry"
    },
    {
      "x": -14,
      "y": 3,
      "z": 2,
      "name": "Soil_Dirt_Dry"
    },
    {
      "x": -14,
      "y": 4,
      "z": 2,
      "name": "Soil_Gravel_Sand"
    },
    {
      "x": -14,
      "y": 5,
      "z": 2,
      "name": "Soil_Dirt_Dry"
    },
    {
      "x": -14,
      "y": 1,
      "z": 3,
      "name": "Rock_Sandstone"
    },
    {
      "x": -14,
      "y": 2,
      "z": 3,
      "name": "Soil_Dirt_Dry"
    },
    {
      "x": -14,
      "y": 3,
      "z": 3,
      "name": "Soil_Dirt_Dry"
    },
    {
      "x": -14,
      "y": 4,
      "z": 3,
      "name": "Soil_Dirt_Dry"
    },
    {
      "x": -14,
      "y": 5,
      "z": 3,
      "name": "Soil_Dirt_Dry"
    },
    {
      "x": -14,
      "y": 6,
      "z": 3,
      "name": "Rubble_Sandstone"
    },
    {
      "x": -14,
      "y": 1,
      "z": 4,
      "name": "Rock_Sandstone"
    },
    {
      "x": -14,
      "y": 2,
      "z": 4,
      "name": "Soil_Dirt_Dry"
    },
    {
      "x": -14,
      "y": 3,
      "z": 4,
      "name": "Soil_Dirt_Dry"
    },
    {
      "x": -14,
      "y": 4,
      "z": 4,
      "name": "Soil_Dirt_Dry"
    },
    {
      "x": -14,
      "y": 5,
      "z": 4,
      "name": "Soil_Dirt_Dry"
    },
    {
      "x": -14,
      "y": 1,
      "z": 5,
      "name": "Rock_Sandstone"
    },
    {
      "x": -14,
      "y": 2,
      "z": 5,
      "name": "Soil_Dirt_Dry"
    },
    {
      "x": -14,
      "y": 3,
      "z": 5,
      "name": "Soil_Dirt_Dry"
    },
    {
      "x": -14,
      "y": 4,
      "z": 5,
      "name": "Soil_Dirt_Dry"
    },
    {
      "x": -14,
      "y": 5,
      "z": 5,
      "name": "Soil_Dirt_Dry"
    },
    {
      "x": -14,
      "y": 1,
      "z": 6,
      "name": "Rock_Sandstone"
    },
    {
      "x": -14,
      "y": 2,
      "z": 6,
      "name": "Soil_Dirt_Dry"
    },
    {
      "x": -14,
      "y": 3,
      "z": 6,
      "name": "Soil_Dirt_Dry"
    },
    {
      "x": -14,
      "y": 4,
      "z": 6,
      "name": "Soil_Dirt_Dry"
    },
    {
      "x": -14,
      "y": 5,
      "z": 6,
      "name": "Soil_Dirt_Dry"
    },
    {
      "x": -14,
      "y": 1,
      "z": 7,
      "name": "Rock_Sandstone"
    },
    {
      "x": -14,
      "y": 2,
      "z": 7,
      "name": "Soil_Dirt_Dry"
    },
    {
      "x": -14,
      "y": 3,
      "z": 7,
      "name": "Soil_Dirt_Dry"
    },
    {
      "x": -14,
      "y": 4,
      "z": 7,
      "name": "Soil_Dirt_Dry"
    },
    {
      "x": -14,
      "y": 5,
      "z": 7,
      "name": "Soil_Dirt_Dry"
    },
    {
      "x": -14,
      "y": 1,
      "z": 8,
      "name": "Rock_Sandstone"
    },
    {
      "x": -14,
      "y": 2,
      "z": 8,
      "name": "Soil_Dirt_Dry"
    },
    {
      "x": -14,
      "y": 3,
      "z": 8,
      "name": "Soil_Dirt_Dry"
    },
    {
      "x": -14,
      "y": 4,
      "z": 8,
      "name": "Soil_Dirt_Dry"
    },
    {
      "x": -14,
      "y": 1,
      "z": 9,
      "name": "Rock_Sandstone"
    },
    {
      "x": -14,
      "y": 2,
      "z": 9,
      "name": "Soil_Dirt_Dry"
    },
    {
      "x": -14,
      "y": 3,
      "z": 9,
      "name": "Soil_Dirt_Dry"
    },
    {
      "x": -14,
      "y": 4,
      "z": 9,
      "name": "Soil_Dirt_Dry"
    },
    {
      "x": -14,
      "y": 0,
      "z": 10,
      "name": "Rock_Sandstone"
    },
    {
      "x": -14,
      "y": 1,
      "z": 10,
      "name": "Rock_Sandstone"
    },
    {
      "x": -14,
      "y": 2,
      "z": 10,
      "name": "Soil_Dirt_Dry"
    },
    {
      "x": -14,
      "y": 3,
      "z": 10,
      "name": "Soil_Dirt_Dry"
    },
    {
      "x": -14,
      "y": 4,
      "z": 10,
      "name": "Soil_Dirt_Dry"
    },
    {
      "x": -14,
      "y": 0,
      "z": 11,
      "name": "Rock_Sandstone"
    },
    {
      "x": -14,
      "y": 1,
      "z": 11,
      "name": "Rock_Sandstone"
    },
    {
      "x": -14,
      "y": 2,
      "z": 11,
      "name": "Soil_Dirt_Dry"
    },
    {
      "x": -14,
      "y": 3,
      "z": 11,
      "name": "Soil_Dirt_Dry"
    },
    {
      "x": -14,
      "y": 4,
      "z": 11,
      "name": "Soil_Dirt_Dry"
    },
    {
      "x": -13,
      "y": 0,
      "z": -22,
      "name": "Rock_Sandstone"
    },
    {
      "x": -13,
      "y": 1,
      "z": -22,
      "name": "Rock_Sandstone"
    },
    {
      "x": -13,
      "y": 2,
      "z": -22,
      "name": "Rock_Sandstone"
    },
    {
      "x": -13,
      "y": 0,
      "z": -21,
      "name": "Rock_Sandstone"
    },
    {
      "x": -13,
      "y": 1,
      "z": -21,
      "name": "Rock_Sandstone"
    },
    {
      "x": -13,
      "y": 2,
      "z": -21,
      "name": "Rock_Sandstone"
    },
    {
      "x": -13,
      "y": 3,
      "z": -21,
      "name": "Soil_Dirt_Dry"
    },
    {
      "x": -13,
      "y": 1,
      "z": -20,
      "name": "Rock_Sandstone"
    },
    {
      "x": -13,
      "y": 2,
      "z": -20,
      "name": "Soil_Dirt_Dry"
    },
    {
      "x": -13,
      "y": 3,
      "z": -20,
      "name": "Soil_Dirt_Dry"
    },
    {
      "x": -13,
      "y": 4,
      "z": -20,
      "name": "Soil_Dirt_Dry"
    },
    {
      "x": -13,
      "y": 1,
      "z": -19,
      "name": "Rock_Sandstone"
    },
    {
      "x": -13,
      "y": 2,
      "z": -19,
      "name": "Soil_Dirt_Dry"
    },
    {
      "x": -13,
      "y": 3,
      "z": -19,
      "name": "Soil_Dirt_Dry"
    },
    {
      "x": -13,
      "y": 4,
      "z": -19,
      "name": "Soil_Dirt_Dry"
    },
    {
      "x": -13,
      "y": 1,
      "z": -18,
      "name": "Rock_Sandstone"
    },
    {
      "x": -13,
      "y": 2,
      "z": -18,
      "name": "Soil_Dirt_Dry"
    },
    {
      "x": -13,
      "y": 3,
      "z": -18,
      "name": "Soil_Dirt_Dry"
    },
    {
      "x": -13,
      "y": 4,
      "z": -18,
      "name": "Soil_Dirt_Dry"
    },
    {
      "x": -13,
      "y": 1,
      "z": -17,
      "name": "Rock_Sandstone"
    },
    {
      "x": -13,
      "y": 2,
      "z": -17,
      "name": "Soil_Dirt_Dry"
    },
    {
      "x": -13,
      "y": 3,
      "z": -17,
      "name": "Soil_Dirt_Dry"
    },
    {
      "x": -13,
      "y": 4,
      "z": -17,
      "name": "Soil_Dirt_Dry"
    },
    {
      "x": -13,
      "y": 5,
      "z": -17,
      "name": "Soil_Dirt_Dry"
    },
    {
      "x": -13,
      "y": 1,
      "z": -16,
      "name": "Rock_Sandstone"
    },
    {
      "x": -13,
      "y": 2,
      "z": -16,
      "name": "Soil_Dirt_Dry"
    },
    {
      "x": -13,
      "y": 3,
      "z": -16,
      "name": "Soil_Dirt_Dry"
    },
    {
      "x": -13,
      "y": 4,
      "z": -16,
      "name": "Soil_Dirt_Dry"
    },
    {
      "x": -13,
      "y": 5,
      "z": -16,
      "name": "Soil_Dirt_Dry"
    },
    {
      "x": -13,
      "y": 1,
      "z": -15,
      "name": "Rock_Sandstone"
    },
    {
      "x": -13,
      "y": 2,
      "z": -15,
      "name": "Soil_Dirt_Dry"
    },
    {
      "x": -13,
      "y": 3,
      "z": -15,
      "name": "Soil_Dirt_Dry"
    },
    {
      "x": -13,
      "y": 4,
      "z": -15,
      "name": "Soil_Dirt_Dry"
    },
    {
      "x": -13,
      "y": 5,
      "z": -15,
      "name": "Soil_Dirt_Dry"
    },
    {
      "x": -13,
      "y": 1,
      "z": -14,
      "name": "Rock_Sandstone"
    },
    {
      "x": -13,
      "y": 2,
      "z": -14,
      "name": "Soil_Dirt_Dry"
    },
    {
      "x": -13,
      "y": 3,
      "z": -14,
      "name": "Soil_Dirt_Dry"
    },
    {
      "x": -13,
      "y": 4,
      "z": -14,
      "name": "Soil_Dirt_Dry"
    },
    {
      "x": -13,
      "y": 5,
      "z": -14,
      "name": "Soil_Dirt_Dry"
    },
    {
      "x": -13,
      "y": 1,
      "z": -13,
      "name": "Rock_Sandstone"
    },
    {
      "x": -13,
      "y": 2,
      "z": -13,
      "name": "Soil_Dirt_Dry"
    },
    {
      "x": -13,
      "y": 3,
      "z": -13,
      "name": "Soil_Dirt_Dry"
    },
    {
      "x": -13,
      "y": 4,
      "z": -13,
      "name": "Soil_Dirt_Dry"
    },
    {
      "x": -13,
      "y": 5,
      "z": -13,
      "name": "Soil_Dirt_Dry"
    },
    {
      "x": -13,
      "y": 6,
      "z": -13,
      "name": "Deco_Bone_Skulls_Feran"
    },
    {
      "x": -13,
      "y": 0,
      "z": -12,
      "name": "Rock_Sandstone"
    },
    {
      "x": -13,
      "y": 1,
      "z": -12,
      "name": "Rock_Sandstone"
    },
    {
      "x": -13,
      "y": 2,
      "z": -12,
      "name": "Soil_Dirt_Dry"
    },
    {
      "x": -13,
      "y": 3,
      "z": -12,
      "name": "Soil_Dirt_Dry"
    },
    {
      "x": -13,
      "y": 4,
      "z": -12,
      "name": "Soil_Gravel_Sand"
    },
    {
      "x": -13,
      "y": 5,
      "z": -12,
      "name": "Soil_Dirt_Dry"
    },
    {
      "x": -13,
      "y": 6,
      "z": -12,
      "name": "Soil_Dirt_Dry"
    },
    {
      "x": -13,
      "y": 0,
      "z": -11,
      "name": "Rock_Sandstone"
    },
    {
      "x": -13,
      "y": 1,
      "z": -11,
      "name": "Rock_Sandstone"
    },
    {
      "x": -13,
      "y": 2,
      "z": -11,
      "name": "Soil_Dirt_Dry"
    },
    {
      "x": -13,
      "y": 3,
      "z": -11,
      "name": "Soil_Dirt_Dry"
    },
    {
      "x": -13,
      "y": 4,
      "z": -11,
      "name": "Soil_Dirt_Dry"
    },
    {
      "x": -13,
      "y": 5,
      "z": -11,
      "name": "Soil_Dirt_Dry"
    },
    {
      "x": -13,
      "y": 6,
      "z": -11,
      "name": "Soil_Dirt_Dry"
    },
    {
      "x": -13,
      "y": 1,
      "z": -10,
      "name": "Rock_Sandstone"
    },
    {
      "x": -13,
      "y": 2,
      "z": -10,
      "name": "Soil_Dirt_Dry"
    },
    {
      "x": -13,
      "y": 3,
      "z": -10,
      "name": "Soil_Dirt_Dry"
    },
    {
      "x": -13,
      "y": 4,
      "z": -10,
      "name": "Soil_Dirt_Dry"
    },
    {
      "x": -13,
      "y": 5,
      "z": -10,
      "name": "Soil_Dirt_Dry"
    },
    {
      "x": -13,
      "y": 6,
      "z": -10,
      "name": "Soil_Dirt_Dry"
    },
    {
      "x": -13,
      "y": 0,
      "z": -9,
      "name": "Rock_Sandstone"
    },
    {
      "x": -13,
      "y": 1,
      "z": -9,
      "name": "Rock_Sandstone"
    },
    {
      "x": -13,
      "y": 2,
      "z": -9,
      "name": "Soil_Dirt_Dry"
    },
    {
      "x": -13,
      "y": 3,
      "z": -9,
      "name": "Soil_Dirt_Dry"
    },
    {
      "x": -13,
      "y": 4,
      "z": -9,
      "name": "Soil_Dirt_Dry"
    },
    {
      "x": -13,
      "y": 5,
      "z": -9,
      "name": "Soil_Dirt_Dry"
    },
    {
      "x": -13,
      "y": 0,
      "z": -8,
      "name": "Rock_Sandstone"
    },
    {
      "x": -13,
      "y": 1,
      "z": -8,
      "name": "Rock_Sandstone"
    },
    {
      "x": -13,
      "y": 2,
      "z": -8,
      "name": "Soil_Dirt_Dry"
    },
    {
      "x": -13,
      "y": 3,
      "z": -8,
      "name": "Soil_Dirt_Dry"
    },
    {
      "x": -13,
      "y": 4,
      "z": -8,
      "name": "Soil_Dirt_Dry"
    },
    {
      "x": -13,
      "y": 5,
      "z": -8,
      "name": "Soil_Dirt_Dry"
    },
    {
      "x": -13,
      "y": 1,
      "z": -7,
      "name": "Rock_Sandstone"
    },
    {
      "x": -13,
      "y": 2,
      "z": -7,
      "name": "Soil_Dirt_Dry"
    },
    {
      "x": -13,
      "y": 3,
      "z": -7,
      "name": "Soil_Dirt_Dry"
    },
    {
      "x": -13,
      "y": 4,
      "z": -7,
      "name": "Soil_Dirt_Dry"
    },
    {
      "x": -13,
      "y": 5,
      "z": -7,
      "name": "Soil_Gravel_Sand"
    },
    {
      "x": -13,
      "y": 1,
      "z": -6,
      "name": "Rock_Sandstone"
    },
    {
      "x": -13,
      "y": 2,
      "z": -6,
      "name": "Soil_Dirt_Dry"
    },
    {
      "x": -13,
      "y": 3,
      "z": -6,
      "name": "Soil_Dirt_Dry"
    },
    {
      "x": -13,
      "y": 4,
      "z": -6,
      "name": "Soil_Dirt_Dry"
    },
    {
      "x": -13,
      "y": 5,
      "z": -6,
      "name": "Soil_Dirt_Dry"
    },
    {
      "x": -13,
      "y": 1,
      "z": -5,
      "name": "Rock_Sandstone"
    },
    {
      "x": -13,
      "y": 2,
      "z": -5,
      "name": "Soil_Dirt_Dry"
    },
    {
      "x": -13,
      "y": 3,
      "z": -5,
      "name": "Soil_Dirt_Dry"
    },
    {
      "x": -13,
      "y": 4,
      "z": -5,
      "name": "Soil_Dirt_Dry"
    },
    {
      "x": -13,
      "y": 5,
      "z": -5,
      "name": "Soil_Dirt_Dry"
    },
    {
      "x": -13,
      "y": 1,
      "z": -4,
      "name": "Rock_Sandstone"
    },
    {
      "x": -13,
      "y": 2,
      "z": -4,
      "name": "Soil_Dirt_Dry"
    },
    {
      "x": -13,
      "y": 3,
      "z": -4,
      "name": "Soil_Dirt_Dry"
    },
    {
      "x": -13,
      "y": 4,
      "z": -4,
      "name": "Soil_Dirt_Dry"
    },
    {
      "x": -13,
      "y": 5,
      "z": -4,
      "name": "Soil_Dirt_Dry"
    },
    {
      "x": -13,
      "y": 1,
      "z": -3,
      "name": "Rock_Sandstone"
    },
    {
      "x": -13,
      "y": 2,
      "z": -3,
      "name": "Soil_Dirt_Dry"
    },
    {
      "x": -13,
      "y": 3,
      "z": -3,
      "name": "Soil_Dirt_Dry"
    },
    {
      "x": -13,
      "y": 4,
      "z": -3,
      "name": "Soil_Dirt_Dry"
    },
    {
      "x": -13,
      "y": 5,
      "z": -3,
      "name": "Soil_Dirt_Dry"
    },
    {
      "x": -13,
      "y": 6,
      "z": -3,
      "name": "Soil_Dirt_Dry"
    },
    {
      "x": -13,
      "y": 0,
      "z": -2,
      "name": "Rock_Sandstone"
    },
    {
      "x": -13,
      "y": 1,
      "z": -2,
      "name": "Rock_Sandstone"
    },
    {
      "x": -13,
      "y": 2,
      "z": -2,
      "name": "Soil_Dirt_Dry"
    },
    {
      "x": -13,
      "y": 3,
      "z": -2,
      "name": "Soil_Dirt_Dry"
    },
    {
      "x": -13,
      "y": 4,
      "z": -2,
      "name": "Soil_Dirt_Dry"
    },
    {
      "x": -13,
      "y": 5,
      "z": -2,
      "name": "Soil_Dirt_Dry"
    },
    {
      "x": -13,
      "y": 6,
      "z": -2,
      "name": "Soil_Dirt_Dry"
    },
    {
      "x": -13,
      "y": 7,
      "z": -2,
      "name": "Rubble_Sandstone"
    },
    {
      "x": -13,
      "y": 0,
      "z": -1,
      "name": "Rock_Sandstone"
    },
    {
      "x": -13,
      "y": 1,
      "z": -1,
      "name": "Rock_Sandstone"
    },
    {
      "x": -13,
      "y": 2,
      "z": -1,
      "name": "Soil_Dirt_Dry"
    },
    {
      "x": -13,
      "y": 3,
      "z": -1,
      "name": "Soil_Dirt_Dry"
    },
    {
      "x": -13,
      "y": 4,
      "z": -1,
      "name": "Soil_Dirt_Dry"
    },
    {
      "x": -13,
      "y": 5,
      "z": -1,
      "name": "Soil_Dirt_Dry"
    },
    {
      "x": -13,
      "y": 6,
      "z": -1,
      "name": "Soil_Dirt_Dry"
    },
    {
      "x": -13,
      "y": 0,
      "z": 0,
      "name": "Rock_Sandstone"
    },
    {
      "x": -13,
      "y": 1,
      "z": 0,
      "name": "Rock_Sandstone"
    },
    {
      "x": -13,
      "y": 2,
      "z": 0,
      "name": "Soil_Dirt_Dry"
    },
    {
      "x": -13,
      "y": 3,
      "z": 0,
      "name": "Soil_Dirt_Dry"
    },
    {
      "x": -13,
      "y": 4,
      "z": 0,
      "name": "Soil_Dirt_Dry"
    },
    {
      "x": -13,
      "y": 5,
      "z": 0,
      "name": "Soil_Dirt_Dry"
    },
    {
      "x": -13,
      "y": 6,
      "z": 0,
      "name": "Wood_Dry_Trunk"
    },
    {
      "x": -13,
      "y": 7,
      "z": 0,
      "name": "Wood_Dry_Trunk"
    },
    {
      "x": -13,
      "y": 8,
      "z": 0,
      "name": "Wood_Dry_Trunk"
    },
    {
      "x": -13,
      "y": 9,
      "z": 0,
      "name": "Wood_Dry_Trunk"
    },
    {
      "x": -13,
      "y": 10,
      "z": 0,
      "name": "Survival_Trap_Spike_Wood"
    },
    {
      "x": -13,
      "y": 1,
      "z": 1,
      "name": "Rock_Sandstone"
    },
    {
      "x": -13,
      "y": 2,
      "z": 1,
      "name": "Soil_Dirt_Dry"
    },
    {
      "x": -13,
      "y": 3,
      "z": 1,
      "name": "Soil_Dirt_Dry"
    },
    {
      "x": -13,
      "y": 4,
      "z": 1,
      "name": "Soil_Dirt_Dry"
    },
    {
      "x": -13,
      "y": 5,
      "z": 1,
      "name": "Soil_Dirt_Dry"
    },
    {
      "x": -13,
      "y": 6,
      "z": 1,
      "name": "Soil_Dirt_Dry"
    },
    {
      "x": -13,
      "y": 8,
      "z": 1,
      "name": "Wood_Dry_Branch_Long",
      "rotation": 4
    },
    {
      "x": -13,
      "y": 1,
      "z": 2,
      "name": "Rock_Sandstone"
    },
    {
      "x": -13,
      "y": 2,
      "z": 2,
      "name": "Soil_Dirt_Dry"
    },
    {
      "x": -13,
      "y": 3,
      "z": 2,
      "name": "Soil_Dirt_Dry"
    },
    {
      "x": -13,
      "y": 4,
      "z": 2,
      "name": "Soil_Dirt_Dry"
    },
    {
      "x": -13,
      "y": 5,
      "z": 2,
      "name": "Soil_Dirt_Dry"
    },
    {
      "x": -13,
      "y": 6,
      "z": 2,
      "name": "Wood_Dry_Trunk"
    },
    {
      "x": -13,
      "y": 7,
      "z": 2,
      "name": "Wood_Dry_Trunk"
    },
    {
      "x": -13,
      "y": 8,
      "z": 2,
      "name": "Wood_Dry_Trunk"
    },
    {
      "x": -13,
      "y": 9,
      "z": 2,
      "name": "Wood_Dry_Trunk"
    },
    {
      "x": -13,
      "y": 10,
      "z": 2,
      "name": "Survival_Trap_Spike_Wood"
    },
    {
      "x": -13,
      "y": 1,
      "z": 3,
      "name": "Rock_Sandstone"
    },
    {
      "x": -13,
      "y": 2,
      "z": 3,
      "name": "Soil_Dirt_Dry"
    },
    {
      "x": -13,
      "y": 3,
      "z": 3,
      "name": "Soil_Dirt_Dry"
    },
    {
      "x": -13,
      "y": 4,
      "z": 3,
      "name": "Soil_Dirt_Dry"
    },
    {
      "x": -13,
      "y": 5,
      "z": 3,
      "name": "Soil_Dirt_Dry"
    },
    {
      "x": -13,
      "y": 6,
      "z": 3,
      "name": "Soil_Dirt_Dry"
    },
    {
      "x": -13,
      "y": 8,
      "z": 3,
      "name": "Wood_Dry_Branch_Long",
      "rotation": 4
    },
    {
      "x": -13,
      "y": 1,
      "z": 4,
      "name": "Rock_Sandstone"
    },
    {
      "x": -13,
      "y": 2,
      "z": 4,
      "name": "Soil_Dirt_Dry"
    },
    {
      "x": -13,
      "y": 3,
      "z": 4,
      "name": "Soil_Dirt_Dry"
    },
    {
      "x": -13,
      "y": 4,
      "z": 4,
      "name": "Soil_Dirt_Dry"
    },
    {
      "x": -13,
      "y": 5,
      "z": 4,
      "name": "Soil_Dirt_Dry"
    },
    {
      "x": -13,
      "y": 1,
      "z": 5,
      "name": "Rock_Sandstone"
    },
    {
      "x": -13,
      "y": 2,
      "z": 5,
      "name": "Soil_Dirt_Dry"
    },
    {
      "x": -13,
      "y": 3,
      "z": 5,
      "name": "Soil_Dirt_Dry"
    },
    {
      "x": -13,
      "y": 4,
      "z": 5,
      "name": "Soil_Dirt_Dry"
    },
    {
      "x": -13,
      "y": 5,
      "z": 5,
      "name": "Soil_Dirt_Dry"
    },
    {
      "x": -13,
      "y": 1,
      "z": 6,
      "name": "Rock_Sandstone"
    },
    {
      "x": -13,
      "y": 2,
      "z": 6,
      "name": "Soil_Dirt_Dry"
    },
    {
      "x": -13,
      "y": 3,
      "z": 6,
      "name": "Soil_Dirt_Dry"
    },
    {
      "x": -13,
      "y": 4,
      "z": 6,
      "name": "Soil_Dirt_Dry"
    },
    {
      "x": -13,
      "y": 5,
      "z": 6,
      "name": "Soil_Dirt_Dry"
    },
    {
      "x": -13,
      "y": 1,
      "z": 7,
      "name": "Rock_Sandstone"
    },
    {
      "x": -13,
      "y": 2,
      "z": 7,
      "name": "Soil_Dirt_Dry"
    },
    {
      "x": -13,
      "y": 3,
      "z": 7,
      "name": "Soil_Dirt_Dry"
    },
    {
      "x": -13,
      "y": 4,
      "z": 7,
      "name": "Soil_Dirt_Dry"
    },
    {
      "x": -13,
      "y": 5,
      "z": 7,
      "name": "Soil_Dirt_Dry"
    },
    {
      "x": -13,
      "y": 1,
      "z": 8,
      "name": "Rock_Sandstone"
    },
    {
      "x": -13,
      "y": 2,
      "z": 8,
      "name": "Soil_Dirt_Dry"
    },
    {
      "x": -13,
      "y": 3,
      "z": 8,
      "name": "Soil_Dirt_Dry"
    },
    {
      "x": -13,
      "y": 4,
      "z": 8,
      "name": "Soil_Dirt_Dry"
    },
    {
      "x": -13,
      "y": 5,
      "z": 8,
      "name": "Soil_Dirt_Dry"
    },
    {
      "x": -13,
      "y": 1,
      "z": 9,
      "name": "Rock_Sandstone"
    },
    {
      "x": -13,
      "y": 2,
      "z": 9,
      "name": "Soil_Dirt_Dry"
    },
    {
      "x": -13,
      "y": 3,
      "z": 9,
      "name": "Soil_Dirt_Dry"
    },
    {
      "x": -13,
      "y": 4,
      "z": 9,
      "name": "Soil_Dirt_Dry"
    },
    {
      "x": -13,
      "y": 1,
      "z": 10,
      "name": "Rock_Sandstone"
    },
    {
      "x": -13,
      "y": 2,
      "z": 10,
      "name": "Soil_Dirt_Dry"
    },
    {
      "x": -13,
      "y": 3,
      "z": 10,
      "name": "Soil_Dirt_Dry"
    },
    {
      "x": -13,
      "y": 4,
      "z": 10,
      "name": "Soil_Dirt_Dry"
    },
    {
      "x": -13,
      "y": 0,
      "z": 11,
      "name": "Rock_Sandstone"
    },
    {
      "x": -13,
      "y": 1,
      "z": 11,
      "name": "Rock_Sandstone"
    },
    {
      "x": -13,
      "y": 2,
      "z": 11,
      "name": "Soil_Dirt_Dry"
    },
    {
      "x": -13,
      "y": 3,
      "z": 11,
      "name": "Soil_Dirt_Dry"
    },
    {
      "x": -13,
      "y": 4,
      "z": 11,
      "name": "Soil_Dirt_Dry"
    },
    {
      "x": -13,
      "y": 0,
      "z": 12,
      "name": "Rock_Sandstone"
    },
    {
      "x": -13,
      "y": 1,
      "z": 12,
      "name": "Rock_Sandstone"
    },
    {
      "x": -13,
      "y": 2,
      "z": 12,
      "name": "Soil_Dirt_Dry"
    },
    {
      "x": -13,
      "y": 3,
      "z": 12,
      "name": "Soil_Dirt_Dry"
    },
    {
      "x": -13,
      "y": 4,
      "z": 12,
      "name": "Soil_Dirt_Dry"
    },
    {
      "x": -13,
      "y": 0,
      "z": 13,
      "name": "Rock_Sandstone"
    },
    {
      "x": -13,
      "y": 1,
      "z": 13,
      "name": "Rock_Sandstone"
    },
    {
      "x": -13,
      "y": 2,
      "z": 13,
      "name": "Rock_Sandstone"
    },
    {
      "x": -13,
      "y": 3,
      "z": 13,
      "name": "Soil_Dirt_Dry"
    },
    {
      "x": -13,
      "y": 0,
      "z": 14,
      "name": "Rock_Sandstone"
    },
    {
      "x": -13,
      "y": 1,
      "z": 14,
      "name": "Rock_Sandstone"
    },
    {
      "x": -13,
      "y": 2,
      "z": 14,
      "name": "Rock_Sandstone"
    },
    {
      "x": -13,
      "y": 3,
      "z": 14,
      "name": "Soil_Dirt_Dry"
    },
    {
      "x": -13,
      "y": 0,
      "z": 15,
      "name": "Rock_Sandstone"
    },
    {
      "x": -13,
      "y": 1,
      "z": 15,
      "name": "Rock_Sandstone"
    },
    {
      "x": -13,
      "y": 2,
      "z": 15,
      "name": "Rock_Sandstone"
    },
    {
      "x": -13,
      "y": 3,
      "z": 15,
      "name": "Soil_Dirt_Dry"
    },
    {
      "x": -13,
      "y": 0,
      "z": 16,
      "name": "Rock_Sandstone"
    },
    {
      "x": -13,
      "y": 1,
      "z": 16,
      "name": "Rock_Sandstone"
    },
    {
      "x": -13,
      "y": 2,
      "z": 16,
      "name": "Rock_Sandstone"
    },
    {
      "x": -13,
      "y": 3,
      "z": 16,
      "name": "Soil_Dirt_Dry"
    },
    {
      "x": -13,
      "y": 0,
      "z": 17,
      "name": "Rock_Sandstone"
    },
    {
      "x": -13,
      "y": 1,
      "z": 17,
      "name": "Rock_Sandstone"
    },
    {
      "x": -13,
      "y": 2,
      "z": 17,
      "name": "Rock_Sandstone"
    },
    {
      "x": -12,
      "y": 0,
      "z": -22,
      "name": "Rock_Sandstone"
    },
    {
      "x": -12,
      "y": 1,
      "z": -22,
      "name": "Rock_Sandstone"
    },
    {
      "x": -12,
      "y": 2,
      "z": -22,
      "name": "Rock_Sandstone"
    },
    {
      "x": -12,
      "y": 3,
      "z": -22,
      "name": "Soil_Dirt_Dry"
    },
    {
      "x": -12,
      "y": 0,
      "z": -21,
      "name": "Rock_Sandstone"
    },
    {
      "x": -12,
      "y": 1,
      "z": -21,
      "name": "Rock_Sandstone"
    },
    {
      "x": -12,
      "y": 2,
      "z": -21,
      "name": "Rock_Sandstone"
    },
    {
      "x": -12,
      "y": 3,
      "z": -21,
      "name": "Soil_Dirt_Dry"
    },
    {
      "x": -12,
      "y": 1,
      "z": -20,
      "name": "Rock_Sandstone"
    },
    {
      "x": -12,
      "y": 2,
      "z": -20,
      "name": "Soil_Dirt_Dry"
    },
    {
      "x": -12,
      "y": 3,
      "z": -20,
      "name": "Soil_Dirt_Dry"
    },
    {
      "x": -12,
      "y": 4,
      "z": -20,
      "name": "Soil_Dirt_Dry"
    },
    {
      "x": -12,
      "y": 1,
      "z": -19,
      "name": "Rock_Sandstone"
    },
    {
      "x": -12,
      "y": 2,
      "z": -19,
      "name": "Soil_Dirt_Dry"
    },
    {
