{
  "version": 8,
  "blockIdVersion": 11,
  "anchorX": 2,
  "anchorY": 6,
  "anchorZ": 3,
  "blocks": [
    {
      "x": -17,
      "y": 1,
      "z": -19,
      "name": "Soil_Dirt_Dry"
    },
    {
      "x": -17,
      "y": 1,
      "z": -18,
      "name": "Soil_Dirt_Dry"
    },
    {
      "x": -17,
      "y": 2,
      "z": -18,
      "name": "Soil_Dirt_Dry"
    },
    {
      "x": -17,
      "y": 1,
      "z": -17,
      "name": "Soil_Dirt_Dry"
    },
    {
      "x": -17,
      "y": 2,
      "z": -17,
      "name": "Soil_Dirt_Dry"
    },
    {
      "x": -17,
      "y": 3,
      "z": -17,
      "name": "Soil_Dirt_Dry"
    },
    {
      "x": -17,
      "y": 2,
      "z": -16,
      "name": "Soil_Dirt_Dry"
    },
    {
      "x": -17,
      "y": 3,
      "z": -16,
      "name": "Soil_Dirt_Dry"
    },
    {
      "x": -17,
      "y": 2,
      "z": -15,
      "name": "Soil_Dirt_Dry"
    },
    {
      "x": -17,
      "y": 3,
      "z": -15,
      "name": "Soil_Dirt_Dry"
    },
    {
      "x": -17,
      "y": 2,
      "z": -14,
      "name": "Soil_Dirt_Dry"
    },
    {
      "x": -17,
      "y": 3,
      "z": -14,
      "name": "Soil_Dirt_Dry"
    },
    {
      "x": -17,
      "y": 2,
      "z": -13,
      "name": "Soil_Dirt_Dry"
    },
    {
      "x": -17,
      "y": 3,
      "z": -13,
      "name": "Soil_Dirt_Dry"
    },
    {
      "x": -17,
      "y": 2,
      "z": -12,
      "name": "Soil_Dirt_Dry"
    },
    {
      "x": -17,
      "y": 3,
      "z": -12,
      "name": "Soil_Dirt_Dry"
    },
    {
      "x": -17,
      "y": 2,
      "z": -11,
      "name": "Soil_Dirt_Dry"
    },
    {
      "x": -17,
      "y": 3,
      "z": -11,
      "name": "Soil_Dirt_Dry"
    },
    {
      "x": -17,
      "y": 2,
      "z": -10,
      "name": "Soil_Dirt_Dry"
    },
    {
      "x": -17,
      "y": 3,
      "z": -10,
      "name": "Soil_Dirt_Dry"
    },
    {
      "x": -17,
      "y": 1,
      "z": -9,
      "name": "Soil_Dirt_Dry"
    },
    {
      "x": -17,
      "y": 2,
      "z": -9,
      "name": "Soil_Dirt_Dry"
    },
    {
      "x": -17,
      "y": 3,
      "z": -9,
      "name": "Soil_Dirt_Dry"
    },
    {
      "x": -17,
      "y": 1,
      "z": -8,
      "name": "Soil_Dirt_Dry"
    },
    {
      "x": -17,
      "y": 2,
      "z": -8,
      "name": "Soil_Dirt_Dry"
    },
    {
      "x": -17,
      "y": 3,
      "z": -8,
      "name": "Soil_Dirt_Dry"
    },
    {
      "x": -17,
      "y": 1,
      "z": -7,
      "name": "Soil_Dirt_Dry"
    },
    {
      "x": -17,
      "y": 2,
      "z": -7,
      "name": "Soil_Dirt_Dry"
    },
    {
      "x": -17,
      "y": 3,
      "z": -7,
      "name": "Soil_Dirt_Dry"
    },
    {
      "x": -17,
      "y": 2,
      "z": -6,
      "name": "Soil_Dirt_Dry"
    },
    {
      "x": -17,
      "y": 3,
      "z": -6,
      "name": "Soil_Dirt_Dry"
    },
    {
      "x": -17,
      "y": 3,
      "z": -5,
      "name": "Soil_Dirt_Dry"
    },
    {
      "x": -17,
      "y": 4,
      "z": -5,
      "name": "Soil_Dirt_Dry"
    },
    {
      "x": -17,
      "y": 3,
      "z": -4,
      "name": "Soil_Dirt_Dry"
    },
    {
      "x": -17,
      "y": 4,
      "z": -4,
      "name": "Soil_Dirt_Dry"
    },
    {
      "x": -17,
      "y": 3,
      "z": -3,
      "name": "Soil_Dirt_Dry"
    },
    {
      "x": -17,
      "y": 4,
      "z": -3,
      "name": "Soil_Dirt_Dry"
    },
    {
      "x": -17,
      "y": 3,
      "z": -2,
      "name": "Soil_Dirt_Dry"
    },
    {
      "x": -17,
      "y": 4,
      "z": -2,
      "name": "Soil_Dirt_Dry"
    },
    {
      "x": -17,
      "y": 3,
      "z": -1,
      "name": "Soil_Dirt_Dry"
    },
    {
      "x": -17,
      "y": 4,
      "z": -1,
      "name": "Soil_Dirt_Dry"
    },
    {
      "x": -17,
      "y": 3,
      "z": 0,
      "name": "Soil_Dirt_Dry"
    },
    {
      "x": -17,
      "y": 4,
      "z": 0,
      "name": "Soil_Dirt_Dry"
    },
    {
      "x": -17,
      "y": 3,
      "z": 1,
      "name": "Soil_Dirt_Dry"
    },
    {
      "x": -17,
      "y": 4,
      "z": 1,
      "name": "Soil_Dirt_Dry"
    },
    {
      "x": -17,
      "y": 2,
      "z": 2,
      "name": "Soil_Dirt_Dry"
    },
    {
      "x": -17,
      "y": 3,
      "z": 2,
      "name": "Soil_Dirt_Dry"
    },
    {
      "x": -17,
      "y": 2,
      "z": 3,
      "name": "Soil_Dirt_Dry"
    },
    {
      "x": -17,
      "y": 3,
      "z": 3,
      "name": "Soil_Dirt_Dry"
    },
    {
      "x": -17,
      "y": 1,
      "z": 4,
      "name": "Soil_Dirt_Dry"
    },
    {
      "x": -17,
      "y": 2,
      "z": 4,
      "name": "Soil_Dirt_Dry"
    },
    {
      "x": -17,
      "y": 3,
      "z": 4,
      "name": "Soil_Dirt_Dry"
    },
    {
      "x": -17,
      "y": 1,
      "z": 5,
      "name": "Soil_Dirt_Dry"
    },
    {
      "x": -17,
      "y": 2,
      "z": 5,
      "name": "Soil_Dirt_Dry"
    },
    {
      "x": -17,
      "y": 3,
      "z": 5,
      "name": "Soil_Dirt_Dry"
    },
    {
      "x": -17,
      "y": 1,
      "z": 7,
      "name": "Soil_Dirt_Dry"
    },
    {
      "x": -17,
      "y": 1,
      "z": 8,
      "name": "Soil_Dirt_Dry"
    },
    {
      "x": -17,
      "y": 2,
      "z": 8,
      "name": "Soil_Dirt_Dry"
    },
    {
      "x": -17,
      "y": 1,
      "z": 9,
      "name": "Soil_Dirt_Dry"
    },
    {
      "x": -17,
      "y": 2,
      "z": 9,
      "name": "Soil_Dirt_Dry"
    },
    {
      "x": -17,
      "y": 1,
      "z": 10,
      "name": "Soil_Dirt_Dry"
    },
    {
      "x": -17,
      "y": 2,
      "z": 10,
      "name": "Soil_Dirt_Dry"
    },
    {
      "x": -17,
      "y": 1,
      "z": 11,
      "name": "Soil_Dirt_Dry"
    },
    {
      "x": -16,
      "y": 1,
      "z": -19,
      "name": "Soil_Dirt_Dry"
    },
    {
      "x": -16,
      "y": 2,
      "z": -19,
      "name": "Soil_Dirt_Dry"
    },
    {
      "x": -16,
      "y": 1,
      "z": -18,
      "name": "Soil_Dirt_Dry"
    },
    {
      "x": -16,
      "y": 2,
      "z": -18,
      "name": "Soil_Dirt_Dry"
    },
    {
      "x": -16,
      "y": 3,
      "z": -18,
      "name": "Soil_Dirt_Dry"
    },
    {
      "x": -16,
      "y": 2,
      "z": -17,
      "name": "Soil_Dirt_Dry"
    },
    {
      "x": -16,
      "y": 3,
      "z": -17,
      "name": "Soil_Dirt_Dry"
    },
    {
      "x": -16,
      "y": 2,
      "z": -16,
      "name": "Soil_Dirt_Dry"
    },
    {
      "x": -16,
      "y": 3,
      "z": -16,
      "name": "Soil_Dirt_Dry"
    },
    {
      "x": -16,
      "y": 3,
      "z": -15,
      "name": "Soil_Dirt_Dry"
    },
    {
      "x": -16,
      "y": 3,
      "z": -14,
      "name": "Soil_Dirt_Dry"
    },
    {
      "x": -16,
      "y": 4,
      "z": -14,
      "name": "Soil_Dirt_Dry"
    },
    {
      "x": -16,
      "y": 3,
      "z": -13,
      "name": "Soil_Dirt_Dry"
    },
    {
      "x": -16,
      "y": 4,
      "z": -13,
      "name": "Soil_Dirt_Dry"
    },
    {
      "x": -16,
      "y": 3,
      "z": -12,
      "name": "Soil_Dirt_Dry"
    },
    {
      "x": -16,
      "y": 4,
      "z": -12,
      "name": "Soil_Dirt_Dry"
    },
    {
      "x": -16,
      "y": 3,
      "z": -11,
      "name": "Soil_Dirt_Dry"
    },
    {
      "x": -16,
      "y": 4,
      "z": -11,
      "name": "Soil_Dirt_Dry"
    },
    {
      "x": -16,
      "y": 2,
      "z": -10,
      "name": "Soil_Dirt_Dry"
    },
    {
      "x": -16,
      "y": 3,
      "z": -10,
      "name": "Soil_Dirt_Dry"
    },
    {
      "x": -16,
      "y": 4,
      "z": -10,
      "name": "Soil_Dirt_Dry"
    },
    {
      "x": -16,
      "y": 1,
      "z": -9,
      "name": "Soil_Dirt_Dry"
    },
    {
      "x": -16,
      "y": 2,
      "z": -9,
      "name": "Soil_Dirt_Dry"
    },
    {
      "x": -16,
      "y": 3,
      "z": -9,
      "name": "Soil_Dirt_Dry"
    },
    {
      "x": -16,
      "y": 4,
      "z": -9,
      "name": "Soil_Dirt_Dry"
    },
    {
      "x": -16,
      "y": 1,
      "z": -8,
      "name": "Soil_Dirt_Dry"
    },
    {
      "x": -16,
      "y": 2,
      "z": -8,
      "name": "Soil_Dirt_Dry"
    },
    {
      "x": -16,
      "y": 3,
      "z": -8,
      "name": "Soil_Dirt_Dry"
    },
    {
      "x": -16,
      "y": 4,
      "z": -8,
      "name": "Soil_Dirt_Dry"
    },
    {
      "x": -16,
      "y": 1,
      "z": -7,
      "name": "Soil_Dirt_Dry"
    },
    {
      "x": -16,
      "y": 2,
      "z": -7,
      "name": "Soil_Dirt_Dry"
    },
    {
      "x": -16,
      "y": 3,
      "z": -7,
      "name": "Soil_Dirt_Dry"
    },
    {
      "x": -16,
      "y": 2,
      "z": -6,
      "name": "Soil_Dirt_Dry"
    },
    {
      "x": -16,
      "y": 3,
      "z": -6,
      "name": "Soil_Dirt_Dry"
    },
    {
      "x": -16,
      "y": 3,
      "z": -5,
      "name": "Soil_Dirt_Dry"
    },
    {
      "x": -16,
      "y": 4,
      "z": -5,
      "name": "Soil_Dirt_Dry"
    },
    {
      "x": -16,
      "y": 3,
      "z": -4,
      "name": "Soil_Dirt_Dry"
    },
    {
      "x": -16,
      "y": 4,
      "z": -4,
      "name": "Soil_Dirt_Dry"
    },
    {
      "x": -16,
      "y": 3,
      "z": -3,
      "name": "Soil_Dirt_Dry"
    },
    {
      "x": -16,
      "y": 4,
      "z": -3,
      "name": "Soil_Dirt_Dry"
    },
    {
      "x": -16,
      "y": 3,
      "z": -2,
      "name": "Soil_Dirt_Dry"
    },
    {
      "x": -16,
      "y": 4,
      "z": -2,
      "name": "Soil_Dirt_Dry"
    },
    {
      "x": -16,
      "y": 3,
      "z": -1,
      "name": "Soil_Dirt_Dry"
    },
    {
      "x": -16,
      "y": 4,
      "z": -1,
      "name": "Soil_Dirt_Dry"
    },
    {
      "x": -16,
      "y": 3,
      "z": 0,
      "name": "Soil_Dirt_Dry"
    },
    {
      "x": -16,
      "y": 4,
      "z": 0,
      "name": "Soil_Dirt_Dry"
    },
    {
      "x": -16,
      "y": 3,
      "z": 1,
      "name": "Soil_Dirt_Dry"
    },
    {
      "x": -16,
      "y": 4,
      "z": 1,
      "name": "Soil_Dirt_Dry"
    },
    {
      "x": -16,
      "y": 2,
      "z": 2,
      "name": "Soil_Dirt_Dry"
    },
    {
      "x": -16,
      "y": 3,
      "z": 2,
      "name": "Soil_Dirt_Dry"
    },
    {
      "x": -16,
      "y": 4,
      "z": 2,
      "name": "Soil_Dirt_Dry"
    },
    {
      "x": -16,
      "y": 2,
      "z": 3,
      "name": "Soil_Dirt_Dry"
    },
    {
      "x": -16,
      "y": 3,
      "z": 3,
      "name": "Soil_Dirt_Dry"
    },
    {
      "x": -16,
      "y": 4,
      "z": 3,
      "name": "Soil_Dirt_Dry"
    },
    {
      "x": -16,
      "y": 1,
      "z": 4,
      "name": "Soil_Dirt_Dry"
    },
    {
      "x": -16,
      "y": 2,
      "z": 4,
      "name": "Soil_Dirt_Dry"
    },
    {
      "x": -16,
      "y": 3,
      "z": 4,
      "name": "Soil_Dirt_Dry"
    },
    {
      "x": -16,
      "y": 4,
      "z": 4,
      "name": "Soil_Dirt_Dry"
    },
    {
      "x": -16,
      "y": 1,
      "z": 5,
      "name": "Soil_Dirt_Dry"
    },
    {
      "x": -16,
      "y": 2,
      "z": 5,
      "name": "Soil_Dirt_Dry"
    },
    {
      "x": -16,
      "y": 3,
      "z": 5,
      "name": "Soil_Dirt_Dry"
    },
    {
      "x": -16,
      "y": 4,
      "z": 5,
      "name": "Soil_Dirt_Dry"
    },
    {
      "x": -16,
      "y": 1,
      "z": 6,
      "name": "Soil_Dirt_Dry"
    },
    {
      "x": -16,
      "y": 2,
      "z": 6,
      "name": "Soil_Dirt_Dry"
    },
    {
      "x": -16,
      "y": 3,
      "z": 6,
      "name": "Soil_Dirt_Dry"
    },
    {
      "x": -16,
      "y": 4,
      "z": 6,
      "name": "Soil_Dirt_Dry"
    },
    {
      "x": -16,
      "y": 1,
      "z": 7,
      "name": "Soil_Dirt_Dry"
    },
    {
      "x": -16,
      "y": 2,
      "z": 7,
      "name": "Soil_Dirt_Dry"
    },
    {
      "x": -16,
      "y": 1,
      "z": 8,
      "name": "Soil_Dirt_Dry"
    },
    {
      "x": -16,
      "y": 2,
      "z": 8,
      "name": "Soil_Dirt_Dry"
    },
    {
      "x": -16,
      "y": 1,
      "z": 9,
      "name": "Soil_Dirt_Dry"
    },
    {
      "x": -16,
      "y": 2,
      "z": 9,
      "name": "Soil_Dirt_Dry"
    },
    {
      "x": -16,
      "y": 3,
      "z": 9,
      "name": "Soil_Dirt_Dry"
    },
    {
      "x": -16,
      "y": 1,
      "z": 10,
      "name": "Soil_Dirt_Dry"
    },
    {
      "x": -16,
      "y": 2,
      "z": 10,
      "name": "Soil_Dirt_Dry"
    },
    {
      "x": -16,
      "y": 1,
      "z": 11,
      "name": "Soil_Dirt_Dry"
    },
    {
      "x": -16,
      "y": 2,
      "z": 11,
      "name": "Soil_Dirt_Dry"
    },
    {
      "x": -16,
      "y": 1,
      "z": 12,
      "name": "Soil_Dirt_Dry"
    },
    {
      "x": -16,
      "y": 2,
      "z": 12,
      "name": "Soil_Dirt_Dry"
    },
    {
      "x": -16,
      "y": 1,
      "z": 13,
      "name": "Soil_Dirt_Dry"
    },
    {
      "x": -15,
      "y": 1,
      "z": -20,
      "name": "Soil_Dirt_Dry"
    },
    {
      "x": -15,
      "y": 1,
      "z": -19,
      "name": "Soil_Dirt_Dry"
    },
    {
      "x": -15,
      "y": 2,
      "z": -19,
      "name": "Soil_Dirt_Dry"
    },
    {
      "x": -15,
      "y": 2,
      "z": -18,
      "name": "Soil_Dirt_Dry"
    },
    {
      "x": -15,
      "y": 3,
      "z": -18,
      "name": "Soil_Dirt_Dry"
    },
    {
      "x": -15,
      "y": 2,
      "z": -17,
      "name": "Soil_Dirt_Dry"
    },
    {
      "x": -15,
      "y": 3,
      "z": -17,
      "name": "Soil_Dirt_Dry"
    },
    {
      "x": -15,
      "y": 3,
      "z": -16,
      "name": "Soil_Dirt_Dry"
    },
    {
      "x": -15,
      "y": 3,
      "z": -15,
      "name": "Soil_Dirt_Dry"
    },
    {
      "x": -15,
      "y": 4,
      "z": -15,
      "name": "Soil_Dirt_Dry"
    },
    {
      "x": -15,
      "y": 3,
      "z": -14,
      "name": "Soil_Dirt_Dry"
    },
    {
      "x": -15,
      "y": 4,
      "z": -14,
      "name": "Soil_Dirt_Dry"
    },
    {
      "x": -15,
      "y": 3,
      "z": -13,
      "name": "Soil_Dirt_Dry"
    },
    {
      "x": -15,
      "y": 4,
      "z": -13,
      "name": "Soil_Dirt_Dry"
    },
    {
      "x": -15,
      "y": 3,
      "z": -12,
      "name": "Soil_Dirt_Dry"
    },
    {
      "x": -15,
      "y": 4,
      "z": -12,
      "name": "Soil_Dirt_Dry"
    },
    {
      "x": -15,
      "y": 3,
      "z": -11,
      "name": "Soil_Dirt_Dry"
    },
    {
      "x": -15,
      "y": 4,
      "z": -11,
      "name": "Soil_Dirt_Dry"
    },
    {
      "x": -15,
      "y": 3,
      "z": -10,
      "name": "Soil_Dirt_Dry"
    },
    {
      "x": -15,
      "y": 4,
      "z": -10,
      "name": "Soil_Dirt_Dry"
    },
    {
      "x": -15,
      "y": 1,
      "z": -9,
      "name": "Soil_Dirt_Dry"
    },
    {
      "x": -15,
      "y": 2,
      "z": -9,
      "name": "Soil_Dirt_Dry"
    },
    {
      "x": -15,
      "y": 3,
      "z": -9,
      "name": "Soil_Dirt_Dry"
    },
    {
      "x": -15,
      "y": 4,
      "z": -9,
      "name": "Soil_Dirt_Dry"
    },
    {
      "x": -15,
      "y": 1,
      "z": -8,
      "name": "Soil_Dirt_Dry"
    },
    {
      "x": -15,
      "y": 2,
      "z": -8,
      "name": "Soil_Dirt_Dry"
    },
    {
      "x": -15,
      "y": 3,
      "z": -8,
      "name": "Soil_Dirt_Dry"
    },
    {
      "x": -15,
      "y": 4,
      "z": -8,
      "name": "Soil_Dirt_Dry"
    },
    {
      "x": -15,
      "y": 1,
      "z": -7,
      "name": "Soil_Dirt_Dry"
    },
    {
      "x": -15,
      "y": 2,
      "z": -7,
      "name": "Soil_Dirt_Dry"
    },
    {
      "x": -15,
      "y": 3,
      "z": -7,
      "name": "Soil_Dirt_Dry"
    },
    {
      "x": -15,
      "y": 4,
      "z": -7,
      "name": "Soil_Dirt_Dry"
    },
    {
      "x": -15,
      "y": 1,
      "z": -6,
      "name": "Soil_Dirt_Dry"
    },
    {
      "x": -15,
      "y": 2,
      "z": -6,
      "name": "Soil_Dirt_Dry"
    },
    {
      "x": -15,
      "y": 3,
      "z": -6,
      "name": "Soil_Dirt_Dry"
    },
    {
      "x": -15,
      "y": 4,
      "z": -6,
      "name": "Soil_Dirt_Dry"
    },
    {
      "x": -15,
      "y": 3,
      "z": -5,
      "name": "Soil_Dirt_Dry"
    },
    {
      "x": -15,
      "y": 4,
      "z": -5,
      "name": "Soil_Dirt_Dry"
    },
    {
      "x": -15,
      "y": 3,
      "z": -4,
      "name": "Soil_Dirt_Dry"
    },
    {
      "x": -15,
      "y": 4,
      "z": -4,
      "name": "Soil_Dirt_Dry"
    },
    {
      "x": -15,
      "y": 3,
      "z": -3,
      "name": "Soil_Dirt_Dry"
    },
    {
      "x": -15,
      "y": 4,
      "z": -3,
      "name": "Soil_Dirt_Dry"
    },
    {
      "x": -15,
      "y": 3,
      "z": -2,
      "name": "Soil_Dirt_Dry"
    },
    {
      "x": -15,
      "y": 4,
      "z": -2,
      "name": "Soil_Dirt_Dry"
    },
    {
      "x": -15,
      "y": 3,
      "z": -1,
      "name": "Soil_Dirt_Dry"
    },
    {
      "x": -15,
      "y": 4,
      "z": -1,
      "name": "Soil_Dirt_Dry"
    },
    {
      "x": -15,
      "y": 3,
      "z": 0,
      "name": "Soil_Dirt_Dry"
    },
    {
      "x": -15,
      "y": 4,
      "z": 0,
      "name": "Soil_Dirt_Dry"
    },
    {
      "x": -15,
      "y": 3,
      "z": 1,
      "name": "Soil_Dirt_Dry"
    },
    {
      "x": -15,
      "y": 4,
      "z": 1,
      "name": "Soil_Dirt_Dry"
    },
    {
      "x": -15,
      "y": 2,
      "z": 2,
      "name": "Soil_Dirt_Dry"
    },
    {
      "x": -15,
      "y": 3,
      "z": 2,
      "name": "Soil_Dirt_Dry"
    },
    {
      "x": -15,
      "y": 4,
      "z": 2,
      "name": "Soil_Dirt_Dry"
    },
    {
      "x": -15,
      "y": 2,
      "z": 3,
      "name": "Soil_Dirt_Dry"
    },
    {
      "x": -15,
      "y": 3,
      "z": 3,
      "name": "Soil_Dirt_Dry"
    },
    {
      "x": -15,
      "y": 4,
      "z": 3,
      "name": "Soil_Dirt_Dry"
    },
    {
      "x": -15,
      "y": 1,
      "z": 4,
      "name": "Soil_Dirt_Dry"
    },
    {
      "x": -15,
      "y": 2,
      "z": 4,
      "name": "Soil_Dirt_Dry"
    },
    {
      "x": -15,
      "y": 3,
      "z": 4,
      "name": "Soil_Dirt_Dry"
    },
    {
      "x": -15,
      "y": 4,
      "z": 4,
      "name": "Soil_Dirt_Dry"
    },
    {
      "x": -15,
      "y": 5,
      "z": 4,
      "name": "Rubble_Sandstone",
      "support": 15
    },
    {
      "x": -15,
      "y": 1,
      "z": 5,
      "name": "Soil_Dirt_Dry"
    },
    {
      "x": -15,
      "y": 2,
      "z": 5,
      "name": "Soil_Dirt_Dry"
    },
    {
      "x": -15,
      "y": 3,
      "z": 5,
      "name": "Soil_Dirt_Dry"
    },
    {
      "x": -15,
      "y": 4,
      "z": 5,
      "name": "Soil_Dirt_Dry"
    },
    {
      "x": -15,
      "y": 1,
      "z": 6,
      "name": "Soil_Dirt_Dry"
    },
    {
      "x": -15,
      "y": 2,
      "z": 6,
      "name": "Soil_Dirt_Dry"
    },
    {
      "x": -15,
      "y": 3,
      "z": 6,
      "name": "Soil_Dirt_Dry"
    },
    {
      "x": -15,
      "y": 4,
      "z": 6,
      "name": "Soil_Dirt_Dry"
    },
    {
      "x": -15,
      "y": 2,
      "z": 7,
      "name": "Soil_Dirt_Dry"
    },
    {
      "x": -15,
      "y": 3,
      "z": 7,
      "name": "Soil_Dirt_Dry"
    },
    {
      "x": -15,
      "y": 4,
      "z": 7,
      "name": "Soil_Dirt_Dry"
    },
    {
      "x": -15,
      "y": 2,
      "z": 8,
      "name": "Soil_Dirt_Dry"
    },
    {
      "x": -15,
      "y": 3,
      "z": 8,
      "name": "Soil_Dirt_Dry"
    },
    {
      "x": -15,
      "y": 4,
      "z": 8,
      "name": "Soil_Dirt_Dry"
    },
    {
      "x": -15,
      "y": 2,
      "z": 9,
      "name": "Soil_Dirt_Dry"
    },
    {
      "x": -15,
      "y": 3,
      "z": 9,
      "name": "Soil_Dirt_Dry"
    },
    {
      "x": -15,
      "y": 2,
      "z": 10,
      "name": "Soil_Dirt_Dry"
    },
    {
      "x": -15,
      "y": 3,
      "z": 10,
      "name": "Soil_Dirt_Dry"
    },
    {
      "x": -15,
      "y": 2,
      "z": 11,
      "name": "Soil_Dirt_Dry"
    },
    {
      "x": -15,
      "y": 3,
      "z": 11,
      "name": "Soil_Dirt_Dry"
    },
    {
      "x": -15,
      "y": 1,
      "z": 12,
      "name": "Soil_Dirt_Dry"
    },
    {
      "x": -15,
      "y": 2,
      "z": 12,
      "name": "Soil_Dirt_Dry"
    },
    {
      "x": -15,
      "y": 3,
      "z": 12,
      "name": "Soil_Dirt_Dry"
    },
    {
      "x": -15,
      "y": 1,
      "z": 13,
      "name": "Soil_Dirt_Dry"
    },
    {
      "x": -15,
      "y": 2,
      "z": 13,
      "name": "Soil_Dirt_Dry"
    },
    {
      "x": -15,
      "y": 1,
      "z": 14,
      "name": "Soil_Dirt_Dry"
    },
    {
      "x": -15,
      "y": 2,
      "z": 14,
      "name": "Soil_Dirt_Dry"
    },
    {
      "x": -14,
      "y": 1,
      "z": -20,
      "name": "Soil_Dirt_Dry"
    },
    {
      "x": -14,
      "y": 2,
      "z": -20,
      "name": "Soil_Dirt_Dry"
    },
    {
      "x": -14,
      "y": 1,
      "z": -19,
      "name": "Soil_Dirt_Dry"
    },
    {
      "x": -14,
      "y": 2,
      "z": -19,
      "name": "Soil_Dirt_Dry"
    },
    {
      "x": -14,
      "y": 2,
      "z": -18,
      "name": "Soil_Dirt_Dry"
    },
    {
      "x": -14,
      "y": 3,
      "z": -18,
      "name": "Soil_Dirt_Dry"
    },
    {
      "x": -14,
      "y": 2,
      "z": -17,
      "name": "Soil_Dirt_Dry"
    },
    {
      "x": -14,
      "y": 3,
      "z": -17,
      "name": "Soil_Dirt_Dry"
    },
    {
      "x": -14,
      "y": 3,
      "z": -16,
      "name": "Soil_Dirt_Dry"
    },
    {
      "x": -14,
      "y": 4,
      "z": -16,
      "name": "Soil_Dirt_Dry"
    },
    {
      "x": -14,
      "y": 3,
      "z": -15,
      "name": "Soil_Dirt_Dry"
    },
    {
      "x": -14,
      "y": 4,
      "z": -15,
      "name": "Soil_Dirt_Dry"
    },
    {
      "x": -14,
      "y": 3,
      "z": -14,
      "name": "Soil_Dirt_Dry"
    },
    {
      "x": -14,
      "y": 4,
      "z": -14,
      "name": "Soil_Dirt_Dry"
    },
    {
      "x": -14,
      "y": 3,
      "z": -13,
      "name": "Soil_Dirt_Dry"
    },
    {
      "x": -14,
      "y": 4,
      "z": -13,
      "name": "Soil_Dirt_Dry"
    },
    {
      "x": -14,
      "y": 3,
      "z": -12,
      "name": "Soil_Dirt_Dry"
    },
    {
      "x": -14,
      "y": 4,
      "z": -12,
      "name": "Soil_Dirt_Dry"
    },
    {
      "x": -14,
      "y": 5,
      "z": -12,
      "name": "Deco_Bone_Skulls_Feran"
    },
    {
      "x": -14,
      "y": 3,
      "z": -11,
      "name": "Soil_Dirt_Dry"
    },
    {
      "x": -14,
      "y": 4,
      "z": -11,
      "name": "Soil_Dirt_Dry"
    },
    {
      "x": -14,
      "y": 5,
      "z": -11,
      "name": "Soil_Dirt_Dry"
    },
    {
      "x": -14,
      "y": 3,
      "z": -10,
      "name": "Soil_Dirt_Dry"
    },
    {
      "x": -14,
      "y": 4,
      "z": -10,
      "name": "Soil_Dirt_Dry"
    },
    {
      "x": -14,
      "y": 5,
      "z": -10,
      "name": "Soil_Dirt_Dry"
    },
    {
      "x": -14,
      "y": 1,
      "z": -9,
      "name": "Soil_Dirt_Dry"
    },
    {
      "x": -14,
      "y": 2,
      "z": -9,
      "name": "Soil_Dirt_Dry"
    },
    {
      "x": -14,
      "y": 3,
      "z": -9,
      "name": "Soil_Dirt_Dry"
    },
    {
      "x": -14,
      "y": 4,
      "z": -9,
      "name": "Soil_Dirt_Dry"
    },
    {
      "x": -14,
      "y": 5,
      "z": -9,
      "name": "Soil_Dirt_Dry"
    },
    {
      "x": -14,
      "y": 1,
      "z": -8,
      "name": "Soil_Dirt_Dry"
    },
    {
      "x": -14,
      "y": 2,
      "z": -8,
      "name": "Soil_Dirt_Dry"
    },
    {
      "x": -14,
      "y": 3,
      "z": -8,
      "name": "Soil_Dirt_Dry"
    },
    {
      "x": -14,
      "y": 4,
      "z": -8,
      "name": "Soil_Dirt_Dry"
    },
    {
      "x": -14,
      "y": 1,
      "z": -7,
      "name": "Soil_Dirt_Dry"
    },
    {
      "x": -14,
      "y": 2,
      "z": -7,
      "name": "Soil_Dirt_Dry"
    },
    {
      "x": -14,
      "y": 3,
      "z": -7,
      "name": "Soil_Dirt_Dry"
    },
    {
      "x": -14,
      "y": 4,
      "z": -7,
      "name": "Soil_Dirt_Dry"
    },
    {
      "x": -14,
      "y": 1,
      "z": -6,
      "name": "Soil_Dirt_Dry"
    },
    {
      "x": -14,
      "y": 2,
      "z": -6,
      "name": "Soil_Dirt_Dry"
    },
    {
      "x": -14,
      "y": 3,
      "z": -6,
      "name": "Soil_Dirt_Dry"
    },
    {
      "x": -14,
      "y": 4,
      "z": -6,
      "name": "Soil_Dirt_Dry"
    },
    {
      "x": -14,
      "y": 3,
      "z": -5,
      "name": "Soil_Dirt_Dry"
    },
    {
      "x": -14,
      "y": 4,
      "z": -5,
      "name": "Soil_Dirt_Dry"
    },
    {
      "x": -14,
      "y": 3,
      "z": -4,
      "name": "Soil_Dirt_Dry"
    },
    {
      "x": -14,
      "y": 4,
      "z": -4,
      "name": "Soil_Dirt_Dry"
    },
    {
      "x": -14,
      "y": 3,
      "z": -3,
      "name": "Soil_Dirt_Dry"
    },
    {
      "x": -14,
      "y": 4,
      "z": -3,
      "name": "Soil_Dirt_Dry"
    },
    {
      "x": -14,
      "y": 3,
      "z": -2,
      "name": "Soil_Dirt_Dry"
    },
    {
      "x": -14,
      "y": 4,
      "z": -2,
      "name": "Soil_Dirt_Dry"
    },
    {
      "x": -14,
      "y": 5,
      "z": -2,
      "name": "Soil_Dirt_Dry"
    },
    {
      "x": -14,
      "y": 3,
      "z": -1,
      "name": "Soil_Dirt_Dry"
    },
    {
      "x": -14,
      "y": 4,
      "z": -1,
      "name": "Soil_Dirt_Dry"
    },
    {
      "x": -14,
      "y": 5,
      "z": -1,
      "name": "Soil_Dirt_Dry"
    },
    {
      "x": -14,
      "y": 6,
      "z": -1,
      "name": "Rubble_Sandstone",
      "support": 15
    },
    {
      "x": -14,
      "y": 3,
      "z": 0,
      "name": "Soil_Dirt_Dry"
    },
    {
      "x": -14,
      "y": 4,
      "z": 0,
      "name": "Soil_Dirt_Dry"
    },
    {
      "x": -14,
      "y": 5,
      "z": 0,
      "name": "Soil_Dirt_Dry"
    },
    {
      "x": -14,
      "y": 3,
      "z": 1,
      "name": "Soil_Dirt_Dry"
    },
    {
      "x": -14,
      "y": 4,
      "z": 1,
      "name": "Soil_Dirt_Dry"
    },
    {
      "x": -14,
      "y": 5,
      "z": 1,
      "name": "Wood_Dry_Trunk",
      "support": 15
    },
    {
      "x": -14,
      "y": 6,
      "z": 1,
      "name": "Wood_Dry_Trunk",
      "support": 15
    },
    {
      "x": -14,
      "y": 7,
      "z": 1,
      "name": "Wood_Dry_Trunk",
      "support": 15
    },
    {
      "x": -14,
      "y": 8,
      "z": 1,
      "name": "Wood_Dry_Trunk",
      "support": 15
    },
    {
      "x": -14,
      "y": 9,
      "z": 1,
      "name": "Survival_Trap_Spike_Wood"
    },
    {
      "x": -14,
      "y": 2,
      "z": 2,
      "name": "Soil_Dirt_Dry"
    },
    {
      "x": -14,
      "y": 3,
      "z": 2,
      "name": "Soil_Dirt_Dry"
    },
    {
      "x": -14,
      "y": 4,
      "z": 2,
      "name": "Soil_Dirt_Dry"
    },
    {
      "x": -14,
      "y": 5,
      "z": 2,
      "name": "Soil_Dirt_Dry"
    },
    {
      "x": -14,
      "y": 7,
      "z": 2,
      "name": "Wood_Dry_Branch_Long",
      "support": 15,
      "rotation": 4
    },
    {
      "x": -14,
      "y": 1,
      "z": 3,
      "name": "Soil_Dirt_Dry"
    },
    {
      "x": -14,
      "y": 2,
      "z": 3,
      "name": "Soil_Dirt_Dry"
    },
    {
      "x": -14,
      "y": 3,
      "z": 3,
      "name": "Soil_Dirt_Dry"
    },
    {
      "x": -14,
      "y": 4,
      "z": 3,
      "name": "Soil_Dirt_Dry"
    },
    {
      "x": -14,
      "y": 5,
      "z": 3,
      "name": "Wood_Dry_Trunk",
      "support": 15
    },
    {
      "x": -14,
      "y": 6,
      "z": 3,
      "name": "Wood_Dry_Trunk",
      "support": 15
    },
    {
      "x": -14,
      "y": 7,
      "z": 3,
      "name": "Wood_Dry_Trunk",
      "support": 15
    },
    {
      "x": -14,
      "y": 8,
      "z": 3,
      "name": "Wood_Dry_Trunk",
      "support": 15
    },
    {
      "x": -14,
      "y": 9,
      "z": 3,
      "name": "Survival_Trap_Spike_Wood"
    },
    {
      "x": -14,
      "y": 1,
      "z": 4,
      "name": "Soil_Dirt_Dry"
    },
    {
      "x": -14,
      "y": 2,
      "z": 4,
      "name": "Soil_Dirt_Dry"
    },
    {
      "x": -14,
      "y": 3,
      "z": 4,
      "name": "Soil_Dirt_Dry"
    },
    {
      "x": -14,
      "y": 4,
      "z": 4,
      "name": "Soil_Dirt_Dry"
    },
    {
      "x": -14,
      "y": 5,
      "z": 4,
      "name": "Soil_Dirt_Dry"
    },
    {
      "x": -14,
      "y": 7,
      "z": 4,
      "name": "Wood_Dry_Branch_Long",
      "support": 15,
      "rotation": 4
    },
    {
      "x": -14,
      "y": 1,
      "z": 5,
      "name": "Soil_Dirt_Dry"
    },
    {
      "x": -14,
      "y": 2,
      "z": 5,
      "name": "Soil_Dirt_Dry"
    },
    {
      "x": -14,
      "y": 3,
      "z": 5,
      "name": "Soil_Dirt_Dry"
    },
    {
      "x": -14,
      "y": 4,
      "z": 5,
      "name": "Soil_Dirt_Dry"
    },
    {
      "x": -14,
      "y": 2,
      "z": 6,
      "name": "Soil_Dirt_Dry"
    },
    {
      "x": -14,
      "y": 3,
      "z": 6,
      "name": "Soil_Dirt_Dry"
    },
    {
      "x": -14,
      "y": 4,
      "z": 6,
      "name": "Soil_Dirt_Dry"
    },
    {
      "x": -14,
      "y": 2,
      "z": 7,
      "name": "Soil_Dirt_Dry"
    },
    {
      "x": -14,
      "y": 3,
      "z": 7,
      "name": "Soil_Dirt_Dry"
    },
    {
      "x": -14,
      "y": 4,
      "z": 7,
      "name": "Soil_Dirt_Dry"
    },
    {
      "x": -14,
      "y": 2,
      "z": 8,
      "name": "Soil_Dirt_Dry"
    },
    {
      "x": -14,
      "y": 3,
      "z": 8,
      "name": "Soil_Dirt_Dry"
    },
    {
      "x": -14,
      "y": 4,
      "z": 8,
      "name": "Soil_Dirt_Dry"
    },
    {
      "x": -14,
      "y": 2,
      "z": 9,
      "name": "Soil_Dirt_Dry"
    },
    {
      "x": -14,
      "y": 3,
      "z": 9,
      "name": "Soil_Dirt_Dry"
    },
    {
      "x": -14,
      "y": 4,
      "z": 9,
      "name": "Soil_Dirt_Dry"
    },
    {
      "x": -14,
      "y": 2,
      "z": 10,
      "name": "Soil_Dirt_Dry"
    },
    {
      "x": -14,
      "y": 3,
      "z": 10,
      "name": "Soil_Dirt_Dry"
    },
    {
      "x": -14,
      "y": 2,
      "z": 11,
      "name": "Soil_Dirt_Dry"
    },
    {
      "x": -14,
      "y": 3,
      "z": 11,
      "name": "Soil_Dirt_Dry"
    },
    {
      "x": -14,
      "y": 2,
      "z": 12,
      "name": "Soil_Dirt_Dry"
    },
    {
      "x": -14,
      "y": 3,
      "z": 12,
      "name": "Soil_Dirt_Dry"
    },
    {
      "x": -14,
      "y": 1,
      "z": 13,
      "name": "Soil_Dirt_Dry"
    },
    {
      "x": -14,
      "y": 2,
      "z": 13,
      "name": "Soil_Dirt_Dry"
    },
    {
      "x": -14,
      "y": 3,
      "z": 13,
      "name": "Soil_Dirt_Dry"
    },
    {
      "x": -14,
      "y": 1,
      "z": 14,
      "name": "Soil_Dirt_Dry"
    },
    {
      "x": -14,
      "y": 2,
      "z": 14,
      "name": "Soil_Dirt_Dry"
    },
    {
      "x": -14,
      "y": 1,
      "z": 15,
      "name": "Soil_Dirt_Dry"
    },
    {
      "x": -13,
      "y": 1,
      "z": -20,
      "name": "Soil_Dirt_Dry"
    },
    {
      "x": -13,
      "y": 2,
      "z": -20,
      "name": "Soil_Dirt_Dry"
    },
    {
      "x": -13,
      "y": 1,
      "z": -19,
      "name": "Soil_Dirt_Dry"
    },
    {
      "x": -13,
      "y": 2,
      "z": -19,
      "name": "Soil_Dirt_Dry"
    },
    {
      "x": -13,
      "y": 3,
      "z": -19,
      "name": "Soil_Dirt_Dry"
    },
    {
      "x": -13,
      "y": 2,
      "z": -18,
      "name": "Soil_Dirt_Dry"
    },
    {
      "x": -13,
      "y": 3,
      "z": -18,
      "name": "Soil_Dirt_Dry"
    },
    {
      "x": -13,
      "y": 2,
      "z": -17,
      "name": "Soil_Dirt_Dry"
    },
    {
      "x": -13,
      "y": 3,
      "z": -17,
      "name": "Soil_Dirt_Dry"
    },
    {
      "x": -13,
      "y": 4,
      "z": -17,
      "name": "Soil_Dirt_Dry"
    },
    {
      "x": -13,
      "y": 3,
      "z": -16,
      "name": "Soil_Dirt_Dry"
    },
    {
      "x": -13,
      "y": 4,
      "z": -16,
      "name": "Soil_Dirt_Dry"
    },
    {
      "x": -13,
      "y": 3,
      "z": -15,
      "name": "Soil_Dirt_Dry"
    },
    {
      "x": -13,
      "y": 4,
      "z": -15,
      "name": "Soil_Dirt_Dry"
    },
    {
      "x": -13,
      "y": 3,
      "z": -14,
      "name": "Soil_Dirt_Dry"
    },
    {
      "x": -13,
      "y": 4,
      "z": -14,
      "name": "Soil_Dirt_Dry"
    },
    {
      "x": -13,
      "y": 7,
      "z": -14,
      "name": "Wood_Dry_Branch_Long",
      "support": 15,
      "rotation": 4
    },
    {
      "x": -13,
      "y": 3,
      "z": -13,
      "name": "Soil_Dirt_Dry"
    },
    {
      "x": -13,
      "y": 4,
      "z": -13,
      "name": "Soil_Dirt_Dry"
    },
    {
      "x": -13,
      "y": 5,
      "z": -13,
      "name": "Wood_Dry_Trunk",
      "support": 15
    },
    {
      "x": -13,
      "y": 6,
      "z": -13,
      "name": "Wood_Dry_Trunk",
      "support": 15
    },
    {
      "x": -13,
      "y": 7,
      "z": -13,
      "name": "Wood_Dry_Trunk",
      "support": 15
    },
    {
      "x": -13,
      "y": 8,
      "z": -13,
      "name": "Wood_Dry_Trunk",
      "support": 15
    },
    {
      "x": -13,
      "y": 9,
      "z": -13,
      "name": "Survival_Trap_Spike_Wood"
    },
    {
      "x": -13,
      "y": 3,
      "z": -12,
      "name": "Soil_Dirt_Dry"
    },
    {
      "x": -13,
      "y": 4,
      "z": -12,
      "name": "Soil_Dirt_Dry"
    },
    {
      "x": -13,
      "y": 5,
      "z": -12,
      "name": "Soil_Dirt_Dry"
    },
    {
      "x": -13,
      "y": 7,
      "z": -12,
      "name": "Wood_Dry_Branch_Long",
      "support": 15,
      "rotation": 4
    },
    {
      "x": -13,
      "y": 3,
      "z": -11,
      "name": "Soil_Dirt_Dry"
    },
    {
      "x": -13,
      "y": 4,
      "z": -11,
      "name": "Soil_Dirt_Dry"
    },
    {
      "x": -13,
      "y": 5,
      "z": -11,
      "name": "Soil_Dirt_Dry"
    },
    {
      "x": -13,
      "y": 7,
      "z": -11,
      "name": "Wood_Dry_Branch_Long",
      "support": 15,
      "rotation": 4
    },
    {
      "x": -13,
      "y": 11,
      "z": -11,
      "name": "Wood_Dry_Branch_Short",
      "support": 15,
      "rotation": 2
    },
    {
      "x": -13,
      "y": 3,
      "z": -10,
      "name": "Soil_Dirt_Dry"
    },
    {
      "x": -13,
      "y": 4,
      "z": -10,
      "name": "Soil_Dirt_Dry"
    },
    {
      "x": -13,
      "y": 5,
      "z": -10,
      "name": "Soil_Dirt_Dry"
    },
    {
      "x": -13,
      "y": 6,
      "z": -10,
      "name": "Wood_Dry_Trunk",
      "support": 15
    },
    {
      "x": -13,
      "y": 7,
      "z": -10,
      "name": "Wood_Dry_Trunk",
      "support": 15
    },
    {
      "x": -13,
      "y": 8,
      "z": -10,
      "name": "Wood_Dry_Trunk",
      "support": 15
    },
    {
      "x": -13,
      "y": 9,
      "z": -10,
      "name": "Wood_Dry_Trunk",
      "support": 15
    },
    {
      "x": -13,
      "y": 10,
      "z": -10,
      "name": "Wood_Dry_Trunk",
      "support": 15
    },
    {
      "x": -13,
      "y": 11,
      "z": -10,
      "name": "Wood_Dry_Trunk",
      "support": 15
    },
    {
      "x": -13,
      "y": 12,
      "z": -10,
      "name": "Wood_Dry_Trunk",
      "support": 15
    },
    {
      "x": -13,
      "y": 2,
      "z": -9,
      "name": "Soil_Dirt_Dry"
    },
    {
      "x": -13,
      "y": 3,
      "z": -9,
      "name": "Soil_Dirt_Dry"
    },
    {
      "x": -13,
      "y": 4,
      "z": -9,
      "name": "Soil_Dirt_Dry"
    },
    {
      "x": -13,
      "y": 5,
      "z": -9,
      "name": "Soil_Dirt_Dry"
    },
    {
      "x": -13,
      "y": 11,
      "z": -9,
      "name": "Wood_Dry_Trunk",
      "support": 15,
      "rotation": 4
    },
    {
      "x": -13,
      "y": 1,
      "z": -8,
      "name": "Soil_Dirt_Dry"
    },
    {
      "x": -13,
      "y": 2,
      "z": -8,
      "name": "Soil_Dirt_Dry"
    },
    {
      "x": -13,
      "y": 3,
      "z": -8,
      "name": "Soil_Dirt_Dry"
    },
    {
      "x": -13,
      "y": 4,
      "z": -8,
      "name": "Soil_Dirt_Dry"
    },
    {
      "x": -13,
      "y": 5,
      "z": -8,
      "name": "Soil_Dirt_Dry"
    },
    {
      "x": -13,
      "y": 11,
      "z": -8,
      "name": "Wood_Dry_Trunk",
      "support": 15,
      "rotation": 4
    },
    {
      "x": -13,
      "y": 1,
      "z": -7,
      "name": "Soil_Dirt_Dry"
    },
    {
      "x": -13,
      "y": 2,
      "z": -7,
      "name": "Soil_Dirt_Dry"
    },
    {
      "x": -13,
      "y": 3,
      "z": -7,
      "name": "Soil_Dirt_Dry"
    },
    {
      "x": -13,
      "y": 4,
      "z": -7,
      "name": "Soil_Dirt_Dry"
    },
    {
      "x": -13,
      "y": 5,
      "z": -7,
      "name": "Soil_Dirt_Dry"
    },
    {
      "x": -13,
      "y": 11,
      "z": -7,
      "name": "Wood_Dry_Trunk",
      "support": 15,
      "rotation": 4
    },
    {
      "x": -13,
      "y": 1,
      "z": -6,
      "name": "Soil_Dirt_Dry"
    },
    {
      "x": -13,
      "y": 2,
      "z": -6,
      "name": "Soil_Dirt_Dry"
    },
    {
      "x": -13,
      "y": 3,
      "z": -6,
      "name": "Soil_Dirt_Dry"
    },
    {
      "x": -13,
      "y": 4,
      "z": -6,
      "name": "Soil_Dirt_Dry"
    },
    {
      "x": -13,
      "y": 5,
      "z": -6,
      "name": "Soil_Dirt_Dry"
    },
    {
      "x": -13,
      "y": 11,
      "z": -6,
      "name": "Wood_Dry_Trunk",
      "support": 15,
      "rotation": 4
    },
    {
      "x": -13,
      "y": 2,
      "z": -5,
      "name": "Soil_Dirt_Dry"
    },
    {
      "x": -13,
      "y": 3,
      "z": -5,
      "name": "Soil_Dirt_Dry"
    },
    {
      "x": -13,
      "y": 4,
      "z": -5,
      "name": "Soil_Dirt_Dry"
    },
    {
      "x": -13,
      "y": 5,
      "z": -5,
      "name": "Soil_Dirt_Dry"
    },
    {
      "x": -13,
      "y": 11,
      "z": -5,
      "name": "Wood_Dry_Trunk",
      "support": 15,
      "rotation": 4
    },
    {
      "x": -13,
      "y": 3,
      "z": -4,
      "name": "Soil_Dirt_Dry"
    },
    {
      "x": -13,
      "y": 4,
      "z": -4,
      "name": "Soil_Dirt_Dry"
    },
    {
      "x": -13,
      "y": 5,
      "z": -4,
      "name": "Soil_Dirt_Dry"
    },
    {
      "x": -13,
      "y": 11,
      "z": -4,
      "name": "Wood_Dry_Trunk",
      "support": 15,
      "rotation": 4
    },
    {
      "x": -13,
      "y": 3,
      "z": -3,
      "name": "Soil_Dirt_Dry"
    },
    {
      "x": -13,
      "y": 4,
      "z": -3,
      "name": "Soil_Dirt_Dry"
    },
    {
      "x": -13,
      "y": 5,
      "z": -3,
      "name": "Soil_Dirt_Dry"
    },
    {
      "x": -13,
      "y": 11,
      "z": -3,
      "name": "Wood_Dry_Trunk",
      "support": 15,
      "rotation": 4
    },
    {
      "x": -13,
      "y": 3,
      "z": -2,
      "name": "Soil_Dirt_Dry"
    },
    {
      "x": -13,
      "y": 4,
      "z": -2,
      "name": "Soil_Dirt_Dry"
    },
    {
      "x": -13,
      "y": 5,
      "z": -2,
      "name": "Soil_Dirt_Dry"
    },
    {
      "x": -13,
      "y": 11,
      "z": -2,
      "name": "Wood_Dry_Trunk",
      "support": 15,
      "rotation": 4
    },
    {
      "x": -13,
      "y": 3,
      "z": -1,
      "name": "Soil_Dirt_Dry"
    },
    {
      "x": -13,
      "y": 4,
      "z": -1,
      "name": "Soil_Dirt_Dry"
    },
    {
      "x": -13,
      "y": 5,
      "z": -1,
      "name": "Soil_Dirt_Dry"
    },
    {
      "x": -13,
      "y": 6,
      "z": -1,
      "name": "Wood_Dry_Trunk",
      "support": 15
    },
    {
      "x": -13,
      "y": 7,
      "z": -1,
      "name": "Wood_Dry_Trunk",
      "support": 15
    },
    {
      "x": -13,
      "y": 8,
      "z": -1,
      "name": "Wood_Dry_Trunk",
      "support": 15
    },
    {
      "x": -13,
      "y": 9,
      "z": -1,
      "name": "Wood_Dry_Trunk",
      "support": 15
    },
    {
      "x": -13,
      "y": 10,
      "z": -1,
      "name": "Wood_Dry_Trunk",
      "support": 15
    },
    {
      "x": -13,
      "y": 11,
      "z": -1,
      "name": "Wood_Dry_Trunk",
      "support": 15
    },
    {
      "x": -13,
      "y": 12,
      "z": -1,
      "name": "Wood_Dry_Trunk",
      "support": 15
    },
    {
      "x": -13,
      "y": 3,
      "z": 0,
      "name": "Soil_Dirt_Dry"
    },
    {
      "x": -13,
      "y": 4,
      "z": 0,
      "name": "Soil_Dirt_Dry"
    },
    {
      "x": -13,
      "y": 5,
      "z": 0,
      "name": "Soil_Dirt_Dry"
    },
    {
      "x": -13,
      "y": 7,
      "z": 0,
      "name": "Wood_Dry_Branch_Long",
      "support": 15,
      "rotation": 4
    },
    {
      "x": -13,
      "y": 11,
      "z": 0,
      "name": "Wood_Dry_Branch_Short",
      "support": 15
    },
    {
      "x": -13,
      "y": 2,
      "z": 1,
      "name": "Soil_Dirt_Dry"
    },
    {
      "x": -13,
      "y": 3,
      "z": 1,
      "name": "Soil_Dirt_Dry"
    },
    {
      "x": -13,
      "y": 4,
      "z": 1,
      "name": "Soil_Dirt_Dry"
    },
    {
      "x": -13,
      "y": 5,
      "z": 1,
      "name": "Soil_Dirt_Dry"
    },
    {
      "x": -13,
      "y": 2,
      "z": 2,
      "name": "Soil_Dirt_Dry"
    },
    {
      "x": -13,
      "y": 3,
      "z": 2,
      "name": "Soil_Dirt_Dry"
    },
    {
      "x": -13,
      "y": 4,
      "z": 2,
      "name": "Soil_Dirt_Dry"
    },
    {
      "x": -13,
      "y": 5,
      "z": 2,
      "name": "Soil_Dirt_Dry"
    },
    {
      "x": -13,
      "y": 1,
      "z": 3,
      "name": "Soil_Dirt_Dry"
    },
    {
      "x": -13,
      "y": 2,
      "z": 3,
      "name": "Soil_Dirt_Dry"
    },
    {
      "x": -13,
      "y": 3,
      "z": 3,
      "name": "Soil_Dirt_Dry"
    },
    {
      "x": -13,
      "y": 4,
      "z": 3,
      "name": "Soil_Dirt_Dry"
    },
    {
      "x": -13,
      "y": 5,
      "z": 3,
      "name": "Soil_Dirt_Dry"
    },
    {
      "x": -13,
      "y": 1,
      "z": 4,
      "name": "Soil_Dirt_Dry"
    },
    {
      "x": -13,
      "y": 2,
      "z": 4,
      "name": "Soil_Dirt_Dry"
    },
    {
      "x": -13,
      "y": 3,
      "z": 4,
      "name": "Soil_Dirt_Dry"
    },
    {
      "x": -13,
      "y": 4,
      "z": 4,
      "name": "Soil_Dirt_Dry"
    },
    {
      "x": -13,
      "y": 5,
      "z": 4,
      "name": "Soil_Dirt_Dry"
    },
    {
      "x": -13,
      "y": 2,
      "z": 5,
      "name": "Soil_Dirt_Dry"
    },
    {
      "x": -13,
      "y": 3,
      "z": 5,
      "name": "Soil_Dirt_Dry"
    },
    {
      "x": -13,
      "y": 4,
      "z": 5,
      "name": "Soil_Dirt_Dry"
    },
    {
      "x": -13,
      "y": 5,
      "z": 5,
      "name": "Soil_Dirt_Dry"
    },
    {
      "x": -13,
      "y": 7,
      "z": 5,
      "name": "Wood_Dry_Branch_Long",
      "support": 15,
      "rotation": 4
    },
    {
      "x": -13,
      "y": 8,
      "z": 5,
      "name": "Plant_Leaves_Bramble",
      "support": 15
    },
    {
      "x": -13,
      "y": 2,
      "z": 6,
      "name": "Soil_Dirt_Dry"
    },
    {
      "x": -13,
      "y": 3,
      "z": 6,
      "name": "Soil_Dirt_Dry"
    },
    {
      "x": -13,
      "y": 4,
      "z": 6,
      "name": "Soil_Dirt_Dry"
    },
    {
      "x": -13,
      "y": 5,
      "z": 6,
      "name": "Wood_Dry_Trunk",
      "support": 15
    },
    {
      "x": -13,
      "y": 6,
      "z": 6,
      "name": "Wood_Dry_Trunk",
      "support": 15
    },
    {
      "x": -13,
      "y": 7,
      "z": 6,
      "name": "Wood_Dry_Trunk",
      "support": 15
    },
    {
      "x": -13,
      "y": 8,
      "z": 6,
      "name": "Wood_Dry_Trunk",
      "support": 15
    },
    {
      "x": -13,
      "y": 9,
      "z": 6,
      "name": "Survival_Trap_Spike_Wood"
    },
    {
      "x": -13,
      "y": 3,
      "z": 7,
      "name": "Soil_Dirt_Dry"
    },
    {
      "x": -13,
      "y": 4,
      "z": 7,
      "name": "Soil_Dirt_Dry"
    },
    {
      "x": -13,
      "y": 7,
      "z": 7,
      "name": "Wood_Dry_Branch_Long",
      "support": 15,
      "rotation": 4
    },
    {
      "x": -13,
      "y": 3,
      "z": 8,
      "name": "Soil_Dirt_Dry"
    },
    {
      "x": -13,
      "y": 4,
      "z": 8,
      "name": "Soil_Dirt_Dry"
    },
    {
      "x": -13,
      "y": 7,
      "z": 8,
      "name": "Wood_Dry_Branch_Long",
      "support": 15,
      "rotation": 4
    },
    {
      "x": -13,
      "y": 3,
      "z": 9,
      "name": "Soil_Dirt_Dry"
    },
    {
      "x": -13,
      "y": 4,
      "z": 9,
      "name": "Soil_Dirt_Dry"
    },
    {
      "x": -13,
      "y": 3,
      "z": 10,
      "name": "Soil_Dirt_Dry"
    },
    {
      "x": -13,
      "y": 4,
      "z": 10,
      "name": "Soil_Dirt_Dry"
    },
    {
      "x": -13,
      "y": 3,
      "z": 11,
      "name": "Soil_Dirt_Dry"
    },
    {
      "x": -13,
      "y": 2,
      "z": 12,
      "name": "Soil_Dirt_Dry"
    },
    {
      "x": -13,
      "y": 3,
      "z": 12,
      "name": "Soil_Dirt_Dry"
    },
    {
      "x": -13,
      "y": 2,
      "z": 13,
      "name": "Soil_Dirt_Dry"
    },
    {
      "x": -13,
      "y": 3,
      "z": 13,
      "name": "Soil_Dirt_Dry"
    },
    {
      "x": -13,
      "y": 1,
      "z": 14,
      "name": "Soil_Dirt_Dry"
    },
    {
      "x": -13,
      "y": 2,
      "z": 14,
      "name": "Soil_Dirt_Dry"
    },
    {
      "x": -13,
      "y": 3,
      "z": 14,
      "name": "Soil_Dirt_Dry"
    },
    {
      "x": -13,
      "y": 1,
      "z": 15,
      "name": "Soil_Dirt_Dry"
    },
    {
      "x": -13,
      "y": 2,
      "z": 15,
      "name": "Soil_Dirt_Dry"
    },
    {
      "x": -12,
      "y": 1,
      "z": -20,
      "name": "Soil_Dirt_Dry"
    },
    {
      "x": -12,
      "y": 2,
      "z": -20,
      "name": "Soil_Dirt_Dry"
    },
    {
      "x": -12,
      "y": 1,
      "z": -19,
      "name": "Soil_Dirt_Dry"
    },
    {
      "x": -12,
      "y": 2,
      "z": -19,
      "name": "Soil_Dirt_Dry"
    },
    {
      "x": -12,
      "y": 3,
      "z": -19,
      "name": "Soil_Dirt_Dry"
    },
    {
      "x": -12,
      "y": 2,
      "z": -18,
      "name": "Soil_Dirt_Dry"
    },
    {
      "x": -12,
      "y": 3,
      "z": -18,
      "name": "Soil_Dirt_Dry"
    },
    {
      "x": -12,
      "y": 4,
      "z": -18,
      "name": "Soil_Dirt_Dry"
    },
    {
      "x": -12,
      "y": 2,
      "z": -17,
      "name": "Soil_Dirt_Dry"
    },
    {
      "x": -12,
      "y": 3,
      "z": -17,
      "name": "Soil_Dirt_Dry"
    },
    {
      "x": -12,
      "y": 4,
      "z": -17,
      "name": "Soil_Dirt_Dry"
    },
    {
      "x": -12,
      "y": 3,
      "z": -16,
      "name": "Soil_Dirt_Dry"
    },
    {
      "x": -12,
      "y": 4,
      "z": -16,
      "name": "Soil_Dirt_Dry"
    },
    {
      "x": -12,
      "y": 3,
      "z": -15,
      "name": "Soil_Dirt_Dry"
    },
    {
      "x": -12,
      "y": 4,
      "z": -15,
      "name": "Soil_Dirt_Dry"
    },
    {
      "x": -12,
      "y": 5,
      "z": -15,
      "name": "Wood_Dry_Trunk",
      "support": 15
    },
    {
      "x": -12,
      "y": 6,
      "z": -15,
      "name": "Wood_Dry_Trunk",
      "support": 15
    },
    {
      "x": -12,
      "y": 7,
      "z": -15,
      "name": "Wood_Dry_Trunk",
      "support": 15
    },
    {
      "x": -12,
      "y": 8,
      "z": -15,
      "name": "Wood_Dry_Trunk",
      "support": 15
    },
    {
      "x": -12,
      "y": 9,
      "z": -15,
      "name": "Survival_Trap_Spike_Wood"
    },
    {
      "x": -12,
      "y": 3,
      "z": -14,
      "name": "Soil_Dirt_Dry"
    },
    {
      "x": -12,
      "y": 4,
      "z": -14,
      "name": "Soil_Dirt_Dry"
    },
    {
      "x": -12,
      "y": 5,
      "z": -14,
      "name": "Soil_Dirt_Dry"
    },
    {
      "x": -12,
      "y": 3,
      "z": -13,
      "name": "Soil_Dirt_Dry"
    },
    {
      "x": -12,
      "y": 4,
      "z": -13,
      "name": "Soil_Dirt_Dry"
    },
    {
      "x": -12,
      "y": 5,
      "z": -13,
      "name": "Soil_Dirt_Dry"
    },
    {
      "x": -12,
      "y": 3,
      "z": -12,
      "name": "Soil_Dirt_Dry"
    },
    {
      "x": -12,
      "y": 4,
      "z": -12,
      "name": "Soil_Dirt_Dry"
    },
    {
      "x": -12,
      "y": 5,
      "z": -12,
      "name": "Soil_Dirt_Dry"
    },
    {
      "x": -12,
      "y": 3,
      "z": -11,
      "name": "Soil_Dirt_Dry"
    },
    {
      "x": -12,
      "y": 4,
      "z": -11,
      "name": "Soil_Dirt_Dry"
    },
    {
      "x": -12,
      "y": 5,
      "z": -11,
      "name": "Soil_Dirt_Dry"
    },
    {
      "x": -12,
      "y": 3,
      "z": -10,
      "name": "Soil_Dirt_Dry"
    },
    {
      "x": -12,
      "y": 4,
      "z": -10,
      "name": "Soil_Dirt_Dry"
    },
    {
      "x": -12,
      "y": 5,
      "z": -10,
      "name": "Soil_Dirt_Dry"
    },
    {
      "x": -12,
      "y": 2,
      "z": -9,
      "name": "Soil_Dirt_Dry"
    },
    {
      "x": -12,
      "y": 3,
      "z": -9,
      "name": "Soil_Dirt_Dry"
    },
    {
      "x": -12,
      "y": 4,
      "z": -9,
      "name": "Soil_Dirt_Dry"
    },
    {
      "x": -12,
      "y": 5,
      "z": -9,
      "name": "Soil_Dirt_Dry"
    },
    {
      "x": -12,
      "y": 1,
      "z": -8,
      "name": "Soil_Dirt_Dry"
    },
    {
      "x": -12,
      "y": 2,
      "z": -8,
      "name": "Soil_Dirt_Dry"
    },
    {
      "x": -12,
      "y": 3,
      "z": -8,
      "name": "Soil_Dirt_Dry"
    },
    {
      "x": -12,
      "y": 4,
      "z": -8,
      "name": "Soil_Dirt_Dry"
    },
    {
      "x": -12,
      "y": 5,
      "z": -8,
      "name": "Soil_Dirt_Dry"
    },
    {
      "x": -12,
      "y": 1,
      "z": -7,
      "name": "Soil_Dirt_Dry"
    },
    {
      "x": -12,
      "y": 2,
      "z": -7,
      "name": "Soil_Dirt_Dry"
    },
    {
      "x": -12,
      "y": 3,
      "z": -7,
      "name": "Soil_Dirt_Dry"
    },
    {
      "x": -12,
      "y": 4,
      "z": -7,
      "name": "Soil_Dirt_Dry"
    },
    {
      "x": -12,
      "y": 5,
      "z": -7,
      "name": "Soil_Dirt_Dry"
    },
    {
      "x": -12,
      "y": 1,
      "z": -6,
      "name": "Soil_Dirt_Dry"
    },
    {
      "x": -12,
      "y": 2,
      "z": -6,
      "name": "Soil_Dirt_Dry"
    },
    {
      "x": -12,
      "y": 3,
      "z": -6,
      "name": "Soil_Dirt_Dry"
    },
    {
      "x": -12,
      "y": 4,
      "z": -6,
      "name": "Soil_Dirt_Dry"
    },
    {
      "x": -12,
      "y": 5,
      "z": -6,
      "name": "Soil_Dirt_Dry"
    },
    {
      "x": -12,
      "y": 2,
      "z": -5,
      "name": "Soil_Dirt_Dry"
    },
    {
      "x": -12,
      "y": 3,
      "z": -5,
      "name": "Soil_Dirt_Dry"
    },
    {
      "x": -12,
      "y": 4,
      "z": -5,
      "name": "Soil_Dirt_Dry"
    },
    {
      "x": -12,
      "y": 5,
      "z": -5,
      "name": "Soil_Dirt_Dry"
    },
    {
      "x": -12,
      "y": 2,
      "z": -4,
      "name": "Soil_Dirt_Dry"
    },
    {
      "x": -12,
      "y": 3,
      "z": -4,
      "name": "Soil_Dirt_Dry"
    },
    {
      "x": -12,
      "y": 4,
      "z": -4,
      "name": "Soil_Dirt_Dry"
    },
    {
      "x": -12,
      "y": 5,
      "z": -4,
      "name": "Soil_Dirt_Dry"
    },
    {
      "x": -12,
      "y": 2,
      "z": -3,
      "name": "Soil_Dirt_Dry"
    },
    {
      "x": -12,
      "y": 3,
      "z": -3,
      "name": "Soil_Dirt_Dry"
    },
    {
      "x": -12,
      "y": 4,
      "z": -3,
      "name": "Soil_Dirt_Dry"
    },
    {
      "x": -12,
      "y": 5,
      "z": -3,
      "name": "Soil_Dirt_Dry"
    },
    {
      "x": -12,
      "y": 2,
      "z": -2,
      "name": "Soil_Dirt_Dry"
    },
    {
      "x": -12,
      "y": 3,
      "z": -2,
      "name": "Soil_Dirt_Dry"
    },
    {
      "x": -12,
      "y": 4,
      "z": -2,
      "name": "Soil_Dirt_Dry"
    },
    {
      "x": -12,
      "y": 5,
      "z": -2,
      "name": "Soil_Dirt_Dry"
    },
    {
      "x": -12,
      "y": 2,
      "z": -1,
      "name": "Soil_Dirt_Dry"
    },
    {
      "x": -12,
      "y": 3,
      "z": -1,
      "name": "Soil_Dirt_Dry"
    },
    {
      "x": -12,
      "y": 4,
      "z": -1,
      "name": "Soil_Dirt_Dry"
    },
    {
      "x": -12,
      "y": 5,
      "z": -1,
      "name": "Soil_Dirt_Dry"
    },
    {
      "x": -12,
      "y": 2,
      "z": 0,
      "name": "Soil_Dirt_Dry"
    },
    {
      "x": -12,
      "y": 3,
      "z": 0,
      "name": "Soil_Dirt_Dry"
    },
    {
      "x": -12,
      "y": 4,
      "z": 0,
      "name": "Soil_Dirt_Dry"
    },
    {
      "x": -12,
      "y": 5,
      "z": 0,
      "name": "Soil_Dirt_Dry"
    },
    {
      "x": -12,
      "y": 2,
      "z": 1,
      "name": "Soil_Dirt_Dry"
    },
    {
      "x": -12,
      "y": 3,
      "z": 1,
      "name": "Soil_Dirt_Dry"
    },
    {
      "x": -12,
      "y": 4,
      "z": 1,
      "name": "Soil_Dirt_Dry"
    },
    {
      "x": -12,
      "y": 5,
      "z": 1,
      "name": "Soil_Dirt_Dry"
    },
    {
      "x": -12,
      "y": 1,
      "z": 2,
      "name": "Soil_Dirt_Dry"
    },
    {
      "x": -12,
      "y": 2,
      "z": 2,
      "name": "Soil_Dirt_Dry"
    },
    {
      "x": -12,
      "y": 3,
      "z": 2,
      "name": "Soil_Dirt_Dry"
    },
    {
      "x": -12,
      "y": 4,
      "z": 2,
      "name": "Soil_Dirt_Dry"
    },
    {
      "x": -12,
      "y": 5,
      "z": 2,
      "name": "Soil_Dirt_Dry"
    },
    {
      "x": -12,
      "y": 1,
      "z": 3,
      "name": "Soil_Dirt_Dry"
    },
    {
      "x": -12,
      "y": 2,
      "z": 3,
      "name": "Soil_Dirt_Dry"
    },
    {
      "x": -12,
      "y": 3,
      "z": 3,
      "name": "Soil_Dirt_Dry"
    },
    {
      "x": -12,
      "y": 4,
      "z": 3,
      "name": "Soil_Dirt_Dry"
    },
    {
      "x": -12,
      "y": 5,
      "z": 3,
      "name": "Soil_Dirt_Dry"
    },
    {
      "x": -12,
      "y": 1,
      "z": 4,
      "name": "Soil_Dirt_Dry"
    },
    {
      "x": -12,
      "y": 2,
      "z": 4,
      "name": "Soil_Dirt_Dry"
    },
    {
      "x": -12,
      "y": 3,
      "z": 4,
      "name": "Soil_Dirt_Dry"
    },
    {
      "x": -12,
      "y": 4,
      "z": 4,
      "name": "Soil_Dirt_Dry"
    },
    {
      "x": -12,
      "y": 5,
      "z": 4,
      "name": "Soil_Dirt_Dry"
    },
    {
      "x": -12,
      "y": 2,
      "z": 5,
      "name": "Soil_Dirt_Dry"
    },
    {
      "x": -12,
      "y": 3,
      "z": 5,
      "name": "Soil_Dirt_Dry"
    },
    {
      "x": -12,
      "y": 4,
      "z": 5,
      "name": "Soil_Dirt_Dry"
    },
    {
      "x": -12,
      "y": 5,
      "z": 5,
      "name": "Soil_Dirt_Dry"
    },
    {
      "x": -12,
      "y": 3,
      "z": 6,
      "name": "Soil_Dirt_Dry"
    },
    {
      "x": -12,
      "y": 4,
      "z": 6,
      "name": "Soil_Dirt_Dry"
    },
    {
      "x": -12,
      "y": 5,
      "z": 6,
      "name": "Soil_Dirt_Dry"
    },
    {
      "x": -12,
      "y": 3,
      "z": 7,
      "name": "Soil_Dirt_Dry"
    },
    {
      "x": -12,
      "y": 4,
      "z": 7,
      "name": "Soil_Dirt_Dry"
    },
    {
      "x": -12,
      "y": 5,
      "z": 7,
      "name": "Soil_Dirt_Dry"
    },
    {
      "x": -12,
      "y": 3,
      "z": 8,
      "name": "Soil_Dirt_Dry"
    },
    {
      "x": -12,
      "y": 4,
      "z": 8,
      "name": "Soil_Dirt_Dry"
    },
    {
      "x": -12,
      "y": 3,
      "z": 9,
      "name": "Soil_Dirt_Dry"
    },
    {
      "x": -12,
      "y": 4,
      "z": 9,
      "name": "Soil_Dirt_Dry"
    },
    {
      "x": -12,
      "y": 7,
      "z": 9,
      "name": "Wood_Dry_Branch_Long",
      "support": 15,
      "rotation": 5
    },
    {
      "x": -12,
      "y": 3,
      "z": 10,
      "name": "Soil_Dirt_Dry"
    },
    {
      "x": -12,
      "y": 4,
      "z": 10,
      "name": "Soil_Dirt_Dry"
    },
    {
      "x": -12,
      "y": 3,
      "z": 11,
      "name": "Soil_Dirt_Dry"
    },
    {
      "x": -12,
      "y": 4,
      "z": 11,
      "name": "Soil_Dirt_Dry"
    },
    {
      "x": -12,
      "y": 3,
      "z": 12,
      "name": "Soil_Dirt_Dry"
    },
    {
      "x": -12,
      "y": 4,
      "z": 12,
      "name": "Soil_Dirt_Dry"
    },
    {
      "x": -12,
      "y": 5,
      "z": 12,
      "name": "Deco_Bone_Skulls_Feran"
    },
    {
      "x": -12,
      "y": 2,
      "z": 13,
      "name": "Soil_Dirt_Dry"
    },
    {
      "x": -12,
      "y": 3,
      "z": 13,
      "name": "Soil_Dirt_Dry"
    },
    {
      "x": -12,
      "y": 4,
      "z": 13,
      "name": "Soil_Dirt_Dry"
    },
    {
      "x": -12,
      "y": 5,
      "z": 13,
      "name": "Rubble_Sandstone",
      "support": 15
    },
    {
      "x": -12,
      "y": 2,
      "z": 14,
      "name": "Soil_Dirt_Dry"
    },
    {
      "x": -12,
      "y": 3,
      "z": 14,
      "name": "Soil_Dirt_Dry"
    },
    {
      "x": -12,
      "y": 1,
      "z": 15,
      "name": "Soil_Dirt_Dry"
    },
    {
      "x": -12,
      "y": 2,
      "z": 15,
      "name": "Soil_Dirt_Dry"
    },
    {
      "x": -12,
      "y": 1,
      "z": 16,
      "name": "Soil_Dirt_Dry"
    },
    {
      "x": -12,
      "y": 1,
      "z": 17,
      "name": "Soil_Dirt_Dry"
    },
    {
      "x": -12,
      "y": 2,
      "z": 17,
      "name": "Soil_Dirt_Dry"
    },
    {
      "x": -12,
      "y": 1,
      "z": 18,
      "name": "Soil_Dirt_Dry"
    },
    {
      "x": -12,
      "y": 2,
      "z": 18,
      "name": "Soil_Dirt_Dry"
    },
    {
      "x": -12,
      "y": 1,
      "z": 19,
      "name": "Soil_Dirt_Dry"
    },
    {
      "x": -12,
      "y": 2,
      "z": 19,
      "name": "Soil_Dirt_Dry"
    },
    {
      "x": -12,
      "y": 1,
      "z": 20,
      "name": "Soil_Dirt_Dry"
    },
    {
      "x": -11,
      "y": 1,
      "z": -20,
      "name": "Soil_Dirt_Dry"
    },
    {
      "x": -11,
      "y": 2,
      "z": -20,
      "name": "Soil_Dirt_Dry"
    },
    {
      "x": -11,
      "y": 1,
      "z": -19,
      "name": "Soil_Dirt_Dry"
    },
    {
      "x": -11,
      "y": 2,
      "z": -19,
      "name": "Soil_Dirt_Dry"
    },
    {
      "x": -11,
      "y": 3,
      "z": -19,
      "name": "Soil_Dirt_Dry"
    },
    {
      "x": -11,
      "y": 1,
      "z": -18,
      "name": "Soil_Dirt_Dry"
    },
    {
      "x": -11,
      "y": 2,
      "z": -18,
      "name": "Soil_Dirt_Dry"
    },
    {
      "x": -11,
      "y": 3,
      "z": -18,
      "name": "Soil_Dirt_Dry"
    },
    {
      "x": -11,
      "y": 4,
      "z": -18,
      "name": "Soil_Dirt_Dry"
    },
    {
      "x": -11,
      "y": 1,
      "z": -17,
      "name": "Soil_Dirt_Dry"
    },
    {
      "x": -11,
      "y": 2,
      "z": -17,
      "name": "Soil_Dirt_Dry"
    },
    {
      "x": -11,
      "y": 3,
      "z": -17,
      "name": "Soil_Dirt_Dry"
    },
    {
      "x": -11,
      "y": 4,
      "z": -17,
      "name": "Soil_Dirt_Dry"
    },
    {
      "x": -11,
      "y": 3,
      "z": -16,
      "name": "Soil_Dirt_Dry"
    },
    {
      "x": -11,
      "y": 4,
      "z": -16,
      "name": "Soil_Dirt_Dry"
    },
    {
      "x": -11,
      "y": 5,
      "z": -16,
      "name": "Soil_Dirt_Dry"
    },
    {
      "x": -11,
      "y": 7,
      "z": -16,
      "name": "Wood_Dry_Branch_Long",
      "support": 15,
      "rotation": 5
    },
    {
      "x": -11,
      "y": 8,
      "z": -16,
      "name": "Plant_Leaves_Bramble",
      "support": 15
    },
    {
      "x": -11,
      "y": 3,
      "z": -15,
      "name": "Soil_Dirt_Dry"
    },
    {
      "x": -11,
      "y": 4,
      "z": -15,
      "name": "Soil_Dirt_Dry"
    },
    {
      "x": -11,
      "y": 5,
      "z": -15,
      "name": "Soil_Dirt_Dry"
    },
    {
      "x": -11,
      "y": 3,
      "z": -14,
      "name": "Soil_Dirt_Dry"
    },
    {
      "x": -11,
      "y": 4,
      "z": -14,
      "name": "Soil_Dirt_Dry"
    },
    {
      "x": -11,
      "y": 5,
      "z": -14,
      "name": "Soil_Dirt_Dry"
    },
    {
      "x": -11,
      "y": 3,
      "z": -13,
      "name": "Soil_Dirt_Dry"
    },
    {
      "x": -11,
      "y": 4,
      "z": -13,
      "name": "Soil_Dirt_Dry"
    },
    {
      "x": -11,
      "y": 5,
      "z": -13,
      "name": "Soil_Dirt_Dry"
    },
    {
      "x": -11,
      "y": 3,
      "z": -12,
      "name": "Soil_Dirt_Dry"
    },
    {
      "x": -11,
      "y": 4,
      "z": -12,
      "name": "Soil_Dirt_Dry"
    },
    {
      "x": -11,
      "y": 5,
      "z": -12,
      "name": "Soil_Dirt_Dry"
    },
    {
      "x": -11,
      "y": 3,
      "z": -11,
      "name": "Soil_Dirt_Dry"
    },
    {
      "x": -11,
      "y": 4,
      "z": -11,
      "name": "Soil_Dirt_Dry"
    },
    {
      "x": -11,
      "y": 5,
      "z": -11,
      "name": "Soil_Dirt_Dry"
    },
    {
      "x": -11,
      "y": 3,
      "z": -10,
      "name": "Soil_Dirt_Dry"
    },
    {
      "x": -11,
      "y": 4,
      "z": -10,
      "name": "Soil_Dirt_Dry"
    },
    {
      "x": -11,
      "y": 5,
      "z": -10,
      "name": "Soil_Dirt_Dry"
    },
    {
      "x": -11,
      "y": 2,
      "z": -9,
      "name": "Soil_Dirt_Dry"
    },
    {
      "x": -11,
      "y": 3,
      "z": -9,
      "name": "Soil_Dirt_Dry"
    },
    {
      "x": -11,
      "y": 4,
      "z": -9,
      "name": "Soil_Dirt_Dry"
    },
    {
      "x": -11,
      "y": 5,
      "z": -9,
      "name": "Soil_Dirt_Dry"
    },
    {
      "x": -11,
      "y": 2,
      "z": -8,
      "name": "Soil_Dirt_Dry"
    },
    {
      "x": -11,
      "y": 3,
      "z": -8,
      "name": "Soil_Dirt_Dry"
    },
    {
      "x": -11,
      "y": 4,
      "z": -8,
      "name": "Soil_Dirt_Dry"
    },
    {
      "x": -11,
      "y": 5,
      "z": -8,
      "name": "Soil_Dirt_Dry"
    },
    {
      "x": -11,
      "y": 1,
      "z": -7,
      "name": "Soil_Dirt_Dry"
    },
    {
      "x": -11,
      "y": 2,
      "z": -7,
      "name": "Soil_Dirt_Dry"
    },
    {
      "x": -11,
      "y": 3,
      "z": -7,
      "name": "Soil_Dirt_Dry"
    },
    {
      "x": -11,
      "y": 4,
      "z": -7,
      "name": "Soil_Dirt_Dry"
    },
    {
      "x": -11,
      "y": 5,
      "z": -7,
      "name": "Soil_Dirt_Dry"
    },
    {
      "x": -11,
      "y": 1,
      "z": -6,
      "name": "Soil_Dirt_Dry"
    },
    {
      "x": -11,
      "y": 2,
      "z": -6,
      "name": "Soil_Dirt_Dry"
    },
    {
      "x": -11,
      "y": 3,
      "z": -6,
      "name": "Soil_Dirt_Dry"
    },
    {
      "x": -11,
      "y": 4,
      "z": -6,
      "name": "Soil_Dirt_Dry"
    },
    {
      "x": -11,
      "y": 5,
      "z": -6,
      "name": "Soil_Dirt_Dry"
    },
    {
      "x": -11,
      "y": 1,
      "z": -5,
      "name": "Soil_Dirt_Dry"
    },
    {
      "x": -11,
      "y": 2,
      "z": -5,
      "name": "Soil_Dirt_Dry"
    },
    {
      "x": -11,
      "y": 3,
      "z": -5,
      "name": "Soil_Dirt_Dry"
    },
    {
      "x": -11,
      "y": 4,
      "z": -5,
      "name": "Soil_Dirt_Dry"
    },
    {
      "x": -11,
      "y": 5,
      "z": -5,
      "name": "Soil_Dirt_Dry"
    },
    {
      "x": -11,
      "y": 2,
      "z": -4,
      "name": "Soil_Dirt_Dry"
    },
    {
      "x": -11,
      "y": 3,
      "z": -4,
      "name": "Soil_Dirt_Dry"
    },
    {
      "x": -11,
      "y": 4,
      "z": -4,
      "name": "Soil_Dirt_Dry"
    },
    {
      "x": -11,
      "y": 5,
      "z": -4,
      "name": "Soil_Dirt_Dry"
    },
    {
      "x": -11,
      "y": 2,
      "z": -3,
      "name": "Soil_Dirt_Dry"
    },
    {
      "x": -11,
      "y": 3,
      "z": -3,
      "name": "Soil_Dirt_Dry"
    },
    {
      "x": -11,
      "y": 4,
      "z": -3,
      "name": "Soil_Dirt_Dry"
    },
    {
      "x": -11,
      "y": 5,
      "z": -3,
      "name": "Soil_Dirt_Dry"
    },
    {
      "x": -11,
      "y": 2,
      "z": -2,
      "name": "Soil_Dirt_Dry"
    },
    {
      "x": -11,
      "y": 3,
      "z": -2,
      "name": "Soil_Dirt_Dry"
    },
    {
      "x": -11,
      "y": 4,
      "z": -2,
      "name": "Soil_Dirt_Dry"
    },
    {
      "x": -11,
      "y": 5,
      "z": -2,
      "name": "Soil_Dirt_Dry"
    },
    {
      "x": -11,
      "y": 2,
      "z": -1,
      "name": "Soil_Dirt_Dry"
    },
    {
      "x": -11,
      "y": 3,
      "z": -1,
      "name": "Soil_Dirt_Dry"
    },
    {
      "x": -11,
      "y": 4,
      "z": -1,
      "name": "Soil_Dirt_Dry"
    },
    {
      "x": -11,
      "y": 5,
      "z": -1,
      "name": "Soil_Dirt_Dry"
    },
    {
      "x": -11,
      "y": 2,
      "z": 0,
      "name": "Soil_Dirt_Dry"
    },
    {
      "x": -11,
      "y": 3,
      "z": 0,
      "name": "Soil_Dirt_Dry"
    },
    {
      "x": -11,
      "y": 4,
      "z": 0,
      "name": "Soil_Dirt_Dry"
    },
    {
      "x": -11,
      "y": 5,
      "z": 0,
      "name": "Soil_Dirt_Dry"
    },
    {
      "x": -11,
      "y": 1,
      "z": 1,
      "name": "Soil_Dirt_Dry"
    },
    {
      "x": -11,
      "y": 2,
      "z": 1,
      "name": "Soil_Dirt_Dry"
    },
    {
      "x": -11,
      "y": 3,
      "z": 1,
      "name": "Soil_Dirt_Dry"
    },
    {
      "x": -11,
      "y": 4,
      "z": 1,
      "name": "Soil_Dirt_Dry"
    },
    {
      "x": -11,
      "y": 5,
      "z": 1,
      "name": "Soil_Dirt_Dry"
    },
    {
      "x": -11,
      "y": 1,
      "z": 2,
      "name": "Soil_Dirt_Dry"
    },
    {
      "x": -11,
      "y": 2,
      "z": 2,
      "name": "Soil_Dirt_Dry"
    },
    {
      "x": -11,
      "y": 3,
      "z": 2,
      "name": "Soil_Dirt_Dry"
    },
    {
      "x": -11,
      "y": 4,
      "z": 2,
      "name": "Soil_Dirt_Dry"
    },
    {
      "x": -11,
      "y": 5,
      "z": 2,
      "name": "Soil_Dirt_Dry"
    },
    {
      "x": -11,
      "y": 6,
      "z": 2,
      "name": "Deco_Rope_Diagonal",
      "rotation": 3
    },
    {
      "x": -11,
      "y": 1,
      "z": 3,
      "name": "Soil_Dirt_Dry"
    },
    {
      "x": -11,
      "y": 2,
      "z": 3,
      "name": "Soil_Dirt_Dry"
    },
    {
      "x": -11,
      "y": 3,
      "z": 3,
      "name": "Soil_Dirt_Dry"
    },
    {
      "x": -11,
      "y": 4,
      "z": 3,
      "name": "Soil_Dirt_Dry"
    },
    {
      "x": -11,
      "y": 5,
      "z": 3,
      "name": "Soil_Dirt_Dry"
    },
    {
      "x": -11,
      "y": 2,
      "z": 4,
      "name": "Soil_Dirt_Dry"
    },
    {
      "x": -11,
      "y": 3,
      "z": 4,
      "name": "Soil_Dirt_Dry"
    },
    {
      "x": -11,
      "y": 4,
      "z": 4,
      "name": "Soil_Dirt_Dry"
    },
    {
      "x": -11,
      "y": 5,
      "z": 4,
      "name": "Soil_Dirt_Dry"
    },
    {
      "x": -11,
      "y": 2,
      "z": 5,
      "name": "Soil_Dirt_Dry"
    },
    {
      "x": -11,
      "y": 3,
      "z": 5,
      "name": "Soil_Dirt_Dry"
    },
    {
      "x": -11,
      "y": 4,
      "z": 5,
      "name": "Soil_Dirt_Dry"
    },
    {
      "x": -11,
      "y": 5,
      "z": 5,
      "name": "Soil_Dirt_Dry"
    },
    {
      "x": -11,
      "y": 6,
      "z": 5,
      "name": "Deco_Rope_Diagonal",
      "rotation": 3
    },
    {
      "x": -11,
      "y": 3,
      "z": 6,
      "name": "Soil_Dirt_Dry"
    },
    {
      "x": -11,
      "y": 4,
      "z": 6,
      "name": "Soil_Dirt_Dry"
    },
    {
      "x": -11,
      "y": 5,
      "z": 6,
      "name": "Soil_Dirt_Dry"
    },
    {
      "x": -11,
      "y": 3,
      "z": 7,
      "name": "Soil_Dirt_Dry"
    },
    {
      "x": -11,
      "y": 4,
      "z": 7,
      "name": "Soil_Dirt_Dry"
    },
    {
      "x": -11,
      "y": 5,
      "z": 7,
      "name": "Soil_Dirt_Dry"
    },
    {
      "x": -11,
      "y": 3,
      "z": 8,
      "name": "Soil_Dirt_Dry"
    },
    {
      "x": -11,
      "y": 4,
      "z": 8,
      "name": "Soil_Dirt_Dry"
    },
    {
      "x": -11,
      "y": 5,
      "z": 8,
      "name": "Soil_Dirt_Dry"
    },
    {
      "x": -11,
      "y": 3,
      "z": 9,
      "name": "Soil_Dirt_Dry"
    },
    {
      "x": -11,
      "y": 4,
      "z": 9,
      "name": "Soil_Dirt_Dry"
    },
    {
      "x": -11,
      "y": 5,
      "z": 9,
      "name": "Wood_Dry_Trunk",
      "support": 15
    },
    {
      "x": -11,
      "y": 6,
      "z": 9,
      "name": "Wood_Dry_Trunk",
      "support": 15
    },
    {
      "x": -11,
      "y": 7,
      "z": 9,
      "name": "Wood_Dry_Trunk",
      "support": 15
    },
    {
      "x": -11,
      "y": 8,
      "z": 9,
      "name": "Wood_Dry_Trunk",
      "support": 15
    },
    {
      "x": -11,
      "y": 9,
      "z": 9,
      "name": "Survival_Trap_Spike_Wood"
    },
    {
      "x": -11,
      "y": 3,
      "z": 10,
      "name": "Soil_Dirt_Dry"
    },
    {
      "x": -11,
      "y": 4,
      "z": 10,
      "name": "Soil_Dirt_Dry"
    },
    {
      "x": -11,
      "y": 7,
      "z": 10,
      "name": "Wood_Dry_Branch_Long",
      "support": 15,
      "rotation": 4
    },
    {
      "x": -11,
      "y": 3,
      "z": 11,
      "name": "Soil_Dirt_Dry"
    },
    {
      "x": -11,
      "y": 4,
      "z": 11,
      "name": "Soil_Dirt_Dry"
    },
    {
      "x": -11,
      "y": 3,
      "z": 12,
      "name": "Soil_Dirt_Dry"
    },
    {
      "x": -11,
      "y": 4,
      "z": 12,
      "name": "Soil_Dirt_Dry"
    },
    {
      "x": -11,
      "y": 2,
      "z": 13,
      "name": "Soil_Dirt_Dry"
    },
    {
      "x": -11,
      "y": 3,
      "z": 13,
      "name": "Soil_Dirt_Dry"
    },
    {
      "x": -11,
      "y": 4,
      "z": 13,
      "name": "Soil_Dirt_Dry"
    },
    {
      "x": -11,
      "y": 1,
      "z": 14,
      "name": "Soil_Dirt_Dry"
    },
    {
      "x": -11,
      "y": 2,
      "z": 14,
      "name": "Soil_Dirt_Dry"
    },
    {
      "x": -11,
      "y": 3,
      "z": 14,
      "name": "Soil_Dirt_Dry"
    },
    {
      "x": -11,
      "y": 4,
      "z": 14,
      "name": "Soil_Dirt_Dry"
    },
    {
      "x": -11,
      "y": 1,
      "z": 15,
      "name": "Soil_Dirt_Dry"
    },
    {
      "x": -11,
      "y": 2,
      "z": 15,
      "name": "Soil_Dirt_Dry"
    },
    {
      "x": -11,
      "y": 3,
      "z": 15,
      "name": "Soil_Dirt_Dry"
    },
    {
      "x": -11,
      "y": 4,
      "z": 15,
      "name": "Soil_Dirt_Dry"
    },
    {
      "x": -11,
      "y": 1,
      "z": 16,
      "name": "Soil_Dirt_Dry"
    },
    {
      "x": -11,
      "y": 2,
      "z": 16,
      "name": "Soil_Dirt_Dry"
    },
    {
      "x": -11,
      "y": 3,
      "z": 16,
      "name": "Soil_Dirt_Dry"
    },
    {
      "x": -11,
      "y": 1,
      "z": 17,
      "name": "Soil_Dirt_Dry"
    },
    {
      "x": -11,
      "y": 2,
      "z": 17,
      "name": "Soil_Dirt_Dry"
    },
    {
      "x": -11,
      "y": 1,
      "z": 18,
      "name": "Soil_Dirt_Dry"
    },
    {
      "x": -11,
      "y": 2,
      "z": 18,
      "name": "Soil_Dirt_Dry"
    },
    {
      "x": -11,
      "y": 3,
      "z": 18,
      "name": "Soil_Dirt_Dry"
    },
    {
      "x": -11,
      "y": 1,
      "z": 19,
      "name": "Soil_Dirt_Dry"
    },
    {
      "x": -11,
      "y": 2,
      "z": 19,
      "name": "Soil_Dirt_Dry"
    },
    {
      "x": -11,
      "y": 1,
      "z": 20,
      "name": "Soil_Dirt_Dry"
    },
    {
      "x": -11,
      "y": 2,
      "z": 20,
      "name": "Soil_Dirt_Dry"
    },
    {
      "x": -10,
      "y": 1,
      "z": -20,
      "name": "Soil_Dirt_Dry"
    },
    {
      "x": -10,
      "y": 2,
      "z": -20,
      "name": "Soil_Dirt_Dry"
    },
    {
      "x": -10,
      "y": 3,
      "z": -20,
      "name": "Soil_Dirt_Dry"
    },
    {
      "x": -10,
      "y": 1,
      "z": -19,
      "name": "Soil_Dirt_Dry"
    },
    {
      "x": -10,
      "y": 2,
      "z": -19,
      "name": "Soil_Dirt_Dry"
    },
    {
      "x": -10,
      "y": 3,
      "z": -19,
      "name": "Soil_Dirt_Dry"
    },
    {
      "x": -10,
      "y": 4,
      "z": -19,
      "name": "Soil_Dirt_Dry"
    },
    {
      "x": -10,
      "y": 1,
      "z": -18,
      "name": "Soil_Dirt_Dry"
    },
    {
      "x": -10,
      "y": 2,
      "z": -18,
      "name": "Soil_Dirt_Dry"
    },
    {
      "x": -10,
      "y": 3,
      "z": -18,
      "name": "Soil_Dirt_Dry"
    },
    {
      "x": -10,
      "y": 4,
      "z": -18,
      "name": "Soil_Dirt_Dry"
    },
    {
      "x": -10,
      "y": 1,
      "z": -17,
      "name": "Soil_Dirt_Dry"
    },
    {
      "x": -10,
      "y": 2,
      "z": -17,
      "name": "Soil_Dirt_Dry"
    },
    {
      "x": -10,
      "y": 3,
      "z": -17,
      "name": "Soil_Dirt_Dry"
    },
    {
      "x": -10,
      "y": 4,
      "z": -17,
      "name": "Soil_Dirt_Dry"
    },
    {
      "x": -10,
      "y": 1,
      "z": -16,
      "name": "Soil_Dirt_Dry"
    },
    {
      "x": -10,
      "y": 2,
      "z": -16,
      "name": "Soil_Dirt_Dry"
    },
    {
      "x": -10,
      "y": 3,
      "z": -16,
      "name": "Soil_Dirt_Dry"
    },
    {
      "x": -10,
      "y": 4,
      "z": -16,
      "name": "Soil_Dirt_Dry"
    },
    {
      "x": -10,
      "y": 5,
      "z": -16,
      "name": "Wood_Dry_Trunk",
      "support": 15
    },
    {
      "x": -10,
      "y": 6,
      "z": -16,
      "name": "Wood_Dry_Trunk",
      "support": 15
    },
    {
      "x": -10,
      "y": 7,
      "z": -16,
      "name": "Wood_Dry_Trunk",
      "support": 15
    },
    {
      "x": -10,
      "y": 8,
      "z": -16,
      "name": "Wood_Dry_Trunk",
      "support": 15
    },
    {
      "x": -10,
      "y": 9,
      "z": -16,
      "name": "Survival_Trap_Spike_Wood"
    },
    {
      "x": -10,
      "y": 1,
      "z": -15,
      "name": "Soil_Dirt_Dry"
    },
    {
      "x": -10,
      "y": 3,
      "z": -15,
      "name": "Soil_Dirt_Dry"
    },
    {
      "x": -10,
      "y": 4,
      "z": -15,
      "name": "Soil_Dirt_Dry"
    },
    {
      "x": -10,
      "y": 5,
      "z": -15,
      "name": "Soil_Dirt_Dry"
    },
    {
      "x": -10,
      "y": 3,
      "z": -14,
      "name": "Soil_Dirt_Dry"
    },
    {
      "x": -10,
      "y": 4,
      "z": -14,
      "name": "Soil_Dirt_Dry"
    },
    {
      "x": -10,
      "y": 5,
      "z": -14,
      "name": "Soil_Dirt_Dry"
    },
    {
      "x": -10,
      "y": 3,
      "z": -13,
      "name": "Soil_Dirt_Dry"
    },
    {
      "x": -10,
      "y": 4,
      "z": -13,
      "name": "Soil_Dirt_Dry"
    },
    {
      "x": -10,
      "y": 5,
      "z": -13,
      "name": "Soil_Dirt_Dry"
    },
    {
      "x": -10,
      "y": 3,
      "z": -12,
      "name": "Soil_Dirt_Dry"
    },
    {
      "x": -10,
      "y": 4,
      "z": -12,
      "name": "Soil_Dirt_Dry"
    },
    {
      "x": -10,
      "y": 5,
      "z": -12,
      "name": "Soil_Dirt_Dry"
    },
    {
      "x": -10,
      "y": 7,
      "z": -12,
      "name": "Wood_Dry_Branch_Corner",
      "support": 15,
      "rotation": 3
    },
    {
      "x": -10,
      "y": 8,
      "z": -12,
      "name": "Wood_Dry_Branch_Corner",
      "support": 15,
      "rotation": 11
    },
    {
      "x": -10,
      "y": 3,
      "z": -11,
      "name": "Soil_Dirt_Dry"
    },
    {
      "x": -10,
      "y": 4,
      "z": -11,
      "name": "Soil_Dirt_Dry"
    },
    {
      "x": -10,
      "y": 5,
      "z": -11,
      "name": "Soil_Dirt_Dry"
    },
    {
      "x": -10,
      "y": 2,
      "z": -10,
      "name": "Soil_Dirt_Dry"
    },
    {
      "x": -10,
      "y": 3,
      "z": -10,
      "name": "Soil_Dirt_Dry"
    },
    {
      "x": -10,
      "y": 4,
      "z": -10,
      "name": "Soil_Dirt_Dry"
    },
    {
      "x": -10,
      "y": 5,
      "z": -10,
      "name": "Soil_Dirt_Dry"
    },
    {
      "x": -10,
      "y": 2,
      "z": -9,
      "name": "Soil_Dirt_Dry"
    },
    {
      "x": -10,
      "y": 3,
      "z": -9,
      "name": "Soil_Dirt_Dry"
    },
    {
      "x": -10,
      "y": 4,
      "z": -9,
      "name": "Soil_Dirt_Dry"
    },
    {
      "x": -10,
      "y": 5,
      "z": -9,
      "name": "Soil_Dirt_Dry"
    },
    {
      "x": -10,
      "y": 1,
      "z": -8,
      "name": "Soil_Dirt_Dry"
    },
    {
      "x": -10,
      "y": 2,
      "z": -8,
      "name": "Soil_Dirt_Dry"
    },
    {
      "x": -10,
      "y": 3,
      "z": -8,
      "name": "Soil_Dirt_Dry"
    },
    {
      "x": -10,
      "y": 4,
      "z": -8,
      "name": "Soil_Dirt_Dry"
    },
    {
      "x": -10,
      "y": 5,
      "z": -8,
      "name": "Soil_Dirt_Dry"
    },
    {
      "x": -10,
      "y": 1,
      "z": -7,
      "name": "Soil_Dirt_Dry"
    },
    {
      "x": -10,
      "y": 2,
      "z": -7,
      "name": "Soil_Dirt_Dry"
    },
    {
      "x": -10,
      "y": 3,
      "z": -7,
      "name": "Soil_Dirt_Dry"
    },
    {
      "x": -10,
      "y": 4,
      "z": -7,
      "name": "Soil_Dirt_Dry"
    },
    {
      "x": -10,
      "y": 5,
      "z": -7,
      "name": "Soil_Dirt_Dry"
    },
    {
      "x": -10,
      "y": 1,
      "z": -6,
      "name": "Soil_Dirt_Dry"
    },
    {
      "x": -10,
      "y": 3,
      "z": -6,
      "name": "Soil_Dirt_Dry"
    },
    {
      "x": -10,
      "y": 4,
      "z": -6,
      "name": "Soil_Dirt_Dry"
    },
    {
      "x": -10,
      "y": 5,
      "z": -6,
      "name": "Soil_Dirt_Dry"
    },
    {
      "x": -10,
      "y": 1,
      "z": -5,
      "name": "Soil_Dirt_Dry"
    },
    {
      "x": -10,
      "y": 2,
      "z": -5,
      "name": "Soil_Dirt_Dry"
    },
    {
      "x": -10,
      "y": 3,
      "z": -5,
      "name": "Soil_Dirt_Dry"
    },
    {
      "x": -10,
      "y": 4,
      "z": -5,
      "name": "Soil_Dirt_Dry"
    },
    {
      "x": -10,
      "y": 5,
      "z": -5,
      "name": "Soil_Dirt_Dry"
    },
    {
      "x": -10,
      "y": 1,
      "z": -4,
      "name": "Soil_Dirt_Dry"
    },
    {
      "x": -10,
      "y": 2,
      "z": -4,
      "name": "Soil_Dirt_Dry"
    },
    {
      "x": -10,
      "y": 3,
      "z": -4,
      "name": "Soil_Dirt_Dry"
    },
    {
      "x": -10,
      "y": 4,
      "z": -4,
      "name": "Soil_Dirt_Dry"
    },
    {
      "x": -10,
      "y": 5,
      "z": -4,
      "name": "Soil_Dirt_Dry"
    },
    {
      "x": -10,
      "y": 1,
      "z": -3,
      "name": "Soil_Dirt_Dry"
    },
    {
      "x": -10,
      "y": 2,
      "z": -3,
      "name": "Soil_Dirt_Dry"
    },
    {
      "x": -10,
      "y": 3,
      "z": -3,
      "name": "Soil_Dirt_Dry"
    },
    {
      "x": -10,
      "y": 4,
      "z": -3,
      "name": "Soil_Dirt_Dry"
    },
    {
      "x": -10,
      "y": 5,
      "z": -3,
      "name": "Soil_Dirt_Dry"
    },
    {
      "x": -10,
      "y": 1,
      "z": -2,
      "name": "Soil_Dirt_Dry"
    },
    {
      "x": -10,
      "y": 2,
      "z": -2,
      "name": "Soil_Dirt_Dry"
    },
    {
      "x": -10,
      "y": 3,
      "z": -2,
      "name": "Soil_Dirt_Dry"
    },
    {
      "x": -10,
      "y": 4,
      "z": -2,
      "name": "Soil_Dirt_Dry"
    },
    {
      "x": -10,
      "y": 5,
      "z": -2,
      "name": "Soil_Dirt_Dry"
    },
    {
      "x": -10,
      "y": 1,
      "z": -1,
      "name": "Soil_Dirt_Dry"
    },
    {
      "x": -10,
      "y": 2,
      "z": -1,
      "name": "Soil_Dirt_Dry"
    },
    {
      "x": -10,
      "y": 3,
      "z": -1,
      "name": "Soil_Dirt_Dry"
    },
    {
      "x": -10,
      "y": 4,
      "z": -1,
      "name": "Soil_Dirt_Dry"
    },
    {
      "x": -10,
      "y": 5,
      "z": -1,
      "name": "Soil_Dirt_Dry"
    },
    {
      "x": -10,
      "y": 1,
      "z": 0,
      "name": "Soil_Dirt_Dry"
    },
    {
      "x": -10,
      "y": 2,
      "z": 0,
      "name": "Soil_Dirt_Dry"
    },
    {
      "x": -10,
      "y": 3,
      "z": 0,
      "name": "Soil_Dirt_Dry"
    },
    {
      "x": -10,
      "y": 4,
      "z": 0,
      "name": "Soil_Dirt_Dry"
    },
    {
      "x": -10,
      "y": 5,
      "z": 0,
      "name": "Soil_Dirt_Dry"
    },
    {
      "x": -10,
      "y": 1,
      "z": 1,
      "name": "Soil_Dirt_Dry"
    },
    {
      "x": -10,
      "y": 2,
      "z": 1,
      "name": "Soil_Dirt_Dry"
    },
    {
      "x": -10,
      "y": 3,
      "z": 1,
      "name": "Soil_Dirt_Dry"
    },
    {
      "x": -10,
      "y": 4,
      "z": 1,
      "name": "Soil_Dirt_Dry"
    },
    {
      "x": -10,
      "y": 5,
      "z": 1,
      "name": "Soil_Dirt_Dry"
    },
    {
      "x": -10,
      "y": 6,
      "z": 1,
      "name": "Wood_Dry_Trunk",
      "support": 15,
      "rotation": 4
    },
    {
      "x": -10,
      "y": 1,
      "z": 2,
      "name": "Soil_Dirt_Dry"
    },
    {
      "x": -10,
      "y": 2,
      "z": 2,
      "name": "Soil_Dirt_Dry"
    },
    {
      "x": -10,
      "y": 3,
      "z": 2,
      "name": "Soil_Dirt_Dry"
    },
    {
      "x": -10,
      "y": 4,
      "z": 2,
      "name": "Soil_Dirt_Dry"
    },
    {
      "x": -10,
      "y": 5,
      "z": 2,
      "name": "Soil_Dirt_Dry"
    },
    {
      "x": -10,
      "y": 6,
      "z": 2,
      "name": "Wood_Dry_Trunk",
      "support": 15,
      "rotation": 4
    },
    {
      "x": -10,
      "y": 7,
      "z": 2,
      "name": "Deco_Rope_Diagonal",
      "rotation": 3
    },
    {
      "x": -10,
      "y": 1,
      "z": 3,
      "name": "Soil_Dirt_Dry"
    },
    {
      "x": -10,
      "y": 2,
      "z": 3,
      "name": "Soil_Dirt_Dry"
    },
    {
      "x": -10,
      "y": 3,
      "z": 3,
      "name": "Soil_Dirt_Dry"
    },
    {
      "x": -10,
      "y": 4,
      "z": 3,
      "name": "Soil_Dirt_Dry"
    },
    {
      "x": -10,
      "y": 5,
      "z": 3,
      "name": "Soil_Dirt_Dry"
    },
    {
      "x": -10,
      "y": 6,
      "z": 3,
      "name": "Wood_Dry_Trunk",
      "support": 15,
      "rotation": 4
    },
    {
      "x": -10,
      "y": 2,
      "z": 4,
      "name": "Soil_Dirt_Dry"
    },
    {
      "x": -10,
      "y": 3,
      "z": 4,
      "name": "Soil_Dirt_Dry"
    },
    {
      "x": -10,
      "y": 4,
      "z": 4,
      "name": "Soil_Dirt_Dry"
    },
    {
      "x": -10,
      "y": 5,
      "z": 4,
      "name": "Soil_Dirt_Dry"
    },
    {
      "x": -10,
      "y": 6,
      "z": 4,
      "name": "Wood_Dry_Trunk",
      "support": 15,
      "rotation": 4
    },
    {
      "x": -10,
      "y": 2,
      "z": 5,
      "name": "Soil_Dirt_Dry"
    },
    {
      "x": -10,
      "y": 3,
      "z": 5,
      "name": "Soil_Dirt_Dry"
    },
    {
      "x": -10,
      "y": 4,
      "z": 5,
      "name": "Soil_Dirt_Dry"
    },
    {
      "x": -10,
      "y": 5,
      "z": 5,
      "name": "Soil_Dirt_Dry"
    },
    {
      "x": -10,
      "y": 6,
      "z": 5,
      "name": "Wood_Dry_Trunk",
      "support": 15,
      "rotation": 4
    },
    {
      "x": -10,
      "y": 7,
      "z": 5,
      "name": "Deco_Rope_Diagonal",
      "rotation": 3
    },
    {
      "x": -10,
      "y": 3,
      "z": 6,
      "name": "Soil_Dirt_Dry"
    },
    {
      "x": -10,
      "y": 4,
      "z": 6,
      "name": "Soil_Dirt_Dry"
    },
    {
      "x": -10,
      "y": 5,
      "z": 6,
      "name": "Soil_Dirt_Dry"
    },
    {
      "x": -10,
      "y": 6,
      "z": 6,
      "name": "Wood_Dry_Trunk",
      "support": 15,
      "rotation": 4
    },
    {
      "x": -10,
      "y": 3,
      "z": 7,
      "name": "Soil_Dirt_Dry"
    },
    {
      "x": -10,
      "y": 4,
      "z": 7,
      "name": "Soil_Dirt_Dry"
    },
    {
      "x": -10,
      "y": 5,
      "z": 7,
      "name": "Soil_Dirt_Dry"
    },
    {
      "x": -10,
      "y": 3,
      "z": 8,
      "name": "Soil_Dirt_Dry"
    },
    {
      "x": -10,
      "y": 4,
      "z": 8,
      "name": "Soil_Dirt_Dry"
    },
    {
      "x": -10,
      "y": 5,
      "z": 8,
      "name": "Soil_Dirt_Dry"
    },
    {
      "x": -10,
      "y": 3,
      "z": 9,
      "name": "Soil_Dirt_Dry"
    },
    {
      "x": -10,
      "y": 4,
      "z": 9,
      "name": "Soil_Dirt_Dry"
    },
    {
      "x": -10,
      "y": 5,
      "z": 9,
      "name": "Soil_Dirt_Dry"
    },
    {
      "x": -10,
      "y": 3,
      "z": 10,
      "name": "Soil_Dirt_Dry"
    },
    {
      "x": -10,
      "y": 4,
      "z": 10,
      "name": "Soil_Dirt_Dry"
    },
    {
      "x": -10,
      "y": 5,
      "z": 10,
      "name": "Soil_Dirt_Dry"
    },
    {
      "x": -10,
      "y": 3,
      "z": 11,
      "name": "Soil_Dirt_Dry"
    },
    {
      "x": -10,
      "y": 4,
      "z": 11,
      "name": "Soil_Dirt_Dry"
    },
    {
      "x": -10,
      "y": 5,
      "z": 11,
      "name": "Wood_Dry_Trunk",
      "support": 15
    },
    {
      "x": -10,
      "y": 6,
      "z": 11,
      "name": "Wood_Dry_Trunk",
      "support": 15
    },
    {
      "x": -10,
      "y": 7,
      "z": 11,
      "name": "Wood_Dry_Trunk",
      "support": 15
    },
    {
      "x": -10,
      "y": 8,
      "z": 11,
      "name": "Wood_Dry_Trunk",
      "support": 15
    },
    {
      "x": -10,
      "y": 9,
      "z": 11,
      "name": "Survival_Trap_Spike_Wood"
    },
    {
      "x": -10,
      "y": 3,
      "z": 12,
      "name": "Soil_Dirt_Dry"
    },
    {
      "x": -10,
      "y": 4,
      "z": 12,
      "name": "Soil_Dirt_Dry"
    },
    {
      "x": -10,
      "y": 7,
      "z": 12,
      "name": "Wood_Dry_Branch_Long",
      "support": 15,
      "rotation": 4
    },
    {
      "x": -10,
      "y": 1,
      "z": 13,
      "name": "Soil_Dirt_Dry"
    },
    {
      "x": -10,
      "y": 2,
      "z": 13,
      "name": "Soil_Dirt_Dry"
    },
    {
      "x": -10,
      "y": 3,
      "z": 13,
      "name": "Soil_Dirt_Dry"
    },
    {
      "x": -10,
      "y": 4,
      "z": 13,
      "name": "Soil_Dirt_Dry"
    },
    {
      "x": -10,
      "y": 1,
      "z": 14,
      "name": "Soil_Dirt_Dry"
    },
    {
      "x": -10,
      "y": 2,
      "z": 14,
      "name": "Soil_Dirt_Dry"
    },
    {
      "x": -10,
      "y": 3,
      "z": 14,
      "name": "Soil_Dirt_Dry"
    },
    {
      "x": -10,
      "y": 4,
      "z": 14,
      "name": "Soil_Dirt_Dry"
    },
    {
      "x": -10,
      "y": 1,
      "z": 15,
      "name": "Soil_Dirt_Dry"
    },
    {
      "x": -10,
      "y": 2,
      "z": 15,
      "name": "Soil_Dirt_Dry"
    },
    {
      "x": -10,
      "y": 3,
      "z": 15,
      "name": "Soil_Dirt_Dry"
    },
    {
      "x": -10,
      "y": 4,
      "z": 15,
      "name": "Soil_Dirt_Dry"
    },
    {
      "x": -10,
      "y": 1,
      "z": 16,
      "name": "Soil_Dirt_Dry"
    },
    {
      "x": -10,
      "y": 2,
      "z": 16,
      "name": "Soil_Dirt_Dry"
    },
    {
      "x": -10,
      "y": 3,
      "z": 16,
      "name": "Soil_Dirt_Dry"
    },
    {
      "x": -10,
      "y": 4,
      "z": 16,
      "name": "Soil_Dirt_Dry"
    },
    {
      "x": -10,
      "y": 2,
      "z": 17,
      "name": "Soil_Dirt_Dry"
    },
    {
      "x": -10,
      "y": 3,
      "z": 17,
      "name": "Soil_Dirt_Dry"
    },
    {
      "x": -10,
      "y": 4,
      "z": 17,
      "name": "Rubble_Sandstone",
      "support": 15
    },
    {
      "x": -10,
      "y": 2,
      "z": 18,
      "name": "Soil_Dirt_Dry"
    },
    {
      "x": -10,
      "y": 3,
      "z": 18,
      "name": "Soil_Dirt_Dry"
    },
    {
      "x": -10,
      "y": 2,
      "z": 19,
      "name": "Soil_Dirt_Dry"
    },
    {
      "x": -10,
      "y": 3,
      "z": 19,
      "name": "Soil_Dirt_Dry"
    },
    {
      "x": -10,
      "y": 2,
      "z": 20,
      "name": "Soil_Dirt_Dry"
    },
    {
      "x": -10,
      "y": 3,
      "z": 20,
      "name": "Soil_Dirt_Dry"
    },
    {
      "x": -9,
      "y": 2,
      "z": -20,
      "name": "Soil_Dirt_Dry"
    },
    {
      "x": -9,
      "y": 3,
      "z": -20,
      "name": "Soil_Dirt_Dry"
    },
    {
      "x": -9,
      "y": 4,
      "z": -20,
      "name": "Soil_Dirt_Dry"
    },
    {
      "x": -9,
      "y": 1,
      "z": -19,
      "name": "Soil_Dirt_Dry"
    },
    {
      "x": -9,
      "y": 2,
      "z": -19,
      "name": "Soil_Dirt_Dry"
    },
    {
      "x": -9,
      "y": 3,
      "z": -19,
      "name": "Soil_Dirt_Dry"
    },
    {
      "x": -9,
      "y": 4,
      "z": -19,
      "name": "Soil_Dirt_Dry"
    },
    {
      "x": -9,
      "y": 1,
      "z": -18,
      "name": "Soil_Dirt_Dry"
    },
    {
      "x": -9,
      "y": 2,
      "z": -18,
      "name": "Soil_Dirt_Dry"
    },
    {
      "x": -9,
      "y": 3,
      "z": -18,
      "name": "Soil_Dirt_Dry"
    },
    {
      "x": -9,
      "y": 4,
      "z": -18,
      "name": "Soil_Dirt_Dry"
    },
    {
      "x": -9,
      "y": 1,
      "z": -17,
      "name": "Soil_Dirt_Dry"
    },
    {
      "x": -9,
      "y": 2,
      "z": -17,
      "name": "Soil_Dirt_Dry"
    },
    {
      "x": -9,
      "y": 3,
      "z": -17,
      "name": "Soil_Dirt_Dry"
    },
    {
      "x": -9,
      "y": 4,
      "z": -17,
      "name": "Soil_Dirt_Dry"
    },
    {
      "x": -9,
      "y": 5,
      "z": -17,
      "name": "Soil_Dirt_Dry"
    },
    {
      "x": -9,
      "y": 7,
      "z": -17,
      "name": "Wood_Dry_Branch_Long",
      "support": 15,
      "rotation": 5
    },
    {
      "x": -9,
      "y": 1,
      "z": -16,
      "name": "Soil_Dirt_Dry"
    },
    {
      "x": -9,
      "y": 2,
      "z": -16,
      "name": "Soil_Dirt_Dry"
    },
    {
      "x": -9,
      "y": 3,
      "z": -16,
      "name": "Soil_Dirt_Dry"
    },
    {
      "x": -9,
      "y": 4,
      "z": -16,
      "name": "Soil_Dirt_Dry"
    },
    {
      "x": -9,
      "y": 5,
      "z": -16,
      "name": "Soil_Dirt_Dry"
    },
    {
      "x": -9,
      "y": 1,
      "z": -15,
      "name": "Soil_Dirt_Dry"
    },
    {
      "x": -9,
      "y": 2,
      "z": -15,
      "name": "Soil_Dirt_Dry"
    },
    {
      "x": -9,
      "y": 3,
      "z": -15,
      "name": "Soil_Dirt_Dry"
    },
    {
      "x": -9,
      "y": 4,
      "z": -15,
      "name": "Soil_Dirt_Dry"
    },
    {
      "x": -9,
      "y": 5,
      "z": -15,
      "name": "Soil_Dirt_Dry"
    },
    {
      "x": -9,
      "y": 1,
      "z": -14,
      "name": "Soil_Dirt_Dry"
    },
    {
      "x": -9,
      "y": 2,
      "z": -14,
      "name": "Soil_Dirt_Dry"
    },
    {
      "x": -9,
      "y": 3,
      "z": -14,
      "name": "Soil_Dirt_Dry"
    },
    {
      "x": -9,
      "y": 4,
      "z": -14,
      "name": "Soil_Dirt_Dry"
    },
    {
      "x": -9,
      "y": 5,
      "z": -14,
      "name": "Soil_Dirt_Dry"
    },
    {
      "x": -9,
      "y": 2,
      "z": -13,
      "name": "Soil_Dirt_Dry"
    },
    {
      "x": -9,
      "y": 3,
      "z": -13,
      "name": "Soil_Dirt_Dry"
    },
    {
      "x": -9,
      "y": 4,
      "z": -13,
      "name": "Soil_Dirt_Dry"
    },
    {
      "x": -9,
      "y": 5,
      "z": -13,
      "name": "Soil_Dirt_Dry"
    },
    {
      "x": -9,
      "y": 2,
      "z": -12,
      "name": "Soil_Dirt_Dry"
    },
    {
      "x": -9,
      "y": 3,
      "z": -12,
      "name": "Soil_Dirt_Dry"
    },
    {
      "x": -9,
      "y": 4,
      "z": -12,
      "name": "Soil_Dirt_Dry"
    },
    {
      "x": -9,
      "y": 5,
      "z": -12,
      "name": "Soil_Dirt_Dry"
    },
    {
      "x": -9,
      "y": 7,
      "z": -12,
      "name": "Wood_Dry_Branch_Long",
      "support": 15,
      "rotation": 5
    },
    {
      "x": -9,
      "y": 2,
      "z": -11,
      "name": "Soil_Dirt_Dry"
    },
    {
      "x": -9,
      "y": 3,
      "z": -11,
      "name": "Soil_Dirt_Dry"
    },
    {
      "x": -9,
      "y": 4,
      "z": -11,
      "name": "Soil_Dirt_Dry"
    },
    {
      "x": -9,
      "y": 5,
      "z": -11,
      "name": "Soil_Dirt_Dry"
    },
    {
      "x": -9,
      "y": 2,
      "z": -10,
      "name": "Soil_Dirt_Dry"
    },
    {
      "x": -9,
      "y": 3,
      "z": -10,
      "name": "Soil_Dirt_Dry"
    },
    {
      "x": -9,
      "y": 4,
      "z": -10,
      "name": "Soil_Dirt_Dry"
    },
    {
      "x": -9,
      "y": 5,
      "z": -10,
      "name": "Soil_Dirt_Dry"
    },
    {
      "x": -9,
      "y": 1,
      "z": -9,
      "name": "Soil_Dirt_Dry"
    },
    {
      "x": -9,
      "y": 2,
      "z": -9,
      "name": "Soil_Dirt_Dry"
    },
    {
      "x": -9,
      "y": 3,
      "z": -9,
      "name": "Soil_Dirt_Dry"
    },
    {
      "x": -9,
      "y": 4,
      "z": -9,
      "name": "Soil_Dirt_Dry"
    },
    {
      "x": -9,
      "y": 5,
      "z": -9,
      "name": "Soil_Dirt_Dry"
    },
    {
      "x": -9,
      "y": 1,
      "z": -8,
      "name": "Soil_Dirt_Dry"
    },
    {
      "x": -9,
      "y": 2,
      "z": -8,
      "name": "Soil_Dirt_Dry"
    },
    {
      "x": -9,
      "y": 3,
      "z": -8,
      "name": "Soil_Dirt_Dry"
    },
    {
      "x": -9,
      "y": 4,
      "z": -8,
      "name": "Soil_Dirt_Dry"
    },
    {
      "x": -9,
      "y": 5,
      "z": -8,
      "name": "Soil_Dirt_Dry"
    },
    {
      "x": -9,
      "y": 1,
      "z": -7,
      "name": "Soil_Dirt_Dry"
    },
    {
      "x": -9,
      "y": 3,
      "z": -7,
      "name": "Soil_Dirt_Dry"
    },
    {
      "x": -9,
      "y": 4,
      "z": -7,
      "name": "Soil_Dirt_Dry"
    },
    {
      "x": -9,
      "y": 5,
      "z": -7,
      "name": "Soil_Dirt_Dry"
    },
    {
      "x": -9,
      "y": 3,
      "z": -6,
      "name": "Soil_Dirt_Dry"
    },
    {
      "x": -9,
      "y": 4,
      "z": -6,
      "name": "Soil_Dirt_Dry"
    },
    {
      "x": -9,
      "y": 5,
      "z": -6,
      "name": "Soil_Dirt_Dry"
    },
    {
      "x": -9,
      "y": 3,
      "z": -5,
      "name": "Soil_Dirt_Dry"
    },
    {
      "x": -9,
      "y": 4,
      "z": -5,
      "name": "Soil_Dirt_Dry"
    },
    {
      "x": -9,
      "y": 5,
      "z": -5,
      "name": "Soil_Dirt_Dry"
    },
    {
      "x": -9,
      "y": 1,
      "z": -4,
      "name": "Soil_Dirt_Dry"
    },
    {
      "x": -9,
      "y": 3,
      "z": -4,
      "name": "Soil_Dirt_Dry"
    },
    {
      "x": -9,
      "y": 4,
      "z": -4,
      "name": "Soil_Dirt_Dry"
    },
    {
      "x": -9,
      "y": 5,
      "z": -4,
      "name": "Soil_Dirt_Dry"
    },
    {
      "x": -9,
      "y": 1,
      "z": -3,
      "name": "Soil_Dirt_Dry"
    },
    {
      "x": -9,
      "y": 2,
      "z": -3,
      "name": "Soil_Dirt_Dry"
    },
    {
      "x": -9,
      "y": 3,
      "z": -3,
      "name": "Soil_Dirt_Dry"
    },
    {
      "x": -9,
      "y": 4,
      "z": -3,
      "name": "Soil_Dirt_Dry"
    },
    {
      "x": -9,
      "y": 5,
      "z": -3,
      "name": "Soil_Dirt_Dry"
    },
    {
      "x": -9,
      "y": 1,
      "z": -2,
      "name": "Soil_Dirt_Dry"
    },
    {
      "x": -9,
      "y": 2,
      "z": -2,
      "name": "Soil_Dirt_Dry"
    },
    {
      "x": -9,
      "y": 3,
      "z": -2,
      "name": "Soil_Dirt_Dry"
    },
    {
      "x": -9,
      "y": 4,
      "z": -2,
      "name": "Soil_Dirt_Dry"
    },
    {
      "x": -9,
      "y": 5,
      "z": -2,
      "name": "Soil_Dirt_Dry"
    },
    {
      "x": -9,
      "y": 1,
      "z": -1,
      "name": "Soil_Dirt_Dry"
    },
    {
      "x": -9,
      "y": 2,
      "z": -1,
      "name": "Soil_Dirt_Dry"
    },
    {
      "x": -9,
      "y": 3,
      "z": -1,
      "name": "Soil_Dirt_Dry"
    },
    {
      "x": -9,
      "y": 4,
      "z": -1,
      "name": "Soil_Dirt_Dry"
    },
    {
      "x": -9,
      "y": 5,
      "z": -1,
      "name": "Soil_Dirt_Dry"
    },
    {
      "x": -9,
      "y": 1,
      "z": 0,
      "name": "Soil_Dirt_Dry"
    },
    {
      "x": -9,
      "y": 3,
      "z": 0,
      "name": "Soil_Dirt_Dry"
    },
    {
      "x": -9,
      "y": 4,
      "z": 0,
      "name": "Soil_Dirt_Dry"
    },
    {
      "x": -9,
      "y": 5,
      "z": 0,
      "name": "Soil_Dirt_Dry"
    },
    {
      "x": -9,
      "y": 6,
      "z": 0,
      "name": "Bench_Lumbermill",
      "filler": 31
    },
    {
      "x": -9,
      "y": 3,
      "z": 1,
      "name": "Soil_Dirt_Dry"
    },
    {
      "x": -9,
      "y": 4,
      "z": 1,
      "name": "Soil_Dirt_Dry"
    },
    {
      "x": -9,
      "y": 5,
      "z": 1,
      "name": "Soil_Dirt_Dry"
    },
    {
      "x": -9,
      "y": 6,
      "z": 1,
      "name": "Wood_Dry_Trunk",
      "support": 15,
      "rotation": 4
    },
    {
      "x": -9,
      "y": 7,
      "z": 1,
      "name": "Wood_Dry_Trunk",
      "support": 15,
      "rotation": 4
    },
    {
      "x": -9,
      "y": 1,
      "z": 2,
      "name": "Soil_Dirt_Dry"
    },
    {
      "x": -9,
      "y": 2,
      "z": 2,
      "name": "Soil_Dirt_Dry"
    },
    {
      "x": -9,
      "y": 3,
      "z": 2,
      "name": "Soil_Dirt_Dry"
    },
    {
      "x": -9,
      "y": 4,
      "z": 2,
      "name": "Soil_Dirt_Dry"
    },
    {
      "x": -9,
      "y": 5,
      "z": 2,
      "name": "Soil_Dirt_Dry"
    },
    {
      "x": -9,
      "y": 6,
      "z": 2,
      "name": "Wood_Dry_Trunk",
      "support": 15,
      "rotation": 4
    },
    {
      "x": -9,
      "y": 7,
      "z": 2,
      "name": "Wood_Dry_Trunk",
      "support": 15,
      "rotation": 4
    },
    {
      "x": -9,
      "y": 1,
      "z": 3,
      "name": "Soil_Dirt_Dry"
    },
    {
      "x": -9,
      "y": 2,
      "z": 3,
      "name": "Soil_Dirt_Dry"
    },
    {
      "x": -9,
      "y": 3,
      "z": 3,
      "name": "Soil_Dirt_Dry"
    },
    {
      "x": -9,
      "y": 4,
      "z": 3,
      "name": "Soil_Dirt_Dry"
    },
    {
      "x": -9,
      "y": 5,
      "z": 3,
      "name": "Soil_Dirt_Dry"
    },
    {
      "x": -9,
      "y": 6,
      "z": 3,
      "name": "Wood_Dry_Trunk",
      "support": 15,
      "rotation": 4
    },
    {
      "x": -9,
      "y": 7,
      "z": 3,
      "name": "Wood_Dry_Trunk",
      "support": 15,
      "rotation": 4
    },
    {
      "x": -9,
      "y": 2,
      "z": 4,
      "name": "Soil_Dirt_Dry"
    },
    {
      "x": -9,
      "y": 3,
      "z": 4,
      "name": "Soil_Dirt_Dry"
    },
    {
      "x": -9,
      "y": 4,
      "z": 4,
      "name": "Soil_Dirt_Dry"
    },
    {
      "x": -9,
      "y": 5,
      "z": 4,
      "name": "Soil_Dirt_Dry"
    },
    {
      "x": -9,
      "y": 6,
      "z": 4,
      "name": "Wood_Dry_Trunk",
      "support": 15,
      "rotation": 4
    },
    {
      "x": -9,
      "y": 7,
      "z": 4,
      "name": "Wood_Dry_Trunk",
      "support": 15,
      "rotation": 4
    },
    {
      "x": -9,
      "y": 2,
      "z": 5,
      "name": "Soil_Dirt_Dry"
    },
    {
      "x": -9,
      "y": 3,
      "z": 5,
      "name": "Soil_Dirt_Dry"
    },
    {
      "x": -9,
      "y": 4,
      "z": 5,
      "name": "Soil_Dirt_Dry"
    },
    {
      "x": -9,
      "y": 5,
      "z": 5,
      "name": "Soil_Dirt_Dry"
    },
    {
      "x": -9,
      "y": 6,
      "z": 5,
      "name": "Wood_Dry_Trunk",
      "support": 15,
      "rotation": 4
    },
    {
      "x": -9,
      "y": 7,
      "z": 5,
      "name": "Wood_Dry_Trunk",
      "support": 15,
      "rotation": 4
    },
    {
      "x": -9,
      "y": 3,
      "z": 6,
      "name": "Soil_Dirt_Dry"
    },
    {
      "x": -9,
      "y": 4,
      "z": 6,
      "name": "Soil_Dirt_Dry"
    },
    {
      "x": -9,
      "y": 5,
      "z": 6,
      "name": "Soil_Dirt_Dry"
    },
    {
      "x": -9,
      "y": 6,
      "z": 6,
      "name": "Wood_Dry_Trunk",
      "support": 15,
      "rotation": 4
    },
    {
      "x": -9,
      "y": 7,
      "z": 6,
      "name": "Wood_Dry_Trunk",
      "support": 15,
      "rotation": 4
    },
    {
      "x": -9,
      "y": 3,
      "z": 7,
      "name": "Soil_Dirt_Dry"
    },
    {
      "x": -9,
      "y": 4,
      "z": 7,
      "name": "Soil_Dirt_Dry"
    },
    {
      "x": -9,
      "y": 5,
      "z": 7,
      "name": "Soil_Dirt_Dry"
    },
    {
      "x": -9,
      "y": 3,
      "z": 8,
      "name": "Soil_Dirt_Dry"
    },
    {
      "x": -9,
      "y": 4,
      "z": 8,
      "name": "Soil_Dirt_Dry"
    },
    {
      "x": -9,
      "y": 5,
      "z": 8,
      "name": "Soil_Dirt_Dry"
    },
    {
      "x": -9,
      "y": 3,
      "z": 9,
      "name": "Soil_Dirt_Dry"
    },
    {
      "x": -9,
      "y": 4,
      "z": 9,
      "name": "Soil_Dirt_Dry"
    },
    {
      "x": -9,
      "y": 5,
      "z": 9,
      "name": "Soil_Dirt_Dry"
    },
    {
      "x": -9,
      "y": 3,
      "z": 10,
      "name": "Soil_Dirt_Dry"
    },
    {
      "x": -9,
      "y": 4,
      "z": 10,
      "name": "Soil_Dirt_Dry"
    },
    {
      "x": -9,
      "y": 5,
      "z": 10,
      "name": "Soil_Dirt_Dry"
    },
    {
      "x": -9,
      "y": 3,
      "z": 11,
      "name": "Soil_Dirt_Dry"
    },
    {
      "x": -9,
      "y": 4,
      "z": 11,
      "name": "Soil_Dirt_Dry"
    },
    {
      "x": -9,
      "y": 5,
      "z": 11,
      "name": "Soil_Dirt_Dry"
    },
    {
      "x": -9,
