{
  "version": 8,
  "blockIdVersion": 11,
  "anchorX": 0,
  "anchorY": 0,
  "anchorZ": 0,
  "blocks": [
    {
      "x": -38,
      "y": 0,
      "z": -15,
      "name": "Soil_Pathway"
    },
    {
      "x": -38,
      "y": 0,
      "z": -14,
      "name": "Soil_Pathway"
    },
    {
      "x": -38,
      "y": 0,
      "z": -13,
      "name": "Soil_Pathway"
    },
    {
      "x": -38,
      "y": 0,
      "z": -12,
      "name": "Soil_Pathway"
    },
    {
      "x": -38,
      "y": 0,
      "z": -11,
      "name": "Soil_Pathway"
    },
    {
      "x": -38,
      "y": 0,
      "z": -10,
      "name": "Soil_Pathway"
    },
    {
      "x": -38,
      "y": 0,
      "z": -9,
      "name": "Soil_Pathway"
    },
    {
      "x": -38,
      "y": 0,
      "z": -8,
      "name": "Soil_Pathway"
    },
    {
      "x": -38,
      "y": 0,
      "z": -7,
      "name": "Soil_Pathway"
    },
    {
      "x": -38,
      "y": 0,
      "z": -6,
      "name": "Soil_Pathway"
    },
    {
      "x": -38,
      "y": 0,
      "z": -5,
      "name": "Soil_Pathway"
    },
    {
      "x": -38,
      "y": 0,
      "z": -4,
      "name": "Soil_Pathway"
    },
    {
      "x": -38,
      "y": 0,
      "z": -3,
      "name": "Soil_Pathway"
    },
    {
      "x": -38,
      "y": 0,
      "z": -2,
      "name": "Soil_Pathway"
    },
    {
      "x": -38,
      "y": 0,
      "z": -1,
      "name": "Soil_Pathway"
    },
    {
      "x": -38,
      "y": 0,
      "z": 0,
      "name": "Soil_Pathway"
    },
    {
      "x": -38,
      "y": 0,
      "z": 1,
      "name": "Soil_Pathway"
    },
    {
      "x": -38,
      "y": 0,
      "z": 2,
      "name": "Soil_Pathway"
    },
    {
      "x": -38,
      "y": 0,
      "z": 3,
      "name": "Soil_Pathway"
    },
    {
      "x": -38,
      "y": 0,
      "z": 4,
      "name": "Soil_Pathway"
    },
    {
      "x": -38,
      "y": 0,
      "z": 5,
      "name": "Soil_Pathway"
    },
    {
      "x": -38,
      "y": 0,
      "z": 6,
      "name": "Soil_Pathway"
    },
    {
      "x": -38,
      "y": 0,
      "z": 7,
      "name": "Soil_Pathway"
    },
    {
      "x": -38,
      "y": 0,
      "z": 8,
      "name": "Soil_Pathway"
    },
    {
      "x": -38,
      "y": 0,
      "z": 9,
      "name": "Soil_Pathway"
    },
    {
      "x": -38,
      "y": 0,
      "z": 10,
      "name": "Soil_Pathway"
    },
    {
      "x": -38,
      "y": 0,
      "z": 11,
      "name": "Soil_Pathway"
    },
    {
      "x": -37,
      "y": 0,
      "z": -17,
      "name": "Soil_Pathway"
    },
    {
      "x": -37,
      "y": 0,
      "z": -16,
      "name": "Soil_Pathway"
    },
    {
      "x": -37,
      "y": 0,
      "z": -15,
      "name": "Soil_Pathway"
    },
    {
      "x": -37,
      "y": 0,
      "z": -14,
      "name": "Soil_Pathway"
    },
    {
      "x": -37,
      "y": 0,
      "z": -13,
      "name": "Soil_Pathway"
    },
    {
      "x": -37,
      "y": 0,
      "z": -12,
      "name": "Soil_Pathway"
    },
    {
      "x": -37,
      "y": 1,
      "z": -12,
      "name": "Soil_Dirt_Dry"
    },
    {
      "x": -37,
      "y": 0,
      "z": -11,
      "name": "Soil_Pathway"
    },
    {
      "x": -37,
      "y": 1,
      "z": -11,
      "name": "Soil_Dirt_Dry"
    },
    {
      "x": -37,
      "y": 0,
      "z": -10,
      "name": "Soil_Pathway"
    },
    {
      "x": -37,
      "y": 1,
      "z": -10,
      "name": "Soil_Dirt_Dry"
    },
    {
      "x": -37,
      "y": 0,
      "z": -9,
      "name": "Soil_Pathway"
    },
    {
      "x": -37,
      "y": 1,
      "z": -9,
      "name": "Soil_Dirt_Dry"
    },
    {
      "x": -37,
      "y": 0,
      "z": -8,
      "name": "Soil_Pathway"
    },
    {
      "x": -37,
      "y": 1,
      "z": -8,
      "name": "Soil_Dirt_Dry"
    },
    {
      "x": -37,
      "y": 0,
      "z": -7,
      "name": "Soil_Pathway"
    },
    {
      "x": -37,
      "y": 1,
      "z": -7,
      "name": "Soil_Dirt_Dry"
    },
    {
      "x": -37,
      "y": 0,
      "z": -6,
      "name": "Soil_Pathway"
    },
    {
      "x": -37,
      "y": 1,
      "z": -6,
      "name": "Soil_Dirt_Dry"
    },
    {
      "x": -37,
      "y": 0,
      "z": -5,
      "name": "Soil_Pathway"
    },
    {
      "x": -37,
      "y": 0,
      "z": -4,
      "name": "Soil_Pathway"
    },
    {
      "x": -37,
      "y": 0,
      "z": -3,
      "name": "Soil_Pathway"
    },
    {
      "x": -37,
      "y": 0,
      "z": -2,
      "name": "Soil_Pathway"
    },
    {
      "x": -37,
      "y": 0,
      "z": -1,
      "name": "Soil_Pathway"
    },
    {
      "x": -37,
      "y": 0,
      "z": 0,
      "name": "Soil_Pathway"
    },
    {
      "x": -37,
      "y": 0,
      "z": 1,
      "name": "Soil_Pathway"
    },
    {
      "x": -37,
      "y": 0,
      "z": 2,
      "name": "Soil_Pathway"
    },
    {
      "x": -37,
      "y": 0,
      "z": 3,
      "name": "Soil_Pathway"
    },
    {
      "x": -37,
      "y": 0,
      "z": 4,
      "name": "Soil_Pathway"
    },
    {
      "x": -37,
      "y": 0,
      "z": 5,
      "name": "Soil_Pathway"
    },
    {
      "x": -37,
      "y": 0,
      "z": 6,
      "name": "Soil_Pathway"
    },
    {
      "x": -37,
      "y": 0,
      "z": 7,
      "name": "Soil_Pathway"
    },
    {
      "x": -37,
      "y": 0,
      "z": 8,
      "name": "Soil_Pathway"
    },
    {
      "x": -37,
      "y": 0,
      "z": 9,
      "name": "Soil_Pathway"
    },
    {
      "x": -37,
      "y": 0,
      "z": 10,
      "name": "Soil_Pathway"
    },
    {
      "x": -37,
      "y": 0,
      "z": 11,
      "name": "Soil_Pathway"
    },
    {
      "x": -37,
      "y": 0,
      "z": 12,
      "name": "Soil_Pathway"
    },
    {
      "x": -37,
      "y": 0,
      "z": 13,
      "name": "Soil_Pathway"
    },
    {
      "x": -36,
      "y": 0,
      "z": -18,
      "name": "Soil_Pathway"
    },
    {
      "x": -36,
      "y": 0,
      "z": -17,
      "name": "Soil_Pathway"
    },
    {
      "x": -36,
      "y": 0,
      "z": -16,
      "name": "Soil_Dirt_Dry"
    },
    {
      "x": -36,
      "y": 1,
      "z": -16,
      "name": "Soil_Dirt_Dry"
    },
    {
      "x": -36,
      "y": 0,
      "z": -15,
      "name": "Soil_Dirt_Dry"
    },
    {
      "x": -36,
      "y": 1,
      "z": -15,
      "name": "Soil_Dirt_Dry"
    },
    {
      "x": -36,
      "y": 0,
      "z": -14,
      "name": "Soil_Dirt_Dry"
    },
    {
      "x": -36,
      "y": 1,
      "z": -14,
      "name": "Soil_Dirt_Dry"
    },
    {
      "x": -36,
      "y": 0,
      "z": -13,
      "name": "Soil_Dirt_Dry"
    },
    {
      "x": -36,
      "y": 1,
      "z": -13,
      "name": "Soil_Dirt_Dry"
    },
    {
      "x": -36,
      "y": 0,
      "z": -12,
      "name": "Soil_Pathway"
    },
    {
      "x": -36,
      "y": 1,
      "z": -12,
      "name": "Soil_Dirt_Dry"
    },
    {
      "x": -36,
      "y": 0,
      "z": -11,
      "name": "Soil_Pathway"
    },
    {
      "x": -36,
      "y": 1,
      "z": -11,
      "name": "Soil_Dirt_Dry"
    },
    {
      "x": -36,
      "y": 0,
      "z": -10,
      "name": "Soil_Dirt_Dry"
    },
    {
      "x": -36,
      "y": 1,
      "z": -10,
      "name": "Soil_Dirt_Dry"
    },
    {
      "x": -36,
      "y": 0,
      "z": -9,
      "name": "Soil_Dirt_Dry"
    },
    {
      "x": -36,
      "y": 1,
      "z": -9,
      "name": "Soil_Dirt_Dry"
    },
    {
      "x": -36,
      "y": 0,
      "z": -8,
      "name": "Soil_Dirt_Dry"
    },
    {
      "x": -36,
      "y": 1,
      "z": -8,
      "name": "Soil_Dirt_Dry"
    },
    {
      "x": -36,
      "y": 0,
      "z": -7,
      "name": "Soil_Pathway"
    },
    {
      "x": -36,
      "y": 1,
      "z": -7,
      "name": "Soil_Dirt_Dry"
    },
    {
      "x": -36,
      "y": 0,
      "z": -6,
      "name": "Soil_Pathway"
    },
    {
      "x": -36,
      "y": 1,
      "z": -6,
      "name": "Soil_Dirt_Dry"
    },
    {
      "x": -36,
      "y": 0,
      "z": -5,
      "name": "Soil_Pathway"
    },
    {
      "x": -36,
      "y": 1,
      "z": -5,
      "name": "Soil_Dirt_Dry"
    },
    {
      "x": -36,
      "y": 0,
      "z": -4,
      "name": "Soil_Pathway"
    },
    {
      "x": -36,
      "y": 0,
      "z": -3,
      "name": "Soil_Pathway"
    },
    {
      "x": -36,
      "y": 0,
      "z": -2,
      "name": "Soil_Pathway"
    },
    {
      "x": -36,
      "y": 0,
      "z": -1,
      "name": "Soil_Pathway"
    },
    {
      "x": -36,
      "y": 0,
      "z": 0,
      "name": "Soil_Pathway"
    },
    {
      "x": -36,
      "y": 0,
      "z": 1,
      "name": "Soil_Pathway"
    },
    {
      "x": -36,
      "y": 0,
      "z": 2,
      "name": "Soil_Pathway"
    },
    {
      "x": -36,
      "y": 0,
      "z": 3,
      "name": "Soil_Pathway"
    },
    {
      "x": -36,
      "y": 0,
      "z": 4,
      "name": "Soil_Pathway"
    },
    {
      "x": -36,
      "y": 0,
      "z": 5,
      "name": "Soil_Pathway"
    },
    {
      "x": -36,
      "y": 0,
      "z": 6,
      "name": "Soil_Pathway"
    },
    {
      "x": -36,
      "y": 0,
      "z": 7,
      "name": "Soil_Pathway"
    },
    {
      "x": -36,
      "y": 0,
      "z": 8,
      "name": "Soil_Pathway"
    },
    {
      "x": -36,
      "y": 0,
      "z": 9,
      "name": "Soil_Pathway"
    },
    {
      "x": -36,
      "y": 0,
      "z": 10,
      "name": "Soil_Pathway"
    },
    {
      "x": -36,
      "y": 0,
      "z": 11,
      "name": "Soil_Pathway"
    },
    {
      "x": -36,
      "y": 0,
      "z": 12,
      "name": "Soil_Pathway"
    },
    {
      "x": -36,
      "y": 0,
      "z": 13,
      "name": "Soil_Pathway"
    },
    {
      "x": -36,
      "y": 0,
      "z": 14,
      "name": "Soil_Pathway"
    },
    {
      "x": -35,
      "y": 0,
      "z": -19,
      "name": "Soil_Pathway"
    },
    {
      "x": -35,
      "y": 0,
      "z": -18,
      "name": "Soil_Pathway"
    },
    {
      "x": -35,
      "y": 0,
      "z": -17,
      "name": "Soil_Pathway"
    },
    {
      "x": -35,
      "y": 0,
      "z": -16,
      "name": "Soil_Dirt_Dry"
    },
    {
      "x": -35,
      "y": 1,
      "z": -16,
      "name": "Soil_Dirt_Dry"
    },
    {
      "x": -35,
      "y": 0,
      "z": -15,
      "name": "Soil_Dirt_Dry"
    },
    {
      "x": -35,
      "y": 1,
      "z": -15,
      "name": "Soil_Dirt_Dry"
    },
    {
      "x": -35,
      "y": 0,
      "z": -14,
      "name": "Soil_Dirt_Dry"
    },
    {
      "x": -35,
      "y": 1,
      "z": -14,
      "name": "Soil_Dirt_Dry"
    },
    {
      "x": -35,
      "y": 8,
      "z": -14,
      "name": "*Cloth_Roof_Leather_State_Definitions_Corner_Left",
      "rotation": 2
    },
    {
      "x": -35,
      "y": 0,
      "z": -13,
      "name": "Soil_Pathway"
    },
    {
      "x": -35,
      "y": 2,
      "z": -13,
      "name": "Soil_Dirt_Dry"
    },
    {
      "x": -35,
      "y": 8,
      "z": -13,
      "name": "Cloth_Roof_Leather",
      "rotation": 3
    },
    {
      "x": -35,
      "y": 0,
      "z": -12,
      "name": "Soil_Dirt_Dry"
    },
    {
      "x": -35,
      "y": 1,
      "z": -12,
      "name": "Soil_Dirt_Dry"
    },
    {
      "x": -35,
      "y": 2,
      "z": -12,
      "name": "Soil_Dirt_Dry"
    },
    {
      "x": -35,
      "y": 8,
      "z": -12,
      "name": "Cloth_Roof_Leather",
      "rotation": 3
    },
    {
      "x": -35,
      "y": 0,
      "z": -11,
      "name": "Soil_Pathway"
    },
    {
      "x": -35,
      "y": 1,
      "z": -11,
      "name": "Soil_Dirt_Dry"
    },
    {
      "x": -35,
      "y": 2,
      "z": -11,
      "name": "Soil_Dirt_Dry"
    },
    {
      "x": -35,
      "y": 8,
      "z": -11,
      "name": "Cloth_Roof_Leather",
      "rotation": 3
    },
    {
      "x": -35,
      "y": 0,
      "z": -10,
      "name": "Soil_Dirt_Dry"
    },
    {
      "x": -35,
      "y": 1,
      "z": -10,
      "name": "Soil_Dirt_Dry"
    },
    {
      "x": -35,
      "y": 8,
      "z": -10,
      "name": "Cloth_Roof_Leather",
      "rotation": 3
    },
    {
      "x": -35,
      "y": 0,
      "z": -9,
      "name": "Soil_Pathway"
    },
    {
      "x": -35,
      "y": 1,
      "z": -9,
      "name": "Soil_Dirt_Dry"
    },
    {
      "x": -35,
      "y": 8,
      "z": -9,
      "name": "Cloth_Roof_Leather",
      "rotation": 3
    },
    {
      "x": -35,
      "y": 0,
      "z": -8,
      "name": "Soil_Dirt_Dry"
    },
    {
      "x": -35,
      "y": 1,
      "z": -8,
      "name": "Soil_Dirt_Dry"
    },
    {
      "x": -35,
      "y": 8,
      "z": -8,
      "name": "Cloth_Roof_Leather",
      "rotation": 3
    },
    {
      "x": -35,
      "y": 0,
      "z": -7,
      "name": "Soil_Dirt_Dry"
    },
    {
      "x": -35,
      "y": 1,
      "z": -7,
      "name": "Soil_Dirt_Dry"
    },
    {
      "x": -35,
      "y": 8,
      "z": -7,
      "name": "Cloth_Roof_Leather",
      "rotation": 3
    },
    {
      "x": -35,
      "y": 0,
      "z": -6,
      "name": "Soil_Dirt_Dry"
    },
    {
      "x": -35,
      "y": 1,
      "z": -6,
      "name": "Soil_Dirt_Dry"
    },
    {
      "x": -35,
      "y": 8,
      "z": -6,
      "name": "Cloth_Roof_Leather",
      "rotation": 3
    },
    {
      "x": -35,
      "y": 0,
      "z": -5,
      "name": "Soil_Pathway"
    },
    {
      "x": -35,
      "y": 1,
      "z": -5,
      "name": "Soil_Dirt_Dry"
    },
    {
      "x": -35,
      "y": 8,
      "z": -5,
      "name": "Cloth_Roof_Leather",
      "rotation": 3
    },
    {
      "x": -35,
      "y": 0,
      "z": -4,
      "name": "Soil_Pathway"
    },
    {
      "x": -35,
      "y": 1,
      "z": -4,
      "name": "Soil_Dirt_Dry"
    },
    {
      "x": -35,
      "y": 8,
      "z": -4,
      "name": "*Cloth_Roof_Leather_State_Definitions_Corner_Left",
      "rotation": 3
    },
    {
      "x": -35,
      "y": 0,
      "z": -3,
      "name": "Soil_Pathway"
    },
    {
      "x": -35,
      "y": 0,
      "z": -2,
      "name": "Soil_Pathway"
    },
    {
      "x": -35,
      "y": 0,
      "z": -1,
      "name": "Soil_Pathway"
    },
    {
      "x": -35,
      "y": 0,
      "z": 0,
      "name": "Soil_Pathway"
    },
    {
      "x": -35,
      "y": 0,
      "z": 1,
      "name": "Soil_Pathway"
    },
    {
      "x": -35,
      "y": 0,
      "z": 2,
      "name": "Soil_Pathway"
    },
    {
      "x": -35,
      "y": 0,
      "z": 3,
      "name": "Soil_Pathway"
    },
    {
      "x": -35,
      "y": 0,
      "z": 4,
      "name": "Soil_Pathway"
    },
    {
      "x": -35,
      "y": 0,
      "z": 5,
      "name": "Soil_Pathway"
    },
    {
      "x": -35,
      "y": 0,
      "z": 6,
      "name": "Soil_Pathway"
    },
    {
      "x": -35,
      "y": 0,
      "z": 7,
      "name": "Soil_Pathway"
    },
    {
      "x": -35,
      "y": 0,
      "z": 8,
      "name": "Soil_Pathway"
    },
    {
      "x": -35,
      "y": 0,
      "z": 9,
      "name": "Soil_Pathway"
    },
    {
      "x": -35,
      "y": 0,
      "z": 10,
      "name": "Soil_Pathway"
    },
    {
      "x": -35,
      "y": 0,
      "z": 11,
      "name": "Soil_Pathway"
    },
    {
      "x": -35,
      "y": 0,
      "z": 12,
      "name": "Soil_Pathway"
    },
    {
      "x": -35,
      "y": 0,
      "z": 13,
      "name": "Soil_Pathway"
    },
    {
      "x": -35,
      "y": 0,
      "z": 14,
      "name": "Soil_Pathway"
    },
    {
      "x": -34,
      "y": 0,
      "z": -20,
      "name": "Soil_Pathway"
    },
    {
      "x": -34,
      "y": 0,
      "z": -19,
      "name": "Soil_Dirt_Dry"
    },
    {
      "x": -34,
      "y": 1,
      "z": -19,
      "name": "Soil_Dirt_Dry"
    },
    {
      "x": -34,
      "y": 0,
      "z": -18,
      "name": "Soil_Dirt_Dry"
    },
    {
      "x": -34,
      "y": 1,
      "z": -18,
      "name": "Soil_Dirt_Dry"
    },
    {
      "x": -34,
      "y": 0,
      "z": -17,
      "name": "Soil_Dirt_Dry"
    },
    {
      "x": -34,
      "y": 1,
      "z": -17,
      "name": "Soil_Dirt_Dry"
    },
    {
      "x": -34,
      "y": 0,
      "z": -16,
      "name": "Soil_Dirt_Dry"
    },
    {
      "x": -34,
      "y": 1,
      "z": -16,
      "name": "Soil_Dirt_Dry"
    },
    {
      "x": -34,
      "y": 2,
      "z": -16,
      "name": "Soil_Dirt_Dry"
    },
    {
      "x": -34,
      "y": 0,
      "z": -15,
      "name": "Soil_Dirt_Dry"
    },
    {
      "x": -34,
      "y": 1,
      "z": -15,
      "name": "Soil_Dirt_Dry"
    },
    {
      "x": -34,
      "y": 2,
      "z": -15,
      "name": "Soil_Dirt_Dry"
    },
    {
      "x": -34,
      "y": 0,
      "z": -14,
      "name": "Soil_Pathway"
    },
    {
      "x": -34,
      "y": 2,
      "z": -14,
      "name": "Soil_Dirt_Dry"
    },
    {
      "x": -34,
      "y": 8,
      "z": -14,
      "name": "Cloth_Roof_Leather",
      "rotation": 2
    },
    {
      "x": -34,
      "y": 0,
      "z": -13,
      "name": "Soil_Dirt_Dry"
    },
    {
      "x": -34,
      "y": 1,
      "z": -13,
      "name": "Soil_Dirt_Dry"
    },
    {
      "x": -34,
      "y": 2,
      "z": -13,
      "name": "Soil_Dirt_Dry"
    },
    {
      "x": -34,
      "y": 3,
      "z": -13,
      "name": "Wood_Gumboab_Trunk",
      "rotation": 3
    },
    {
      "x": -34,
      "y": 4,
      "z": -13,
      "name": "Wood_Gumboab_Trunk",
      "rotation": 3
    },
    {
      "x": -34,
      "y": 5,
      "z": -13,
      "name": "Wood_Gumboab_Trunk",
      "rotation": 3
    },
    {
      "x": -34,
      "y": 6,
      "z": -13,
      "name": "Wood_Gumboab_Trunk",
      "rotation": 3
    },
    {
      "x": -34,
      "y": 7,
      "z": -13,
      "name": "Wood_Gumboab_Trunk",
      "rotation": 3
    },
    {
      "x": -34,
      "y": 8,
      "z": -13,
      "name": "Wood_Gumboab_Trunk",
      "rotation": 7
    },
    {
      "x": -34,
      "y": 9,
      "z": -13,
      "name": "Wood_Gumboab_Trunk",
      "rotation": 3
    },
    {
      "x": -34,
      "y": 10,
      "z": -13,
      "name": "Wood_Gumboab_Branch_Long",
      "rotation": 3
    },
    {
      "x": -34,
      "y": 11,
      "z": -13,
      "name": "Survival_Trap_Spike_Wood_Large",
      "rotation": 3
    },
    {
      "x": -34,
      "y": 0,
      "z": -12,
      "name": "Soil_Dirt_Dry"
    },
    {
      "x": -34,
      "y": 1,
      "z": -12,
      "name": "Soil_Dirt_Dry"
    },
    {
      "x": -34,
      "y": 2,
      "z": -12,
      "name": "Soil_Dirt_Dry"
    },
    {
      "x": -34,
      "y": 8,
      "z": -12,
      "name": "Wood_Gumboab_Trunk",
      "rotation": 4
    },
    {
      "x": -34,
      "y": 9,
      "z": -12,
      "name": "Cloth_Roof_Leather",
      "rotation": 3
    },
    {
      "x": -34,
      "y": 0,
      "z": -11,
      "name": "Soil_Dirt_Dry"
    },
    {
      "x": -34,
      "y": 1,
      "z": -11,
      "name": "Soil_Dirt_Dry"
    },
    {
      "x": -34,
      "y": 2,
      "z": -11,
      "name": "Soil_Dirt_Dry"
    },
    {
      "x": -34,
      "y": 8,
      "z": -11,
      "name": "Wood_Gumboab_Trunk",
      "rotation": 4
    },
    {
      "x": -34,
      "y": 9,
      "z": -11,
      "name": "Cloth_Roof_Leather",
      "rotation": 3
    },
    {
      "x": -34,
      "y": 0,
      "z": -10,
      "name": "Soil_Dirt_Dry"
    },
    {
      "x": -34,
      "y": 1,
      "z": -10,
      "name": "Soil_Dirt_Dry"
    },
    {
      "x": -34,
      "y": 2,
      "z": -10,
      "name": "Soil_Dirt_Dry"
    },
    {
      "x": -34,
      "y": 8,
      "z": -10,
      "name": "Wood_Gumboab_Trunk",
      "rotation": 4
    },
    {
      "x": -34,
      "y": 9,
      "z": -10,
      "name": "Cloth_Roof_Leather",
      "rotation": 3
    },
    {
      "x": -34,
      "y": 0,
      "z": -9,
      "name": "Soil_Pathway"
    },
    {
      "x": -34,
      "y": 1,
      "z": -9,
      "name": "Soil_Dirt_Dry"
    },
    {
      "x": -34,
      "y": 2,
      "z": -9,
      "name": "Soil_Dirt_Dry"
    },
    {
      "x": -34,
      "y": 8,
      "z": -9,
      "name": "Wood_Gumboab_Trunk",
      "rotation": 4
    },
    {
      "x": -34,
      "y": 9,
      "z": -9,
      "name": "Cloth_Roof_Leather",
      "rotation": 3
    },
    {
      "x": -34,
      "y": 0,
      "z": -8,
      "name": "Soil_Dirt_Dry"
    },
    {
      "x": -34,
      "y": 1,
      "z": -8,
      "name": "Soil_Dirt_Dry"
    },
    {
      "x": -34,
      "y": 2,
      "z": -8,
      "name": "Soil_Dirt_Dry"
    },
    {
      "x": -34,
      "y": 8,
      "z": -8,
      "name": "Wood_Gumboab_Trunk",
      "rotation": 4
    },
    {
      "x": -34,
      "y": 9,
      "z": -8,
      "name": "Cloth_Roof_Leather",
      "rotation": 3
    },
    {
      "x": -34,
      "y": 0,
      "z": -7,
      "name": "Soil_Dirt_Dry"
    },
    {
      "x": -34,
      "y": 1,
      "z": -7,
      "name": "Soil_Dirt_Dry"
    },
    {
      "x": -34,
      "y": 8,
      "z": -7,
      "name": "Wood_Gumboab_Trunk",
      "rotation": 4
    },
    {
      "x": -34,
      "y": 9,
      "z": -7,
      "name": "Cloth_Roof_Leather",
      "rotation": 3
    },
    {
      "x": -34,
      "y": 0,
      "z": -6,
      "name": "Soil_Dirt_Dry"
    },
    {
      "x": -34,
      "y": 1,
      "z": -6,
      "name": "Soil_Dirt_Dry"
    },
    {
      "x": -34,
      "y": 8,
      "z": -6,
      "name": "Wood_Gumboab_Trunk",
      "rotation": 4
    },
    {
      "x": -34,
      "y": 9,
      "z": -6,
      "name": "Cloth_Roof_Leather",
      "rotation": 3
    },
    {
      "x": -34,
      "y": 0,
      "z": -5,
      "name": "Soil_Dirt_Dry"
    },
    {
      "x": -34,
      "y": 1,
      "z": -5,
      "name": "Soil_Dirt_Dry"
    },
    {
      "x": -34,
      "y": 2,
      "z": -5,
      "name": "Wood_Gumboab_Trunk",
      "support": 15
    },
    {
      "x": -34,
      "y": 3,
      "z": -5,
      "name": "Wood_Gumboab_Trunk",
      "rotation": 3
    },
    {
      "x": -34,
      "y": 4,
      "z": -5,
      "name": "Wood_Gumboab_Trunk",
      "rotation": 3
    },
    {
      "x": -34,
      "y": 5,
      "z": -5,
      "name": "Wood_Gumboab_Trunk",
      "rotation": 3
    },
    {
      "x": -34,
      "y": 6,
      "z": -5,
      "name": "Wood_Gumboab_Trunk",
      "rotation": 3
    },
    {
      "x": -34,
      "y": 7,
      "z": -5,
      "name": "Wood_Gumboab_Trunk",
      "rotation": 3
    },
    {
      "x": -34,
      "y": 8,
      "z": -5,
      "name": "Wood_Gumboab_Trunk",
      "rotation": 7
    },
    {
      "x": -34,
      "y": 9,
      "z": -5,
      "name": "Wood_Gumboab_Trunk",
      "rotation": 3
    },
    {
      "x": -34,
      "y": 10,
      "z": -5,
      "name": "Wood_Gumboab_Branch_Long",
      "rotation": 3
    },
    {
      "x": -34,
      "y": 11,
      "z": -5,
      "name": "Survival_Trap_Spike_Wood_Large",
      "rotation": 3
    },
    {
      "x": -34,
      "y": 0,
      "z": -4,
      "name": "Soil_Pathway"
    },
    {
      "x": -34,
      "y": 1,
      "z": -4,
      "name": "Soil_Dirt_Dry"
    },
    {
      "x": -34,
      "y": 8,
      "z": -4,
      "name": "Cloth_Roof_Leather"
    },
    {
      "x": -34,
      "y": 0,
      "z": -3,
      "name": "Soil_Pathway"
    },
    {
      "x": -34,
      "y": 1,
      "z": -3,
      "name": "Soil_Dirt_Dry"
    },
    {
      "x": -34,
      "y": 0,
      "z": -2,
      "name": "Soil_Pathway"
    },
    {
      "x": -34,
      "y": 0,
      "z": -1,
      "name": "Soil_Pathway"
    },
    {
      "x": -34,
      "y": 0,
      "z": 0,
      "name": "Soil_Pathway"
    },
    {
      "x": -34,
      "y": 0,
      "z": 1,
      "name": "Soil_Pathway"
    },
    {
      "x": -34,
      "y": 0,
      "z": 2,
      "name": "Soil_Pathway"
    },
    {
      "x": -34,
      "y": 0,
      "z": 3,
      "name": "Soil_Pathway"
    },
    {
      "x": -34,
      "y": 0,
      "z": 4,
      "name": "Soil_Pathway"
    },
    {
      "x": -34,
      "y": 0,
      "z": 5,
      "name": "Soil_Pathway"
    },
    {
      "x": -34,
      "y": 0,
      "z": 6,
      "name": "Soil_Pathway"
    },
    {
      "x": -34,
      "y": 0,
      "z": 7,
      "name": "Soil_Pathway"
    },
    {
      "x": -34,
      "y": 0,
      "z": 8,
      "name": "Soil_Pathway"
    },
    {
      "x": -34,
      "y": 0,
      "z": 9,
      "name": "Soil_Pathway"
    },
    {
      "x": -34,
      "y": 0,
      "z": 10,
      "name": "Soil_Pathway"
    },
    {
      "x": -34,
      "y": 0,
      "z": 11,
      "name": "Soil_Pathway"
    },
    {
      "x": -34,
      "y": 0,
      "z": 12,
      "name": "Soil_Pathway"
    },
    {
      "x": -34,
      "y": 0,
      "z": 13,
      "name": "Soil_Pathway"
    },
    {
      "x": -34,
      "y": 0,
      "z": 14,
      "name": "Soil_Pathway"
    },
    {
      "x": -34,
      "y": 0,
      "z": 15,
      "name": "Soil_Pathway"
    },
    {
      "x": -33,
      "y": 0,
      "z": -22,
      "name": "Soil_Pathway"
    },
    {
      "x": -33,
      "y": 0,
      "z": -21,
      "name": "Soil_Pathway"
    },
    {
      "x": -33,
      "y": 0,
      "z": -20,
      "name": "Soil_Dirt_Dry"
    },
    {
      "x": -33,
      "y": 1,
      "z": -20,
      "name": "Soil_Dirt_Dry"
    },
    {
      "x": -33,
      "y": 0,
      "z": -19,
      "name": "Soil_Dirt_Dry"
    },
    {
      "x": -33,
      "y": 1,
      "z": -19,
      "name": "Soil_Dirt_Dry"
    },
    {
      "x": -33,
      "y": 0,
      "z": -18,
      "name": "Soil_Dirt_Dry"
    },
    {
      "x": -33,
      "y": 1,
      "z": -18,
      "name": "Soil_Dirt_Dry"
    },
    {
      "x": -33,
      "y": 2,
      "z": -18,
      "name": "Soil_Dirt_Dry"
    },
    {
      "x": -33,
      "y": 0,
      "z": -17,
      "name": "Soil_Dirt_Dry"
    },
    {
      "x": -33,
      "y": 1,
      "z": -17,
      "name": "Soil_Dirt_Dry"
    },
    {
      "x": -33,
      "y": 2,
      "z": -17,
      "name": "Soil_Dirt_Dry"
    },
    {
      "x": -33,
      "y": 0,
      "z": -16,
      "name": "Soil_Dirt_Dry"
    },
    {
      "x": -33,
      "y": 1,
      "z": -16,
      "name": "Soil_Dirt_Dry"
    },
    {
      "x": -33,
      "y": 2,
      "z": -16,
      "name": "Soil_Dirt_Dry"
    },
    {
      "x": -33,
      "y": 0,
      "z": -15,
      "name": "Soil_Dirt_Dry"
    },
    {
      "x": -33,
      "y": 1,
      "z": -15,
      "name": "Soil_Dirt_Dry"
    },
    {
      "x": -33,
      "y": 2,
      "z": -15,
      "name": "Soil_Dirt_Dry"
    },
    {
      "x": -33,
      "y": 0,
      "z": -14,
      "name": "Soil_Pathway"
    },
    {
      "x": -33,
      "y": 1,
      "z": -14,
      "name": "Plant_Grass_Arid_Short"
    },
    {
      "x": -33,
      "y": 2,
      "z": -14,
      "name": "Soil_Dirt_Dry"
    },
    {
      "x": -33,
      "y": 8,
      "z": -14,
      "name": "Cloth_Roof_Leather",
      "rotation": 2
    },
    {
      "x": -33,
      "y": 0,
      "z": -13,
      "name": "Soil_Dirt_Dry"
    },
    {
      "x": -33,
      "y": 1,
      "z": -13,
      "name": "Soil_Dirt_Dry"
    },
    {
      "x": -33,
      "y": 2,
      "z": -13,
      "name": "Soil_Dirt_Dry"
    },
    {
      "x": -33,
      "y": 8,
      "z": -13,
      "name": "Wood_Gumboab_Trunk",
      "rotation": 7
    },
    {
      "x": -33,
      "y": 9,
      "z": -13,
      "name": "Cloth_Roof_Leather",
      "support": 15,
      "rotation": 2
    },
    {
      "x": -33,
      "y": 0,
      "z": -12,
      "name": "Soil_Dirt_Dry"
    },
    {
      "x": -33,
      "y": 1,
      "z": -12,
      "name": "Soil_Dirt_Dry"
    },
    {
      "x": -33,
      "y": 2,
      "z": -12,
      "name": "Soil_Dirt_Dry"
    },
    {
      "x": -33,
      "y": 10,
      "z": -12,
      "name": "Cloth_Roof_Leather_Flat",
      "rotation": 3
    },
    {
      "x": -33,
      "y": 0,
      "z": -11,
      "name": "Soil_Dirt_Dry"
    },
    {
      "x": -33,
      "y": 1,
      "z": -11,
      "name": "Soil_Dirt_Dry"
    },
    {
      "x": -33,
      "y": 2,
      "z": -11,
      "name": "Soil_Dirt_Dry"
    },
    {
      "x": -33,
      "y": 10,
      "z": -11,
      "name": "Cloth_Roof_Leather_Flat",
      "rotation": 3
    },
    {
      "x": -33,
      "y": 0,
      "z": -10,
      "name": "Soil_Pathway"
    },
    {
      "x": -33,
      "y": 1,
      "z": -10,
      "name": "Plant_Grass_Arid"
    },
    {
      "x": -33,
      "y": 2,
      "z": -10,
      "name": "Soil_Dirt_Dry"
    },
    {
      "x": -33,
      "y": 10,
      "z": -10,
      "name": "Cloth_Roof_Leather_Flat",
      "rotation": 3
    },
    {
      "x": -33,
      "y": 0,
      "z": -9,
      "name": "Soil_Pathway"
    },
    {
      "x": -33,
      "y": 1,
      "z": -9,
      "name": "Soil_Dirt_Dry"
    },
    {
      "x": -33,
      "y": 2,
      "z": -9,
      "name": "Soil_Dirt_Dry"
    },
    {
      "x": -33,
      "y": 8,
      "z": -9,
      "name": "Wood_Gumboab_Trunk",
      "rotation": 7
    },
    {
      "x": -33,
      "y": 9,
      "z": -9,
      "name": "Wood_Gumboab_Trunk",
      "rotation": 7
    },
    {
      "x": -33,
      "y": 10,
      "z": -9,
      "name": "Cloth_Roof_Leather_Flat",
      "rotation": 3
    },
    {
      "x": -33,
      "y": 0,
      "z": -8,
      "name": "Soil_Pathway"
    },
    {
      "x": -33,
      "y": 1,
      "z": -8,
      "name": "Plant_Grass_Arid"
    },
    {
      "x": -33,
      "y": 2,
      "z": -8,
      "name": "Soil_Dirt_Dry"
    },
    {
      "x": -33,
      "y": 10,
      "z": -8,
      "name": "Cloth_Roof_Leather_Flat",
      "rotation": 3
    },
    {
      "x": -33,
      "y": 0,
      "z": -7,
      "name": "Soil_Pathway"
    },
    {
      "x": -33,
      "y": 1,
      "z": -7,
      "name": "Plant_Grass_Arid"
    },
    {
      "x": -33,
      "y": 2,
      "z": -7,
      "name": "Soil_Dirt_Dry"
    },
    {
      "x": -33,
      "y": 10,
      "z": -7,
      "name": "Cloth_Roof_Leather_Flat",
      "rotation": 3
    },
    {
      "x": -33,
      "y": 0,
      "z": -6,
      "name": "Soil_Dirt_Dry"
    },
    {
      "x": -33,
      "y": 1,
      "z": -6,
      "name": "Soil_Dirt_Dry"
    },
    {
      "x": -33,
      "y": 2,
      "z": -6,
      "name": "Soil_Dirt_Dry"
    },
    {
      "x": -33,
      "y": 10,
      "z": -6,
      "name": "Cloth_Roof_Leather_Flat",
      "rotation": 3
    },
    {
      "x": -33,
      "y": 0,
      "z": -5,
      "name": "Soil_Dirt_Dry"
    },
    {
      "x": -33,
      "y": 1,
      "z": -5,
      "name": "Soil_Dirt_Dry"
    },
    {
      "x": -33,
      "y": 8,
      "z": -5,
      "name": "Wood_Gumboab_Trunk",
      "rotation": 7
    },
    {
      "x": -33,
      "y": 9,
      "z": -5,
      "name": "Cloth_Roof_Leather"
    },
    {
      "x": -33,
      "y": 0,
      "z": -4,
      "name": "Soil_Dirt_Dry"
    },
    {
      "x": -33,
      "y": 1,
      "z": -4,
      "name": "Soil_Dirt_Dry"
    },
    {
      "x": -33,
      "y": 8,
      "z": -4,
      "name": "Cloth_Roof_Leather"
    },
    {
      "x": -33,
      "y": 0,
      "z": -3,
      "name": "Soil_Pathway"
    },
    {
      "x": -33,
      "y": 1,
      "z": -3,
      "name": "Soil_Dirt_Dry"
    },
    {
      "x": -33,
      "y": 0,
      "z": -2,
      "name": "Soil_Pathway"
    },
    {
      "x": -33,
      "y": 0,
      "z": -1,
      "name": "Soil_Pathway"
    },
    {
      "x": -33,
      "y": 0,
      "z": 0,
      "name": "Soil_Pathway"
    },
    {
      "x": -33,
      "y": 0,
      "z": 1,
      "name": "Soil_Pathway"
    },
    {
      "x": -33,
      "y": 0,
      "z": 2,
      "name": "Soil_Pathway"
    },
    {
      "x": -33,
      "y": 0,
      "z": 3,
      "name": "Soil_Pathway"
    },
    {
      "x": -33,
      "y": 0,
      "z": 4,
      "name": "Soil_Pathway"
    },
    {
      "x": -33,
      "y": 0,
      "z": 5,
      "name": "Soil_Pathway"
    },
    {
      "x": -33,
      "y": 0,
      "z": 6,
      "name": "Soil_Pathway"
    },
    {
      "x": -33,
      "y": 0,
      "z": 7,
      "name": "Soil_Pathway"
    },
    {
      "x": -33,
      "y": 0,
      "z": 8,
      "name": "Soil_Pathway"
    },
    {
      "x": -33,
      "y": 0,
      "z": 9,
      "name": "Soil_Pathway"
    },
    {
      "x": -33,
      "y": 0,
      "z": 10,
      "name": "Soil_Pathway"
    },
    {
      "x": -33,
      "y": 0,
      "z": 11,
      "name": "Soil_Pathway"
    },
    {
      "x": -33,
      "y": 0,
      "z": 12,
      "name": "Soil_Pathway"
    },
    {
      "x": -33,
      "y": 0,
      "z": 13,
      "name": "Soil_Pathway"
    },
    {
      "x": -33,
      "y": 0,
      "z": 14,
      "name": "Soil_Pathway"
    },
    {
      "x": -33,
      "y": 0,
      "z": 15,
      "name": "Soil_Pathway"
    },
    {
      "x": -33,
      "y": 0,
      "z": 16,
      "name": "Soil_Pathway"
    },
    {
      "x": -32,
      "y": 0,
      "z": -23,
      "name": "Soil_Pathway"
    },
    {
      "x": -32,
      "y": 0,
      "z": -22,
      "name": "Soil_Pathway"
    },
    {
      "x": -32,
      "y": 0,
      "z": -21,
      "name": "Soil_Dirt_Dry"
    },
    {
      "x": -32,
      "y": 1,
      "z": -21,
      "name": "Soil_Dirt_Dry"
    },
    {
      "x": -32,
      "y": 0,
      "z": -20,
      "name": "Soil_Dirt_Dry"
    },
    {
      "x": -32,
      "y": 1,
      "z": -20,
      "name": "Soil_Dirt_Dry"
    },
    {
      "x": -32,
      "y": 0,
      "z": -19,
      "name": "Soil_Dirt_Dry"
    },
    {
      "x": -32,
      "y": 1,
      "z": -19,
      "name": "Soil_Dirt_Dry"
    },
    {
      "x": -32,
      "y": 2,
      "z": -19,
      "name": "Soil_Dirt_Dry"
    },
    {
      "x": -32,
      "y": 0,
      "z": -18,
      "name": "Soil_Dirt_Dry"
    },
    {
      "x": -32,
      "y": 1,
      "z": -18,
      "name": "Soil_Dirt_Dry"
    },
    {
      "x": -32,
      "y": 2,
      "z": -18,
      "name": "Soil_Dirt_Dry"
    },
    {
      "x": -32,
      "y": 0,
      "z": -17,
      "name": "Soil_Dirt_Dry"
    },
    {
      "x": -32,
      "y": 1,
      "z": -17,
      "name": "Soil_Dirt_Dry"
    },
    {
      "x": -32,
      "y": 2,
      "z": -17,
      "name": "Soil_Dirt_Dry"
    },
    {
      "x": -32,
      "y": 0,
      "z": -16,
      "name": "Soil_Dirt_Dry"
    },
    {
      "x": -32,
      "y": 1,
      "z": -16,
      "name": "Soil_Dirt_Dry"
    },
    {
      "x": -32,
      "y": 2,
      "z": -16,
      "name": "Soil_Dirt_Dry"
    },
    {
      "x": -32,
      "y": 0,
      "z": -15,
      "name": "Soil_Dirt_Dry"
    },
    {
      "x": -32,
      "y": 1,
      "z": -15,
      "name": "Soil_Dirt_Dry"
    },
    {
      "x": -32,
      "y": 2,
      "z": -15,
      "name": "Soil_Dirt_Dry"
    },
    {
      "x": -32,
      "y": 0,
      "z": -14,
      "name": "Soil_Pathway"
    },
    {
      "x": -32,
      "y": 1,
      "z": -14,
      "name": "Plant_Grass_Arid"
    },
    {
      "x": -32,
      "y": 2,
      "z": -14,
      "name": "Soil_Dirt_Dry"
    },
    {
      "x": -32,
      "y": 8,
      "z": -14,
      "name": "Cloth_Roof_Leather",
      "rotation": 2
    },
    {
      "x": -32,
      "y": 0,
      "z": -13,
      "name": "Soil_Pathway"
    },
    {
      "x": -32,
      "y": 1,
      "z": -13,
      "name": "Plant_Grass_Arid_Short"
    },
    {
      "x": -32,
      "y": 2,
      "z": -13,
      "name": "Soil_Dirt_Dry"
    },
    {
      "x": -32,
      "y": 8,
      "z": -13,
      "name": "Wood_Gumboab_Trunk",
      "rotation": 7
    },
    {
      "x": -32,
      "y": 9,
      "z": -13,
      "name": "Cloth_Roof_Leather",
      "support": 15,
      "rotation": 2
    },
    {
      "x": -32,
      "y": 0,
      "z": -12,
      "name": "Soil_Pathway"
    },
    {
      "x": -32,
      "y": 1,
      "z": -12,
      "name": "Plant_Grass_Arid"
    },
    {
      "x": -32,
      "y": 2,
      "z": -12,
      "name": "Soil_Dirt_Dry"
    },
    {
      "x": -32,
      "y": 10,
      "z": -12,
      "name": "Cloth_Roof_Leather_Flat",
      "rotation": 3
    },
    {
      "x": -32,
      "y": 0,
      "z": -11,
      "name": "Soil_Dirt_Dry"
    },
    {
      "x": -32,
      "y": 1,
      "z": -11,
      "name": "Soil_Dirt_Dry"
    },
    {
      "x": -32,
      "y": 2,
      "z": -11,
      "name": "Soil_Dirt_Dry"
    },
    {
      "x": -32,
      "y": 10,
      "z": -11,
      "name": "Cloth_Roof_Leather_Flat",
      "rotation": 3
    },
    {
      "x": -32,
      "y": 0,
      "z": -10,
      "name": "Soil_Pathway"
    },
    {
      "x": -32,
      "y": 1,
      "z": -10,
      "name": "Plant_Grass_Arid"
    },
    {
      "x": -32,
      "y": 2,
      "z": -10,
      "name": "Soil_Dirt_Dry"
    },
    {
      "x": -32,
      "y": 10,
      "z": -10,
      "name": "Cloth_Roof_Leather_Flat",
      "rotation": 3
    },
    {
      "x": -32,
      "y": 0,
      "z": -9,
      "name": "Soil_Dirt_Dry"
    },
    {
      "x": -32,
      "y": 1,
      "z": -9,
      "name": "Soil_Dirt_Dry"
    },
    {
      "x": -32,
      "y": 2,
      "z": -9,
      "name": "Soil_Dirt_Dry"
    },
    {
      "x": -32,
      "y": 8,
      "z": -9,
      "name": "Wood_Gumboab_Trunk",
      "rotation": 7
    },
    {
      "x": -32,
      "y": 9,
      "z": -9,
      "name": "Wood_Gumboab_Trunk",
      "rotation": 7
    },
    {
      "x": -32,
      "y": 10,
      "z": -9,
      "name": "Cloth_Roof_Leather_Flat",
      "rotation": 3
    },
    {
      "x": -32,
      "y": 0,
      "z": -8,
      "name": "Soil_Dirt_Dry"
    },
    {
      "x": -32,
      "y": 1,
      "z": -8,
      "name": "Soil_Dirt_Dry"
    },
    {
      "x": -32,
      "y": 2,
      "z": -8,
      "name": "Soil_Dirt_Dry"
    },
    {
      "x": -32,
      "y": 10,
      "z": -8,
      "name": "Cloth_Roof_Leather_Flat",
      "rotation": 3
    },
    {
      "x": -32,
      "y": 0,
      "z": -7,
      "name": "Soil_Dirt_Dry"
    },
    {
      "x": -32,
      "y": 1,
      "z": -7,
      "name": "Soil_Dirt_Dry"
    },
    {
      "x": -32,
      "y": 2,
      "z": -7,
      "name": "Soil_Dirt_Dry"
    },
    {
      "x": -32,
      "y": 10,
      "z": -7,
      "name": "Cloth_Roof_Leather_Flat",
      "rotation": 3
    },
    {
      "x": -32,
      "y": 0,
      "z": -6,
      "name": "Soil_Dirt_Dry"
    },
    {
      "x": -32,
      "y": 1,
      "z": -6,
      "name": "Soil_Dirt_Dry"
    },
    {
      "x": -32,
      "y": 2,
      "z": -6,
      "name": "Soil_Dirt_Dry"
    },
    {
      "x": -32,
      "y": 10,
      "z": -6,
      "name": "Cloth_Roof_Leather_Flat",
      "rotation": 3
    },
    {
      "x": -32,
      "y": 0,
      "z": -5,
      "name": "Soil_Dirt_Dry"
    },
    {
      "x": -32,
      "y": 1,
      "z": -5,
      "name": "Soil_Dirt_Dry"
    },
    {
      "x": -32,
      "y": 2,
      "z": -5,
      "name": "Soil_Dirt_Dry"
    },
    {
      "x": -32,
      "y": 8,
      "z": -5,
      "name": "Wood_Gumboab_Trunk",
      "rotation": 7
    },
    {
      "x": -32,
      "y": 9,
      "z": -5,
      "name": "Cloth_Roof_Leather"
    },
    {
      "x": -32,
      "y": 0,
      "z": -4,
      "name": "Soil_Dirt_Dry"
    },
    {
      "x": -32,
      "y": 1,
      "z": -4,
      "name": "Soil_Dirt_Dry"
    },
    {
      "x": -32,
      "y": 8,
      "z": -4,
      "name": "Cloth_Roof_Leather"
    },
    {
      "x": -32,
      "y": 0,
      "z": -3,
      "name": "Soil_Dirt_Dry"
    },
    {
      "x": -32,
      "y": 1,
      "z": -3,
      "name": "Soil_Dirt_Dry"
    },
    {
      "x": -32,
      "y": 0,
      "z": -2,
      "name": "Soil_Pathway"
    },
    {
      "x": -32,
      "y": 0,
      "z": -1,
      "name": "Soil_Pathway"
    },
    {
      "x": -32,
      "y": 0,
      "z": 0,
      "name": "Soil_Dirt_Dry"
    },
    {
      "x": -32,
      "y": 1,
      "z": 0,
      "name": "Soil_Dirt_Dry"
    },
    {
      "x": -32,
      "y": 0,
      "z": 1,
      "name": "Soil_Dirt_Dry"
    },
    {
      "x": -32,
      "y": 1,
      "z": 1,
      "name": "Soil_Dirt_Dry"
    },
    {
      "x": -32,
      "y": 0,
      "z": 2,
      "name": "Soil_Dirt_Dry"
    },
    {
      "x": -32,
      "y": 1,
      "z": 2,
      "name": "Soil_Dirt_Dry"
    },
    {
      "x": -32,
      "y": 0,
      "z": 3,
      "name": "Soil_Dirt_Dry"
    },
    {
      "x": -32,
      "y": 1,
      "z": 3,
      "name": "Soil_Dirt_Dry"
    },
    {
      "x": -32,
      "y": 0,
      "z": 4,
      "name": "Soil_Dirt_Dry"
    },
    {
      "x": -32,
      "y": 1,
      "z": 4,
      "name": "Soil_Dirt_Dry"
    },
    {
      "x": -32,
      "y": 0,
      "z": 5,
      "name": "Soil_Dirt_Dry"
    },
    {
      "x": -32,
      "y": 1,
      "z": 5,
      "name": "Soil_Dirt_Dry"
    },
    {
      "x": -32,
      "y": 0,
      "z": 6,
      "name": "Soil_Dirt_Dry"
    },
    {
      "x": -32,
      "y": 1,
      "z": 6,
      "name": "Soil_Dirt_Dry"
    },
    {
      "x": -32,
      "y": 0,
      "z": 7,
      "name": "Soil_Dirt_Dry"
    },
    {
      "x": -32,
      "y": 1,
      "z": 7,
      "name": "Soil_Dirt_Dry"
    },
    {
      "x": -32,
      "y": 0,
      "z": 8,
      "name": "Soil_Dirt_Dry"
    },
    {
      "x": -32,
      "y": 1,
      "z": 8,
      "name": "Soil_Dirt_Dry"
    },
    {
      "x": -32,
      "y": 0,
      "z": 9,
      "name": "Soil_Pathway"
    },
    {
      "x": -32,
      "y": 0,
      "z": 10,
      "name": "Soil_Pathway"
    },
    {
      "x": -32,
      "y": 0,
      "z": 11,
      "name": "Soil_Pathway"
    },
    {
      "x": -32,
      "y": 0,
      "z": 12,
      "name": "Soil_Pathway"
    },
    {
      "x": -32,
      "y": 0,
      "z": 13,
      "name": "Soil_Pathway"
    },
    {
      "x": -32,
      "y": 0,
      "z": 14,
      "name": "Soil_Pathway"
    },
    {
      "x": -32,
      "y": 0,
      "z": 15,
      "name": "Soil_Pathway"
    },
    {
      "x": -32,
      "y": 0,
      "z": 16,
      "name": "Soil_Pathway"
    },
    {
      "x": -32,
      "y": 0,
      "z": 17,
      "name": "Soil_Pathway"
    },
    {
      "x": -31,
      "y": 0,
      "z": -23,
      "name": "Soil_Pathway"
    },
    {
      "x": -31,
      "y": 0,
      "z": -22,
      "name": "Soil_Dirt_Dry"
    },
    {
      "x": -31,
      "y": 1,
      "z": -22,
      "name": "Soil_Dirt_Dry"
    },
    {
      "x": -31,
      "y": 0,
      "z": -21,
      "name": "Soil_Dirt_Dry"
    },
    {
      "x": -31,
      "y": 1,
      "z": -21,
      "name": "Soil_Dirt_Dry"
    },
    {
      "x": -31,
      "y": 0,
      "z": -20,
      "name": "Soil_Dirt_Dry"
    },
    {
      "x": -31,
      "y": 1,
      "z": -20,
      "name": "Soil_Dirt_Dry"
    },
    {
      "x": -31,
      "y": 2,
      "z": -20,
      "name": "Soil_Dirt_Dry"
    },
    {
      "x": -31,
      "y": 0,
      "z": -19,
      "name": "Soil_Dirt_Dry"
    },
    {
      "x": -31,
      "y": 1,
      "z": -19,
      "name": "Soil_Dirt_Dry"
    },
    {
      "x": -31,
      "y": 2,
      "z": -19,
      "name": "Soil_Dirt_Dry"
    },
    {
      "x": -31,
      "y": 0,
      "z": -18,
      "name": "Soil_Dirt_Dry"
    },
    {
      "x": -31,
      "y": 1,
      "z": -18,
      "name": "Soil_Dirt_Dry"
    },
    {
      "x": -31,
      "y": 2,
      "z": -18,
      "name": "Soil_Dirt_Dry"
    },
    {
      "x": -31,
      "y": 0,
      "z": -17,
      "name": "Soil_Dirt_Dry"
    },
    {
      "x": -31,
      "y": 1,
      "z": -17,
      "name": "Soil_Dirt_Dry"
    },
    {
      "x": -31,
      "y": 2,
      "z": -17,
      "name": "Soil_Dirt_Dry"
    },
    {
      "x": -31,
      "y": 0,
      "z": -16,
      "name": "Soil_Dirt_Dry"
    },
    {
      "x": -31,
      "y": 1,
      "z": -16,
      "name": "Soil_Dirt_Dry"
    },
    {
      "x": -31,
      "y": 2,
      "z": -16,
      "name": "Soil_Dirt_Dry"
    },
    {
      "x": -31,
      "y": 0,
      "z": -15,
      "name": "Soil_Dirt_Dry"
    },
    {
      "x": -31,
      "y": 1,
      "z": -15,
      "name": "Soil_Dirt_Dry"
    },
    {
      "x": -31,
      "y": 2,
      "z": -15,
      "name": "Soil_Dirt_Dry"
    },
    {
      "x": -31,
      "y": 0,
      "z": -14,
      "name": "Soil_Dirt_Dry"
    },
    {
      "x": -31,
      "y": 1,
      "z": -14,
      "name": "Soil_Dirt_Dry"
    },
    {
      "x": -31,
      "y": 2,
      "z": -14,
      "name": "Soil_Dirt_Dry"
    },
    {
      "x": -31,
      "y": 8,
      "z": -14,
      "name": "Cloth_Roof_Leather",
      "rotation": 2
    },
    {
      "x": -31,
      "y": 0,
      "z": -13,
      "name": "Soil_Dirt_Dry"
    },
    {
      "x": -31,
      "y": 1,
      "z": -13,
      "name": "Soil_Dirt_Dry"
    },
    {
      "x": -31,
      "y": 2,
      "z": -13,
      "name": "Soil_Dirt_Dry"
    },
    {
      "x": -31,
      "y": 8,
      "z": -13,
      "name": "Wood_Gumboab_Trunk",
      "rotation": 7
    },
    {
      "x": -31,
      "y": 9,
      "z": -13,
      "name": "Cloth_Roof_Leather",
      "support": 15,
      "rotation": 2
    },
    {
      "x": -31,
      "y": 0,
      "z": -12,
      "name": "Soil_Dirt_Dry"
    },
    {
      "x": -31,
      "y": 1,
      "z": -12,
      "name": "Soil_Dirt_Dry"
    },
    {
      "x": -31,
      "y": 2,
      "z": -12,
      "name": "Soil_Dirt_Dry"
    },
    {
      "x": -31,
      "y": 10,
      "z": -12,
      "name": "Cloth_Roof_Leather_Flat",
      "rotation": 3
    },
    {
      "x": -31,
      "y": 0,
      "z": -11,
      "name": "Soil_Pathway"
    },
    {
      "x": -31,
      "y": 1,
      "z": -11,
      "name": "Plant_Grass_Arid"
    },
    {
      "x": -31,
      "y": 2,
      "z": -11,
      "name": "Soil_Dirt_Dry"
    },
    {
      "x": -31,
      "y": 10,
      "z": -11,
      "name": "Cloth_Roof_Leather_Flat",
      "rotation": 3
    },
    {
      "x": -31,
      "y": 0,
      "z": -10,
      "name": "Soil_Dirt_Dry"
    },
    {
      "x": -31,
      "y": 1,
      "z": -10,
      "name": "Soil_Dirt_Dry"
    },
    {
      "x": -31,
      "y": 2,
      "z": -10,
      "name": "Soil_Dirt_Dry"
    },
    {
      "x": -31,
      "y": 10,
      "z": -10,
      "name": "Cloth_Roof_Leather_Flat",
      "rotation": 3
    },
    {
      "x": -31,
      "y": 0,
      "z": -9,
      "name": "Soil_Dirt_Dry"
    },
    {
      "x": -31,
      "y": 1,
      "z": -9,
      "name": "Soil_Dirt_Dry"
    },
    {
      "x": -31,
      "y": 2,
      "z": -9,
      "name": "Soil_Dirt_Dry"
    },
    {
      "x": -31,
      "y": 9,
      "z": -9,
      "name": "Wood_Gumboab_Trunk",
      "rotation": 7
    },
    {
      "x": -31,
      "y": 10,
      "z": -9,
      "name": "Cloth_Roof_Leather_Flat",
      "rotation": 3
    },
    {
      "x": -31,
      "y": 0,
      "z": -8,
      "name": "Soil_Dirt_Dry"
    },
    {
      "x": -31,
      "y": 1,
      "z": -8,
      "name": "Soil_Dirt_Dry"
    },
    {
      "x": -31,
      "y": 2,
      "z": -8,
      "name": "Soil_Dirt_Dry"
    },
    {
      "x": -31,
      "y": 10,
      "z": -8,
      "name": "Cloth_Roof_Leather_Flat",
      "rotation": 3
    },
    {
      "x": -31,
      "y": 0,
      "z": -7,
      "name": "Soil_Dirt_Dry"
    },
    {
      "x": -31,
      "y": 1,
      "z": -7,
      "name": "Soil_Dirt_Dry"
    },
    {
      "x": -31,
      "y": 2,
      "z": -7,
      "name": "Soil_Dirt_Dry"
    },
    {
      "x": -31,
      "y": 10,
      "z": -7,
      "name": "Cloth_Roof_Leather_Flat",
      "rotation": 3
    },
    {
      "x": -31,
      "y": 0,
      "z": -6,
      "name": "Soil_Dirt_Dry"
    },
    {
      "x": -31,
      "y": 1,
      "z": -6,
      "name": "Soil_Dirt_Dry"
    },
    {
      "x": -31,
      "y": 2,
      "z": -6,
      "name": "Soil_Dirt_Dry"
    },
    {
      "x": -31,
      "y": 10,
      "z": -6,
      "name": "Cloth_Roof_Leather_Flat",
      "rotation": 3
    },
    {
      "x": -31,
      "y": 0,
      "z": -5,
      "name": "Soil_Dirt_Dry"
    },
    {
      "x": -31,
      "y": 1,
      "z": -5,
      "name": "Soil_Dirt_Dry"
    },
    {
      "x": -31,
      "y": 2,
      "z": -5,
      "name": "Soil_Dirt_Dry"
    },
    {
      "x": -31,
      "y": 8,
      "z": -5,
      "name": "Wood_Gumboab_Trunk",
      "rotation": 7
    },
    {
      "x": -31,
      "y": 9,
      "z": -5,
      "name": "Cloth_Roof_Leather"
    },
    {
      "x": -31,
      "y": 0,
      "z": -4,
      "name": "Soil_Dirt_Dry"
    },
    {
      "x": -31,
      "y": 1,
      "z": -4,
      "name": "Soil_Dirt_Dry"
    },
    {
      "x": -31,
      "y": 2,
      "z": -4,
      "name": "Soil_Dirt_Dry"
    },
    {
      "x": -31,
      "y": 8,
      "z": -4,
      "name": "Cloth_Roof_Leather"
    },
    {
      "x": -31,
      "y": 0,
      "z": -3,
      "name": "Soil_Dirt_Dry"
    },
    {
      "x": -31,
      "y": 1,
      "z": -3,
      "name": "Soil_Dirt_Dry"
    },
    {
      "x": -31,
      "y": 0,
      "z": -2,
      "name": "Soil_Dirt_Dry"
    },
    {
      "x": -31,
      "y": 1,
      "z": -2,
      "name": "Soil_Dirt_Dry"
    },
    {
      "x": -31,
      "y": 0,
      "z": -1,
      "name": "Soil_Dirt_Dry"
    },
    {
      "x": -31,
      "y": 1,
      "z": -1,
      "name": "Soil_Dirt_Dry"
    },
    {
      "x": -31,
      "y": 0,
      "z": 0,
      "name": "Soil_Dirt_Dry"
    },
    {
      "x": -31,
      "y": 1,
      "z": 0,
      "name": "Soil_Dirt_Dry"
    },
    {
      "x": -31,
      "y": 7,
      "z": 0,
      "name": "Wood_Gumboab_Branch_Long",
      "support": 15,
      "rotation": 5
    },
    {
      "x": -31,
      "y": 0,
      "z": 1,
      "name": "Soil_Dirt_Dry"
    },
    {
      "x": -31,
      "y": 1,
      "z": 1,
      "name": "Soil_Dirt_Dry"
    },
    {
      "x": -31,
      "y": 0,
      "z": 2,
      "name": "Soil_Dirt_Dry"
    },
    {
      "x": -31,
      "y": 1,
      "z": 2,
      "name": "Soil_Dirt_Dry"
    },
    {
      "x": -31,
      "y": 7,
      "z": 2,
      "name": "Wood_Gumboab_Branch_Long",
      "support": 15,
      "rotation": 5
    },
    {
      "x": -31,
      "y": 0,
      "z": 3,
      "name": "Soil_Dirt_Dry"
    },
    {
      "x": -31,
      "y": 1,
      "z": 3,
      "name": "Soil_Dirt_Dry"
    },
    {
      "x": -31,
      "y": 2,
      "z": 3,
      "name": "Soil_Dirt_Dry"
    },
    {
      "x": -31,
      "y": 0,
      "z": 4,
      "name": "Soil_Dirt_Dry"
    },
    {
      "x": -31,
      "y": 1,
      "z": 4,
      "name": "Soil_Dirt_Dry"
    },
    {
      "x": -31,
      "y": 2,
      "z": 4,
      "name": "Soil_Dirt_Dry"
    },
    {
      "x": -31,
      "y": 0,
      "z": 5,
      "name": "Soil_Dirt_Dry"
    },
    {
      "x": -31,
      "y": 1,
      "z": 5,
      "name": "Soil_Dirt_Dry"
    },
    {
      "x": -31,
      "y": 2,
      "z": 5,
      "name": "Soil_Dirt_Dry"
    },
    {
      "x": -31,
      "y": 0,
      "z": 6,
      "name": "Soil_Dirt_Dry"
    },
    {
      "x": -31,
      "y": 1,
      "z": 6,
      "name": "Soil_Dirt_Dry"
    },
    {
      "x": -31,
      "y": 0,
      "z": 7,
      "name": "Soil_Dirt_Dry"
    },
    {
      "x": -31,
      "y": 1,
      "z": 7,
      "name": "Soil_Dirt_Dry"
    },
    {
      "x": -31,
      "y": 0,
      "z": 8,
      "name": "Soil_Dirt_Dry"
    },
    {
      "x": -31,
      "y": 1,
      "z": 8,
      "name": "Soil_Dirt_Dry"
    },
    {
      "x": -31,
      "y": 0,
      "z": 9,
      "name": "Soil_Dirt_Dry"
    },
    {
      "x": -31,
      "y": 1,
      "z": 9,
      "name": "Soil_Dirt_Dry"
    },
    {
      "x": -31,
      "y": 0,
      "z": 10,
      "name": "Soil_Dirt_Dry"
    },
    {
      "x": -31,
      "y": 1,
      "z": 10,
      "name": "Soil_Dirt_Dry"
    },
    {
      "x": -31,
      "y": 0,
      "z": 11,
      "name": "Soil_Pathway"
    },
    {
      "x": -31,
      "y": 0,
      "z": 12,
      "name": "Soil_Pathway"
    },
    {
      "x": -31,
      "y": 0,
      "z": 13,
      "name": "Soil_Pathway"
    },
    {
      "x": -31,
      "y": 0,
      "z": 14,
      "name": "Soil_Pathway"
    },
    {
      "x": -31,
      "y": 0,
      "z": 15,
      "name": "Soil_Pathway"
    },
    {
      "x": -31,
      "y": 0,
      "z": 16,
      "name": "Soil_Pathway"
    },
    {
      "x": -31,
      "y": 0,
      "z": 17,
      "name": "Soil_Pathway"
    },
    {
      "x": -31,
      "y": 0,
      "z": 18,
      "name": "Soil_Pathway"
    },
    {
      "x": -31,
      "y": 0,
      "z": 19,
      "name": "Soil_Pathway"
    },
    {
      "x": -30,
      "y": 0,
      "z": -23,
      "name": "Soil_Pathway"
    },
    {
      "x": -30,
      "y": 0,
      "z": -22,
      "name": "Soil_Dirt_Dry"
    },
    {
      "x": -30,
      "y": 1,
      "z": -22,
      "name": "Soil_Dirt_Dry"
    },
    {
      "x": -30,
      "y": 0,
      "z": -21,
      "name": "Soil_Dirt_Dry"
    },
    {
      "x": -30,
      "y": 1,
      "z": -21,
      "name": "Soil_Dirt_Dry"
    },
    {
      "x": -30,
      "y": 0,
      "z": -20,
      "name": "Soil_Dirt_Dry"
    },
    {
      "x": -30,
      "y": 1,
      "z": -20,
      "name": "Soil_Dirt_Dry"
    },
    {
      "x": -30,
      "y": 2,
      "z": -20,
      "name": "Soil_Dirt_Dry"
    },
    {
      "x": -30,
      "y": 0,
      "z": -19,
      "name": "Soil_Dirt_Dry"
    },
    {
      "x": -30,
      "y": 1,
      "z": -19,
      "name": "Soil_Dirt_Dry"
    },
    {
      "x": -30,
      "y": 2,
      "z": -19,
      "name": "Soil_Dirt_Dry"
    },
    {
      "x": -30,
      "y": 0,
      "z": -18,
      "name": "Soil_Dirt_Dry"
    },
    {
      "x": -30,
      "y": 1,
      "z": -18,
      "name": "Soil_Dirt_Dry"
    },
    {
      "x": -30,
      "y": 2,
      "z": -18,
      "name": "Soil_Dirt_Dry"
    },
    {
      "x": -30,
      "y": 0,
      "z": -17,
      "name": "Soil_Dirt_Dry"
    },
    {
      "x": -30,
      "y": 1,
      "z": -17,
      "name": "Soil_Dirt_Dry"
    },
    {
      "x": -30,
      "y": 2,
      "z": -17,
      "name": "Soil_Dirt_Dry"
    },
    {
      "x": -30,
      "y": 0,
      "z": -16,
      "name": "Soil_Dirt_Dry"
    },
    {
      "x": -30,
      "y": 1,
      "z": -16,
      "name": "Soil_Dirt_Dry"
    },
    {
      "x": -30,
      "y": 2,
      "z": -16,
      "name": "Soil_Dirt_Dry"
    },
    {
      "x": -30,
      "y": 0,
      "z": -15,
      "name": "Soil_Dirt_Dry"
    },
    {
      "x": -30,
      "y": 1,
      "z": -15,
      "name": "Soil_Dirt_Dry"
    },
    {
      "x": -30,
      "y": 2,
      "z": -15,
      "name": "Soil_Dirt_Dry"
    },
    {
      "x": -30,
      "y": 3,
      "z": -15,
      "name": "Soil_Dirt_Dry"
    },
    {
      "x": -30,
      "y": 0,
      "z": -14,
      "name": "Soil_Dirt_Dry"
    },
    {
      "x": -30,
      "y": 1,
      "z": -14,
      "name": "Soil_Dirt_Dry"
    },
    {
      "x": -30,
      "y": 2,
      "z": -14,
      "name": "Soil_Dirt_Dry"
    },
    {
      "x": -30,
      "y": 3,
      "z": -14,
      "name": "Soil_Dirt_Dry"
    },
    {
      "x": -30,
      "y": 8,
      "z": -14,
      "name": "Cloth_Roof_Leather",
      "rotation": 2
    },
    {
      "x": -30,
      "y": 0,
      "z": -13,
      "name": "Soil_Dirt_Dry"
    },
    {
      "x": -30,
      "y": 1,
      "z": -13,
      "name": "Soil_Dirt_Dry"
    },
    {
      "x": -30,
      "y": 2,
      "z": -13,
      "name": "Soil_Dirt_Dry"
    },
    {
      "x": -30,
      "y": 8,
      "z": -13,
      "name": "Wood_Gumboab_Trunk",
      "rotation": 7
    },
    {
      "x": -30,
      "y": 9,
      "z": -13,
      "name": "Cloth_Roof_Leather",
      "support": 15,
      "rotation": 2
    },
    {
      "x": -30,
      "y": 0,
      "z": -12,
      "name": "Soil_Dirt_Dry"
    },
    {
      "x": -30,
      "y": 1,
      "z": -12,
      "name": "Soil_Dirt_Dry"
    },
    {
      "x": -30,
      "y": 2,
      "z": -12,
      "name": "Soil_Dirt_Dry"
    },
    {
      "x": -30,
      "y": 10,
      "z": -12,
      "name": "Cloth_Roof_Leather_Flat",
      "rotation": 3
    },
    {
      "x": -30,
      "y": 0,
      "z": -11,
      "name": "Soil_Dirt_Dry"
    },
    {
      "x": -30,
      "y": 1,
      "z": -11,
      "name": "Soil_Dirt_Dry"
    },
    {
      "x": -30,
      "y": 2,
      "z": -11,
      "name": "Soil_Dirt_Dry"
    },
    {
      "x": -30,
      "y": 10,
      "z": -11,
      "name": "Cloth_Roof_Leather_Flat",
      "rotation": 3
    },
    {
      "x": -30,
      "y": 0,
      "z": -10,
      "name": "Soil_Dirt_Dry"
    },
    {
      "x": -30,
      "y": 1,
      "z": -10,
      "name": "Soil_Dirt_Dry"
    },
    {
      "x": -30,
      "y": 2,
      "z": -10,
      "name": "Soil_Dirt_Dry"
    },
    {
      "x": -30,
      "y": 10,
      "z": -10,
      "name": "Cloth_Roof_Leather_Flat",
      "rotation": 3
    },
    {
      "x": -30,
      "y": 0,
      "z": -9,
      "name": "Soil_Dirt_Dry"
    },
    {
      "x": -30,
      "y": 1,
      "z": -9,
      "name": "Soil_Dirt_Dry"
    },
    {
      "x": -30,
      "y": 2,
      "z": -9,
      "name": "Soil_Dirt_Dry"
    },
    {
      "x": -30,
      "y": 9,
      "z": -9,
      "name": "Wood_Gumboab_Trunk",
      "rotation": 7
    },
    {
      "x": -30,
      "y": 10,
      "z": -9,
      "name": "Cloth_Roof_Leather_Flat",
      "rotation": 3
    },
    {
      "x": -30,
      "y": 0,
      "z": -8,
      "name": "Soil_Dirt_Dry"
    },
    {
      "x": -30,
      "y": 1,
      "z": -8,
      "name": "Soil_Dirt_Dry"
    },
    {
      "x": -30,
      "y": 2,
      "z": -8,
      "name": "Soil_Dirt_Dry"
    },
    {
      "x": -30,
      "y": 10,
      "z": -8,
      "name": "Cloth_Roof_Leather_Flat",
      "rotation": 3
    },
    {
      "x": -30,
      "y": 0,
      "z": -7,
      "name": "Soil_Dirt_Dry"
    },
    {
      "x": -30,
      "y": 1,
      "z": -7,
      "name": "Soil_Dirt_Dry"
    },
    {
      "x": -30,
      "y": 2,
      "z": -7,
      "name": "Soil_Dirt_Dry"
    },
    {
      "x": -30,
      "y": 10,
      "z": -7,
      "name": "Cloth_Roof_Leather_Flat",
      "rotation": 3
    },
    {
      "x": -30,
      "y": 0,
      "z": -6,
      "name": "Soil_Dirt_Dry"
    },
    {
      "x": -30,
      "y": 1,
      "z": -6,
      "name": "Soil_Dirt_Dry"
    },
    {
      "x": -30,
      "y": 2,
      "z": -6,
      "name": "Soil_Dirt_Dry"
    },
    {
      "x": -30,
      "y": 10,
      "z": -6,
      "name": "Cloth_Roof_Leather_Flat",
      "rotation": 3
    },
    {
      "x": -30,
      "y": 0,
      "z": -5,
      "name": "Soil_Dirt_Dry"
    },
    {
      "x": -30,
      "y": 1,
      "z": -5,
      "name": "Soil_Dirt_Dry"
    },
    {
      "x": -30,
      "y": 2,
      "z": -5,
      "name": "Soil_Dirt_Dry"
    },
    {
      "x": -30,
      "y": 8,
      "z": -5,
      "name": "Wood_Gumboab_Trunk",
      "rotation": 7
    },
    {
      "x": -30,
      "y": 9,
      "z": -5,
      "name": "Cloth_Roof_Leather"
    },
    {
      "x": -30,
      "y": 0,
      "z": -4,
      "name": "Soil_Dirt_Dry"
    },
    {
      "x": -30,
      "y": 1,
      "z": -4,
      "name": "Soil_Dirt_Dry"
    },
    {
      "x": -30,
      "y": 2,
      "z": -4,
      "name": "Soil_Dirt_Dry"
    },
    {
      "x": -30,
      "y": 8,
      "z": -4,
      "name": "Cloth_Roof_Leather"
    },
    {
      "x": -30,
      "y": 0,
      "z": -3,
      "name": "Soil_Dirt_Dry"
    },
    {
      "x": -30,
      "y": 1,
      "z": -3,
      "name": "Soil_Dirt_Dry"
    },
    {
      "x": -30,
      "y": 0,
      "z": -2,
      "name": "Soil_Dirt_Dry"
    },
    {
      "x": -30,
      "y": 1,
      "z": -2,
      "name": "Soil_Dirt_Dry"
    },
    {
      "x": -30,
      "y": 0,
      "z": -1,
      "name": "Soil_Dirt_Dry"
    },
    {
      "x": -30,
      "y": 1,
      "z": -1,
      "name": "Soil_Dirt_Dry"
    },
    {
      "x": -30,
      "y": 0,
      "z": 0,
      "name": "Soil_Dirt_Dry"
    },
    {
      "x": -30,
      "y": 1,
      "z": 0,
      "name": "Soil_Dirt_Dry"
    },
    {
      "x": -30,
      "y": 2,
      "z": 0,
      "name": "Soil_Dirt_Dry"
    },
    {
      "x": -30,
      "y": 7,
      "z": 0,
      "name": "Wood_Gumboab_Branch_Long",
      "support": 15,
      "rotation": 5
    },
    {
      "x": -30,
      "y": 0,
      "z": 1,
      "name": "Soil_Dirt_Dry"
    },
    {
      "x": -30,
      "y": 1,
      "z": 1,
      "name": "Soil_Dirt_Dry"
    },
    {
      "x": -30,
      "y": 2,
      "z": 1,
      "name": "Soil_Dirt_Dry"
    },
    {
      "x": -30,
      "y": 0,
      "z": 2,
      "name": "Soil_Dirt_Dry"
    },
    {
      "x": -30,
      "y": 1,
      "z": 2,
      "name": "Soil_Dirt_Dry"
    },
    {
      "x": -30,
      "y": 2,
      "z": 2,
      "name": "Soil_Dirt_Dry"
    },
    {
      "x": -30,
      "y": 7,
      "z": 2,
      "name": "Wood_Gumboab_Branch_Long",
      "support": 15,
      "rotation": 5
    },
    {
      "x": -30,
      "y": 0,
      "z": 3,
      "name": "Soil_Dirt_Dry"
    },
    {
      "x": -30,
      "y": 1,
      "z": 3,
      "name": "Soil_Dirt_Dry"
    },
    {
      "x": -30,
      "y": 2,
      "z": 3,
      "name": "Soil_Dirt_Dry"
    },
    {
      "x": -30,
      "y": 0,
      "z": 4,
      "name": "Soil_Dirt_Dry"
    },
    {
      "x": -30,
      "y": 1,
      "z": 4,
      "name": "Soil_Dirt_Dry"
    },
    {
      "x": -30,
      "y": 2,
      "z": 4,
      "name": "Soil_Dirt_Dry"
    },
    {
      "x": -30,
      "y": 7,
      "z": 4,
      "name": "Wood_Gumboab_Branch_Long",
      "support": 15,
      "rotation": 5
    },
    {
      "x": -30,
      "y": 0,
      "z": 5,
      "name": "Soil_Dirt_Dry"
    },
    {
      "x": -30,
      "y": 1,
      "z": 5,
      "name": "Soil_Dirt_Dry"
    },
    {
      "x": -30,
      "y": 2,
      "z": 5,
      "name": "Soil_Dirt_Dry"
    },
    {
      "x": -30,
      "y": 0,
      "z": 6,
      "name": "Soil_Dirt_Dry"
    },
    {
      "x": -30,
      "y": 1,
      "z": 6,
      "name": "Soil_Dirt_Dry"
    },
    {
      "x": -30,
      "y": 2,
      "z": 6,
      "name": "Soil_Dirt_Dry"
    },
    {
      "x": -30,
      "y": 7,
      "z": 6,
      "name": "Wood_Gumboab_Branch_Long",
      "support": 15,
      "rotation": 5
    },
    {
      "x": -30,
      "y": 0,
      "z": 7,
      "name": "Soil_Dirt_Dry"
    },
    {
      "x": -30,
      "y": 1,
      "z": 7,
      "name": "Soil_Dirt_Dry"
    },
    {
      "x": -30,
      "y": 2,
      "z": 7,
      "name": "Soil_Dirt_Dry"
    },
    {
      "x": -30,
      "y": 0,
      "z": 8,
      "name": "Soil_Dirt_Dry"
    },
    {
      "x": -30,
      "y": 1,
      "z": 8,
      "name": "Soil_Dirt_Dry"
    },
    {
      "x": -30,
      "y": 2,
      "z": 8,
      "name": "Soil_Dirt_Dry"
    },
    {
      "x": -30,
      "y": 7,
      "z": 8,
      "name": "Wood_Gumboab_Branch_Long",
      "support": 15,
      "rotation": 5
    },
    {
      "x": -30,
      "y": 0,
      "z": 9,
      "name": "Soil_Dirt_Dry"
    },
    {
      "x": -30,
      "y": 1,
      "z": 9,
      "name": "Soil_Dirt_Dry"
    },
    {
      "x": -30,
      "y": 0,
      "z": 10,
      "name": "Soil_Dirt_Dry"
    },
    {
      "x": -30,
      "y": 1,
      "z": 10,
      "name": "Soil_Dirt_Dry"
    },
    {
      "x": -30,
      "y": 7,
      "z": 10,
      "name": "Wood_Gumboab_Branch_Long",
      "support": 15,
      "rotation": 5
    },
    {
      "x": -30,
      "y": 0,
      "z": 11,
      "name": "Soil_Dirt_Dry"
    },
    {
      "x": -30,
      "y": 1,
      "z": 11,
      "name": "Soil_Dirt_Dry"
    },
    {
      "x": -30,
      "y": 0,
      "z": 12,
      "name": "Soil_Pathway"
    },
    {
      "x": -30,
      "y": 0,
      "z": 13,
      "name": "Soil_Pathway"
    },
    {
      "x": -30,
      "y": 0,
      "z": 14,
      "name": "Soil_Pathway"
    },
    {
      "x": -30,
      "y": 0,
      "z": 15,
      "name": "Soil_Pathway"
    },
    {
      "x": -30,
      "y": 0,
      "z": 16,
      "name": "Soil_Pathway"
    },
    {
      "x": -30,
      "y": 0,
      "z": 17,
      "name": "Soil_Pathway"
    },
    {
      "x": -30,
      "y": 0,
      "z": 18,
      "name": "Soil_Pathway"
    },
    {
      "x": -30,
      "y": 0,
      "z": 19,
      "name": "Soil_Pathway"
    },
    {
      "x": -30,
      "y": 0,
      "z": 20,
      "name": "Soil_Pathway"
    },
    {
      "x": -29,
      "y": 0,
      "z": -24,
      "name": "Soil_Pathway"
    },
    {
      "x": -29,
      "y": 0,
      "z": -23,
      "name": "Soil_Dirt_Dry"
    },
    {
      "x": -29,
      "y": 1,
      "z": -23,
      "name": "Soil_Dirt_Dry"
    },
    {
      "x": -29,
      "y": 0,
      "z": -22,
      "name": "Soil_Dirt_Dry"
    },
    {
      "x": -29,
      "y": 1,
      "z": -22,
      "name": "Soil_Dirt_Dry"
    },
    {
      "x": -29,
      "y": 2,
      "z": -22,
      "name": "Soil_Gravel_Sand",
      "rotation": 13
    },
    {
      "x": -29,
      "y": 3,
      "z": -22,
      "name": "Soil_Gravel_Sand",
      "rotation": 13
    },
    {
      "x": -29,
      "y": 4,
      "z": -22,
      "name": "Rock_Sandstone",
      "rotation": 13
    },
    {
      "x": -29,
      "y": 0,
      "z": -21,
      "name": "Soil_Dirt_Dry"
    },
    {
      "x": -29,
      "y": 1,
      "z": -21,
      "name": "Soil_Dirt_Dry"
    },
    {
      "x": -29,
      "y": 2,
      "z": -21,
      "name": "Rock_Sandstone",
      "rotation": 13
    },
    {
      "x": -29,
      "y": 3,
      "z": -21,
      "name": "Rock_Sandstone",
      "rotation": 13
    },
    {
      "x": -29,
      "y": 4,
      "z": -21,
      "name": "Rock_Sandstone",
      "rotation": 13
    },
    {
      "x": -29,
      "y": 5,
      "z": -21,
      "name": "Rock_Sandstone",
      "rotation": 13
    },
    {
      "x": -29,
      "y": 0,
      "z": -20,
      "name": "Soil_Dirt_Dry"
    },
    {
      "x": -29,
      "y": 1,
      "z": -20,
      "name": "Rock_Sandstone",
      "rotation": 13
    },
    {
      "x": -29,
      "y": 2,
      "z": -20,
      "name": "Rock_Sandstone",
      "rotation": 13
    },
    {
      "x": -29,
      "y": 3,
      "z": -20,
      "name": "Rock_Sandstone",
      "rotation": 13
    },
    {
      "x": -29,
      "y": 4,
      "z": -20,
      "name": "Rock_Sandstone",
      "rotation": 13
    },
    {
      "x": -29,
      "y": 5,
      "z": -20,
      "name": "Rock_Sandstone_White",
      "rotation": 13
    },
    {
      "x": -29,
      "y": 0,
      "z": -19,
      "name": "Soil_Dirt_Dry"
    },
    {
      "x": -29,
      "y": 1,
      "z": -19,
      "name": "Soil_Dirt_Dry"
    },
    {
      "x": -29,
      "y": 2,
      "z": -19,
      "name": "Rock_Sandstone",
      "rotation": 13
    },
    {
      "x": -29,
      "y": 3,
      "z": -19,
      "name": "Rock_Sandstone",
      "rotation": 13
    },
    {
      "x": -29,
      "y": 4,
      "z": -19,
      "name": "Rock_Sandstone_White",
      "rotation": 13
    },
    {
      "x": -29,
      "y": 0,
      "z": -18,
      "name": "Soil_Dirt_Dry"
    },
    {
      "x": -29,
      "y": 1,
      "z": -18,
      "name": "Soil_Dirt_Dry"
    },
    {
      "x": -29,
      "y": 2,
      "z": -18,
      "name": "Rock_Sandstone",
      "rotation": 13
    },
    {
      "x": -29,
      "y": 3,
      "z": -18,
      "name": "Rock_Sandstone_White",
      "rotation": 13
    },
    {
      "x": -29,
      "y": 0,
      "z": -17,
      "name": "Soil_Dirt_Dry"
    },
    {
      "x": -29,
      "y": 1,
      "z": -17,
      "name": "Soil_Dirt_Dry"
    },
    {
      "x": -29,
      "y": 2,
      "z": -17,
      "name": "Soil_Dirt_Dry"
    },
    {
      "x": -29,
      "y": 0,
      "z": -16,
      "name": "Soil_Dirt_Dry"
    },
    {
      "x": -29,
      "y": 1,
      "z": -16,
      "name": "Soil_Dirt_Dry"
    },
    {
      "x": -29,
      "y": 2,
      "z": -16,
      "name": "Soil_Dirt_Dry"
    },
    {
      "x": -29,
      "y": 3,
      "z": -16,
      "name": "Soil_Dirt_Dry"
    },
    {
      "x": -29,
      "y": 8,
      "z": -16,
      "name": "Wood_Gumboab_Branch_Long",
      "support": 15,
      "rotation": 5
    },
    {
      "x": -29,
      "y": 0,
      "z": -15,
      "name": "Soil_Dirt_Dry"
    },
    {
      "x": -29,
      "y": 1,
      "z": -15,
      "name": "Soil_Dirt_Dry"
    },
    {
      "x": -29,
      "y": 2,
      "z": -15,
      "name": "Soil_Dirt_Dry"
    },
    {
      "x": -29,
      "y": 3,
      "z": -15,
      "name": "Soil_Dirt_Dry"
    },
    {
      "x": -29,
      "y": 0,
      "z": -14,
      "name": "Soil_Dirt_Dry"
    },
    {
      "x": -29,
      "y": 1,
      "z": -14,
      "name": "Soil_Dirt_Dry"
    },
    {
      "x": -29,
      "y": 2,
      "z": -14,
      "name": "Soil_Dirt_Dry"
    },
    {
      "x": -29,
      "y": 3,
      "z": -14,
      "name": "Soil_Dirt_Dry"
    },
    {
      "x": -29,
      "y": 8,
      "z": -14,
      "name": "Cloth_Roof_Leather",
      "support": 15,
      "rotation": 2
    },
    {
      "x": -29,
      "y": 0,
      "z": -13,
      "name": "Soil_Dirt_Dry"
    },
    {
      "x": -29,
      "y": 1,
      "z": -13,
      "name": "Soil_Dirt_Dry"
    },
    {
      "x": -29,
      "y": 2,
      "z": -13,
      "name": "Soil_Dirt_Dry"
    },
    {
      "x": -29,
      "y": 3,
      "z": -13,
      "name": "Soil_Dirt_Dry"
    },
    {
      "x": -29,
      "y": 8,
      "z": -13,
      "name": "Wood_Gumboab_Trunk",
      "rotation": 7
    },
    {
      "x": -29,
      "y": 9,
      "z": -13,
      "name": "Cloth_Roof_Leather",
      "support": 15,
      "rotation": 2
    },
    {
      "x": -29,
      "y": 0,
      "z": -12,
      "name": "Soil_Dirt_Dry"
    },
    {
      "x": -29,
      "y": 1,
      "z": -12,
      "name": "Soil_Dirt_Dry"
    },
    {
      "x": -29,
      "y": 2,
      "z": -12,
      "name": "Soil_Dirt_Dry"
    },
    {
      "x": -29,
      "y": 10,
      "z": -12,
      "name": "Cloth_Roof_Leather_Flat",
      "rotation": 3
    },
    {
      "x": -29,
      "y": 0,
      "z": -11,
      "name": "Soil_Dirt_Dry"
    },
    {
      "x": -29,
      "y": 1,
      "z": -11,
      "name": "Soil_Dirt_Dry"
    },
    {
      "x": -29,
      "y": 2,
      "z": -11,
      "name": "Soil_Dirt_Dry"
    },
    {
      "x": -29,
      "y": 10,
      "z": -11,
      "name": "Cloth_Roof_Leather_Flat",
      "rotation": 3
    },
    {
      "x": -29,
      "y": 0,
      "z": -10,
      "name": "Soil_Dirt_Dry"
    },
    {
      "x": -29,
      "y": 1,
      "z": -10,
      "name": "Soil_Dirt_Dry"
    },
    {
      "x": -29,
      "y": 2,
      "z": -10,
      "name": "Soil_Dirt_Dry"
    },
    {
      "x": -29,
      "y": 10,
      "z": -10,
      "name": "Cloth_Roof_Leather_Flat",
      "rotation": 3
    },
    {
      "x": -29,
      "y": 0,
      "z": -9,
      "name": "Soil_Dirt_Dry"
    },
    {
      "x": -29,
      "y": 1,
      "z": -9,
      "name": "Soil_Dirt_Dry"
    },
    {
      "x": -29,
      "y": 2,
      "z": -9,
      "name": "Soil_Dirt_Dry"
    },
    {
      "x": -29,
      "y": 9,
      "z": -9,
      "name": "Wood_Gumboab_Trunk",
      "rotation": 7
    },
    {
      "x": -29,
      "y": 10,
      "z": -9,
      "name": "Cloth_Roof_Leather_Flat",
      "rotation": 3
    },
    {
      "x": -29,
      "y": 0,
      "z": -8,
      "name": "Soil_Dirt_Dry"
    },
    {
      "x": -29,
      "y": 1,
      "z": -8,
      "name": "Soil_Dirt_Dry"
    },
    {
      "x": -29,
      "y": 2,
      "z": -8,
      "name": "Soil_Dirt_Dry"
    },
    {
      "x": -29,
      "y": 10,
      "z": -8,
      "name": "Cloth_Roof_Leather_Flat",
      "rotation": 3
    },
    {
      "x": -29,
      "y": 0,
      "z": -7,
      "name": "Soil_Dirt_Dry"
    },
    {
      "x": -29,
      "y": 1,
      "z": -7,
      "name": "Soil_Dirt_Dry"
    },
    {
      "x": -29,
      "y": 2,
      "z": -7,
      "name": "Soil_Dirt_Dry"
    },
    {
      "x": -29,
      "y": 10,
      "z": -7,
      "name": "Cloth_Roof_Leather_Flat",
      "rotation": 3
    },
    {
      "x": -29,
      "y": 0,
      "z": -6,
      "name": "Soil_Dirt_Dry"
    },
    {
      "x": -29,
      "y": 1,
      "z": -6,
      "name": "Soil_Dirt_Dry"
    },
    {
      "x": -29,
      "y": 2,
      "z": -6,
      "name": "Soil_Dirt_Dry"
    },
    {
      "x": -29,
      "y": 10,
      "z": -6,
      "name": "Cloth_Roof_Leather_Flat",
      "rotation": 3
    },
    {
      "x": -29,
      "y": 0,
      "z": -5,
      "name": "Soil_Dirt_Dry"
    },
    {
      "x": -29,
      "y": 1,
      "z": -5,
      "name": "Soil_Dirt_Dry"
    },
    {
      "x": -29,
      "y": 2,
      "z": -5,
      "name": "Soil_Dirt_Dry"
    },
    {
      "x": -29,
      "y": 8,
      "z": -5,
      "name": "Wood_Gumboab_Trunk",
      "rotation": 7
    },
    {
      "x": -29,
      "y": 9,
      "z": -5,
      "name": "Cloth_Roof_Leather"
    },
    {
      "x": -29,
      "y": 0,
      "z": -4,
      "name": "Soil_Dirt_Dry"
    },
    {
      "x": -29,
      "y": 1,
      "z": -4,
      "name": "Soil_Dirt_Dry"
    },
    {
      "x": -29,
      "y": 2,
      "z": -4,
      "name": "Soil_Dirt_Dry"
    },
    {
      "x": -29,
      "y": 7,
      "z": -4,
      "name": "Wood_Gumboab_Branch_Long",
      "support": 15,
      "rotation": 5
    },
    {
      "x": -29,
      "y": 8,
      "z": -4,
      "name": "Cloth_Roof_Leather"
    },
    {
      "x": -29,
      "y": 0,
      "z": -3,
      "name": "Soil_Dirt_Dry"
    },
    {
      "x": -29,
      "y": 1,
      "z": -3,
      "name": "Soil_Dirt_Dry"
    },
    {
      "x": -29,
      "y": 2,
      "z": -3,
      "name": "Soil_Dirt_Dry"
    },
    {
      "x": -29,
      "y": 0,
      "z": -2,
      "name": "Soil_Dirt_Dry"
    },
    {
      "x": -29,
      "y": 1,
      "z": -2,
      "name": "Soil_Dirt_Dry"
    },
    {
      "x": -29,
      "y": 2,
      "z": -2,
      "name": "Soil_Dirt_Dry"
    },
    {
      "x": -29,
      "y": 7,
      "z": -2,
      "name": "Wood_Gumboab_Branch_Long",
      "support": 15,
      "rotation": 5
    },
    {
      "x": -29,
      "y": 0,
      "z": -1,
      "name": "Soil_Dirt_Dry"
    },
    {
      "x": -29,
      "y": 1,
      "z": -1,
      "name": "Soil_Dirt_Dry"
    },
    {
      "x": -29,
      "y": 2,
      "z": -1,
      "name": "Soil_Dirt_Dry"
    },
    {
      "x": -29,
      "y": 0,
      "z": 0,
      "name": "Soil_Dirt_Dry"
    },
    {
      "x": -29,
      "y": 1,
      "z": 0,
      "name": "Soil_Dirt_Dry"
    },
    {
      "x": -29,
      "y": 2,
      "z": 0,
      "name": "Soil_Dirt_Dry"
    },
    {
      "x": -29,
      "y": 3,
      "z": 0,
      "name": "Wood_Gumboab_Trunk",
      "support": 15
    },
    {
      "x": -29,
      "y": 4,
      "z": 0,
      "name": "Wood_Gumboab_Trunk",
      "support": 15
    },
    {
      "x": -29,
      "y": 5,
      "z": 0,
      "name": "Wood_Gumboab_Trunk",
      "support": 15
    },
    {
      "x": -29,
      "y": 6,
      "z": 0,
      "name": "Wood_Gumboab_Trunk",
      "support": 15
    },
    {
      "x": -29,
      "y": 7,
      "z": 0,
      "name": "Wood_Gumboab_Trunk",
      "support": 15
    },
    {
      "x": -29,
      "y": 8,
      "z": 0,
      "name": "Wood_Gumboab_Branch_Long",
      "support": 15
    },
    {
      "x": -29,
      "y": 9,
      "z": 0,
      "name": "Survival_Trap_Spike_Wood_Large"
    },
    {
      "x": -29,
      "y": 0,
      "z": 1,
      "name": "Soil_Dirt_Dry"
    },
    {
      "x": -29,
      "y": 1,
      "z": 1,
      "name": "Soil_Dirt_Dry"
    },
    {
      "x": -29,
      "y": 2,
      "z": 1,
      "name": "Soil_Dirt_Dry"
    },
    {
      "x": -29,
      "y": 0,
      "z": 2,
      "name": "Soil_Dirt_Dry"
    },
    {
      "x": -29,
      "y": 1,
      "z": 2,
      "name": "Soil_Dirt_Dry"
    },
    {
      "x": -29,
      "y": 2,
      "z": 2,
      "name": "Soil_Dirt_Dry"
    },
    {
      "x": -29,
      "y": 3,
      "z": 2,
      "name": "Wood_Gumboab_Trunk",
      "support": 15
    },
    {
      "x": -29,
      "y": 4,
      "z": 2,
      "name": "Wood_Gumboab_Trunk",
      "support": 15
    },
    {
      "x": -29,
      "y": 5,
      "z": 2,
      "name": "Wood_Gumboab_Trunk",
      "support": 15
    },
    {
      "x": -29,
      "y": 6,
      "z": 2,
      "name": "Wood_Gumboab_Trunk",
      "support": 15
    },
    {
      "x": -29,
      "y": 7,
      "z": 2,
      "name": "Wood_Gumboab_Trunk",
      "support": 15
    },
    {
      "x": -29,
      "y": 8,
      "z": 2,
      "name": "Wood_Gumboab_Branch_Long",
      "support": 15
    },
    {
      "x": -29,
      "y": 9,
      "z": 2,
      "name": "Survival_Trap_Spike_Wood_Large"
    },
    {
      "x": -29,
      "y": 0,
      "z": 3,
      "name": "Soil_Dirt_Dry"
    },
    {
      "x": -29,
      "y": 1,
      "z": 3,
      "name": "Soil_Dirt_Dry"
    },
    {
      "x": -29,
      "y": 2,
      "z": 3,
      "name": "Soil_Dirt_Dry"
    },
    {
      "x": -29,
      "y": 0,
      "z": 4,
      "name": "Soil_Dirt_Dry"
    },
    {
      "x": -29,
      "y": 1,
      "z": 4,
      "name": "Soil_Dirt_Dry"
    },
    {
      "x": -29,
      "y": 2,
      "z": 4,
      "name": "Soil_Dirt_Dry"
    },
    {
      "x": -29,
      "y": 7,
      "z": 4,
      "name": "Wood_Gumboab_Branch_Long",
      "support": 15,
      "rotation": 5
    },
    {
      "x": -29,
      "y": 0,
      "z": 5,
      "name": "Soil_Dirt_Dry"
    },
    {
      "x": -29,
      "y": 1,
      "z": 5,
      "name": "Soil_Dirt_Dry"
    },
    {
      "x": -29,
      "y": 2,
      "z": 5,
      "name": "Soil_Dirt_Dry"
    },
    {
      "x": -29,
      "y": 3,
      "z": 5,
      "name": "Wood_Gumboab_Trunk",
      "support": 15
    },
    {
      "x": -29,
      "y": 4,
      "z": 5,
      "name": "Wood_Gumboab_Trunk",
      "support": 15
    },
    {
      "x": -29,
      "y": 5,
      "z": 5,
      "name": "Wood_Gumboab_Trunk",
      "support": 15
    },
    {
      "x": -29,
      "y": 6,
      "z": 5,
      "name": "Wood_Gumboab_Trunk",
      "support": 15
    },
    {
      "x": -29,
      "y": 7,
      "z": 5,
      "name": "Wood_Gumboab_Trunk",
      "support": 15
    },
    {
      "x": -29,
      "y": 8,
      "z": 5,
      "name": "Wood_Gumboab_Branch_Long",
      "support": 15
    },
    {
      "x": -29,
      "y": 9,
      "z": 5,
      "name": "Survival_Trap_Spike_Wood_Large"
    },
    {
      "x": -29,
      "y": 0,
      "z": 6,
      "name": "Soil_Dirt_Dry"
    },
    {
      "x": -29,
      "y": 1,
      "z": 6,
      "name": "Soil_Dirt_Dry"
    },
    {
      "x": -29,
      "y": 2,
      "z": 6,
      "name": "Soil_Dirt_Dry"
    },
    {
      "x": -29,
      "y": 7,
      "z": 6,
      "name": "Wood_Gumboab_Branch_Long",
      "support": 15,
      "rotation": 5
    },
    {
      "x": -29,
      "y": 0,
      "z": 7,
      "name": "Soil_Dirt_Dry"
    },
    {
      "x": -29,
      "y": 1,
      "z": 7,
      "name": "Soil_Dirt_Dry"
    },
    {
      "x": -29,
      "y": 2,
      "z": 7,
      "name": "Soil_Dirt_Dry"
    },
    {
      "x": -29,
      "y": 3,
      "z": 7,
      "name": "Wood_Gumboab_Trunk",
      "support": 15
    },
    {
      "x": -29,
      "y": 4,
      "z": 7,
      "name": "Wood_Gumboab_Trunk",
      "support": 15
    },
    {
      "x": -29,
      "y": 5,
      "z": 7,
      "name": "Wood_Gumboab_Trunk",
      "support": 15
    },
    {
      "x": -29,
      "y": 6,
      "z": 7,
      "name": "Wood_Gumboab_Trunk",
      "support": 15
    },
    {
      "x": -29,
      "y": 7,
      "z": 7,
      "name": "Wood_Gumboab_Trunk",
      "support": 15
    },
    {
      "x": -29,
      "y": 8,
      "z": 7,
      "name": "Wood_Gumboab_Branch_Long",
      "support": 15
    },
    {
      "x": -29,
      "y": 9,
      "z": 7,
      "name": "Survival_Trap_Spike_Wood_Large"
    },
    {
      "x": -29,
      "y": 0,
      "z": 8,
      "name": "Soil_Dirt_Dry"
    },
    {
      "x": -29,
      "y": 1,
      "z": 8,
      "name": "Soil_Dirt_Dry"
    },
    {
      "x": -29,
      "y": 2,
      "z": 8,
      "name": "Soil_Dirt_Dry"
    },
    {
      "x": -29,
      "y": 7,
      "z": 8,
      "name": "Wood_Gumboab_Branch_Long",
      "support": 15,
      "rotation": 5
    },
    {
      "x": -29,
      "y": 0,
      "z": 9,
      "name": "Soil_Dirt_Dry"
    },
    {
      "x": -29,
      "y": 1,
      "z": 9,
      "name": "Soil_Dirt_Dry"
    },
    {
      "x": -29,
      "y": 2,
      "z": 9,
      "name": "Soil_Dirt_Dry"
    },
    {
      "x": -29,
      "y": 0,
      "z": 10,
      "name": "Soil_Dirt_Dry"
    },
    {
      "x": -29,
      "y": 1,
      "z": 10,
      "name": "Soil_Dirt_Dry"
    },
    {
      "x": -29,
      "y": 2,
      "z": 10,
      "name": "Soil_Dirt_Dry"
    },
    {
      "x": -29,
      "y": 7,
      "z": 10,
      "name": "Wood_Gumboab_Branch_Long",
      "support": 15,
      "rotation": 5
    },
    {
      "x": -29,
      "y": 0,
      "z": 11,
      "name": "Soil_Dirt_Dry"
    },
    {
      "x": -29,
      "y": 1,
      "z": 11,
      "name": "Soil_Dirt_Dry"
    },
    {
      "x": -29,
      "y": 0,
      "z": 12,
      "name": "Soil_Dirt_Dry"
    },
    {
      "x": -29,
      "y": 1,
      "z": 12,
      "name": "Soil_Dirt_Dry"
    },
    {
      "x": -29,
      "y": 0,
      "z": 13,
      "name": "Soil_Pathway"
    },
    {
      "x": -29,
      "y": 0,
      "z": 14,
      "name": "Soil_Pathway"
    },
    {
      "x": -29,
      "y": 0,
      "z": 15,
      "name": "Soil_Pathway"
    },
    {
      "x": -29,
      "y": 0,
      "z": 16,
      "name": "Soil_Pathway"
    },
    {
      "x": -29,
      "y": 0,
      "z": 17,
      "name": "Soil_Pathway"
    },
    {
      "x": -29,
      "y": 0,
      "z": 18,
      "name": "Soil_Pathway"
    },
    {
      "x": -29,
      "y": 0,
      "z": 19,
      "name": "Soil_Pathway"
    },
    {
      "x": -29,
      "y": 0,
      "z": 20,
      "name": "Soil_Pathway"
    },
    {
      "x": -29,
      "y": 0,
      "z": 21,
      "name": "Soil_Pathway"
    },
    {
      "x": -28,
      "y": 0,
      "z": -25,
      "name": "Soil_Pathway"
    },
    {
      "x": -28,
      "y": 0,
      "z": -24,
      "name": "Soil_Dirt_Dry"
    },
    {
      "x": -28,
      "y": 1,
      "z": -24,
      "name": "Soil_Dirt_Dry"
    },
    {
      "x": -28,
      "y": 0,
      "z": -23,
      "name": "Soil_Dirt_Dry"
    },
    {
      "x": -28,
      "y": 1,
      "z": -23,
      "name": "Soil_Dirt_Dry"
    },
    {
      "x": -28,
      "y": 0,
      "z": -22,
      "name": "Soil_Dirt_Dry"
    },
    {
      "x": -28,
      "y": 1,
      "z": -22,
      "name": "Rock_Sandstone_White",
      "rotation": 13
    },
    {
      "x": -28,
      "y": 2,
      "z": -22,
      "name": "Rock_Sandstone_White",
      "rotation": 13
    },
    {
      "x": -28,
      "y": 3,
      "z": -22,
      "name": "Rock_Sandstone_White",
      "rotation": 13
    },
    {
      "x": -28,
      "y": 4,
      "z": -22,
      "name": "Rock_Sandstone_White",
      "rotation": 13
    },
    {
      "x": -28,
      "y": 5,
      "z": -22,
      "name": "Rock_Sandstone_White",
      "rotation": 13
    },
    {
      "x": -28,
      "y": 0,
      "z": -21,
      "name": "Rock_Sandstone_White",
      "rotation": 13
    },
    {
      "x": -28,
      "y": 1,
      "z": -21,
      "name": "Rock_Sandstone_White",
      "rotation": 13
    },
    {
      "x": -28,
      "y": 2,
      "z": -21,
      "name": "Rock_Sandstone_White",
      "rotation": 13
    },
    {
      "x": -28,
      "y": 3,
      "z": -21,
      "name": "Rock_Sandstone_White",
      "rotation": 13
    },
    {
      "x": -28,
      "y": 4,
      "z": -21,
      "name": "Rock_Sandstone_White",
      "rotation": 13
    },
    {
      "x": -28,
      "y": 5,
      "z": -21,
      "name": "Rock_Sandstone_White",
      "rotation": 13
    },
    {
      "x": -28,
      "y": 0,
      "z": -20,
      "name": "Rock_Sandstone_White",
      "rotation": 13
    },
    {
      "x": -28,
      "y": 1,
      "z": -20,
      "name": "Rock_Sandstone_White",
      "rotation": 13
    },
    {
      "x": -28,
      "y": 2,
      "z": -20,
      "name": "Rock_Sandstone_White",
      "rotation": 13
    },
    {
      "x": -28,
      "y": 3,
      "z": -20,
      "name": "Rock_Sandstone_White",
      "rotation": 13
    },
    {
      "x": -28,
      "y": 4,
      "z": -20,
      "name": "Rock_Sandstone_White",
      "rotation": 13
    },
    {
      "x": -28,
      "y": 5,
      "z": -20,
      "name": "Rock_Sandstone_White",
      "rotation": 13
    },
    {
      "x": -28,
      "y": 6,
      "z": -20,
      "name": "Rock_Sandstone_White",
      "rotation": 13
    },
    {
      "x": -28,
      "y": 0,
      "z": -19,
      "name": "Rock_Sandstone_White",
      "rotation": 13
    },
    {
      "x": -28,
      "y": 1,
      "z": -19,
      "name": "Rock_Sandstone_White",
      "rotation": 13
    },
    {
      "x": -28,
      "y": 2,
      "z": -19,
      "name": "Rock_Sandstone_White",
      "rotation": 13
    },
    {
      "x": -28,
      "y": 3,
      "z": -19,
      "name": "Rock_Sandstone_White",
      "rotation": 13
    },
    {
      "x": -28,
      "y": 4,
      "z": -19,
      "name": "Rock_Sandstone_White",
      "rotation": 13
    },
    {
      "x": -28,
      "y": 5,
      "z": -19,
      "name": "Rock_Sandstone_White",
      "rotation": 13
    },
    {
      "x": -28,
      "y": 0,
      "z": -18,
      "name": "Soil_Dirt_Dry"
    },
    {
      "x": -28,
      "y": 1,
      "z": -18,
      "name": "Rock_Sandstone_White",
      "rotation": 13
    },
    {
      "x": -28,
      "y": 2,
      "z": -18,
      "name": "Rock_Sandstone_White",
      "rotation": 13
    },
    {
      "x": -28,
      "y": 3,
      "z": -18,
      "name": "Rock_Sandstone_White",
      "rotation": 13
    },
    {
      "x": -28,
      "y": 0,
      "z": -17,
      "name": "Soil_Dirt_Dry"
    },
    {
      "x": -28,
      "y": 1,
      "z": -17,
      "name": "Soil_Dirt_Dry"
    },
    {
      "x": -28,
      "y": 2,
      "z": -17,
      "name": "Rock_Sandstone_White",
      "rotation": 13
    },
    {
      "x": -28,
      "y": 3,
      "z": -17,
      "name": "Rock_Sandstone_White",
      "rotation": 13
    },
    {
      "x": -28,
      "y": 0,
      "z": -16,
      "name": "Soil_Dirt_Dry"
    },
    {
      "x": -28,
      "y": 1,
      "z": -16,
      "name": "Soil_Dirt_Dry"
    },
    {
      "x": -28,
      "y": 2,
      "z": -16,
      "name": "Soil_Dirt_Dry"
    },
    {
      "x": -28,
      "y": 3,
      "z": -16,
      "name": "Soil_Dirt_Dry"
    },
    {
      "x": -28,
      "y": 8,
      "z": -16,
      "name": "Wood_Gumboab_Branch_Long",
      "support": 15,
      "rotation": 5
    },
    {
      "x": -28,
      "y": 0,
      "z": -15,
      "name": "Soil_Dirt_Dry"
    },
    {
      "x": -28,
      "y": 1,
      "z": -15,
      "name": "Soil_Dirt_Dry"
    },
    {
      "x": -28,
      "y": 2,
      "z": -15,
      "name": "Soil_Dirt_Dry"
    },
    {
      "x": -28,
      "y": 3,
      "z": -15,
      "name": "Soil_Dirt_Dry"
    },
    {
      "x": -28,
      "y": 4,
      "z": -15,
      "name": "Wood_Gumboab_Trunk",
      "support": 15
    },
    {
      "x": -28,
      "y": 5,
      "z": -15,
      "name": "Wood_Gumboab_Trunk",
      "support": 15
    },
    {
      "x": -28,
      "y": 6,
      "z": -15,
      "name": "Wood_Gumboab_Trunk",
      "support": 15
    },
    {
      "x": -28,
      "y": 7,
      "z": -15,
      "name": "Wood_Gumboab_Trunk",
      "support": 15
    },
    {
      "x": -28,
      "y": 8,
      "z": -15,
      "name": "Wood_Gumboab_Trunk",
      "support": 15
    },
    {
      "x": -28,
      "y": 9,
      "z": -15,
      "name": "Wood_Gumboab_Branch_Long",
      "support": 15
    },
    {
      "x": -28,
      "y": 10,
      "z": -15,
      "name": "Survival_Trap_Spike_Wood_Large"
    },
    {
      "x": -28,
      "y": 0,
      "z": -14,
      "name": "Soil_Dirt_Dry"
    },
    {
      "x": -28,
      "y": 1,
      "z": -14,
      "name": "Soil_Dirt_Dry"
    },
    {
      "x": -28,
      "y": 2,
      "z": -14,
      "name": "Soil_Dirt_Dry"
    },
    {
      "x": -28,
      "y": 3,
      "z": -14,
      "name": "Soil_Dirt_Dry"
    },
    {
      "x": -28,
      "y": 8,
      "z": -14,
      "name": "Cloth_Roof_Leather",
      "support": 15,
      "rotation": 2
    },
    {
      "x": -28,
      "y": 0,
      "z": -13,
      "name": "Soil_Dirt_Dry"
    },
    {
      "x": -28,
      "y": 1,
      "z": -13,
      "name": "Soil_Dirt_Dry"
    },
    {
      "x": -28,
      "y": 2,
      "z": -13,
      "name": "Soil_Dirt_Dry"
    },
    {
      "x": -28,
      "y": 3,
      "z": -13,
      "name": "Wood_Gumboab_Trunk",
      "rotation": 3
    },
    {
      "x": -28,
      "y": 4,
      "z": -13,
      "name": "Wood_Gumboab_Trunk",
      "support": 15,
      "rotation": 3
    },
    {
      "x": -28,
      "y": 5,
      "z": -13,
      "name": "Wood_Gumboab_Trunk",
      "support": 15,
      "rotation": 3
    },
    {
      "x": -28,
      "y": 6,
      "z": -13,
      "name": "Wood_Gumboab_Trunk",
      "support": 15,
      "rotation": 3
    },
    {
      "x": -28,
      "y": 7,
      "z": -13,
      "name": "Wood_Gumboab_Trunk",
      "support": 15,
      "rotation": 3
    },
    {
      "x": -28,
      "y": 8,
      "z": -13,
      "name": "Wood_Gumboab_Trunk",
      "support": 15,
      "rotation": 7
    },
    {
      "x": -28,
      "y": 9,
      "z": -13,
      "name": "Wood_Gumboab_Trunk",
      "support": 15,
      "rotation": 3
    },
    {
      "x": -28,
      "y": 10,
      "z": -13,
      "name": "Wood_Gumboab_Branch_Long",
      "rotation": 3
    },
    {
      "x": -28,
      "y": 11,
      "z": -13,
      "name": "Survival_Trap_Spike_Wood_Large",
      "rotation": 3
    },
    {
      "x": -28,
      "y": 0,
      "z": -12,
      "name": "Soil_Dirt_Dry"
    },
    {
      "x": -28,
      "y": 1,
      "z": -12,
      "name": "Soil_Dirt_Dry"
    },
    {
      "x": -28,
      "y": 2,
      "z": -12,
      "name": "Soil_Dirt_Dry"
    },
    {
      "x": -28,
      "y": 3,
      "z": -12,
      "name": "Soil_Dirt_Dry"
    },
    {
      "x": -28,
      "y": 8,
      "z": -12,
      "name": "Wood_Gumboab_Trunk",
      "rotation": 4
    },
    {
      "x": -28,
      "y": 9,
      "z": -12,
      "name": "Wood_Gumboab_Branch_Long",
      "support": 15,
      "rotation": 4
    },
    {
      "x": -28,
      "y": 10,
      "z": -12,
      "name": "Cloth_Roof_Leather_Flat",
      "rotation": 3
    },
    {
      "x": -28,
      "y": 0,
      "z": -11,
      "name": "Soil_Dirt_Dry"
    },
    {
      "x": -28,
      "y": 1,
      "z": -11,
      "name": "Soil_Dirt_Dry"
    },
    {
      "x": -28,
      "y": 2,
      "z": -11,
      "name": "Soil_Dirt_Dry"
    },
    {
      "x": -28,
      "y": 8,
      "z": -11,
      "name": "Wood_Gumboab_Trunk",
      "rotation": 4
    },
    {
      "x": -28,
      "y": 9,
      "z": -11,
      "name": "Wood_Gumboab_Branch_Long",
      "support": 15,
      "rotation": 4
    },
    {
      "x": -28,
      "y": 10,
      "z": -11,
      "name": "Cloth_Roof_Leather_Flat",
      "rotation": 3
    },
    {
      "x": -28,
      "y": 0,
      "z": -10,
      "name": "Soil_Dirt_Dry"
    },
    {
      "x": -28,
      "y": 1,
      "z": -10,
      "name": "Soil_Dirt_Dry"
    },
    {
      "x": -28,
      "y": 2,
      "z": -10,
      "name": "Soil_Dirt_Dry"
    },
    {
      "x": -28,
      "y": 8,
      "z": -10,
      "name": "Wood_Gumboab_Trunk",
      "rotation": 4
    },
    {
      "x": -28,
      "y": 9,
      "z": -10,
      "name": "Wood_Gumboab_Branch_Long",
      "support": 15,
      "rotation": 4
    },
    {
      "x": -28,
      "y": 10,
      "z": -10,
      "name": "Cloth_Roof_Leather_Flat",
      "rotation": 3
    },
    {
      "x": -28,
      "y": 0,
      "z": -9,
      "name": "Soil_Dirt_Dry"
    },
    {
      "x": -28,
      "y": 1,
      "z": -9,
      "name": "Soil_Dirt_Dry"
    },
    {
      "x": -28,
      "y": 2,
      "z": -9,
      "name": "Soil_Dirt_Dry"
    },
    {
      "x": -28,
      "y": 8,
      "z": -9,
      "name": "Wood_Gumboab_Trunk",
      "rotation": 4
    },
    {
      "x": -28,
      "y": 9,
      "z": -9,
      "name": "Wood_Gumboab_Branch_Long",
      "support": 15,
      "rotation": 4
    },
    {
      "x": -28,
      "y": 10,
      "z": -9,
      "name": "Cloth_Roof_Leather_Flat",
      "rotation": 3
    },
    {
      "x": -28,
      "y": 0,
      "z": -8,
      "name": "Soil_Dirt_Dry"
    },
    {
      "x": -28,
      "y": 1,
      "z": -8,
      "name": "Soil_Dirt_Dry"
    },
    {
      "x": -28,
      "y": 2,
      "z": -8,
      "name": "Soil_Dirt_Dry"
    },
    {
      "x": -28,
      "y": 8,
      "z": -8,
      "name": "Wood_Gumboab_Trunk",
      "rotation": 4
    },
    {
      "x": -28,
      "y": 9,
      "z": -8,
      "name": "Wood_Gumboab_Branch_Long",
      "support": 15,
      "rotation": 4
    },
    {
      "x": -28,
      "y": 10,
      "z": -8,
      "name": "Cloth_Roof_Leather_Flat",
      "rotation": 3
    },
    {
      "x": -28,
      "y": 0,
      "z": -7,
      "name": "Soil_Dirt_Dry"
    },
    {
      "x": -28,
      "y": 1,
      "z": -7,
      "name": "Soil_Dirt_Dry"
    },
    {
      "x": -28,
      "y": 2,
      "z": -7,
      "name": "Soil_Dirt_Dry"
    },
    {
      "x": -28,
      "y": 8,
      "z": -7,
      "name": "Wood_Gumboab_Trunk",
      "rotation": 4
    },
    {
      "x": -28,
      "y": 9,
      "z": -7,
      "name": "Wood_Gumboab_Branch_Long",
      "support": 15,
      "rotation": 4
    },
    {
      "x": -28,
      "y": 10,
      "z": -7,
      "name": "Cloth_Roof_Leather_Flat",
      "rotation": 3
    },
    {
      "x": -28,
      "y": 0,
      "z": -6,
      "name": "Soil_Dirt_Dry"
    },
    {
      "x": -28,
      "y": 1,
      "z": -6,
      "name": "Soil_Dirt_Dry"
    },
    {
      "x": -28,
      "y": 2,
      "z": -6,
      "name": "Soil_Dirt_Dry"
    },
    {
      "x": -28,
      "y": 8,
      "z": -6,
      "name": "Wood_Gumboab_Trunk",
      "rotation": 4
    },
    {
      "x": -28,
      "y": 9,
      "z": -6,
      "name": "Wood_Gumboab_Branch_Long",
      "support": 15,
      "rotation": 4
    },
    {
      "x": -28,
      "y": 10,
      "z": -6,
      "name": "Cloth_Roof_Leather_Flat",
      "rotation": 3
    },
    {
      "x": -28,
      "y": 0,
      "z": -5,
      "name": "Soil_Dirt_Dry"
    },
    {
      "x": -28,
      "y": 1,
      "z": -5,
      "name": "Soil_Dirt_Dry"
    },
    {
      "x": -28,
      "y": 2,
      "z": -5,
      "name": "Soil_Dirt_Dry"
    },
    {
      "x": -28,
      "y": 3,
      "z": -5,
      "name": "Wood_Gumboab_Trunk",
      "support": 15,
      "rotation": 3
    },
    {
      "x": -28,
      "y": 4,
      "z": -5,
      "name": "Wood_Gumboab_Trunk",
      "support": 15,
      "rotation": 3
    },
    {
      "x": -28,
      "y": 5,
      "z": -5,
      "name": "Wood_Gumboab_Trunk",
      "support": 15,
      "rotation": 3
    },
    {
      "x": -28,
      "y": 6,
      "z": -5,
      "name": "Wood_Gumboab_Trunk",
      "support": 15,
      "rotation": 3
    },
    {
      "x": -28,
      "y": 7,
      "z": -5,
      "name": "Wood_Gumboab_Trunk",
      "support": 15,
      "rotation": 3
    },
    {
      "x": -28,
      "y": 8,
      "z": -5,
      "name": "Wood_Gumboab_Trunk",
      "support": 15,
      "rotation": 7
    },
    {
      "x": -28,
      "y": 9,
      "z": -5,
      "name": "Wood_Gumboab_Trunk",
      "support": 15,
      "rotation": 3
    },
    {
      "x": -28,
      "y": 10,
      "z": -5,
      "name": "Wood_Gumboab_Branch_Long",
      "rotation": 3
    },
    {
      "x": -28,
      "y": 11,
      "z": -5,
      "name": "Survival_Trap_Spike_Wood_Large",
      "rotation": 3
    },
    {
      "x": -28,
      "y": 0,
      "z": -4,
      "name": "Soil_Dirt_Dry"
    },
    {
      "x": -28,
      "y": 1,
      "z": -4,
      "name": "Soil_Dirt_Dry"
    },
    {
      "x": -28,
      "y": 2,
      "z": -4,
      "name": "Soil_Dirt_Dry"
    },
    {
      "x": -28,
      "y": 7,
      "z": -4,
      "name": "Wood_Gumboab_Branch_Long",
      "support": 15,
      "rotation": 5
    },
    {
      "x": -28,
      "y": 8,
      "z": -4,
      "name": "Cloth_Roof_Leather"
    },
    {
      "x": -28,
      "y": 0,
      "z": -3,
      "name": "Soil_Dirt_Dry"
    },
    {
      "x": -28,
      "y": 1,
      "z": -3,
      "name": "Soil_Dirt_Dry"
    },
    {
      "x": -28,
      "y": 2,
      "z": -3,
      "name": "Soil_Dirt_Dry"
    },
    {
      "x": -28,
      "y": 3,
      "z": -3,
      "name": "Wood_Gumboab_Trunk",
      "support": 15
    },
    {
      "x": -28,
      "y": 4,
      "z": -3,
      "name": "Wood_Gumboab_Trunk",
      "support": 15
    },
    {
      "x": -28,
      "y": 5,
      "z": -3,
      "name": "Wood_Gumboab_Trunk",
      "support": 15
    },
    {
      "x": -28,
      "y": 6,
      "z": -3,
      "name": "Wood_Gumboab_Trunk",
      "support": 15
    },
    {
      "x": -28,
      "y": 7,
      "z": -3,
      "name": "Wood_Gumboab_Trunk",
      "support": 15
    },
    {
      "x": -28,
      "y": 8,
      "z": -3,
      "name": "Wood_Gumboab_Branch_Long",
      "support": 15
    },
    {
      "x": -28,
      "y": 9,
      "z": -3,
      "name": "Survival_Trap_Spike_Wood_Large"
    },
    {
      "x": -28,
      "y": 0,
      "z": -2,
      "name": "Soil_Dirt_Dry"
    },
    {
      "x": -28,
      "y": 1,
      "z": -2,
      "name": "Soil_Dirt_Dry"
    },
    {
      "x": -28,
      "y": 2,
      "z": -2,
      "name": "Soil_Dirt_Dry"
    },
    {
      "x": -28,
      "y": 7,
      "z": -2,
      "name": "Wood_Gumboab_Branch_Long",
      "support": 15,
      "rotation": 5
    },
    {
      "x": -28,
      "y": 0,
      "z": -1,
      "name": "Soil_Dirt_Dry"
    },
    {
      "x": -28,
      "y": 1,
      "z": -1,
      "name": "Soil_Dirt_Dry"
    },
    {
      "x": -28,
      "y": 2,
      "z": -1,
      "name": "Soil_Dirt_Dry"
    },
    {
      "x": -28,
      "y": 3,
      "z": -1,
      "name": "Wood_Gumboab_Trunk",
      "support": 15
    },
    {
      "x": -28,
      "y": 4,
      "z": -1,
      "name": "Wood_Gumboab_Trunk",
      "support": 15
    },
    {
      "x": -28,
      "y": 5,
      "z": -1,
      "name": "Wood_Gumboab_Trunk",
      "support": 15
    },
    {
      "x": -28,
      "y": 6,
      "z": -1,
      "name": "Wood_Gumboab_Trunk",
      "support": 15
    },
    {
      "x": -28,
      "y": 7,
      "z": -1,
      "name": "Wood_Gumboab_Trunk",
      "support": 15
    },
    {
      "x": -28,
      "y": 8,
      "z": -1,
      "name": "Wood_Gumboab_Branch_Long",
      "support": 15
    },
    {
      "x": -28,
      "y": 9,
      "z": -1,
      "name": "Survival_Trap_Spike_Wood_Large"
    },
    {
      "x": -28,
      "y": 0,
      "z": 0,
      "name": "Soil_Dirt_Dry"
    },
    {
      "x": -28,
      "y": 1,
      "z": 0,
      "name": "Soil_Dirt_Dry"
    },
    {
      "x": -28,
      "y": 2,
      "z": 0,
      "name": "Soil_Dirt_Dry"
    },
    {
      "x": -28,
      "y": 0,
      "z": 1,
      "name": "Soil_Dirt_Dry"
    },
    {
      "x": -28,
      "y": 1,
      "z": 1,
      "name": "Soil_Dirt_Dry"
    },
    {
      "x": -28,
      "y": 2,
      "z": 1,
      "name": "Soil_Dirt_Dry"
    },
    {
      "x": -28,
      "y": 3,
      "z": 1,
      "name": "Wood_Gumboab_Trunk",
      "support": 15
    },
    {
      "x": -28,
      "y": 4,
      "z": 1,
      "name": "Wood_Gumboab_Trunk",
      "support": 15
    },
    {
      "x": -28,
      "y": 5,
      "z": 1,
      "name": "Wood_Gumboab_Trunk",
      "support": 15
    },
    {
      "x": -28,
      "y": 6,
      "z": 1,
      "name": "Wood_Gumboab_Trunk",
      "support": 15
    },
    {
      "x": -28,
      "y": 7,
      "z": 1,
      "name": "Wood_Gumboab_Trunk",
      "support": 15
    },
    {
      "x": -28,
      "y": 8,
      "z": 1,
      "name": "Wood_Gumboab_Branch_Long",
      "support": 15
    },
    {
      "x": -28,
      "y": 9,
      "z": 1,
      "name": "Survival_Trap_Spike_Wood_Large"
    },
    {
      "x": -28,
      "y": 0,
      "z": 2,
      "name": "Soil_Dirt_Dry"
    },
    {
      "x": -28,
      "y": 1,
      "z": 2,
      "name": "Soil_Dirt_Dry"
    },
    {
      "x": -28,
      "y": 2,
      "z": 2,
