{
  "version": 8,
  "blockIdVersion": 11,
  "anchorX": 0,
  "anchorY": 0,
  "anchorZ": 0,
  "blocks": [
    {
      "x": -15,
      "y": 0,
      "z": -12,
      "name": "Soil_Dirt"
    },
    {
      "x": -15,
      "y": 0,
      "z": -11,
      "name": "Soil_Dirt"
    },
    {
      "x": -15,
      "y": 0,
      "z": -10,
      "name": "Soil_Dirt"
    },
    {
      "x": -15,
      "y": 0,
      "z": -9,
      "name": "Soil_Dirt"
    },
    {
      "x": -15,
      "y": 0,
      "z": -8,
      "name": "Soil_Dirt"
    },
    {
      "x": -15,
      "y": 0,
      "z": -7,
      "name": "Soil_Dirt"
    },
    {
      "x": -15,
      "y": 0,
      "z": -6,
      "name": "Soil_Dirt"
    },
    {
      "x": -15,
      "y": 0,
      "z": -5,
      "name": "Soil_Dirt"
    },
    {
      "x": -15,
      "y": 0,
      "z": -4,
      "name": "Soil_Dirt"
    },
    {
      "x": -15,
      "y": 0,
      "z": -3,
      "name": "Soil_Dirt"
    },
    {
      "x": -15,
      "y": 0,
      "z": -2,
      "name": "Soil_Dirt"
    },
    {
      "x": -15,
      "y": 0,
      "z": -1,
      "name": "Soil_Dirt"
    },
    {
      "x": -15,
      "y": 0,
      "z": 0,
      "name": "Soil_Dirt"
    },
    {
      "x": -15,
      "y": 0,
      "z": 1,
      "name": "Soil_Dirt"
    },
    {
      "x": -15,
      "y": 0,
      "z": 2,
      "name": "Soil_Dirt"
    },
    {
      "x": -15,
      "y": 0,
      "z": 3,
      "name": "Soil_Dirt"
    },
    {
      "x": -15,
      "y": 0,
      "z": 4,
      "name": "Soil_Dirt"
    },
    {
      "x": -15,
      "y": 0,
      "z": 5,
      "name": "Soil_Dirt"
    },
    {
      "x": -15,
      "y": 0,
      "z": 6,
      "name": "Soil_Dirt"
    },
    {
      "x": -15,
      "y": 0,
      "z": 7,
      "name": "Soil_Dirt"
    },
    {
      "x": -15,
      "y": 0,
      "z": 8,
      "name": "Soil_Dirt"
    },
    {
      "x": -15,
      "y": 0,
      "z": 9,
      "name": "Soil_Dirt"
    },
    {
      "x": -15,
      "y": 0,
      "z": 10,
      "name": "Soil_Dirt"
    },
    {
      "x": -15,
      "y": 0,
      "z": 11,
      "name": "Soil_Dirt"
    },
    {
      "x": -15,
      "y": 0,
      "z": 12,
      "name": "Soil_Dirt"
    },
    {
      "x": -15,
      "y": 0,
      "z": 13,
      "name": "Soil_Dirt"
    },
    {
      "x": -15,
      "y": 0,
      "z": 14,
      "name": "Soil_Dirt"
    },
    {
      "x": -15,
      "y": 0,
      "z": 15,
      "name": "Soil_Dirt"
    },
    {
      "x": -15,
      "y": 0,
      "z": 16,
      "name": "Soil_Dirt"
    },
    {
      "x": -14,
      "y": 0,
      "z": -12,
      "name": "Soil_Dirt"
    },
    {
      "x": -14,
      "y": 0,
      "z": -11,
      "name": "Soil_Dirt"
    },
    {
      "x": -14,
      "y": 0,
      "z": -10,
      "name": "Soil_Dirt"
    },
    {
      "x": -14,
      "y": 0,
      "z": -9,
      "name": "Soil_Dirt"
    },
    {
      "x": -14,
      "y": 0,
      "z": -8,
      "name": "Soil_Dirt"
    },
    {
      "x": -14,
      "y": 0,
      "z": -7,
      "name": "Soil_Dirt"
    },
    {
      "x": -14,
      "y": 0,
      "z": -6,
      "name": "Soil_Dirt"
    },
    {
      "x": -14,
      "y": 0,
      "z": -5,
      "name": "Soil_Dirt"
    },
    {
      "x": -14,
      "y": 0,
      "z": -4,
      "name": "Soil_Dirt"
    },
    {
      "x": -14,
      "y": 0,
      "z": -3,
      "name": "Soil_Dirt"
    },
    {
      "x": -14,
      "y": 0,
      "z": -2,
      "name": "Soil_Dirt"
    },
    {
      "x": -14,
      "y": 0,
      "z": -1,
      "name": "Soil_Dirt"
    },
    {
      "x": -14,
      "y": 0,
      "z": 0,
      "name": "Soil_Dirt"
    },
    {
      "x": -14,
      "y": 0,
      "z": 1,
      "name": "Soil_Dirt"
    },
    {
      "x": -14,
      "y": 0,
      "z": 2,
      "name": "Soil_Dirt"
    },
    {
      "x": -14,
      "y": 0,
      "z": 3,
      "name": "Soil_Dirt"
    },
    {
      "x": -14,
      "y": 0,
      "z": 4,
      "name": "Soil_Dirt"
    },
    {
      "x": -14,
      "y": 0,
      "z": 5,
      "name": "Soil_Dirt"
    },
    {
      "x": -14,
      "y": 0,
      "z": 6,
      "name": "Soil_Dirt"
    },
    {
      "x": -14,
      "y": 0,
      "z": 7,
      "name": "Soil_Dirt"
    },
    {
      "x": -14,
      "y": 0,
      "z": 8,
      "name": "Soil_Dirt"
    },
    {
      "x": -14,
      "y": 0,
      "z": 9,
      "name": "Soil_Dirt"
    },
    {
      "x": -14,
      "y": 0,
      "z": 10,
      "name": "Soil_Dirt"
    },
    {
      "x": -14,
      "y": 0,
      "z": 11,
      "name": "Soil_Dirt"
    },
    {
      "x": -14,
      "y": 0,
      "z": 12,
      "name": "Soil_Dirt"
    },
    {
      "x": -14,
      "y": 0,
      "z": 13,
      "name": "Soil_Dirt"
    },
    {
      "x": -14,
      "y": 0,
      "z": 14,
      "name": "Soil_Dirt"
    },
    {
      "x": -14,
      "y": 0,
      "z": 15,
      "name": "Soil_Dirt"
    },
    {
      "x": -14,
      "y": 0,
      "z": 16,
      "name": "Soil_Dirt"
    },
    {
      "x": -13,
      "y": 0,
      "z": -12,
      "name": "Soil_Dirt"
    },
    {
      "x": -13,
      "y": 0,
      "z": -11,
      "name": "Soil_Dirt"
    },
    {
      "x": -13,
      "y": 0,
      "z": -10,
      "name": "Soil_Dirt"
    },
    {
      "x": -13,
      "y": 0,
      "z": -9,
      "name": "Soil_Dirt"
    },
    {
      "x": -13,
      "y": 0,
      "z": -8,
      "name": "Soil_Dirt"
    },
    {
      "x": -13,
      "y": 0,
      "z": -7,
      "name": "Soil_Dirt"
    },
    {
      "x": -13,
      "y": 0,
      "z": -6,
      "name": "Soil_Dirt"
    },
    {
      "x": -13,
      "y": 0,
      "z": -5,
      "name": "Soil_Dirt"
    },
    {
      "x": -13,
      "y": 0,
      "z": -4,
      "name": "Soil_Dirt"
    },
    {
      "x": -13,
      "y": 0,
      "z": -3,
      "name": "Soil_Dirt"
    },
    {
      "x": -13,
      "y": 0,
      "z": -2,
      "name": "Soil_Dirt"
    },
    {
      "x": -13,
      "y": 0,
      "z": -1,
      "name": "Soil_Dirt"
    },
    {
      "x": -13,
      "y": 0,
      "z": 0,
      "name": "Soil_Dirt"
    },
    {
      "x": -13,
      "y": 0,
      "z": 1,
      "name": "Soil_Dirt"
    },
    {
      "x": -13,
      "y": 0,
      "z": 2,
      "name": "Soil_Dirt"
    },
    {
      "x": -13,
      "y": 0,
      "z": 3,
      "name": "Soil_Dirt"
    },
    {
      "x": -13,
      "y": 0,
      "z": 4,
      "name": "Soil_Dirt"
    },
    {
      "x": -13,
      "y": 0,
      "z": 5,
      "name": "Soil_Dirt"
    },
    {
      "x": -13,
      "y": 0,
      "z": 6,
      "name": "Soil_Dirt"
    },
    {
      "x": -13,
      "y": 0,
      "z": 7,
      "name": "Soil_Dirt"
    },
    {
      "x": -13,
      "y": 0,
      "z": 8,
      "name": "Soil_Dirt"
    },
    {
      "x": -13,
      "y": 0,
      "z": 9,
      "name": "Soil_Dirt"
    },
    {
      "x": -13,
      "y": 0,
      "z": 10,
      "name": "Soil_Dirt"
    },
    {
      "x": -13,
      "y": 0,
      "z": 11,
      "name": "Soil_Dirt"
    },
    {
      "x": -13,
      "y": 0,
      "z": 12,
      "name": "Soil_Dirt"
    },
    {
      "x": -13,
      "y": 0,
      "z": 13,
      "name": "Soil_Dirt"
    },
    {
      "x": -13,
      "y": 0,
      "z": 14,
      "name": "Soil_Dirt"
    },
    {
      "x": -13,
      "y": 0,
      "z": 15,
      "name": "Soil_Dirt"
    },
    {
      "x": -13,
      "y": 0,
      "z": 16,
      "name": "Soil_Dirt"
    },
    {
      "x": -12,
      "y": 0,
      "z": -12,
      "name": "Soil_Dirt"
    },
    {
      "x": -12,
      "y": 0,
      "z": -11,
      "name": "Soil_Dirt"
    },
    {
      "x": -12,
      "y": 0,
      "z": -10,
      "name": "Soil_Dirt"
    },
    {
      "x": -12,
      "y": 0,
      "z": -9,
      "name": "Soil_Dirt"
    },
    {
      "x": -12,
      "y": 0,
      "z": -8,
      "name": "Soil_Dirt"
    },
    {
      "x": -12,
      "y": 0,
      "z": -7,
      "name": "Soil_Dirt"
    },
    {
      "x": -12,
      "y": 0,
      "z": -6,
      "name": "Soil_Dirt"
    },
    {
      "x": -12,
      "y": 0,
      "z": -5,
      "name": "Soil_Dirt"
    },
    {
      "x": -12,
      "y": 0,
      "z": -4,
      "name": "Soil_Dirt"
    },
    {
      "x": -12,
      "y": 0,
      "z": -3,
      "name": "Soil_Dirt"
    },
    {
      "x": -12,
      "y": 0,
      "z": -2,
      "name": "Soil_Dirt"
    },
    {
      "x": -12,
      "y": 0,
      "z": -1,
      "name": "Soil_Dirt"
    },
    {
      "x": -12,
      "y": 0,
      "z": 0,
      "name": "Soil_Dirt"
    },
    {
      "x": -12,
      "y": 0,
      "z": 1,
      "name": "Soil_Dirt"
    },
    {
      "x": -12,
      "y": 0,
      "z": 2,
      "name": "Soil_Dirt"
    },
    {
      "x": -12,
      "y": 0,
      "z": 3,
      "name": "Soil_Dirt"
    },
    {
      "x": -12,
      "y": 0,
      "z": 4,
      "name": "Soil_Dirt"
    },
    {
      "x": -12,
      "y": 0,
      "z": 5,
      "name": "Soil_Dirt"
    },
    {
      "x": -12,
      "y": 0,
      "z": 6,
      "name": "Soil_Dirt"
    },
    {
      "x": -12,
      "y": 0,
      "z": 7,
      "name": "Soil_Dirt"
    },
    {
      "x": -12,
      "y": 0,
      "z": 8,
      "name": "Soil_Dirt"
    },
    {
      "x": -12,
      "y": 0,
      "z": 9,
      "name": "Soil_Dirt"
    },
    {
      "x": -12,
      "y": 0,
      "z": 10,
      "name": "Soil_Dirt"
    },
    {
      "x": -12,
      "y": 0,
      "z": 11,
      "name": "Soil_Dirt"
    },
    {
      "x": -12,
      "y": 0,
      "z": 12,
      "name": "Soil_Dirt"
    },
    {
      "x": -12,
      "y": 0,
      "z": 13,
      "name": "Soil_Dirt"
    },
    {
      "x": -12,
      "y": 0,
      "z": 14,
      "name": "Soil_Dirt"
    },
    {
      "x": -12,
      "y": 0,
      "z": 15,
      "name": "Soil_Dirt"
    },
    {
      "x": -12,
      "y": 0,
      "z": 16,
      "name": "Soil_Dirt"
    },
    {
      "x": -11,
      "y": 0,
      "z": -12,
      "name": "Soil_Dirt"
    },
    {
      "x": -11,
      "y": 0,
      "z": -11,
      "name": "Soil_Dirt"
    },
    {
      "x": -11,
      "y": 0,
      "z": -10,
      "name": "Soil_Dirt"
    },
    {
      "x": -11,
      "y": 0,
      "z": -9,
      "name": "Soil_Dirt"
    },
    {
      "x": -11,
      "y": 0,
      "z": -8,
      "name": "Soil_Dirt"
    },
    {
      "x": -11,
      "y": 0,
      "z": -7,
      "name": "Soil_Dirt"
    },
    {
      "x": -11,
      "y": 0,
      "z": -6,
      "name": "Soil_Dirt"
    },
    {
      "x": -11,
      "y": 0,
      "z": -5,
      "name": "Soil_Dirt"
    },
    {
      "x": -11,
      "y": 0,
      "z": -4,
      "name": "Soil_Dirt"
    },
    {
      "x": -11,
      "y": 0,
      "z": -3,
      "name": "Soil_Dirt"
    },
    {
      "x": -11,
      "y": 0,
      "z": -2,
      "name": "Soil_Dirt"
    },
    {
      "x": -11,
      "y": 0,
      "z": -1,
      "name": "Soil_Dirt"
    },
    {
      "x": -11,
      "y": 0,
      "z": 0,
      "name": "Soil_Dirt"
    },
    {
      "x": -11,
      "y": 0,
      "z": 1,
      "name": "Soil_Dirt"
    },
    {
      "x": -11,
      "y": 0,
      "z": 2,
      "name": "Soil_Dirt"
    },
    {
      "x": -11,
      "y": 0,
      "z": 3,
      "name": "Soil_Dirt"
    },
    {
      "x": -11,
      "y": 0,
      "z": 4,
      "name": "Soil_Dirt"
    },
    {
      "x": -11,
      "y": 0,
      "z": 5,
      "name": "Soil_Dirt"
    },
    {
      "x": -11,
      "y": 0,
      "z": 6,
      "name": "Soil_Dirt"
    },
    {
      "x": -11,
      "y": 0,
      "z": 7,
      "name": "Soil_Dirt"
    },
    {
      "x": -11,
      "y": 0,
      "z": 8,
      "name": "Soil_Dirt"
    },
    {
      "x": -11,
      "y": 0,
      "z": 9,
      "name": "Soil_Dirt"
    },
    {
      "x": -11,
      "y": 0,
      "z": 10,
      "name": "Soil_Dirt"
    },
    {
      "x": -11,
      "y": 0,
      "z": 11,
      "name": "Soil_Dirt"
    },
    {
      "x": -11,
      "y": 0,
      "z": 12,
      "name": "Soil_Dirt"
    },
    {
      "x": -11,
      "y": 0,
      "z": 13,
      "name": "Soil_Dirt"
    },
    {
      "x": -11,
      "y": 0,
      "z": 14,
      "name": "Soil_Dirt"
    },
    {
      "x": -11,
      "y": 0,
      "z": 15,
      "name": "Soil_Dirt"
    },
    {
      "x": -11,
      "y": 0,
      "z": 16,
      "name": "Soil_Dirt"
    },
    {
      "x": -10,
      "y": 0,
      "z": -12,
      "name": "Soil_Dirt"
    },
    {
      "x": -10,
      "y": 0,
      "z": -11,
      "name": "Soil_Dirt"
    },
    {
      "x": -10,
      "y": 0,
      "z": -10,
      "name": "Soil_Dirt"
    },
    {
      "x": -10,
      "y": 0,
      "z": -9,
      "name": "Soil_Dirt"
    },
    {
      "x": -10,
      "y": 0,
      "z": -8,
      "name": "Soil_Dirt"
    },
    {
      "x": -10,
      "y": 0,
      "z": -7,
      "name": "Soil_Dirt"
    },
    {
      "x": -10,
      "y": 0,
      "z": -6,
      "name": "Soil_Dirt"
    },
    {
      "x": -10,
      "y": 0,
      "z": -5,
      "name": "Soil_Dirt"
    },
    {
      "x": -10,
      "y": 0,
      "z": -4,
      "name": "Soil_Dirt"
    },
    {
      "x": -10,
      "y": 0,
      "z": -3,
      "name": "Soil_Dirt"
    },
    {
      "x": -10,
      "y": 0,
      "z": -2,
      "name": "Soil_Dirt"
    },
    {
      "x": -10,
      "y": 0,
      "z": -1,
      "name": "Soil_Dirt"
    },
    {
      "x": -10,
      "y": 0,
      "z": 0,
      "name": "Soil_Dirt"
    },
    {
      "x": -10,
      "y": 0,
      "z": 1,
      "name": "Soil_Dirt"
    },
    {
      "x": -10,
      "y": 0,
      "z": 2,
      "name": "Soil_Dirt"
    },
    {
      "x": -10,
      "y": 0,
      "z": 3,
      "name": "Soil_Dirt"
    },
    {
      "x": -10,
      "y": 0,
      "z": 4,
      "name": "Soil_Dirt"
    },
    {
      "x": -10,
      "y": 0,
      "z": 5,
      "name": "Soil_Dirt"
    },
    {
      "x": -10,
      "y": 0,
      "z": 6,
      "name": "Soil_Dirt"
    },
    {
      "x": -10,
      "y": 0,
      "z": 7,
      "name": "Soil_Dirt"
    },
    {
      "x": -10,
      "y": 0,
      "z": 8,
      "name": "Soil_Dirt"
    },
    {
      "x": -10,
      "y": 0,
      "z": 9,
      "name": "Soil_Dirt"
    },
    {
      "x": -10,
      "y": 0,
      "z": 10,
      "name": "Soil_Dirt"
    },
    {
      "x": -10,
      "y": 0,
      "z": 11,
      "name": "Soil_Dirt"
    },
    {
      "x": -10,
      "y": 0,
      "z": 12,
      "name": "Soil_Dirt"
    },
    {
      "x": -10,
      "y": 0,
      "z": 13,
      "name": "Soil_Dirt"
    },
    {
      "x": -10,
      "y": 0,
      "z": 14,
      "name": "Soil_Dirt"
    },
    {
      "x": -10,
      "y": 0,
      "z": 15,
      "name": "Soil_Dirt"
    },
    {
      "x": -10,
      "y": 0,
      "z": 16,
      "name": "Soil_Dirt"
    },
    {
      "x": -9,
      "y": 0,
      "z": -12,
      "name": "Soil_Dirt"
    },
    {
      "x": -9,
      "y": 0,
      "z": -11,
      "name": "Soil_Dirt"
    },
    {
      "x": -9,
      "y": 0,
      "z": -10,
      "name": "Soil_Dirt"
    },
    {
      "x": -9,
      "y": 0,
      "z": -9,
      "name": "Soil_Dirt"
    },
    {
      "x": -9,
      "y": 0,
      "z": -8,
      "name": "Soil_Dirt"
    },
    {
      "x": -9,
      "y": 0,
      "z": -7,
      "name": "Soil_Dirt"
    },
    {
      "x": -9,
      "y": 0,
      "z": -6,
      "name": "Soil_Dirt"
    },
    {
      "x": -9,
      "y": 0,
      "z": -5,
      "name": "Soil_Dirt"
    },
    {
      "x": -9,
      "y": 0,
      "z": -4,
      "name": "Soil_Dirt"
    },
    {
      "x": -9,
      "y": 0,
      "z": -3,
      "name": "Soil_Dirt"
    },
    {
      "x": -9,
      "y": 0,
      "z": -2,
      "name": "Soil_Dirt"
    },
    {
      "x": -9,
      "y": 0,
      "z": -1,
      "name": "Soil_Dirt"
    },
    {
      "x": -9,
      "y": 0,
      "z": 0,
      "name": "Soil_Dirt"
    },
    {
      "x": -9,
      "y": 0,
      "z": 1,
      "name": "Soil_Dirt"
    },
    {
      "x": -9,
      "y": 0,
      "z": 2,
      "name": "Soil_Dirt"
    },
    {
      "x": -9,
      "y": 0,
      "z": 3,
      "name": "Soil_Dirt"
    },
    {
      "x": -9,
      "y": 0,
      "z": 4,
      "name": "Soil_Dirt"
    },
    {
      "x": -9,
      "y": 0,
      "z": 5,
      "name": "Soil_Dirt"
    },
    {
      "x": -9,
      "y": 0,
      "z": 6,
      "name": "Soil_Dirt"
    },
    {
      "x": -9,
      "y": 0,
      "z": 7,
      "name": "Soil_Dirt"
    },
    {
      "x": -9,
      "y": 0,
      "z": 8,
      "name": "Soil_Dirt"
    },
    {
      "x": -9,
      "y": 0,
      "z": 9,
      "name": "Soil_Dirt"
    },
    {
      "x": -9,
      "y": 0,
      "z": 10,
      "name": "Soil_Dirt"
    },
    {
      "x": -9,
      "y": 0,
      "z": 11,
      "name": "Soil_Dirt"
    },
    {
      "x": -9,
      "y": 0,
      "z": 12,
      "name": "Soil_Dirt"
    },
    {
      "x": -9,
      "y": 0,
      "z": 13,
      "name": "Soil_Dirt"
    },
    {
      "x": -9,
      "y": 0,
      "z": 14,
      "name": "Soil_Dirt"
    },
    {
      "x": -9,
      "y": 0,
      "z": 15,
      "name": "Soil_Dirt"
    },
    {
      "x": -9,
      "y": 0,
      "z": 16,
      "name": "Soil_Dirt"
    },
    {
      "x": -8,
      "y": 0,
      "z": -12,
      "name": "Soil_Dirt"
    },
    {
      "x": -8,
      "y": 0,
      "z": -11,
      "name": "Soil_Dirt"
    },
    {
      "x": -8,
      "y": 0,
      "z": -10,
      "name": "Soil_Dirt"
    },
    {
      "x": -8,
      "y": 0,
      "z": -9,
      "name": "Soil_Dirt"
    },
    {
      "x": -8,
      "y": 0,
      "z": -8,
      "name": "Soil_Dirt"
    },
    {
      "x": -8,
      "y": 0,
      "z": -7,
      "name": "Soil_Dirt"
    },
    {
      "x": -8,
      "y": 0,
      "z": -6,
      "name": "Soil_Dirt"
    },
    {
      "x": -8,
      "y": 0,
      "z": -5,
      "name": "Soil_Dirt"
    },
    {
      "x": -8,
      "y": 0,
      "z": -4,
      "name": "Soil_Dirt"
    },
    {
      "x": -8,
      "y": 0,
      "z": -3,
      "name": "Soil_Dirt"
    },
    {
      "x": -8,
      "y": 0,
      "z": -2,
      "name": "Soil_Dirt"
    },
    {
      "x": -8,
      "y": 0,
      "z": -1,
      "name": "Soil_Dirt"
    },
    {
      "x": -8,
      "y": 0,
      "z": 0,
      "name": "Soil_Dirt"
    },
    {
      "x": -8,
      "y": 0,
      "z": 1,
      "name": "Soil_Dirt"
    },
    {
      "x": -8,
      "y": 0,
      "z": 2,
      "name": "Soil_Dirt"
    },
    {
      "x": -8,
      "y": 0,
      "z": 3,
      "name": "Soil_Dirt"
    },
    {
      "x": -8,
      "y": 0,
      "z": 4,
      "name": "Soil_Dirt"
    },
    {
      "x": -8,
      "y": 0,
      "z": 5,
      "name": "Soil_Dirt"
    },
    {
      "x": -8,
      "y": 0,
      "z": 6,
      "name": "Soil_Dirt"
    },
    {
      "x": -8,
      "y": 0,
      "z": 7,
      "name": "Soil_Dirt"
    },
    {
      "x": -8,
      "y": 0,
      "z": 8,
      "name": "Soil_Dirt"
    },
    {
      "x": -8,
      "y": 0,
      "z": 9,
      "name": "Soil_Dirt"
    },
    {
      "x": -8,
      "y": 0,
      "z": 10,
      "name": "Soil_Dirt"
    },
    {
      "x": -8,
      "y": 0,
      "z": 11,
      "name": "Soil_Dirt"
    },
    {
      "x": -8,
      "y": 0,
      "z": 12,
      "name": "Soil_Dirt"
    },
    {
      "x": -8,
      "y": 0,
      "z": 13,
      "name": "Soil_Dirt"
    },
    {
      "x": -8,
      "y": 0,
      "z": 14,
      "name": "Soil_Dirt"
    },
    {
      "x": -8,
      "y": 0,
      "z": 15,
      "name": "Soil_Dirt"
    },
    {
      "x": -8,
      "y": 0,
      "z": 16,
      "name": "Soil_Dirt"
    },
    {
      "x": -7,
      "y": 0,
      "z": -12,
      "name": "Soil_Dirt"
    },
    {
      "x": -7,
      "y": 0,
      "z": -11,
      "name": "Soil_Dirt"
    },
    {
      "x": -7,
      "y": 0,
      "z": -10,
      "name": "Soil_Dirt"
    },
    {
      "x": -7,
      "y": 0,
      "z": -9,
      "name": "Soil_Dirt"
    },
    {
      "x": -7,
      "y": 0,
      "z": -8,
      "name": "Soil_Dirt"
    },
    {
      "x": -7,
      "y": 0,
      "z": -7,
      "name": "Soil_Dirt"
    },
    {
      "x": -7,
      "y": 0,
      "z": -6,
      "name": "Soil_Dirt"
    },
    {
      "x": -7,
      "y": 0,
      "z": -5,
      "name": "Soil_Dirt"
    },
    {
      "x": -7,
      "y": 0,
      "z": -4,
      "name": "Soil_Dirt"
    },
    {
      "x": -7,
      "y": 0,
      "z": -3,
      "name": "Soil_Dirt"
    },
    {
      "x": -7,
      "y": 0,
      "z": -2,
      "name": "Soil_Dirt"
    },
    {
      "x": -7,
      "y": 0,
      "z": -1,
      "name": "Soil_Dirt"
    },
    {
      "x": -7,
      "y": 0,
      "z": 0,
      "name": "Soil_Dirt"
    },
    {
      "x": -7,
      "y": 0,
      "z": 1,
      "name": "Soil_Dirt"
    },
    {
      "x": -7,
      "y": 0,
      "z": 2,
      "name": "Soil_Dirt"
    },
    {
      "x": -7,
      "y": 0,
      "z": 3,
      "name": "Soil_Dirt"
    },
    {
      "x": -7,
      "y": 0,
      "z": 4,
      "name": "Soil_Dirt"
    },
    {
      "x": -7,
      "y": 0,
      "z": 5,
      "name": "Soil_Dirt"
    },
    {
      "x": -7,
      "y": 0,
      "z": 6,
      "name": "Soil_Dirt"
    },
    {
      "x": -7,
      "y": 0,
      "z": 7,
      "name": "Soil_Dirt"
    },
    {
      "x": -7,
      "y": 0,
      "z": 8,
      "name": "Soil_Dirt"
    },
    {
      "x": -7,
      "y": 0,
      "z": 9,
      "name": "Soil_Dirt"
    },
    {
      "x": -7,
      "y": 0,
      "z": 10,
      "name": "Soil_Dirt"
    },
    {
      "x": -7,
      "y": 0,
      "z": 11,
      "name": "Soil_Dirt"
    },
    {
      "x": -7,
      "y": 0,
      "z": 12,
      "name": "Soil_Dirt"
    },
    {
      "x": -7,
      "y": 0,
      "z": 13,
      "name": "Soil_Dirt"
    },
    {
      "x": -7,
      "y": 0,
      "z": 14,
      "name": "Soil_Dirt"
    },
    {
      "x": -7,
      "y": 0,
      "z": 15,
      "name": "Soil_Dirt"
    },
    {
      "x": -7,
      "y": 0,
      "z": 16,
      "name": "Soil_Dirt"
    },
    {
      "x": -6,
      "y": 0,
      "z": -12,
      "name": "Soil_Dirt"
    },
    {
      "x": -6,
      "y": 0,
      "z": -11,
      "name": "Soil_Dirt"
    },
    {
      "x": -6,
      "y": 0,
      "z": -10,
      "name": "Soil_Dirt"
    },
    {
      "x": -6,
      "y": 0,
      "z": -9,
      "name": "Soil_Dirt"
    },
    {
      "x": -6,
      "y": 0,
      "z": -8,
      "name": "Soil_Dirt"
    },
    {
      "x": -6,
      "y": 0,
      "z": -7,
      "name": "Soil_Dirt"
    },
    {
      "x": -6,
      "y": 0,
      "z": -6,
      "name": "Soil_Dirt"
    },
    {
      "x": -6,
      "y": 0,
      "z": -5,
      "name": "Soil_Dirt"
    },
    {
      "x": -6,
      "y": 0,
      "z": -4,
      "name": "Soil_Dirt"
    },
    {
      "x": -6,
      "y": 0,
      "z": -3,
      "name": "Soil_Dirt"
    },
    {
      "x": -6,
      "y": 0,
      "z": -2,
      "name": "Soil_Dirt"
    },
    {
      "x": -6,
      "y": 0,
      "z": -1,
      "name": "Soil_Dirt"
    },
    {
      "x": -6,
      "y": -1,
      "z": 0,
      "name": "Rock_Stone"
    },
    {
      "x": -6,
      "y": 0,
      "z": 0,
      "name": "Soil_Dirt"
    },
    {
      "x": -6,
      "y": -1,
      "z": 1,
      "name": "Rock_Stone"
    },
    {
      "x": -6,
      "y": 0,
      "z": 1,
      "name": "Soil_Dirt"
    },
    {
      "x": -6,
      "y": -2,
      "z": 2,
      "name": "Rock_Stone"
    },
    {
      "x": -6,
      "y": 0,
      "z": 2,
      "name": "Soil_Dirt"
    },
    {
      "x": -6,
      "y": -2,
      "z": 3,
      "name": "Rock_Stone"
    },
    {
      "x": -6,
      "y": 0,
      "z": 3,
      "name": "Soil_Dirt"
    },
    {
      "x": -6,
      "y": 0,
      "z": 4,
      "name": "Soil_Dirt"
    },
    {
      "x": -6,
      "y": 0,
      "z": 5,
      "name": "Soil_Dirt"
    },
    {
      "x": -6,
      "y": 0,
      "z": 6,
      "name": "Soil_Dirt"
    },
    {
      "x": -6,
      "y": 0,
      "z": 7,
      "name": "Soil_Dirt"
    },
    {
      "x": -6,
      "y": 0,
      "z": 8,
      "name": "Soil_Dirt"
    },
    {
      "x": -6,
      "y": 0,
      "z": 9,
      "name": "Soil_Dirt"
    },
    {
      "x": -6,
      "y": 0,
      "z": 10,
      "name": "Soil_Dirt"
    },
    {
      "x": -6,
      "y": 0,
      "z": 11,
      "name": "Soil_Dirt"
    },
    {
      "x": -6,
      "y": 0,
      "z": 12,
      "name": "Soil_Dirt"
    },
    {
      "x": -6,
      "y": 0,
      "z": 13,
      "name": "Soil_Dirt"
    },
    {
      "x": -6,
      "y": 0,
      "z": 14,
      "name": "Soil_Dirt"
    },
    {
      "x": -6,
      "y": 0,
      "z": 15,
      "name": "Soil_Dirt"
    },
    {
      "x": -6,
      "y": 0,
      "z": 16,
      "name": "Soil_Dirt"
    },
    {
      "x": -5,
      "y": 0,
      "z": -12,
      "name": "Soil_Dirt"
    },
    {
      "x": -5,
      "y": 0,
      "z": -11,
      "name": "Soil_Dirt"
    },
    {
      "x": -5,
      "y": 0,
      "z": -10,
      "name": "Soil_Dirt"
    },
    {
      "x": -5,
      "y": 0,
      "z": -9,
      "name": "Soil_Dirt"
    },
    {
      "x": -5,
      "y": 0,
      "z": -8,
      "name": "Soil_Dirt"
    },
    {
      "x": -5,
      "y": 0,
      "z": -7,
      "name": "Soil_Dirt"
    },
    {
      "x": -5,
      "y": 0,
      "z": -6,
      "name": "Soil_Dirt"
    },
    {
      "x": -5,
      "y": 0,
      "z": -5,
      "name": "Soil_Dirt"
    },
    {
      "x": -5,
      "y": 0,
      "z": -4,
      "name": "Soil_Dirt"
    },
    {
      "x": -5,
      "y": 0,
      "z": -3,
      "name": "Soil_Dirt"
    },
    {
      "x": -5,
      "y": -1,
      "z": -2,
      "name": "Rock_Stone"
    },
    {
      "x": -5,
      "y": 0,
      "z": -2,
      "name": "Soil_Dirt"
    },
    {
      "x": -5,
      "y": -3,
      "z": -1,
      "name": "Rock_Stone"
    },
    {
      "x": -5,
      "y": -2,
      "z": -1,
      "name": "Rock_Stone"
    },
    {
      "x": -5,
      "y": -1,
      "z": -1,
      "name": "Rock_Stone"
    },
    {
      "x": -5,
      "y": 0,
      "z": -1,
      "name": "Soil_Dirt"
    },
    {
      "x": -5,
      "y": -3,
      "z": 0,
      "name": "Rock_Stone"
    },
    {
      "x": -5,
      "y": 0,
      "z": 0,
      "name": "Soil_Dirt"
    },
    {
      "x": -5,
      "y": -1,
      "z": 1,
      "name": "Rock_Stone"
    },
    {
      "x": -5,
      "y": 0,
      "z": 1,
      "name": "Soil_Dirt"
    },
    {
      "x": -5,
      "y": -4,
      "z": 2,
      "name": "Rock_Stone"
    },
    {
      "x": -5,
      "y": -3,
      "z": 2,
      "name": "Rock_Stone"
    },
    {
      "x": -5,
      "y": -2,
      "z": 2,
      "name": "Rock_Stone"
    },
    {
      "x": -5,
      "y": -1,
      "z": 2,
      "name": "Rock_Stone"
    },
    {
      "x": -5,
      "y": 0,
      "z": 2,
      "name": "Soil_Dirt"
    },
    {
      "x": -5,
      "y": -4,
      "z": 3,
      "name": "Rock_Stone"
    },
    {
      "x": -5,
      "y": -3,
      "z": 3,
      "name": "Rock_Stone"
    },
    {
      "x": -5,
      "y": -1,
      "z": 3,
      "name": "Rock_Stone"
    },
    {
      "x": -5,
      "y": 0,
      "z": 3,
      "name": "Soil_Dirt"
    },
    {
      "x": -5,
      "y": -3,
      "z": 4,
      "name": "Rock_Stone"
    },
    {
      "x": -5,
      "y": -2,
      "z": 4,
      "name": "Rock_Stone"
    },
    {
      "x": -5,
      "y": -1,
      "z": 4,
      "name": "Rock_Stone"
    },
    {
      "x": -5,
      "y": 0,
      "z": 4,
      "name": "Soil_Dirt"
    },
    {
      "x": -5,
      "y": 0,
      "z": 5,
      "name": "Soil_Dirt"
    },
    {
      "x": -5,
      "y": -1,
      "z": 6,
      "name": "Rock_Stone"
    },
    {
      "x": -5,
      "y": 0,
      "z": 6,
      "name": "Soil_Dirt"
    },
    {
      "x": -5,
      "y": 0,
      "z": 7,
      "name": "Soil_Dirt"
    },
    {
      "x": -5,
      "y": 0,
      "z": 8,
      "name": "Soil_Dirt"
    },
    {
      "x": -5,
      "y": 0,
      "z": 9,
      "name": "Soil_Dirt"
    },
    {
      "x": -5,
      "y": 0,
      "z": 10,
      "name": "Soil_Dirt"
    },
    {
      "x": -5,
      "y": 0,
      "z": 11,
      "name": "Soil_Dirt"
    },
    {
      "x": -5,
      "y": 0,
      "z": 12,
      "name": "Soil_Dirt"
    },
    {
      "x": -5,
      "y": 0,
      "z": 13,
      "name": "Soil_Dirt"
    },
    {
      "x": -5,
      "y": 0,
      "z": 14,
      "name": "Soil_Dirt"
    },
    {
      "x": -5,
      "y": 0,
      "z": 15,
      "name": "Soil_Dirt"
    },
    {
      "x": -5,
      "y": 0,
      "z": 16,
      "name": "Soil_Dirt"
    },
    {
      "x": -4,
      "y": 0,
      "z": -12,
      "name": "Soil_Dirt"
    },
    {
      "x": -4,
      "y": 0,
      "z": -11,
      "name": "Soil_Dirt"
    },
    {
      "x": -4,
      "y": 0,
      "z": -10,
      "name": "Soil_Dirt"
    },
    {
      "x": -4,
      "y": 0,
      "z": -9,
      "name": "Soil_Dirt"
    },
    {
      "x": -4,
      "y": 0,
      "z": -8,
      "name": "Soil_Dirt"
    },
    {
      "x": -4,
      "y": 0,
      "z": -7,
      "name": "Soil_Dirt"
    },
    {
      "x": -4,
      "y": 0,
      "z": -6,
      "name": "Soil_Dirt"
    },
    {
      "x": -4,
      "y": 0,
      "z": -5,
      "name": "Soil_Dirt"
    },
    {
      "x": -4,
      "y": 0,
      "z": -4,
      "name": "Soil_Dirt"
    },
    {
      "x": -4,
      "y": 0,
      "z": -3,
      "name": "Soil_Dirt"
    },
    {
      "x": -4,
      "y": 0,
      "z": -2,
      "name": "Soil_Dirt"
    },
    {
      "x": -4,
      "y": 0,
      "z": -1,
      "name": "Soil_Dirt"
    },
    {
      "x": -4,
      "y": -1,
      "z": 0,
      "name": "Rock_Stone"
    },
    {
      "x": -4,
      "y": 0,
      "z": 0,
      "name": "Soil_Dirt"
    },
    {
      "x": -4,
      "y": 0,
      "z": 1,
      "name": "Soil_Dirt"
    },
    {
      "x": -4,
      "y": -3,
      "z": 2,
      "name": "Rock_Stone"
    },
    {
      "x": -4,
      "y": 0,
      "z": 2,
      "name": "Soil_Dirt"
    },
    {
      "x": -4,
      "y": -5,
      "z": 3,
      "name": "Rock_Stone"
    },
    {
      "x": -4,
      "y": 0,
      "z": 3,
      "name": "Soil_Dirt"
    },
    {
      "x": -4,
      "y": -4,
      "z": 4,
      "name": "Rock_Stone"
    },
    {
      "x": -4,
      "y": -1,
      "z": 4,
      "name": "Rock_Stone"
    },
    {
      "x": -4,
      "y": 0,
      "z": 4,
      "name": "Soil_Dirt"
    },
    {
      "x": -4,
      "y": -3,
      "z": 5,
      "name": "Rock_Stone"
    },
    {
      "x": -4,
      "y": -1,
      "z": 5,
      "name": "Rock_Stone"
    },
    {
      "x": -4,
      "y": 0,
      "z": 5,
      "name": "Soil_Dirt"
    },
    {
      "x": -4,
      "y": -3,
      "z": 6,
      "name": "Rock_Stone"
    },
    {
      "x": -4,
      "y": -2,
      "z": 6,
      "name": "Rock_Stone"
    },
    {
      "x": -4,
      "y": 0,
      "z": 6,
      "name": "Soil_Dirt"
    },
    {
      "x": -4,
      "y": -1,
      "z": 7,
      "name": "Rock_Stone"
    },
    {
      "x": -4,
      "y": 0,
      "z": 7,
      "name": "Soil_Dirt"
    },
    {
      "x": -4,
      "y": 0,
      "z": 8,
      "name": "Soil_Dirt"
    },
    {
      "x": -4,
      "y": 0,
      "z": 9,
      "name": "Soil_Dirt"
    },
    {
      "x": -4,
      "y": 0,
      "z": 10,
      "name": "Soil_Dirt"
    },
    {
      "x": -4,
      "y": 0,
      "z": 11,
      "name": "Soil_Dirt"
    },
    {
      "x": -4,
      "y": 0,
      "z": 12,
      "name": "Soil_Dirt"
    },
    {
      "x": -4,
      "y": 0,
      "z": 13,
      "name": "Soil_Dirt"
    },
    {
      "x": -4,
      "y": 0,
      "z": 14,
      "name": "Soil_Dirt"
    },
    {
      "x": -4,
      "y": 0,
      "z": 15,
      "name": "Soil_Dirt"
    },
    {
      "x": -4,
      "y": 0,
      "z": 16,
      "name": "Soil_Dirt"
    },
    {
      "x": -3,
      "y": 0,
      "z": -12,
      "name": "Soil_Dirt"
    },
    {
      "x": -3,
      "y": 0,
      "z": -11,
      "name": "Soil_Dirt"
    },
    {
      "x": -3,
      "y": 0,
      "z": -10,
      "name": "Soil_Dirt"
    },
    {
      "x": -3,
      "y": 0,
      "z": -9,
      "name": "Soil_Dirt"
    },
    {
      "x": -3,
      "y": 0,
      "z": -8,
      "name": "Soil_Dirt"
    },
    {
      "x": -3,
      "y": 0,
      "z": -7,
      "name": "Soil_Dirt"
    },
    {
      "x": -3,
      "y": 0,
      "z": -6,
      "name": "Soil_Dirt"
    },
    {
      "x": -3,
      "y": 0,
      "z": -5,
      "name": "Soil_Dirt"
    },
    {
      "x": -3,
      "y": 0,
      "z": -4,
      "name": "Soil_Dirt"
    },
    {
      "x": -3,
      "y": -2,
      "z": -3,
      "name": "Rock_Stone"
    },
    {
      "x": -3,
      "y": -1,
      "z": -3,
      "name": "Rock_Stone"
    },
    {
      "x": -3,
      "y": 0,
      "z": -3,
      "name": "Soil_Dirt"
    },
    {
      "x": -3,
      "y": -4,
      "z": -2,
      "name": "Rock_Stone"
    },
    {
      "x": -3,
      "y": -3,
      "z": -2,
      "name": "Rock_Stone"
    },
    {
      "x": -3,
      "y": -2,
      "z": -2,
      "name": "Rock_Stone"
    },
    {
      "x": -3,
      "y": -1,
      "z": -2,
      "name": "Rock_Stone"
    },
    {
      "x": -3,
      "y": 0,
      "z": -2,
      "name": "Soil_Dirt"
    },
    {
      "x": -3,
      "y": -5,
      "z": -1,
      "name": "Rock_Stone"
    },
    {
      "x": -3,
      "y": -4,
      "z": -1,
      "name": "Rock_Stone"
    },
    {
      "x": -3,
      "y": -2,
      "z": -1,
      "name": "Rock_Stone"
    },
    {
      "x": -3,
      "y": 0,
      "z": -1,
      "name": "Soil_Dirt"
    },
    {
      "x": -3,
      "y": -5,
      "z": 0,
      "name": "Rock_Stone"
    },
    {
      "x": -3,
      "y": -4,
      "z": 0,
      "name": "Rock_Stone"
    },
    {
      "x": -3,
      "y": -3,
      "z": 0,
      "name": "Rock_Stone"
    },
    {
      "x": -3,
      "y": -1,
      "z": 0,
      "name": "Rock_Stone"
    },
    {
      "x": -3,
      "y": 0,
      "z": 0,
      "name": "Soil_Dirt"
    },
    {
      "x": -3,
      "y": -4,
      "z": 1,
      "name": "Rock_Stone"
    },
    {
      "x": -3,
      "y": -2,
      "z": 1,
      "name": "Rock_Stone"
    },
    {
      "x": -3,
      "y": -1,
      "z": 1,
      "name": "Rock_Stone"
    },
    {
      "x": -3,
      "y": 0,
      "z": 1,
      "name": "Soil_Dirt"
    },
    {
      "x": -3,
      "y": -5,
      "z": 2,
      "name": "Rock_Stone"
    },
    {
      "x": -3,
      "y": -3,
      "z": 2,
      "name": "Rock_Stone"
    },
    {
      "x": -3,
      "y": -2,
      "z": 2,
      "name": "Rock_Stone"
    },
    {
      "x": -3,
      "y": -1,
      "z": 2,
      "name": "Rock_Stone"
    },
    {
      "x": -3,
      "y": 0,
      "z": 2,
      "name": "Soil_Dirt"
    },
    {
      "x": -3,
      "y": -5,
      "z": 3,
      "name": "Rock_Stone"
    },
    {
      "x": -3,
      "y": -4,
      "z": 3,
      "name": "Rock_Stone"
    },
    {
      "x": -3,
      "y": -1,
      "z": 3,
      "name": "Rock_Stone"
    },
    {
      "x": -3,
      "y": 0,
      "z": 3,
      "name": "Soil_Dirt"
    },
    {
      "x": -3,
      "y": -3,
      "z": 4,
      "name": "Rock_Stone"
    },
    {
      "x": -3,
      "y": 0,
      "z": 4,
      "name": "Soil_Dirt"
    },
    {
      "x": -3,
      "y": -4,
      "z": 5,
      "name": "Rock_Stone"
    },
    {
      "x": -3,
      "y": -3,
      "z": 5,
      "name": "Rock_Stone"
    },
    {
      "x": -3,
      "y": -2,
      "z": 5,
      "name": "Rock_Stone"
    },
    {
      "x": -3,
      "y": 0,
      "z": 5,
      "name": "Soil_Dirt"
    },
    {
      "x": -3,
      "y": -2,
      "z": 6,
      "name": "Rock_Stone"
    },
    {
      "x": -3,
      "y": -1,
      "z": 6,
      "name": "Rock_Stone"
    },
    {
      "x": -3,
      "y": 0,
      "z": 6,
      "name": "Soil_Dirt"
    },
    {
      "x": -3,
      "y": -2,
      "z": 7,
      "name": "Rock_Stone"
    },
    {
      "x": -3,
      "y": 0,
      "z": 7,
      "name": "Soil_Dirt"
    },
    {
      "x": -3,
      "y": 0,
      "z": 8,
      "name": "Soil_Dirt"
    },
    {
      "x": -3,
      "y": 0,
      "z": 9,
      "name": "Soil_Dirt"
    },
    {
      "x": -3,
      "y": 0,
      "z": 10,
      "name": "Soil_Dirt"
    },
    {
      "x": -3,
      "y": 0,
      "z": 11,
      "name": "Soil_Dirt"
    },
    {
      "x": -3,
      "y": 0,
      "z": 12,
      "name": "Soil_Dirt"
    },
    {
      "x": -3,
      "y": 0,
      "z": 13,
      "name": "Soil_Dirt"
    },
    {
      "x": -3,
      "y": 0,
      "z": 14,
      "name": "Soil_Dirt"
    },
    {
      "x": -3,
      "y": 0,
      "z": 15,
      "name": "Soil_Dirt"
    },
    {
      "x": -3,
      "y": 0,
      "z": 16,
      "name": "Soil_Dirt"
    },
    {
      "x": -2,
      "y": 0,
      "z": -12,
      "name": "Soil_Dirt"
    },
    {
      "x": -2,
      "y": 0,
      "z": -11,
      "name": "Soil_Dirt"
    },
    {
      "x": -2,
      "y": 0,
      "z": -10,
      "name": "Soil_Dirt"
    },
    {
      "x": -2,
      "y": 0,
      "z": -9,
      "name": "Soil_Dirt"
    },
    {
      "x": -2,
      "y": 0,
      "z": -8,
      "name": "Soil_Dirt"
    },
    {
      "x": -2,
      "y": 0,
      "z": -7,
      "name": "Soil_Dirt"
    },
    {
      "x": -2,
      "y": 0,
      "z": -6,
      "name": "Soil_Dirt"
    },
    {
      "x": -2,
      "y": 0,
      "z": -5,
      "name": "Soil_Dirt"
    },
    {
      "x": -2,
      "y": 0,
      "z": -4,
      "name": "Soil_Dirt"
    },
    {
      "x": -2,
      "y": -3,
      "z": -3,
      "name": "Rock_Stone"
    },
    {
      "x": -2,
      "y": -2,
      "z": -3,
      "name": "Rock_Stone"
    },
    {
      "x": -2,
      "y": -1,
      "z": -3,
      "name": "Rock_Stone"
    },
    {
      "x": -2,
      "y": 0,
      "z": -3,
      "name": "Soil_Dirt"
    },
    {
      "x": -2,
      "y": -4,
      "z": -2,
      "name": "Rock_Stone"
    },
    {
      "x": -2,
      "y": -2,
      "z": -2,
      "name": "Rock_Stone"
    },
    {
      "x": -2,
      "y": -1,
      "z": -2,
      "name": "Rock_Stone"
    },
    {
      "x": -2,
      "y": 0,
      "z": -2,
      "name": "Soil_Dirt"
    },
    {
      "x": -2,
      "y": -4,
      "z": -1,
      "name": "Rock_Stone"
    },
    {
      "x": -2,
      "y": -3,
      "z": -1,
      "name": "Rock_Stone"
    },
    {
      "x": -2,
      "y": -2,
      "z": -1,
      "name": "Rock_Stone"
    },
    {
      "x": -2,
      "y": 0,
      "z": -1,
      "name": "Soil_Dirt"
    },
    {
      "x": -2,
      "y": -3,
      "z": 0,
      "name": "Rock_Stone"
    },
    {
      "x": -2,
      "y": -2,
      "z": 0,
      "name": "Rock_Stone"
    },
    {
      "x": -2,
      "y": -1,
      "z": 0,
      "name": "Rock_Stone"
    },
    {
      "x": -2,
      "y": 0,
      "z": 0,
      "name": "Soil_Dirt"
    },
    {
      "x": -2,
      "y": -5,
      "z": 1,
      "name": "Rock_Stone"
    },
    {
      "x": -2,
      "y": 0,
      "z": 1,
      "name": "Soil_Dirt"
    },
    {
      "x": -2,
      "y": -3,
      "z": 2,
      "name": "Rock_Stone"
    },
    {
      "x": -2,
      "y": -2,
      "z": 2,
      "name": "Rock_Stone"
    },
    {
      "x": -2,
      "y": 0,
      "z": 2,
      "name": "Soil_Dirt"
    },
    {
      "x": -2,
      "y": -4,
      "z": 3,
      "name": "Rock_Stone"
    },
    {
      "x": -2,
      "y": -2,
      "z": 3,
      "name": "Rock_Stone"
    },
    {
      "x": -2,
      "y": -1,
      "z": 3,
      "name": "Rock_Stone"
    },
    {
      "x": -2,
      "y": 0,
      "z": 3,
      "name": "Soil_Dirt"
    },
    {
      "x": -2,
      "y": -5,
      "z": 4,
      "name": "Rock_Stone"
    },
    {
      "x": -2,
      "y": -2,
      "z": 4,
      "name": "Rock_Stone"
    },
    {
      "x": -2,
      "y": -1,
      "z": 4,
      "name": "Rock_Stone"
    },
    {
      "x": -2,
      "y": 0,
      "z": 4,
      "name": "Soil_Dirt"
    },
    {
      "x": -2,
      "y": -3,
      "z": 5,
      "name": "Rock_Stone"
    },
    {
      "x": -2,
      "y": 0,
      "z": 5,
      "name": "Soil_Dirt"
    },
    {
      "x": -2,
      "y": 0,
      "z": 6,
      "name": "Soil_Dirt"
    },
    {
      "x": -2,
      "y": -3,
      "z": 7,
      "name": "Rock_Stone"
    },
    {
      "x": -2,
      "y": -1,
      "z": 7,
      "name": "Rock_Stone"
    },
    {
      "x": -2,
      "y": 0,
      "z": 7,
      "name": "Soil_Dirt"
    },
    {
      "x": -2,
      "y": -1,
      "z": 8,
      "name": "Rock_Stone"
    },
    {
      "x": -2,
      "y": 0,
      "z": 8,
      "name": "Soil_Dirt"
    },
    {
      "x": -2,
      "y": 0,
      "z": 9,
      "name": "Soil_Dirt"
    },
    {
      "x": -2,
      "y": 0,
      "z": 10,
      "name": "Soil_Dirt"
    },
    {
      "x": -2,
      "y": 0,
      "z": 11,
      "name": "Soil_Dirt"
    },
    {
      "x": -2,
      "y": 0,
      "z": 12,
      "name": "Soil_Dirt"
    },
    {
      "x": -2,
      "y": 0,
      "z": 13,
      "name": "Soil_Dirt"
    },
    {
      "x": -2,
      "y": 0,
      "z": 14,
      "name": "Soil_Dirt"
    },
    {
      "x": -2,
      "y": 0,
      "z": 15,
      "name": "Soil_Dirt"
    },
    {
      "x": -2,
      "y": 0,
      "z": 16,
      "name": "Soil_Dirt"
    },
    {
      "x": -1,
      "y": 0,
      "z": -12,
      "name": "Soil_Dirt"
    },
    {
      "x": -1,
      "y": 0,
      "z": -11,
      "name": "Soil_Dirt"
    },
    {
      "x": -1,
      "y": 0,
      "z": -10,
      "name": "Soil_Dirt"
    },
    {
      "x": -1,
      "y": 0,
      "z": -9,
      "name": "Soil_Dirt"
    },
    {
      "x": -1,
      "y": 0,
      "z": -8,
      "name": "Soil_Dirt"
    },
    {
      "x": -1,
      "y": 0,
      "z": -7,
      "name": "Soil_Dirt"
    },
    {
      "x": -1,
      "y": 0,
      "z": -6,
      "name": "Soil_Dirt"
    },
    {
      "x": -1,
      "y": 0,
      "z": -5,
      "name": "Soil_Dirt"
    },
    {
      "x": -1,
      "y": -1,
      "z": -4,
      "name": "Rock_Stone"
    },
    {
      "x": -1,
      "y": 0,
      "z": -4,
      "name": "Soil_Dirt"
    },
    {
      "x": -1,
      "y": -3,
      "z": -3,
      "name": "Rock_Stone"
    },
    {
      "x": -1,
      "y": 0,
      "z": -3,
      "name": "Soil_Dirt"
    },
    {
      "x": -1,
      "y": -4,
      "z": -2,
      "name": "Rock_Stone"
    },
    {
      "x": -1,
      "y": -3,
      "z": -2,
      "name": "Rock_Stone"
    },
    {
      "x": -1,
      "y": -1,
      "z": -2,
      "name": "Rock_Stone"
    },
    {
      "x": -1,
      "y": 0,
      "z": -2,
      "name": "Soil_Dirt"
    },
    {
      "x": -1,
      "y": -2,
      "z": -1,
      "name": "Rock_Stone"
    },
    {
      "x": -1,
      "y": 0,
      "z": -1,
      "name": "Soil_Dirt"
    },
    {
      "x": -1,
      "y": 1,
      "z": -1,
      "name": "Soil_Dirt"
    },
    {
      "x": -1,
      "y": 2,
      "z": -1,
      "name": "Soil_Dirt"
    },
    {
      "x": -1,
      "y": 3,
      "z": -1,
      "name": "Soil_Dirt"
    },
    {
      "x": -1,
      "y": 4,
      "z": -1,
      "name": "Soil_Dirt"
    },
    {
      "x": -1,
      "y": 5,
      "z": -1,
      "name": "Soil_Dirt"
    },
    {
      "x": -1,
      "y": 6,
      "z": -1,
      "name": "Soil_Dirt"
    },
    {
      "x": -1,
      "y": 7,
      "z": -1,
      "name": "Soil_Dirt"
    },
    {
      "x": -1,
      "y": 8,
      "z": -1,
      "name": "Soil_Dirt"
    },
    {
      "x": -1,
      "y": 9,
      "z": -1,
      "name": "Soil_Dirt"
    },
    {
      "x": -1,
      "y": 10,
      "z": -1,
      "name": "Soil_Dirt"
    },
    {
      "x": -1,
      "y": 11,
      "z": -1,
      "name": "Soil_Dirt"
    },
    {
      "x": -1,
      "y": 12,
      "z": -1,
      "name": "Soil_Dirt"
    },
    {
      "x": -1,
      "y": 13,
      "z": -1,
      "name": "Soil_Dirt"
    },
    {
      "x": -1,
      "y": 14,
      "z": -1,
      "name": "Soil_Dirt"
    },
    {
      "x": -1,
      "y": 15,
      "z": -1,
      "name": "Soil_Dirt"
    },
    {
      "x": -1,
      "y": 16,
      "z": -1,
      "name": "Soil_Dirt"
    },
    {
      "x": -1,
      "y": 17,
      "z": -1,
      "name": "Soil_Dirt"
    },
    {
      "x": -1,
      "y": 18,
      "z": -1,
      "name": "Soil_Dirt"
    },
    {
      "x": -1,
      "y": 19,
      "z": -1,
      "name": "Soil_Dirt"
    },
    {
      "x": -1,
      "y": 20,
      "z": -1,
      "name": "Soil_Dirt"
    },
    {
      "x": -1,
      "y": 21,
      "z": -1,
      "name": "Soil_Dirt"
    },
    {
      "x": -1,
      "y": -5,
      "z": 0,
      "name": "Rock_Stone"
    },
    {
      "x": -1,
      "y": -2,
      "z": 0,
      "name": "Rock_Stone"
    },
    {
      "x": -1,
      "y": 0,
      "z": 0,
      "name": "Soil_Dirt"
    },
    {
      "x": -1,
      "y": 1,
      "z": 0,
      "name": "Soil_Dirt"
    },
    {
      "x": -1,
      "y": 2,
      "z": 0,
      "name": "Soil_Dirt"
    },
    {
      "x": -1,
      "y": 3,
      "z": 0,
      "name": "Soil_Dirt"
    },
    {
      "x": -1,
      "y": 4,
      "z": 0,
      "name": "Soil_Dirt"
    },
    {
      "x": -1,
      "y": 5,
      "z": 0,
      "name": "Soil_Dirt"
    },
    {
      "x": -1,
      "y": 6,
      "z": 0,
      "name": "Soil_Dirt"
    },
    {
      "x": -1,
      "y": 7,
      "z": 0,
      "name": "Soil_Dirt"
    },
    {
      "x": -1,
      "y": 8,
      "z": 0,
      "name": "Soil_Dirt"
    },
    {
      "x": -1,
      "y": 9,
      "z": 0,
      "name": "Soil_Dirt"
    },
    {
      "x": -1,
      "y": 10,
      "z": 0,
      "name": "Soil_Dirt"
    },
    {
      "x": -1,
      "y": 11,
      "z": 0,
      "name": "Soil_Dirt"
    },
    {
      "x": -1,
      "y": 12,
      "z": 0,
      "name": "Soil_Dirt"
    },
    {
      "x": -1,
      "y": 13,
      "z": 0,
      "name": "Soil_Dirt"
    },
    {
      "x": -1,
      "y": 14,
      "z": 0,
      "name": "Soil_Dirt"
    },
    {
      "x": -1,
      "y": 15,
      "z": 0,
      "name": "Soil_Dirt"
    },
    {
      "x": -1,
      "y": 16,
      "z": 0,
      "name": "Soil_Dirt"
    },
    {
      "x": -1,
      "y": 17,
      "z": 0,
      "name": "Soil_Dirt"
    },
    {
      "x": -1,
      "y": 18,
      "z": 0,
      "name": "Soil_Dirt"
    },
    {
      "x": -1,
      "y": 19,
      "z": 0,
      "name": "Soil_Dirt"
    },
    {
      "x": -1,
      "y": 20,
      "z": 0,
      "name": "Soil_Dirt"
    },
    {
      "x": -1,
      "y": 21,
      "z": 0,
      "name": "Soil_Dirt"
    },
    {
      "x": -1,
      "y": -3,
      "z": 1,
      "name": "Rock_Stone"
    },
    {
      "x": -1,
      "y": -2,
      "z": 1,
      "name": "Rock_Stone"
    },
    {
      "x": -1,
      "y": 0,
      "z": 1,
      "name": "Soil_Dirt"
    },
    {
      "x": -1,
      "y": 1,
      "z": 1,
      "name": "Soil_Dirt"
    },
    {
      "x": -1,
      "y": 2,
      "z": 1,
      "name": "Soil_Dirt"
    },
    {
      "x": -1,
      "y": 3,
      "z": 1,
      "name": "Soil_Dirt"
    },
    {
      "x": -1,
      "y": 4,
      "z": 1,
      "name": "Soil_Dirt"
    },
    {
      "x": -1,
      "y": 5,
      "z": 1,
      "name": "Soil_Dirt"
    },
    {
      "x": -1,
      "y": 6,
      "z": 1,
      "name": "Soil_Dirt"
    },
    {
      "x": -1,
      "y": 7,
      "z": 1,
      "name": "Soil_Dirt"
    },
    {
      "x": -1,
      "y": 8,
      "z": 1,
      "name": "Soil_Dirt"
    },
    {
      "x": -1,
      "y": 9,
      "z": 1,
      "name": "Soil_Dirt"
    },
    {
      "x": -1,
      "y": 10,
      "z": 1,
      "name": "Soil_Dirt"
    },
    {
      "x": -1,
      "y": 11,
      "z": 1,
      "name": "Soil_Dirt"
    },
    {
      "x": -1,
      "y": 12,
      "z": 1,
      "name": "Soil_Dirt"
    },
    {
      "x": -1,
      "y": 13,
      "z": 1,
      "name": "Soil_Dirt"
    },
    {
      "x": -1,
      "y": 14,
      "z": 1,
      "name": "Soil_Dirt"
    },
    {
      "x": -1,
      "y": 15,
      "z": 1,
      "name": "Soil_Dirt"
    },
    {
      "x": -1,
      "y": 16,
      "z": 1,
      "name": "Soil_Dirt"
    },
    {
      "x": -1,
      "y": 17,
      "z": 1,
      "name": "Soil_Dirt"
    },
    {
      "x": -1,
      "y": 18,
      "z": 1,
      "name": "Soil_Dirt"
    },
    {
      "x": -1,
      "y": 19,
      "z": 1,
      "name": "Soil_Dirt"
    },
    {
      "x": -1,
      "y": 20,
      "z": 1,
      "name": "Soil_Dirt"
    },
    {
      "x": -1,
      "y": 21,
      "z": 1,
      "name": "Soil_Dirt"
    },
    {
      "x": -1,
      "y": -5,
      "z": 2,
      "name": "Rock_Stone"
    },
    {
      "x": -1,
      "y": -4,
      "z": 2,
      "name": "Rock_Stone"
    },
    {
      "x": -1,
      "y": -3,
      "z": 2,
      "name": "Rock_Stone"
    },
    {
      "x": -1,
      "y": -1,
      "z": 2,
      "name": "Rock_Stone"
    },
    {
      "x": -1,
      "y": 0,
      "z": 2,
      "name": "Soil_Dirt"
    },
    {
      "x": -1,
      "y": -5,
      "z": 3,
      "name": "Rock_Stone"
    },
    {
      "x": -1,
      "y": -3,
      "z": 3,
      "name": "Rock_Stone"
    },
    {
      "x": -1,
      "y": 0,
      "z": 3,
      "name": "Soil_Dirt"
    },
    {
      "x": -1,
      "y": -5,
      "z": 4,
      "name": "Rock_Stone"
    },
    {
      "x": -1,
      "y": -4,
      "z": 4,
      "name": "Rock_Stone"
    },
    {
      "x": -1,
      "y": -3,
      "z": 4,
      "name": "Rock_Stone"
    },
    {
      "x": -1,
      "y": 0,
      "z": 4,
      "name": "Soil_Dirt"
    },
    {
      "x": -1,
      "y": -5,
      "z": 5,
      "name": "Rock_Stone"
    },
    {
      "x": -1,
      "y": -4,
      "z": 5,
      "name": "Rock_Stone"
    },
    {
      "x": -1,
      "y": -3,
      "z": 5,
      "name": "Rock_Stone"
    },
    {
      "x": -1,
      "y": -2,
      "z": 5,
      "name": "Rock_Stone"
    },
    {
      "x": -1,
      "y": 0,
      "z": 5,
      "name": "Soil_Dirt"
    },
    {
      "x": -1,
      "y": -5,
      "z": 6,
      "name": "Rock_Stone"
    },
    {
      "x": -1,
      "y": 0,
      "z": 6,
      "name": "Soil_Dirt"
    },
    {
      "x": -1,
      "y": 0,
      "z": 7,
      "name": "Soil_Dirt"
    },
    {
      "x": -1,
      "y": -2,
      "z": 8,
      "name": "Rock_Stone"
    },
    {
      "x": -1,
      "y": 0,
      "z": 8,
      "name": "Soil_Dirt"
    },
    {
      "x": -1,
      "y": 0,
      "z": 9,
      "name": "Soil_Dirt"
    },
    {
      "x": -1,
      "y": 0,
      "z": 10,
      "name": "Soil_Dirt"
    },
    {
      "x": -1,
      "y": 0,
      "z": 11,
      "name": "Soil_Dirt"
    },
    {
      "x": -1,
      "y": 0,
      "z": 12,
      "name": "Soil_Dirt"
    },
    {
      "x": -1,
      "y": 0,
      "z": 13,
      "name": "Soil_Dirt"
    },
    {
      "x": -1,
      "y": 0,
      "z": 14,
      "name": "Soil_Dirt"
    },
    {
      "x": -1,
      "y": 0,
      "z": 15,
      "name": "Soil_Dirt"
    },
    {
      "x": -1,
      "y": 0,
      "z": 16,
      "name": "Soil_Dirt"
    },
    {
      "x": 0,
      "y": 0,
      "z": -12,
      "name": "Soil_Dirt"
    },
    {
      "x": 0,
      "y": 0,
      "z": -11,
      "name": "Soil_Dirt"
    },
    {
      "x": 0,
      "y": 0,
      "z": -10,
      "name": "Soil_Dirt"
    },
    {
      "x": 0,
      "y": 0,
      "z": -9,
      "name": "Soil_Dirt"
    },
    {
      "x": 0,
      "y": 0,
      "z": -8,
      "name": "Soil_Dirt"
    },
    {
      "x": 0,
      "y": 0,
      "z": -7,
      "name": "Soil_Dirt"
    },
    {
      "x": 0,
      "y": 0,
      "z": -6,
      "name": "Soil_Dirt"
    },
    {
      "x": 0,
      "y": 0,
      "z": -5,
      "name": "Soil_Dirt"
    },
    {
      "x": 0,
      "y": 0,
      "z": -4,
      "name": "Soil_Dirt"
    },
    {
      "x": 0,
      "y": -4,
      "z": -3,
      "name": "Rock_Stone"
    },
    {
      "x": 0,
      "y": 0,
      "z": -3,
      "name": "Soil_Dirt"
    },
    {
      "x": 0,
      "y": -5,
      "z": -2,
      "name": "Rock_Stone"
    },
    {
      "x": 0,
      "y": -2,
      "z": -2,
      "name": "Rock_Stone"
    },
    {
      "x": 0,
      "y": 0,
      "z": -2,
      "name": "Soil_Dirt"
    },
    {
      "x": 0,
      "y": -5,
      "z": -1,
      "name": "Rock_Stone"
    },
    {
      "x": 0,
      "y": -4,
      "z": -1,
      "name": "Rock_Stone"
    },
    {
      "x": 0,
      "y": -3,
      "z": -1,
      "name": "Rock_Stone"
    },
    {
      "x": 0,
      "y": 0,
      "z": -1,
      "name": "Soil_Dirt"
    },
    {
      "x": 0,
      "y": 1,
      "z": -1,
      "name": "Soil_Dirt"
    },
    {
      "x": 0,
      "y": 2,
      "z": -1,
      "name": "Soil_Dirt"
    },
    {
      "x": 0,
      "y": 3,
      "z": -1,
      "name": "Soil_Dirt"
    },
    {
      "x": 0,
      "y": 4,
      "z": -1,
      "name": "Soil_Dirt"
    },
    {
      "x": 0,
      "y": 5,
      "z": -1,
      "name": "Soil_Dirt"
    },
    {
      "x": 0,
      "y": 6,
      "z": -1,
      "name": "Soil_Dirt"
    },
    {
      "x": 0,
      "y": 7,
      "z": -1,
      "name": "Soil_Dirt"
    },
    {
      "x": 0,
      "y": 8,
      "z": -1,
      "name": "Soil_Dirt"
    },
    {
      "x": 0,
      "y": 9,
      "z": -1,
      "name": "Soil_Dirt"
    },
    {
      "x": 0,
      "y": 10,
      "z": -1,
      "name": "Soil_Dirt"
    },
    {
      "x": 0,
      "y": 11,
      "z": -1,
      "name": "Soil_Dirt"
    },
    {
      "x": 0,
      "y": 12,
      "z": -1,
      "name": "Soil_Dirt"
    },
    {
      "x": 0,
      "y": 13,
      "z": -1,
      "name": "Soil_Dirt"
    },
    {
      "x": 0,
      "y": 14,
      "z": -1,
      "name": "Soil_Dirt"
    },
    {
      "x": 0,
      "y": 15,
      "z": -1,
      "name": "Soil_Dirt"
    },
    {
      "x": 0,
      "y": 16,
      "z": -1,
      "name": "Soil_Dirt"
    },
    {
      "x": 0,
      "y": 17,
      "z": -1,
      "name": "Soil_Dirt"
    },
    {
      "x": 0,
      "y": 18,
      "z": -1,
      "name": "Soil_Dirt"
    },
    {
      "x": 0,
      "y": 19,
      "z": -1,
      "name": "Soil_Dirt"
    },
    {
      "x": 0,
      "y": 20,
      "z": -1,
      "name": "Soil_Dirt"
    },
    {
      "x": 0,
      "y": 21,
      "z": -1,
      "name": "Soil_Dirt"
    },
    {
      "x": 0,
      "y": -4,
      "z": 0,
      "name": "Rock_Stone"
    },
    {
      "x": 0,
      "y": -3,
      "z": 0,
      "name": "Rock_Stone"
    },
    {
      "x": 0,
      "y": -2,
      "z": 0,
      "name": "Rock_Stone"
    },
    {
      "x": 0,
      "y": -1,
      "z": 0,
      "name": "Rock_Stone"
    },
    {
      "x": 0,
      "y": 0,
      "z": 0,
      "name": "Soil_Dirt"
    },
    {
      "x": 0,
      "y": 1,
      "z": 0,
      "name": "Soil_Dirt"
    },
    {
      "x": 0,
      "y": 2,
      "z": 0,
      "name": "Soil_Dirt"
    },
    {
      "x": 0,
      "y": 3,
      "z": 0,
      "name": "Soil_Dirt"
    },
    {
      "x": 0,
      "y": 4,
      "z": 0,
      "name": "Soil_Dirt"
    },
    {
      "x": 0,
      "y": 5,
      "z": 0,
      "name": "Soil_Dirt"
    },
    {
      "x": 0,
      "y": 6,
      "z": 0,
      "name": "Soil_Dirt"
    },
    {
      "x": 0,
      "y": 7,
      "z": 0,
      "name": "Soil_Dirt"
    },
    {
      "x": 0,
      "y": 8,
      "z": 0,
      "name": "Soil_Dirt"
    },
    {
      "x": 0,
      "y": 9,
      "z": 0,
      "name": "Soil_Dirt"
    },
    {
      "x": 0,
      "y": 10,
      "z": 0,
      "name": "Soil_Dirt"
    },
    {
      "x": 0,
      "y": 11,
      "z": 0,
      "name": "Soil_Dirt"
    },
    {
      "x": 0,
      "y": 12,
      "z": 0,
      "name": "Soil_Dirt"
    },
    {
      "x": 0,
      "y": 13,
      "z": 0,
      "name": "Soil_Dirt"
    },
    {
      "x": 0,
      "y": 14,
      "z": 0,
      "name": "Soil_Dirt"
    },
    {
      "x": 0,
      "y": 15,
      "z": 0,
      "name": "Soil_Dirt"
    },
    {
      "x": 0,
      "y": 16,
      "z": 0,
      "name": "Soil_Dirt"
    },
    {
      "x": 0,
      "y": 17,
      "z": 0,
      "name": "Soil_Dirt"
    },
    {
      "x": 0,
      "y": 18,
      "z": 0,
      "name": "Soil_Dirt"
    },
    {
      "x": 0,
      "y": 19,
      "z": 0,
      "name": "Soil_Dirt"
    },
    {
      "x": 0,
      "y": 20,
      "z": 0,
      "name": "Soil_Dirt"
    },
    {
      "x": 0,
      "y": 21,
      "z": 0,
      "name": "Soil_Dirt"
    },
    {
      "x": 0,
      "y": -3,
      "z": 1,
      "name": "Rock_Stone"
    },
    {
      "x": 0,
      "y": 0,
      "z": 1,
      "name": "Soil_Dirt"
    },
    {
      "x": 0,
      "y": 1,
      "z": 1,
      "name": "Soil_Dirt"
    },
    {
      "x": 0,
      "y": 2,
      "z": 1,
      "name": "Soil_Dirt"
    },
    {
      "x": 0,
      "y": 3,
      "z": 1,
      "name": "Soil_Dirt"
    },
    {
      "x": 0,
      "y": 4,
      "z": 1,
      "name": "Soil_Dirt"
    },
    {
      "x": 0,
      "y": 5,
      "z": 1,
      "name": "Soil_Dirt"
    },
    {
      "x": 0,
      "y": 6,
      "z": 1,
      "name": "Soil_Dirt"
    },
    {
      "x": 0,
      "y": 7,
      "z": 1,
      "name": "Soil_Dirt"
    },
    {
      "x": 0,
      "y": 8,
      "z": 1,
      "name": "Soil_Dirt"
    },
    {
      "x": 0,
      "y": 9,
      "z": 1,
      "name": "Soil_Dirt"
    },
    {
      "x": 0,
      "y": 10,
      "z": 1,
      "name": "Soil_Dirt"
    },
    {
      "x": 0,
      "y": 11,
      "z": 1,
      "name": "Soil_Dirt"
    },
    {
      "x": 0,
      "y": 12,
      "z": 1,
      "name": "Soil_Dirt"
    },
    {
      "x": 0,
      "y": 13,
      "z": 1,
      "name": "Soil_Dirt"
    },
    {
      "x": 0,
      "y": 14,
      "z": 1,
      "name": "Soil_Dirt"
    },
    {
      "x": 0,
      "y": 15,
      "z": 1,
      "name": "Soil_Dirt"
    },
    {
      "x": 0,
      "y": 16,
      "z": 1,
      "name": "Soil_Dirt"
    },
    {
      "x": 0,
      "y": 17,
      "z": 1,
      "name": "Soil_Dirt"
    },
    {
      "x": 0,
      "y": 18,
      "z": 1,
      "name": "Soil_Dirt"
    },
    {
      "x": 0,
      "y": 19,
      "z": 1,
      "name": "Soil_Dirt"
    },
    {
      "x": 0,
      "y": 20,
      "z": 1,
      "name": "Soil_Dirt"
    },
    {
      "x": 0,
      "y": 21,
      "z": 1,
      "name": "Soil_Dirt"
    },
    {
      "x": 0,
      "y": -4,
      "z": 2,
      "name": "Rock_Stone"
    },
    {
      "x": 0,
      "y": -2,
      "z": 2,
      "name": "Rock_Stone"
    },
    {
      "x": 0,
      "y": 0,
      "z": 2,
      "name": "Soil_Dirt"
    },
    {
      "x": 0,
      "y": -5,
      "z": 3,
      "name": "Rock_Stone"
    },
    {
      "x": 0,
      "y": -1,
      "z": 3,
      "name": "Rock_Stone"
    },
    {
      "x": 0,
      "y": 0,
      "z": 3,
      "name": "Soil_Dirt"
    },
    {
      "x": 0,
      "y": -4,
      "z": 4,
      "name": "Rock_Stone"
    },
    {
      "x": 0,
      "y": -3,
      "z": 4,
      "name": "Rock_Stone"
    },
    {
      "x": 0,
      "y": -2,
      "z": 4,
      "name": "Rock_Stone"
    },
    {
      "x": 0,
      "y": 0,
      "z": 4,
      "name": "Soil_Dirt"
    },
    {
      "x": 0,
      "y": -5,
      "z": 5,
      "name": "Rock_Stone"
    },
    {
      "x": 0,
      "y": -3,
      "z": 5,
      "name": "Rock_Stone"
    },
    {
      "x": 0,
      "y": 0,
      "z": 5,
      "name": "Soil_Dirt"
    },
    {
      "x": 0,
      "y": -3,
      "z": 6,
      "name": "Rock_Stone"
    },
    {
      "x": 0,
      "y": -2,
      "z": 6,
      "name": "Rock_Stone"
    },
    {
      "x": 0,
      "y": -1,
      "z": 6,
      "name": "Rock_Stone"
    },
    {
      "x": 0,
      "y": 0,
      "z": 6,
      "name": "Soil_Dirt"
    },
    {
      "x": 0,
      "y": -3,
      "z": 7,
      "name": "Rock_Stone"
    },
    {
      "x": 0,
      "y": -1,
      "z": 7,
      "name": "Rock_Stone"
    },
    {
      "x": 0,
      "y": 0,
      "z": 7,
      "name": "Soil_Dirt"
    },
    {
      "x": 0,
      "y": -1,
      "z": 8,
      "name": "Rock_Stone"
    },
    {
      "x": 0,
      "y": 0,
      "z": 8,
      "name": "Soil_Dirt"
    },
    {
      "x": 0,
      "y": 0,
      "z": 9,
      "name": "Soil_Dirt"
    },
    {
      "x": 0,
      "y": 0,
      "z": 10,
      "name": "Soil_Dirt"
    },
    {
      "x": 0,
      "y": 0,
      "z": 11,
      "name": "Soil_Dirt"
    },
    {
      "x": 0,
      "y": 0,
      "z": 12,
      "name": "Soil_Dirt"
    },
    {
      "x": 0,
      "y": 0,
      "z": 13,
      "name": "Soil_Dirt"
    },
    {
      "x": 0,
      "y": 0,
      "z": 14,
      "name": "Soil_Dirt"
    },
    {
      "x": 0,
      "y": 0,
      "z": 15,
      "name": "Soil_Dirt"
    },
    {
      "x": 0,
      "y": 0,
      "z": 16,
      "name": "Soil_Dirt"
    },
    {
      "x": 1,
      "y": 0,
      "z": -12,
      "name": "Soil_Dirt"
    },
    {
      "x": 1,
      "y": 0,
      "z": -11,
      "name": "Soil_Dirt"
    },
    {
      "x": 1,
      "y": 0,
      "z": -10,
      "name": "Soil_Dirt"
    },
    {
      "x": 1,
      "y": 0,
      "z": -9,
      "name": "Soil_Dirt"
    },
    {
      "x": 1,
      "y": 0,
      "z": -8,
      "name": "Soil_Dirt"
    },
    {
      "x": 1,
      "y": 0,
      "z": -7,
      "name": "Soil_Dirt"
    },
    {
      "x": 1,
      "y": 0,
      "z": -6,
      "name": "Soil_Dirt"
    },
    {
      "x": 1,
      "y": 0,
      "z": -5,
      "name": "Soil_Dirt"
    },
    {
      "x": 1,
      "y": -2,
      "z": -4,
      "name": "Rock_Stone"
    },
    {
      "x": 1,
      "y": -1,
      "z": -4,
      "name": "Rock_Stone"
    },
    {
      "x": 1,
      "y": 0,
      "z": -4,
      "name": "Soil_Dirt"
    },
    {
      "x": 1,
      "y": -4,
      "z": -3,
      "name": "Rock_Stone"
    },
    {
      "x": 1,
      "y": -3,
      "z": -3,
      "name": "Rock_Stone"
    },
    {
      "x": 1,
      "y": -2,
      "z": -3,
      "name": "Rock_Stone"
    },
    {
      "x": 1,
      "y": -1,
      "z": -3,
      "name": "Rock_Stone"
    },
    {
      "x": 1,
      "y": 0,
      "z": -3,
      "name": "Soil_Dirt"
    },
    {
      "x": 1,
      "y": -3,
      "z": -2,
      "name": "Rock_Stone"
    },
    {
      "x": 1,
      "y": -2,
      "z": -2,
      "name": "Rock_Stone"
    },
    {
      "x": 1,
      "y": -1,
      "z": -2,
      "name": "Rock_Stone"
    },
    {
      "x": 1,
      "y": 0,
      "z": -2,
      "name": "Soil_Dirt"
    },
    {
      "x": 1,
      "y": -5,
      "z": -1,
      "name": "Rock_Stone"
    },
    {
      "x": 1,
      "y": -4,
      "z": -1,
      "name": "Rock_Stone"
    },
    {
      "x": 1,
      "y": -3,
      "z": -1,
      "name": "Rock_Stone"
    },
    {
      "x": 1,
      "y": -2,
      "z": -1,
      "name": "Rock_Stone"
    },
    {
      "x": 1,
      "y": 0,
      "z": -1,
      "name": "Soil_Dirt"
    },
    {
      "x": 1,
      "y": 1,
      "z": -1,
      "name": "Soil_Dirt"
    },
    {
      "x": 1,
      "y": 2,
      "z": -1,
      "name": "Soil_Dirt"
    },
    {
      "x": 1,
      "y": 3,
      "z": -1,
      "name": "Soil_Dirt"
    },
    {
      "x": 1,
      "y": 4,
      "z": -1,
      "name": "Soil_Dirt"
    },
    {
      "x": 1,
      "y": 5,
      "z": -1,
      "name": "Soil_Dirt"
    },
    {
      "x": 1,
      "y": 6,
      "z": -1,
      "name": "Soil_Dirt"
    },
    {
      "x": 1,
      "y": 7,
      "z": -1,
      "name": "Soil_Dirt"
    },
    {
      "x": 1,
      "y": 8,
      "z": -1,
      "name": "Soil_Dirt"
    },
    {
      "x": 1,
      "y": 9,
      "z": -1,
      "name": "Soil_Dirt"
    },
    {
      "x": 1,
      "y": 10,
      "z": -1,
      "name": "Soil_Dirt"
    },
    {
      "x": 1,
      "y": 11,
      "z": -1,
      "name": "Soil_Dirt"
    },
    {
      "x": 1,
      "y": 12,
      "z": -1,
      "name": "Soil_Dirt"
    },
    {
      "x": 1,
      "y": 13,
      "z": -1,
      "name": "Soil_Dirt"
    },
    {
      "x": 1,
      "y": 14,
      "z": -1,
      "name": "Soil_Dirt"
    },
    {
      "x": 1,
      "y": 15,
      "z": -1,
      "name": "Soil_Dirt"
    },
    {
      "x": 1,
      "y": 16,
      "z": -1,
      "name": "Soil_Dirt"
    },
    {
      "x": 1,
      "y": 17,
      "z": -1,
      "name": "Soil_Dirt"
    },
    {
      "x": 1,
      "y": 18,
      "z": -1,
      "name": "Soil_Dirt"
    },
    {
      "x": 1,
      "y": 19,
      "z": -1,
      "name": "Soil_Dirt"
    },
    {
      "x": 1,
      "y": 20,
      "z": -1,
      "name": "Soil_Dirt"
    },
    {
      "x": 1,
      "y": 21,
      "z": -1,
      "name": "Soil_Dirt"
    },
    {
      "x": 1,
      "y": -4,
      "z": 0,
      "name": "Rock_Stone"
    },
    {
      "x": 1,
      "y": -2,
      "z": 0,
      "name": "Rock_Stone"
    },
    {
      "x": 1,
      "y": 0,
      "z": 0,
      "name": "Soil_Dirt"
    },
    {
      "x": 1,
      "y": 1,
      "z": 0,
      "name": "Soil_Dirt"
    },
    {
      "x": 1,
      "y": 2,
      "z": 0,
      "name": "Soil_Dirt"
    },
    {
      "x": 1,
      "y": 3,
      "z": 0,
      "name": "Soil_Dirt"
    },
    {
      "x": 1,
      "y": 4,
      "z": 0,
      "name": "Soil_Dirt"
    },
    {
      "x": 1,
      "y": 5,
      "z": 0,
      "name": "Soil_Dirt"
    },
    {
      "x": 1,
      "y": 6,
      "z": 0,
      "name": "Soil_Dirt"
    },
    {
      "x": 1,
      "y": 7,
      "z": 0,
      "name": "Soil_Dirt"
    },
    {
      "x": 1,
      "y": 8,
      "z": 0,
      "name": "Soil_Dirt"
    },
    {
      "x": 1,
      "y": 9,
      "z": 0,
      "name": "Soil_Dirt"
    },
    {
      "x": 1,
      "y": 10,
      "z": 0,
      "name": "Soil_Dirt"
    },
    {
      "x": 1,
      "y": 11,
      "z": 0,
      "name": "Soil_Dirt"
    },
    {
      "x": 1,
      "y": 12,
      "z": 0,
      "name": "Soil_Dirt"
    },
    {
      "x": 1,
      "y": 13,
      "z": 0,
      "name": "Soil_Dirt"
    },
    {
      "x": 1,
      "y": 14,
      "z": 0,
      "name": "Soil_Dirt"
    },
    {
      "x": 1,
      "y": 15,
      "z": 0,
      "name": "Soil_Dirt"
    },
    {
      "x": 1,
      "y": 16,
      "z": 0,
      "name": "Soil_Dirt"
    },
    {
      "x": 1,
      "y": 17,
      "z": 0,
      "name": "Soil_Dirt"
    },
    {
      "x": 1,
      "y": 18,
      "z": 0,
      "name": "Soil_Dirt"
    },
    {
      "x": 1,
      "y": 19,
      "z": 0,
      "name": "Soil_Dirt"
    },
    {
      "x": 1,
      "y": 20,
      "z": 0,
      "name": "Soil_Dirt"
    },
    {
      "x": 1,
      "y": 21,
      "z": 0,
      "name": "Soil_Dirt"
    },
    {
      "x": 1,
      "y": -3,
      "z": 1,
      "name": "Rock_Stone"
    },
    {
      "x": 1,
      "y": 0,
      "z": 1,
      "name": "Soil_Dirt"
    },
    {
      "x": 1,
      "y": 1,
      "z": 1,
      "name": "Soil_Dirt"
    },
    {
      "x": 1,
      "y": 2,
      "z": 1,
      "name": "Soil_Dirt"
    },
    {
      "x": 1,
      "y": 3,
      "z": 1,
      "name": "Soil_Dirt"
    },
    {
      "x": 1,
      "y": 4,
      "z": 1,
      "name": "Soil_Dirt"
    },
    {
      "x": 1,
      "y": 5,
      "z": 1,
      "name": "Soil_Dirt"
    },
    {
      "x": 1,
      "y": 6,
      "z": 1,
      "name": "Soil_Dirt"
    },
    {
      "x": 1,
      "y": 7,
      "z": 1,
      "name": "Soil_Dirt"
    },
    {
      "x": 1,
      "y": 8,
      "z": 1,
      "name": "Soil_Dirt"
    },
    {
      "x": 1,
      "y": 9,
      "z": 1,
      "name": "Soil_Dirt"
    },
    {
      "x": 1,
      "y": 10,
      "z": 1,
      "name": "Soil_Dirt"
    },
    {
      "x": 1,
      "y": 11,
      "z": 1,
      "name": "Soil_Dirt"
    },
    {
      "x": 1,
      "y": 12,
      "z": 1,
      "name": "Soil_Dirt"
    },
    {
      "x": 1,
      "y": 13,
      "z": 1,
      "name": "Soil_Dirt"
    },
    {
      "x": 1,
      "y": 14,
      "z": 1,
      "name": "Soil_Dirt"
    },
    {
      "x": 1,
      "y": 15,
      "z": 1,
      "name": "Soil_Dirt"
    },
    {
      "x": 1,
      "y": 16,
      "z": 1,
      "name": "Soil_Dirt"
    },
    {
      "x": 1,
      "y": 17,
      "z": 1,
      "name": "Soil_Dirt"
    },
    {
      "x": 1,
      "y": 18,
      "z": 1,
      "name": "Soil_Dirt"
    },
    {
      "x": 1,
      "y": 19,
      "z": 1,
      "name": "Soil_Dirt"
    },
    {
      "x": 1,
      "y": 20,
      "z": 1,
      "name": "Soil_Dirt"
    },
    {
      "x": 1,
      "y": 21,
      "z": 1,
      "name": "Soil_Dirt"
    },
    {
      "x": 1,
      "y": -5,
      "z": 2,
      "name": "Rock_Stone"
    },
    {
      "x": 1,
      "y": -3,
      "z": 2,
      "name": "Rock_Stone"
    },
    {
      "x": 1,
      "y": -2,
      "z": 2,
      "name": "Rock_Stone"
    },
    {
      "x": 1,
      "y": -1,
      "z": 2,
      "name": "Rock_Stone"
    },
    {
      "x": 1,
      "y": 0,
      "z": 2,
      "name": "Soil_Dirt"
    },
    {
      "x": 1,
      "y": -5,
      "z": 3,
      "name": "Rock_Stone"
    },
    {
      "x": 1,
      "y": -3,
      "z": 3,
      "name": "Rock_Stone"
    },
    {
      "x": 1,
      "y": -2,
      "z": 3,
      "name": "Rock_Stone"
    },
    {
      "x": 1,
      "y": 0,
      "z": 3,
      "name": "Soil_Dirt"
    },
    {
      "x": 1,
      "y": -1,
      "z": 4,
      "name": "Rock_Stone"
    },
    {
      "x": 1,
      "y": 0,
      "z": 4,
      "name": "Soil_Dirt"
    },
    {
      "x": 1,
      "y": -5,
      "z": 5,
      "name": "Rock_Stone"
    },
    {
      "x": 1,
      "y": -4,
      "z": 5,
      "name": "Rock_Stone"
    },
    {
      "x": 1,
      "y": -3,
      "z": 5,
      "name": "Rock_Stone"
    },
    {
      "x": 1,
      "y": -2,
      "z": 5,
      "name": "Rock_Stone"
    },
    {
      "x": 1,
      "y": -1,
      "z": 5,
      "name": "Rock_Stone"
    },
    {
      "x": 1,
      "y": 0,
      "z": 5,
      "name": "Soil_Dirt"
    },
    {
      "x": 1,
      "y": -4,
      "z": 6,
      "name": "Rock_Stone"
    },
    {
      "x": 1,
      "y": -3,
      "z": 6,
      "name": "Rock_Stone"
    },
    {
      "x": 1,
      "y": 0,
      "z": 6,
      "name": "Soil_Dirt"
    },
    {
      "x": 1,
      "y": -1,
      "z": 7,
      "name": "Rock_Stone"
    },
    {
      "x": 1,
      "y": 0,
      "z": 7,
      "name": "Soil_Dirt"
    },
    {
      "x": 1,
      "y": -2,
      "z": 8,
      "name": "Rock_Stone"
    },
    {
      "x": 1,
      "y": -1,
      "z": 8,
      "name": "Rock_Stone"
    },
    {
      "x": 1,
      "y": 0,
      "z": 8,
      "name": "Soil_Dirt"
    },
    {
      "x": 1,
      "y": 0,
      "z": 9,
      "name": "Soil_Dirt"
    },
    {
      "x": 1,
      "y": 0,
      "z": 10,
      "name": "Soil_Dirt"
    },
    {
      "x": 1,
      "y": 0,
      "z": 11,
      "name": "Soil_Dirt"
    },
    {
      "x": 1,
      "y": 0,
      "z": 12,
      "name": "Soil_Dirt"
    },
    {
      "x": 1,
      "y": 0,
      "z": 13,
      "name": "Soil_Dirt"
    },
    {
      "x": 1,
      "y": 0,
      "z": 14,
      "name": "Soil_Dirt"
    },
    {
      "x": 1,
      "y": 0,
      "z": 15,
      "name": "Soil_Dirt"
    },
    {
      "x": 1,
      "y": 0,
      "z": 16,
      "name": "Soil_Dirt"
    },
    {
      "x": 2,
      "y": 0,
      "z": -12,
      "name": "Soil_Dirt"
    },
    {
      "x": 2,
      "y": 0,
      "z": -11,
      "name": "Soil_Dirt"
    },
    {
      "x": 2,
      "y": 0,
      "z": -10,
      "name": "Soil_Dirt"
    },
    {
      "x": 2,
      "y": 0,
      "z": -9,
      "name": "Soil_Dirt"
    },
    {
      "x": 2,
      "y": 0,
      "z": -8,
      "name": "Soil_Dirt"
    },
    {
      "x": 2,
      "y": 0,
      "z": -7,
      "name": "Soil_Dirt"
    },
    {
      "x": 2,
      "y": 0,
      "z": -6,
      "name": "Soil_Dirt"
    },
    {
      "x": 2,
      "y": 0,
      "z": -5,
      "name": "Soil_Dirt"
    },
    {
      "x": 2,
      "y": 0,
      "z": -4,
      "name": "Soil_Dirt"
    },
    {
      "x": 2,
      "y": -3,
      "z": -3,
      "name": "Rock_Stone"
    },
    {
      "x": 2,
      "y": -1,
      "z": -3,
      "name": "Rock_Stone"
    },
    {
      "x": 2,
      "y": 0,
      "z": -3,
      "name": "Soil_Dirt"
    },
    {
      "x": 2,
      "y": -3,
      "z": -2,
      "name": "Rock_Stone"
    },
    {
      "x": 2,
      "y": -1,
      "z": -2,
      "name": "Rock_Stone"
    },
    {
      "x": 2,
      "y": 0,
      "z": -2,
      "name": "Soil_Dirt"
    },
    {
      "x": 2,
      "y": -5,
      "z": -1,
      "name": "Rock_Stone"
    },
    {
      "x": 2,
      "y": -2,
      "z": -1,
      "name": "Rock_Stone"
    },
    {
      "x": 2,
      "y": 0,
      "z": -1,
      "name": "Soil_Dirt"
    },
    {
      "x": 2,
      "y": -3,
      "z": 0,
      "name": "Rock_Stone"
    },
    {
      "x": 2,
      "y": -1,
      "z": 0,
      "name": "Rock_Stone"
    },
    {
      "x": 2,
      "y": 0,
      "z": 0,
      "name": "Soil_Dirt"
    },
    {
      "x": 2,
      "y": -5,
      "z": 1,
      "name": "Rock_Stone"
    },
    {
      "x": 2,
      "y": -2,
      "z": 1,
      "name": "Rock_Stone"
    },
    {
      "x": 2,
      "y": 0,
      "z": 1,
      "name": "Soil_Dirt"
    },
    {
      "x": 2,
      "y": -2,
      "z": 2,
      "name": "Rock_Stone"
    },
    {
      "x": 2,
      "y": 0,
      "z": 2,
      "name": "Soil_Dirt"
    },
    {
      "x": 2,
      "y": -5,
      "z": 3,
      "name": "Rock_Stone"
    },
    {
      "x": 2,
      "y": -2,
      "z": 3,
      "name": "Rock_Stone"
    },
    {
      "x": 2,
      "y": 0,
      "z": 3,
      "name": "Soil_Dirt"
    },
    {
      "x": 2,
      "y": -3,
      "z": 4,
      "name": "Rock_Stone"
    },
    {
      "x": 2,
      "y": -2,
      "z": 4,
      "name": "Rock_Stone"
    },
    {
      "x": 2,
      "y": 0,
      "z": 4,
      "name": "Soil_Dirt"
    },
    {
      "x": 2,
      "y": -2,
      "z": 5,
      "name": "Rock_Stone"
    },
    {
      "x": 2,
      "y": -1,
      "z": 5,
      "name": "Rock_Stone"
    },
    {
      "x": 2,
      "y": 0,
      "z": 5,
      "name": "Soil_Dirt"
    },
    {
      "x": 2,
      "y": 0,
      "z": 6,
      "name": "Soil_Dirt"
    },
    {
      "x": 2,
      "y": -1,
      "z": 7,
      "name": "Rock_Stone"
    },
    {
      "x": 2,
      "y": 0,
      "z": 7,
      "name": "Soil_Dirt"
    },
    {
      "x": 2,
      "y": -1,
      "z": 8,
      "name": "Rock_Stone"
    },
    {
      "x": 2,
      "y": 0,
      "z": 8,
      "name": "Soil_Dirt"
    },
    {
      "x": 2,
      "y": 0,
      "z": 9,
      "name": "Soil_Dirt"
    },
    {
      "x": 2,
      "y": 0,
      "z": 10,
      "name": "Soil_Dirt"
    },
    {
      "x": 2,
      "y": 0,
      "z": 11,
      "name": "Soil_Dirt"
    },
    {
      "x": 2,
      "y": 0,
      "z": 12,
      "name": "Soil_Dirt"
    },
    {
      "x": 2,
      "y": 0,
      "z": 13,
      "name": "Soil_Dirt"
    },
    {
      "x": 2,
      "y": 0,
      "z": 14,
      "name": "Soil_Dirt"
    },
    {
      "x": 2,
      "y": 0,
      "z": 15,
      "name": "Soil_Dirt"
    },
    {
      "x": 2,
      "y": 0,
      "z": 16,
      "name": "Soil_Dirt"
    },
    {
      "x": 3,
      "y": 0,
      "z": -12,
      "name": "Soil_Dirt"
    },
    {
      "x": 3,
      "y": 0,
      "z": -11,
      "name": "Soil_Dirt"
    },
    {
      "x": 3,
      "y": 0,
      "z": -10,
      "name": "Soil_Dirt"
    },
    {
      "x": 3,
      "y": 0,
      "z": -9,
      "name": "Soil_Dirt"
    },
    {
      "x": 3,
      "y": 0,
      "z": -8,
      "name": "Soil_Dirt"
    },
    {
      "x": 3,
      "y": 0,
      "z": -7,
      "name": "Soil_Dirt"
    },
    {
      "x": 3,
      "y": 0,
      "z": -6,
      "name": "Soil_Dirt"
    },
    {
      "x": 3,
      "y": 0,
      "z": -5,
      "name": "Soil_Dirt"
    },
    {
      "x": 3,
      "y": 0,
      "z": -4,
      "name": "Soil_Dirt"
    },
    {
      "x": 3,
      "y": -3,
      "z": -3,
      "name": "Rock_Stone"
    },
    {
      "x": 3,
      "y": 0,
      "z": -3,
      "name": "Soil_Dirt"
    },
    {
      "x": 3,
      "y": -4,
      "z": -2,
      "name": "Rock_Stone"
    },
    {
      "x": 3,
      "y": -1,
      "z": -2,
      "name": "Rock_Stone"
    },
    {
      "x": 3,
      "y": 0,
      "z": -2,
      "name": "Soil_Dirt"
    },
    {
      "x": 3,
      "y": -5,
      "z": -1,
      "name": "Rock_Stone"
    },
    {
      "x": 3,
      "y": -3,
      "z": -1,
      "name": "Rock_Stone"
    },
    {
      "x": 3,
      "y": -2,
      "z": -1,
      "name": "Rock_Stone"
    },
    {
      "x": 3,
      "y": 0,
      "z": -1,
      "name": "Soil_Dirt"
    },
    {
      "x": 3,
      "y": -5,
      "z": 0,
      "name": "Rock_Stone"
    },
    {
      "x": 3,
      "y": -3,
      "z": 0,
      "name": "Rock_Stone"
    },
    {
      "x": 3,
      "y": -2,
      "z": 0,
      "name": "Rock_Stone"
    },
    {
      "x": 3,
      "y": 0,
      "z": 0,
      "name": "Soil_Dirt"
    },
    {
      "x": 3,
      "y": -3,
      "z": 1,
      "name": "Rock_Stone"
    },
    {
      "x": 3,
      "y": -1,
      "z": 1,
      "name": "Rock_Stone"
    },
    {
      "x": 3,
      "y": 0,
      "z": 1,
      "name": "Soil_Dirt"
    },
    {
      "x": 3,
      "y": -3,
      "z": 2,
      "name": "Rock_Stone"
    },
    {
      "x": 3,
      "y": -2,
      "z": 2,
      "name": "Rock_Stone"
    },
    {
      "x": 3,
      "y": -1,
      "z": 2,
      "name": "Rock_Stone"
    },
    {
      "x": 3,
      "y": 0,
      "z": 2,
      "name": "Soil_Dirt"
    },
    {
      "x": 3,
      "y": -5,
      "z": 3,
      "name": "Rock_Stone"
    },
    {
      "x": 3,
      "y": 0,
      "z": 3,
      "name": "Soil_Dirt"
    },
    {
      "x": 3,
      "y": -5,
      "z": 4,
      "name": "Rock_Stone"
    },
    {
      "x": 3,
      "y": -2,
      "z": 4,
      "name": "Rock_Stone"
    },
    {
      "x": 3,
      "y": 0,
      "z": 4,
      "name": "Soil_Dirt"
    },
    {
      "x": 3,
      "y": -5,
      "z": 5,
      "name": "Rock_Stone"
    },
    {
      "x": 3,
      "y": -4,
      "z": 5,
      "name": "Rock_Stone"
    },
    {
      "x": 3,
      "y": -2,
      "z": 5,
      "name": "Rock_Stone"
    },
    {
      "x": 3,
      "y": 0,
      "z": 5,
      "name": "Soil_Dirt"
    },
    {
      "x": 3,
      "y": -2,
      "z": 6,
      "name": "Rock_Stone"
    },
    {
      "x": 3,
      "y": 0,
      "z": 6,
      "name": "Soil_Dirt"
    },
    {
      "x": 3,
      "y": -2,
      "z": 7,
      "name": "Rock_Stone"
    },
    {
      "x": 3,
      "y": 0,
      "z": 7,
      "name": "Soil_Dirt"
    },
    {
      "x": 3,
      "y": 0,
      "z": 8,
      "name": "Soil_Dirt"
    },
    {
      "x": 3,
      "y": 0,
      "z": 9,
      "name": "Soil_Dirt"
    },
    {
      "x": 3,
      "y": 0,
      "z": 10,
      "name": "Soil_Dirt"
    },
    {
      "x": 3,
      "y": 0,
      "z": 11,
      "name": "Soil_Dirt"
    },
    {
      "x": 3,
      "y": 0,
      "z": 12,
      "name": "Soil_Dirt"
    },
    {
      "x": 3,
      "y": 0,
      "z": 13,
      "name": "Soil_Dirt"
    },
    {
      "x": 3,
      "y": 0,
      "z": 14,
      "name": "Soil_Dirt"
    },
    {
      "x": 3,
      "y": 0,
      "z": 15,
      "name": "Soil_Dirt"
    },
    {
      "x": 3,
      "y": 0,
      "z": 16,
      "name": "Soil_Dirt"
    },
    {
      "x": 4,
      "y": 0,
      "z": -12,
      "name": "Soil_Dirt"
    },
    {
      "x": 4,
      "y": 0,
      "z": -11,
      "name": "Soil_Dirt"
    },
    {
      "x": 4,
      "y": 0,
      "z": -10,
      "name": "Soil_Dirt"
    },
    {
      "x": 4,
      "y": 0,
      "z": -9,
      "name": "Soil_Dirt"
    },
    {
      "x": 4,
      "y": 0,
      "z": -8,
      "name": "Soil_Dirt"
    },
    {
      "x": 4,
      "y": 0,
      "z": -7,
      "name": "Soil_Dirt"
    },
    {
      "x": 4,
      "y": 0,
      "z": -6,
      "name": "Soil_Dirt"
    },
    {
      "x": 4,
      "y": 0,
      "z": -5,
      "name": "Soil_Dirt"
    },
    {
      "x": 4,
      "y": 0,
      "z": -4,
      "name": "Soil_Dirt"
    },
    {
      "x": 4,
      "y": -1,
      "z": -3,
      "name": "Rock_Stone"
    },
    {
      "x": 4,
      "y": 0,
      "z": -3,
      "name": "Soil_Dirt"
    },
    {
      "x": 4,
      "y": -3,
      "z": -2,
      "name": "Rock_Stone"
    },
    {
      "x": 4,
      "y": -1,
      "z": -2,
      "name": "Rock_Stone"
    },
    {
      "x": 4,
      "y": 0,
      "z": -2,
      "name": "Soil_Dirt"
    },
    {
      "x": 4,
      "y": -3,
      "z": -1,
      "name": "Rock_Stone"
    },
    {
      "x": 4,
      "y": -2,
      "z": -1,
      "name": "Rock_Stone"
    },
    {
      "x": 4,
      "y": -1,
      "z": -1,
      "name": "Rock_Stone"
    },
    {
      "x": 4,
      "y": 0,
      "z": -1,
      "name": "Soil_Dirt"
    },
    {
      "x": 4,
      "y": -3,
      "z": 0,
      "name": "Rock_Stone"
    },
    {
      "x": 4,
      "y": -1,
      "z": 0,
      "name": "Rock_Stone"
    },
    {
      "x": 4,
      "y": 0,
      "z": 0,
      "name": "Soil_Dirt"
    },
    {
      "x": 4,
      "y": -5,
      "z": 1,
      "name": "Rock_Stone"
    },
    {
      "x": 4,
      "y": -3,
      "z": 1,
      "name": "Rock_Stone"
    },
    {
      "x": 4,
      "y": 0,
      "z": 1,
      "name": "Soil_Dirt"
    },
    {
      "x": 4,
      "y": -2,
      "z": 2,
      "name": "Rock_Stone"
    },
    {
      "x": 4,
      "y": -1,
      "z": 2,
      "name": "Rock_Stone"
    },
    {
      "x": 4,
      "y": 0,
      "z": 2,
      "name": "Soil_Dirt"
    },
    {
      "x": 4,
      "y": -4,
      "z": 3,
      "name": "Rock_Stone"
    },
    {
      "x": 4,
      "y": -1,
      "z": 3,
      "name": "Rock_Stone"
    },
    {
      "x": 4,
      "y": 0,
      "z": 3,
      "name": "Soil_Dirt"
    },
    {
      "x": 4,
      "y": -1,
      "z": 4,
      "name": "Rock_Stone"
    },
    {
      "x": 4,
      "y": 0,
      "z": 4,
      "name": "Soil_Dirt"
    },
    {
      "x": 4,
      "y": -4,
      "z": 5,
      "name": "Rock_Stone"
    },
    {
      "x": 4,
      "y": -3,
      "z": 5,
      "name": "Rock_Stone"
    },
    {
      "x": 4,
      "y": -2,
      "z": 5,
      "name": "Rock_Stone"
    },
    {
      "x": 4,
      "y": 0,
      "z": 5,
      "name": "Soil_Dirt"
    },
    {
      "x": 4,
      "y": -3,
      "z": 6,
      "name": "Rock_Stone"
    },
    {
      "x": 4,
      "y": -2,
      "z": 6,
      "name": "Rock_Stone"
    },
    {
      "x": 4,
      "y": -1,
      "z": 6,
      "name": "Rock_Stone"
    },
    {
      "x": 4,
      "y": 0,
      "z": 6,
      "name": "Soil_Dirt"
    },
    {
      "x": 4,
      "y": -1,
      "z": 7,
      "name": "Rock_Stone"
    },
    {
      "x": 4,
      "y": 0,
      "z": 7,
      "name": "Soil_Dirt"
    },
    {
      "x": 4,
      "y": 0,
      "z": 8,
      "name": "Soil_Dirt"
    },
    {
      "x": 4,
      "y": 0,
      "z": 9,
      "name": "Soil_Dirt"
    },
    {
      "x": 4,
      "y": 0,
      "z": 10,
      "name": "Soil_Dirt"
    },
    {
      "x": 4,
      "y": 0,
      "z": 11,
      "name": "Soil_Dirt"
    },
    {
      "x": 4,
      "y": 0,
      "z": 12,
      "name": "Soil_Dirt"
    },
    {
      "x": 4,
      "y": 0,
      "z": 13,
      "name": "Soil_Dirt"
    },
    {
      "x": 4,
      "y": 0,
      "z": 14,
      "name": "Soil_Dirt"
    },
    {
      "x": 4,
      "y": 0,
      "z": 15,
      "name": "Soil_Dirt"
    },
    {
      "x": 4,
      "y": 0,
      "z": 16,
      "name": "Soil_Dirt"
    },
    {
      "x": 5,
      "y": 0,
      "z": -12,
      "name": "Soil_Dirt"
    },
    {
      "x": 5,
      "y": 0,
      "z": -11,
      "name": "Soil_Dirt"
    },
    {
      "x": 5,
      "y": 0,
      "z": -10,
      "name": "Soil_Dirt"
    },
    {
      "x": 5,
      "y": 0,
      "z": -9,
      "name": "Soil_Dirt"
    },
    {
      "x": 5,
      "y": 0,
      "z": -8,
      "name": "Soil_Dirt"
    },
    {
      "x": 5,
      "y": 0,
      "z": -7,
      "name": "Soil_Dirt"
    },
    {
      "x": 5,
      "y": 0,
      "z": -6,
      "name": "Soil_Dirt"
    },
    {
      "x": 5,
      "y": 0,
      "z": -5,
      "name": "Soil_Dirt"
    },
    {
      "x": 5,
      "y": 0,
      "z": -4,
      "name": "Soil_Dirt"
    },
    {
      "x": 5,
      "y": 0,
      "z": -3,
      "name": "Soil_Dirt"
    },
    {
      "x": 5,
      "y": -1,
      "z": -2,
      "name": "Rock_Stone"
    },
    {
      "x": 5,
      "y": 0,
      "z": -2,
      "name": "Soil_Dirt"
    },
    {
      "x": 5,
      "y": -1,
      "z": -1,
      "name": "Rock_Stone"
    },
    {
      "x": 5,
      "y": 0,
      "z": -1,
      "name": "Soil_Dirt"
    },
    {
      "x": 5,
      "y": -3,
      "z": 0,
      "name": "Rock_Stone"
    },
    {
      "x": 5,
      "y": -1,
      "z": 0,
      "name": "Rock_Stone"
    },
    {
      "x": 5,
      "y": 0,
      "z": 0,
      "name": "Soil_Dirt"
    },
    {
      "x": 5,
      "y": -3,
      "z": 1,
      "name": "Rock_Stone"
    },
    {
      "x": 5,
      "y": -1,
      "z": 1,
      "name": "Rock_Stone"
    },
    {
      "x": 5,
      "y": 0,
      "z": 1,
      "name": "Soil_Dirt"
    },
    {
      "x": 5,
      "y": -4,
      "z": 2,
      "name": "Rock_Stone"
    },
    {
      "x": 5,
      "y": -2,
      "z": 2,
      "name": "Rock_Stone"
    },
    {
      "x": 5,
      "y": -1,
      "z": 2,
      "name": "Rock_Stone"
    },
    {
      "x": 5,
      "y": 0,
      "z": 2,
      "name": "Soil_Dirt"
    },
    {
      "x": 5,
      "y": -4,
      "z": 3,
      "name": "Rock_Stone"
    },
    {
      "x": 5,
      "y": -2,
      "z": 3,
      "name": "Rock_Stone"
    },
    {
      "x": 5,
      "y": 0,
      "z": 3,
      "name": "Soil_Dirt"
    },
    {
      "x": 5,
      "y": -3,
      "z": 4,
      "name": "Rock_Stone"
    },
    {
      "x": 5,
      "y": 0,
      "z": 4,
      "name": "Soil_Dirt"
    },
    {
      "x": 5,
      "y": -2,
      "z": 5,
      "name": "Rock_Stone"
    },
    {
      "x": 5,
      "y": -1,
      "z": 5,
      "name": "Rock_Stone"
    },
    {
      "x": 5,
      "y": 0,
      "z": 5,
      "name": "Soil_Dirt"
    },
    {
      "x": 5,
      "y": 0,
      "z": 6,
      "name": "Soil_Dirt"
    },
    {
      "x": 5,
      "y": 0,
      "z": 7,
      "name": "Soil_Dirt"
    },
    {
      "x": 5,
      "y": 0,
      "z": 8,
      "name": "Soil_Dirt"
    },
    {
      "x": 5,
      "y": 0,
      "z": 9,
      "name": "Soil_Dirt"
    },
    {
      "x": 5,
      "y": 0,
      "z": 10,
      "name": "Soil_Dirt"
    },
    {
      "x": 5,
      "y": 0,
      "z": 11,
      "name": "Soil_Dirt"
    },
    {
      "x": 5,
      "y": 0,
      "z": 12,
      "name": "Soil_Dirt"
    },
    {
      "x": 5,
      "y": 0,
      "z": 13,
      "name": "Soil_Dirt"
    },
    {
      "x": 5,
      "y": 0,
      "z": 14,
      "name": "Soil_Dirt"
    },
    {
      "x": 5,
      "y": 0,
      "z": 15,
      "name": "Soil_Dirt"
    },
    {
      "x": 5,
      "y": 0,
      "z": 16,
      "name": "Soil_Dirt"
    },
    {
      "x": 6,
      "y": 0,
      "z": -12,
      "name": "Soil_Dirt"
    },
    {
      "x": 6,
      "y": 0,
      "z": -11,
      "name": "Soil_Dirt"
    },
    {
      "x": 6,
      "y": 0,
      "z": -10,
      "name": "Soil_Dirt"
    },
    {
      "x": 6,
      "y": 0,
      "z": -9,
      "name": "Soil_Dirt"
    },
    {
      "x": 6,
      "y": 0,
      "z": -8,
      "name": "Soil_Dirt"
    },
    {
      "x": 6,
      "y": 0,
      "z": -7,
      "name": "Soil_Dirt"
    },
    {
      "x": 6,
      "y": 0,
      "z": -6,
      "name": "Soil_Dirt"
    },
    {
      "x": 6,
      "y": 0,
      "z": -5,
      "name": "Soil_Dirt"
    },
    {
      "x": 6,
      "y": 0,
      "z": -4,
      "name": "Soil_Dirt"
    },
    {
      "x": 6,
      "y": 0,
      "z": -3,
      "name": "Soil_Dirt"
    },
    {
      "x": 6,
      "y": 0,
      "z": -2,
      "name": "Soil_Dirt"
    },
    {
      "x": 6,
      "y": 0,
      "z": -1,
      "name": "Soil_Dirt"
    },
    {
      "x": 6,
      "y": -1,
      "z": 0,
      "name": "Rock_Stone"
    },
    {
      "x": 6,
      "y": 0,
      "z": 0,
      "name": "Soil_Dirt"
    },
    {
      "x": 6,
      "y": -2,
      "z": 1,
      "name": "Rock_Stone"
    },
    {
      "x": 6,
      "y": -1,
      "z": 1,
      "name": "Rock_Stone"
    },
    {
      "x": 6,
      "y": 0,
      "z": 1,
      "name": "Soil_Dirt"
    },
    {
      "x": 6,
      "y": -2,
      "z": 2,
      "name": "Rock_Stone"
    },
    {
      "x": 6,
      "y": -1,
      "z": 2,
      "name": "Rock_Stone"
    },
    {
      "x": 6,
      "y": 0,
      "z": 2,
      "name": "Soil_Dirt"
    },
    {
      "x": 6,
      "y": -2,
      "z": 3,
      "name": "Rock_Stone"
    },
    {
      "x": 6,
      "y": 0,
      "z": 3,
      "name": "Soil_Dirt"
    },
    {
      "x": 6,
      "y": -1,
      "z": 4,
      "name": "Rock_Stone"
    },
    {
      "x": 6,
      "y": 0,
      "z": 4,
      "name": "Soil_Dirt"
    },
    {
      "x": 6,
      "y": 0,
      "z": 5,
      "name": "Soil_Dirt"
    },
    {
      "x": 6,
      "y": 0,
      "z": 6,
      "name": "Soil_Dirt"
    },
    {
      "x": 6,
      "y": 0,
      "z": 7,
      "name": "Soil_Dirt"
    },
    {
      "x": 6,
      "y": 0,
      "z": 8,
      "name": "Soil_Dirt"
    },
    {
      "x": 6,
      "y": 0,
      "z": 9,
      "name": "Soil_Dirt"
    },
    {
      "x": 6,
      "y": 0,
      "z": 10,
      "name": "Soil_Dirt"
    },
    {
      "x": 6,
      "y": 0,
      "z": 11,
      "name": "Soil_Dirt"
    },
    {
      "x": 6,
      "y": 0,
      "z": 12,
      "name": "Soil_Dirt"
    },
    {
      "x": 6,
      "y": 0,
      "z": 13,
      "name": "Soil_Dirt"
    },
    {
      "x": 6,
      "y": 0,
      "z": 14,
      "name": "Soil_Dirt"
    },
    {
      "x": 6,
      "y": 0,
      "z": 15,
      "name": "Soil_Dirt"
    },
    {
      "x": 6,
      "y": 0,
      "z": 16,
      "name": "Soil_Dirt"
    },
    {
      "x": 7,
      "y": 0,
      "z": -12,
      "name": "Soil_Dirt"
    },
    {
      "x": 7,
      "y": 0,
      "z": -11,
      "name": "Soil_Dirt"
    },
    {
      "x": 7,
      "y": 0,
      "z": -10,
      "name": "Soil_Dirt"
    },
    {
      "x": 7,
      "y": 0,
      "z": -9,
      "name": "Soil_Dirt"
    },
    {
      "x": 7,
      "y": 0,
      "z": -8,
      "name": "Soil_Dirt"
    },
    {
      "x": 7,
      "y": 0,
      "z": -7,
      "name": "Soil_Dirt"
    },
    {
      "x": 7,
      "y": 0,
      "z": -6,
      "name": "Soil_Dirt"
    },
    {
      "x": 7,
      "y": 0,
      "z": -5,
      "name": "Soil_Dirt"
    },
    {
      "x": 7,
      "y": 0,
      "z": -4,
      "name": "Soil_Dirt"
    },
    {
      "x": 7,
      "y": 0,
      "z": -3,
      "name": "Soil_Dirt"
    },
    {
      "x": 7,
      "y": 0,
      "z": -2,
      "name": "Soil_Dirt"
    },
    {
      "x": 7,
      "y": 0,
      "z": -1,
      "name": "Soil_Dirt"
    },
    {
      "x": 7,
      "y": 0,
      "z": 0,
      "name": "Soil_Dirt"
    },
    {
      "x": 7,
      "y": 0,
      "z": 1,
      "name": "Soil_Dirt"
    },
    {
      "x": 7,
      "y": 0,
      "z": 2,
      "name": "Soil_Dirt"
    },
    {
      "x": 7,
      "y": 0,
      "z": 3,
      "name": "Soil_Dirt"
    },
    {
      "x": 7,
      "y": 0,
      "z": 4,
      "name": "Soil_Dirt"
    },
    {
      "x": 7,
      "y": 0,
      "z": 5,
      "name": "Soil_Dirt"
    },
    {
      "x": 7,
      "y": 0,
      "z": 6,
      "name": "Soil_Dirt"
    },
    {
      "x": 7,
      "y": 0,
      "z": 7,
      "name": "Soil_Dirt"
    },
    {
      "x": 7,
      "y": 0,
      "z": 8,
      "name": "Soil_Dirt"
    },
    {
      "x": 7,
      "y": 0,
      "z": 9,
      "name": "Soil_Dirt"
    },
    {
      "x": 7,
      "y": 0,
      "z": 10,
      "name": "Soil_Dirt"
    },
    {
      "x": 7,
      "y": 0,
      "z": 11,
      "name": "Soil_Dirt"
    },
    {
      "x": 7,
      "y": 0,
      "z": 12,
      "name": "Soil_Dirt"
    },
    {
      "x": 7,
      "y": 0,
      "z": 13,
      "name": "Soil_Dirt"
    },
    {
      "x": 7,
      "y": 0,
      "z": 14,
      "name": "Soil_Dirt"
    },
    {
      "x": 7,
      "y": 0,
      "z": 15,
      "name": "Soil_Dirt"
    },
    {
      "x": 7,
      "y": 0,
      "z": 16,
      "name": "Soil_Dirt"
    },
    {
      "x": 8,
      "y": 0,
      "z": -12,
      "name": "Soil_Dirt"
    },
    {
      "x": 8,
      "y": 0,
      "z": -11,
      "name": "Soil_Dirt"
    },
    {
      "x": 8,
      "y": 0,
      "z": -10,
      "name": "Soil_Dirt"
    },
    {
      "x": 8,
      "y": 0,
      "z": -9,
      "name": "Soil_Dirt"
    },
    {
      "x": 8,
      "y": 0,
      "z": -8,
      "name": "Soil_Dirt"
    },
    {
      "x": 8,
      "y": 0,
      "z": -7,
      "name": "Soil_Dirt"
    },
    {
      "x": 8,
      "y": 0,
      "z": -6,
      "name": "Soil_Dirt"
    },
    {
      "x": 8,
      "y": 0,
      "z": -5,
      "name": "Soil_Dirt"
    },
    {
      "x": 8,
      "y": 0,
      "z": -4,
      "name": "Soil_Dirt"
    },
    {
      "x": 8,
      "y": 0,
      "z": -3,
      "name": "Soil_Dirt"
    },
    {
      "x": 8,
      "y": 0,
      "z": -2,
      "name": "Soil_Dirt"
    },
    {
      "x": 8,
      "y": 0,
      "z": -1,
      "name": "Soil_Dirt"
    },
    {
      "x": 8,
      "y": 0,
      "z": 0,
      "name": "Soil_Dirt"
    },
    {
      "x": 8,
      "y": 0,
      "z": 1,
      "name": "Soil_Dirt"
    },
    {
      "x": 8,
      "y": 0,
      "z": 2,
      "name": "Soil_Dirt"
    },
    {
      "x": 8,
      "y": 0,
      "z": 3,
      "name": "Soil_Dirt"
    },
    {
      "x": 8,
      "y": 0,
      "z": 4,
      "name": "Soil_Dirt"
    },
    {
      "x": 8,
      "y": 0,
      "z": 5,
      "name": "Soil_Dirt"
    },
    {
      "x": 8,
      "y": 0,
      "z": 6,
      "name": "Soil_Dirt"
    },
    {
      "x": 8,
      "y": 0,
      "z": 7,
      "name": "Soil_Dirt"
    },
    {
      "x": 8,
      "y": 0,
      "z": 8,
      "name": "Soil_Dirt"
    },
    {
      "x": 8,
      "y": 0,
      "z": 9,
      "name": "Soil_Dirt"
    },
    {
      "x": 8,
      "y": 0,
      "z": 10,
      "name": "Soil_Dirt"
    },
    {
      "x": 8,
      "y": 0,
      "z": 11,
      "name": "Soil_Dirt"
    },
    {
      "x": 8,
      "y": 0,
      "z": 12,
      "name": "Soil_Dirt"
    },
    {
      "x": 8,
      "y": 0,
      "z": 13,
      "name": "Soil_Dirt"
    },
    {
      "x": 8,
      "y": 0,
      "z": 14,
      "name": "Soil_Dirt"
    },
    {
      "x": 8,
      "y": 0,
      "z": 15,
      "name": "Soil_Dirt"
    },
    {
      "x": 8,
      "y": 0,
      "z": 16,
      "name": "Soil_Dirt"
    },
    {
      "x": 9,
      "y": 0,
      "z": -12,
      "name": "Soil_Dirt"
    },
    {
      "x": 9,
      "y": 0,
      "z": -11,
      "name": "Soil_Dirt"
    },
    {
      "x": 9,
      "y": 0,
      "z": -10,
      "name": "Soil_Dirt"
    },
    {
      "x": 9,
      "y": 0,
      "z": -9,
      "name": "Soil_Dirt"
    },
    {
      "x": 9,
      "y": 0,
      "z": -8,
      "name": "Soil_Dirt"
    },
    {
      "x": 9,
      "y": 0,
      "z": -7,
      "name": "Soil_Dirt"
    },
    {
      "x": 9,
      "y": 0,
      "z": -6,
      "name": "Soil_Dirt"
    },
    {
      "x": 9,
      "y": 0,
      "z": -5,
      "name": "Soil_Dirt"
    },
    {
      "x": 9,
      "y": 0,
      "z": -4,
      "name": "Soil_Dirt"
    },
    {
      "x": 9,
      "y": 0,
      "z": -3,
      "name": "Soil_Dirt"
    },
    {
      "x": 9,
      "y": 0,
      "z": -2,
      "name": "Soil_Dirt"
    },
    {
      "x": 9,
      "y": 0,
      "z": -1,
      "name": "Soil_Dirt"
    },
    {
      "x": 9,
      "y": 0,
      "z": 0,
      "name": "Soil_Dirt"
    },
    {
      "x": 9,
      "y": 0,
      "z": 1,
      "name": "Soil_Dirt"
    },
    {
      "x": 9,
      "y": 0,
      "z": 2,
      "name": "Soil_Dirt"
    },
    {
      "x": 9,
      "y": 0,
      "z": 3,
      "name": "Soil_Dirt"
    },
    {
      "x": 9,
      "y": 0,
      "z": 4,
      "name": "Soil_Dirt"
    },
    {
      "x": 9,
      "y": 0,
      "z": 5,
      "name": "Soil_Dirt"
    },
    {
      "x": 9,
      "y": 0,
      "z": 6,
      "name": "Soil_Dirt"
    },
    {
      "x": 9,
      "y": 0,
      "z": 7,
      "name": "Soil_Dirt"
    },
    {
      "x": 9,
      "y": 0,
      "z": 8,
      "name": "Soil_Dirt"
    },
    {
      "x": 9,
      "y": 0,
      "z": 9,
      "name": "Soil_Dirt"
    },
    {
      "x": 9,
      "y": 0,
      "z": 10,
      "name": "Soil_Dirt"
    },
    {
      "x": 9,
      "y": 0,
      "z": 11,
      "name": "Soil_Dirt"
    },
    {
      "x": 9,
      "y": 0,
      "z": 12,
      "name": "Soil_Dirt"
    },
    {
      "x": 9,
      "y": 0,
      "z": 13,
      "name": "Soil_Dirt"
    },
    {
      "x": 9,
      "y": 0,
      "z": 14,
      "name": "Soil_Dirt"
    },
    {
      "x": 9,
      "y": 0,
      "z": 15,
      "name": "Soil_Dirt"
    },
    {
      "x": 9,
      "y": 0,
      "z": 16,
      "name": "Soil_Dirt"
    },
    {
      "x": 10,
      "y": 0,
      "z": -12,
      "name": "Soil_Dirt"
    },
    {
      "x": 10,
      "y": 0,
      "z": -11,
      "name": "Soil_Dirt"
    },
    {
      "x": 10,
      "y": 0,
      "z": -10,
      "name": "Soil_Dirt"
    },
    {
      "x": 10,
      "y": 0,
      "z": -9,
      "name": "Soil_Dirt"
    },
    {
      "x": 10,
      "y": 0,
      "z": -8,
      "name": "Soil_Dirt"
    },
    {
      "x": 10,
      "y": 0,
      "z": -7,
      "name": "Soil_Dirt"
    },
    {
      "x": 10,
      "y": 0,
      "z": -6,
      "name": "Soil_Dirt"
    },
    {
      "x": 10,
      "y": 0,
      "z": -5,
      "name": "Soil_Dirt"
    },
    {
      "x": 10,
      "y": 0,
      "z": -4,
      "name": "Soil_Dirt"
    },
    {
      "x": 10,
      "y": 0,
      "z": -3,
      "name": "Soil_Dirt"
    },
    {
      "x": 10,
      "y": 0,
      "z": -2,
      "name": "Soil_Dirt"
    },
    {
      "x": 10,
      "y": 0,
      "z": -1,
      "name": "Soil_Dirt"
    },
    {
      "x": 10,
      "y": 0,
      "z": 0,
      "name": "Soil_Dirt"
    },
    {
      "x": 10,
      "y": 0,
      "z": 1,
      "name": "Soil_Dirt"
    },
    {
      "x": 10,
      "y": 0,
      "z": 2,
      "name": "Soil_Dirt"
    },
    {
      "x": 10,
      "y": 0,
      "z": 3,
      "name": "Soil_Dirt"
    },
    {
      "x": 10,
      "y": 0,
      "z": 4,
      "name": "Soil_Dirt"
    },
    {
      "x": 10,
      "y": 0,
      "z": 5,
      "name": "Soil_Dirt"
    },
    {
      "x": 10,
      "y": 0,
      "z": 6,
      "name": "Soil_Dirt"
    },
    {
      "x": 10,
      "y": 0,
      "z": 7,
      "name": "Soil_Dirt"
    },
    {
      "x": 10,
      "y": 0,
      "z": 8,
      "name": "Soil_Dirt"
    },
    {
      "x": 10,
      "y": 0,
      "z": 9,
      "name": "Soil_Dirt"
    },
    {
      "x": 10,
      "y": 0,
      "z": 10,
      "name": "Soil_Dirt"
    },
    {
      "x": 10,
      "y": 0,
      "z": 11,
      "name": "Soil_Dirt"
    },
    {
      "x": 10,
      "y": 0,
      "z": 12,
      "name": "Soil_Dirt"
    },
    {
      "x": 10,
      "y": 0,
      "z": 13,
      "name": "Soil_Dirt"
    },
    {
      "x": 10,
      "y": 0,
      "z": 14,
      "name": "Soil_Dirt"
    },
    {
      "x": 10,
      "y": 0,
      "z": 15,
      "name": "Soil_Dirt"
    },
    {
      "x": 10,
      "y": 0,
      "z": 16,
      "name": "Soil_Dirt"
    },
    {
      "x": 11,
      "y": 0,
      "z": -12,
      "name": "Soil_Dirt"
    },
    {
      "x": 11,
      "y": 0,
      "z": -11,
      "name": "Soil_Dirt"
    },
    {
      "x": 11,
      "y": 0,
      "z": -10,
      "name": "Soil_Dirt"
    },
    {
      "x": 11,
      "y": 0,
      "z": -9,
      "name": "Soil_Dirt"
    },
    {
      "x": 11,
      "y": 0,
      "z": -8,
      "name": "Soil_Dirt"
    },
    {
      "x": 11,
      "y": 0,
      "z": -7,
      "name": "Soil_Dirt"
    },
    {
      "x": 11,
      "y": 0,
      "z": -6,
      "name": "Soil_Dirt"
    },
    {
      "x": 11,
      "y": 0,
      "z": -5,
      "name": "Soil_Dirt"
    },
    {
      "x": 11,
      "y": 0,
      "z": -4,
