{
  "version": 8,
  "blockIdVersion": 11,
  "anchorX": 0,
  "anchorY": 0,
  "anchorZ": 0,
  "blocks": [
    {
      "x": -22,
      "y": 2,
      "z": 1,
      "name": "Soil_Dirt"
    },
    {
      "x": -22,
      "y": 2,
      "z": 2,
      "name": "Soil_Dirt"
    },
    {
      "x": -22,
      "y": 2,
      "z": 3,
      "name": "Soil_Dirt"
    },
    {
      "x": -21,
      "y": 2,
      "z": -5,
      "name": "Soil_Dirt"
    },
    {
      "x": -21,
      "y": 2,
      "z": -4,
      "name": "Soil_Dirt"
    },
    {
      "x": -21,
      "y": 2,
      "z": -3,
      "name": "Soil_Dirt"
    },
    {
      "x": -21,
      "y": 2,
      "z": 0,
      "name": "Soil_Dirt"
    },
    {
      "x": -21,
      "y": 2,
      "z": 1,
      "name": "Soil_Dirt"
    },
    {
      "x": -21,
      "y": 2,
      "z": 2,
      "name": "Soil_Dirt"
    },
    {
      "x": -21,
      "y": 2,
      "z": 3,
      "name": "Soil_Dirt"
    },
    {
      "x": -21,
      "y": 2,
      "z": 4,
      "name": "Soil_Dirt"
    },
    {
      "x": -20,
      "y": 2,
      "z": -6,
      "name": "Soil_Dirt"
    },
    {
      "x": -20,
      "y": 2,
      "z": -5,
      "name": "Soil_Dirt"
    },
    {
      "x": -20,
      "y": 2,
      "z": -4,
      "name": "Soil_Dirt"
    },
    {
      "x": -20,
      "y": 2,
      "z": -3,
      "name": "Soil_Dirt"
    },
    {
      "x": -20,
      "y": 2,
      "z": -2,
      "name": "Soil_Dirt"
    },
    {
      "x": -20,
      "y": 2,
      "z": -1,
      "name": "Soil_Dirt"
    },
    {
      "x": -20,
      "y": 2,
      "z": 0,
      "name": "Soil_Dirt"
    },
    {
      "x": -20,
      "y": 2,
      "z": 1,
      "name": "Soil_Dirt"
    },
    {
      "x": -20,
      "y": 2,
      "z": 2,
      "name": "Soil_Dirt"
    },
    {
      "x": -20,
      "y": 2,
      "z": 3,
      "name": "Soil_Dirt"
    },
    {
      "x": -20,
      "y": 2,
      "z": 4,
      "name": "Soil_Dirt"
    },
    {
      "x": -20,
      "y": 2,
      "z": 5,
      "name": "Soil_Dirt"
    },
    {
      "x": -20,
      "y": 2,
      "z": 6,
      "name": "Soil_Dirt"
    },
    {
      "x": -20,
      "y": 2,
      "z": 7,
      "name": "Soil_Dirt"
    },
    {
      "x": -20,
      "y": 2,
      "z": 8,
      "name": "Soil_Dirt"
    },
    {
      "x": -19,
      "y": 2,
      "z": -10,
      "name": "Soil_Dirt"
    },
    {
      "x": -19,
      "y": 2,
      "z": -9,
      "name": "Soil_Dirt"
    },
    {
      "x": -19,
      "y": 2,
      "z": -8,
      "name": "Soil_Dirt"
    },
    {
      "x": -19,
      "y": 2,
      "z": -7,
      "name": "Soil_Dirt"
    },
    {
      "x": -19,
      "y": 2,
      "z": -6,
      "name": "Soil_Dirt"
    },
    {
      "x": -19,
      "y": 2,
      "z": -5,
      "name": "Soil_Dirt"
    },
    {
      "x": -19,
      "y": 2,
      "z": -4,
      "name": "Soil_Dirt"
    },
    {
      "x": -19,
      "y": 2,
      "z": -3,
      "name": "Soil_Dirt"
    },
    {
      "x": -19,
      "y": 3,
      "z": -3,
      "name": "Soil_Dirt"
    },
    {
      "x": -19,
      "y": 1,
      "z": -2,
      "name": "Rock_Stone"
    },
    {
      "x": -19,
      "y": 2,
      "z": -2,
      "name": "Soil_Dirt"
    },
    {
      "x": -19,
      "y": 3,
      "z": -2,
      "name": "Soil_Dirt"
    },
    {
      "x": -19,
      "y": 1,
      "z": -1,
      "name": "Rock_Stone"
    },
    {
      "x": -19,
      "y": 2,
      "z": -1,
      "name": "Soil_Dirt"
    },
    {
      "x": -19,
      "y": 3,
      "z": -1,
      "name": "Soil_Dirt"
    },
    {
      "x": -19,
      "y": 1,
      "z": 0,
      "name": "Rock_Stone"
    },
    {
      "x": -19,
      "y": 2,
      "z": 0,
      "name": "Soil_Dirt"
    },
    {
      "x": -19,
      "y": 3,
      "z": 0,
      "name": "Soil_Dirt"
    },
    {
      "x": -19,
      "y": 1,
      "z": 1,
      "name": "Rock_Stone"
    },
    {
      "x": -19,
      "y": 2,
      "z": 1,
      "name": "Soil_Dirt"
    },
    {
      "x": -19,
      "y": 3,
      "z": 1,
      "name": "Soil_Dirt"
    },
    {
      "x": -19,
      "y": 1,
      "z": 2,
      "name": "Rock_Stone"
    },
    {
      "x": -19,
      "y": 2,
      "z": 2,
      "name": "Soil_Dirt"
    },
    {
      "x": -19,
      "y": 3,
      "z": 2,
      "name": "Soil_Dirt"
    },
    {
      "x": -19,
      "y": 2,
      "z": 3,
      "name": "Soil_Dirt"
    },
    {
      "x": -19,
      "y": 3,
      "z": 3,
      "name": "Soil_Dirt"
    },
    {
      "x": -19,
      "y": 2,
      "z": 4,
      "name": "Soil_Dirt"
    },
    {
      "x": -19,
      "y": 2,
      "z": 5,
      "name": "Soil_Dirt"
    },
    {
      "x": -19,
      "y": 2,
      "z": 6,
      "name": "Soil_Dirt"
    },
    {
      "x": -19,
      "y": 2,
      "z": 7,
      "name": "Soil_Dirt"
    },
    {
      "x": -19,
      "y": 2,
      "z": 8,
      "name": "Soil_Dirt"
    },
    {
      "x": -19,
      "y": 2,
      "z": 9,
      "name": "Soil_Dirt"
    },
    {
      "x": -19,
      "y": 2,
      "z": 10,
      "name": "Soil_Dirt"
    },
    {
      "x": -19,
      "y": 2,
      "z": 11,
      "name": "Soil_Dirt"
    },
    {
      "x": -19,
      "y": 2,
      "z": 12,
      "name": "Soil_Dirt"
    },
    {
      "x": -18,
      "y": 2,
      "z": -11,
      "name": "Soil_Dirt"
    },
    {
      "x": -18,
      "y": 2,
      "z": -10,
      "name": "Soil_Dirt"
    },
    {
      "x": -18,
      "y": 2,
      "z": -9,
      "name": "Soil_Dirt"
    },
    {
      "x": -18,
      "y": 2,
      "z": -8,
      "name": "Soil_Dirt"
    },
    {
      "x": -18,
      "y": 2,
      "z": -7,
      "name": "Soil_Dirt"
    },
    {
      "x": -18,
      "y": 2,
      "z": -6,
      "name": "Soil_Dirt"
    },
    {
      "x": -18,
      "y": 3,
      "z": -6,
      "name": "Soil_Dirt"
    },
    {
      "x": -18,
      "y": 1,
      "z": -5,
      "name": "Rock_Stone"
    },
    {
      "x": -18,
      "y": 2,
      "z": -5,
      "name": "Soil_Dirt"
    },
    {
      "x": -18,
      "y": 3,
      "z": -5,
      "name": "Soil_Dirt"
    },
    {
      "x": -18,
      "y": 1,
      "z": -4,
      "name": "Rock_Stone"
    },
    {
      "x": -18,
      "y": 2,
      "z": -4,
      "name": "Soil_Dirt"
    },
    {
      "x": -18,
      "y": 3,
      "z": -4,
      "name": "Soil_Dirt"
    },
    {
      "x": -18,
      "y": 4,
      "z": -4,
      "name": "Soil_Dirt"
    },
    {
      "x": -18,
      "y": 0,
      "z": -3,
      "name": "Rock_Stone"
    },
    {
      "x": -18,
      "y": 1,
      "z": -3,
      "name": "Rock_Stone"
    },
    {
      "x": -18,
      "y": 2,
      "z": -3,
      "name": "Soil_Dirt"
    },
    {
      "x": -18,
      "y": 3,
      "z": -3,
      "name": "Soil_Dirt"
    },
    {
      "x": -18,
      "y": 4,
      "z": -3,
      "name": "Soil_Dirt"
    },
    {
      "x": -18,
      "y": 0,
      "z": -2,
      "name": "Rock_Stone"
    },
    {
      "x": -18,
      "y": 1,
      "z": -2,
      "name": "Rock_Stone"
    },
    {
      "x": -18,
      "y": 2,
      "z": -2,
      "name": "Soil_Dirt"
    },
    {
      "x": -18,
      "y": 3,
      "z": -2,
      "name": "Soil_Dirt"
    },
    {
      "x": -18,
      "y": 4,
      "z": -2,
      "name": "Rock_Stone"
    },
    {
      "x": -18,
      "y": 0,
      "z": -1,
      "name": "Rock_Stone"
    },
    {
      "x": -18,
      "y": 1,
      "z": -1,
      "name": "Rock_Stone"
    },
    {
      "x": -18,
      "y": 2,
      "z": -1,
      "name": "Soil_Dirt"
    },
    {
      "x": -18,
      "y": 3,
      "z": -1,
      "name": "Soil_Dirt"
    },
    {
      "x": -18,
      "y": 4,
      "z": -1,
      "name": "Rock_Stone_Cobble_Mossy"
    },
    {
      "x": -18,
      "y": 0,
      "z": 0,
      "name": "Rock_Stone"
    },
    {
      "x": -18,
      "y": 1,
      "z": 0,
      "name": "Rock_Stone"
    },
    {
      "x": -18,
      "y": 2,
      "z": 0,
      "name": "Soil_Dirt"
    },
    {
      "x": -18,
      "y": 3,
      "z": 0,
      "name": "Soil_Dirt"
    },
    {
      "x": -18,
      "y": 4,
      "z": 0,
      "name": "Rock_Stone"
    },
    {
      "x": -18,
      "y": 0,
      "z": 1,
      "name": "Rock_Stone"
    },
    {
      "x": -18,
      "y": 1,
      "z": 1,
      "name": "Rock_Stone"
    },
    {
      "x": -18,
      "y": 2,
      "z": 1,
      "name": "Soil_Dirt"
    },
    {
      "x": -18,
      "y": 3,
      "z": 1,
      "name": "Soil_Dirt"
    },
    {
      "x": -18,
      "y": 4,
      "z": 1,
      "name": "Rock_Stone"
    },
    {
      "x": -18,
      "y": 5,
      "z": 1,
      "name": "Rock_Stone_Cobble"
    },
    {
      "x": -18,
      "y": 0,
      "z": 2,
      "name": "Rock_Stone"
    },
    {
      "x": -18,
      "y": 1,
      "z": 2,
      "name": "Rock_Stone"
    },
    {
      "x": -18,
      "y": 2,
      "z": 2,
      "name": "Soil_Dirt"
    },
    {
      "x": -18,
      "y": 3,
      "z": 2,
      "name": "Soil_Dirt"
    },
    {
      "x": -18,
      "y": 4,
      "z": 2,
      "name": "Rock_Stone"
    },
    {
      "x": -18,
      "y": 5,
      "z": 2,
      "name": "Rock_Stone"
    },
    {
      "x": -18,
      "y": 6,
      "z": 2,
      "name": "Deco_Bone_Skulls"
    },
    {
      "x": -18,
      "y": 0,
      "z": 3,
      "name": "Rock_Stone"
    },
    {
      "x": -18,
      "y": 1,
      "z": 3,
      "name": "Rock_Stone"
    },
    {
      "x": -18,
      "y": 2,
      "z": 3,
      "name": "Soil_Dirt"
    },
    {
      "x": -18,
      "y": 3,
      "z": 3,
      "name": "Soil_Dirt"
    },
    {
      "x": -18,
      "y": 4,
      "z": 3,
      "name": "Rock_Stone"
    },
    {
      "x": -18,
      "y": 5,
      "z": 3,
      "name": "Rock_Stone"
    },
    {
      "x": -18,
      "y": 1,
      "z": 4,
      "name": "Rock_Stone"
    },
    {
      "x": -18,
      "y": 2,
      "z": 4,
      "name": "Soil_Dirt"
    },
    {
      "x": -18,
      "y": 3,
      "z": 4,
      "name": "Soil_Dirt"
    },
    {
      "x": -18,
      "y": 4,
      "z": 4,
      "name": "Rock_Stone"
    },
    {
      "x": -18,
      "y": 5,
      "z": 4,
      "name": "Rock_Stone"
    },
    {
      "x": -18,
      "y": 1,
      "z": 5,
      "name": "Rock_Stone"
    },
    {
      "x": -18,
      "y": 2,
      "z": 5,
      "name": "Soil_Dirt"
    },
    {
      "x": -18,
      "y": 3,
      "z": 5,
      "name": "Soil_Dirt"
    },
    {
      "x": -18,
      "y": 4,
      "z": 5,
      "name": "Rock_Stone"
    },
    {
      "x": -18,
      "y": 2,
      "z": 6,
      "name": "Soil_Dirt"
    },
    {
      "x": -18,
      "y": 3,
      "z": 6,
      "name": "Soil_Dirt"
    },
    {
      "x": -18,
      "y": 2,
      "z": 7,
      "name": "Soil_Dirt"
    },
    {
      "x": -18,
      "y": 2,
      "z": 8,
      "name": "Soil_Dirt"
    },
    {
      "x": -18,
      "y": 2,
      "z": 9,
      "name": "Soil_Dirt"
    },
    {
      "x": -18,
      "y": 2,
      "z": 10,
      "name": "Soil_Dirt"
    },
    {
      "x": -18,
      "y": 2,
      "z": 11,
      "name": "Soil_Dirt"
    },
    {
      "x": -18,
      "y": 2,
      "z": 12,
      "name": "Soil_Dirt"
    },
    {
      "x": -18,
      "y": 2,
      "z": 13,
      "name": "Soil_Dirt"
    },
    {
      "x": -17,
      "y": 2,
      "z": -12,
      "name": "Soil_Dirt"
    },
    {
      "x": -17,
      "y": 2,
      "z": -11,
      "name": "Soil_Dirt"
    },
    {
      "x": -17,
      "y": 2,
      "z": -10,
      "name": "Soil_Dirt"
    },
    {
      "x": -17,
      "y": 2,
      "z": -9,
      "name": "Soil_Dirt"
    },
    {
      "x": -17,
      "y": 2,
      "z": -8,
      "name": "Soil_Dirt"
    },
    {
      "x": -17,
      "y": 3,
      "z": -8,
      "name": "Soil_Dirt"
    },
    {
      "x": -17,
      "y": 1,
      "z": -7,
      "name": "Rock_Stone"
    },
    {
      "x": -17,
      "y": 2,
      "z": -7,
      "name": "Soil_Dirt"
    },
    {
      "x": -17,
      "y": 3,
      "z": -7,
      "name": "Soil_Dirt"
    },
    {
      "x": -17,
      "y": 0,
      "z": -6,
      "name": "Rock_Stone"
    },
    {
      "x": -17,
      "y": 1,
      "z": -6,
      "name": "Rock_Stone"
    },
    {
      "x": -17,
      "y": 2,
      "z": -6,
      "name": "Soil_Dirt"
    },
    {
      "x": -17,
      "y": 3,
      "z": -6,
      "name": "Soil_Dirt"
    },
    {
      "x": -17,
      "y": 0,
      "z": -5,
      "name": "Rock_Stone"
    },
    {
      "x": -17,
      "y": 1,
      "z": -5,
      "name": "Rock_Stone"
    },
    {
      "x": -17,
      "y": 2,
      "z": -5,
      "name": "Soil_Dirt"
    },
    {
      "x": -17,
      "y": 3,
      "z": -5,
      "name": "Soil_Dirt"
    },
    {
      "x": -17,
      "y": 4,
      "z": -5,
      "name": "Soil_Dirt"
    },
    {
      "x": -17,
      "y": 0,
      "z": -4,
      "name": "Rock_Stone"
    },
    {
      "x": -17,
      "y": 1,
      "z": -4,
      "name": "Rock_Stone"
    },
    {
      "x": -17,
      "y": 2,
      "z": -4,
      "name": "Soil_Dirt"
    },
    {
      "x": -17,
      "y": 3,
      "z": -4,
      "name": "Soil_Dirt"
    },
    {
      "x": -17,
      "y": 4,
      "z": -4,
      "name": "Soil_Dirt"
    },
    {
      "x": -17,
      "y": 0,
      "z": -3,
      "name": "Rock_Stone"
    },
    {
      "x": -17,
      "y": 1,
      "z": -3,
      "name": "Rock_Stone"
    },
    {
      "x": -17,
      "y": 2,
      "z": -3,
      "name": "Soil_Dirt"
    },
    {
      "x": -17,
      "y": 3,
      "z": -3,
      "name": "Soil_Dirt"
    },
    {
      "x": -17,
      "y": 4,
      "z": -3,
      "name": "Soil_Dirt"
    },
    {
      "x": -17,
      "y": 0,
      "z": -2,
      "name": "Rock_Stone"
    },
    {
      "x": -17,
      "y": 1,
      "z": -2,
      "name": "Rock_Stone"
    },
    {
      "x": -17,
      "y": 2,
      "z": -2,
      "name": "Soil_Dirt"
    },
    {
      "x": -17,
      "y": 3,
      "z": -2,
      "name": "Soil_Dirt"
    },
    {
      "x": -17,
      "y": 4,
      "z": -2,
      "name": "Rock_Stone"
    },
    {
      "x": -17,
      "y": 6,
      "z": -2,
      "name": "Empty"
    },
    {
      "x": -17,
      "y": 7,
      "z": -2,
      "name": "Empty"
    },
    {
      "x": -17,
      "y": 8,
      "z": -2,
      "name": "Empty"
    },
    {
      "x": -17,
      "y": 9,
      "z": -2,
      "name": "Empty"
    },
    {
      "x": -17,
      "y": 10,
      "z": -2,
      "name": "Empty"
    },
    {
      "x": -17,
      "y": 11,
      "z": -2,
      "name": "Empty"
    },
    {
      "x": -17,
      "y": 0,
      "z": -1,
      "name": "Rock_Stone"
    },
    {
      "x": -17,
      "y": 1,
      "z": -1,
      "name": "Rock_Stone"
    },
    {
      "x": -17,
      "y": 2,
      "z": -1,
      "name": "Soil_Dirt"
    },
    {
      "x": -17,
      "y": 3,
      "z": -1,
      "name": "Soil_Dirt"
    },
    {
      "x": -17,
      "y": 4,
      "z": -1,
      "name": "Rock_Stone_Cobble"
    },
    {
      "x": -17,
      "y": 5,
      "z": -1,
      "name": "Rock_Stone"
    },
    {
      "x": -17,
      "y": 6,
      "z": -1,
      "name": "Empty"
    },
    {
      "x": -17,
      "y": 7,
      "z": -1,
      "name": "Empty"
    },
    {
      "x": -17,
      "y": 8,
      "z": -1,
      "name": "Empty"
    },
    {
      "x": -17,
      "y": 9,
      "z": -1,
      "name": "Empty"
    },
    {
      "x": -17,
      "y": 10,
      "z": -1,
      "name": "Empty"
    },
    {
      "x": -17,
      "y": 11,
      "z": -1,
      "name": "Empty"
    },
    {
      "x": -17,
      "y": 0,
      "z": 0,
      "name": "Rock_Stone"
    },
    {
      "x": -17,
      "y": 1,
      "z": 0,
      "name": "Rock_Stone"
    },
    {
      "x": -17,
      "y": 2,
      "z": 0,
      "name": "Soil_Dirt"
    },
    {
      "x": -17,
      "y": 3,
      "z": 0,
      "name": "Soil_Dirt"
    },
    {
      "x": -17,
      "y": 4,
      "z": 0,
      "name": "Rock_Stone_Cobble"
    },
    {
      "x": -17,
      "y": 5,
      "z": 0,
      "name": "Rock_Stone"
    },
    {
      "x": -17,
      "y": 6,
      "z": 0,
      "name": "Empty"
    },
    {
      "x": -17,
      "y": 7,
      "z": 0,
      "name": "Empty"
    },
    {
      "x": -17,
      "y": 8,
      "z": 0,
      "name": "Empty"
    },
    {
      "x": -17,
      "y": 9,
      "z": 0,
      "name": "Empty"
    },
    {
      "x": -17,
      "y": 10,
      "z": 0,
      "name": "Empty"
    },
    {
      "x": -17,
      "y": 11,
      "z": 0,
      "name": "Empty"
    },
    {
      "x": -17,
      "y": 0,
      "z": 1,
      "name": "Rock_Stone"
    },
    {
      "x": -17,
      "y": 1,
      "z": 1,
      "name": "Rock_Stone"
    },
    {
      "x": -17,
      "y": 2,
      "z": 1,
      "name": "Soil_Dirt"
    },
    {
      "x": -17,
      "y": 3,
      "z": 1,
      "name": "Soil_Dirt"
    },
    {
      "x": -17,
      "y": 4,
      "z": 1,
      "name": "Rock_Stone"
    },
    {
      "x": -17,
      "y": 5,
      "z": 1,
      "name": "Rock_Stone"
    },
    {
      "x": -17,
      "y": 6,
      "z": 1,
      "name": "Rock_Stone"
    },
    {
      "x": -17,
      "y": 7,
      "z": 1,
      "name": "Empty"
    },
    {
      "x": -17,
      "y": 8,
      "z": 1,
      "name": "Empty"
    },
    {
      "x": -17,
      "y": 9,
      "z": 1,
      "name": "Empty"
    },
    {
      "x": -17,
      "y": 10,
      "z": 1,
      "name": "Empty"
    },
    {
      "x": -17,
      "y": 11,
      "z": 1,
      "name": "Empty"
    },
    {
      "x": -17,
      "y": 0,
      "z": 2,
      "name": "Rock_Stone"
    },
    {
      "x": -17,
      "y": 1,
      "z": 2,
      "name": "Rock_Stone"
    },
    {
      "x": -17,
      "y": 2,
      "z": 2,
      "name": "Soil_Dirt"
    },
    {
      "x": -17,
      "y": 3,
      "z": 2,
      "name": "Soil_Dirt"
    },
    {
      "x": -17,
      "y": 4,
      "z": 2,
      "name": "Rock_Stone_Cobble"
    },
    {
      "x": -17,
      "y": 5,
      "z": 2,
      "name": "Rock_Stone"
    },
    {
      "x": -17,
      "y": 6,
      "z": 2,
      "name": "Rock_Stone_Cobble"
    },
    {
      "x": -17,
      "y": 7,
      "z": 2,
      "name": "Rock_Stone"
    },
    {
      "x": -17,
      "y": 8,
      "z": 2,
      "name": "Empty"
    },
    {
      "x": -17,
      "y": 9,
      "z": 2,
      "name": "Empty"
    },
    {
      "x": -17,
      "y": 10,
      "z": 2,
      "name": "Empty"
    },
    {
      "x": -17,
      "y": 11,
      "z": 2,
      "name": "Empty"
    },
    {
      "x": -17,
      "y": 0,
      "z": 3,
      "name": "Rock_Stone"
    },
    {
      "x": -17,
      "y": 1,
      "z": 3,
      "name": "Rock_Stone"
    },
    {
      "x": -17,
      "y": 2,
      "z": 3,
      "name": "Soil_Dirt"
    },
    {
      "x": -17,
      "y": 3,
      "z": 3,
      "name": "Soil_Dirt"
    },
    {
      "x": -17,
      "y": 4,
      "z": 3,
      "name": "Rock_Stone"
    },
    {
      "x": -17,
      "y": 5,
      "z": 3,
      "name": "Rock_Stone_Cobble"
    },
    {
      "x": -17,
      "y": 6,
      "z": 3,
      "name": "Rock_Stone_Cobble"
    },
    {
      "x": -17,
      "y": 7,
      "z": 3,
      "name": "Deco_Bone_Skulls_Wall",
      "rotation": 3
    },
    {
      "x": -17,
      "y": 8,
      "z": 3,
      "name": "Rock_Stone_Cobble"
    },
    {
      "x": -17,
      "y": 9,
      "z": 3,
      "name": "Empty"
    },
    {
      "x": -17,
      "y": 10,
      "z": 3,
      "name": "Empty"
    },
    {
      "x": -17,
      "y": 11,
      "z": 3,
      "name": "Empty"
    },
    {
      "x": -17,
      "y": 0,
      "z": 4,
      "name": "Rock_Stone"
    },
    {
      "x": -17,
      "y": 1,
      "z": 4,
      "name": "Rock_Stone"
    },
    {
      "x": -17,
      "y": 2,
      "z": 4,
      "name": "Soil_Dirt"
    },
    {
      "x": -17,
      "y": 3,
      "z": 4,
      "name": "Soil_Dirt"
    },
    {
      "x": -17,
      "y": 4,
      "z": 4,
      "name": "Rock_Stone_Cobble"
    },
    {
      "x": -17,
      "y": 5,
      "z": 4,
      "name": "Rock_Stone_Cobble_Mossy"
    },
    {
      "x": -17,
      "y": 6,
      "z": 4,
      "name": "Rock_Stone_Cobble_Mossy"
    },
    {
      "x": -17,
      "y": 7,
      "z": 4,
      "name": "Rock_Stone"
    },
    {
      "x": -17,
      "y": 8,
      "z": 4,
      "name": "Rock_Stone"
    },
    {
      "x": -17,
      "y": 9,
      "z": 4,
      "name": "Empty"
    },
    {
      "x": -17,
      "y": 10,
      "z": 4,
      "name": "Empty"
    },
    {
      "x": -17,
      "y": 11,
      "z": 4,
      "name": "Empty"
    },
    {
      "x": -17,
      "y": 0,
      "z": 5,
      "name": "Rock_Stone"
    },
    {
      "x": -17,
      "y": 1,
      "z": 5,
      "name": "Rock_Stone"
    },
    {
      "x": -17,
      "y": 2,
      "z": 5,
      "name": "Soil_Dirt"
    },
    {
      "x": -17,
      "y": 3,
      "z": 5,
      "name": "Soil_Dirt"
    },
    {
      "x": -17,
      "y": 4,
      "z": 5,
      "name": "Rock_Stone"
    },
    {
      "x": -17,
      "y": 5,
      "z": 5,
      "name": "Rock_Stone_Cobble"
    },
    {
      "x": -17,
      "y": 6,
      "z": 5,
      "name": "Rock_Stone"
    },
    {
      "x": -17,
      "y": 7,
      "z": 5,
      "name": "Rock_Stone_Cobble_Mossy"
    },
    {
      "x": -17,
      "y": 0,
      "z": 6,
      "name": "Rock_Stone"
    },
    {
      "x": -17,
      "y": 1,
      "z": 6,
      "name": "Rock_Stone"
    },
    {
      "x": -17,
      "y": 2,
      "z": 6,
      "name": "Soil_Dirt"
    },
    {
      "x": -17,
      "y": 3,
      "z": 6,
      "name": "Soil_Dirt"
    },
    {
      "x": -17,
      "y": 4,
      "z": 6,
      "name": "Rock_Stone"
    },
    {
      "x": -17,
      "y": 5,
      "z": 6,
      "name": "Rock_Stone_Cobble"
    },
    {
      "x": -17,
      "y": 1,
      "z": 7,
      "name": "Rock_Stone"
    },
    {
      "x": -17,
      "y": 2,
      "z": 7,
      "name": "Soil_Dirt"
    },
    {
      "x": -17,
      "y": 3,
      "z": 7,
      "name": "Soil_Dirt"
    },
    {
      "x": -17,
      "y": 4,
      "z": 7,
      "name": "Rock_Stone_Cobble"
    },
    {
      "x": -17,
      "y": 2,
      "z": 8,
      "name": "Soil_Dirt"
    },
    {
      "x": -17,
      "y": 3,
      "z": 8,
      "name": "Soil_Dirt"
    },
    {
      "x": -17,
      "y": 2,
      "z": 9,
      "name": "Soil_Dirt"
    },
    {
      "x": -17,
      "y": 3,
      "z": 9,
      "name": "Soil_Dirt"
    },
    {
      "x": -17,
      "y": 2,
      "z": 10,
      "name": "Soil_Dirt"
    },
    {
      "x": -17,
      "y": 3,
      "z": 10,
      "name": "Soil_Dirt"
    },
    {
      "x": -17,
      "y": 2,
      "z": 11,
      "name": "Soil_Dirt"
    },
    {
      "x": -17,
      "y": 3,
      "z": 11,
      "name": "Soil_Dirt"
    },
    {
      "x": -17,
      "y": 2,
      "z": 12,
      "name": "Soil_Dirt"
    },
    {
      "x": -17,
      "y": 3,
      "z": 12,
      "name": "Soil_Dirt"
    },
    {
      "x": -17,
      "y": 2,
      "z": 13,
      "name": "Soil_Dirt"
    },
    {
      "x": -17,
      "y": 2,
      "z": 14,
      "name": "Soil_Dirt"
    },
    {
      "x": -16,
      "y": 2,
      "z": -12,
      "name": "Soil_Dirt"
    },
    {
      "x": -16,
      "y": 2,
      "z": -11,
      "name": "Soil_Dirt"
    },
    {
      "x": -16,
      "y": 2,
      "z": -10,
      "name": "Soil_Dirt"
    },
    {
      "x": -16,
      "y": 1,
      "z": -9,
      "name": "Rock_Stone"
    },
    {
      "x": -16,
      "y": 2,
      "z": -9,
      "name": "Soil_Dirt"
    },
    {
      "x": -16,
      "y": 3,
      "z": -9,
      "name": "Soil_Dirt"
    },
    {
      "x": -16,
      "y": 1,
      "z": -8,
      "name": "Rock_Stone"
    },
    {
      "x": -16,
      "y": 2,
      "z": -8,
      "name": "Soil_Dirt"
    },
    {
      "x": -16,
      "y": 3,
      "z": -8,
      "name": "Soil_Dirt"
    },
    {
      "x": -16,
      "y": 0,
      "z": -7,
      "name": "Rock_Stone"
    },
    {
      "x": -16,
      "y": 1,
      "z": -7,
      "name": "Rock_Stone"
    },
    {
      "x": -16,
      "y": 2,
      "z": -7,
      "name": "Soil_Dirt"
    },
    {
      "x": -16,
      "y": 3,
      "z": -7,
      "name": "Soil_Dirt"
    },
    {
      "x": -16,
      "y": 4,
      "z": -7,
      "name": "Soil_Dirt"
    },
    {
      "x": -16,
      "y": 0,
      "z": -6,
      "name": "Rock_Stone"
    },
    {
      "x": -16,
      "y": 1,
      "z": -6,
      "name": "Rock_Stone"
    },
    {
      "x": -16,
      "y": 2,
      "z": -6,
      "name": "Soil_Dirt"
    },
    {
      "x": -16,
      "y": 3,
      "z": -6,
      "name": "Soil_Dirt"
    },
    {
      "x": -16,
      "y": 4,
      "z": -6,
      "name": "Soil_Dirt"
    },
    {
      "x": -16,
      "y": 0,
      "z": -5,
      "name": "Rock_Stone"
    },
    {
      "x": -16,
      "y": 1,
      "z": -5,
      "name": "Rock_Stone"
    },
    {
      "x": -16,
      "y": 2,
      "z": -5,
      "name": "Soil_Dirt"
    },
    {
      "x": -16,
      "y": 3,
      "z": -5,
      "name": "Soil_Dirt"
    },
    {
      "x": -16,
      "y": 4,
      "z": -5,
      "name": "Soil_Dirt"
    },
    {
      "x": -16,
      "y": 0,
      "z": -4,
      "name": "Rock_Stone"
    },
    {
      "x": -16,
      "y": 1,
      "z": -4,
      "name": "Rock_Stone"
    },
    {
      "x": -16,
      "y": 2,
      "z": -4,
      "name": "Soil_Dirt"
    },
    {
      "x": -16,
      "y": 3,
      "z": -4,
      "name": "Soil_Dirt"
    },
    {
      "x": -16,
      "y": 4,
      "z": -4,
      "name": "Soil_Dirt"
    },
    {
      "x": -16,
      "y": 6,
      "z": -4,
      "name": "Empty"
    },
    {
      "x": -16,
      "y": 7,
      "z": -4,
      "name": "Empty"
    },
    {
      "x": -16,
      "y": 8,
      "z": -4,
      "name": "Empty"
    },
    {
      "x": -16,
      "y": 9,
      "z": -4,
      "name": "Empty"
    },
    {
      "x": -16,
      "y": 10,
      "z": -4,
      "name": "Empty"
    },
    {
      "x": -16,
      "y": 11,
      "z": -4,
      "name": "Empty"
    },
    {
      "x": -16,
      "y": 0,
      "z": -3,
      "name": "Rock_Stone"
    },
    {
      "x": -16,
      "y": 1,
      "z": -3,
      "name": "Rock_Stone"
    },
    {
      "x": -16,
      "y": 2,
      "z": -3,
      "name": "Soil_Dirt"
    },
    {
      "x": -16,
      "y": 3,
      "z": -3,
      "name": "Soil_Dirt"
    },
    {
      "x": -16,
      "y": 4,
      "z": -3,
      "name": "Soil_Dirt"
    },
    {
      "x": -16,
      "y": 6,
      "z": -3,
      "name": "Empty"
    },
    {
      "x": -16,
      "y": 7,
      "z": -3,
      "name": "Empty"
    },
    {
      "x": -16,
      "y": 8,
      "z": -3,
      "name": "Empty"
    },
    {
      "x": -16,
      "y": 9,
      "z": -3,
      "name": "Empty"
    },
    {
      "x": -16,
      "y": 10,
      "z": -3,
      "name": "Empty"
    },
    {
      "x": -16,
      "y": 11,
      "z": -3,
      "name": "Empty"
    },
    {
      "x": -16,
      "y": 0,
      "z": -2,
      "name": "Rock_Stone"
    },
    {
      "x": -16,
      "y": 1,
      "z": -2,
      "name": "Rock_Stone"
    },
    {
      "x": -16,
      "y": 2,
      "z": -2,
      "name": "Soil_Dirt"
    },
    {
      "x": -16,
      "y": 3,
      "z": -2,
      "name": "Soil_Dirt"
    },
    {
      "x": -16,
      "y": 4,
      "z": -2,
      "name": "Rock_Stone"
    },
    {
      "x": -16,
      "y": 6,
      "z": -2,
      "name": "Empty"
    },
    {
      "x": -16,
      "y": 7,
      "z": -2,
      "name": "Empty"
    },
    {
      "x": -16,
      "y": 8,
      "z": -2,
      "name": "Empty"
    },
    {
      "x": -16,
      "y": 9,
      "z": -2,
      "name": "Empty"
    },
    {
      "x": -16,
      "y": 10,
      "z": -2,
      "name": "Empty"
    },
    {
      "x": -16,
      "y": 11,
      "z": -2,
      "name": "Empty"
    },
    {
      "x": -16,
      "y": 0,
      "z": -1,
      "name": "Rock_Stone"
    },
    {
      "x": -16,
      "y": 1,
      "z": -1,
      "name": "Rock_Stone"
    },
    {
      "x": -16,
      "y": 2,
      "z": -1,
      "name": "Rock_Stone"
    },
    {
      "x": -16,
      "y": 3,
      "z": -1,
      "name": "Soil_Dirt"
    },
    {
      "x": -16,
      "y": 4,
      "z": -1,
      "name": "Rock_Stone_Cobble_Mossy"
    },
    {
      "x": -16,
      "y": 5,
      "z": -1,
      "name": "Deco_Bone_Skulls_Wall",
      "rotation": 2
    },
    {
      "x": -16,
      "y": 6,
      "z": -1,
      "name": "Rock_Stone_Cobble"
    },
    {
      "x": -16,
      "y": 7,
      "z": -1,
      "name": "Deco_Bone_Skulls"
    },
    {
      "x": -16,
      "y": 8,
      "z": -1,
      "name": "Empty"
    },
    {
      "x": -16,
      "y": 9,
      "z": -1,
      "name": "Empty"
    },
    {
      "x": -16,
      "y": 10,
      "z": -1,
      "name": "Empty"
    },
    {
      "x": -16,
      "y": 11,
      "z": -1,
      "name": "Empty"
    },
    {
      "x": -16,
      "y": 0,
      "z": 0,
      "name": "Rock_Stone"
    },
    {
      "x": -16,
      "y": 1,
      "z": 0,
      "name": "Rock_Stone"
    },
    {
      "x": -16,
      "y": 2,
      "z": 0,
      "name": "Rock_Stone"
    },
    {
      "x": -16,
      "y": 3,
      "z": 0,
      "name": "Soil_Dirt"
    },
    {
      "x": -16,
      "y": 4,
      "z": 0,
      "name": "Rock_Stone"
    },
    {
      "x": -16,
      "y": 5,
      "z": 0,
      "name": "Rock_Stone_Cobble"
    },
    {
      "x": -16,
      "y": 6,
      "z": 0,
      "name": "Rock_Stone_Cobble"
    },
    {
      "x": -16,
      "y": 7,
      "z": 0,
      "name": "Empty"
    },
    {
      "x": -16,
      "y": 8,
      "z": 0,
      "name": "Empty"
    },
    {
      "x": -16,
      "y": 9,
      "z": 0,
      "name": "Empty"
    },
    {
      "x": -16,
      "y": 10,
      "z": 0,
      "name": "Empty"
    },
    {
      "x": -16,
      "y": 11,
      "z": 0,
      "name": "Empty"
    },
    {
      "x": -16,
      "y": 0,
      "z": 1,
      "name": "Rock_Stone"
    },
    {
      "x": -16,
      "y": 1,
      "z": 1,
      "name": "Rock_Stone"
    },
    {
      "x": -16,
      "y": 2,
      "z": 1,
      "name": "Soil_Dirt"
    },
    {
      "x": -16,
      "y": 3,
      "z": 1,
      "name": "Soil_Dirt"
    },
    {
      "x": -16,
      "y": 4,
      "z": 1,
      "name": "Rock_Stone"
    },
    {
      "x": -16,
      "y": 5,
      "z": 1,
      "name": "Rock_Stone"
    },
    {
      "x": -16,
      "y": 6,
      "z": 1,
      "name": "Rock_Stone_Cobble_Mossy"
    },
    {
      "x": -16,
      "y": 7,
      "z": 1,
      "name": "Rock_Stone_Cobble"
    },
    {
      "x": -16,
      "y": 8,
      "z": 1,
      "name": "Empty"
    },
    {
      "x": -16,
      "y": 9,
      "z": 1,
      "name": "Empty"
    },
    {
      "x": -16,
      "y": 10,
      "z": 1,
      "name": "Empty"
    },
    {
      "x": -16,
      "y": 11,
      "z": 1,
      "name": "Empty"
    },
    {
      "x": -16,
      "y": 0,
      "z": 2,
      "name": "Rock_Stone"
    },
    {
      "x": -16,
      "y": 1,
      "z": 2,
      "name": "Rock_Stone"
    },
    {
      "x": -16,
      "y": 2,
      "z": 2,
      "name": "Soil_Dirt"
    },
    {
      "x": -16,
      "y": 3,
      "z": 2,
      "name": "Soil_Dirt"
    },
    {
      "x": -16,
      "y": 4,
      "z": 2,
      "name": "Rock_Stone"
    },
    {
      "x": -16,
      "y": 5,
      "z": 2,
      "name": "Rock_Stone_Cobble"
    },
    {
      "x": -16,
      "y": 6,
      "z": 2,
      "name": "Rock_Stone"
    },
    {
      "x": -16,
      "y": 7,
      "z": 2,
      "name": "Rock_Stone_Cobble_Mossy"
    },
    {
      "x": -16,
      "y": 8,
      "z": 2,
      "name": "Rock_Stone"
    },
    {
      "x": -16,
      "y": 9,
      "z": 2,
      "name": "Rock_Stone_Cobble_Mossy"
    },
    {
      "x": -16,
      "y": 10,
      "z": 2,
      "name": "Empty"
    },
    {
      "x": -16,
      "y": 11,
      "z": 2,
      "name": "Empty"
    },
    {
      "x": -16,
      "y": 0,
      "z": 3,
      "name": "Rock_Stone"
    },
    {
      "x": -16,
      "y": 1,
      "z": 3,
      "name": "Rock_Stone"
    },
    {
      "x": -16,
      "y": 2,
      "z": 3,
      "name": "Soil_Dirt"
    },
    {
      "x": -16,
      "y": 3,
      "z": 3,
      "name": "Soil_Dirt"
    },
    {
      "x": -16,
      "y": 4,
      "z": 3,
      "name": "Rock_Stone"
    },
    {
      "x": -16,
      "y": 5,
      "z": 3,
      "name": "Rock_Stone"
    },
    {
      "x": -16,
      "y": 6,
      "z": 3,
      "name": "Rock_Stone"
    },
    {
      "x": -16,
      "y": 7,
      "z": 3,
      "name": "Rock_Stone_Cobble_Mossy"
    },
    {
      "x": -16,
      "y": 8,
      "z": 3,
      "name": "Rock_Stone_Cobble_Mossy"
    },
    {
      "x": -16,
      "y": 9,
      "z": 3,
      "name": "Rock_Stone_Cobble"
    },
    {
      "x": -16,
      "y": 10,
      "z": 3,
      "name": "Rock_Stone_Cobble"
    },
    {
      "x": -16,
      "y": 11,
      "z": 3,
      "name": "Empty"
    },
    {
      "x": -16,
      "y": 0,
      "z": 4,
      "name": "Rock_Stone"
    },
    {
      "x": -16,
      "y": 1,
      "z": 4,
      "name": "Rock_Stone"
    },
    {
      "x": -16,
      "y": 2,
      "z": 4,
      "name": "Soil_Dirt"
    },
    {
      "x": -16,
      "y": 3,
      "z": 4,
      "name": "Soil_Dirt"
    },
    {
      "x": -16,
      "y": 4,
      "z": 4,
      "name": "Rock_Stone"
    },
    {
      "x": -16,
      "y": 5,
      "z": 4,
      "name": "Rock_Stone_Cobble"
    },
    {
      "x": -16,
      "y": 6,
      "z": 4,
      "name": "Rock_Stone"
    },
    {
      "x": -16,
      "y": 7,
      "z": 4,
      "name": "Rock_Stone"
    },
    {
      "x": -16,
      "y": 8,
      "z": 4,
      "name": "Rock_Stone_Cobble"
    },
    {
      "x": -16,
      "y": 9,
      "z": 4,
      "name": "Rock_Stone"
    },
    {
      "x": -16,
      "y": 10,
      "z": 4,
      "name": "Rock_Stone_Cobble"
    },
    {
      "x": -16,
      "y": 11,
      "z": 4,
      "name": "Rock_Stone"
    },
    {
      "x": -16,
      "y": 0,
      "z": 5,
      "name": "Rock_Stone"
    },
    {
      "x": -16,
      "y": 1,
      "z": 5,
      "name": "Rock_Stone"
    },
    {
      "x": -16,
      "y": 2,
      "z": 5,
      "name": "Soil_Dirt"
    },
    {
      "x": -16,
      "y": 3,
      "z": 5,
      "name": "Soil_Dirt"
    },
    {
      "x": -16,
      "y": 4,
      "z": 5,
      "name": "Rock_Stone"
    },
    {
      "x": -16,
      "y": 5,
      "z": 5,
      "name": "Rock_Stone_Cobble_Mossy"
    },
    {
      "x": -16,
      "y": 6,
      "z": 5,
      "name": "Rock_Stone"
    },
    {
      "x": -16,
      "y": 7,
      "z": 5,
      "name": "Rock_Stone"
    },
    {
      "x": -16,
      "y": 8,
      "z": 5,
      "name": "Rock_Stone"
    },
    {
      "x": -16,
      "y": 9,
      "z": 5,
      "name": "Rock_Stone"
    },
    {
      "x": -16,
      "y": 10,
      "z": 5,
      "name": "Rock_Stone"
    },
    {
      "x": -16,
      "y": 11,
      "z": 5,
      "name": "Empty"
    },
    {
      "x": -16,
      "y": 0,
      "z": 6,
      "name": "Rock_Stone"
    },
    {
      "x": -16,
      "y": 1,
      "z": 6,
      "name": "Rock_Stone"
    },
    {
      "x": -16,
      "y": 2,
      "z": 6,
      "name": "Soil_Dirt"
    },
    {
      "x": -16,
      "y": 3,
      "z": 6,
      "name": "Soil_Dirt"
    },
    {
      "x": -16,
      "y": 4,
      "z": 6,
      "name": "Rock_Stone"
    },
    {
      "x": -16,
      "y": 5,
      "z": 6,
      "name": "Rock_Stone"
    },
    {
      "x": -16,
      "y": 6,
      "z": 6,
      "name": "Rock_Stone_Cobble_Mossy"
    },
    {
      "x": -16,
      "y": 7,
      "z": 6,
      "name": "Rock_Stone"
    },
    {
      "x": -16,
      "y": 8,
      "z": 6,
      "name": "Rock_Stone"
    },
    {
      "x": -16,
      "y": 9,
      "z": 6,
      "name": "Empty"
    },
    {
      "x": -16,
      "y": 10,
      "z": 6,
      "name": "Empty"
    },
    {
      "x": -16,
      "y": 11,
      "z": 6,
      "name": "Empty"
    },
    {
      "x": -16,
      "y": 0,
      "z": 7,
      "name": "Rock_Stone"
    },
    {
      "x": -16,
      "y": 1,
      "z": 7,
      "name": "Rock_Stone"
    },
    {
      "x": -16,
      "y": 2,
      "z": 7,
      "name": "Soil_Dirt"
    },
    {
      "x": -16,
      "y": 3,
      "z": 7,
      "name": "Soil_Dirt"
    },
    {
      "x": -16,
      "y": 4,
      "z": 7,
      "name": "Rock_Stone_Cobble"
    },
    {
      "x": -16,
      "y": 5,
      "z": 7,
      "name": "Rock_Stone_Cobble_Mossy"
    },
    {
      "x": -16,
      "y": 6,
      "z": 7,
      "name": "Rock_Stone"
    },
    {
      "x": -16,
      "y": 7,
      "z": 7,
      "name": "Deco_Bone_Skulls"
    },
    {
      "x": -16,
      "y": 1,
      "z": 8,
      "name": "Rock_Stone"
    },
    {
      "x": -16,
      "y": 2,
      "z": 8,
      "name": "Soil_Dirt"
    },
    {
      "x": -16,
      "y": 3,
      "z": 8,
      "name": "Soil_Dirt"
    },
    {
      "x": -16,
      "y": 4,
      "z": 8,
      "name": "Rock_Stone"
    },
    {
      "x": -16,
      "y": 1,
      "z": 9,
      "name": "Rock_Stone"
    },
    {
      "x": -16,
      "y": 2,
      "z": 9,
      "name": "Soil_Dirt"
    },
    {
      "x": -16,
      "y": 3,
      "z": 9,
      "name": "Soil_Dirt"
    },
    {
      "x": -16,
      "y": 4,
      "z": 9,
      "name": "Soil_Dirt"
    },
    {
      "x": -16,
      "y": 2,
      "z": 10,
      "name": "Soil_Dirt"
    },
    {
      "x": -16,
      "y": 3,
      "z": 10,
      "name": "Soil_Dirt"
    },
    {
      "x": -16,
      "y": 2,
      "z": 11,
      "name": "Soil_Dirt"
    },
    {
      "x": -16,
      "y": 3,
      "z": 11,
      "name": "Soil_Dirt"
    },
    {
      "x": -16,
      "y": 2,
      "z": 12,
      "name": "Soil_Dirt"
    },
    {
      "x": -16,
      "y": 3,
      "z": 12,
      "name": "Soil_Dirt"
    },
    {
      "x": -16,
      "y": 2,
      "z": 13,
      "name": "Soil_Dirt"
    },
    {
      "x": -16,
      "y": 3,
      "z": 13,
      "name": "Soil_Dirt"
    },
    {
      "x": -16,
      "y": 2,
      "z": 14,
      "name": "Soil_Dirt"
    },
    {
      "x": -15,
      "y": 2,
      "z": -14,
      "name": "Soil_Dirt"
    },
    {
      "x": -15,
      "y": 2,
      "z": -13,
      "name": "Soil_Dirt"
    },
    {
      "x": -15,
      "y": 2,
      "z": -12,
      "name": "Soil_Dirt"
    },
    {
      "x": -15,
      "y": 2,
      "z": -11,
      "name": "Soil_Dirt"
    },
    {
      "x": -15,
      "y": 1,
      "z": -10,
      "name": "Rock_Stone"
    },
    {
      "x": -15,
      "y": 2,
      "z": -10,
      "name": "Soil_Dirt"
    },
    {
      "x": -15,
      "y": 3,
      "z": -10,
      "name": "Soil_Dirt"
    },
    {
      "x": -15,
      "y": 0,
      "z": -9,
      "name": "Rock_Stone"
    },
    {
      "x": -15,
      "y": 1,
      "z": -9,
      "name": "Rock_Stone"
    },
    {
      "x": -15,
      "y": 2,
      "z": -9,
      "name": "Soil_Dirt"
    },
    {
      "x": -15,
      "y": 3,
      "z": -9,
      "name": "Soil_Dirt"
    },
    {
      "x": -15,
      "y": 0,
      "z": -8,
      "name": "Rock_Stone"
    },
    {
      "x": -15,
      "y": 1,
      "z": -8,
      "name": "Rock_Stone"
    },
    {
      "x": -15,
      "y": 2,
      "z": -8,
      "name": "Soil_Dirt"
    },
    {
      "x": -15,
      "y": 3,
      "z": -8,
      "name": "Soil_Dirt"
    },
    {
      "x": -15,
      "y": 4,
      "z": -8,
      "name": "Soil_Dirt"
    },
    {
      "x": -15,
      "y": 0,
      "z": -7,
      "name": "Rock_Stone"
    },
    {
      "x": -15,
      "y": 1,
      "z": -7,
      "name": "Rock_Stone"
    },
    {
      "x": -15,
      "y": 2,
      "z": -7,
      "name": "Soil_Dirt"
    },
    {
      "x": -15,
      "y": 3,
      "z": -7,
      "name": "Soil_Dirt"
    },
    {
      "x": -15,
      "y": 4,
      "z": -7,
      "name": "Soil_Dirt"
    },
    {
      "x": -15,
      "y": 0,
      "z": -6,
      "name": "Rock_Stone"
    },
    {
      "x": -15,
      "y": 1,
      "z": -6,
      "name": "Rock_Stone"
    },
    {
      "x": -15,
      "y": 2,
      "z": -6,
      "name": "Soil_Dirt"
    },
    {
      "x": -15,
      "y": 3,
      "z": -6,
      "name": "Soil_Dirt"
    },
    {
      "x": -15,
      "y": 4,
      "z": -6,
      "name": "Soil_Dirt"
    },
    {
      "x": -15,
      "y": 6,
      "z": -6,
      "name": "Empty"
    },
    {
      "x": -15,
      "y": 7,
      "z": -6,
      "name": "Empty"
    },
    {
      "x": -15,
      "y": 8,
      "z": -6,
      "name": "Empty"
    },
    {
      "x": -15,
      "y": 9,
      "z": -6,
      "name": "Empty"
    },
    {
      "x": -15,
      "y": 10,
      "z": -6,
      "name": "Empty"
    },
    {
      "x": -15,
      "y": 11,
      "z": -6,
      "name": "Empty"
    },
    {
      "x": -15,
      "y": 0,
      "z": -5,
      "name": "Rock_Stone"
    },
    {
      "x": -15,
      "y": 1,
      "z": -5,
      "name": "Rock_Stone"
    },
    {
      "x": -15,
      "y": 2,
      "z": -5,
      "name": "Soil_Dirt"
    },
    {
      "x": -15,
      "y": 3,
      "z": -5,
      "name": "Soil_Dirt"
    },
    {
      "x": -15,
      "y": 4,
      "z": -5,
      "name": "Soil_Dirt"
    },
    {
      "x": -15,
      "y": 6,
      "z": -5,
      "name": "Empty"
    },
    {
      "x": -15,
      "y": 7,
      "z": -5,
      "name": "Empty"
    },
    {
      "x": -15,
      "y": 8,
      "z": -5,
      "name": "Empty"
    },
    {
      "x": -15,
      "y": 9,
      "z": -5,
      "name": "Empty"
    },
    {
      "x": -15,
      "y": 10,
      "z": -5,
      "name": "Empty"
    },
    {
      "x": -15,
      "y": 11,
      "z": -5,
      "name": "Empty"
    },
    {
      "x": -15,
      "y": 0,
      "z": -4,
      "name": "Rock_Stone"
    },
    {
      "x": -15,
      "y": 1,
      "z": -4,
      "name": "Rock_Stone"
    },
    {
      "x": -15,
      "y": 2,
      "z": -4,
      "name": "Soil_Dirt"
    },
    {
      "x": -15,
      "y": 3,
      "z": -4,
      "name": "Soil_Dirt"
    },
    {
      "x": -15,
      "y": 4,
      "z": -4,
      "name": "Soil_Dirt"
    },
    {
      "x": -15,
      "y": 6,
      "z": -4,
      "name": "Empty"
    },
    {
      "x": -15,
      "y": 7,
      "z": -4,
      "name": "Empty"
    },
    {
      "x": -15,
      "y": 8,
      "z": -4,
      "name": "Empty"
    },
    {
      "x": -15,
      "y": 9,
      "z": -4,
      "name": "Empty"
    },
    {
      "x": -15,
      "y": 10,
      "z": -4,
      "name": "Empty"
    },
    {
      "x": -15,
      "y": 11,
      "z": -4,
      "name": "Empty"
    },
    {
      "x": -15,
      "y": 0,
      "z": -3,
      "name": "Rock_Stone"
    },
    {
      "x": -15,
      "y": 1,
      "z": -3,
      "name": "Rock_Stone"
    },
    {
      "x": -15,
      "y": 2,
      "z": -3,
      "name": "Soil_Dirt"
    },
    {
      "x": -15,
      "y": 3,
      "z": -3,
      "name": "Soil_Dirt"
    },
    {
      "x": -15,
      "y": 4,
      "z": -3,
      "name": "Soil_Dirt"
    },
    {
      "x": -15,
      "y": 6,
      "z": -3,
      "name": "Empty"
    },
    {
      "x": -15,
      "y": 7,
      "z": -3,
      "name": "Empty"
    },
    {
      "x": -15,
      "y": 8,
      "z": -3,
      "name": "Empty"
    },
    {
      "x": -15,
      "y": 9,
      "z": -3,
      "name": "Empty"
    },
    {
      "x": -15,
      "y": 10,
      "z": -3,
      "name": "Empty"
    },
    {
      "x": -15,
      "y": 11,
      "z": -3,
      "name": "Empty"
    },
    {
      "x": -15,
      "y": 0,
      "z": -2,
      "name": "Rock_Stone"
    },
    {
      "x": -15,
      "y": 1,
      "z": -2,
      "name": "Rock_Stone"
    },
    {
      "x": -15,
      "y": 2,
      "z": -2,
      "name": "Rock_Stone"
    },
    {
      "x": -15,
      "y": 3,
      "z": -2,
      "name": "Soil_Dirt"
    },
    {
      "x": -15,
      "y": 4,
      "z": -2,
      "name": "Soil_Dirt"
    },
    {
      "x": -15,
      "y": 6,
      "z": -2,
      "name": "Empty"
    },
    {
      "x": -15,
      "y": 7,
      "z": -2,
      "name": "Empty"
    },
    {
      "x": -15,
      "y": 8,
      "z": -2,
      "name": "Empty"
    },
    {
      "x": -15,
      "y": 9,
      "z": -2,
      "name": "Empty"
    },
    {
      "x": -15,
      "y": 10,
      "z": -2,
      "name": "Empty"
    },
    {
      "x": -15,
      "y": 11,
      "z": -2,
      "name": "Empty"
    },
    {
      "x": -15,
      "y": 0,
      "z": -1,
      "name": "Rock_Stone"
    },
    {
      "x": -15,
      "y": 1,
      "z": -1,
      "name": "Rock_Stone"
    },
    {
      "x": -15,
      "y": 2,
      "z": -1,
      "name": "Rock_Stone"
    },
    {
      "x": -15,
      "y": 3,
      "z": -1,
      "name": "Soil_Dirt"
    },
    {
      "x": -15,
      "y": 4,
      "z": -1,
      "name": "Rock_Stone"
    },
    {
      "x": -15,
      "y": 5,
      "z": -1,
      "name": "Rock_Stone_Cobble_Mossy"
    },
    {
      "x": -15,
      "y": 6,
      "z": -1,
      "name": "Rock_Stone"
    },
    {
      "x": -15,
      "y": 7,
      "z": -1,
      "name": "Empty"
    },
    {
      "x": -15,
      "y": 8,
      "z": -1,
      "name": "Empty"
    },
    {
      "x": -15,
      "y": 9,
      "z": -1,
      "name": "Empty"
    },
    {
      "x": -15,
      "y": 10,
      "z": -1,
      "name": "Empty"
    },
    {
      "x": -15,
      "y": 11,
      "z": -1,
      "name": "Empty"
    },
    {
      "x": -15,
      "y": 0,
      "z": 0,
      "name": "Rock_Stone"
    },
    {
      "x": -15,
      "y": 1,
      "z": 0,
      "name": "Rock_Stone"
    },
    {
      "x": -15,
      "y": 2,
      "z": 0,
      "name": "Rock_Stone"
    },
    {
      "x": -15,
      "y": 3,
      "z": 0,
      "name": "Soil_Dirt"
    },
    {
      "x": -15,
      "y": 4,
      "z": 0,
      "name": "Rock_Stone_Cobble"
    },
    {
      "x": -15,
      "y": 5,
      "z": 0,
      "name": "Rock_Stone_Cobble_Mossy"
    },
    {
      "x": -15,
      "y": 6,
      "z": 0,
      "name": "Rock_Stone_Cobble"
    },
    {
      "x": -15,
      "y": 7,
      "z": 0,
      "name": "Rock_Stone_Cobble_Mossy"
    },
    {
      "x": -15,
      "y": 8,
      "z": 0,
      "name": "Empty"
    },
    {
      "x": -15,
      "y": 9,
      "z": 0,
      "name": "Empty"
    },
    {
      "x": -15,
      "y": 10,
      "z": 0,
      "name": "Empty"
    },
    {
      "x": -15,
      "y": 11,
      "z": 0,
      "name": "Empty"
    },
    {
      "x": -15,
      "y": 0,
      "z": 1,
      "name": "Rock_Stone"
    },
    {
      "x": -15,
      "y": 1,
      "z": 1,
      "name": "Rock_Stone"
    },
    {
      "x": -15,
      "y": 2,
      "z": 1,
      "name": "Rock_Stone"
    },
    {
      "x": -15,
      "y": 3,
      "z": 1,
      "name": "Soil_Dirt"
    },
    {
      "x": -15,
      "y": 4,
      "z": 1,
      "name": "Rock_Stone"
    },
    {
      "x": -15,
      "y": 5,
      "z": 1,
      "name": "Rock_Stone_Cobble"
    },
    {
      "x": -15,
      "y": 6,
      "z": 1,
      "name": "Rock_Stone_Cobble"
    },
    {
      "x": -15,
      "y": 7,
      "z": 1,
      "name": "Rock_Stone"
    },
    {
      "x": -15,
      "y": 8,
      "z": 1,
      "name": "Rock_Stone_Cobble"
    },
    {
      "x": -15,
      "y": 9,
      "z": 1,
      "name": "Rock_Stone"
    },
    {
      "x": -15,
      "y": 10,
      "z": 1,
      "name": "Empty"
    },
    {
      "x": -15,
      "y": 11,
      "z": 1,
      "name": "Empty"
    },
    {
      "x": -15,
      "y": 0,
      "z": 2,
      "name": "Rock_Stone"
    },
    {
      "x": -15,
      "y": 1,
      "z": 2,
      "name": "Rock_Stone"
    },
    {
      "x": -15,
      "y": 2,
      "z": 2,
      "name": "Rock_Stone"
    },
    {
      "x": -15,
      "y": 3,
      "z": 2,
      "name": "Soil_Dirt"
    },
    {
      "x": -15,
      "y": 4,
      "z": 2,
      "name": "Rock_Stone"
    },
    {
      "x": -15,
      "y": 5,
      "z": 2,
      "name": "Rock_Stone"
    },
    {
      "x": -15,
      "y": 6,
      "z": 2,
      "name": "Rock_Stone"
    },
    {
      "x": -15,
      "y": 7,
      "z": 2,
      "name": "Rock_Stone"
    },
    {
      "x": -15,
      "y": 8,
      "z": 2,
      "name": "Rock_Stone"
    },
    {
      "x": -15,
      "y": 9,
      "z": 2,
      "name": "Rock_Stone"
    },
    {
      "x": -15,
      "y": 10,
      "z": 2,
      "name": "Rock_Stone_Cobble"
    },
    {
      "x": -15,
      "y": 11,
      "z": 2,
      "name": "Empty"
    },
    {
      "x": -15,
      "y": 0,
      "z": 3,
      "name": "Rock_Stone"
    },
    {
      "x": -15,
      "y": 1,
      "z": 3,
      "name": "Rock_Stone"
    },
    {
      "x": -15,
      "y": 2,
      "z": 3,
      "name": "Rock_Stone"
    },
    {
      "x": -15,
      "y": 3,
      "z": 3,
      "name": "Soil_Dirt"
    },
    {
      "x": -15,
      "y": 4,
      "z": 3,
      "name": "Rock_Stone"
    },
    {
      "x": -15,
      "y": 5,
      "z": 3,
      "name": "Rock_Stone_Cobble"
    },
    {
      "x": -15,
      "y": 6,
      "z": 3,
      "name": "Rock_Stone"
    },
    {
      "x": -15,
      "y": 7,
      "z": 3,
      "name": "Rock_Stone_Cobble"
    },
    {
      "x": -15,
      "y": 8,
      "z": 3,
      "name": "Rock_Stone"
    },
    {
      "x": -15,
      "y": 9,
      "z": 3,
      "name": "Rock_Stone"
    },
    {
      "x": -15,
      "y": 10,
      "z": 3,
      "name": "Rock_Stone_Cobble_Mossy"
    },
    {
      "x": -15,
      "y": 11,
      "z": 3,
      "name": "Rock_Stone_Cobble"
    },
    {
      "x": -15,
      "y": 12,
      "z": 3,
      "name": "Rock_Stone"
    },
    {
      "x": -15,
      "y": 13,
      "z": 3,
      "name": "Wood_Aspen_Trunk",
      "support": 15,
      "rotation": 5
    },
    {
      "x": -15,
      "y": 0,
      "z": 4,
      "name": "Rock_Stone"
    },
    {
      "x": -15,
      "y": 1,
      "z": 4,
      "name": "Rock_Stone"
    },
    {
      "x": -15,
      "y": 2,
      "z": 4,
      "name": "Rock_Stone"
    },
    {
      "x": -15,
      "y": 3,
      "z": 4,
      "name": "Soil_Dirt"
    },
    {
      "x": -15,
      "y": 4,
      "z": 4,
      "name": "Rock_Stone"
    },
    {
      "x": -15,
      "y": 5,
      "z": 4,
      "name": "Rock_Stone_Cobble_Mossy"
    },
    {
      "x": -15,
      "y": 6,
      "z": 4,
      "name": "Rock_Stone"
    },
    {
      "x": -15,
      "y": 7,
      "z": 4,
      "name": "Rock_Stone"
    },
    {
      "x": -15,
      "y": 8,
      "z": 4,
      "name": "Rock_Stone"
    },
    {
      "x": -15,
      "y": 9,
      "z": 4,
      "name": "Rock_Stone"
    },
    {
      "x": -15,
      "y": 10,
      "z": 4,
      "name": "Rock_Stone"
    },
    {
      "x": -15,
      "y": 11,
      "z": 4,
      "name": "Rock_Stone_Cobble_Mossy"
    },
    {
      "x": -15,
      "y": 12,
      "z": 4,
      "name": "Rock_Stone"
    },
    {
      "x": -15,
      "y": 13,
      "z": 4,
      "name": "Wood_Aspen_Trunk",
      "support": 15,
      "rotation": 5
    },
    {
      "x": -15,
      "y": 0,
      "z": 5,
      "name": "Rock_Stone"
    },
    {
      "x": -15,
      "y": 1,
      "z": 5,
      "name": "Rock_Stone"
    },
    {
      "x": -15,
      "y": 2,
      "z": 5,
      "name": "Soil_Dirt"
    },
    {
      "x": -15,
      "y": 3,
      "z": 5,
      "name": "Soil_Dirt"
    },
    {
      "x": -15,
      "y": 4,
      "z": 5,
      "name": "Rock_Stone"
    },
    {
      "x": -15,
      "y": 5,
      "z": 5,
      "name": "Rock_Stone_Cobble_Mossy"
    },
    {
      "x": -15,
      "y": 6,
      "z": 5,
      "name": "Rock_Stone"
    },
    {
      "x": -15,
      "y": 7,
      "z": 5,
      "name": "Rock_Stone_Cobble_Mossy"
    },
    {
      "x": -15,
      "y": 8,
      "z": 5,
      "name": "Rock_Stone_Cobble_Mossy"
    },
    {
      "x": -15,
      "y": 9,
      "z": 5,
      "name": "Rock_Stone_Cobble_Mossy"
    },
    {
      "x": -15,
      "y": 10,
      "z": 5,
      "name": "Rock_Stone_Cobble"
    },
    {
      "x": -15,
      "y": 11,
      "z": 5,
      "name": "Rock_Stone_Cobble_Mossy"
    },
    {
      "x": -15,
      "y": 12,
      "z": 5,
      "name": "Rock_Stone_Cobble_Mossy"
    },
    {
      "x": -15,
      "y": 13,
      "z": 5,
      "name": "Wood_Aspen_Trunk",
      "support": 15,
      "rotation": 5
    },
    {
      "x": -15,
      "y": 0,
      "z": 6,
      "name": "Rock_Stone"
    },
    {
      "x": -15,
      "y": 1,
      "z": 6,
      "name": "Rock_Stone"
    },
    {
      "x": -15,
      "y": 2,
      "z": 6,
      "name": "Soil_Dirt"
    },
    {
      "x": -15,
      "y": 3,
      "z": 6,
      "name": "Soil_Dirt"
    },
    {
      "x": -15,
      "y": 4,
      "z": 6,
      "name": "Rock_Stone"
    },
    {
      "x": -15,
      "y": 5,
      "z": 6,
      "name": "Rock_Stone_Cobble_Mossy"
    },
    {
      "x": -15,
      "y": 6,
      "z": 6,
      "name": "Rock_Stone_Cobble_Mossy"
    },
    {
      "x": -15,
      "y": 7,
      "z": 6,
      "name": "Rock_Stone"
    },
    {
      "x": -15,
      "y": 8,
      "z": 6,
      "name": "Rock_Stone_Cobble"
    },
    {
      "x": -15,
      "y": 9,
      "z": 6,
      "name": "Rock_Stone"
    },
    {
      "x": -15,
      "y": 10,
      "z": 6,
      "name": "Rock_Stone"
    },
    {
      "x": -15,
      "y": 11,
      "z": 6,
      "name": "Empty"
    },
    {
      "x": -15,
      "y": 0,
      "z": 7,
      "name": "Rock_Stone"
    },
    {
      "x": -15,
      "y": 1,
      "z": 7,
      "name": "Rock_Stone"
    },
    {
      "x": -15,
      "y": 2,
      "z": 7,
      "name": "Soil_Dirt"
    },
    {
      "x": -15,
      "y": 3,
      "z": 7,
      "name": "Soil_Dirt"
    },
    {
      "x": -15,
      "y": 4,
      "z": 7,
      "name": "Rock_Stone"
    },
    {
      "x": -15,
      "y": 5,
      "z": 7,
      "name": "Rock_Stone"
    },
    {
      "x": -15,
      "y": 6,
      "z": 7,
      "name": "Rock_Stone_Cobble"
    },
    {
      "x": -15,
      "y": 7,
      "z": 7,
      "name": "Rock_Stone"
    },
    {
      "x": -15,
      "y": 8,
      "z": 7,
      "name": "Empty"
    },
    {
      "x": -15,
      "y": 9,
      "z": 7,
      "name": "Empty"
    },
    {
      "x": -15,
      "y": 10,
      "z": 7,
      "name": "Empty"
    },
    {
      "x": -15,
      "y": 11,
      "z": 7,
      "name": "Empty"
    },
    {
      "x": -15,
      "y": 0,
      "z": 8,
      "name": "Rock_Stone"
    },
    {
      "x": -15,
      "y": 1,
      "z": 8,
      "name": "Rock_Stone"
    },
    {
      "x": -15,
      "y": 2,
      "z": 8,
      "name": "Soil_Dirt"
    },
    {
      "x": -15,
      "y": 3,
      "z": 8,
      "name": "Soil_Dirt"
    },
    {
      "x": -15,
      "y": 4,
      "z": 8,
      "name": "Rock_Stone_Cobble_Mossy"
    },
    {
      "x": -15,
      "y": 5,
      "z": 8,
      "name": "Rock_Stone_Cobble_Mossy"
    },
    {
      "x": -15,
      "y": 6,
      "z": 8,
      "name": "Empty"
    },
    {
      "x": -15,
      "y": 7,
      "z": 8,
      "name": "Empty"
    },
    {
      "x": -15,
      "y": 8,
      "z": 8,
      "name": "Empty"
    },
    {
      "x": -15,
      "y": 9,
      "z": 8,
      "name": "Empty"
    },
    {
      "x": -15,
      "y": 10,
      "z": 8,
      "name": "Empty"
    },
    {
      "x": -15,
      "y": 11,
      "z": 8,
      "name": "Empty"
    },
    {
      "x": -15,
      "y": 0,
      "z": 9,
      "name": "Rock_Stone"
    },
    {
      "x": -15,
      "y": 1,
      "z": 9,
      "name": "Rock_Stone"
    },
    {
      "x": -15,
      "y": 2,
      "z": 9,
      "name": "Soil_Dirt"
    },
    {
      "x": -15,
      "y": 3,
      "z": 9,
      "name": "Soil_Dirt"
    },
    {
      "x": -15,
      "y": 4,
      "z": 9,
      "name": "Soil_Dirt"
    },
    {
      "x": -15,
      "y": 1,
      "z": 10,
      "name": "Rock_Stone"
    },
    {
      "x": -15,
      "y": 2,
      "z": 10,
      "name": "Soil_Dirt"
    },
    {
      "x": -15,
      "y": 3,
      "z": 10,
      "name": "Soil_Dirt"
    },
    {
      "x": -15,
      "y": 4,
      "z": 10,
      "name": "Soil_Dirt"
    },
    {
      "x": -15,
      "y": 2,
      "z": 11,
      "name": "Soil_Dirt"
    },
    {
      "x": -15,
      "y": 3,
      "z": 11,
      "name": "Soil_Dirt"
    },
    {
      "x": -15,
      "y": 2,
      "z": 12,
      "name": "Soil_Dirt"
    },
    {
      "x": -15,
      "y": 3,
      "z": 12,
      "name": "Soil_Dirt"
    },
    {
      "x": -15,
      "y": 2,
      "z": 13,
      "name": "Soil_Dirt"
    },
    {
      "x": -15,
      "y": 3,
      "z": 13,
      "name": "Soil_Dirt"
    },
    {
      "x": -15,
      "y": 2,
      "z": 14,
      "name": "Soil_Dirt"
    },
    {
      "x": -15,
      "y": 3,
      "z": 14,
      "name": "Soil_Dirt"
    },
    {
      "x": -14,
      "y": 2,
      "z": -15,
      "name": "Soil_Dirt"
    },
    {
      "x": -14,
      "y": 2,
      "z": -14,
      "name": "Soil_Dirt"
    },
    {
      "x": -14,
      "y": 2,
      "z": -13,
      "name": "Soil_Dirt"
    },
    {
      "x": -14,
      "y": 2,
      "z": -12,
      "name": "Soil_Dirt"
    },
    {
      "x": -14,
      "y": 1,
      "z": -11,
      "name": "Rock_Stone"
    },
    {
      "x": -14,
      "y": 2,
      "z": -11,
      "name": "Soil_Dirt"
    },
    {
      "x": -14,
      "y": 3,
      "z": -11,
      "name": "Soil_Dirt"
    },
    {
      "x": -14,
      "y": 0,
      "z": -10,
      "name": "Rock_Stone"
    },
    {
      "x": -14,
      "y": 1,
      "z": -10,
      "name": "Rock_Stone"
    },
    {
      "x": -14,
      "y": 2,
      "z": -10,
      "name": "Soil_Dirt"
    },
    {
      "x": -14,
      "y": 3,
      "z": -10,
      "name": "Soil_Dirt"
    },
    {
      "x": -14,
      "y": 0,
      "z": -9,
      "name": "Rock_Stone"
    },
    {
      "x": -14,
      "y": 1,
      "z": -9,
      "name": "Rock_Stone"
    },
    {
      "x": -14,
      "y": 2,
      "z": -9,
      "name": "Soil_Dirt"
    },
    {
      "x": -14,
      "y": 3,
      "z": -9,
      "name": "Soil_Dirt"
    },
    {
      "x": -14,
      "y": 4,
      "z": -9,
      "name": "Soil_Dirt"
    },
    {
      "x": -14,
      "y": 0,
      "z": -8,
      "name": "Rock_Stone"
    },
    {
      "x": -14,
      "y": 1,
      "z": -8,
      "name": "Rock_Stone"
    },
    {
      "x": -14,
      "y": 2,
      "z": -8,
      "name": "Soil_Dirt"
    },
    {
      "x": -14,
      "y": 3,
      "z": -8,
      "name": "Soil_Dirt"
    },
    {
      "x": -14,
      "y": 4,
      "z": -8,
      "name": "Soil_Dirt"
    },
    {
      "x": -14,
      "y": 0,
      "z": -7,
      "name": "Rock_Stone"
    },
    {
      "x": -14,
      "y": 1,
      "z": -7,
      "name": "Rock_Stone"
    },
    {
      "x": -14,
      "y": 2,
      "z": -7,
      "name": "Soil_Dirt"
    },
    {
      "x": -14,
      "y": 3,
      "z": -7,
      "name": "Soil_Dirt"
    },
    {
      "x": -14,
      "y": 4,
      "z": -7,
      "name": "Deco_Bone_Full"
    },
    {
      "x": -14,
      "y": 5,
      "z": -7,
      "name": "Deco_Bone_Full"
    },
    {
      "x": -14,
      "y": 6,
      "z": -7,
      "name": "Deco_Bone_Full"
    },
    {
      "x": -14,
      "y": 7,
      "z": -7,
      "name": "Deco_Bone_Spike_Large"
    },
    {
      "x": -14,
      "y": 8,
      "z": -7,
      "name": "Empty"
    },
    {
      "x": -14,
      "y": 9,
      "z": -7,
      "name": "Empty"
    },
    {
      "x": -14,
      "y": 10,
      "z": -7,
      "name": "Empty"
    },
    {
      "x": -14,
      "y": 11,
      "z": -7,
      "name": "Empty"
    },
    {
      "x": -14,
      "y": 0,
      "z": -6,
      "name": "Rock_Stone"
    },
    {
      "x": -14,
      "y": 1,
      "z": -6,
      "name": "Rock_Stone"
    },
    {
      "x": -14,
      "y": 2,
      "z": -6,
      "name": "Rock_Stone"
    },
    {
      "x": -14,
      "y": 3,
      "z": -6,
      "name": "Soil_Dirt"
    },
    {
      "x": -14,
      "y": 4,
      "z": -6,
      "name": "Deco_Bone_Full"
    },
    {
      "x": -14,
      "y": 5,
      "z": -6,
      "name": "Deco_Bone_Full"
    },
    {
      "x": -14,
      "y": 6,
      "z": -6,
      "name": "Deco_Bone_Full"
    },
    {
      "x": -14,
      "y": 7,
      "z": -6,
      "name": "Deco_Bone_Full"
    },
    {
      "x": -14,
      "y": 8,
      "z": -6,
      "name": "Deco_Bone_Ribs_Long"
    },
    {
      "x": -14,
      "y": 9,
      "z": -6,
      "name": "Empty"
    },
    {
      "x": -14,
      "y": 10,
      "z": -6,
      "name": "Empty"
    },
    {
      "x": -14,
      "y": 11,
      "z": -6,
      "name": "Empty"
    },
    {
      "x": -14,
      "y": 0,
      "z": -5,
      "name": "Rock_Stone"
    },
    {
      "x": -14,
      "y": 1,
      "z": -5,
      "name": "Rock_Stone"
    },
    {
      "x": -14,
      "y": 2,
      "z": -5,
      "name": "Rock_Stone"
    },
    {
      "x": -14,
      "y": 3,
      "z": -5,
      "name": "Soil_Dirt"
    },
    {
      "x": -14,
      "y": 4,
      "z": -5,
      "name": "Soil_Dirt"
    },
    {
      "x": -14,
      "y": 6,
      "z": -5,
      "name": "Empty"
    },
    {
      "x": -14,
      "y": 7,
      "z": -5,
      "name": "Empty"
    },
    {
      "x": -14,
      "y": 8,
      "z": -5,
      "name": "Empty"
    },
    {
      "x": -14,
      "y": 9,
      "z": -5,
      "name": "Empty"
    },
    {
      "x": -14,
      "y": 10,
      "z": -5,
      "name": "Empty"
    },
    {
      "x": -14,
      "y": 11,
      "z": -5,
      "name": "Empty"
    },
    {
      "x": -14,
      "y": 0,
      "z": -4,
      "name": "Rock_Stone"
    },
    {
      "x": -14,
      "y": 1,
      "z": -4,
      "name": "Rock_Stone"
    },
    {
      "x": -14,
      "y": 2,
      "z": -4,
      "name": "Rock_Stone"
    },
    {
      "x": -14,
      "y": 3,
      "z": -4,
      "name": "Soil_Dirt"
    },
    {
      "x": -14,
      "y": 4,
      "z": -4,
      "name": "Soil_Pathway"
    },
    {
      "x": -14,
      "y": 6,
      "z": -4,
      "name": "Empty"
    },
    {
      "x": -14,
      "y": 7,
      "z": -4,
      "name": "Empty"
    },
    {
      "x": -14,
      "y": 8,
      "z": -4,
      "name": "Empty"
    },
    {
      "x": -14,
      "y": 9,
      "z": -4,
      "name": "Empty"
    },
    {
      "x": -14,
      "y": 10,
      "z": -4,
      "name": "Empty"
    },
    {
      "x": -14,
      "y": 11,
      "z": -4,
      "name": "Empty"
    },
    {
      "x": -14,
      "y": 0,
      "z": -3,
      "name": "Rock_Stone"
    },
    {
      "x": -14,
      "y": 1,
      "z": -3,
      "name": "Rock_Stone"
    },
    {
      "x": -14,
      "y": 2,
      "z": -3,
      "name": "Rock_Stone"
    },
    {
      "x": -14,
      "y": 3,
      "z": -3,
      "name": "Soil_Dirt"
    },
    {
      "x": -14,
      "y": 4,
      "z": -3,
      "name": "Soil_Pathway"
    },
    {
      "x": -14,
      "y": 5,
      "z": -3,
      "name": "Soil_Pathway"
    },
    {
      "x": -14,
      "y": 6,
      "z": -3,
      "name": "Plant_Crop_Mushroom_Glowing_Orange"
    },
    {
      "x": -14,
      "y": 7,
      "z": -3,
      "name": "Empty"
    },
    {
      "x": -14,
      "y": 8,
      "z": -3,
      "name": "Empty"
    },
    {
      "x": -14,
      "y": 9,
      "z": -3,
      "name": "Empty"
    },
    {
      "x": -14,
      "y": 10,
      "z": -3,
      "name": "Empty"
    },
    {
      "x": -14,
      "y": 11,
      "z": -3,
      "name": "Empty"
    },
    {
      "x": -14,
      "y": 0,
      "z": -2,
      "name": "Rock_Stone"
    },
    {
      "x": -14,
      "y": 1,
      "z": -2,
      "name": "Rock_Stone"
    },
    {
      "x": -14,
      "y": 2,
      "z": -2,
      "name": "Rock_Stone"
    },
    {
      "x": -14,
      "y": 3,
      "z": -2,
      "name": "Soil_Dirt"
    },
    {
      "x": -14,
      "y": 4,
      "z": -2,
      "name": "Soil_Pathway"
    },
    {
      "x": -14,
      "y": 5,
      "z": -2,
      "name": "Soil_Pathway"
    },
    {
      "x": -14,
      "y": 6,
      "z": -2,
      "name": "Empty"
    },
    {
      "x": -14,
      "y": 7,
      "z": -2,
      "name": "Empty"
    },
    {
      "x": -14,
      "y": 8,
      "z": -2,
      "name": "Empty"
    },
    {
      "x": -14,
      "y": 9,
      "z": -2,
      "name": "Empty"
    },
    {
      "x": -14,
      "y": 10,
      "z": -2,
      "name": "Empty"
    },
    {
      "x": -14,
      "y": 11,
      "z": -2,
      "name": "Empty"
    },
    {
      "x": -14,
      "y": 0,
      "z": -1,
      "name": "Rock_Stone"
    },
    {
      "x": -14,
      "y": 1,
      "z": -1,
      "name": "Rock_Stone"
    },
    {
      "x": -14,
      "y": 2,
      "z": -1,
      "name": "Rock_Stone"
    },
    {
      "x": -14,
      "y": 3,
      "z": -1,
      "name": "Soil_Dirt"
    },
    {
      "x": -14,
      "y": 4,
      "z": -1,
      "name": "Rock_Stone"
    },
    {
      "x": -14,
      "y": 5,
      "z": -1,
      "name": "Rock_Stone_Cobble"
    },
    {
      "x": -14,
      "y": 6,
      "z": -1,
      "name": "Empty"
    },
    {
      "x": -14,
      "y": 7,
      "z": -1,
      "name": "Empty"
    },
    {
      "x": -14,
      "y": 8,
      "z": -1,
      "name": "Empty"
    },
    {
      "x": -14,
      "y": 9,
      "z": -1,
      "name": "Empty"
    },
    {
      "x": -14,
      "y": 10,
      "z": -1,
      "name": "Empty"
    },
    {
      "x": -14,
      "y": 11,
      "z": -1,
      "name": "Empty"
    },
    {
      "x": -14,
      "y": 0,
      "z": 0,
      "name": "Rock_Stone"
    },
    {
      "x": -14,
      "y": 1,
      "z": 0,
      "name": "Rock_Stone"
    },
    {
      "x": -14,
      "y": 2,
      "z": 0,
      "name": "Rock_Stone"
    },
    {
      "x": -14,
      "y": 3,
      "z": 0,
      "name": "Soil_Dirt"
    },
    {
      "x": -14,
      "y": 4,
      "z": 0,
      "name": "Rock_Stone_Cobble"
    },
    {
      "x": -14,
      "y": 5,
      "z": 0,
      "name": "Rock_Stone"
    },
    {
      "x": -14,
      "y": 6,
      "z": 0,
      "name": "Rock_Stone"
    },
    {
      "x": -14,
      "y": 7,
      "z": 0,
      "name": "Rock_Stone"
    },
    {
      "x": -14,
      "y": 8,
      "z": 0,
      "name": "Empty"
    },
    {
      "x": -14,
      "y": 9,
      "z": 0,
      "name": "Empty"
    },
    {
      "x": -14,
      "y": 10,
      "z": 0,
      "name": "Empty"
    },
    {
      "x": -14,
      "y": 11,
      "z": 0,
      "name": "Empty"
    },
    {
      "x": -14,
      "y": 0,
      "z": 1,
      "name": "Rock_Stone"
    },
    {
      "x": -14,
      "y": 1,
      "z": 1,
      "name": "Rock_Stone"
    },
    {
      "x": -14,
      "y": 2,
      "z": 1,
      "name": "Rock_Stone"
    },
    {
      "x": -14,
      "y": 3,
      "z": 1,
      "name": "Soil_Dirt"
    },
    {
      "x": -14,
      "y": 4,
      "z": 1,
      "name": "Rock_Stone"
    },
    {
      "x": -14,
      "y": 5,
      "z": 1,
      "name": "Rock_Stone_Cobble"
    },
    {
      "x": -14,
      "y": 6,
      "z": 1,
      "name": "Rock_Stone"
    },
    {
      "x": -14,
      "y": 7,
      "z": 1,
      "name": "Rock_Stone"
    },
    {
      "x": -14,
      "y": 8,
      "z": 1,
      "name": "Rock_Stone"
    },
    {
      "x": -14,
      "y": 9,
      "z": 1,
      "name": "Rock_Stone_Cobble"
    },
    {
      "x": -14,
      "y": 10,
      "z": 1,
      "name": "Empty"
    },
    {
      "x": -14,
      "y": 11,
      "z": 1,
      "name": "Empty"
    },
    {
      "x": -14,
      "y": 0,
      "z": 2,
      "name": "Rock_Stone"
    },
    {
      "x": -14,
      "y": 1,
      "z": 2,
      "name": "Rock_Stone"
    },
    {
      "x": -14,
      "y": 2,
      "z": 2,
      "name": "Rock_Stone"
    },
    {
      "x": -14,
      "y": 3,
      "z": 2,
      "name": "Soil_Dirt"
    },
    {
      "x": -14,
      "y": 4,
      "z": 2,
      "name": "Rock_Stone"
    },
    {
      "x": -14,
      "y": 5,
      "z": 2,
      "name": "Rock_Stone_Cobble"
    },
    {
      "x": -14,
      "y": 6,
      "z": 2,
      "name": "Rock_Stone"
    },
    {
      "x": -14,
      "y": 7,
      "z": 2,
      "name": "Deco_Bone_Skulls_Wall",
      "rotation": 1
    },
    {
      "x": -14,
      "y": 8,
      "z": 2,
      "name": "Deco_Bone_Skulls_Wall",
      "rotation": 1
    },
    {
      "x": -14,
      "y": 9,
      "z": 2,
      "name": "Rock_Stone"
    },
    {
      "x": -14,
      "y": 10,
      "z": 2,
      "name": "Rock_Stone"
    },
    {
      "x": -14,
      "y": 11,
      "z": 2,
      "name": "Rock_Stone_Cobble"
    },
    {
      "x": -14,
      "y": 0,
      "z": 3,
      "name": "Rock_Stone"
    },
    {
      "x": -14,
      "y": 1,
      "z": 3,
      "name": "Rock_Stone"
    },
    {
      "x": -14,
      "y": 2,
      "z": 3,
      "name": "Rock_Stone"
    },
    {
      "x": -14,
      "y": 3,
      "z": 3,
      "name": "Soil_Dirt"
    },
    {
      "x": -14,
      "y": 4,
      "z": 3,
      "name": "Rock_Stone"
    },
    {
      "x": -14,
      "y": 5,
      "z": 3,
      "name": "Rock_Stone_Cobble"
    },
    {
      "x": -14,
      "y": 6,
      "z": 3,
      "name": "Rock_Stone"
    },
    {
      "x": -14,
      "y": 7,
      "z": 3,
      "name": "Rock_Stone"
    },
    {
      "x": -14,
      "y": 8,
      "z": 3,
      "name": "Rock_Stone"
    },
    {
      "x": -14,
      "y": 9,
      "z": 3,
      "name": "Rock_Stone"
    },
    {
      "x": -14,
      "y": 10,
      "z": 3,
      "name": "Rock_Stone"
    },
    {
      "x": -14,
      "y": 11,
      "z": 3,
      "name": "Rock_Stone_Cobble"
    },
    {
      "x": -14,
      "y": 12,
      "z": 3,
      "name": "Rock_Stone"
    },
    {
      "x": -14,
      "y": 13,
      "z": 3,
      "name": "Wood_Aspen_Trunk",
      "support": 15,
      "rotation": 5
    },
    {
      "x": -14,
      "y": 14,
      "z": 3,
      "name": "Wood_Aspen_Trunk",
      "support": 15,
      "rotation": 5
    },
    {
      "x": -14,
      "y": 0,
      "z": 4,
      "name": "Rock_Stone"
    },
    {
      "x": -14,
      "y": 1,
      "z": 4,
      "name": "Rock_Stone"
    },
    {
      "x": -14,
      "y": 2,
      "z": 4,
      "name": "Rock_Stone"
    },
    {
      "x": -14,
      "y": 3,
      "z": 4,
      "name": "Soil_Dirt"
    },
    {
      "x": -14,
      "y": 4,
      "z": 4,
      "name": "Rock_Stone"
    },
    {
      "x": -14,
      "y": 5,
      "z": 4,
      "name": "Rock_Stone"
    },
    {
      "x": -14,
      "y": 6,
      "z": 4,
      "name": "Rock_Stone"
    },
    {
      "x": -14,
      "y": 7,
      "z": 4,
      "name": "Rock_Stone"
    },
    {
      "x": -14,
      "y": 8,
      "z": 4,
      "name": "Rock_Stone"
    },
    {
      "x": -14,
      "y": 9,
      "z": 4,
      "name": "Rock_Stone"
    },
    {
      "x": -14,
      "y": 10,
      "z": 4,
      "name": "Rock_Stone"
    },
    {
      "x": -14,
      "y": 11,
      "z": 4,
      "name": "Rock_Stone"
    },
    {
      "x": -14,
      "y": 12,
      "z": 4,
      "name": "Rock_Stone"
    },
    {
      "x": -14,
      "y": 13,
      "z": 4,
      "name": "Wood_Aspen_Trunk",
      "support": 15,
      "rotation": 5
    },
    {
      "x": -14,
      "y": 14,
      "z": 4,
      "name": "Wood_Aspen_Trunk",
      "support": 15,
      "rotation": 5
    },
    {
      "x": -14,
      "y": 0,
      "z": 5,
      "name": "Rock_Stone"
    },
    {
      "x": -14,
      "y": 1,
      "z": 5,
      "name": "Rock_Stone"
    },
    {
      "x": -14,
      "y": 2,
      "z": 5,
      "name": "Rock_Stone"
    },
    {
      "x": -14,
      "y": 3,
      "z": 5,
      "name": "Soil_Dirt"
    },
    {
      "x": -14,
      "y": 4,
      "z": 5,
      "name": "Rock_Stone"
    },
    {
      "x": -14,
      "y": 5,
      "z": 5,
      "name": "Rock_Stone_Cobble"
    },
    {
      "x": -14,
      "y": 6,
      "z": 5,
      "name": "Rock_Stone"
    },
    {
      "x": -14,
      "y": 7,
      "z": 5,
      "name": "Rock_Stone"
    },
    {
      "x": -14,
      "y": 8,
      "z": 5,
      "name": "Rock_Stone"
    },
    {
      "x": -14,
      "y": 9,
      "z": 5,
      "name": "Rock_Stone_Cobble_Mossy"
    },
    {
      "x": -14,
      "y": 10,
      "z": 5,
      "name": "Rock_Stone_Cobble"
    },
    {
      "x": -14,
      "y": 11,
      "z": 5,
      "name": "Rock_Stone_Cobble"
    },
    {
      "x": -14,
      "y": 12,
      "z": 5,
      "name": "Rock_Stone_Cobble"
    },
    {
      "x": -14,
      "y": 13,
      "z": 5,
      "name": "Wood_Aspen_Trunk",
      "support": 15,
      "rotation": 5
    },
    {
      "x": -14,
      "y": 14,
      "z": 5,
      "name": "Wood_Aspen_Trunk",
      "support": 15,
      "rotation": 5
    },
    {
      "x": -14,
      "y": 0,
      "z": 6,
      "name": "Rock_Stone"
    },
    {
      "x": -14,
      "y": 1,
      "z": 6,
      "name": "Rock_Stone"
    },
    {
      "x": -14,
      "y": 2,
      "z": 6,
      "name": "Soil_Dirt"
    },
    {
      "x": -14,
      "y": 3,
      "z": 6,
      "name": "Soil_Dirt"
    },
    {
      "x": -14,
      "y": 4,
      "z": 6,
      "name": "Rock_Stone"
    },
    {
      "x": -14,
      "y": 5,
      "z": 6,
      "name": "Rock_Stone"
    },
    {
      "x": -14,
      "y": 6,
      "z": 6,
      "name": "Rock_Stone"
    },
    {
      "x": -14,
      "y": 7,
      "z": 6,
      "name": "Rock_Stone"
    },
    {
      "x": -14,
      "y": 8,
      "z": 6,
      "name": "Rock_Stone"
    },
    {
      "x": -14,
      "y": 9,
      "z": 6,
      "name": "Deco_Bone_Skulls_Wall"
    },
    {
      "x": -14,
      "y": 10,
      "z": 6,
      "name": "Rock_Stone_Cobble"
    },
    {
      "x": -14,
      "y": 11,
      "z": 6,
      "name": "Rock_Stone"
    },
    {
      "x": -14,
      "y": 0,
      "z": 7,
      "name": "Rock_Stone"
    },
    {
      "x": -14,
      "y": 1,
      "z": 7,
      "name": "Rock_Stone"
    },
    {
      "x": -14,
      "y": 2,
      "z": 7,
      "name": "Soil_Dirt"
    },
    {
      "x": -14,
      "y": 3,
      "z": 7,
      "name": "Soil_Dirt"
    },
    {
      "x": -14,
      "y": 4,
      "z": 7,
      "name": "Rock_Stone"
    },
    {
      "x": -14,
      "y": 5,
      "z": 7,
      "name": "Rock_Stone"
    },
    {
      "x": -14,
      "y": 6,
      "z": 7,
      "name": "Rock_Stone"
    },
    {
      "x": -14,
      "y": 7,
      "z": 7,
      "name": "Rock_Stone_Cobble"
    },
    {
      "x": -14,
      "y": 8,
      "z": 7,
      "name": "Empty"
    },
    {
      "x": -14,
      "y": 9,
      "z": 7,
      "name": "Empty"
    },
    {
      "x": -14,
      "y": 10,
      "z": 7,
      "name": "Empty"
    },
    {
      "x": -14,
      "y": 11,
      "z": 7,
      "name": "Empty"
    },
    {
      "x": -14,
      "y": 0,
      "z": 8,
      "name": "Rock_Stone"
    },
    {
      "x": -14,
      "y": 1,
      "z": 8,
      "name": "Rock_Stone"
    },
    {
      "x": -14,
      "y": 2,
      "z": 8,
      "name": "Soil_Dirt"
    },
    {
      "x": -14,
      "y": 3,
      "z": 8,
      "name": "Soil_Dirt"
    },
    {
      "x": -14,
      "y": 4,
      "z": 8,
      "name": "Rock_Stone_Cobble"
    },
    {
      "x": -14,
      "y": 5,
      "z": 8,
      "name": "Rock_Stone"
    },
    {
      "x": -14,
      "y": 6,
      "z": 8,
      "name": "Rock_Stone"
    },
    {
      "x": -14,
      "y": 7,
      "z": 8,
      "name": "Empty"
    },
    {
      "x": -14,
      "y": 8,
      "z": 8,
      "name": "Empty"
    },
    {
      "x": -14,
      "y": 9,
      "z": 8,
      "name": "Empty"
    },
    {
      "x": -14,
      "y": 10,
      "z": 8,
      "name": "Empty"
    },
    {
      "x": -14,
      "y": 11,
      "z": 8,
      "name": "Empty"
    },
    {
      "x": -14,
      "y": 0,
      "z": 9,
      "name": "Rock_Stone"
    },
    {
      "x": -14,
      "y": 1,
      "z": 9,
      "name": "Rock_Stone"
    },
    {
      "x": -14,
      "y": 2,
      "z": 9,
      "name": "Soil_Dirt"
    },
    {
      "x": -14,
      "y": 3,
      "z": 9,
      "name": "Soil_Dirt"
    },
    {
      "x": -14,
      "y": 4,
      "z": 9,
      "name": "Soil_Dirt"
    },
    {
      "x": -14,
      "y": 6,
      "z": 9,
      "name": "Empty"
    },
    {
      "x": -14,
      "y": 7,
      "z": 9,
      "name": "Empty"
    },
    {
      "x": -14,
      "y": 8,
      "z": 9,
      "name": "Empty"
    },
    {
      "x": -14,
      "y": 9,
      "z": 9,
      "name": "Empty"
    },
    {
      "x": -14,
      "y": 10,
      "z": 9,
      "name": "Empty"
    },
    {
      "x": -14,
      "y": 11,
      "z": 9,
      "name": "Empty"
    },
    {
      "x": -14,
      "y": 0,
      "z": 10,
      "name": "Rock_Stone"
    },
    {
      "x": -14,
      "y": 1,
      "z": 10,
      "name": "Rock_Stone"
    },
    {
      "x": -14,
      "y": 2,
      "z": 10,
      "name": "Soil_Dirt"
    },
    {
      "x": -14,
      "y": 3,
      "z": 10,
      "name": "Soil_Dirt"
    },
    {
      "x": -14,
      "y": 4,
      "z": 10,
      "name": "Soil_Dirt"
    },
    {
      "x": -14,
      "y": 1,
      "z": 11,
      "name": "Rock_Stone"
    },
    {
      "x": -14,
      "y": 2,
      "z": 11,
      "name": "Soil_Dirt"
    },
    {
      "x": -14,
      "y": 3,
      "z": 11,
      "name": "Soil_Dirt"
    },
    {
      "x": -14,
      "y": 4,
      "z": 11,
      "name": "Soil_Dirt"
    },
    {
      "x": -14,
      "y": 13,
      "z": 11,
      "name": "Plant_Crop_Mushroom_Shelve_Yellow"
    },
    {
      "x": -14,
      "y": 2,
      "z": 12,
      "name": "Soil_Dirt"
    },
    {
      "x": -14,
      "y": 3,
      "z": 12,
      "name": "Soil_Dirt"
    },
    {
      "x": -14,
      "y": 2,
      "z": 13,
      "name": "Soil_Dirt"
    },
    {
      "x": -14,
      "y": 3,
      "z": 13,
      "name": "Soil_Dirt"
    },
    {
      "x": -14,
      "y": 2,
      "z": 14,
      "name": "Soil_Dirt"
    },
    {
      "x": -14,
      "y": 3,
      "z": 14,
      "name": "Soil_Dirt"
    },
    {
      "x": -14,
      "y": 2,
      "z": 15,
      "name": "Soil_Dirt"
    },
    {
      "x": -13,
      "y": 2,
      "z": -16,
      "name": "Soil_Dirt"
    },
    {
      "x": -13,
      "y": 2,
      "z": -15,
      "name": "Soil_Dirt"
    },
    {
      "x": -13,
      "y": 2,
      "z": -14,
      "name": "Soil_Dirt"
    },
    {
      "x": -13,
      "y": 2,
      "z": -13,
      "name": "Soil_Dirt"
    },
    {
      "x": -13,
      "y": 1,
      "z": -12,
      "name": "Rock_Stone"
    },
    {
      "x": -13,
      "y": 2,
      "z": -12,
      "name": "Soil_Dirt"
    },
    {
      "x": -13,
      "y": 3,
      "z": -12,
      "name": "Soil_Dirt"
    },
    {
      "x": -13,
      "y": 0,
      "z": -11,
      "name": "Rock_Stone"
    },
    {
      "x": -13,
      "y": 1,
      "z": -11,
      "name": "Rock_Stone"
    },
    {
      "x": -13,
      "y": 2,
      "z": -11,
      "name": "Soil_Dirt"
    },
    {
      "x": -13,
      "y": 3,
      "z": -11,
      "name": "Soil_Dirt"
    },
    {
      "x": -13,
      "y": 4,
      "z": -11,
      "name": "Soil_Dirt"
    },
    {
      "x": -13,
      "y": 0,
      "z": -10,
      "name": "Rock_Stone"
    },
    {
      "x": -13,
      "y": 1,
      "z": -10,
      "name": "Rock_Stone"
    },
    {
      "x": -13,
      "y": 2,
      "z": -10,
      "name": "Soil_Dirt"
    },
    {
      "x": -13,
      "y": 3,
      "z": -10,
      "name": "Soil_Dirt"
    },
    {
      "x": -13,
      "y": 4,
      "z": -10,
      "name": "Soil_Dirt"
    },
    {
      "x": -13,
      "y": 0,
      "z": -9,
      "name": "Rock_Stone"
    },
    {
      "x": -13,
      "y": 1,
      "z": -9,
      "name": "Rock_Stone"
    },
    {
      "x": -13,
      "y": 2,
      "z": -9,
      "name": "Soil_Dirt"
    },
    {
      "x": -13,
      "y": 3,
      "z": -9,
      "name": "Soil_Dirt"
    },
    {
      "x": -13,
      "y": 4,
      "z": -9,
      "name": "Soil_Dirt"
    },
    {
      "x": -13,
      "y": 0,
      "z": -8,
      "name": "Rock_Stone"
    },
    {
      "x": -13,
      "y": 1,
      "z": -8,
      "name": "Rock_Stone"
    },
    {
      "x": -13,
      "y": 2,
      "z": -8,
      "name": "Soil_Dirt"
    },
    {
      "x": -13,
      "y": 3,
      "z": -8,
      "name": "Soil_Dirt"
    },
    {
      "x": -13,
      "y": 4,
      "z": -8,
      "name": "Soil_Dirt"
    },
    {
      "x": -13,
      "y": 6,
      "z": -8,
      "name": "Empty"
    },
    {
      "x": -13,
      "y": 7,
      "z": -8,
      "name": "Empty"
    },
    {
      "x": -13,
      "y": 8,
      "z": -8,
      "name": "Empty"
    },
    {
      "x": -13,
      "y": 9,
      "z": -8,
      "name": "Empty"
    },
    {
      "x": -13,
      "y": 10,
      "z": -8,
      "name": "Empty"
    },
    {
      "x": -13,
      "y": 11,
      "z": -8,
      "name": "Empty"
    },
    {
      "x": -13,
      "y": 0,
      "z": -7,
      "name": "Rock_Stone"
    },
    {
      "x": -13,
      "y": 1,
      "z": -7,
      "name": "Rock_Stone"
    },
    {
      "x": -13,
      "y": 2,
      "z": -7,
      "name": "Rock_Stone"
    },
    {
      "x": -13,
      "y": 3,
      "z": -7,
      "name": "Soil_Dirt"
    },
    {
      "x": -13,
      "y": 4,
      "z": -7,
      "name": "Deco_Bone_Full"
    },
    {
      "x": -13,
      "y": 5,
      "z": -7,
      "name": "Deco_Bone_Full"
    },
    {
      "x": -13,
      "y": 6,
      "z": -7,
      "name": "Deco_Bone_Full"
    },
    {
      "x": -13,
      "y": 7,
      "z": -7,
      "name": "Deco_Bone_Full"
    },
    {
      "x": -13,
      "y": 8,
      "z": -7,
      "name": "Deco_Bone_Ribs_Long"
    },
    {
      "x": -13,
      "y": 9,
      "z": -7,
      "name": "Empty"
    },
    {
      "x": -13,
      "y": 10,
      "z": -7,
      "name": "Empty"
    },
    {
      "x": -13,
      "y": 11,
      "z": -7,
      "name": "Empty"
    },
    {
      "x": -13,
      "y": 0,
      "z": -6,
      "name": "Rock_Stone"
    },
    {
      "x": -13,
      "y": 1,
      "z": -6,
      "name": "Rock_Stone"
    },
    {
      "x": -13,
      "y": 2,
      "z": -6,
      "name": "Rock_Stone"
    },
    {
      "x": -13,
      "y": 3,
      "z": -6,
      "name": "Soil_Dirt"
    },
    {
      "x": -13,
      "y": 4,
      "z": -6,
      "name": "Deco_Bone_Full"
    },
    {
      "x": -13,
      "y": 5,
      "z": -6,
      "name": "Deco_Bone_Full"
    },
    {
      "x": -13,
      "y": 6,
      "z": -6,
      "name": "Deco_Bone_Full"
    },
    {
      "x": -13,
      "y": 7,
      "z": -6,
      "name": "Deco_Bone_Full"
    },
    {
      "x": -13,
      "y": 8,
      "z": -6,
      "name": "Deco_Bone_Full"
    },
    {
      "x": -13,
      "y": 9,
      "z": -6,
      "name": "Deco_Bone_Ribs_Long"
    },
    {
      "x": -13,
      "y": 10,
      "z": -6,
      "name": "Empty"
    },
    {
      "x": -13,
      "y": 11,
      "z": -6,
      "name": "Empty"
    },
    {
      "x": -13,
      "y": 0,
      "z": -5,
      "name": "Rock_Stone"
    },
    {
      "x": -13,
      "y": 1,
      "z": -5,
      "name": "Rock_Stone"
    },
    {
      "x": -13,
      "y": 2,
      "z": -5,
      "name": "Rock_Stone"
    },
    {
      "x": -13,
      "y": 3,
      "z": -5,
      "name": "Soil_Dirt"
    },
    {
      "x": -13,
      "y": 4,
      "z": -5,
      "name": "Soil_Pathway"
    },
    {
      "x": -13,
      "y": 5,
      "z": -5,
      "name": "Soil_Pathway"
    },
    {
      "x": -13,
      "y": 6,
      "z": -5,
      "name": "Empty"
    },
    {
      "x": -13,
      "y": 7,
      "z": -5,
      "name": "Empty"
    },
    {
      "x": -13,
      "y": 8,
      "z": -5,
      "name": "Empty"
    },
    {
      "x": -13,
      "y": 9,
      "z": -5,
      "name": "Empty"
    },
    {
      "x": -13,
      "y": 10,
      "z": -5,
      "name": "Empty"
    },
    {
      "x": -13,
      "y": 11,
      "z": -5,
      "name": "Empty"
    },
    {
      "x": -13,
      "y": 0,
      "z": -4,
      "name": "Rock_Stone"
    },
    {
      "x": -13,
      "y": 1,
      "z": -4,
      "name": "Rock_Stone"
    },
    {
      "x": -13,
      "y": 2,
      "z": -4,
      "name": "Rock_Stone"
    },
    {
      "x": -13,
      "y": 3,
      "z": -4,
      "name": "Soil_Dirt"
    },
    {
      "x": -13,
      "y": 4,
      "z": -4,
      "name": "Soil_Pathway"
    },
    {
      "x": -13,
      "y": 5,
      "z": -4,
      "name": "Soil_Pathway"
    },
    {
      "x": -13,
      "y": 6,
      "z": -4,
      "name": "Empty"
    },
    {
      "x": -13,
      "y": 7,
      "z": -4,
      "name": "Empty"
    },
    {
      "x": -13,
      "y": 8,
      "z": -4,
      "name": "Empty"
    },
    {
      "x": -13,
      "y": 9,
      "z": -4,
      "name": "Empty"
    },
    {
      "x": -13,
      "y": 10,
      "z": -4,
      "name": "Empty"
    },
    {
      "x": -13,
      "y": 11,
      "z": -4,
      "name": "Empty"
    },
    {
      "x": -13,
      "y": 0,
      "z": -3,
      "name": "Rock_Stone"
    },
    {
      "x": -13,
      "y": 1,
      "z": -3,
      "name": "Rock_Stone"
    },
    {
      "x": -13,
      "y": 2,
      "z": -3,
      "name": "Rock_Stone"
    },
    {
      "x": -13,
      "y": 3,
      "z": -3,
      "name": "Soil_Dirt"
    },
    {
      "x": -13,
      "y": 4,
      "z": -3,
      "name": "Soil_Pathway"
    },
    {
      "x": -13,
      "y": 5,
      "z": -3,
      "name": "Soil_Pathway"
    },
    {
      "x": -13,
      "y": 6,
      "z": -3,
      "name": "Empty"
    },
    {
      "x": -13,
      "y": 7,
      "z": -3,
      "name": "Empty"
    },
    {
      "x": -13,
      "y": 8,
      "z": -3,
      "name": "Empty"
    },
    {
      "x": -13,
      "y": 9,
      "z": -3,
      "name": "Empty"
    },
    {
      "x": -13,
      "y": 10,
      "z": -3,
      "name": "Empty"
    },
    {
      "x": -13,
      "y": 11,
      "z": -3,
      "name": "Empty"
    },
    {
      "x": -13,
      "y": 0,
      "z": -2,
      "name": "Rock_Stone"
    },
    {
      "x": -13,
      "y": 1,
      "z": -2,
      "name": "Rock_Stone"
    },
    {
      "x": -13,
      "y": 2,
      "z": -2,
      "name": "Rock_Stone"
    },
    {
      "x": -13,
      "y": 3,
      "z": -2,
      "name": "Soil_Dirt"
    },
    {
      "x": -13,
      "y": 4,
      "z": -2,
      "name": "Soil_Pathway"
    },
    {
      "x": -13,
      "y": 5,
      "z": -2,
      "name": "Soil_Pathway"
    },
    {
      "x": -13,
      "y": 6,
      "z": -2,
      "name": "Empty"
    },
    {
      "x": -13,
      "y": 7,
      "z": -2,
      "name": "Empty"
    },
    {
      "x": -13,
      "y": 8,
      "z": -2,
      "name": "Empty"
    },
    {
      "x": -13,
      "y": 9,
      "z": -2,
      "name": "Empty"
    },
    {
      "x": -13,
      "y": 10,
      "z": -2,
      "name": "Empty"
    },
    {
      "x": -13,
      "y": 11,
      "z": -2,
      "name": "Empty"
    },
    {
      "x": -13,
      "y": 0,
      "z": -1,
      "name": "Rock_Stone"
    },
    {
      "x": -13,
      "y": 1,
      "z": -1,
      "name": "Rock_Stone"
    },
    {
      "x": -13,
      "y": 2,
      "z": -1,
      "name": "Rock_Stone"
    },
    {
      "x": -13,
      "y": 3,
      "z": -1,
      "name": "Soil_Dirt"
    },
    {
      "x": -13,
      "y": 4,
      "z": -1,
      "name": "Rock_Stone"
    },
    {
      "x": -13,
      "y": 5,
      "z": -1,
      "name": "Rock_Stone"
    },
    {
      "x": -13,
      "y": 6,
      "z": -1,
      "name": "Empty"
    },
    {
      "x": -13,
      "y": 7,
      "z": -1,
      "name": "Empty"
    },
    {
      "x": -13,
      "y": 8,
      "z": -1,
      "name": "Empty"
    },
    {
      "x": -13,
      "y": 9,
      "z": -1,
      "name": "Empty"
    },
    {
      "x": -13,
      "y": 10,
      "z": -1,
      "name": "Empty"
    },
    {
      "x": -13,
      "y": 11,
      "z": -1,
      "name": "Empty"
    },
    {
      "x": -13,
      "y": 0,
      "z": 0,
      "name": "Rock_Stone"
    },
    {
      "x": -13,
      "y": 1,
      "z": 0,
      "name": "Rock_Stone"
    },
    {
      "x": -13,
      "y": 2,
      "z": 0,
      "name": "Rock_Stone"
    },
    {
      "x": -13,
      "y": 3,
      "z": 0,
      "name": "Soil_Dirt"
    },
    {
      "x": -13,
      "y": 4,
      "z": 0,
      "name": "Rock_Stone_Cobble_Mossy"
    },
    {
      "x": -13,
      "y": 5,
      "z": 0,
      "name": "Rock_Stone"
    },
    {
      "x": -13,
      "y": 6,
      "z": 0,
      "name": "Empty"
    },
    {
      "x": -13,
      "y": 7,
      "z": 0,
      "name": "Empty"
    },
    {
      "x": -13,
      "y": 8,
      "z": 0,
      "name": "Empty"
    },
    {
      "x": -13,
      "y": 9,
      "z": 0,
      "name": "Empty"
    },
    {
      "x": -13,
      "y": 10,
      "z": 0,
      "name": "Empty"
    },
    {
      "x": -13,
      "y": 11,
      "z": 0,
      "name": "Empty"
    },
    {
      "x": -13,
      "y": 0,
      "z": 1,
      "name": "Rock_Stone"
    },
    {
      "x": -13,
      "y": 1,
      "z": 1,
      "name": "Rock_Stone"
    },
    {
      "x": -13,
      "y": 2,
      "z": 1,
      "name": "Rock_Stone"
    },
    {
      "x": -13,
      "y": 3,
      "z": 1,
      "name": "Soil_Dirt"
    },
    {
      "x": -13,
      "y": 4,
      "z": 1,
      "name": "Rock_Stone_Cobble"
    },
    {
      "x": -13,
      "y": 5,
      "z": 1,
      "name": "Rock_Stone_Cobble_Mossy"
    },
    {
      "x": -13,
      "y": 6,
      "z": 1,
      "name": "Empty"
    },
    {
      "x": -13,
      "y": 7,
      "z": 1,
      "name": "Empty"
    },
    {
      "x": -13,
      "y": 8,
      "z": 1,
      "name": "Empty"
    },
    {
      "x": -13,
      "y": 9,
      "z": 1,
      "name": "Empty"
    },
    {
      "x": -13,
      "y": 10,
      "z": 1,
      "name": "Empty"
    },
    {
      "x": -13,
      "y": 11,
      "z": 1,
      "name": "Empty"
    },
    {
      "x": -13,
      "y": 0,
      "z": 2,
      "name": "Rock_Stone"
    },
    {
      "x": -13,
      "y": 1,
      "z": 2,
      "name": "Rock_Stone"
    },
    {
      "x": -13,
      "y": 2,
      "z": 2,
      "name": "Rock_Stone"
    },
    {
      "x": -13,
      "y": 3,
      "z": 2,
      "name": "Soil_Dirt"
    },
    {
      "x": -13,
      "y": 4,
      "z": 2,
      "name": "Rock_Stone"
    },
    {
      "x": -13,
      "y": 5,
      "z": 2,
      "name": "Rock_Stone_Cobble"
    },
    {
      "x": -13,
      "y": 6,
      "z": 2,
      "name": "Empty"
    },
    {
      "x": -13,
      "y": 7,
      "z": 2,
      "name": "Empty"
    },
    {
      "x": -13,
      "y": 8,
      "z": 2,
      "name": "Empty"
    },
    {
      "x": -13,
      "y": 9,
      "z": 2,
      "name": "Empty"
    },
    {
      "x": -13,
      "y": 10,
      "z": 2,
      "name": "Empty"
    },
    {
      "x": -13,
      "y": 11,
      "z": 2,
      "name": "Empty"
    },
    {
      "x": -13,
      "y": 0,
      "z": 3,
      "name": "Rock_Stone"
    },
    {
      "x": -13,
      "y": 1,
      "z": 3,
      "name": "Rock_Stone"
    },
    {
      "x": -13,
      "y": 2,
      "z": 3,
      "name": "Rock_Stone"
    },
    {
      "x": -13,
      "y": 3,
      "z": 3,
      "name": "Soil_Dirt"
    },
    {
      "x": -13,
      "y": 4,
      "z": 3,
      "name": "Rock_Stone"
    },
    {
      "x": -13,
      "y": 5,
      "z": 3,
      "name": "Rock_Stone"
    },
    {
      "x": -13,
      "y": 6,
      "z": 3,
      "name": "Rock_Stone"
    },
    {
      "x": -13,
      "y": 7,
      "z": 3,
      "name": "Rock_Stone"
    },
    {
      "x": -13,
      "y": 8,
      "z": 3,
      "name": "Rock_Stone"
    },
    {
      "x": -13,
      "y": 9,
      "z": 3,
      "name": "Rock_Stone"
    },
    {
      "x": -13,
      "y": 10,
      "z": 3,
      "name": "Rock_Stone"
    },
    {
      "x": -13,
      "y": 11,
      "z": 3,
      "name": "Rock_Stone_Cobble_Mossy"
    },
    {
      "x": -13,
      "y": 12,
      "z": 3,
      "name": "Rock_Stone"
    },
    {
      "x": -13,
      "y": 13,
      "z": 3,
      "name": "Wood_Aspen_Trunk",
      "support": 15,
      "rotation": 5
    },
    {
      "x": -13,
      "y": 14,
      "z": 3,
      "name": "Wood_Aspen_Trunk",
      "support": 15,
      "rotation": 5
    },
    {
      "x": -13,
      "y": 0,
      "z": 4,
      "name": "Rock_Stone"
    },
    {
      "x": -13,
      "y": 1,
      "z": 4,
      "name": "Rock_Stone"
    },
    {
      "x": -13,
      "y": 2,
      "z": 4,
      "name": "Rock_Stone"
    },
    {
      "x": -13,
      "y": 3,
      "z": 4,
      "name": "Soil_Dirt"
    },
    {
      "x": -13,
      "y": 4,
      "z": 4,
      "name": "Rock_Stone"
    },
    {
      "x": -13,
      "y": 5,
      "z": 4,
      "name": "Rock_Stone_Cobble_Mossy"
    },
    {
      "x": -13,
      "y": 6,
      "z": 4,
      "name": "Rock_Stone"
    },
    {
      "x": -13,
      "y": 7,
      "z": 4,
      "name": "Deco_Bone_Skulls_Wall",
      "rotation": 1
    },
    {
      "x": -13,
      "y": 8,
      "z": 4,
      "name": "Deco_Bone_Skulls_Wall",
      "rotation": 1
    },
    {
      "x": -13,
      "y": 9,
      "z": 4,
      "name": "Rock_Stone"
    },
    {
      "x": -13,
      "y": 10,
      "z": 4,
      "name": "Rock_Stone"
    },
    {
      "x": -13,
      "y": 11,
      "z": 4,
      "name": "Rock_Stone_Cobble_Mossy"
    },
    {
      "x": -13,
      "y": 12,
      "z": 4,
      "name": "Rock_Stone"
    },
    {
      "x": -13,
      "y": 13,
      "z": 4,
      "name": "Wood_Aspen_Trunk",
      "support": 15,
      "rotation": 5
    },
    {
      "x": -13,
      "y": 14,
      "z": 4,
      "name": "Wood_Aspen_Trunk",
      "support": 15,
      "rotation": 5
    },
    {
      "x": -13,
      "y": 0,
      "z": 5,
      "name": "Rock_Stone"
    },
    {
      "x": -13,
      "y": 1,
      "z": 5,
      "name": "Rock_Stone"
    },
    {
      "x": -13,
      "y": 2,
      "z": 5,
      "name": "Rock_Stone"
    },
    {
      "x": -13,
      "y": 3,
      "z": 5,
      "name": "Soil_Dirt"
    },
    {
      "x": -13,
      "y": 4,
      "z": 5,
      "name": "Rock_Stone"
    },
    {
      "x": -13,
      "y": 5,
      "z": 5,
      "name": "Rock_Stone_Cobble_Mossy"
    },
    {
      "x": -13,
      "y": 6,
      "z": 5,
      "name": "Rock_Stone"
    },
    {
      "x": -13,
      "y": 7,
      "z": 5,
      "name": "Rock_Stone_Cobble_Mossy"
    },
    {
      "x": -13,
      "y": 8,
      "z": 5,
      "name": "Rock_Stone"
    },
    {
      "x": -13,
      "y": 9,
      "z": 5,
      "name": "Rock_Stone_Cobble_Mossy"
    },
    {
      "x": -13,
      "y": 10,
      "z": 5,
      "name": "Rock_Stone"
    },
    {
      "x": -13,
      "y": 11,
      "z": 5,
      "name": "Rock_Stone_Cobble"
    },
    {
      "x": -13,
      "y": 12,
      "z": 5,
      "name": "Rock_Stone_Cobble"
    },
    {
      "x": -13,
      "y": 13,
      "z": 5,
      "name": "Wood_Aspen_Trunk",
      "support": 15,
      "rotation": 5
    },
    {
      "x": -13,
      "y": 14,
      "z": 5,
      "name": "Wood_Aspen_Trunk",
      "support": 15,
      "rotation": 5
    },
    {
      "x": -13,
      "y": 0,
      "z": 6,
      "name": "Rock_Stone"
    },
    {
      "x": -13,
      "y": 1,
      "z": 6,
      "name": "Rock_Stone"
    },
    {
      "x": -13,
      "y": 2,
      "z": 6,
      "name": "Rock_Stone"
    },
    {
      "x": -13,
      "y": 3,
      "z": 6,
      "name": "Soil_Dirt"
    },
    {
      "x": -13,
      "y": 4,
      "z": 6,
      "name": "Rock_Stone"
    },
    {
      "x": -13,
      "y": 5,
      "z": 6,
      "name": "Rock_Stone_Cobble"
    },
    {
      "x": -13,
      "y": 6,
      "z": 6,
      "name": "Rock_Stone"
    },
    {
      "x": -13,
      "y": 7,
      "z": 6,
      "name": "Rock_Stone_Cobble_Mossy"
    },
    {
      "x": -13,
      "y": 8,
      "z": 6,
      "name": "Rock_Stone_Cobble"
    },
    {
      "x": -13,
      "y": 9,
      "z": 6,
      "name": "Rock_Stone_Cobble_Mossy"
    },
    {
      "x": -13,
      "y": 10,
      "z": 6,
      "name": "Rock_Stone"
    },
    {
      "x": -13,
      "y": 11,
      "z": 6,
      "name": "Empty"
    },
    {
      "x": -13,
      "y": 13,
      "z": 6,
      "name": "Wood_Aspen_Trunk",
      "support": 15,
      "rotation": 4
    },
    {
      "x": -13,
      "y": 14,
      "z": 6,
      "name": "Wood_Aspen_Trunk",
      "support": 15,
      "rotation": 4
    },
    {
      "x": -13,
      "y": 0,
      "z": 7,
      "name": "Rock_Stone"
    },
    {
      "x": -13,
      "y": 1,
      "z": 7,
      "name": "Rock_Stone"
    },
    {
      "x": -13,
      "y": 2,
      "z": 7,
      "name": "Rock_Stone"
    },
    {
      "x": -13,
      "y": 3,
      "z": 7,
      "name": "Soil_Dirt"
    },
    {
      "x": -13,
      "y": 4,
      "z": 7,
      "name": "Rock_Stone_Cobble"
    },
    {
      "x": -13,
      "y": 5,
      "z": 7,
      "name": "Rock_Stone"
    },
    {
      "x": -13,
      "y": 6,
      "z": 7,
      "name": "Rock_Stone_Cobble"
    },
    {
      "x": -13,
      "y": 7,
      "z": 7,
      "name": "Rock_Stone_Cobble_Mossy"
    },
    {
      "x": -13,
      "y": 8,
      "z": 7,
      "name": "Empty"
    },
    {
      "x": -13,
      "y": 9,
      "z": 7,
      "name": "Empty"
    },
    {
      "x": -13,
      "y": 10,
      "z": 7,
      "name": "Empty"
    },
    {
      "x": -13,
      "y": 11,
      "z": 7,
      "name": "Empty"
    },
    {
      "x": -13,
      "y": 13,
      "z": 7,
      "name": "Wood_Aspen_Trunk",
      "support": 15,
      "rotation": 4
    },
    {
      "x": -13,
      "y": 14,
      "z": 7,
      "name": "Wood_Aspen_Trunk",
      "support": 15,
      "rotation": 4
    },
    {
      "x": -13,
      "y": 0,
      "z": 8,
      "name": "Rock_Stone"
    },
    {
      "x": -13,
      "y": 1,
      "z": 8,
      "name": "Rock_Stone"
    },
    {
      "x": -13,
      "y": 2,
      "z": 8,
      "name": "Rock_Stone"
    },
    {
      "x": -13,
      "y": 3,
      "z": 8,
      "name": "Soil_Dirt"
    },
    {
      "x": -13,
      "y": 4,
      "z": 8,
      "name": "Rock_Stone_Cobble_Mossy"
    },
    {
      "x": -13,
      "y": 5,
      "z": 8,
      "name": "Rock_Stone_Cobble_Mossy"
    },
    {
      "x": -13,
      "y": 6,
      "z": 8,
      "name": "Empty"
    },
    {
      "x": -13,
      "y": 7,
      "z": 8,
      "name": "Empty"
    },
    {
      "x": -13,
      "y": 8,
      "z": 8,
      "name": "Empty"
    },
    {
      "x": -13,
      "y": 9,
      "z": 8,
      "name": "Empty"
    },
    {
      "x": -13,
      "y": 10,
      "z": 8,
      "name": "Empty"
    },
    {
      "x": -13,
      "y": 11,
      "z": 8,
      "name": "Empty"
    },
    {
      "x": -13,
      "y": 13,
      "z": 8,
      "name": "Wood_Aspen_Trunk",
      "support": 15,
      "rotation": 4
    },
    {
      "x": -13,
      "y": 14,
      "z": 8,
      "name": "Wood_Aspen_Trunk",
      "support": 15,
      "rotation": 4
    },
    {
      "x": -13,
      "y": 0,
      "z": 9,
      "name": "Rock_Stone"
    },
    {
      "x": -13,
      "y": 1,
      "z": 9,
      "name": "Rock_Stone"
    },
    {
      "x": -13,
      "y": 2,
      "z": 9,
      "name": "Soil_Dirt"
    },
    {
      "x": -13,
      "y": 3,
      "z": 9,
      "name": "Soil_Dirt"
    },
    {
      "x": -13,
      "y": 4,
      "z": 9,
      "name": "Soil_Dirt"
    },
    {
      "x": -13,
      "y": 6,
      "z": 9,
      "name": "Empty"
    },
    {
      "x": -13,
      "y": 7,
      "z": 9,
      "name": "Empty"
    },
    {
      "x": -13,
      "y": 8,
      "z": 9,
      "name": "Empty"
    },
    {
      "x": -13,
      "y": 9,
      "z": 9,
      "name": "Empty"
    },
    {
      "x": -13,
      "y": 10,
      "z": 9,
      "name": "Empty"
    },
    {
      "x": -13,
      "y": 11,
      "z": 9,
      "name": "Empty"
    },
    {
      "x": -13,
      "y": 13,
      "z": 9,
      "name": "Wood_Aspen_Trunk",
      "support": 15,
      "rotation": 4
    },
    {
      "x": -13,
      "y": 14,
      "z": 9,
