{
  "version": 8,
  "blockIdVersion": 11,
  "anchorX": 0,
  "anchorY": 5,
  "anchorZ": 0,
  "blocks": [
    {
      "x": -13,
      "y": 3,
      "z": -6,
      "name": "Rock_Sandstone"
    },
    {
      "x": -13,
      "y": 4,
      "z": -6,
      "name": "Soil_Dirt_Dry"
    },
    {
      "x": -13,
      "y": 5,
      "z": -6,
      "name": "Soil_Dirt_Dry"
    },
    {
      "x": -13,
      "y": 9,
      "z": -6,
      "name": "*Cloth_Roof_Leather_State_Definitions_Corner_Left",
      "rotation": 2
    },
    {
      "x": -13,
      "y": 3,
      "z": -5,
      "name": "Rock_Sandstone"
    },
    {
      "x": -13,
      "y": 4,
      "z": -5,
      "name": "Soil_Dirt_Dry"
    },
    {
      "x": -13,
      "y": 5,
      "z": -5,
      "name": "Soil_Dirt_Dry"
    },
    {
      "x": -13,
      "y": 9,
      "z": -5,
      "name": "Cloth_Roof_Leather",
      "rotation": 3
    },
    {
      "x": -13,
      "y": 3,
      "z": -4,
      "name": "Rock_Sandstone"
    },
    {
      "x": -13,
      "y": 4,
      "z": -4,
      "name": "Soil_Dirt_Dry"
    },
    {
      "x": -13,
      "y": 5,
      "z": -4,
      "name": "Soil_Dirt_Dry"
    },
    {
      "x": -13,
      "y": 9,
      "z": -4,
      "name": "Cloth_Roof_Leather",
      "rotation": 3
    },
    {
      "x": -13,
      "y": 3,
      "z": -3,
      "name": "Rock_Sandstone"
    },
    {
      "x": -13,
      "y": 4,
      "z": -3,
      "name": "Soil_Dirt_Dry"
    },
    {
      "x": -13,
      "y": 5,
      "z": -3,
      "name": "Soil_Dirt_Dry"
    },
    {
      "x": -13,
      "y": 9,
      "z": -3,
      "name": "Cloth_Roof_Leather",
      "rotation": 3
    },
    {
      "x": -13,
      "y": 3,
      "z": -2,
      "name": "Rock_Sandstone"
    },
    {
      "x": -13,
      "y": 4,
      "z": -2,
      "name": "Soil_Dirt_Dry"
    },
    {
      "x": -13,
      "y": 5,
      "z": -2,
      "name": "Soil_Dirt_Dry"
    },
    {
      "x": -13,
      "y": 9,
      "z": -2,
      "name": "Cloth_Roof_Leather",
      "rotation": 3
    },
    {
      "x": -13,
      "y": 3,
      "z": -1,
      "name": "Rock_Sandstone"
    },
    {
      "x": -13,
      "y": 4,
      "z": -1,
      "name": "Soil_Dirt_Dry"
    },
    {
      "x": -13,
      "y": 5,
      "z": -1,
      "name": "Soil_Dirt_Dry"
    },
    {
      "x": -13,
      "y": 9,
      "z": -1,
      "name": "Cloth_Roof_Leather",
      "rotation": 3
    },
    {
      "x": -13,
      "y": 3,
      "z": 0,
      "name": "Rock_Sandstone"
    },
    {
      "x": -13,
      "y": 4,
      "z": 0,
      "name": "Soil_Dirt_Dry"
    },
    {
      "x": -13,
      "y": 5,
      "z": 0,
      "name": "Soil_Dirt_Dry"
    },
    {
      "x": -13,
      "y": 9,
      "z": 0,
      "name": "Cloth_Roof_Leather",
      "rotation": 3
    },
    {
      "x": -13,
      "y": 3,
      "z": 1,
      "name": "Rock_Sandstone"
    },
    {
      "x": -13,
      "y": 4,
      "z": 1,
      "name": "Soil_Dirt_Dry"
    },
    {
      "x": -13,
      "y": 5,
      "z": 1,
      "name": "Soil_Dirt_Dry"
    },
    {
      "x": -13,
      "y": 9,
      "z": 1,
      "name": "Cloth_Roof_Leather",
      "rotation": 3
    },
    {
      "x": -13,
      "y": 3,
      "z": 2,
      "name": "Rock_Sandstone"
    },
    {
      "x": -13,
      "y": 4,
      "z": 2,
      "name": "Soil_Dirt_Dry"
    },
    {
      "x": -13,
      "y": 5,
      "z": 2,
      "name": "Soil_Dirt_Dry"
    },
    {
      "x": -13,
      "y": 9,
      "z": 2,
      "name": "Cloth_Roof_Leather",
      "rotation": 3
    },
    {
      "x": -13,
      "y": 3,
      "z": 3,
      "name": "Rock_Sandstone"
    },
    {
      "x": -13,
      "y": 4,
      "z": 3,
      "name": "Soil_Dirt_Dry"
    },
    {
      "x": -13,
      "y": 5,
      "z": 3,
      "name": "Soil_Dirt_Dry"
    },
    {
      "x": -13,
      "y": 9,
      "z": 3,
      "name": "Cloth_Roof_Leather",
      "rotation": 3
    },
    {
      "x": -13,
      "y": 3,
      "z": 4,
      "name": "Rock_Sandstone"
    },
    {
      "x": -13,
      "y": 4,
      "z": 4,
      "name": "Soil_Dirt_Dry"
    },
    {
      "x": -13,
      "y": 5,
      "z": 4,
      "name": "Soil_Dirt_Dry"
    },
    {
      "x": -13,
      "y": 9,
      "z": 4,
      "name": "Cloth_Roof_Leather",
      "rotation": 3
    },
    {
      "x": -13,
      "y": 3,
      "z": 5,
      "name": "Rock_Sandstone"
    },
    {
      "x": -13,
      "y": 4,
      "z": 5,
      "name": "Soil_Dirt_Dry"
    },
    {
      "x": -13,
      "y": 5,
      "z": 5,
      "name": "Soil_Dirt_Dry"
    },
    {
      "x": -13,
      "y": 9,
      "z": 5,
      "name": "Cloth_Roof_Leather",
      "rotation": 3
    },
    {
      "x": -13,
      "y": 3,
      "z": 6,
      "name": "Rock_Sandstone"
    },
    {
      "x": -13,
      "y": 4,
      "z": 6,
      "name": "Soil_Dirt_Dry"
    },
    {
      "x": -13,
      "y": 5,
      "z": 6,
      "name": "Soil_Dirt_Dry"
    },
    {
      "x": -13,
      "y": 9,
      "z": 6,
      "name": "*Cloth_Roof_Leather_State_Definitions_Corner_Right"
    },
    {
      "x": -12,
      "y": 3,
      "z": -6,
      "name": "Rock_Sandstone"
    },
    {
      "x": -12,
      "y": 4,
      "z": -6,
      "name": "Soil_Dirt_Dry"
    },
    {
      "x": -12,
      "y": 5,
      "z": -6,
      "name": "Soil_Dirt_Dry"
    },
    {
      "x": -12,
      "y": 9,
      "z": -6,
      "name": "Cloth_Roof_Leather",
      "rotation": 2
    },
    {
      "x": -12,
      "y": 2,
      "z": -5,
      "name": "Rock_Sandstone"
    },
    {
      "x": -12,
      "y": 3,
      "z": -5,
      "name": "Rock_Sandstone"
    },
    {
      "x": -12,
      "y": 4,
      "z": -5,
      "name": "Soil_Dirt_Dry"
    },
    {
      "x": -12,
      "y": 5,
      "z": -5,
      "name": "Rock_Sandstone_Cobble"
    },
    {
      "x": -12,
      "y": 6,
      "z": -5,
      "name": "Rock_Sandstone_Cobble"
    },
    {
      "x": -12,
      "y": 7,
      "z": -5,
      "name": "Rock_Sandstone_Cobble"
    },
    {
      "x": -12,
      "y": 8,
      "z": -5,
      "name": "Rock_Sandstone_Cobble"
    },
    {
      "x": -12,
      "y": 9,
      "z": -5,
      "name": "Rock_Sandstone_Cobble"
    },
    {
      "x": -12,
      "y": 10,
      "z": -5,
      "name": "Rock_Sandstone_Cobble"
    },
    {
      "x": -12,
      "y": 11,
      "z": -5,
      "name": "Rock_Sandstone_Stalactite_Large"
    },
    {
      "x": -12,
      "y": 12,
      "z": -5,
      "name": "Rock_Sandstone_Stalactite_Large",
      "filler": 1024
    },
    {
      "x": -12,
      "y": 2,
      "z": -4,
      "name": "Rock_Sandstone"
    },
    {
      "x": -12,
      "y": 3,
      "z": -4,
      "name": "Rock_Sandstone"
    },
    {
      "x": -12,
      "y": 4,
      "z": -4,
      "name": "Soil_Dirt_Dry"
    },
    {
      "x": -12,
      "y": 5,
      "z": -4,
      "name": "Rock_Sandstone_Cobble"
    },
    {
      "x": -12,
      "y": 6,
      "z": -4,
      "name": "Rock_Sandstone_Cobble_Half",
      "rotation": 4
    },
    {
      "x": -12,
      "y": 7,
      "z": -4,
      "name": "Rock_Sandstone_Cobble_Half",
      "rotation": 4
    },
    {
      "x": -12,
      "y": 8,
      "z": -4,
      "name": "Rock_Sandstone_Cobble_Stairs",
      "rotation": 10
    },
    {
      "x": -12,
      "y": 9,
      "z": -4,
      "name": "Rock_Sandstone_Cobble"
    },
    {
      "x": -12,
      "y": 10,
      "z": -4,
      "name": "Cloth_Roof_Leather",
      "rotation": 3
    },
    {
      "x": -12,
      "y": 2,
      "z": -3,
      "name": "Rock_Sandstone"
    },
    {
      "x": -12,
      "y": 3,
      "z": -3,
      "name": "Rock_Sandstone"
    },
    {
      "x": -12,
      "y": 4,
      "z": -3,
      "name": "Soil_Dirt_Dry"
    },
    {
      "x": -12,
      "y": 5,
      "z": -3,
      "name": "Rock_Sandstone_Cobble"
    },
    {
      "x": -12,
      "y": 8,
      "z": -3,
      "name": "Rock_Sandstone_Cobble_Half",
      "rotation": 8
    },
    {
      "x": -12,
      "y": 9,
      "z": -3,
      "name": "Rock_Sandstone_Cobble"
    },
    {
      "x": -12,
      "y": 10,
      "z": -3,
      "name": "Cloth_Roof_Leather",
      "rotation": 3
    },
    {
      "x": -12,
      "y": 2,
      "z": -2,
      "name": "Rock_Sandstone"
    },
    {
      "x": -12,
      "y": 3,
      "z": -2,
      "name": "Rock_Sandstone"
    },
    {
      "x": -12,
      "y": 4,
      "z": -2,
      "name": "Soil_Dirt_Dry"
    },
    {
      "x": -12,
      "y": 5,
      "z": -2,
      "name": "Rock_Sandstone_Cobble"
    },
    {
      "x": -12,
      "y": 8,
      "z": -2,
      "name": "Rock_Sandstone_Cobble_Half",
      "rotation": 8
    },
    {
      "x": -12,
      "y": 9,
      "z": -2,
      "name": "Rock_Sandstone_Cobble"
    },
    {
      "x": -12,
      "y": 10,
      "z": -2,
      "name": "Cloth_Roof_Leather",
      "rotation": 3
    },
    {
      "x": -12,
      "y": 2,
      "z": -1,
      "name": "Rock_Sandstone"
    },
    {
      "x": -12,
      "y": 3,
      "z": -1,
      "name": "Rock_Sandstone"
    },
    {
      "x": -12,
      "y": 4,
      "z": -1,
      "name": "Soil_Dirt_Dry"
    },
    {
      "x": -12,
      "y": 5,
      "z": -1,
      "name": "Rock_Sandstone_Cobble"
    },
    {
      "x": -12,
      "y": 6,
      "z": -1,
      "name": "Rock_Sandstone_Cobble_Half",
      "rotation": 6
    },
    {
      "x": -12,
      "y": 7,
      "z": -1,
      "name": "Rock_Sandstone_Cobble_Half",
      "rotation": 6
    },
    {
      "x": -12,
      "y": 8,
      "z": -1,
      "name": "Rock_Sandstone_Cobble_Stairs",
      "rotation": 8
    },
    {
      "x": -12,
      "y": 9,
      "z": -1,
      "name": "Rock_Sandstone_Cobble"
    },
    {
      "x": -12,
      "y": 10,
      "z": -1,
      "name": "Cloth_Roof_Leather",
      "rotation": 3
    },
    {
      "x": -12,
      "y": 2,
      "z": 0,
      "name": "Rock_Sandstone"
    },
    {
      "x": -12,
      "y": 3,
      "z": 0,
      "name": "Rock_Sandstone"
    },
    {
      "x": -12,
      "y": 4,
      "z": 0,
      "name": "Soil_Dirt_Dry"
    },
    {
      "x": -12,
      "y": 5,
      "z": 0,
      "name": "Rock_Sandstone_Cobble"
    },
    {
      "x": -12,
      "y": 6,
      "z": 0,
      "name": "Rock_Sandstone_Cobble"
    },
    {
      "x": -12,
      "y": 7,
      "z": 0,
      "name": "Rock_Sandstone_Cobble"
    },
    {
      "x": -12,
      "y": 8,
      "z": 0,
      "name": "Rock_Sandstone_Cobble"
    },
    {
      "x": -12,
      "y": 9,
      "z": 0,
      "name": "Rock_Sandstone_Brick_Smooth"
    },
    {
      "x": -12,
      "y": 10,
      "z": 0,
      "name": "Cloth_Roof_Leather",
      "rotation": 3
    },
    {
      "x": -12,
      "y": 2,
      "z": 1,
      "name": "Rock_Sandstone"
    },
    {
      "x": -12,
      "y": 3,
      "z": 1,
      "name": "Rock_Sandstone"
    },
    {
      "x": -12,
      "y": 4,
      "z": 1,
      "name": "Soil_Dirt_Dry"
    },
    {
      "x": -12,
      "y": 5,
      "z": 1,
      "name": "Rock_Sandstone_Cobble"
    },
    {
      "x": -12,
      "y": 6,
      "z": 1,
      "name": "Rock_Sandstone_Cobble_Half",
      "rotation": 4
    },
    {
      "x": -12,
      "y": 7,
      "z": 1,
      "name": "Rock_Sandstone_Cobble_Half",
      "rotation": 4
    },
    {
      "x": -12,
      "y": 8,
      "z": 1,
      "name": "Rock_Sandstone_Cobble_Stairs",
      "rotation": 10
    },
    {
      "x": -12,
      "y": 9,
      "z": 1,
      "name": "Rock_Sandstone_Cobble"
    },
    {
      "x": -12,
      "y": 10,
      "z": 1,
      "name": "Cloth_Roof_Leather",
      "rotation": 3
    },
    {
      "x": -12,
      "y": 2,
      "z": 2,
      "name": "Rock_Sandstone"
    },
    {
      "x": -12,
      "y": 3,
      "z": 2,
      "name": "Rock_Sandstone"
    },
    {
      "x": -12,
      "y": 4,
      "z": 2,
      "name": "Soil_Dirt_Dry"
    },
    {
      "x": -12,
      "y": 5,
      "z": 2,
      "name": "Rock_Sandstone_Cobble"
    },
    {
      "x": -12,
      "y": 8,
      "z": 2,
      "name": "Rock_Sandstone_Cobble_Half",
      "rotation": 8
    },
    {
      "x": -12,
      "y": 9,
      "z": 2,
      "name": "Rock_Sandstone_Cobble"
    },
    {
      "x": -12,
      "y": 10,
      "z": 2,
      "name": "Cloth_Roof_Leather",
      "rotation": 3
    },
    {
      "x": -12,
      "y": 2,
      "z": 3,
      "name": "Rock_Sandstone"
    },
    {
      "x": -12,
      "y": 3,
      "z": 3,
      "name": "Rock_Sandstone"
    },
    {
      "x": -12,
      "y": 4,
      "z": 3,
      "name": "Soil_Dirt_Dry"
    },
    {
      "x": -12,
      "y": 5,
      "z": 3,
      "name": "Rock_Sandstone_Cobble"
    },
    {
      "x": -12,
      "y": 8,
      "z": 3,
      "name": "Rock_Sandstone_Cobble_Half",
      "rotation": 8
    },
    {
      "x": -12,
      "y": 9,
      "z": 3,
      "name": "Rock_Sandstone_Cobble"
    },
    {
      "x": -12,
      "y": 10,
      "z": 3,
      "name": "Cloth_Roof_Leather",
      "rotation": 3
    },
    {
      "x": -12,
      "y": 2,
      "z": 4,
      "name": "Rock_Sandstone"
    },
    {
      "x": -12,
      "y": 3,
      "z": 4,
      "name": "Rock_Sandstone"
    },
    {
      "x": -12,
      "y": 4,
      "z": 4,
      "name": "Soil_Dirt_Dry"
    },
    {
      "x": -12,
      "y": 5,
      "z": 4,
      "name": "Rock_Sandstone_Cobble"
    },
    {
      "x": -12,
      "y": 6,
      "z": 4,
      "name": "Rock_Sandstone_Cobble_Half",
      "rotation": 6
    },
    {
      "x": -12,
      "y": 7,
      "z": 4,
      "name": "Rock_Sandstone_Cobble_Half",
      "rotation": 6
    },
    {
      "x": -12,
      "y": 8,
      "z": 4,
      "name": "Rock_Sandstone_Cobble_Stairs",
      "rotation": 8
    },
    {
      "x": -12,
      "y": 9,
      "z": 4,
      "name": "Rock_Sandstone_Cobble"
    },
    {
      "x": -12,
      "y": 10,
      "z": 4,
      "name": "Cloth_Roof_Leather",
      "rotation": 3
    },
    {
      "x": -12,
      "y": 2,
      "z": 5,
      "name": "Rock_Sandstone"
    },
    {
      "x": -12,
      "y": 3,
      "z": 5,
      "name": "Rock_Sandstone"
    },
    {
      "x": -12,
      "y": 4,
      "z": 5,
      "name": "Soil_Dirt_Dry"
    },
    {
      "x": -12,
      "y": 5,
      "z": 5,
      "name": "Rock_Sandstone_Cobble"
    },
    {
      "x": -12,
      "y": 6,
      "z": 5,
      "name": "Rock_Sandstone_Cobble"
    },
    {
      "x": -12,
      "y": 7,
      "z": 5,
      "name": "Rock_Sandstone_Cobble"
    },
    {
      "x": -12,
      "y": 8,
      "z": 5,
      "name": "Rock_Sandstone_Cobble"
    },
    {
      "x": -12,
      "y": 9,
      "z": 5,
      "name": "Rock_Sandstone_Cobble"
    },
    {
      "x": -12,
      "y": 10,
      "z": 5,
      "name": "Rock_Sandstone_Cobble"
    },
    {
      "x": -12,
      "y": 11,
      "z": 5,
      "name": "Rock_Sandstone_Stalactite_Large"
    },
    {
      "x": -12,
      "y": 12,
      "z": 5,
      "name": "Rock_Sandstone_Stalactite_Large",
      "filler": 1024
    },
    {
      "x": -12,
      "y": 3,
      "z": 6,
      "name": "Rock_Sandstone"
    },
    {
      "x": -12,
      "y": 4,
      "z": 6,
      "name": "Soil_Dirt_Dry"
    },
    {
      "x": -12,
      "y": 5,
      "z": 6,
      "name": "Soil_Dirt_Dry"
    },
    {
      "x": -12,
      "y": 9,
      "z": 6,
      "name": "Cloth_Roof_Leather"
    },
    {
      "x": -11,
      "y": 3,
      "z": -6,
      "name": "Rock_Sandstone"
    },
    {
      "x": -11,
      "y": 4,
      "z": -6,
      "name": "Soil_Dirt_Dry"
    },
    {
      "x": -11,
      "y": 5,
      "z": -6,
      "name": "Soil_Dirt_Dry"
    },
    {
      "x": -11,
      "y": 9,
      "z": -6,
      "name": "Cloth_Roof_Leather",
      "rotation": 2
    },
    {
      "x": -11,
      "y": 2,
      "z": -5,
      "name": "Rock_Sandstone"
    },
    {
      "x": -11,
      "y": 3,
      "z": -5,
      "name": "Rock_Sandstone"
    },
    {
      "x": -11,
      "y": 4,
      "z": -5,
      "name": "Soil_Dirt_Dry"
    },
    {
      "x": -11,
      "y": 5,
      "z": -5,
      "name": "Rock_Sandstone_Cobble"
    },
    {
      "x": -11,
      "y": 6,
      "z": -5,
      "name": "Rock_Sandstone_Cobble"
    },
    {
      "x": -11,
      "y": 7,
      "z": -5,
      "name": "Rock_Sandstone_Cobble"
    },
    {
      "x": -11,
      "y": 8,
      "z": -5,
      "name": "Rock_Sandstone_Cobble"
    },
    {
      "x": -11,
      "y": 9,
      "z": -5,
      "name": "Rock_Sandstone_Cobble"
    },
    {
      "x": -11,
      "y": 10,
      "z": -5,
      "name": "Cloth_Roof_Leather",
      "rotation": 2
    },
    {
      "x": -11,
      "y": 1,
      "z": -4,
      "name": "Rock_Sandstone"
    },
    {
      "x": -11,
      "y": 2,
      "z": -4,
      "name": "Rock_Sandstone"
    },
    {
      "x": -11,
      "y": 3,
      "z": -4,
      "name": "Soil_Mud"
    },
    {
      "x": -11,
      "y": 4,
      "z": -4,
      "name": "Soil_Mud"
    },
    {
      "x": -11,
      "y": 11,
      "z": -4,
      "name": "Cloth_Roof_Leather_Flat"
    },
    {
      "x": -11,
      "y": 1,
      "z": -3,
      "name": "Rock_Sandstone"
    },
    {
      "x": -11,
      "y": 2,
      "z": -3,
      "name": "Rock_Sandstone"
    },
    {
      "x": -11,
      "y": 3,
      "z": -3,
      "name": "Soil_Mud"
    },
    {
      "x": -11,
      "y": 4,
      "z": -3,
      "name": "Soil_Mud"
    },
    {
      "x": -11,
      "y": 11,
      "z": -3,
      "name": "Cloth_Roof_Leather_Flat"
    },
    {
      "x": -11,
      "y": 1,
      "z": -2,
      "name": "Rock_Sandstone"
    },
    {
      "x": -11,
      "y": 2,
      "z": -2,
      "name": "Rock_Sandstone"
    },
    {
      "x": -11,
      "y": 3,
      "z": -2,
      "name": "Soil_Mud"
    },
    {
      "x": -11,
      "y": 4,
      "z": -2,
      "name": "Soil_Mud"
    },
    {
      "x": -11,
      "y": 9,
      "z": -2,
      "name": "Rock_Sandstone_Cobble"
    },
    {
      "x": -11,
      "y": 10,
      "z": -2,
      "name": "Rock_Sandstone_Brick_Smooth"
    },
    {
      "x": -11,
      "y": 11,
      "z": -2,
      "name": "Cloth_Roof_Leather_Flat"
    },
    {
      "x": -11,
      "y": 1,
      "z": -1,
      "name": "Rock_Sandstone"
    },
    {
      "x": -11,
      "y": 2,
      "z": -1,
      "name": "Rock_Sandstone"
    },
    {
      "x": -11,
      "y": 3,
      "z": -1,
      "name": "Soil_Mud"
    },
    {
      "x": -11,
      "y": 4,
      "z": -1,
      "name": "Soil_Mud"
    },
    {
      "x": -11,
      "y": 10,
      "z": -1,
      "name": "Rock_Sandstone_Brick_Smooth"
    },
    {
      "x": -11,
      "y": 11,
      "z": -1,
      "name": "Cloth_Roof_Leather_Flat"
    },
    {
      "x": -11,
      "y": 1,
      "z": 0,
      "name": "Rock_Sandstone"
    },
    {
      "x": -11,
      "y": 2,
      "z": 0,
      "name": "Rock_Sandstone"
    },
    {
      "x": -11,
      "y": 3,
      "z": 0,
      "name": "Soil_Mud"
    },
    {
      "x": -11,
      "y": 4,
      "z": 0,
      "name": "Soil_Mud"
    },
    {
      "x": -11,
      "y": 9,
      "z": 0,
      "name": "Rock_Sandstone_Brick_Smooth"
    },
    {
      "x": -11,
      "y": 10,
      "z": 0,
      "name": "Rock_Sandstone_Brick_Smooth"
    },
    {
      "x": -11,
      "y": 11,
      "z": 0,
      "name": "Cloth_Roof_Leather_Flat"
    },
    {
      "x": -11,
      "y": 1,
      "z": 1,
      "name": "Rock_Sandstone"
    },
    {
      "x": -11,
      "y": 2,
      "z": 1,
      "name": "Rock_Sandstone"
    },
    {
      "x": -11,
      "y": 3,
      "z": 1,
      "name": "Soil_Mud"
    },
    {
      "x": -11,
      "y": 4,
      "z": 1,
      "name": "Soil_Mud"
    },
    {
      "x": -11,
      "y": 10,
      "z": 1,
      "name": "Rock_Sandstone_Brick_Smooth"
    },
    {
      "x": -11,
      "y": 11,
      "z": 1,
      "name": "Cloth_Roof_Leather_Flat"
    },
    {
      "x": -11,
      "y": 1,
      "z": 2,
      "name": "Rock_Sandstone"
    },
    {
      "x": -11,
      "y": 2,
      "z": 2,
      "name": "Rock_Sandstone"
    },
    {
      "x": -11,
      "y": 3,
      "z": 2,
      "name": "Soil_Mud"
    },
    {
      "x": -11,
      "y": 4,
      "z": 2,
      "name": "Soil_Mud"
    },
    {
      "x": -11,
      "y": 9,
      "z": 2,
      "name": "Rock_Sandstone_Cobble"
    },
    {
      "x": -11,
      "y": 10,
      "z": 2,
      "name": "Rock_Sandstone_Brick_Smooth"
    },
    {
      "x": -11,
      "y": 11,
      "z": 2,
      "name": "Cloth_Roof_Leather_Flat"
    },
    {
      "x": -11,
      "y": 1,
      "z": 3,
      "name": "Rock_Sandstone"
    },
    {
      "x": -11,
      "y": 2,
      "z": 3,
      "name": "Rock_Sandstone"
    },
    {
      "x": -11,
      "y": 3,
      "z": 3,
      "name": "Soil_Mud"
    },
    {
      "x": -11,
      "y": 4,
      "z": 3,
      "name": "Soil_Mud"
    },
    {
      "x": -11,
      "y": 11,
      "z": 3,
      "name": "Cloth_Roof_Leather_Flat"
    },
    {
      "x": -11,
      "y": 1,
      "z": 4,
      "name": "Rock_Sandstone"
    },
    {
      "x": -11,
      "y": 2,
      "z": 4,
      "name": "Rock_Sandstone"
    },
    {
      "x": -11,
      "y": 3,
      "z": 4,
      "name": "Soil_Mud"
    },
    {
      "x": -11,
      "y": 4,
      "z": 4,
      "name": "Soil_Mud"
    },
    {
      "x": -11,
      "y": 11,
      "z": 4,
      "name": "Cloth_Roof_Leather_Flat"
    },
    {
      "x": -11,
      "y": 2,
      "z": 5,
      "name": "Rock_Sandstone"
    },
    {
      "x": -11,
      "y": 3,
      "z": 5,
      "name": "Rock_Sandstone"
    },
    {
      "x": -11,
      "y": 4,
      "z": 5,
      "name": "Soil_Dirt_Dry"
    },
    {
      "x": -11,
      "y": 5,
      "z": 5,
      "name": "Rock_Sandstone_Cobble"
    },
    {
      "x": -11,
      "y": 6,
      "z": 5,
      "name": "Rock_Sandstone_Cobble"
    },
    {
      "x": -11,
      "y": 7,
      "z": 5,
      "name": "Rock_Sandstone_Cobble"
    },
    {
      "x": -11,
      "y": 8,
      "z": 5,
      "name": "Rock_Sandstone_Cobble"
    },
    {
      "x": -11,
      "y": 9,
      "z": 5,
      "name": "Rock_Sandstone_Cobble"
    },
    {
      "x": -11,
      "y": 10,
      "z": 5,
      "name": "Cloth_Roof_Leather"
    },
    {
      "x": -11,
      "y": 3,
      "z": 6,
      "name": "Rock_Sandstone"
    },
    {
      "x": -11,
      "y": 4,
      "z": 6,
      "name": "Soil_Dirt_Dry"
    },
    {
      "x": -11,
      "y": 5,
      "z": 6,
      "name": "Soil_Dirt_Dry"
    },
    {
      "x": -11,
      "y": 9,
      "z": 6,
      "name": "Cloth_Roof_Leather"
    },
    {
      "x": -10,
      "y": 3,
      "z": -6,
      "name": "Rock_Sandstone"
    },
    {
      "x": -10,
      "y": 4,
      "z": -6,
      "name": "Soil_Dirt_Dry"
    },
    {
      "x": -10,
      "y": 5,
      "z": -6,
      "name": "Soil_Dirt_Dry"
    },
    {
      "x": -10,
      "y": 9,
      "z": -6,
      "name": "Cloth_Roof_Leather",
      "rotation": 2
    },
    {
      "x": -10,
      "y": 2,
      "z": -5,
      "name": "Rock_Sandstone"
    },
    {
      "x": -10,
      "y": 3,
      "z": -5,
      "name": "Rock_Sandstone"
    },
    {
      "x": -10,
      "y": 4,
      "z": -5,
      "name": "Soil_Dirt_Dry"
    },
    {
      "x": -10,
      "y": 5,
      "z": -5,
      "name": "Rock_Sandstone_Cobble"
    },
    {
      "x": -10,
      "y": 9,
      "z": -5,
      "name": "Rock_Sandstone_Cobble"
    },
    {
      "x": -10,
      "y": 10,
      "z": -5,
      "name": "Cloth_Roof_Leather",
      "rotation": 2
    },
    {
      "x": -10,
      "y": 1,
      "z": -4,
      "name": "Rock_Sandstone"
    },
    {
      "x": -10,
      "y": 2,
      "z": -4,
      "name": "Rock_Sandstone"
    },
    {
      "x": -10,
      "y": 3,
      "z": -4,
      "name": "Soil_Mud"
    },
    {
      "x": -10,
      "y": 4,
      "z": -4,
      "name": "Soil_Mud"
    },
    {
      "x": -10,
      "y": 11,
      "z": -4,
      "name": "Cloth_Roof_Leather_Flat"
    },
    {
      "x": -10,
      "y": 0,
      "z": -3,
      "name": "Rock_Sandstone"
    },
    {
      "x": -10,
      "y": 1,
      "z": -3,
      "name": "Rock_Sandstone"
    },
    {
      "x": -10,
      "y": 2,
      "z": -3,
      "name": "Rock_Sandstone"
    },
    {
      "x": -10,
      "y": 3,
      "z": -3,
      "name": "Soil_Mud"
    },
    {
      "x": -10,
      "y": 4,
      "z": -3,
      "name": "Soil_Mud"
    },
    {
      "x": -10,
      "y": 11,
      "z": -3,
      "name": "Cloth_Roof_Leather_Flat"
    },
    {
      "x": -10,
      "y": 0,
      "z": -2,
      "name": "Rock_Sandstone"
    },
    {
      "x": -10,
      "y": 1,
      "z": -2,
      "name": "Rock_Sandstone"
    },
    {
      "x": -10,
      "y": 2,
      "z": -2,
      "name": "Rock_Sandstone"
    },
    {
      "x": -10,
      "y": 3,
      "z": -2,
      "name": "Soil_Mud"
    },
    {
      "x": -10,
      "y": 4,
      "z": -2,
      "name": "Soil_Mud"
    },
    {
      "x": -10,
      "y": 11,
      "z": -2,
      "name": "Cloth_Roof_Leather_Flat"
    },
    {
      "x": -10,
      "y": 0,
      "z": -1,
      "name": "Rock_Sandstone"
    },
    {
      "x": -10,
      "y": 1,
      "z": -1,
      "name": "Rock_Sandstone"
    },
    {
      "x": -10,
      "y": 2,
      "z": -1,
      "name": "Rock_Sandstone"
    },
    {
      "x": -10,
      "y": 3,
      "z": -1,
      "name": "Soil_Mud"
    },
    {
      "x": -10,
      "y": 4,
      "z": -1,
      "name": "Soil_Mud"
    },
    {
      "x": -10,
      "y": 11,
      "z": -1,
      "name": "Cloth_Roof_Leather_Flat"
    },
    {
      "x": -10,
      "y": 0,
      "z": 0,
      "name": "Rock_Sandstone"
    },
    {
      "x": -10,
      "y": 1,
      "z": 0,
      "name": "Rock_Sandstone"
    },
    {
      "x": -10,
      "y": 2,
      "z": 0,
      "name": "Rock_Sandstone"
    },
    {
      "x": -10,
      "y": 3,
      "z": 0,
      "name": "Soil_Mud"
    },
    {
      "x": -10,
      "y": 4,
      "z": 0,
      "name": "Soil_Mud"
    },
    {
      "x": -10,
      "y": 10,
      "z": 0,
      "name": "Rock_Sandstone_Brick_Smooth"
    },
    {
      "x": -10,
      "y": 11,
      "z": 0,
      "name": "Cloth_Roof_Leather_Flat"
    },
    {
      "x": -10,
      "y": 0,
      "z": 1,
      "name": "Rock_Sandstone"
    },
    {
      "x": -10,
      "y": 1,
      "z": 1,
      "name": "Rock_Sandstone"
    },
    {
      "x": -10,
      "y": 2,
      "z": 1,
      "name": "Rock_Sandstone"
    },
    {
      "x": -10,
      "y": 3,
      "z": 1,
      "name": "Soil_Mud"
    },
    {
      "x": -10,
      "y": 4,
      "z": 1,
      "name": "Soil_Mud"
    },
    {
      "x": -10,
      "y": 11,
      "z": 1,
      "name": "Cloth_Roof_Leather_Flat"
    },
    {
      "x": -10,
      "y": 0,
      "z": 2,
      "name": "Rock_Sandstone"
    },
    {
      "x": -10,
      "y": 1,
      "z": 2,
      "name": "Rock_Sandstone"
    },
    {
      "x": -10,
      "y": 2,
      "z": 2,
      "name": "Rock_Sandstone"
    },
    {
      "x": -10,
      "y": 3,
      "z": 2,
      "name": "Soil_Mud"
    },
    {
      "x": -10,
      "y": 4,
      "z": 2,
      "name": "Soil_Mud"
    },
    {
      "x": -10,
      "y": 11,
      "z": 2,
      "name": "Cloth_Roof_Leather_Flat"
    },
    {
      "x": -10,
      "y": 0,
      "z": 3,
      "name": "Rock_Sandstone"
    },
    {
      "x": -10,
      "y": 1,
      "z": 3,
      "name": "Rock_Sandstone"
    },
    {
      "x": -10,
      "y": 2,
      "z": 3,
      "name": "Rock_Sandstone"
    },
    {
      "x": -10,
      "y": 3,
      "z": 3,
      "name": "Soil_Mud"
    },
    {
      "x": -10,
      "y": 4,
      "z": 3,
      "name": "Soil_Mud"
    },
    {
      "x": -10,
      "y": 11,
      "z": 3,
      "name": "Cloth_Roof_Leather_Flat"
    },
    {
      "x": -10,
      "y": 1,
      "z": 4,
      "name": "Rock_Sandstone"
    },
    {
      "x": -10,
      "y": 2,
      "z": 4,
      "name": "Rock_Sandstone"
    },
    {
      "x": -10,
      "y": 3,
      "z": 4,
      "name": "Soil_Mud"
    },
    {
      "x": -10,
      "y": 4,
      "z": 4,
      "name": "Soil_Mud"
    },
    {
      "x": -10,
      "y": 11,
      "z": 4,
      "name": "Cloth_Roof_Leather_Flat"
    },
    {
      "x": -10,
      "y": 2,
      "z": 5,
      "name": "Rock_Sandstone"
    },
    {
      "x": -10,
      "y": 3,
      "z": 5,
      "name": "Rock_Sandstone"
    },
    {
      "x": -10,
      "y": 4,
      "z": 5,
      "name": "Soil_Dirt_Dry"
    },
    {
      "x": -10,
      "y": 5,
      "z": 5,
      "name": "Rock_Sandstone_Cobble"
    },
    {
      "x": -10,
      "y": 9,
      "z": 5,
      "name": "Rock_Sandstone_Cobble"
    },
    {
      "x": -10,
      "y": 10,
      "z": 5,
      "name": "Cloth_Roof_Leather"
    },
    {
      "x": -10,
      "y": 3,
      "z": 6,
      "name": "Rock_Sandstone"
    },
    {
      "x": -10,
      "y": 4,
      "z": 6,
      "name": "Soil_Dirt_Dry"
    },
    {
      "x": -10,
      "y": 5,
      "z": 6,
      "name": "Soil_Dirt_Dry"
    },
    {
      "x": -10,
      "y": 9,
      "z": 6,
      "name": "Cloth_Roof_Leather"
    },
    {
      "x": -9,
      "y": 3,
      "z": -6,
      "name": "Rock_Sandstone"
    },
    {
      "x": -9,
      "y": 4,
      "z": -6,
      "name": "Soil_Dirt_Dry"
    },
    {
      "x": -9,
      "y": 5,
      "z": -6,
      "name": "Soil_Dirt_Dry"
    },
    {
      "x": -9,
      "y": 9,
      "z": -6,
      "name": "Cloth_Roof_Leather",
      "rotation": 2
    },
    {
      "x": -9,
      "y": 2,
      "z": -5,
      "name": "Rock_Sandstone"
    },
    {
      "x": -9,
      "y": 3,
      "z": -5,
      "name": "Rock_Sandstone"
    },
    {
      "x": -9,
      "y": 4,
      "z": -5,
      "name": "Soil_Dirt_Dry"
    },
    {
      "x": -9,
      "y": 5,
      "z": -5,
      "name": "Rock_Sandstone_Cobble"
    },
    {
      "x": -9,
      "y": 9,
      "z": -5,
      "name": "Rock_Sandstone_Cobble"
    },
    {
      "x": -9,
      "y": 10,
      "z": -5,
      "name": "Cloth_Roof_Leather",
      "rotation": 2
    },
    {
      "x": -9,
      "y": 1,
      "z": -4,
      "name": "Rock_Sandstone"
    },
    {
      "x": -9,
      "y": 2,
      "z": -4,
      "name": "Rock_Sandstone"
    },
    {
      "x": -9,
      "y": 3,
      "z": -4,
      "name": "Soil_Mud"
    },
    {
      "x": -9,
      "y": 4,
      "z": -4,
      "name": "Soil_Mud"
    },
    {
      "x": -9,
      "y": 11,
      "z": -4,
      "name": "Cloth_Roof_Leather_Flat"
    },
    {
      "x": -9,
      "y": 0,
      "z": -3,
      "name": "Rock_Sandstone"
    },
    {
      "x": -9,
      "y": 1,
      "z": -3,
      "name": "Rock_Sandstone"
    },
    {
      "x": -9,
      "y": 2,
      "z": -3,
      "name": "Rock_Sandstone"
    },
    {
      "x": -9,
      "y": 3,
      "z": -3,
      "name": "Soil_Mud"
    },
    {
      "x": -9,
      "y": 4,
      "z": -3,
      "name": "Soil_Mud"
    },
    {
      "x": -9,
      "y": 5,
      "z": -3,
      "name": "Plant_Crop_Mushroom_Block_Brown_Branch",
      "support": 15
    },
    {
      "x": -9,
      "y": 6,
      "z": -3,
      "name": "Plant_Crop_Mushroom_Block_Brown"
    },
    {
      "x": -9,
      "y": 11,
      "z": -3,
      "name": "Cloth_Roof_Leather_Flat"
    },
    {
      "x": -9,
      "y": 0,
      "z": -2,
      "name": "Rock_Sandstone"
    },
    {
      "x": -9,
      "y": 1,
      "z": -2,
      "name": "Rock_Sandstone"
    },
    {
      "x": -9,
      "y": 2,
      "z": -2,
      "name": "Rock_Sandstone"
    },
    {
      "x": -9,
      "y": 3,
      "z": -2,
      "name": "Soil_Mud"
    },
    {
      "x": -9,
      "y": 4,
      "z": -2,
      "name": "Soil_Mud"
    },
    {
      "x": -9,
      "y": 11,
      "z": -2,
      "name": "Cloth_Roof_Leather_Flat"
    },
    {
      "x": -9,
      "y": 0,
      "z": -1,
      "name": "Rock_Sandstone"
    },
    {
      "x": -9,
      "y": 1,
      "z": -1,
      "name": "Rock_Sandstone"
    },
    {
      "x": -9,
      "y": 2,
      "z": -1,
      "name": "Rock_Sandstone"
    },
    {
      "x": -9,
      "y": 3,
      "z": -1,
      "name": "Soil_Mud"
    },
    {
      "x": -9,
      "y": 4,
      "z": -1,
      "name": "Soil_Mud"
    },
    {
      "x": -9,
      "y": 11,
      "z": -1,
      "name": "Cloth_Roof_Leather_Flat"
    },
    {
      "x": -9,
      "y": 0,
      "z": 0,
      "name": "Rock_Sandstone"
    },
    {
      "x": -9,
      "y": 1,
      "z": 0,
      "name": "Rock_Sandstone"
    },
    {
      "x": -9,
      "y": 2,
      "z": 0,
      "name": "Rock_Sandstone"
    },
    {
      "x": -9,
      "y": 3,
      "z": 0,
      "name": "Soil_Mud"
    },
    {
      "x": -9,
      "y": 4,
      "z": 0,
      "name": "Soil_Mud"
    },
    {
      "x": -9,
      "y": 5,
      "z": 0,
      "name": "Plant_Crop_Mushroom_Cap_Brown",
      "components": {
        "Components": {
          "FarmingBlock": {
            "LastTickGameTime": "0001-01-01T12:00:00Z"
          },
          "PlacedByInteraction": {
            "WhoPlacedUuid": {
              "$binary": "jmZp6ZgrSpi8/YFXQtu79Q==",
              "$type": "04"
            }
          }
        }
      }
    },
    {
      "x": -9,
      "y": 10,
      "z": 0,
      "name": "Rock_Sandstone_Brick_Smooth"
    },
    {
      "x": -9,
      "y": 11,
      "z": 0,
      "name": "Cloth_Roof_Leather_Flat"
    },
    {
      "x": -9,
      "y": 0,
      "z": 1,
      "name": "Rock_Sandstone"
    },
    {
      "x": -9,
      "y": 1,
      "z": 1,
      "name": "Rock_Sandstone"
    },
    {
      "x": -9,
      "y": 2,
      "z": 1,
      "name": "Rock_Sandstone"
    },
    {
      "x": -9,
      "y": 3,
      "z": 1,
      "name": "Soil_Mud"
    },
    {
      "x": -9,
      "y": 4,
      "z": 1,
      "name": "Soil_Mud"
    },
    {
      "x": -9,
      "y": 5,
      "z": 1,
      "name": "Plant_Crop_Mushroom_Shelve_Brown"
    },
    {
      "x": -9,
      "y": 11,
      "z": 1,
      "name": "Cloth_Roof_Leather_Flat"
    },
    {
      "x": -9,
      "y": 0,
      "z": 2,
      "name": "Rock_Sandstone"
    },
    {
      "x": -9,
      "y": 1,
      "z": 2,
      "name": "Rock_Sandstone"
    },
    {
      "x": -9,
      "y": 2,
      "z": 2,
      "name": "Rock_Sandstone"
    },
    {
      "x": -9,
      "y": 3,
      "z": 2,
      "name": "Soil_Mud"
    },
    {
      "x": -9,
      "y": 4,
      "z": 2,
      "name": "Soil_Mud"
    },
    {
      "x": -9,
      "y": 5,
      "z": 2,
      "name": "Plant_Crop_Mushroom_Block_Brown"
    },
    {
      "x": -9,
      "y": 6,
      "z": 2,
      "name": "Plant_Crop_Mushroom_Shelve_Brown"
    },
    {
      "x": -9,
      "y": 11,
      "z": 2,
      "name": "Cloth_Roof_Leather_Flat"
    },
    {
      "x": -9,
      "y": 0,
      "z": 3,
      "name": "Rock_Sandstone"
    },
    {
      "x": -9,
      "y": 1,
      "z": 3,
      "name": "Rock_Sandstone"
    },
    {
      "x": -9,
      "y": 2,
      "z": 3,
      "name": "Rock_Sandstone"
    },
    {
      "x": -9,
      "y": 3,
      "z": 3,
      "name": "Soil_Mud"
    },
    {
      "x": -9,
      "y": 4,
      "z": 3,
      "name": "Soil_Mud"
    },
    {
      "x": -9,
      "y": 5,
      "z": 3,
      "name": "Plant_Crop_Mushroom_Block_Brown"
    },
    {
      "x": -9,
      "y": 6,
      "z": 3,
      "name": "Plant_Crop_Mushroom_Shelve_Brown"
    },
    {
      "x": -9,
      "y": 11,
      "z": 3,
      "name": "Cloth_Roof_Leather_Flat"
    },
    {
      "x": -9,
      "y": 1,
      "z": 4,
      "name": "Rock_Sandstone"
    },
    {
      "x": -9,
      "y": 2,
      "z": 4,
      "name": "Rock_Sandstone"
    },
    {
      "x": -9,
      "y": 3,
      "z": 4,
      "name": "Soil_Mud"
    },
    {
      "x": -9,
      "y": 4,
      "z": 4,
      "name": "Soil_Mud"
    },
    {
      "x": -9,
      "y": 11,
      "z": 4,
      "name": "Cloth_Roof_Leather_Flat"
    },
    {
      "x": -9,
      "y": 2,
      "z": 5,
      "name": "Rock_Sandstone"
    },
    {
      "x": -9,
      "y": 3,
      "z": 5,
      "name": "Rock_Sandstone"
    },
    {
      "x": -9,
      "y": 4,
      "z": 5,
      "name": "Soil_Dirt_Dry"
    },
    {
      "x": -9,
      "y": 5,
      "z": 5,
      "name": "Rock_Sandstone_Cobble"
    },
    {
      "x": -9,
      "y": 9,
      "z": 5,
      "name": "Rock_Sandstone_Cobble"
    },
    {
      "x": -9,
      "y": 10,
      "z": 5,
      "name": "Cloth_Roof_Leather"
    },
    {
      "x": -9,
      "y": 3,
      "z": 6,
      "name": "Rock_Sandstone"
    },
    {
      "x": -9,
      "y": 4,
      "z": 6,
      "name": "Soil_Dirt_Dry"
    },
    {
      "x": -9,
      "y": 5,
      "z": 6,
      "name": "Soil_Dirt_Dry"
    },
    {
      "x": -9,
      "y": 9,
      "z": 6,
      "name": "Cloth_Roof_Leather"
    },
    {
      "x": -8,
      "y": 3,
      "z": -6,
      "name": "Rock_Sandstone"
    },
    {
      "x": -8,
      "y": 4,
      "z": -6,
      "name": "Soil_Dirt_Dry"
    },
    {
      "x": -8,
      "y": 5,
      "z": -6,
      "name": "Soil_Dirt_Dry"
    },
    {
      "x": -8,
      "y": 9,
      "z": -6,
      "name": "Cloth_Roof_Leather",
      "rotation": 2
    },
    {
      "x": -8,
      "y": 2,
      "z": -5,
      "name": "Rock_Sandstone"
    },
    {
      "x": -8,
      "y": 3,
      "z": -5,
      "name": "Rock_Sandstone"
    },
    {
      "x": -8,
      "y": 4,
      "z": -5,
      "name": "Soil_Dirt_Dry"
    },
    {
      "x": -8,
      "y": 5,
      "z": -5,
      "name": "Rock_Sandstone_Cobble"
    },
    {
      "x": -8,
      "y": 6,
      "z": -5,
      "name": "Rock_Sandstone_Cobble"
    },
    {
      "x": -8,
      "y": 7,
      "z": -5,
      "name": "Rock_Sandstone_Cobble"
    },
    {
      "x": -8,
      "y": 8,
      "z": -5,
      "name": "Rock_Sandstone_Cobble"
    },
    {
      "x": -8,
      "y": 9,
      "z": -5,
      "name": "Rock_Sandstone_Cobble"
    },
    {
      "x": -8,
      "y": 10,
      "z": -5,
      "name": "Cloth_Roof_Leather",
      "rotation": 2
    },
    {
      "x": -8,
      "y": 1,
      "z": -4,
      "name": "Rock_Sandstone"
    },
    {
      "x": -8,
      "y": 2,
      "z": -4,
      "name": "Rock_Sandstone"
    },
    {
      "x": -8,
      "y": 3,
      "z": -4,
      "name": "Soil_Mud"
    },
    {
      "x": -8,
      "y": 4,
      "z": -4,
      "name": "Soil_Mud"
    },
    {
      "x": -8,
      "y": 10,
      "z": -4,
      "name": "Rock_Sandstone_Brick_Smooth"
    },
    {
      "x": -8,
      "y": 11,
      "z": -4,
      "name": "Cloth_Roof_Leather_Flat"
    },
    {
      "x": -8,
      "y": 0,
      "z": -3,
      "name": "Rock_Sandstone"
    },
    {
      "x": -8,
      "y": 1,
      "z": -3,
      "name": "Rock_Sandstone"
    },
    {
      "x": -8,
      "y": 2,
      "z": -3,
      "name": "Rock_Sandstone"
    },
    {
      "x": -8,
      "y": 3,
      "z": -3,
      "name": "Soil_Mud"
    },
    {
      "x": -8,
      "y": 4,
      "z": -3,
      "name": "Soil_Mud"
    },
    {
      "x": -8,
      "y": 11,
      "z": -3,
      "name": "Cloth_Roof_Leather_Flat"
    },
    {
      "x": -8,
      "y": 0,
      "z": -2,
      "name": "Rock_Sandstone"
    },
    {
      "x": -8,
      "y": 1,
      "z": -2,
      "name": "Rock_Sandstone"
    },
    {
      "x": -8,
      "y": 2,
      "z": -2,
      "name": "Rock_Sandstone"
    },
    {
      "x": -8,
      "y": 3,
      "z": -2,
      "name": "Soil_Mud"
    },
    {
      "x": -8,
      "y": 4,
      "z": -2,
      "name": "Soil_Mud"
    },
    {
      "x": -8,
      "y": 11,
      "z": -2,
      "name": "Cloth_Roof_Leather_Flat"
    },
    {
      "x": -8,
      "y": 0,
      "z": -1,
      "name": "Rock_Sandstone"
    },
    {
      "x": -8,
      "y": 1,
      "z": -1,
      "name": "Rock_Sandstone"
    },
    {
      "x": -8,
      "y": 2,
      "z": -1,
      "name": "Rock_Sandstone"
    },
    {
      "x": -8,
      "y": 3,
      "z": -1,
      "name": "Soil_Mud"
    },
    {
      "x": -8,
      "y": 4,
      "z": -1,
      "name": "Soil_Mud"
    },
    {
      "x": -8,
      "y": 5,
      "z": -1,
      "name": "Plant_Crop_Mushroom_Cap_Brown",
      "components": {
        "Components": {
          "FarmingBlock": {
            "LastTickGameTime": "0001-01-01T12:00:00Z"
          },
          "PlacedByInteraction": {
            "WhoPlacedUuid": {
              "$binary": "jmZp6ZgrSpi8/YFXQtu79Q==",
              "$type": "04"
            }
          }
        }
      }
    },
    {
      "x": -8,
      "y": 11,
      "z": -1,
      "name": "Cloth_Roof_Leather_Flat"
    },
    {
      "x": -8,
      "y": 0,
      "z": 0,
      "name": "Rock_Sandstone"
    },
    {
      "x": -8,
      "y": 1,
      "z": 0,
      "name": "Rock_Sandstone"
    },
    {
      "x": -8,
      "y": 2,
      "z": 0,
      "name": "Rock_Sandstone"
    },
    {
      "x": -8,
      "y": 3,
      "z": 0,
      "name": "Soil_Mud"
    },
    {
      "x": -8,
      "y": 4,
      "z": 0,
      "name": "Soil_Mud"
    },
    {
      "x": -8,
      "y": 8,
      "z": 0,
      "name": "Plant_Crop_Mushroom_Block_Brown"
    },
    {
      "x": -8,
      "y": 10,
      "z": 0,
      "name": "Rock_Sandstone_Brick_Smooth"
    },
    {
      "x": -8,
      "y": 11,
      "z": 0,
      "name": "Cloth_Roof_Leather_Flat"
    },
    {
      "x": -8,
      "y": 0,
      "z": 1,
      "name": "Rock_Sandstone"
    },
    {
      "x": -8,
      "y": 1,
      "z": 1,
      "name": "Rock_Sandstone"
    },
    {
      "x": -8,
      "y": 2,
      "z": 1,
      "name": "Rock_Sandstone"
    },
    {
      "x": -8,
      "y": 3,
      "z": 1,
      "name": "Soil_Mud"
    },
    {
      "x": -8,
      "y": 4,
      "z": 1,
      "name": "Soil_Mud"
    },
    {
      "x": -8,
      "y": 11,
      "z": 1,
      "name": "Cloth_Roof_Leather_Flat"
    },
    {
      "x": -8,
      "y": 0,
      "z": 2,
      "name": "Rock_Sandstone"
    },
    {
      "x": -8,
      "y": 1,
      "z": 2,
      "name": "Rock_Sandstone"
    },
    {
      "x": -8,
      "y": 2,
      "z": 2,
      "name": "Rock_Sandstone"
    },
    {
      "x": -8,
      "y": 3,
      "z": 2,
      "name": "Soil_Mud"
    },
    {
      "x": -8,
      "y": 4,
      "z": 2,
      "name": "Soil_Mud"
    },
    {
      "x": -8,
      "y": 5,
      "z": 2,
      "name": "Plant_Crop_Mushroom_Block_Brown"
    },
    {
      "x": -8,
      "y": 6,
      "z": 2,
      "name": "Plant_Crop_Mushroom_Shelve_Brown"
    },
    {
      "x": -8,
      "y": 11,
      "z": 2,
      "name": "Cloth_Roof_Leather_Flat"
    },
    {
      "x": -8,
      "y": 0,
      "z": 3,
      "name": "Rock_Sandstone"
    },
    {
      "x": -8,
      "y": 1,
      "z": 3,
      "name": "Rock_Sandstone"
    },
    {
      "x": -8,
      "y": 2,
      "z": 3,
      "name": "Rock_Sandstone"
    },
    {
      "x": -8,
      "y": 3,
      "z": 3,
      "name": "Soil_Mud"
    },
    {
      "x": -8,
      "y": 4,
      "z": 3,
      "name": "Soil_Mud"
    },
    {
      "x": -8,
      "y": 5,
      "z": 3,
      "name": "Plant_Crop_Mushroom_Block_Brown"
    },
    {
      "x": -8,
      "y": 6,
      "z": 3,
      "name": "Plant_Crop_Mushroom_Shelve_Brown"
    },
    {
      "x": -8,
      "y": 11,
      "z": 3,
      "name": "Cloth_Roof_Leather_Flat"
    },
    {
      "x": -8,
      "y": 1,
      "z": 4,
      "name": "Rock_Sandstone"
    },
    {
      "x": -8,
      "y": 2,
      "z": 4,
      "name": "Rock_Sandstone"
    },
    {
      "x": -8,
      "y": 3,
      "z": 4,
      "name": "Soil_Mud"
    },
    {
      "x": -8,
      "y": 4,
      "z": 4,
      "name": "Soil_Mud"
    },
    {
      "x": -8,
      "y": 10,
      "z": 4,
      "name": "Rock_Sandstone_Brick_Smooth"
    },
    {
      "x": -8,
      "y": 11,
      "z": 4,
      "name": "Cloth_Roof_Leather_Flat"
    },
    {
      "x": -8,
      "y": 2,
      "z": 5,
      "name": "Rock_Sandstone"
    },
    {
      "x": -8,
      "y": 3,
      "z": 5,
      "name": "Rock_Sandstone"
    },
    {
      "x": -8,
      "y": 4,
      "z": 5,
      "name": "Soil_Dirt_Dry"
    },
    {
      "x": -8,
      "y": 5,
      "z": 5,
      "name": "Rock_Sandstone_Cobble"
    },
    {
      "x": -8,
      "y": 6,
      "z": 5,
      "name": "Rock_Sandstone_Cobble"
    },
    {
      "x": -8,
      "y": 7,
      "z": 5,
      "name": "Rock_Sandstone_Cobble"
    },
    {
      "x": -8,
      "y": 8,
      "z": 5,
      "name": "Rock_Sandstone_Cobble"
    },
    {
      "x": -8,
      "y": 9,
      "z": 5,
      "name": "Rock_Sandstone_Cobble"
    },
    {
      "x": -8,
      "y": 10,
      "z": 5,
      "name": "Cloth_Roof_Leather"
    },
    {
      "x": -8,
      "y": 3,
      "z": 6,
      "name": "Rock_Sandstone"
    },
    {
      "x": -8,
      "y": 4,
      "z": 6,
      "name": "Soil_Dirt_Dry"
    },
    {
      "x": -8,
      "y": 5,
      "z": 6,
      "name": "Soil_Dirt_Dry"
    },
    {
      "x": -8,
      "y": 9,
      "z": 6,
      "name": "Cloth_Roof_Leather"
    },
    {
      "x": -7,
      "y": 3,
      "z": -6,
      "name": "Rock_Sandstone"
    },
    {
      "x": -7,
      "y": 4,
      "z": -6,
      "name": "Soil_Dirt_Dry"
    },
    {
      "x": -7,
      "y": 5,
      "z": -6,
      "name": "Soil_Dirt_Dry"
    },
    {
      "x": -7,
      "y": 9,
      "z": -6,
      "name": "Cloth_Roof_Leather",
      "rotation": 2
    },
    {
      "x": -7,
      "y": 2,
      "z": -5,
      "name": "Rock_Sandstone"
    },
    {
      "x": -7,
      "y": 3,
      "z": -5,
      "name": "Rock_Sandstone"
    },
    {
      "x": -7,
      "y": 4,
      "z": -5,
      "name": "Soil_Dirt_Dry"
    },
    {
      "x": -7,
      "y": 5,
      "z": -5,
      "name": "Rock_Sandstone_Cobble"
    },
    {
      "x": -7,
      "y": 6,
      "z": -5,
      "name": "Rock_Sandstone_Brick_Smooth"
    },
    {
      "x": -7,
      "y": 7,
      "z": -5,
      "name": "Rock_Sandstone_Brick_Smooth"
    },
    {
      "x": -7,
      "y": 8,
      "z": -5,
      "name": "Rock_Sandstone_Brick_Smooth"
    },
    {
      "x": -7,
      "y": 9,
      "z": -5,
      "name": "Rock_Sandstone_Brick_Smooth"
    },
    {
      "x": -7,
      "y": 10,
      "z": -5,
      "name": "Cloth_Roof_Leather",
      "rotation": 2
    },
    {
      "x": -7,
      "y": 1,
      "z": -4,
      "name": "Rock_Sandstone"
    },
    {
      "x": -7,
      "y": 2,
      "z": -4,
      "name": "Rock_Sandstone"
    },
    {
      "x": -7,
      "y": 3,
      "z": -4,
      "name": "Soil_Mud"
    },
    {
      "x": -7,
      "y": 4,
      "z": -4,
      "name": "Soil_Mud"
    },
    {
      "x": -7,
      "y": 9,
      "z": -4,
      "name": "Rock_Sandstone_Brick_Smooth"
    },
    {
      "x": -7,
      "y": 10,
      "z": -4,
      "name": "Rock_Sandstone_Brick_Smooth"
    },
    {
      "x": -7,
      "y": 11,
      "z": -4,
      "name": "Cloth_Roof_Leather_Flat"
    },
    {
      "x": -7,
      "y": 0,
      "z": -3,
      "name": "Rock_Sandstone"
    },
    {
      "x": -7,
      "y": 1,
      "z": -3,
      "name": "Rock_Sandstone"
    },
    {
      "x": -7,
      "y": 2,
      "z": -3,
      "name": "Rock_Sandstone"
    },
    {
      "x": -7,
      "y": 3,
      "z": -3,
      "name": "Soil_Mud"
    },
    {
      "x": -7,
      "y": 4,
      "z": -3,
      "name": "Soil_Mud"
    },
    {
      "x": -7,
      "y": 11,
      "z": -3,
      "name": "Cloth_Roof_Leather_Flat"
    },
    {
      "x": -7,
      "y": 0,
      "z": -2,
      "name": "Rock_Sandstone"
    },
    {
      "x": -7,
      "y": 1,
      "z": -2,
      "name": "Rock_Sandstone"
    },
    {
      "x": -7,
      "y": 2,
      "z": -2,
      "name": "Rock_Sandstone"
    },
    {
      "x": -7,
      "y": 3,
      "z": -2,
      "name": "Soil_Mud"
    },
    {
      "x": -7,
      "y": 4,
      "z": -2,
      "name": "Soil_Mud"
    },
    {
      "x": -7,
      "y": 11,
      "z": -2,
      "name": "Cloth_Roof_Leather_Flat"
    },
    {
      "x": -7,
      "y": 0,
      "z": -1,
      "name": "Rock_Sandstone"
    },
    {
      "x": -7,
      "y": 1,
      "z": -1,
      "name": "Rock_Sandstone"
    },
    {
      "x": -7,
      "y": 2,
      "z": -1,
      "name": "Rock_Sandstone"
    },
    {
      "x": -7,
      "y": 3,
      "z": -1,
      "name": "Soil_Mud"
    },
    {
      "x": -7,
      "y": 4,
      "z": -1,
      "name": "Soil_Mud"
    },
    {
      "x": -7,
      "y": 8,
      "z": -1,
      "name": "Plant_Crop_Mushroom_Block_Brown"
    },
    {
      "x": -7,
      "y": 9,
      "z": -1,
      "name": "Plant_Crop_Mushroom_Block_Brown"
    },
    {
      "x": -7,
      "y": 11,
      "z": -1,
      "name": "Cloth_Roof_Leather_Flat"
    },
    {
      "x": -7,
      "y": 0,
      "z": 0,
      "name": "Rock_Sandstone"
    },
    {
      "x": -7,
      "y": 1,
      "z": 0,
      "name": "Rock_Sandstone"
    },
    {
      "x": -7,
      "y": 2,
      "z": 0,
      "name": "Rock_Sandstone"
    },
    {
      "x": -7,
      "y": 3,
      "z": 0,
      "name": "Soil_Mud"
    },
    {
      "x": -7,
      "y": 4,
      "z": 0,
      "name": "Soil_Mud"
    },
    {
      "x": -7,
      "y": 8,
      "z": 0,
      "name": "Plant_Crop_Mushroom_Block_Brown"
    },
    {
      "x": -7,
      "y": 9,
      "z": 0,
      "name": "Plant_Crop_Mushroom_Block_Brown"
    },
    {
      "x": -7,
      "y": 10,
      "z": 0,
      "name": "Rock_Sandstone_Brick_Smooth"
    },
    {
      "x": -7,
      "y": 11,
      "z": 0,
      "name": "Cloth_Roof_Leather_Flat"
    },
    {
      "x": -7,
      "y": 0,
      "z": 1,
      "name": "Rock_Sandstone"
    },
    {
      "x": -7,
      "y": 1,
      "z": 1,
      "name": "Rock_Sandstone"
    },
    {
      "x": -7,
      "y": 2,
      "z": 1,
      "name": "Rock_Sandstone"
    },
    {
      "x": -7,
      "y": 3,
      "z": 1,
      "name": "Soil_Mud"
    },
    {
      "x": -7,
      "y": 4,
      "z": 1,
      "name": "Soil_Mud"
    },
    {
      "x": -7,
      "y": 8,
      "z": 1,
      "name": "Plant_Crop_Mushroom_Block_Brown"
    },
    {
      "x": -7,
      "y": 9,
      "z": 1,
      "name": "Plant_Crop_Mushroom_Block_Brown"
    },
    {
      "x": -7,
      "y": 11,
      "z": 1,
      "name": "Cloth_Roof_Leather_Flat"
    },
    {
      "x": -7,
      "y": 0,
      "z": 2,
      "name": "Rock_Sandstone"
    },
    {
      "x": -7,
      "y": 1,
      "z": 2,
      "name": "Rock_Sandstone"
    },
    {
      "x": -7,
      "y": 2,
      "z": 2,
      "name": "Rock_Sandstone"
    },
    {
      "x": -7,
      "y": 3,
      "z": 2,
      "name": "Soil_Mud"
    },
    {
      "x": -7,
      "y": 4,
      "z": 2,
      "name": "Soil_Mud"
    },
    {
      "x": -7,
      "y": 5,
      "z": 2,
      "name": "Plant_Crop_Mushroom_Shelve_Brown"
    },
    {
      "x": -7,
      "y": 11,
      "z": 2,
      "name": "Cloth_Roof_Leather_Flat"
    },
    {
      "x": -7,
      "y": 0,
      "z": 3,
      "name": "Rock_Sandstone"
    },
    {
      "x": -7,
      "y": 1,
      "z": 3,
      "name": "Rock_Sandstone"
    },
    {
      "x": -7,
      "y": 2,
      "z": 3,
      "name": "Rock_Sandstone"
    },
    {
      "x": -7,
      "y": 3,
      "z": 3,
      "name": "Soil_Mud"
    },
    {
      "x": -7,
      "y": 4,
      "z": 3,
      "name": "Soil_Mud"
    },
    {
      "x": -7,
      "y": 11,
      "z": 3,
      "name": "Cloth_Roof_Leather_Flat"
    },
    {
      "x": -7,
      "y": 1,
      "z": 4,
      "name": "Rock_Sandstone"
    },
    {
      "x": -7,
      "y": 2,
      "z": 4,
      "name": "Rock_Sandstone"
    },
    {
      "x": -7,
      "y": 3,
      "z": 4,
      "name": "Soil_Mud"
    },
    {
      "x": -7,
      "y": 4,
      "z": 4,
      "name": "Soil_Mud"
    },
    {
      "x": -7,
      "y": 9,
      "z": 4,
      "name": "Rock_Sandstone_Brick_Smooth"
    },
    {
      "x": -7,
      "y": 10,
      "z": 4,
      "name": "Rock_Sandstone_Brick_Smooth"
    },
    {
      "x": -7,
      "y": 11,
      "z": 4,
      "name": "Cloth_Roof_Leather_Flat"
    },
    {
      "x": -7,
      "y": 2,
      "z": 5,
      "name": "Rock_Sandstone"
    },
    {
      "x": -7,
      "y": 3,
      "z": 5,
      "name": "Rock_Sandstone"
    },
    {
      "x": -7,
      "y": 4,
      "z": 5,
      "name": "Soil_Dirt_Dry"
    },
    {
      "x": -7,
      "y": 5,
      "z": 5,
      "name": "Rock_Sandstone_Cobble"
    },
    {
      "x": -7,
      "y": 6,
      "z": 5,
      "name": "Rock_Sandstone_Brick_Smooth"
    },
    {
      "x": -7,
      "y": 7,
      "z": 5,
      "name": "Rock_Sandstone_Brick_Smooth"
    },
    {
      "x": -7,
      "y": 8,
      "z": 5,
      "name": "Rock_Sandstone_Brick_Smooth"
    },
    {
      "x": -7,
      "y": 9,
      "z": 5,
      "name": "Rock_Sandstone_Brick_Smooth"
    },
    {
      "x": -7,
      "y": 10,
      "z": 5,
      "name": "Cloth_Roof_Leather"
    },
    {
      "x": -7,
      "y": 3,
      "z": 6,
      "name": "Rock_Sandstone"
    },
    {
      "x": -7,
      "y": 4,
      "z": 6,
      "name": "Soil_Dirt_Dry"
    },
    {
      "x": -7,
      "y": 5,
      "z": 6,
      "name": "Soil_Dirt_Dry"
    },
    {
      "x": -7,
      "y": 9,
      "z": 6,
      "name": "Cloth_Roof_Leather"
    },
    {
      "x": -6,
      "y": 3,
      "z": -6,
      "name": "Rock_Sandstone"
    },
    {
      "x": -6,
      "y": 4,
      "z": -6,
      "name": "Soil_Dirt_Dry"
    },
    {
      "x": -6,
      "y": 5,
      "z": -6,
      "name": "Soil_Dirt_Dry"
    },
    {
      "x": -6,
      "y": 9,
      "z": -6,
      "name": "Cloth_Roof_Leather",
      "rotation": 2
    },
    {
      "x": -6,
      "y": 2,
      "z": -5,
      "name": "Rock_Sandstone"
    },
    {
      "x": -6,
      "y": 3,
      "z": -5,
      "name": "Rock_Sandstone"
    },
    {
      "x": -6,
      "y": 4,
      "z": -5,
      "name": "Soil_Dirt_Dry"
    },
    {
      "x": -6,
      "y": 5,
      "z": -5,
      "name": "Rock_Sandstone_Cobble"
    },
    {
      "x": -6,
      "y": 6,
      "z": -5,
      "name": "Rock_Sandstone_Cobble"
    },
    {
      "x": -6,
      "y": 7,
      "z": -5,
      "name": "Rock_Sandstone_Cobble"
    },
    {
      "x": -6,
      "y": 8,
      "z": -5,
      "name": "Rock_Sandstone_Cobble"
    },
    {
      "x": -6,
      "y": 9,
      "z": -5,
      "name": "Rock_Sandstone_Cobble"
    },
    {
      "x": -6,
      "y": 10,
      "z": -5,
      "name": "Cloth_Roof_Leather",
      "rotation": 2
    },
    {
      "x": -6,
      "y": 1,
      "z": -4,
      "name": "Rock_Sandstone"
    },
    {
      "x": -6,
      "y": 2,
      "z": -4,
      "name": "Rock_Sandstone"
    },
    {
      "x": -6,
      "y": 3,
      "z": -4,
      "name": "Soil_Mud"
    },
    {
      "x": -6,
      "y": 4,
      "z": -4,
      "name": "Soil_Mud"
    },
    {
      "x": -6,
      "y": 10,
      "z": -4,
      "name": "Rock_Sandstone_Brick_Smooth"
    },
    {
      "x": -6,
      "y": 11,
      "z": -4,
      "name": "Cloth_Roof_Leather_Flat"
    },
    {
      "x": -6,
      "y": 0,
      "z": -3,
      "name": "Rock_Sandstone"
    },
    {
      "x": -6,
      "y": 1,
      "z": -3,
      "name": "Rock_Sandstone"
    },
    {
      "x": -6,
      "y": 2,
      "z": -3,
      "name": "Rock_Sandstone"
    },
    {
      "x": -6,
      "y": 3,
      "z": -3,
      "name": "Soil_Mud"
    },
    {
      "x": -6,
      "y": 4,
      "z": -3,
      "name": "Soil_Mud"
    },
    {
      "x": -6,
      "y": 5,
      "z": -3,
      "name": "Plant_Crop_Mushroom_Cap_Brown",
      "components": {
        "Components": {
          "FarmingBlock": {
            "LastTickGameTime": "0001-01-01T12:00:00Z"
          },
          "PlacedByInteraction": {
            "WhoPlacedUuid": {
              "$binary": "jmZp6ZgrSpi8/YFXQtu79Q==",
              "$type": "04"
            }
          }
        }
      }
    },
    {
      "x": -6,
      "y": 11,
      "z": -3,
      "name": "Cloth_Roof_Leather_Flat"
    },
    {
      "x": -6,
      "y": 0,
      "z": -2,
      "name": "Rock_Sandstone"
    },
    {
      "x": -6,
      "y": 1,
      "z": -2,
      "name": "Rock_Sandstone"
    },
    {
      "x": -6,
      "y": 2,
      "z": -2,
      "name": "Rock_Sandstone"
    },
    {
      "x": -6,
      "y": 3,
      "z": -2,
      "name": "Soil_Mud"
    },
    {
      "x": -6,
      "y": 4,
      "z": -2,
      "name": "Soil_Mud"
    },
    {
      "x": -6,
      "y": 8,
      "z": -2,
      "name": "Plant_Crop_Mushroom_Block_Brown"
    },
    {
      "x": -6,
      "y": 11,
      "z": -2,
      "name": "Cloth_Roof_Leather_Flat"
    },
    {
      "x": -6,
      "y": 0,
      "z": -1,
      "name": "Rock_Sandstone"
    },
    {
      "x": -6,
      "y": 1,
      "z": -1,
      "name": "Rock_Sandstone"
    },
    {
      "x": -6,
      "y": 2,
      "z": -1,
      "name": "Rock_Sandstone"
    },
    {
      "x": -6,
      "y": 3,
      "z": -1,
      "name": "Soil_Mud"
    },
    {
      "x": -6,
      "y": 4,
      "z": -1,
      "name": "Soil_Mud"
    },
    {
      "x": -6,
      "y": 8,
      "z": -1,
      "name": "Plant_Crop_Mushroom_Block_Brown"
    },
    {
      "x": -6,
      "y": 9,
      "z": -1,
      "name": "Plant_Crop_Mushroom_Block_Brown"
    },
    {
      "x": -6,
      "y": 11,
      "z": -1,
      "name": "Cloth_Roof_Leather_Flat"
    },
    {
      "x": -6,
      "y": 0,
      "z": 0,
      "name": "Rock_Sandstone"
    },
    {
      "x": -6,
      "y": 1,
      "z": 0,
      "name": "Rock_Sandstone"
    },
    {
      "x": -6,
      "y": 2,
      "z": 0,
      "name": "Rock_Sandstone"
    },
    {
      "x": -6,
      "y": 3,
      "z": 0,
      "name": "Soil_Mud"
    },
    {
      "x": -6,
      "y": 4,
      "z": 0,
      "name": "Soil_Mud"
    },
    {
      "x": -6,
      "y": 5,
      "z": 0,
      "name": "Plant_Crop_Mushroom_Block_Brown_Trunk"
    },
    {
      "x": -6,
      "y": 6,
      "z": 0,
      "name": "Plant_Crop_Mushroom_Block_Brown_Trunk"
    },
    {
      "x": -6,
      "y": 7,
      "z": 0,
      "name": "Plant_Crop_Mushroom_Block_Brown_Trunk"
    },
    {
      "x": -6,
      "y": 8,
      "z": 0,
      "name": "Plant_Crop_Mushroom_Block_Brown"
    },
    {
      "x": -6,
      "y": 9,
      "z": 0,
      "name": "Plant_Crop_Mushroom_Block_Brown"
    },
    {
      "x": -6,
      "y": 10,
      "z": 0,
      "name": "Rock_Sandstone_Brick_Smooth"
    },
    {
      "x": -6,
      "y": 11,
      "z": 0,
      "name": "Cloth_Roof_Leather_Flat"
    },
    {
      "x": -6,
      "y": 0,
      "z": 1,
      "name": "Rock_Sandstone"
    },
    {
      "x": -6,
      "y": 1,
      "z": 1,
      "name": "Rock_Sandstone"
    },
    {
      "x": -6,
      "y": 2,
      "z": 1,
      "name": "Rock_Sandstone"
    },
    {
      "x": -6,
      "y": 3,
      "z": 1,
      "name": "Soil_Mud"
    },
    {
      "x": -6,
      "y": 4,
      "z": 1,
      "name": "Soil_Mud"
    },
    {
      "x": -6,
      "y": 8,
      "z": 1,
      "name": "Plant_Crop_Mushroom_Block_Brown"
    },
    {
      "x": -6,
      "y": 9,
      "z": 1,
      "name": "Plant_Crop_Mushroom_Block_Brown"
    },
    {
      "x": -6,
      "y": 11,
      "z": 1,
      "name": "Cloth_Roof_Leather_Flat"
    },
    {
      "x": -6,
      "y": 0,
      "z": 2,
      "name": "Rock_Sandstone"
    },
    {
      "x": -6,
      "y": 1,
      "z": 2,
      "name": "Rock_Sandstone"
    },
    {
      "x": -6,
      "y": 2,
      "z": 2,
      "name": "Rock_Sandstone"
    },
    {
      "x": -6,
      "y": 3,
      "z": 2,
      "name": "Soil_Mud"
    },
    {
      "x": -6,
      "y": 4,
      "z": 2,
      "name": "Soil_Mud"
    },
    {
      "x": -6,
      "y": 8,
      "z": 2,
      "name": "Plant_Crop_Mushroom_Block_Brown"
    },
    {
      "x": -6,
      "y": 11,
      "z": 2,
      "name": "Cloth_Roof_Leather_Flat"
    },
    {
      "x": -6,
      "y": 0,
      "z": 3,
      "name": "Rock_Sandstone"
    },
    {
      "x": -6,
      "y": 1,
      "z": 3,
      "name": "Rock_Sandstone"
    },
    {
      "x": -6,
      "y": 2,
      "z": 3,
      "name": "Rock_Sandstone"
    },
    {
      "x": -6,
      "y": 3,
      "z": 3,
      "name": "Soil_Mud"
    },
    {
      "x": -6,
      "y": 4,
      "z": 3,
      "name": "Soil_Mud"
    },
    {
      "x": -6,
      "y": 11,
      "z": 3,
      "name": "Cloth_Roof_Leather_Flat"
    },
    {
      "x": -6,
      "y": 1,
      "z": 4,
      "name": "Rock_Sandstone"
    },
    {
      "x": -6,
      "y": 2,
      "z": 4,
      "name": "Rock_Sandstone"
    },
    {
      "x": -6,
      "y": 3,
      "z": 4,
      "name": "Soil_Mud"
    },
    {
      "x": -6,
      "y": 4,
      "z": 4,
      "name": "Soil_Mud"
    },
    {
      "x": -6,
      "y": 10,
      "z": 4,
      "name": "Rock_Sandstone_Brick_Smooth"
    },
    {
      "x": -6,
      "y": 11,
      "z": 4,
      "name": "Cloth_Roof_Leather_Flat"
    },
    {
      "x": -6,
      "y": 2,
      "z": 5,
      "name": "Rock_Sandstone"
    },
    {
      "x": -6,
      "y": 3,
      "z": 5,
      "name": "Rock_Sandstone"
    },
    {
      "x": -6,
      "y": 4,
      "z": 5,
      "name": "Soil_Dirt_Dry"
    },
    {
      "x": -6,
      "y": 5,
      "z": 5,
      "name": "Rock_Sandstone_Cobble"
    },
    {
      "x": -6,
      "y": 6,
      "z": 5,
      "name": "Rock_Sandstone_Cobble"
    },
    {
      "x": -6,
      "y": 7,
      "z": 5,
      "name": "Rock_Sandstone_Cobble"
    },
    {
      "x": -6,
      "y": 8,
      "z": 5,
      "name": "Rock_Sandstone_Cobble"
    },
    {
      "x": -6,
      "y": 9,
      "z": 5,
      "name": "Rock_Sandstone_Cobble"
    },
    {
      "x": -6,
      "y": 10,
      "z": 5,
      "name": "Cloth_Roof_Leather"
    },
    {
      "x": -6,
      "y": 3,
      "z": 6,
      "name": "Rock_Sandstone"
    },
    {
      "x": -6,
      "y": 4,
      "z": 6,
      "name": "Soil_Dirt_Dry"
    },
    {
      "x": -6,
      "y": 5,
      "z": 6,
      "name": "Soil_Dirt_Dry"
    },
    {
      "x": -6,
      "y": 9,
      "z": 6,
      "name": "Cloth_Roof_Leather"
    },
    {
      "x": -5,
      "y": 3,
      "z": -6,
      "name": "Rock_Sandstone"
    },
    {
      "x": -5,
      "y": 4,
      "z": -6,
      "name": "Soil_Dirt_Dry"
    },
    {
      "x": -5,
      "y": 5,
      "z": -6,
      "name": "Soil_Dirt_Dry"
    },
    {
      "x": -5,
      "y": 9,
      "z": -6,
      "name": "Cloth_Roof_Leather",
      "rotation": 2
    },
    {
      "x": -5,
      "y": 2,
      "z": -5,
      "name": "Rock_Sandstone"
    },
    {
      "x": -5,
      "y": 3,
      "z": -5,
      "name": "Rock_Sandstone"
    },
    {
      "x": -5,
      "y": 4,
      "z": -5,
      "name": "Soil_Dirt_Dry"
    },
    {
      "x": -5,
      "y": 5,
      "z": -5,
      "name": "Rock_Sandstone_Cobble"
    },
    {
      "x": -5,
      "y": 9,
      "z": -5,
      "name": "Rock_Sandstone_Cobble"
    },
    {
      "x": -5,
      "y": 10,
      "z": -5,
      "name": "Cloth_Roof_Leather",
      "rotation": 2
    },
    {
      "x": -5,
      "y": 1,
      "z": -4,
      "name": "Rock_Sandstone"
    },
    {
      "x": -5,
      "y": 2,
      "z": -4,
      "name": "Rock_Sandstone"
    },
    {
      "x": -5,
      "y": 3,
      "z": -4,
      "name": "Soil_Mud"
    },
    {
      "x": -5,
      "y": 4,
      "z": -4,
      "name": "Soil_Mud"
    },
    {
      "x": -5,
      "y": 10,
      "z": -4,
      "name": "Rock_Sandstone_Brick_Smooth"
    },
    {
      "x": -5,
      "y": 11,
      "z": -4,
      "name": "Cloth_Roof_Leather_Flat"
    },
    {
      "x": -5,
      "y": 0,
      "z": -3,
      "name": "Rock_Sandstone"
    },
    {
      "x": -5,
      "y": 1,
      "z": -3,
      "name": "Rock_Sandstone"
    },
    {
      "x": -5,
      "y": 2,
      "z": -3,
      "name": "Rock_Sandstone"
    },
    {
      "x": -5,
      "y": 3,
      "z": -3,
      "name": "Soil_Mud"
    },
    {
      "x": -5,
      "y": 4,
      "z": -3,
      "name": "Soil_Mud"
    },
    {
      "x": -5,
      "y": 10,
      "z": -3,
      "name": "Rock_Sandstone_Brick_Smooth"
    },
    {
      "x": -5,
      "y": 11,
      "z": -3,
      "name": "Cloth_Roof_Leather_Flat"
    },
    {
      "x": -5,
      "y": 0,
      "z": -2,
      "name": "Rock_Sandstone"
    },
    {
      "x": -5,
      "y": 1,
      "z": -2,
      "name": "Rock_Sandstone"
    },
    {
      "x": -5,
      "y": 2,
      "z": -2,
      "name": "Rock_Sandstone"
    },
    {
      "x": -5,
      "y": 3,
      "z": -2,
      "name": "Soil_Mud"
    },
    {
      "x": -5,
      "y": 4,
      "z": -2,
      "name": "Soil_Mud"
    },
    {
      "x": -5,
      "y": 10,
      "z": -2,
      "name": "Rock_Sandstone_Brick_Smooth"
    },
    {
      "x": -5,
      "y": 11,
      "z": -2,
      "name": "Cloth_Roof_Leather_Flat"
    },
    {
      "x": -5,
      "y": 0,
      "z": -1,
      "name": "Rock_Sandstone"
    },
    {
      "x": -5,
      "y": 1,
      "z": -1,
      "name": "Rock_Sandstone"
    },
    {
      "x": -5,
      "y": 2,
      "z": -1,
      "name": "Rock_Sandstone"
    },
    {
      "x": -5,
      "y": 3,
      "z": -1,
      "name": "Soil_Mud"
    },
    {
      "x": -5,
      "y": 4,
      "z": -1,
      "name": "Soil_Mud"
    },
    {
      "x": -5,
      "y": 8,
      "z": -1,
      "name": "Plant_Crop_Mushroom_Block_Brown"
    },
    {
      "x": -5,
      "y": 9,
      "z": -1,
      "name": "Plant_Crop_Mushroom_Block_Brown"
    },
    {
      "x": -5,
      "y": 10,
      "z": -1,
      "name": "Rock_Sandstone_Brick_Smooth"
    },
    {
      "x": -5,
      "y": 11,
      "z": -1,
      "name": "Cloth_Roof_Leather_Flat"
    },
    {
      "x": -5,
      "y": 0,
      "z": 0,
      "name": "Rock_Sandstone"
    },
    {
      "x": -5,
      "y": 1,
      "z": 0,
      "name": "Rock_Sandstone"
    },
    {
      "x": -5,
      "y": 2,
      "z": 0,
      "name": "Rock_Sandstone"
    },
    {
      "x": -5,
      "y": 3,
      "z": 0,
      "name": "Soil_Mud"
    },
    {
      "x": -5,
      "y": 4,
      "z": 0,
      "name": "Soil_Mud"
    },
    {
      "x": -5,
      "y": 8,
      "z": 0,
      "name": "Plant_Crop_Mushroom_Block_Brown"
    },
    {
      "x": -5,
      "y": 9,
      "z": 0,
      "name": "Plant_Crop_Mushroom_Block_Brown"
    },
    {
      "x": -5,
      "y": 10,
      "z": 0,
      "name": "Rock_Sandstone_Brick_Smooth"
    },
    {
      "x": -5,
      "y": 11,
      "z": 0,
      "name": "Cloth_Roof_Leather_Flat"
    },
    {
      "x": -5,
      "y": 0,
      "z": 1,
      "name": "Rock_Sandstone"
    },
    {
      "x": -5,
      "y": 1,
      "z": 1,
      "name": "Rock_Sandstone"
    },
    {
      "x": -5,
      "y": 2,
      "z": 1,
      "name": "Rock_Sandstone"
    },
    {
      "x": -5,
      "y": 3,
      "z": 1,
      "name": "Soil_Mud"
    },
    {
      "x": -5,
      "y": 4,
      "z": 1,
      "name": "Soil_Mud"
    },
    {
      "x": -5,
      "y": 8,
      "z": 1,
      "name": "Plant_Crop_Mushroom_Block_Brown"
    },
    {
      "x": -5,
      "y": 9,
      "z": 1,
      "name": "Plant_Crop_Mushroom_Block_Brown"
    },
    {
      "x": -5,
      "y": 10,
      "z": 1,
      "name": "Rock_Sandstone_Brick_Smooth"
    },
    {
      "x": -5,
      "y": 11,
      "z": 1,
      "name": "Cloth_Roof_Leather_Flat"
    },
    {
      "x": -5,
      "y": 0,
      "z": 2,
      "name": "Rock_Sandstone"
    },
    {
      "x": -5,
      "y": 1,
      "z": 2,
      "name": "Rock_Sandstone"
    },
    {
      "x": -5,
      "y": 2,
      "z": 2,
      "name": "Rock_Sandstone"
    },
    {
      "x": -5,
      "y": 3,
      "z": 2,
      "name": "Soil_Mud"
    },
    {
      "x": -5,
      "y": 4,
      "z": 2,
      "name": "Soil_Mud"
    },
    {
      "x": -5,
      "y": 10,
      "z": 2,
      "name": "Rock_Sandstone_Brick_Smooth"
    },
    {
      "x": -5,
      "y": 11,
      "z": 2,
      "name": "Cloth_Roof_Leather_Flat"
    },
    {
      "x": -5,
      "y": 0,
      "z": 3,
      "name": "Rock_Sandstone"
    },
    {
      "x": -5,
      "y": 1,
      "z": 3,
      "name": "Rock_Sandstone"
    },
    {
      "x": -5,
      "y": 2,
      "z": 3,
      "name": "Rock_Sandstone"
    },
    {
      "x": -5,
      "y": 3,
      "z": 3,
      "name": "Soil_Mud"
    },
    {
      "x": -5,
      "y": 4,
      "z": 3,
      "name": "Soil_Mud"
    },
    {
      "x": -5,
      "y": 10,
      "z": 3,
      "name": "Rock_Sandstone_Brick_Smooth"
    },
    {
      "x": -5,
      "y": 11,
      "z": 3,
      "name": "Cloth_Roof_Leather_Flat"
    },
    {
      "x": -5,
      "y": 1,
      "z": 4,
      "name": "Rock_Sandstone"
    },
    {
      "x": -5,
      "y": 2,
      "z": 4,
      "name": "Rock_Sandstone"
    },
    {
      "x": -5,
      "y": 3,
      "z": 4,
      "name": "Soil_Mud"
    },
    {
      "x": -5,
      "y": 4,
      "z": 4,
      "name": "Soil_Mud"
    },
    {
      "x": -5,
      "y": 10,
      "z": 4,
      "name": "Rock_Sandstone_Brick_Smooth"
    },
    {
      "x": -5,
      "y": 11,
      "z": 4,
      "name": "Cloth_Roof_Leather_Flat"
    },
    {
      "x": -5,
      "y": 2,
      "z": 5,
      "name": "Rock_Sandstone"
    },
    {
      "x": -5,
      "y": 3,
      "z": 5,
      "name": "Rock_Sandstone"
    },
    {
      "x": -5,
      "y": 4,
      "z": 5,
      "name": "Soil_Dirt_Dry"
    },
    {
      "x": -5,
      "y": 5,
      "z": 5,
      "name": "Rock_Sandstone_Cobble"
    },
    {
      "x": -5,
      "y": 9,
      "z": 5,
      "name": "Rock_Sandstone_Cobble"
    },
    {
      "x": -5,
      "y": 10,
      "z": 5,
      "name": "Cloth_Roof_Leather"
    },
    {
      "x": -5,
      "y": 3,
      "z": 6,
      "name": "Rock_Sandstone"
    },
    {
      "x": -5,
      "y": 4,
      "z": 6,
      "name": "Soil_Dirt_Dry"
    },
    {
      "x": -5,
      "y": 5,
      "z": 6,
      "name": "Soil_Dirt_Dry"
    },
    {
      "x": -5,
      "y": 9,
      "z": 6,
      "name": "Cloth_Roof_Leather"
    },
    {
      "x": -4,
      "y": 3,
      "z": -6,
      "name": "Rock_Sandstone"
    },
    {
      "x": -4,
      "y": 4,
      "z": -6,
      "name": "Soil_Dirt_Dry"
    },
    {
      "x": -4,
      "y": 5,
      "z": -6,
      "name": "Soil_Dirt_Dry"
    },
    {
      "x": -4,
      "y": 9,
      "z": -6,
      "name": "Cloth_Roof_Leather",
      "rotation": 2
    },
    {
      "x": -4,
      "y": 2,
      "z": -5,
      "name": "Rock_Sandstone"
    },
    {
      "x": -4,
      "y": 3,
      "z": -5,
      "name": "Rock_Sandstone"
    },
    {
      "x": -4,
      "y": 4,
      "z": -5,
      "name": "Soil_Dirt_Dry"
    },
    {
      "x": -4,
      "y": 5,
      "z": -5,
      "name": "Rock_Sandstone_Cobble"
    },
    {
      "x": -4,
      "y": 9,
      "z": -5,
      "name": "Rock_Sandstone_Cobble"
    },
    {
      "x": -4,
      "y": 10,
      "z": -5,
      "name": "Cloth_Roof_Leather",
      "rotation": 2
    },
    {
      "x": -4,
      "y": 1,
      "z": -4,
      "name": "Rock_Sandstone"
    },
    {
      "x": -4,
      "y": 2,
      "z": -4,
      "name": "Rock_Sandstone"
    },
    {
      "x": -4,
      "y": 3,
      "z": -4,
      "name": "Soil_Mud"
    },
    {
      "x": -4,
      "y": 4,
      "z": -4,
      "name": "Soil_Mud"
    },
    {
      "x": -4,
      "y": 10,
      "z": -4,
      "name": "Rock_Sandstone_Brick_Smooth"
    },
    {
      "x": -4,
      "y": 11,
      "z": -4,
      "name": "Cloth_Roof_Leather_Flat"
    },
    {
      "x": -4,
      "y": 0,
      "z": -3,
      "name": "Rock_Sandstone"
    },
    {
      "x": -4,
      "y": 1,
      "z": -3,
      "name": "Rock_Sandstone"
    },
    {
      "x": -4,
      "y": 2,
      "z": -3,
      "name": "Rock_Sandstone"
    },
    {
      "x": -4,
      "y": 3,
      "z": -3,
      "name": "Soil_Mud"
    },
    {
      "x": -4,
      "y": 4,
      "z": -3,
      "name": "Soil_Mud"
    },
    {
      "x": -4,
      "y": 11,
      "z": -3,
      "name": "Cloth_Roof_Leather_Flat"
    },
    {
      "x": -4,
      "y": 0,
      "z": -2,
      "name": "Rock_Sandstone"
    },
    {
      "x": -4,
      "y": 1,
      "z": -2,
      "name": "Rock_Sandstone"
    },
    {
      "x": -4,
      "y": 2,
      "z": -2,
      "name": "Rock_Sandstone"
    },
    {
      "x": -4,
      "y": 3,
      "z": -2,
      "name": "Soil_Mud"
    },
    {
      "x": -4,
      "y": 4,
      "z": -2,
      "name": "Soil_Mud"
    },
    {
      "x": -4,
      "y": 11,
      "z": -2,
      "name": "Cloth_Roof_Leather_Flat"
    },
    {
      "x": -4,
      "y": 0,
      "z": -1,
      "name": "Rock_Sandstone"
    },
    {
      "x": -4,
      "y": 1,
      "z": -1,
      "name": "Rock_Sandstone"
    },
    {
      "x": -4,
      "y": 2,
      "z": -1,
      "name": "Rock_Sandstone"
    },
    {
      "x": -4,
      "y": 3,
      "z": -1,
      "name": "Soil_Mud"
    },
    {
      "x": -4,
      "y": 4,
      "z": -1,
      "name": "Soil_Mud"
    },
    {
      "x": -4,
      "y": 11,
      "z": -1,
      "name": "Cloth_Roof_Leather_Flat"
    },
    {
      "x": -4,
      "y": 0,
      "z": 0,
      "name": "Rock_Sandstone"
    },
    {
      "x": -4,
      "y": 1,
      "z": 0,
      "name": "Rock_Sandstone"
    },
    {
      "x": -4,
      "y": 2,
      "z": 0,
      "name": "Rock_Sandstone"
    },
    {
      "x": -4,
      "y": 3,
      "z": 0,
      "name": "Soil_Mud"
    },
    {
      "x": -4,
      "y": 4,
      "z": 0,
      "name": "Soil_Mud"
    },
    {
      "x": -4,
      "y": 5,
      "z": 0,
      "name": "Plant_Crop_Mushroom_Cap_Brown",
      "components": {
        "Components": {
          "FarmingBlock": {
            "LastTickGameTime": "0001-01-01T12:00:00Z"
          },
          "PlacedByInteraction": {
            "WhoPlacedUuid": {
              "$binary": "jmZp6ZgrSpi8/YFXQtu79Q==",
              "$type": "04"
            }
          }
        }
      }
    },
    {
      "x": -4,
      "y": 8,
      "z": 0,
      "name": "Plant_Crop_Mushroom_Block_Brown"
    },
    {
      "x": -4,
      "y": 10,
      "z": 0,
      "name": "Rock_Sandstone_Brick_Smooth"
    },
    {
      "x": -4,
      "y": 11,
      "z": 0,
      "name": "Cloth_Roof_Leather_Flat"
    },
    {
      "x": -4,
      "y": 0,
      "z": 1,
      "name": "Rock_Sandstone"
    },
    {
      "x": -4,
      "y": 1,
      "z": 1,
      "name": "Rock_Sandstone"
    },
    {
      "x": -4,
      "y": 2,
      "z": 1,
      "name": "Rock_Sandstone"
    },
    {
      "x": -4,
      "y": 3,
      "z": 1,
      "name": "Soil_Mud"
    },
    {
      "x": -4,
      "y": 4,
      "z": 1,
      "name": "Soil_Mud"
    },
    {
      "x": -4,
      "y": 11,
      "z": 1,
      "name": "Cloth_Roof_Leather_Flat"
    },
    {
      "x": -4,
      "y": 0,
      "z": 2,
      "name": "Rock_Sandstone"
    },
    {
      "x": -4,
      "y": 1,
      "z": 2,
      "name": "Rock_Sandstone"
    },
    {
      "x": -4,
      "y": 2,
      "z": 2,
      "name": "Rock_Sandstone"
    },
    {
      "x": -4,
      "y": 3,
      "z": 2,
      "name": "Soil_Mud"
    },
    {
      "x": -4,
      "y": 4,
      "z": 2,
      "name": "Soil_Mud"
    },
    {
      "x": -4,
      "y": 11,
      "z": 2,
      "name": "Cloth_Roof_Leather_Flat"
    },
    {
      "x": -4,
      "y": 0,
      "z": 3,
      "name": "Rock_Sandstone"
    },
    {
      "x": -4,
      "y": 1,
      "z": 3,
      "name": "Rock_Sandstone"
    },
    {
      "x": -4,
      "y": 2,
      "z": 3,
      "name": "Rock_Sandstone"
    },
    {
      "x": -4,
      "y": 3,
      "z": 3,
      "name": "Soil_Mud"
    },
    {
      "x": -4,
      "y": 4,
      "z": 3,
      "name": "Soil_Mud"
    },
    {
      "x": -4,
      "y": 11,
      "z": 3,
      "name": "Cloth_Roof_Leather_Flat"
    },
    {
      "x": -4,
      "y": 1,
      "z": 4,
      "name": "Rock_Sandstone"
    },
    {
      "x": -4,
      "y": 2,
      "z": 4,
      "name": "Rock_Sandstone"
    },
    {
      "x": -4,
      "y": 3,
      "z": 4,
      "name": "Soil_Mud"
    },
    {
      "x": -4,
      "y": 4,
      "z": 4,
      "name": "Soil_Mud"
    },
    {
      "x": -4,
      "y": 10,
      "z": 4,
      "name": "Rock_Sandstone_Brick_Smooth"
    },
    {
      "x": -4,
      "y": 11,
      "z": 4,
      "name": "Cloth_Roof_Leather_Flat"
    },
    {
      "x": -4,
      "y": 2,
      "z": 5,
      "name": "Rock_Sandstone"
    },
    {
      "x": -4,
      "y": 3,
      "z": 5,
      "name": "Rock_Sandstone"
    },
    {
      "x": -4,
      "y": 4,
      "z": 5,
      "name": "Soil_Dirt_Dry"
    },
    {
      "x": -4,
      "y": 5,
      "z": 5,
      "name": "Rock_Sandstone_Cobble"
    },
    {
      "x": -4,
      "y": 9,
      "z": 5,
      "name": "Rock_Sandstone_Cobble"
    },
    {
      "x": -4,
      "y": 10,
      "z": 5,
      "name": "Cloth_Roof_Leather"
    },
    {
      "x": -4,
      "y": 3,
      "z": 6,
      "name": "Rock_Sandstone"
    },
    {
      "x": -4,
      "y": 4,
      "z": 6,
      "name": "Soil_Dirt_Dry"
    },
    {
      "x": -4,
      "y": 5,
      "z": 6,
      "name": "Soil_Dirt_Dry"
    },
    {
      "x": -4,
      "y": 9,
      "z": 6,
      "name": "Cloth_Roof_Leather"
    },
    {
      "x": -3,
      "y": 3,
      "z": -6,
      "name": "Rock_Sandstone"
    },
    {
      "x": -3,
      "y": 4,
      "z": -6,
      "name": "Soil_Dirt_Dry"
    },
    {
      "x": -3,
      "y": 5,
      "z": -6,
      "name": "Soil_Dirt_Dry"
    },
    {
      "x": -3,
      "y": 9,
      "z": -6,
      "name": "Cloth_Roof_Leather",
      "rotation": 2
    },
    {
      "x": -3,
      "y": 2,
      "z": -5,
      "name": "Rock_Sandstone"
    },
    {
      "x": -3,
      "y": 3,
      "z": -5,
      "name": "Rock_Sandstone"
    },
    {
      "x": -3,
      "y": 4,
      "z": -5,
      "name": "Soil_Dirt_Dry"
    },
    {
      "x": -3,
      "y": 5,
      "z": -5,
      "name": "Rock_Sandstone_Cobble"
    },
    {
      "x": -3,
      "y": 6,
      "z": -5,
      "name": "Rock_Sandstone_Cobble"
    },
    {
      "x": -3,
      "y": 7,
      "z": -5,
      "name": "Rock_Sandstone_Cobble"
    },
    {
      "x": -3,
      "y": 8,
      "z": -5,
      "name": "Rock_Sandstone_Cobble"
    },
    {
      "x": -3,
      "y": 9,
      "z": -5,
      "name": "Rock_Sandstone_Cobble"
    },
    {
      "x": -3,
      "y": 10,
      "z": -5,
      "name": "Cloth_Roof_Leather",
      "rotation": 2
    },
    {
      "x": -3,
      "y": 1,
      "z": -4,
      "name": "Rock_Sandstone"
    },
    {
      "x": -3,
      "y": 2,
      "z": -4,
      "name": "Rock_Sandstone"
    },
    {
      "x": -3,
      "y": 3,
      "z": -4,
      "name": "Soil_Mud"
    },
    {
      "x": -3,
      "y": 4,
      "z": -4,
      "name": "Soil_Mud"
    },
    {
      "x": -3,
      "y": 10,
      "z": -4,
      "name": "Rock_Sandstone_Brick_Smooth"
    },
    {
      "x": -3,
      "y": 11,
      "z": -4,
      "name": "Cloth_Roof_Leather_Flat"
    },
    {
      "x": -3,
      "y": 0,
      "z": -3,
      "name": "Rock_Sandstone"
    },
    {
      "x": -3,
      "y": 1,
      "z": -3,
      "name": "Rock_Sandstone"
    },
    {
      "x": -3,
      "y": 2,
      "z": -3,
      "name": "Rock_Sandstone"
    },
    {
      "x": -3,
      "y": 3,
      "z": -3,
      "name": "Soil_Mud"
    },
    {
      "x": -3,
      "y": 4,
      "z": -3,
      "name": "Soil_Mud"
    },
    {
      "x": -3,
      "y": 5,
      "z": -3,
      "name": "Plant_Crop_Mushroom_Block_Brown"
    },
    {
      "x": -3,
      "y": 11,
      "z": -3,
      "name": "Cloth_Roof_Leather_Flat"
    },
    {
      "x": -3,
      "y": 0,
      "z": -2,
      "name": "Rock_Sandstone"
    },
    {
      "x": -3,
      "y": 1,
      "z": -2,
      "name": "Rock_Sandstone"
    },
    {
      "x": -3,
      "y": 2,
      "z": -2,
      "name": "Rock_Sandstone"
    },
    {
      "x": -3,
      "y": 3,
      "z": -2,
      "name": "Soil_Mud"
    },
    {
      "x": -3,
      "y": 4,
      "z": -2,
      "name": "Soil_Mud"
    },
    {
      "x": -3,
      "y": 11,
      "z": -2,
      "name": "Cloth_Roof_Leather_Flat"
    },
    {
      "x": -3,
      "y": 0,
      "z": -1,
      "name": "Rock_Sandstone"
    },
    {
      "x": -3,
      "y": 1,
      "z": -1,
      "name": "Rock_Sandstone"
    },
    {
      "x": -3,
      "y": 2,
      "z": -1,
      "name": "Rock_Sandstone"
    },
    {
      "x": -3,
      "y": 3,
      "z": -1,
      "name": "Soil_Mud"
    },
    {
      "x": -3,
      "y": 4,
      "z": -1,
      "name": "Soil_Mud"
    },
    {
      "x": -3,
      "y": 11,
      "z": -1,
      "name": "Cloth_Roof_Leather_Flat"
    },
    {
      "x": -3,
      "y": 0,
      "z": 0,
      "name": "Rock_Sandstone"
    },
    {
      "x": -3,
      "y": 1,
      "z": 0,
      "name": "Rock_Sandstone"
    },
    {
      "x": -3,
      "y": 2,
      "z": 0,
      "name": "Rock_Sandstone"
    },
    {
      "x": -3,
      "y": 3,
      "z": 0,
      "name": "Soil_Mud"
    },
    {
      "x": -3,
      "y": 4,
      "z": 0,
      "name": "Soil_Mud"
    },
    {
      "x": -3,
      "y": 10,
      "z": 0,
      "name": "Rock_Sandstone_Brick_Smooth"
    },
    {
      "x": -3,
      "y": 11,
      "z": 0,
      "name": "Cloth_Roof_Leather_Flat"
    },
    {
      "x": -3,
      "y": 0,
      "z": 1,
      "name": "Rock_Sandstone"
    },
    {
      "x": -3,
      "y": 1,
      "z": 1,
      "name": "Rock_Sandstone"
    },
    {
      "x": -3,
      "y": 2,
      "z": 1,
      "name": "Rock_Sandstone"
    },
    {
      "x": -3,
      "y": 3,
      "z": 1,
      "name": "Soil_Mud"
    },
    {
      "x": -3,
      "y": 4,
      "z": 1,
      "name": "Soil_Mud"
    },
    {
      "x": -3,
      "y": 11,
      "z": 1,
      "name": "Cloth_Roof_Leather_Flat"
    },
    {
      "x": -3,
      "y": 0,
      "z": 2,
      "name": "Rock_Sandstone"
    },
    {
      "x": -3,
      "y": 1,
      "z": 2,
      "name": "Rock_Sandstone"
    },
    {
      "x": -3,
      "y": 2,
      "z": 2,
      "name": "Rock_Sandstone"
    },
    {
      "x": -3,
      "y": 3,
      "z": 2,
      "name": "Soil_Mud"
    },
    {
      "x": -3,
      "y": 4,
      "z": 2,
      "name": "Soil_Mud"
    },
    {
      "x": -3,
      "y": 5,
      "z": 2,
      "name": "Plant_Crop_Mushroom_Cap_Brown",
      "components": {
        "Components": {
          "FarmingBlock": {
            "LastTickGameTime": "0001-01-01T12:00:00Z"
          },
          "PlacedByInteraction": {
            "WhoPlacedUuid": {
              "$binary": "jmZp6ZgrSpi8/YFXQtu79Q==",
              "$type": "04"
            }
          }
        }
      }
    },
    {
      "x": -3,
      "y": 11,
      "z": 2,
      "name": "Cloth_Roof_Leather_Flat"
    },
    {
      "x": -3,
      "y": 0,
      "z": 3,
      "name": "Rock_Sandstone"
    },
    {
      "x": -3,
      "y": 1,
      "z": 3,
      "name": "Rock_Sandstone"
    },
    {
      "x": -3,
      "y": 2,
      "z": 3,
      "name": "Rock_Sandstone"
    },
    {
      "x": -3,
      "y": 3,
      "z": 3,
      "name": "Soil_Mud"
    },
    {
      "x": -3,
      "y": 4,
      "z": 3,
      "name": "Soil_Mud"
    },
    {
      "x": -3,
      "y": 11,
      "z": 3,
      "name": "Cloth_Roof_Leather_Flat"
    },
    {
      "x": -3,
      "y": 1,
      "z": 4,
      "name": "Rock_Sandstone"
    },
    {
      "x": -3,
      "y": 2,
      "z": 4,
      "name": "Rock_Sandstone"
    },
    {
      "x": -3,
      "y": 3,
      "z": 4,
      "name": "Soil_Mud"
    },
    {
      "x": -3,
      "y": 4,
      "z": 4,
      "name": "Soil_Mud"
    },
    {
      "x": -3,
      "y": 10,
      "z": 4,
      "name": "Rock_Sandstone_Brick_Smooth"
    },
    {
      "x": -3,
      "y": 11,
      "z": 4,
      "name": "Cloth_Roof_Leather_Flat"
    },
    {
      "x": -3,
      "y": 2,
      "z": 5,
      "name": "Rock_Sandstone"
    },
    {
      "x": -3,
      "y": 3,
      "z": 5,
      "name": "Rock_Sandstone"
    },
    {
      "x": -3,
      "y": 4,
      "z": 5,
      "name": "Soil_Dirt_Dry"
    },
    {
      "x": -3,
      "y": 5,
      "z": 5,
      "name": "Rock_Sandstone_Cobble"
    },
    {
      "x": -3,
      "y": 6,
      "z": 5,
      "name": "Rock_Sandstone_Cobble"
    },
    {
      "x": -3,
      "y": 7,
      "z": 5,
      "name": "Rock_Sandstone_Cobble"
    },
    {
      "x": -3,
      "y": 8,
      "z": 5,
      "name": "Rock_Sandstone_Cobble"
    },
    {
      "x": -3,
      "y": 9,
      "z": 5,
      "name": "Rock_Sandstone_Cobble"
    },
    {
      "x": -3,
      "y": 10,
      "z": 5,
      "name": "Cloth_Roof_Leather"
    },
    {
      "x": -3,
      "y": 3,
      "z": 6,
      "name": "Rock_Sandstone"
    },
    {
      "x": -3,
      "y": 4,
      "z": 6,
      "name": "Soil_Dirt_Dry"
    },
    {
      "x": -3,
      "y": 5,
      "z": 6,
      "name": "Soil_Dirt_Dry"
    },
    {
      "x": -3,
      "y": 9,
      "z": 6,
      "name": "Cloth_Roof_Leather"
    },
    {
      "x": -2,
      "y": 3,
      "z": -6,
      "name": "Rock_Sandstone"
    },
    {
      "x": -2,
      "y": 4,
      "z": -6,
      "name": "Soil_Dirt_Dry"
    },
    {
      "x": -2,
      "y": 5,
      "z": -6,
      "name": "Soil_Dirt_Dry"
    },
    {
      "x": -2,
      "y": 9,
      "z": -6,
      "name": "Cloth_Roof_Leather",
      "rotation": 2
    },
    {
      "x": -2,
      "y": 2,
      "z": -5,
      "name": "Rock_Sandstone"
    },
    {
      "x": -2,
      "y": 3,
      "z": -5,
      "name": "Rock_Sandstone"
    },
    {
      "x": -2,
      "y": 4,
      "z": -5,
      "name": "Soil_Dirt_Dry"
    },
    {
      "x": -2,
      "y": 5,
      "z": -5,
      "name": "Rock_Sandstone_Cobble"
    },
    {
      "x": -2,
      "y": 6,
      "z": -5,
      "name": "Rock_Sandstone_Brick_Smooth"
    },
    {
      "x": -2,
      "y": 7,
      "z": -5,
      "name": "Rock_Sandstone_Brick_Smooth"
    },
    {
      "x": -2,
      "y": 8,
      "z": -5,
      "name": "Rock_Sandstone_Brick_Smooth"
    },
    {
      "x": -2,
      "y": 9,
      "z": -5,
      "name": "Rock_Sandstone_Brick_Smooth"
    },
    {
      "x": -2,
      "y": 10,
      "z": -5,
      "name": "Cloth_Roof_Leather",
      "rotation": 2
    },
    {
      "x": -2,
      "y": 1,
      "z": -4,
      "name": "Rock_Sandstone"
    },
    {
      "x": -2,
      "y": 2,
      "z": -4,
      "name": "Rock_Sandstone"
    },
    {
      "x": -2,
      "y": 3,
      "z": -4,
      "name": "Soil_Mud"
    },
    {
      "x": -2,
      "y": 4,
      "z": -4,
      "name": "Soil_Mud"
    },
    {
      "x": -2,
      "y": 9,
      "z": -4,
      "name": "Rock_Sandstone_Brick_Smooth"
    },
    {
      "x": -2,
      "y": 10,
      "z": -4,
      "name": "Rock_Sandstone_Brick_Smooth"
    },
    {
      "x": -2,
      "y": 11,
      "z": -4,
      "name": "Cloth_Roof_Leather_Flat"
    },
    {
      "x": -2,
      "y": 0,
      "z": -3,
      "name": "Rock_Sandstone"
    },
    {
      "x": -2,
      "y": 1,
      "z": -3,
      "name": "Rock_Sandstone"
    },
    {
      "x": -2,
      "y": 2,
      "z": -3,
      "name": "Rock_Sandstone"
    },
    {
      "x": -2,
      "y": 3,
      "z": -3,
      "name": "Soil_Mud"
    },
    {
      "x": -2,
      "y": 4,
      "z": -3,
      "name": "Soil_Mud"
    },
    {
      "x": -2,
      "y": 11,
      "z": -3,
      "name": "Cloth_Roof_Leather_Flat"
    },
    {
      "x": -2,
      "y": 0,
      "z": -2,
      "name": "Rock_Sandstone"
    },
    {
      "x": -2,
      "y": 1,
      "z": -2,
      "name": "Rock_Sandstone"
    },
    {
      "x": -2,
      "y": 2,
      "z": -2,
      "name": "Rock_Sandstone"
    },
    {
      "x": -2,
      "y": 3,
      "z": -2,
      "name": "Soil_Mud"
    },
    {
      "x": -2,
      "y": 4,
      "z": -2,
      "name": "Soil_Mud"
    },
    {
      "x": -2,
      "y": 11,
      "z": -2,
      "name": "Cloth_Roof_Leather_Flat"
    },
    {
      "x": -2,
      "y": 0,
      "z": -1,
      "name": "Rock_Sandstone"
    },
    {
      "x": -2,
      "y": 1,
      "z": -1,
      "name": "Rock_Sandstone"
    },
    {
      "x": -2,
      "y": 2,
      "z": -1,
      "name": "Rock_Sandstone"
    },
    {
      "x": -2,
      "y": 3,
      "z": -1,
      "name": "Soil_Mud"
    },
    {
      "x": -2,
      "y": 4,
      "z": -1,
      "name": "Soil_Mud"
    },
    {
      "x": -2,
      "y": 5,
      "z": -1,
      "name": "Plant_Crop_Mushroom_Block_Brown_Branch",
      "support": 15
    },
    {
      "x": -2,
      "y": 6,
      "z": -1,
      "name": "Plant_Crop_Mushroom_Block_Brown"
    },
    {
      "x": -2,
      "y": 11,
      "z": -1,
      "name": "Cloth_Roof_Leather_Flat"
    },
    {
      "x": -2,
      "y": 0,
      "z": 0,
      "name": "Rock_Sandstone"
    },
    {
      "x": -2,
      "y": 1,
      "z": 0,
      "name": "Rock_Sandstone"
    },
    {
      "x": -2,
      "y": 2,
      "z": 0,
      "name": "Rock_Sandstone"
    },
    {
      "x": -2,
      "y": 3,
      "z": 0,
      "name": "Soil_Mud"
    },
    {
      "x": -2,
      "y": 4,
      "z": 0,
      "name": "Soil_Mud"
    },
    {
      "x": -2,
      "y": 10,
      "z": 0,
      "name": "Rock_Sandstone_Brick_Smooth"
    },
    {
      "x": -2,
      "y": 11,
      "z": 0,
      "name": "Cloth_Roof_Leather_Flat"
    },
    {
      "x": -2,
      "y": 0,
      "z": 1,
      "name": "Rock_Sandstone"
    },
    {
      "x": -2,
      "y": 1,
      "z": 1,
      "name": "Rock_Sandstone"
    },
    {
      "x": -2,
      "y": 2,
      "z": 1,
      "name": "Rock_Sandstone"
    },
    {
      "x": -2,
      "y": 3,
      "z": 1,
      "name": "Soil_Mud"
    },
    {
      "x": -2,
      "y": 4,
      "z": 1,
      "name": "Soil_Mud"
    },
    {
      "x": -2,
      "y": 11,
      "z": 1,
      "name": "Cloth_Roof_Leather_Flat"
    },
    {
      "x": -2,
      "y": 0,
      "z": 2,
      "name": "Rock_Sandstone"
    },
    {
      "x": -2,
      "y": 1,
      "z": 2,
      "name": "Rock_Sandstone"
    },
    {
      "x": -2,
      "y": 2,
      "z": 2,
      "name": "Rock_Sandstone"
    },
    {
      "x": -2,
      "y": 3,
      "z": 2,
      "name": "Soil_Mud"
    },
    {
      "x": -2,
      "y": 4,
      "z": 2,
      "name": "Soil_Mud"
    },
    {
      "x": -2,
      "y": 11,
      "z": 2,
      "name": "Cloth_Roof_Leather_Flat"
    },
    {
      "x": -2,
      "y": 0,
      "z": 3,
      "name": "Rock_Sandstone"
    },
    {
      "x": -2,
      "y": 1,
      "z": 3,
      "name": "Rock_Sandstone"
    },
    {
      "x": -2,
      "y": 2,
      "z": 3,
      "name": "Rock_Sandstone"
    },
    {
      "x": -2,
      "y": 3,
      "z": 3,
      "name": "Soil_Mud"
    },
    {
      "x": -2,
      "y": 4,
      "z": 3,
      "name": "Soil_Mud"
    },
    {
      "x": -2,
      "y": 11,
      "z": 3,
      "name": "Cloth_Roof_Leather_Flat"
    },
    {
      "x": -2,
      "y": 1,
      "z": 4,
      "name": "Rock_Sandstone"
    },
    {
      "x": -2,
      "y": 2,
      "z": 4,
      "name": "Rock_Sandstone"
    },
    {
      "x": -2,
      "y": 3,
      "z": 4,
      "name": "Soil_Mud"
    },
    {
      "x": -2,
      "y": 4,
      "z": 4,
      "name": "Soil_Mud"
    },
    {
      "x": -2,
      "y": 9,
      "z": 4,
      "name": "Rock_Sandstone_Brick_Smooth"
    },
    {
      "x": -2,
      "y": 10,
      "z": 4,
      "name": "Rock_Sandstone_Brick_Smooth"
    },
    {
      "x": -2,
      "y": 11,
      "z": 4,
      "name": "Cloth_Roof_Leather_Flat"
    },
    {
      "x": -2,
      "y": 2,
      "z": 5,
      "name": "Rock_Sandstone"
    },
    {
      "x": -2,
      "y": 3,
      "z": 5,
      "name": "Rock_Sandstone"
    },
    {
      "x": -2,
      "y": 4,
      "z": 5,
      "name": "Soil_Dirt_Dry"
    },
    {
      "x": -2,
      "y": 5,
      "z": 5,
      "name": "Rock_Sandstone_Cobble"
    },
    {
      "x": -2,
      "y": 6,
      "z": 5,
      "name": "Rock_Sandstone_Brick_Smooth"
    },
    {
      "x": -2,
      "y": 7,
      "z": 5,
      "name": "Rock_Sandstone_Brick_Smooth"
    },
    {
      "x": -2,
      "y": 8,
      "z": 5,
      "name": "Rock_Sandstone_Brick_Smooth"
    },
    {
      "x": -2,
      "y": 9,
      "z": 5,
      "name": "Rock_Sandstone_Brick_Smooth"
    },
    {
      "x": -2,
      "y": 10,
      "z": 5,
      "name": "Cloth_Roof_Leather"
    },
    {
      "x": -2,
      "y": 3,
      "z": 6,
      "name": "Rock_Sandstone"
    },
    {
      "x": -2,
      "y": 4,
      "z": 6,
      "name": "Soil_Dirt_Dry"
    },
    {
      "x": -2,
      "y": 5,
      "z": 6,
      "name": "Soil_Dirt_Dry"
    },
    {
      "x": -2,
      "y": 9,
      "z": 6,
      "name": "Cloth_Roof_Leather"
    },
    {
      "x": -1,
      "y": 3,
      "z": -6,
      "name": "Rock_Sandstone"
    },
    {
      "x": -1,
      "y": 4,
      "z": -6,
      "name": "Soil_Dirt_Dry"
    },
    {
      "x": -1,
      "y": 5,
      "z": -6,
      "name": "Soil_Dirt_Dry"
    },
    {
      "x": -1,
      "y": 9,
      "z": -6,
      "name": "Cloth_Roof_Leather",
      "rotation": 2
    },
    {
      "x": -1,
      "y": 2,
      "z": -5,
      "name": "Rock_Sandstone"
    },
    {
      "x": -1,
      "y": 3,
      "z": -5,
      "name": "Rock_Sandstone"
    },
    {
      "x": -1,
      "y": 4,
      "z": -5,
      "name": "Soil_Dirt_Dry"
    },
    {
      "x": -1,
      "y": 5,
      "z": -5,
      "name": "Rock_Sandstone_Cobble"
    },
    {
      "x": -1,
      "y": 6,
      "z": -5,
      "name": "Rock_Sandstone_Cobble"
    },
    {
      "x": -1,
      "y": 7,
      "z": -5,
      "name": "Rock_Sandstone_Cobble"
    },
    {
      "x": -1,
      "y": 8,
      "z": -5,
      "name": "Rock_Sandstone_Cobble"
    },
    {
      "x": -1,
      "y": 9,
      "z": -5,
      "name": "Rock_Sandstone_Cobble"
    },
    {
      "x": -1,
      "y": 10,
      "z": -5,
      "name": "Cloth_Roof_Leather",
      "rotation": 2
    },
    {
      "x": -1,
      "y": 1,
      "z": -4,
      "name": "Rock_Sandstone"
    },
    {
      "x": -1,
      "y": 2,
      "z": -4,
      "name": "Rock_Sandstone"
    },
    {
      "x": -1,
      "y": 3,
      "z": -4,
      "name": "Soil_Mud"
    },
    {
      "x": -1,
      "y": 4,
      "z": -4,
      "name": "Soil_Mud"
    },
    {
      "x": -1,
      "y": 10,
      "z": -4,
      "name": "Rock_Sandstone_Brick_Smooth"
    },
    {
      "x": -1,
      "y": 11,
      "z": -4,
      "name": "Cloth_Roof_Leather_Flat"
    },
    {
      "x": -1,
      "y": 0,
      "z": -3,
      "name": "Rock_Sandstone"
    },
    {
      "x": -1,
      "y": 1,
      "z": -3,
      "name": "Rock_Sandstone"
    },
    {
      "x": -1,
      "y": 2,
      "z": -3,
      "name": "Rock_Sandstone"
    },
    {
      "x": -1,
      "y": 3,
      "z": -3,
      "name": "Soil_Mud"
    },
    {
      "x": -1,
      "y": 4,
      "z": -3,
      "name": "Soil_Mud"
    },
    {
      "x": -1,
      "y": 11,
      "z": -3,
      "name": "Cloth_Roof_Leather_Flat"
    },
    {
      "x": -1,
      "y": 0,
      "z": -2,
      "name": "Rock_Sandstone"
    },
    {
      "x": -1,
      "y": 1,
      "z": -2,
      "name": "Rock_Sandstone"
    },
    {
      "x": -1,
      "y": 2,
      "z": -2,
      "name": "Rock_Sandstone"
    },
    {
      "x": -1,
      "y": 3,
      "z": -2,
      "name": "Soil_Mud"
    },
    {
      "x": -1,
      "y": 4,
      "z": -2,
      "name": "Soil_Mud"
    },
    {
      "x": -1,
      "y": 11,
      "z": -2,
      "name": "Cloth_Roof_Leather_Flat"
    },
    {
      "x": -1,
      "y": 0,
      "z": -1,
      "name": "Rock_Sandstone"
    },
    {
      "x": -1,
      "y": 1,
      "z": -1,
      "name": "Rock_Sandstone"
    },
    {
      "x": -1,
      "y": 2,
      "z": -1,
      "name": "Rock_Sandstone"
    },
    {
      "x": -1,
      "y": 3,
      "z": -1,
      "name": "Soil_Mud"
    },
    {
      "x": -1,
      "y": 4,
      "z": -1,
      "name": "Soil_Mud"
    },
    {
      "x": -1,
      "y": 11,
      "z": -1,
      "name": "Cloth_Roof_Leather_Flat"
    },
    {
      "x": -1,
      "y": 0,
      "z": 0,
      "name": "Rock_Sandstone"
    },
    {
      "x": -1,
      "y": 1,
      "z": 0,
      "name": "Rock_Sandstone"
    },
    {
      "x": -1,
      "y": 2,
      "z": 0,
      "name": "Rock_Sandstone"
    },
    {
      "x": -1,
      "y": 3,
      "z": 0,
      "name": "Soil_Mud"
    },
    {
      "x": -1,
      "y": 4,
      "z": 0,
      "name": "Soil_Mud"
    },
    {
      "x": -1,
      "y": 10,
      "z": 0,
      "name": "Rock_Sandstone_Brick_Smooth"
    },
    {
      "x": -1,
      "y": 11,
      "z": 0,
      "name": "Cloth_Roof_Leather_Flat"
    },
    {
      "x": -1,
      "y": 0,
      "z": 1,
      "name": "Rock_Sandstone"
    },
    {
      "x": -1,
      "y": 1,
      "z": 1,
      "name": "Rock_Sandstone"
    },
    {
      "x": -1,
      "y": 2,
      "z": 1,
      "name": "Rock_Sandstone"
    },
    {
      "x": -1,
      "y": 3,
      "z": 1,
      "name": "Soil_Mud"
    },
    {
      "x": -1,
      "y": 4,
      "z": 1,
      "name": "Soil_Mud"
    },
    {
      "x": -1,
      "y": 11,
      "z": 1,
      "name": "Cloth_Roof_Leather_Flat"
    },
    {
      "x": -1,
      "y": 0,
      "z": 2,
      "name": "Rock_Sandstone"
    },
    {
      "x": -1,
      "y": 1,
      "z": 2,
      "name": "Rock_Sandstone"
    },
    {
      "x": -1,
      "y": 2,
      "z": 2,
      "name": "Rock_Sandstone"
    },
    {
      "x": -1,
      "y": 3,
      "z": 2,
      "name": "Soil_Mud"
    },
    {
      "x": -1,
      "y": 4,
      "z": 2,
      "name": "Soil_Mud"
    },
    {
      "x": -1,
      "y": 5,
      "z": 2,
      "name": "Plant_Crop_Mushroom_Block_Brown_Branch",
      "support": 15
    },
    {
      "x": -1,
      "y": 6,
      "z": 2,
      "name": "Plant_Crop_Mushroom_Block_Brown"
    },
    {
      "x": -1,
      "y": 11,
      "z": 2,
      "name": "Cloth_Roof_Leather_Flat"
    },
    {
      "x": -1,
      "y": 0,
      "z": 3,
      "name": "Rock_Sandstone"
    },
    {
      "x": -1,
      "y": 1,
      "z": 3,
      "name": "Rock_Sandstone"
    },
    {
      "x": -1,
      "y": 2,
      "z": 3,
      "name": "Rock_Sandstone"
    },
    {
      "x": -1,
      "y": 3,
      "z": 3,
      "name": "Soil_Mud"
    },
    {
      "x": -1,
      "y": 4,
      "z": 3,
      "name": "Soil_Mud"
    },
    {
      "x": -1,
      "y": 11,
      "z": 3,
      "name": "Cloth_Roof_Leather_Flat"
    },
    {
      "x": -1,
      "y": 1,
      "z": 4,
      "name": "Rock_Sandstone"
    },
    {
      "x": -1,
      "y": 2,
      "z": 4,
      "name": "Rock_Sandstone"
    },
    {
      "x": -1,
      "y": 3,
      "z": 4,
      "name": "Soil_Mud"
    },
    {
      "x": -1,
      "y": 4,
      "z": 4,
      "name": "Soil_Mud"
    },
    {
      "x": -1,
      "y": 10,
      "z": 4,
      "name": "Rock_Sandstone_Brick_Smooth"
    },
    {
      "x": -1,
      "y": 11,
      "z": 4,
      "name": "Cloth_Roof_Leather_Flat"
    },
    {
      "x": -1,
      "y": 2,
      "z": 5,
      "name": "Rock_Sandstone"
    },
    {
      "x": -1,
      "y": 3,
      "z": 5,
      "name": "Rock_Sandstone"
    },
    {
      "x": -1,
      "y": 4,
      "z": 5,
      "name": "Soil_Dirt_Dry"
    },
    {
      "x": -1,
      "y": 5,
      "z": 5,
      "name": "Rock_Sandstone_Cobble"
    },
    {
      "x": -1,
      "y": 6,
      "z": 5,
      "name": "Rock_Sandstone_Cobble"
    },
    {
      "x": -1,
      "y": 7,
      "z": 5,
      "name": "Rock_Sandstone_Cobble"
    },
    {
      "x": -1,
      "y": 8,
      "z": 5,
      "name": "Rock_Sandstone_Cobble"
    },
    {
      "x": -1,
      "y": 9,
      "z": 5,
      "name": "Rock_Sandstone_Cobble"
    },
    {
      "x": -1,
      "y": 10,
      "z": 5,
      "name": "Cloth_Roof_Leather"
    },
    {
      "x": -1,
      "y": 3,
      "z": 6,
      "name": "Rock_Sandstone"
    },
    {
      "x": -1,
      "y": 4,
      "z": 6,
      "name": "Soil_Dirt_Dry"
    },
    {
      "x": -1,
      "y": 5,
      "z": 6,
      "name": "Soil_Dirt_Dry"
    },
    {
      "x": -1,
      "y": 9,
      "z": 6,
      "name": "Cloth_Roof_Leather"
    },
    {
