{
  "version": 8,
  "blockIdVersion": 11,
  "anchorX": 0,
  "anchorY": 0,
  "anchorZ": 0,
  "blocks": [
    {
      "x": -13,
      "y": 3,
      "z": -6,
      "name": "Rock_Sandstone"
    },
    {
      "x": -13,
      "y": 4,
      "z": -6,
      "name": "Soil_Dirt_Dry"
    },
    {
      "x": -13,
      "y": 5,
      "z": -6,
      "name": "Soil_Mud_Dry"
    },
    {
      "x": -13,
      "y": 3,
      "z": -5,
      "name": "Rock_Sandstone"
    },
    {
      "x": -13,
      "y": 4,
      "z": -5,
      "name": "Soil_Dirt_Dry"
    },
    {
      "x": -13,
      "y": 5,
      "z": -5,
      "name": "Soil_Mud_Dry"
    },
    {
      "x": -13,
      "y": 13,
      "z": -5,
      "name": "Wood_Dry_Branch_Long",
      "support": 15,
      "rotation": 5
    },
    {
      "x": -13,
      "y": 14,
      "z": -5,
      "name": "Wood_Drywood_Planks_Half",
      "rotation": 7
    },
    {
      "x": -13,
      "y": 15,
      "z": -5,
      "name": "Wood_Drywood_Planks_Half",
      "rotation": 7
    },
    {
      "x": -13,
      "y": 3,
      "z": -4,
      "name": "Rock_Sandstone"
    },
    {
      "x": -13,
      "y": 4,
      "z": -4,
      "name": "Soil_Dirt_Dry"
    },
    {
      "x": -13,
      "y": 5,
      "z": -4,
      "name": "Soil_Mud_Dry"
    },
    {
      "x": -13,
      "y": 14,
      "z": -4,
      "name": "Wood_Drywood_Planks_Half",
      "rotation": 7
    },
    {
      "x": -13,
      "y": 15,
      "z": -4,
      "name": "Wood_Drywood_Planks_Half",
      "rotation": 7
    },
    {
      "x": -13,
      "y": 3,
      "z": -3,
      "name": "Rock_Sandstone"
    },
    {
      "x": -13,
      "y": 4,
      "z": -3,
      "name": "Soil_Dirt_Dry"
    },
    {
      "x": -13,
      "y": 5,
      "z": -3,
      "name": "Soil_Mud_Dry"
    },
    {
      "x": -13,
      "y": 14,
      "z": -3,
      "name": "Wood_Drywood_Planks_Half",
      "rotation": 7
    },
    {
      "x": -13,
      "y": 3,
      "z": -2,
      "name": "Rock_Sandstone"
    },
    {
      "x": -13,
      "y": 4,
      "z": -2,
      "name": "Soil_Dirt_Dry"
    },
    {
      "x": -13,
      "y": 5,
      "z": -2,
      "name": "Soil_Mud_Dry"
    },
    {
      "x": -13,
      "y": 14,
      "z": -2,
      "name": "Wood_Drywood_Planks_Half",
      "rotation": 7
    },
    {
      "x": -13,
      "y": 3,
      "z": -1,
      "name": "Rock_Sandstone"
    },
    {
      "x": -13,
      "y": 4,
      "z": -1,
      "name": "Soil_Dirt_Dry"
    },
    {
      "x": -13,
      "y": 5,
      "z": -1,
      "name": "Soil_Mud_Dry"
    },
    {
      "x": -13,
      "y": 14,
      "z": -1,
      "name": "Wood_Drywood_Planks_Half",
      "rotation": 7
    },
    {
      "x": -13,
      "y": 3,
      "z": 0,
      "name": "Rock_Sandstone"
    },
    {
      "x": -13,
      "y": 4,
      "z": 0,
      "name": "Soil_Dirt_Dry"
    },
    {
      "x": -13,
      "y": 5,
      "z": 0,
      "name": "Soil_Mud_Dry"
    },
    {
      "x": -13,
      "y": 14,
      "z": 0,
      "name": "Wood_Drywood_Planks_Half",
      "rotation": 7
    },
    {
      "x": -13,
      "y": 3,
      "z": 1,
      "name": "Rock_Sandstone"
    },
    {
      "x": -13,
      "y": 4,
      "z": 1,
      "name": "Soil_Dirt_Dry"
    },
    {
      "x": -13,
      "y": 5,
      "z": 1,
      "name": "Soil_Mud_Dry"
    },
    {
      "x": -13,
      "y": 14,
      "z": 1,
      "name": "Wood_Drywood_Planks_Half",
      "rotation": 7
    },
    {
      "x": -13,
      "y": 3,
      "z": 2,
      "name": "Rock_Sandstone"
    },
    {
      "x": -13,
      "y": 4,
      "z": 2,
      "name": "Soil_Dirt_Dry"
    },
    {
      "x": -13,
      "y": 5,
      "z": 2,
      "name": "Soil_Mud_Dry"
    },
    {
      "x": -13,
      "y": 14,
      "z": 2,
      "name": "Wood_Drywood_Planks_Half",
      "rotation": 7
    },
    {
      "x": -13,
      "y": 3,
      "z": 3,
      "name": "Rock_Sandstone"
    },
    {
      "x": -13,
      "y": 4,
      "z": 3,
      "name": "Soil_Dirt_Dry"
    },
    {
      "x": -13,
      "y": 5,
      "z": 3,
      "name": "Soil_Mud_Dry"
    },
    {
      "x": -13,
      "y": 14,
      "z": 3,
      "name": "Wood_Drywood_Planks_Half",
      "rotation": 7
    },
    {
      "x": -13,
      "y": 3,
      "z": 4,
      "name": "Rock_Sandstone"
    },
    {
      "x": -13,
      "y": 4,
      "z": 4,
      "name": "Soil_Dirt_Dry"
    },
    {
      "x": -13,
      "y": 5,
      "z": 4,
      "name": "Soil_Mud_Dry"
    },
    {
      "x": -13,
      "y": 14,
      "z": 4,
      "name": "Wood_Drywood_Planks_Half",
      "rotation": 7
    },
    {
      "x": -13,
      "y": 15,
      "z": 4,
      "name": "Wood_Drywood_Planks_Half",
      "rotation": 7
    },
    {
      "x": -13,
      "y": 3,
      "z": 5,
      "name": "Rock_Sandstone"
    },
    {
      "x": -13,
      "y": 4,
      "z": 5,
      "name": "Soil_Dirt_Dry"
    },
    {
      "x": -13,
      "y": 5,
      "z": 5,
      "name": "Soil_Mud_Dry"
    },
    {
      "x": -13,
      "y": 13,
      "z": 5,
      "name": "Wood_Dry_Branch_Long",
      "support": 15,
      "rotation": 5
    },
    {
      "x": -13,
      "y": 14,
      "z": 5,
      "name": "Wood_Drywood_Planks_Half",
      "rotation": 7
    },
    {
      "x": -13,
      "y": 15,
      "z": 5,
      "name": "Wood_Drywood_Planks_Half",
      "rotation": 7
    },
    {
      "x": -13,
      "y": 3,
      "z": 6,
      "name": "Rock_Sandstone"
    },
    {
      "x": -13,
      "y": 4,
      "z": 6,
      "name": "Soil_Dirt_Dry"
    },
    {
      "x": -13,
      "y": 5,
      "z": 6,
      "name": "Soil_Mud_Dry"
    },
    {
      "x": -12,
      "y": 3,
      "z": -6,
      "name": "Rock_Sandstone"
    },
    {
      "x": -12,
      "y": 4,
      "z": -6,
      "name": "Soil_Dirt_Dry"
    },
    {
      "x": -12,
      "y": 5,
      "z": -6,
      "name": "Soil_Mud_Dry"
    },
    {
      "x": -12,
      "y": 13,
      "z": -6,
      "name": "Wood_Dry_Branch_Long",
      "support": 15,
      "rotation": 4
    },
    {
      "x": -12,
      "y": 14,
      "z": -6,
      "name": "Wood_Drywood_Planks_Half",
      "rotation": 6
    },
    {
      "x": -12,
      "y": 15,
      "z": -6,
      "name": "Wood_Drywood_Planks_Half",
      "rotation": 6
    },
    {
      "x": -12,
      "y": 2,
      "z": -5,
      "name": "Rock_Sandstone"
    },
    {
      "x": -12,
      "y": 3,
      "z": -5,
      "name": "Rock_Sandstone"
    },
    {
      "x": -12,
      "y": 4,
      "z": -5,
      "name": "Soil_Dirt_Dry"
    },
    {
      "x": -12,
      "y": 5,
      "z": -5,
      "name": "Wood_Dry_Trunk",
      "support": 15
    },
    {
      "x": -12,
      "y": 6,
      "z": -5,
      "name": "Wood_Dry_Trunk",
      "support": 15
    },
    {
      "x": -12,
      "y": 7,
      "z": -5,
      "name": "Wood_Dry_Trunk",
      "support": 15
    },
    {
      "x": -12,
      "y": 8,
      "z": -5,
      "name": "Wood_Dry_Trunk",
      "support": 15
    },
    {
      "x": -12,
      "y": 9,
      "z": -5,
      "name": "Wood_Dry_Trunk",
      "support": 15
    },
    {
      "x": -12,
      "y": 10,
      "z": -5,
      "name": "Wood_Dry_Trunk",
      "support": 15
    },
    {
      "x": -12,
      "y": 11,
      "z": -5,
      "name": "Wood_Dry_Trunk",
      "support": 15
    },
    {
      "x": -12,
      "y": 12,
      "z": -5,
      "name": "Wood_Dry_Trunk",
      "support": 15
    },
    {
      "x": -12,
      "y": 13,
      "z": -5,
      "name": "Wood_Dry_Trunk",
      "support": 15
    },
    {
      "x": -12,
      "y": 14,
      "z": -5,
      "name": "Wood_Dry_Trunk",
      "support": 15
    },
    {
      "x": -12,
      "y": 15,
      "z": -5,
      "name": "Wood_Dry_Trunk",
      "support": 15
    },
    {
      "x": -12,
      "y": 16,
      "z": -5,
      "name": "Wood_Dry_Branch_Long",
      "support": 15
    },
    {
      "x": -12,
      "y": 17,
      "z": -5,
      "name": "Survival_Trap_Spike_Wood_Large"
    },
    {
      "x": -12,
      "y": 2,
      "z": -4,
      "name": "Rock_Sandstone"
    },
    {
      "x": -12,
      "y": 3,
      "z": -4,
      "name": "Rock_Sandstone"
    },
    {
      "x": -12,
      "y": 4,
      "z": -4,
      "name": "Soil_Dirt_Dry"
    },
    {
      "x": -12,
      "y": 5,
      "z": -4,
      "name": "Wood_Dry_Trunk",
      "support": 15
    },
    {
      "x": -12,
      "y": 6,
      "z": -4,
      "name": "Wood_Dry_Trunk",
      "support": 15
    },
    {
      "x": -12,
      "y": 7,
      "z": -4,
      "name": "Wood_Dry_Trunk",
      "support": 15
    },
    {
      "x": -12,
      "y": 8,
      "z": -4,
      "name": "Wood_Dry_Trunk",
      "support": 15
    },
    {
      "x": -12,
      "y": 9,
      "z": -4,
      "name": "Wood_Dry_Trunk",
      "support": 15
    },
    {
      "x": -12,
      "y": 10,
      "z": -4,
      "name": "Wood_Dry_Trunk",
      "support": 15
    },
    {
      "x": -12,
      "y": 11,
      "z": -4,
      "name": "Wood_Dry_Trunk",
      "support": 15
    },
    {
      "x": -12,
      "y": 12,
      "z": -4,
      "name": "Wood_Dry_Trunk",
      "support": 15
    },
    {
      "x": -12,
      "y": 13,
      "z": -4,
      "name": "Wood_Dry_Trunk",
      "support": 15
    },
    {
      "x": -12,
      "y": 14,
      "z": -4,
      "name": "Wood_Dry_Trunk",
      "support": 15
    },
    {
      "x": -12,
      "y": 15,
      "z": -4,
      "name": "Cloth_Roof_Leather"
    },
    {
      "x": -12,
      "y": 2,
      "z": -3,
      "name": "Rock_Sandstone"
    },
    {
      "x": -12,
      "y": 3,
      "z": -3,
      "name": "Rock_Sandstone"
    },
    {
      "x": -12,
      "y": 4,
      "z": -3,
      "name": "Soil_Dirt_Dry"
    },
    {
      "x": -12,
      "y": 5,
      "z": -3,
      "name": "Soil_Mud_Dry"
    },
    {
      "x": -12,
      "y": 13,
      "z": -3,
      "name": "Wood_Dry_Trunk",
      "support": 15,
      "rotation": 4
    },
    {
      "x": -12,
      "y": 14,
      "z": -3,
      "name": "Cloth_Roof_Leather",
      "rotation": 1
    },
    {
      "x": -12,
      "y": 2,
      "z": -2,
      "name": "Rock_Sandstone"
    },
    {
      "x": -12,
      "y": 3,
      "z": -2,
      "name": "Rock_Sandstone"
    },
    {
      "x": -12,
      "y": 4,
      "z": -2,
      "name": "Soil_Dirt_Dry"
    },
    {
      "x": -12,
      "y": 5,
      "z": -2,
      "name": "Soil_Mud_Dry"
    },
    {
      "x": -12,
      "y": 13,
      "z": -2,
      "name": "Wood_Dry_Trunk",
      "support": 15,
      "rotation": 4
    },
    {
      "x": -12,
      "y": 14,
      "z": -2,
      "name": "Cloth_Roof_Leather",
      "rotation": 1
    },
    {
      "x": -12,
      "y": 2,
      "z": -1,
      "name": "Rock_Sandstone"
    },
    {
      "x": -12,
      "y": 3,
      "z": -1,
      "name": "Rock_Sandstone"
    },
    {
      "x": -12,
      "y": 4,
      "z": -1,
      "name": "Soil_Dirt_Dry"
    },
    {
      "x": -12,
      "y": 5,
      "z": -1,
      "name": "Soil_Mud_Dry"
    },
    {
      "x": -12,
      "y": 13,
      "z": -1,
      "name": "Wood_Dry_Trunk",
      "support": 15,
      "rotation": 4
    },
    {
      "x": -12,
      "y": 14,
      "z": -1,
      "name": "Cloth_Roof_Leather",
      "rotation": 1
    },
    {
      "x": -12,
      "y": 2,
      "z": 0,
      "name": "Rock_Sandstone"
    },
    {
      "x": -12,
      "y": 3,
      "z": 0,
      "name": "Rock_Sandstone"
    },
    {
      "x": -12,
      "y": 4,
      "z": 0,
      "name": "Soil_Dirt_Dry"
    },
    {
      "x": -12,
      "y": 5,
      "z": 0,
      "name": "Soil_Mud_Dry"
    },
    {
      "x": -12,
      "y": 13,
      "z": 0,
      "name": "Wood_Dry_Trunk",
      "support": 15,
      "rotation": 4
    },
    {
      "x": -12,
      "y": 14,
      "z": 0,
      "name": "Cloth_Roof_Leather",
      "rotation": 1
    },
    {
      "x": -12,
      "y": 2,
      "z": 1,
      "name": "Rock_Sandstone"
    },
    {
      "x": -12,
      "y": 3,
      "z": 1,
      "name": "Rock_Sandstone"
    },
    {
      "x": -12,
      "y": 4,
      "z": 1,
      "name": "Soil_Dirt_Dry"
    },
    {
      "x": -12,
      "y": 5,
      "z": 1,
      "name": "Soil_Mud_Dry"
    },
    {
      "x": -12,
      "y": 13,
      "z": 1,
      "name": "Wood_Dry_Trunk",
      "support": 15,
      "rotation": 4
    },
    {
      "x": -12,
      "y": 14,
      "z": 1,
      "name": "Cloth_Roof_Leather",
      "rotation": 1
    },
    {
      "x": -12,
      "y": 2,
      "z": 2,
      "name": "Rock_Sandstone"
    },
    {
      "x": -12,
      "y": 3,
      "z": 2,
      "name": "Rock_Sandstone"
    },
    {
      "x": -12,
      "y": 4,
      "z": 2,
      "name": "Soil_Dirt_Dry"
    },
    {
      "x": -12,
      "y": 5,
      "z": 2,
      "name": "Soil_Mud_Dry"
    },
    {
      "x": -12,
      "y": 13,
      "z": 2,
      "name": "Wood_Dry_Trunk",
      "support": 15,
      "rotation": 4
    },
    {
      "x": -12,
      "y": 14,
      "z": 2,
      "name": "Cloth_Roof_Leather",
      "rotation": 1
    },
    {
      "x": -12,
      "y": 2,
      "z": 3,
      "name": "Rock_Sandstone"
    },
    {
      "x": -12,
      "y": 3,
      "z": 3,
      "name": "Rock_Sandstone"
    },
    {
      "x": -12,
      "y": 4,
      "z": 3,
      "name": "Soil_Dirt_Dry"
    },
    {
      "x": -12,
      "y": 5,
      "z": 3,
      "name": "Soil_Mud_Dry"
    },
    {
      "x": -12,
      "y": 13,
      "z": 3,
      "name": "Wood_Dry_Trunk",
      "support": 15,
      "rotation": 4
    },
    {
      "x": -12,
      "y": 14,
      "z": 3,
      "name": "Cloth_Roof_Leather",
      "rotation": 1
    },
    {
      "x": -12,
      "y": 2,
      "z": 4,
      "name": "Rock_Sandstone"
    },
    {
      "x": -12,
      "y": 3,
      "z": 4,
      "name": "Rock_Sandstone"
    },
    {
      "x": -12,
      "y": 4,
      "z": 4,
      "name": "Soil_Dirt_Dry"
    },
    {
      "x": -12,
      "y": 5,
      "z": 4,
      "name": "Wood_Dry_Trunk",
      "support": 15
    },
    {
      "x": -12,
      "y": 6,
      "z": 4,
      "name": "Wood_Dry_Trunk",
      "support": 15
    },
    {
      "x": -12,
      "y": 7,
      "z": 4,
      "name": "Wood_Dry_Trunk",
      "support": 15
    },
    {
      "x": -12,
      "y": 8,
      "z": 4,
      "name": "Wood_Dry_Trunk",
      "support": 15
    },
    {
      "x": -12,
      "y": 9,
      "z": 4,
      "name": "Wood_Dry_Trunk",
      "support": 15
    },
    {
      "x": -12,
      "y": 10,
      "z": 4,
      "name": "Wood_Dry_Trunk",
      "support": 15
    },
    {
      "x": -12,
      "y": 11,
      "z": 4,
      "name": "Wood_Dry_Trunk",
      "support": 15
    },
    {
      "x": -12,
      "y": 12,
      "z": 4,
      "name": "Wood_Dry_Trunk",
      "support": 15
    },
    {
      "x": -12,
      "y": 13,
      "z": 4,
      "name": "Wood_Dry_Trunk",
      "support": 15
    },
    {
      "x": -12,
      "y": 14,
      "z": 4,
      "name": "Wood_Dry_Trunk",
      "support": 15
    },
    {
      "x": -12,
      "y": 15,
      "z": 4,
      "name": "Cloth_Roof_Leather",
      "rotation": 2
    },
    {
      "x": -12,
      "y": 2,
      "z": 5,
      "name": "Rock_Sandstone"
    },
    {
      "x": -12,
      "y": 3,
      "z": 5,
      "name": "Rock_Sandstone"
    },
    {
      "x": -12,
      "y": 4,
      "z": 5,
      "name": "Soil_Dirt_Dry"
    },
    {
      "x": -12,
      "y": 5,
      "z": 5,
      "name": "Wood_Dry_Trunk",
      "support": 15
    },
    {
      "x": -12,
      "y": 6,
      "z": 5,
      "name": "Wood_Dry_Trunk",
      "support": 15
    },
    {
      "x": -12,
      "y": 7,
      "z": 5,
      "name": "Wood_Dry_Trunk",
      "support": 15
    },
    {
      "x": -12,
      "y": 8,
      "z": 5,
      "name": "Wood_Dry_Trunk",
      "support": 15
    },
    {
      "x": -12,
      "y": 9,
      "z": 5,
      "name": "Wood_Dry_Trunk",
      "support": 15
    },
    {
      "x": -12,
      "y": 10,
      "z": 5,
      "name": "Wood_Dry_Trunk",
      "support": 15
    },
    {
      "x": -12,
      "y": 11,
      "z": 5,
      "name": "Wood_Dry_Trunk",
      "support": 15
    },
    {
      "x": -12,
      "y": 12,
      "z": 5,
      "name": "Wood_Dry_Trunk",
      "support": 15
    },
    {
      "x": -12,
      "y": 13,
      "z": 5,
      "name": "Wood_Dry_Trunk",
      "support": 15
    },
    {
      "x": -12,
      "y": 14,
      "z": 5,
      "name": "Wood_Dry_Trunk",
      "support": 15
    },
    {
      "x": -12,
      "y": 15,
      "z": 5,
      "name": "Wood_Dry_Trunk",
      "support": 15
    },
    {
      "x": -12,
      "y": 16,
      "z": 5,
      "name": "Wood_Dry_Branch_Long",
      "support": 15
    },
    {
      "x": -12,
      "y": 17,
      "z": 5,
      "name": "Survival_Trap_Spike_Wood_Large"
    },
    {
      "x": -12,
      "y": 3,
      "z": 6,
      "name": "Rock_Sandstone"
    },
    {
      "x": -12,
      "y": 4,
      "z": 6,
      "name": "Soil_Dirt_Dry"
    },
    {
      "x": -12,
      "y": 5,
      "z": 6,
      "name": "Soil_Mud_Dry"
    },
    {
      "x": -12,
      "y": 13,
      "z": 6,
      "name": "Wood_Dry_Branch_Long",
      "support": 15,
      "rotation": 4
    },
    {
      "x": -12,
      "y": 14,
      "z": 6,
      "name": "Wood_Drywood_Planks_Half",
      "rotation": 4
    },
    {
      "x": -12,
      "y": 15,
      "z": 6,
      "name": "Wood_Drywood_Planks_Half",
      "rotation": 4
    },
    {
      "x": -11,
      "y": 3,
      "z": -6,
      "name": "Rock_Sandstone"
    },
    {
      "x": -11,
      "y": 4,
      "z": -6,
      "name": "Soil_Dirt_Dry"
    },
    {
      "x": -11,
      "y": 5,
      "z": -6,
      "name": "Soil_Mud_Dry"
    },
    {
      "x": -11,
      "y": 14,
      "z": -6,
      "name": "Wood_Drywood_Planks_Half",
      "rotation": 6
    },
    {
      "x": -11,
      "y": 15,
      "z": -6,
      "name": "Wood_Drywood_Planks_Half",
      "rotation": 6
    },
    {
      "x": -11,
      "y": 2,
      "z": -5,
      "name": "Rock_Sandstone"
    },
    {
      "x": -11,
      "y": 3,
      "z": -5,
      "name": "Rock_Sandstone"
    },
    {
      "x": -11,
      "y": 4,
      "z": -5,
      "name": "Soil_Dirt_Dry"
    },
    {
      "x": -11,
      "y": 5,
      "z": -5,
      "name": "Wood_Dry_Trunk",
      "support": 15
    },
    {
      "x": -11,
      "y": 6,
      "z": -5,
      "name": "Wood_Dry_Trunk",
      "support": 15
    },
    {
      "x": -11,
      "y": 7,
      "z": -5,
      "name": "Wood_Dry_Trunk",
      "support": 15
    },
    {
      "x": -11,
      "y": 8,
      "z": -5,
      "name": "Wood_Dry_Trunk",
      "support": 15
    },
    {
      "x": -11,
      "y": 9,
      "z": -5,
      "name": "Wood_Dry_Trunk",
      "support": 15
    },
    {
      "x": -11,
      "y": 10,
      "z": -5,
      "name": "Wood_Dry_Trunk",
      "support": 15
    },
    {
      "x": -11,
      "y": 11,
      "z": -5,
      "name": "Wood_Dry_Trunk",
      "support": 15
    },
    {
      "x": -11,
      "y": 12,
      "z": -5,
      "name": "Wood_Dry_Trunk",
      "support": 15
    },
    {
      "x": -11,
      "y": 13,
      "z": -5,
      "name": "Wood_Dry_Trunk",
      "support": 15
    },
    {
      "x": -11,
      "y": 14,
      "z": -5,
      "name": "Wood_Dry_Trunk",
      "support": 15
    },
    {
      "x": -11,
      "y": 15,
      "z": -5,
      "name": "Cloth_Roof_Leather",
      "rotation": 1
    },
    {
      "x": -11,
      "y": 1,
      "z": -4,
      "name": "Rock_Sandstone"
    },
    {
      "x": -11,
      "y": 2,
      "z": -4,
      "name": "Rock_Sandstone"
    },
    {
      "x": -11,
      "y": 3,
      "z": -4,
      "name": "Rock_Sandstone"
    },
    {
      "x": -11,
      "y": 4,
      "z": -4,
      "name": "Soil_Dirt_Dry"
    },
    {
      "x": -11,
      "y": 5,
      "z": -4,
      "name": "Wood_Dry_Trunk",
      "support": 15
    },
    {
      "x": -11,
      "y": 6,
      "z": -4,
      "name": "Wood_Dry_Trunk",
      "support": 15
    },
    {
      "x": -11,
      "y": 7,
      "z": -4,
      "name": "Wood_Dry_Trunk",
      "support": 15
    },
    {
      "x": -11,
      "y": 8,
      "z": -4,
      "name": "Wood_Dry_Trunk",
      "support": 15
    },
    {
      "x": -11,
      "y": 9,
      "z": -4,
      "name": "Wood_Dry_Trunk",
      "support": 15
    },
    {
      "x": -11,
      "y": 10,
      "z": -4,
      "name": "Wood_Dry_Trunk",
      "support": 15
    },
    {
      "x": -11,
      "y": 11,
      "z": -4,
      "name": "Wood_Dry_Trunk",
      "support": 15
    },
    {
      "x": -11,
      "y": 12,
      "z": -4,
      "name": "Wood_Dry_Trunk",
      "support": 15
    },
    {
      "x": -11,
      "y": 13,
      "z": -4,
      "name": "Wood_Dry_Trunk",
      "support": 15
    },
    {
      "x": -11,
      "y": 14,
      "z": -4,
      "name": "Wood_Dry_Trunk",
      "support": 15
    },
    {
      "x": -11,
      "y": 15,
      "z": -4,
      "name": "*Cloth_Roof_Leather_State_Definitions_Corner_Right",
      "rotation": 1
    },
    {
      "x": -11,
      "y": 1,
      "z": -3,
      "name": "Rock_Sandstone"
    },
    {
      "x": -11,
      "y": 2,
      "z": -3,
      "name": "Rock_Sandstone"
    },
    {
      "x": -11,
      "y": 3,
      "z": -3,
      "name": "Rock_Sandstone"
    },
    {
      "x": -11,
      "y": 4,
      "z": -3,
      "name": "Soil_Dirt_Dry"
    },
    {
      "x": -11,
      "y": 5,
      "z": -3,
      "name": "Soil_Mud_Dry"
    },
    {
      "x": -11,
      "y": 12,
      "z": -3,
      "name": "Wood_Dry_Branch_Long",
      "support": 15,
      "rotation": 4
    },
    {
      "x": -11,
      "y": 13,
      "z": -3,
      "name": "Cloth_Roof_Leather",
      "rotation": 1
    },
    {
      "x": -11,
      "y": 1,
      "z": -2,
      "name": "Rock_Sandstone"
    },
    {
      "x": -11,
      "y": 2,
      "z": -2,
      "name": "Rock_Sandstone"
    },
    {
      "x": -11,
      "y": 3,
      "z": -2,
      "name": "Rock_Sandstone"
    },
    {
      "x": -11,
      "y": 4,
      "z": -2,
      "name": "Soil_Dirt_Dry"
    },
    {
      "x": -11,
      "y": 5,
      "z": -2,
      "name": "Soil_Mud_Dry"
    },
    {
      "x": -11,
      "y": 12,
      "z": -2,
      "name": "Wood_Dry_Branch_Long",
      "support": 15,
      "rotation": 4
    },
    {
      "x": -11,
      "y": 13,
      "z": -2,
      "name": "Cloth_Roof_Leather",
      "rotation": 1
    },
    {
      "x": -11,
      "y": 1,
      "z": -1,
      "name": "Rock_Sandstone"
    },
    {
      "x": -11,
      "y": 2,
      "z": -1,
      "name": "Rock_Sandstone"
    },
    {
      "x": -11,
      "y": 3,
      "z": -1,
      "name": "Rock_Sandstone",
      "rotation": 1
    },
    {
      "x": -11,
      "y": 4,
      "z": -1,
      "name": "Rock_Sandstone",
      "rotation": 1
    },
    {
      "x": -11,
      "y": 5,
      "z": -1,
      "name": "Rock_Sandstone",
      "rotation": 1
    },
    {
      "x": -11,
      "y": 6,
      "z": -1,
      "name": "Rock_Sandstone_Red",
      "rotation": 1
    },
    {
      "x": -11,
      "y": 12,
      "z": -1,
      "name": "Wood_Dry_Branch_Long",
      "support": 15,
      "rotation": 4
    },
    {
      "x": -11,
      "y": 13,
      "z": -1,
      "name": "Cloth_Roof_Leather",
      "rotation": 1
    },
    {
      "x": -11,
      "y": 1,
      "z": 0,
      "name": "Rock_Sandstone"
    },
    {
      "x": -11,
      "y": 2,
      "z": 0,
      "name": "Rock_Sandstone"
    },
    {
      "x": -11,
      "y": 3,
      "z": 0,
      "name": "Rock_Sandstone",
      "rotation": 1
    },
    {
      "x": -11,
      "y": 4,
      "z": 0,
      "name": "Rock_Sandstone",
      "rotation": 1
    },
    {
      "x": -11,
      "y": 5,
      "z": 0,
      "name": "Rock_Sandstone",
      "rotation": 1
    },
    {
      "x": -11,
      "y": 6,
      "z": 0,
      "name": "Rock_Sandstone_Red",
      "rotation": 1
    },
    {
      "x": -11,
      "y": 7,
      "z": 0,
      "name": "Rock_Sandstone",
      "rotation": 1
    },
    {
      "x": -11,
      "y": 12,
      "z": 0,
      "name": "Wood_Dry_Branch_Long",
      "support": 15,
      "rotation": 4
    },
    {
      "x": -11,
      "y": 13,
      "z": 0,
      "name": "Cloth_Roof_Leather",
      "rotation": 1
    },
    {
      "x": -11,
      "y": 14,
      "z": 0,
      "name": "Plant_Leaves_Bramble",
      "support": 15
    },
    {
      "x": -11,
      "y": 1,
      "z": 1,
      "name": "Rock_Sandstone"
    },
    {
      "x": -11,
      "y": 2,
      "z": 1,
      "name": "Rock_Sandstone"
    },
    {
      "x": -11,
      "y": 3,
      "z": 1,
      "name": "Rock_Sandstone",
      "rotation": 1
    },
    {
      "x": -11,
      "y": 4,
      "z": 1,
      "name": "Rock_Sandstone",
      "rotation": 1
    },
    {
      "x": -11,
      "y": 5,
      "z": 1,
      "name": "Rock_Sandstone_Red",
      "rotation": 1
    },
    {
      "x": -11,
      "y": 6,
      "z": 1,
      "name": "Rock_Sandstone_Red",
      "rotation": 1
    },
    {
      "x": -11,
      "y": 7,
      "z": 1,
      "name": "Rock_Sandstone",
      "rotation": 1
    },
    {
      "x": -11,
      "y": 12,
      "z": 1,
      "name": "Wood_Dry_Branch_Long",
      "support": 15,
      "rotation": 4
    },
    {
      "x": -11,
      "y": 13,
      "z": 1,
      "name": "Cloth_Roof_Leather",
      "rotation": 1
    },
    {
      "x": -11,
      "y": 1,
      "z": 2,
      "name": "Rock_Sandstone"
    },
    {
      "x": -11,
      "y": 2,
      "z": 2,
      "name": "Rock_Sandstone"
    },
    {
      "x": -11,
      "y": 3,
      "z": 2,
      "name": "Rock_Sandstone",
      "rotation": 1
    },
    {
      "x": -11,
      "y": 4,
      "z": 2,
      "name": "Rock_Sandstone",
      "rotation": 1
    },
    {
      "x": -11,
      "y": 5,
      "z": 2,
      "name": "Rock_Sandstone_Red",
      "rotation": 1
    },
    {
      "x": -11,
      "y": 6,
      "z": 2,
      "name": "Rock_Sandstone_Red"
    },
    {
      "x": -11,
      "y": 12,
      "z": 2,
      "name": "Wood_Dry_Branch_Long",
      "support": 15,
      "rotation": 4
    },
    {
      "x": -11,
      "y": 13,
      "z": 2,
      "name": "Cloth_Roof_Leather",
      "rotation": 1
    },
    {
      "x": -11,
      "y": 1,
      "z": 3,
      "name": "Rock_Sandstone"
    },
    {
      "x": -11,
      "y": 2,
      "z": 3,
      "name": "Rock_Sandstone"
    },
    {
      "x": -11,
      "y": 3,
      "z": 3,
      "name": "Rock_Sandstone"
    },
    {
      "x": -11,
      "y": 4,
      "z": 3,
      "name": "Soil_Dirt_Dry"
    },
    {
      "x": -11,
      "y": 5,
      "z": 3,
      "name": "Soil_Mud_Dry"
    },
    {
      "x": -11,
      "y": 12,
      "z": 3,
      "name": "Wood_Dry_Branch_Long",
      "support": 15,
      "rotation": 4
    },
    {
      "x": -11,
      "y": 13,
      "z": 3,
      "name": "Cloth_Roof_Leather",
      "rotation": 1
    },
    {
      "x": -11,
      "y": 1,
      "z": 4,
      "name": "Rock_Sandstone"
    },
    {
      "x": -11,
      "y": 2,
      "z": 4,
      "name": "Rock_Sandstone"
    },
    {
      "x": -11,
      "y": 3,
      "z": 4,
      "name": "Rock_Sandstone"
    },
    {
      "x": -11,
      "y": 4,
      "z": 4,
      "name": "Soil_Dirt_Dry"
    },
    {
      "x": -11,
      "y": 5,
      "z": 4,
      "name": "Wood_Dry_Trunk",
      "support": 15
    },
    {
      "x": -11,
      "y": 6,
      "z": 4,
      "name": "Wood_Dry_Trunk",
      "support": 15
    },
    {
      "x": -11,
      "y": 7,
      "z": 4,
      "name": "Wood_Dry_Trunk",
      "support": 15
    },
    {
      "x": -11,
      "y": 8,
      "z": 4,
      "name": "Wood_Dry_Trunk",
      "support": 15
    },
    {
      "x": -11,
      "y": 9,
      "z": 4,
      "name": "Wood_Dry_Trunk",
      "support": 15
    },
    {
      "x": -11,
      "y": 10,
      "z": 4,
      "name": "Wood_Dry_Trunk",
      "support": 15
    },
    {
      "x": -11,
      "y": 11,
      "z": 4,
      "name": "Wood_Dry_Trunk",
      "support": 15
    },
    {
      "x": -11,
      "y": 12,
      "z": 4,
      "name": "Wood_Dry_Trunk",
      "support": 15
    },
    {
      "x": -11,
      "y": 13,
      "z": 4,
      "name": "Wood_Dry_Trunk",
      "support": 15
    },
    {
      "x": -11,
      "y": 14,
      "z": 4,
      "name": "Wood_Dry_Trunk",
      "support": 15
    },
    {
      "x": -11,
      "y": 15,
      "z": 4,
      "name": "*Cloth_Roof_Leather_State_Definitions_Corner_Left",
      "rotation": 1
    },
    {
      "x": -11,
      "y": 2,
      "z": 5,
      "name": "Rock_Sandstone"
    },
    {
      "x": -11,
      "y": 3,
      "z": 5,
      "name": "Rock_Sandstone"
    },
    {
      "x": -11,
      "y": 4,
      "z": 5,
      "name": "Soil_Dirt_Dry"
    },
    {
      "x": -11,
      "y": 5,
      "z": 5,
      "name": "Wood_Dry_Trunk",
      "support": 15
    },
    {
      "x": -11,
      "y": 6,
      "z": 5,
      "name": "Wood_Dry_Trunk",
      "support": 15
    },
    {
      "x": -11,
      "y": 7,
      "z": 5,
      "name": "Wood_Dry_Trunk",
      "support": 15
    },
    {
      "x": -11,
      "y": 8,
      "z": 5,
      "name": "Wood_Dry_Trunk",
      "support": 15
    },
    {
      "x": -11,
      "y": 9,
      "z": 5,
      "name": "Wood_Dry_Trunk",
      "support": 15
    },
    {
      "x": -11,
      "y": 10,
      "z": 5,
      "name": "Wood_Dry_Trunk",
      "support": 15
    },
    {
      "x": -11,
      "y": 11,
      "z": 5,
      "name": "Wood_Dry_Trunk",
      "support": 15
    },
    {
      "x": -11,
      "y": 12,
      "z": 5,
      "name": "Wood_Dry_Trunk",
      "support": 15
    },
    {
      "x": -11,
      "y": 13,
      "z": 5,
      "name": "Wood_Dry_Trunk",
      "support": 15
    },
    {
      "x": -11,
      "y": 14,
      "z": 5,
      "name": "Wood_Dry_Trunk",
      "support": 15
    },
    {
      "x": -11,
      "y": 15,
      "z": 5,
      "name": "Cloth_Roof_Leather",
      "rotation": 1
    },
    {
      "x": -11,
      "y": 3,
      "z": 6,
      "name": "Rock_Sandstone"
    },
    {
      "x": -11,
      "y": 4,
      "z": 6,
      "name": "Soil_Dirt_Dry"
    },
    {
      "x": -11,
      "y": 5,
      "z": 6,
      "name": "Soil_Mud_Dry"
    },
    {
      "x": -11,
      "y": 14,
      "z": 6,
      "name": "Wood_Drywood_Planks_Half",
      "rotation": 4
    },
    {
      "x": -11,
      "y": 15,
      "z": 6,
      "name": "Wood_Drywood_Planks_Half",
      "rotation": 4
    },
    {
      "x": -10,
      "y": 3,
      "z": -6,
      "name": "Rock_Sandstone"
    },
    {
      "x": -10,
      "y": 4,
      "z": -6,
      "name": "Soil_Dirt_Dry"
    },
    {
      "x": -10,
      "y": 5,
      "z": -6,
      "name": "Soil_Mud_Dry"
    },
    {
      "x": -10,
      "y": 14,
      "z": -6,
      "name": "Wood_Drywood_Planks_Half",
      "rotation": 6
    },
    {
      "x": -10,
      "y": 2,
      "z": -5,
      "name": "Rock_Sandstone"
    },
    {
      "x": -10,
      "y": 3,
      "z": -5,
      "name": "Rock_Sandstone"
    },
    {
      "x": -10,
      "y": 4,
      "z": -5,
      "name": "Soil_Dirt_Dry"
    },
    {
      "x": -10,
      "y": 5,
      "z": -5,
      "name": "Soil_Mud_Dry"
    },
    {
      "x": -10,
      "y": 13,
      "z": -5,
      "name": "Wood_Dry_Trunk",
      "support": 15,
      "rotation": 5
    },
    {
      "x": -10,
      "y": 14,
      "z": -5,
      "name": "Cloth_Roof_Leather"
    },
    {
      "x": -10,
      "y": 1,
      "z": -4,
      "name": "Rock_Sandstone"
    },
    {
      "x": -10,
      "y": 2,
      "z": -4,
      "name": "Rock_Sandstone"
    },
    {
      "x": -10,
      "y": 3,
      "z": -4,
      "name": "Rock_Sandstone"
    },
    {
      "x": -10,
      "y": 4,
      "z": -4,
      "name": "Soil_Dirt_Dry"
    },
    {
      "x": -10,
      "y": 5,
      "z": -4,
      "name": "Soil_Mud_Dry"
    },
    {
      "x": -10,
      "y": 12,
      "z": -4,
      "name": "Wood_Dry_Branch_Long",
      "support": 15,
      "rotation": 5
    },
    {
      "x": -10,
      "y": 13,
      "z": -4,
      "name": "Cloth_Roof_Leather"
    },
    {
      "x": -10,
      "y": 0,
      "z": -3,
      "name": "Rock_Sandstone"
    },
    {
      "x": -10,
      "y": 1,
      "z": -3,
      "name": "Rock_Sandstone"
    },
    {
      "x": -10,
      "y": 2,
      "z": -3,
      "name": "Rock_Sandstone"
    },
    {
      "x": -10,
      "y": 3,
      "z": -3,
      "name": "Rock_Sandstone"
    },
    {
      "x": -10,
      "y": 4,
      "z": -3,
      "name": "Soil_Dirt_Dry"
    },
    {
      "x": -10,
      "y": 5,
      "z": -3,
      "name": "Soil_Mud_Dry"
    },
    {
      "x": -10,
      "y": 0,
      "z": -2,
      "name": "Rock_Sandstone"
    },
    {
      "x": -10,
      "y": 1,
      "z": -2,
      "name": "Rock_Sandstone"
    },
    {
      "x": -10,
      "y": 2,
      "z": -2,
      "name": "Rock_Sandstone"
    },
    {
      "x": -10,
      "y": 3,
      "z": -2,
      "name": "Rock_Sandstone",
      "rotation": 1
    },
    {
      "x": -10,
      "y": 4,
      "z": -2,
      "name": "Rock_Sandstone",
      "rotation": 1
    },
    {
      "x": -10,
      "y": 5,
      "z": -2,
      "name": "Rock_Sandstone",
      "rotation": 1
    },
    {
      "x": -10,
      "y": 6,
      "z": -2,
      "name": "Rock_Sandstone"
    },
    {
      "x": -10,
      "y": 7,
      "z": -2,
      "name": "Deco_Bone_Skulls"
    },
    {
      "x": -10,
      "y": 12,
      "z": -2,
      "name": "Cloth_Roof_Leather",
      "rotation": 1
    },
    {
      "x": -10,
      "y": 0,
      "z": -1,
      "name": "Rock_Sandstone"
    },
    {
      "x": -10,
      "y": 1,
      "z": -1,
      "name": "Rock_Sandstone"
    },
    {
      "x": -10,
      "y": 2,
      "z": -1,
      "name": "Rock_Sandstone"
    },
    {
      "x": -10,
      "y": 3,
      "z": -1,
      "name": "Rock_Sandstone",
      "rotation": 1
    },
    {
      "x": -10,
      "y": 4,
      "z": -1,
      "name": "Rock_Sandstone",
      "rotation": 1
    },
    {
      "x": -10,
      "y": 5,
      "z": -1,
      "name": "Rock_Sandstone",
      "rotation": 1
    },
    {
      "x": -10,
      "y": 6,
      "z": -1,
      "name": "Rock_Sandstone",
      "rotation": 1
    },
    {
      "x": -10,
      "y": 7,
      "z": -1,
      "name": "Rock_Sandstone_Red",
      "rotation": 1
    },
    {
      "x": -10,
      "y": 8,
      "z": -1,
      "name": "Rock_Sandstone",
      "rotation": 1
    },
    {
      "x": -10,
      "y": 9,
      "z": -1,
      "name": "Rock_Sandstone_White",
      "rotation": 1
    },
    {
      "x": -10,
      "y": 12,
      "z": -1,
      "name": "Cloth_Roof_Leather",
      "rotation": 1
    },
    {
      "x": -10,
      "y": 0,
      "z": 0,
      "name": "Rock_Sandstone"
    },
    {
      "x": -10,
      "y": 1,
      "z": 0,
      "name": "Rock_Sandstone"
    },
    {
      "x": -10,
      "y": 2,
      "z": 0,
      "name": "Rock_Sandstone"
    },
    {
      "x": -10,
      "y": 3,
      "z": 0,
      "name": "Rock_Sandstone",
      "rotation": 1
    },
    {
      "x": -10,
      "y": 4,
      "z": 0,
      "name": "Rock_Sandstone",
      "rotation": 1
    },
    {
      "x": -10,
      "y": 5,
      "z": 0,
      "name": "Rock_Sandstone",
      "rotation": 1
    },
    {
      "x": -10,
      "y": 6,
      "z": 0,
      "name": "Rock_Sandstone",
      "rotation": 1
    },
    {
      "x": -10,
      "y": 7,
      "z": 0,
      "name": "Rock_Sandstone",
      "rotation": 1
    },
    {
      "x": -10,
      "y": 8,
      "z": 0,
      "name": "Rock_Sandstone",
      "rotation": 1
    },
    {
      "x": -10,
      "y": 9,
      "z": 0,
      "name": "Rock_Sandstone_White",
      "rotation": 1
    },
    {
      "x": -10,
      "y": 12,
      "z": 0,
      "name": "Cloth_Roof_Leather",
      "rotation": 1
    },
    {
      "x": -10,
      "y": 0,
      "z": 1,
      "name": "Rock_Sandstone"
    },
    {
      "x": -10,
      "y": 1,
      "z": 1,
      "name": "Rock_Sandstone"
    },
    {
      "x": -10,
      "y": 2,
      "z": 1,
      "name": "Rock_Sandstone"
    },
    {
      "x": -10,
      "y": 3,
      "z": 1,
      "name": "Rock_Sandstone",
      "rotation": 1
    },
    {
      "x": -10,
      "y": 4,
      "z": 1,
      "name": "Rock_Sandstone",
      "rotation": 1
    },
    {
      "x": -10,
      "y": 5,
      "z": 1,
      "name": "Rock_Sandstone",
      "rotation": 1
    },
    {
      "x": -10,
      "y": 6,
      "z": 1,
      "name": "Rock_Sandstone",
      "rotation": 1
    },
    {
      "x": -10,
      "y": 7,
      "z": 1,
      "name": "Rock_Sandstone",
      "rotation": 1
    },
    {
      "x": -10,
      "y": 8,
      "z": 1,
      "name": "Rock_Sandstone",
      "rotation": 1
    },
    {
      "x": -10,
      "y": 9,
      "z": 1,
      "name": "Rock_Sandstone_White",
      "rotation": 1
    },
    {
      "x": -10,
      "y": 12,
      "z": 1,
      "name": "Cloth_Roof_Leather",
      "rotation": 1
    },
    {
      "x": -10,
      "y": 0,
      "z": 2,
      "name": "Rock_Sandstone"
    },
    {
      "x": -10,
      "y": 1,
      "z": 2,
      "name": "Rock_Sandstone"
    },
    {
      "x": -10,
      "y": 2,
      "z": 2,
      "name": "Rock_Sandstone"
    },
    {
      "x": -10,
      "y": 3,
      "z": 2,
      "name": "Rock_Sandstone",
      "rotation": 1
    },
    {
      "x": -10,
      "y": 4,
      "z": 2,
      "name": "Rock_Sandstone",
      "rotation": 1
    },
    {
      "x": -10,
      "y": 5,
      "z": 2,
      "name": "Soil_Sand",
      "rotation": 1
    },
    {
      "x": -10,
      "y": 6,
      "z": 2,
      "name": "Rock_Sandstone_Red"
    },
    {
      "x": -10,
      "y": 7,
      "z": 2,
      "name": "Rock_Sandstone",
      "rotation": 1
    },
    {
      "x": -10,
      "y": 8,
      "z": 2,
      "name": "Rock_Sandstone"
    },
    {
      "x": -10,
      "y": 12,
      "z": 2,
      "name": "Cloth_Roof_Leather",
      "rotation": 1
    },
    {
      "x": -10,
      "y": 0,
      "z": 3,
      "name": "Rock_Sandstone"
    },
    {
      "x": -10,
      "y": 1,
      "z": 3,
      "name": "Rock_Sandstone"
    },
    {
      "x": -10,
      "y": 2,
      "z": 3,
      "name": "Rock_Sandstone"
    },
    {
      "x": -10,
      "y": 3,
      "z": 3,
      "name": "Rock_Sandstone",
      "rotation": 1
    },
    {
      "x": -10,
      "y": 4,
      "z": 3,
      "name": "Rock_Sandstone",
      "rotation": 1
    },
    {
      "x": -10,
      "y": 5,
      "z": 3,
      "name": "Soil_Sand",
      "rotation": 1
    },
    {
      "x": -10,
      "y": 1,
      "z": 4,
      "name": "Rock_Sandstone"
    },
    {
      "x": -10,
      "y": 2,
      "z": 4,
      "name": "Rock_Sandstone"
    },
    {
      "x": -10,
      "y": 3,
      "z": 4,
      "name": "Rock_Sandstone"
    },
    {
      "x": -10,
      "y": 4,
      "z": 4,
      "name": "Soil_Dirt_Dry"
    },
    {
      "x": -10,
      "y": 5,
      "z": 4,
      "name": "Soil_Mud_Dry"
    },
    {
      "x": -10,
      "y": 12,
      "z": 4,
      "name": "Wood_Dry_Branch_Long",
      "support": 15,
      "rotation": 5
    },
    {
      "x": -10,
      "y": 13,
      "z": 4,
      "name": "Cloth_Roof_Leather",
      "rotation": 2
    },
    {
      "x": -10,
      "y": 2,
      "z": 5,
      "name": "Rock_Sandstone"
    },
    {
      "x": -10,
      "y": 3,
      "z": 5,
      "name": "Rock_Sandstone"
    },
    {
      "x": -10,
      "y": 4,
      "z": 5,
      "name": "Soil_Dirt_Dry"
    },
    {
      "x": -10,
      "y": 5,
      "z": 5,
      "name": "Soil_Mud_Dry"
    },
    {
      "x": -10,
      "y": 13,
      "z": 5,
      "name": "Wood_Dry_Trunk",
      "support": 15,
      "rotation": 5
    },
    {
      "x": -10,
      "y": 14,
      "z": 5,
      "name": "Cloth_Roof_Leather",
      "rotation": 2
    },
    {
      "x": -10,
      "y": 3,
      "z": 6,
      "name": "Rock_Sandstone"
    },
    {
      "x": -10,
      "y": 4,
      "z": 6,
      "name": "Soil_Dirt_Dry"
    },
    {
      "x": -10,
      "y": 5,
      "z": 6,
      "name": "Soil_Mud_Dry"
    },
    {
      "x": -10,
      "y": 14,
      "z": 6,
      "name": "Wood_Drywood_Planks_Half",
      "rotation": 4
    },
    {
      "x": -9,
      "y": 3,
      "z": -6,
      "name": "Rock_Sandstone"
    },
    {
      "x": -9,
      "y": 4,
      "z": -6,
      "name": "Soil_Dirt_Dry"
    },
    {
      "x": -9,
      "y": 5,
      "z": -6,
      "name": "Soil_Mud_Dry"
    },
    {
      "x": -9,
      "y": 14,
      "z": -6,
      "name": "Wood_Drywood_Planks_Half",
      "rotation": 6
    },
    {
      "x": -9,
      "y": 2,
      "z": -5,
      "name": "Rock_Sandstone"
    },
    {
      "x": -9,
      "y": 3,
      "z": -5,
      "name": "Rock_Sandstone"
    },
    {
      "x": -9,
      "y": 4,
      "z": -5,
      "name": "Soil_Dirt_Dry"
    },
    {
      "x": -9,
      "y": 5,
      "z": -5,
      "name": "Soil_Mud_Dry"
    },
    {
      "x": -9,
      "y": 13,
      "z": -5,
      "name": "Wood_Dry_Trunk",
      "support": 15,
      "rotation": 5
    },
    {
      "x": -9,
      "y": 14,
      "z": -5,
      "name": "Cloth_Roof_Leather"
    },
    {
      "x": -9,
      "y": 1,
      "z": -4,
      "name": "Rock_Sandstone"
    },
    {
      "x": -9,
      "y": 2,
      "z": -4,
      "name": "Rock_Sandstone"
    },
    {
      "x": -9,
      "y": 3,
      "z": -4,
      "name": "Rock_Sandstone"
    },
    {
      "x": -9,
      "y": 4,
      "z": -4,
      "name": "Soil_Dirt_Dry"
    },
    {
      "x": -9,
      "y": 5,
      "z": -4,
      "name": "Soil_Mud_Dry"
    },
    {
      "x": -9,
      "y": 12,
      "z": -4,
      "name": "Wood_Dry_Branch_Long",
      "support": 15,
      "rotation": 5
    },
    {
      "x": -9,
      "y": 13,
      "z": -4,
      "name": "Cloth_Roof_Leather"
    },
    {
      "x": -9,
      "y": 0,
      "z": -3,
      "name": "Rock_Sandstone"
    },
    {
      "x": -9,
      "y": 1,
      "z": -3,
      "name": "Rock_Sandstone"
    },
    {
      "x": -9,
      "y": 2,
      "z": -3,
      "name": "Rock_Sandstone"
    },
    {
      "x": -9,
      "y": 3,
      "z": -3,
      "name": "Rock_Sandstone"
    },
    {
      "x": -9,
      "y": 4,
      "z": -3,
      "name": "Soil_Dirt_Dry"
    },
    {
      "x": -9,
      "y": 5,
      "z": -3,
      "name": "Soil_Mud_Dry"
    },
    {
      "x": -9,
      "y": 12,
      "z": -3,
      "name": "Cloth_Roof_Leather"
    },
    {
      "x": -9,
      "y": 0,
      "z": -2,
      "name": "Rock_Sandstone"
    },
    {
      "x": -9,
      "y": 1,
      "z": -2,
      "name": "Rock_Sandstone"
    },
    {
      "x": -9,
      "y": 2,
      "z": -2,
      "name": "Rock_Sandstone"
    },
    {
      "x": -9,
      "y": 3,
      "z": -2,
      "name": "Rock_Sandstone",
      "rotation": 1
    },
    {
      "x": -9,
      "y": 4,
      "z": -2,
      "name": "Rock_Sandstone",
      "rotation": 1
    },
    {
      "x": -9,
      "y": 5,
      "z": -2,
      "name": "Rock_Sandstone",
      "rotation": 1
    },
    {
      "x": -9,
      "y": 6,
      "z": -2,
      "name": "Rock_Sandstone"
    },
    {
      "x": -9,
      "y": 7,
      "z": -2,
      "name": "Rock_Sandstone_Red",
      "rotation": 1
    },
    {
      "x": -9,
      "y": 8,
      "z": -2,
      "name": "Rock_Sandstone",
      "rotation": 1
    },
    {
      "x": -9,
      "y": 9,
      "z": -2,
      "name": "Rock_Sandstone_White",
      "rotation": 1
    },
    {
      "x": -9,
      "y": 0,
      "z": -1,
      "name": "Rock_Sandstone"
    },
    {
      "x": -9,
      "y": 1,
      "z": -1,
      "name": "Rock_Sandstone"
    },
    {
      "x": -9,
      "y": 2,
      "z": -1,
      "name": "Rock_Sandstone"
    },
    {
      "x": -9,
      "y": 3,
      "z": -1,
      "name": "Rock_Sandstone",
      "rotation": 1
    },
    {
      "x": -9,
      "y": 4,
      "z": -1,
      "name": "Rock_Sandstone",
      "rotation": 1
    },
    {
      "x": -9,
      "y": 5,
      "z": -1,
      "name": "Rock_Sandstone",
      "rotation": 1
    },
    {
      "x": -9,
      "y": 6,
      "z": -1,
      "name": "Rock_Sandstone",
      "rotation": 1
    },
    {
      "x": -9,
      "y": 7,
      "z": -1,
      "name": "Rock_Sandstone",
      "rotation": 1
    },
    {
      "x": -9,
      "y": 8,
      "z": -1,
      "name": "Rock_Sandstone",
      "rotation": 1
    },
    {
      "x": -9,
      "y": 9,
      "z": -1,
      "name": "Empty"
    },
    {
      "x": -9,
      "y": 0,
      "z": 0,
      "name": "Rock_Sandstone"
    },
    {
      "x": -9,
      "y": 1,
      "z": 0,
      "name": "Rock_Sandstone"
    },
    {
      "x": -9,
      "y": 2,
      "z": 0,
      "name": "Rock_Sandstone"
    },
    {
      "x": -9,
      "y": 3,
      "z": 0,
      "name": "Rock_Sandstone",
      "rotation": 1
    },
    {
      "x": -9,
      "y": 4,
      "z": 0,
      "name": "Rock_Sandstone",
      "rotation": 1
    },
    {
      "x": -9,
      "y": 5,
      "z": 0,
      "name": "Rock_Sandstone",
      "rotation": 1
    },
    {
      "x": -9,
      "y": 6,
      "z": 0,
      "name": "Rock_Sandstone",
      "rotation": 1
    },
    {
      "x": -9,
      "y": 7,
      "z": 0,
      "name": "Rock_Sandstone",
      "rotation": 1
    },
    {
      "x": -9,
      "y": 8,
      "z": 0,
      "name": "Rock_Sandstone",
      "rotation": 1
    },
    {
      "x": -9,
      "y": 9,
      "z": 0,
      "name": "Empty"
    },
    {
      "x": -9,
      "y": 0,
      "z": 1,
      "name": "Rock_Sandstone"
    },
    {
      "x": -9,
      "y": 1,
      "z": 1,
      "name": "Rock_Sandstone"
    },
    {
      "x": -9,
      "y": 2,
      "z": 1,
      "name": "Rock_Sandstone"
    },
    {
      "x": -9,
      "y": 3,
      "z": 1,
      "name": "Rock_Sandstone",
      "rotation": 1
    },
    {
      "x": -9,
      "y": 4,
      "z": 1,
      "name": "Rock_Sandstone",
      "rotation": 1
    },
    {
      "x": -9,
      "y": 5,
      "z": 1,
      "name": "Rock_Sandstone",
      "rotation": 1
    },
    {
      "x": -9,
      "y": 6,
      "z": 1,
      "name": "Rock_Sandstone",
      "rotation": 1
    },
    {
      "x": -9,
      "y": 7,
      "z": 1,
      "name": "Rock_Sandstone",
      "rotation": 1
    },
    {
      "x": -9,
      "y": 8,
      "z": 1,
      "name": "Rock_Sandstone",
      "rotation": 1
    },
    {
      "x": -9,
      "y": 9,
      "z": 1,
      "name": "Empty"
    },
    {
      "x": -9,
      "y": 0,
      "z": 2,
      "name": "Rock_Sandstone"
    },
    {
      "x": -9,
      "y": 1,
      "z": 2,
      "name": "Rock_Sandstone"
    },
    {
      "x": -9,
      "y": 2,
      "z": 2,
      "name": "Rock_Sandstone"
    },
    {
      "x": -9,
      "y": 3,
      "z": 2,
      "name": "Rock_Sandstone",
      "rotation": 1
    },
    {
      "x": -9,
      "y": 4,
      "z": 2,
      "name": "Rock_Sandstone",
      "rotation": 1
    },
    {
      "x": -9,
      "y": 5,
      "z": 2,
      "name": "Rock_Sandstone",
      "rotation": 1
    },
    {
      "x": -9,
      "y": 6,
      "z": 2,
      "name": "Rock_Sandstone",
      "rotation": 1
    },
    {
      "x": -9,
      "y": 7,
      "z": 2,
      "name": "Rock_Sandstone",
      "rotation": 1
    },
    {
      "x": -9,
      "y": 8,
      "z": 2,
      "name": "Rock_Sandstone",
      "rotation": 1
    },
    {
      "x": -9,
      "y": 9,
      "z": 2,
      "name": "Rock_Sandstone_White",
      "rotation": 1
    },
    {
      "x": -9,
      "y": 0,
      "z": 3,
      "name": "Rock_Sandstone"
    },
    {
      "x": -9,
      "y": 1,
      "z": 3,
      "name": "Rock_Sandstone"
    },
    {
      "x": -9,
      "y": 2,
      "z": 3,
      "name": "Rock_Sandstone"
    },
    {
      "x": -9,
      "y": 3,
      "z": 3,
      "name": "Rock_Sandstone",
      "rotation": 1
    },
    {
      "x": -9,
      "y": 4,
      "z": 3,
      "name": "Rock_Sandstone",
      "rotation": 1
    },
    {
      "x": -9,
      "y": 5,
      "z": 3,
      "name": "Soil_Sand",
      "rotation": 1
    },
    {
      "x": -9,
      "y": 6,
      "z": 3,
      "name": "Rock_Sandstone_Red"
    },
    {
      "x": -9,
      "y": 7,
      "z": 3,
      "name": "Rock_Sandstone",
      "rotation": 1
    },
    {
      "x": -9,
      "y": 8,
      "z": 3,
      "name": "Rock_Sandstone",
      "rotation": 1
    },
    {
      "x": -9,
      "y": 9,
      "z": 3,
      "name": "Rock_Sandstone_White",
      "rotation": 1
    },
    {
      "x": -9,
      "y": 12,
      "z": 3,
      "name": "Cloth_Roof_Leather",
      "rotation": 2
    },
    {
      "x": -9,
      "y": 1,
      "z": 4,
      "name": "Rock_Sandstone"
    },
    {
      "x": -9,
      "y": 2,
      "z": 4,
      "name": "Rock_Sandstone"
    },
    {
      "x": -9,
      "y": 3,
      "z": 4,
      "name": "Rock_Sandstone",
      "rotation": 1
    },
    {
      "x": -9,
      "y": 4,
      "z": 4,
      "name": "Rock_Sandstone_Red",
      "rotation": 1
    },
    {
      "x": -9,
      "y": 5,
      "z": 4,
      "name": "Soil_Sand",
      "rotation": 1
    },
    {
      "x": -9,
      "y": 6,
      "z": 4,
      "name": "Rock_Sandstone_Red"
    },
    {
      "x": -9,
      "y": 7,
      "z": 4,
      "name": "Deco_Bone_Skulls"
    },
    {
      "x": -9,
      "y": 12,
      "z": 4,
      "name": "Wood_Dry_Branch_Long",
      "support": 15,
      "rotation": 5
    },
    {
      "x": -9,
      "y": 13,
      "z": 4,
      "name": "Cloth_Roof_Leather",
      "rotation": 2
    },
    {
      "x": -9,
      "y": 2,
      "z": 5,
      "name": "Rock_Sandstone"
    },
    {
      "x": -9,
      "y": 3,
      "z": 5,
      "name": "Rock_Sandstone"
    },
    {
      "x": -9,
      "y": 4,
      "z": 5,
      "name": "Soil_Dirt_Dry"
    },
    {
      "x": -9,
      "y": 5,
      "z": 5,
      "name": "Soil_Mud_Dry"
    },
    {
      "x": -9,
      "y": 13,
      "z": 5,
      "name": "Wood_Dry_Trunk",
      "support": 15,
      "rotation": 5
    },
    {
      "x": -9,
      "y": 14,
      "z": 5,
      "name": "Cloth_Roof_Leather",
      "rotation": 2
    },
    {
      "x": -9,
      "y": 3,
      "z": 6,
      "name": "Rock_Sandstone"
    },
    {
      "x": -9,
      "y": 4,
      "z": 6,
      "name": "Soil_Dirt_Dry"
    },
    {
      "x": -9,
      "y": 5,
      "z": 6,
      "name": "Soil_Mud_Dry"
    },
    {
      "x": -9,
      "y": 14,
      "z": 6,
      "name": "Wood_Drywood_Planks_Half",
      "rotation": 4
    },
    {
      "x": -8,
      "y": 3,
      "z": -6,
      "name": "Rock_Sandstone"
    },
    {
      "x": -8,
      "y": 4,
      "z": -6,
      "name": "Soil_Dirt_Dry"
    },
    {
      "x": -8,
      "y": 5,
      "z": -6,
      "name": "Soil_Mud_Dry"
    },
    {
      "x": -8,
      "y": 14,
      "z": -6,
      "name": "Wood_Drywood_Planks_Half",
      "rotation": 6
    },
    {
      "x": -8,
      "y": 2,
      "z": -5,
      "name": "Rock_Sandstone"
    },
    {
      "x": -8,
      "y": 3,
      "z": -5,
      "name": "Rock_Sandstone"
    },
    {
      "x": -8,
      "y": 4,
      "z": -5,
      "name": "Soil_Dirt_Dry"
    },
    {
      "x": -8,
      "y": 5,
      "z": -5,
      "name": "Soil_Mud_Dry"
    },
    {
      "x": -8,
      "y": 13,
      "z": -5,
      "name": "Wood_Dry_Trunk",
      "support": 15,
      "rotation": 5
    },
    {
      "x": -8,
      "y": 14,
      "z": -5,
      "name": "Cloth_Roof_Leather"
    },
    {
      "x": -8,
      "y": 1,
      "z": -4,
      "name": "Rock_Sandstone"
    },
    {
      "x": -8,
      "y": 2,
      "z": -4,
      "name": "Rock_Sandstone"
    },
    {
      "x": -8,
      "y": 3,
      "z": -4,
      "name": "Rock_Sandstone"
    },
    {
      "x": -8,
      "y": 4,
      "z": -4,
      "name": "Soil_Dirt_Dry"
    },
    {
      "x": -8,
      "y": 5,
      "z": -4,
      "name": "Soil_Mud_Dry"
    },
    {
      "x": -8,
      "y": 12,
      "z": -4,
      "name": "Wood_Dry_Branch_Long",
      "support": 15,
      "rotation": 5
    },
    {
      "x": -8,
      "y": 13,
      "z": -4,
      "name": "Cloth_Roof_Leather"
    },
    {
      "x": -8,
      "y": 0,
      "z": -3,
      "name": "Rock_Sandstone"
    },
    {
      "x": -8,
      "y": 1,
      "z": -3,
      "name": "Rock_Sandstone"
    },
    {
      "x": -8,
      "y": 2,
      "z": -3,
      "name": "Rock_Sandstone"
    },
    {
      "x": -8,
      "y": 3,
      "z": -3,
      "name": "Rock_Sandstone"
    },
    {
      "x": -8,
      "y": 4,
      "z": -3,
      "name": "Soil_Dirt_Dry"
    },
    {
      "x": -8,
      "y": 5,
      "z": -3,
      "name": "Soil_Mud_Dry"
    },
    {
      "x": -8,
      "y": 12,
      "z": -3,
      "name": "Cloth_Roof_Leather"
    },
    {
      "x": -8,
      "y": 0,
      "z": -2,
      "name": "Rock_Sandstone"
    },
    {
      "x": -8,
      "y": 1,
      "z": -2,
      "name": "Rock_Sandstone"
    },
    {
      "x": -8,
      "y": 2,
      "z": -2,
      "name": "Rock_Sandstone"
    },
    {
      "x": -8,
      "y": 3,
      "z": -2,
      "name": "Rock_Sandstone",
      "rotation": 1
    },
    {
      "x": -8,
      "y": 4,
      "z": -2,
      "name": "Rock_Sandstone",
      "rotation": 1
    },
    {
      "x": -8,
      "y": 5,
      "z": -2,
      "name": "Rock_Sandstone",
      "rotation": 1
    },
    {
      "x": -8,
      "y": 6,
      "z": -2,
      "name": "Rock_Sandstone"
    },
    {
      "x": -8,
      "y": 7,
      "z": -2,
      "name": "Rock_Sandstone_Red",
      "rotation": 1
    },
    {
      "x": -8,
      "y": 8,
      "z": -2,
      "name": "Rock_Sandstone",
      "rotation": 1
    },
    {
      "x": -8,
      "y": 9,
      "z": -2,
      "name": "Rock_Sandstone_White",
      "rotation": 1
    },
    {
      "x": -8,
      "y": 0,
      "z": -1,
      "name": "Rock_Sandstone"
    },
    {
      "x": -8,
      "y": 1,
      "z": -1,
      "name": "Rock_Sandstone"
    },
    {
      "x": -8,
      "y": 2,
      "z": -1,
      "name": "Rock_Sandstone"
    },
    {
      "x": -8,
      "y": 3,
      "z": -1,
      "name": "Rock_Sandstone",
      "rotation": 1
    },
    {
      "x": -8,
      "y": 4,
      "z": -1,
      "name": "Rock_Sandstone",
      "rotation": 1
    },
    {
      "x": -8,
      "y": 5,
      "z": -1,
      "name": "Rock_Sandstone",
      "rotation": 1
    },
    {
      "x": -8,
      "y": 6,
      "z": -1,
      "name": "Rock_Sandstone",
      "rotation": 1
    },
    {
      "x": -8,
      "y": 7,
      "z": -1,
      "name": "Rock_Sandstone",
      "rotation": 1
    },
    {
      "x": -8,
      "y": 8,
      "z": -1,
      "name": "Rock_Sandstone",
      "rotation": 1
    },
    {
      "x": -8,
      "y": 9,
      "z": -1,
      "name": "Empty"
    },
    {
      "x": -8,
      "y": 0,
      "z": 0,
      "name": "Rock_Sandstone"
    },
    {
      "x": -8,
      "y": 1,
      "z": 0,
      "name": "Rock_Sandstone"
    },
    {
      "x": -8,
      "y": 2,
      "z": 0,
      "name": "Rock_Sandstone"
    },
    {
      "x": -8,
      "y": 3,
      "z": 0,
      "name": "Rock_Sandstone",
      "rotation": 1
    },
    {
      "x": -8,
      "y": 4,
      "z": 0,
      "name": "Rock_Sandstone",
      "rotation": 1
    },
    {
      "x": -8,
      "y": 5,
      "z": 0,
      "name": "Rock_Sandstone",
      "rotation": 1
    },
    {
      "x": -8,
      "y": 6,
      "z": 0,
      "name": "Rock_Sandstone",
      "rotation": 1
    },
    {
      "x": -8,
      "y": 7,
      "z": 0,
      "name": "Rock_Sandstone"
    },
    {
      "x": -8,
      "y": 8,
      "z": 0,
      "name": "Empty"
    },
    {
      "x": -8,
      "y": 9,
      "z": 0,
      "name": "Empty"
    },
    {
      "x": -8,
      "y": 0,
      "z": 1,
      "name": "Rock_Sandstone"
    },
    {
      "x": -8,
      "y": 1,
      "z": 1,
      "name": "Rock_Sandstone"
    },
    {
      "x": -8,
      "y": 2,
      "z": 1,
      "name": "Rock_Sandstone"
    },
    {
      "x": -8,
      "y": 3,
      "z": 1,
      "name": "Rock_Sandstone",
      "rotation": 1
    },
    {
      "x": -8,
      "y": 4,
      "z": 1,
      "name": "Rock_Sandstone",
      "rotation": 1
    },
    {
      "x": -8,
      "y": 5,
      "z": 1,
      "name": "Rock_Sandstone",
      "rotation": 1
    },
    {
      "x": -8,
      "y": 6,
      "z": 1,
      "name": "Rock_Sandstone",
      "rotation": 1
    },
    {
      "x": -8,
      "y": 7,
      "z": 1,
      "name": "Rock_Sandstone",
      "rotation": 1
    },
    {
      "x": -8,
      "y": 8,
      "z": 1,
      "name": "Rock_Sandstone",
      "rotation": 1
    },
    {
      "x": -8,
      "y": 9,
      "z": 1,
      "name": "Empty"
    },
    {
      "x": -8,
      "y": 0,
      "z": 2,
      "name": "Rock_Sandstone"
    },
    {
      "x": -8,
      "y": 1,
      "z": 2,
      "name": "Rock_Sandstone"
    },
    {
      "x": -8,
      "y": 2,
      "z": 2,
      "name": "Rock_Sandstone"
    },
    {
      "x": -8,
      "y": 3,
      "z": 2,
      "name": "Rock_Sandstone",
      "rotation": 1
    },
    {
      "x": -8,
      "y": 4,
      "z": 2,
      "name": "Rock_Sandstone",
      "rotation": 1
    },
    {
      "x": -8,
      "y": 5,
      "z": 2,
      "name": "Rock_Sandstone",
      "rotation": 1
    },
    {
      "x": -8,
      "y": 6,
      "z": 2,
      "name": "Rock_Sandstone",
      "rotation": 1
    },
    {
      "x": -8,
      "y": 7,
      "z": 2,
      "name": "Rock_Sandstone",
      "rotation": 1
    },
    {
      "x": -8,
      "y": 8,
      "z": 2,
      "name": "Rock_Sandstone",
      "rotation": 1
    },
    {
      "x": -8,
      "y": 9,
      "z": 2,
      "name": "Empty"
    },
    {
      "x": -8,
      "y": 0,
      "z": 3,
      "name": "Rock_Sandstone"
    },
    {
      "x": -8,
      "y": 1,
      "z": 3,
      "name": "Rock_Sandstone"
    },
    {
      "x": -8,
      "y": 2,
      "z": 3,
      "name": "Rock_Sandstone"
    },
    {
      "x": -8,
      "y": 3,
      "z": 3,
      "name": "Rock_Sandstone",
      "rotation": 1
    },
    {
      "x": -8,
      "y": 4,
      "z": 3,
      "name": "Rock_Sandstone",
      "rotation": 1
    },
    {
      "x": -8,
      "y": 5,
      "z": 3,
      "name": "Rock_Sandstone",
      "rotation": 1
    },
    {
      "x": -8,
      "y": 6,
      "z": 3,
      "name": "Rock_Sandstone",
      "rotation": 1
    },
    {
      "x": -8,
      "y": 7,
      "z": 3,
      "name": "Rock_Sandstone",
      "rotation": 1
    },
    {
      "x": -8,
      "y": 8,
      "z": 3,
      "name": "Rock_Sandstone",
      "rotation": 1
    },
    {
      "x": -8,
      "y": 9,
      "z": 3,
      "name": "Rock_Sandstone_White",
      "rotation": 1
    },
    {
      "x": -8,
      "y": 12,
      "z": 3,
      "name": "Cloth_Roof_Leather",
      "rotation": 2
    },
    {
      "x": -8,
      "y": 1,
      "z": 4,
      "name": "Rock_Sandstone"
    },
    {
      "x": -8,
      "y": 2,
      "z": 4,
      "name": "Rock_Sandstone"
    },
    {
      "x": -8,
      "y": 3,
      "z": 4,
      "name": "Rock_Sandstone",
      "rotation": 1
    },
    {
      "x": -8,
      "y": 4,
      "z": 4,
      "name": "Rock_Sandstone_Red",
      "rotation": 1
    },
    {
      "x": -8,
      "y": 5,
      "z": 4,
      "name": "Rock_Sandstone_Red",
      "rotation": 1
    },
    {
      "x": -8,
      "y": 6,
      "z": 4,
      "name": "Rock_Sandstone_Red",
      "rotation": 1
    },
    {
      "x": -8,
      "y": 7,
      "z": 4,
      "name": "Rock_Sandstone",
      "rotation": 1
    },
    {
      "x": -8,
      "y": 12,
      "z": 4,
      "name": "Wood_Dry_Branch_Long",
      "support": 15,
      "rotation": 5
    },
    {
      "x": -8,
      "y": 13,
      "z": 4,
      "name": "Cloth_Roof_Leather",
      "rotation": 2
    },
    {
      "x": -8,
      "y": 2,
      "z": 5,
      "name": "Rock_Sandstone"
    },
    {
      "x": -8,
      "y": 3,
      "z": 5,
      "name": "Rock_Sandstone"
    },
    {
      "x": -8,
      "y": 4,
      "z": 5,
      "name": "Soil_Dirt_Dry"
    },
    {
      "x": -8,
      "y": 5,
      "z": 5,
      "name": "Soil_Mud_Dry"
    },
    {
      "x": -8,
      "y": 13,
      "z": 5,
      "name": "Wood_Dry_Trunk",
      "support": 15,
      "rotation": 5
    },
    {
      "x": -8,
      "y": 14,
      "z": 5,
      "name": "Cloth_Roof_Leather",
      "rotation": 2
    },
    {
      "x": -8,
      "y": 3,
      "z": 6,
      "name": "Rock_Sandstone"
    },
    {
      "x": -8,
      "y": 4,
      "z": 6,
      "name": "Soil_Dirt_Dry"
    },
    {
      "x": -8,
      "y": 5,
      "z": 6,
      "name": "Soil_Mud_Dry"
    },
    {
      "x": -8,
      "y": 14,
      "z": 6,
      "name": "Wood_Drywood_Planks_Half",
      "rotation": 4
    },
    {
      "x": -7,
      "y": 3,
      "z": -6,
      "name": "Rock_Sandstone"
    },
    {
      "x": -7,
      "y": 4,
      "z": -6,
      "name": "Soil_Dirt_Dry"
    },
    {
      "x": -7,
      "y": 5,
      "z": -6,
      "name": "Soil_Mud_Dry"
    },
    {
      "x": -7,
      "y": 14,
      "z": -6,
      "name": "Wood_Drywood_Planks_Half",
      "rotation": 6
    },
    {
      "x": -7,
      "y": 2,
      "z": -5,
      "name": "Rock_Sandstone"
    },
    {
      "x": -7,
      "y": 3,
      "z": -5,
      "name": "Rock_Sandstone"
    },
    {
      "x": -7,
      "y": 4,
      "z": -5,
      "name": "Soil_Dirt_Dry"
    },
    {
      "x": -7,
      "y": 5,
      "z": -5,
      "name": "Soil_Mud_Dry"
    },
    {
      "x": -7,
      "y": 13,
      "z": -5,
      "name": "Wood_Dry_Trunk",
      "support": 15,
      "rotation": 5
    },
    {
      "x": -7,
      "y": 14,
      "z": -5,
      "name": "Cloth_Roof_Leather"
    },
    {
      "x": -7,
      "y": 1,
      "z": -4,
      "name": "Rock_Sandstone"
    },
    {
      "x": -7,
      "y": 2,
      "z": -4,
      "name": "Rock_Sandstone"
    },
    {
      "x": -7,
      "y": 3,
      "z": -4,
      "name": "Rock_Sandstone"
    },
    {
      "x": -7,
      "y": 4,
      "z": -4,
      "name": "Soil_Dirt_Dry"
    },
    {
      "x": -7,
      "y": 5,
      "z": -4,
      "name": "Soil_Mud_Dry"
    },
    {
      "x": -7,
      "y": 12,
      "z": -4,
      "name": "Wood_Dry_Branch_Long",
      "support": 15,
      "rotation": 5
    },
    {
      "x": -7,
      "y": 13,
      "z": -4,
      "name": "Cloth_Roof_Leather"
    },
    {
      "x": -7,
      "y": 0,
      "z": -3,
      "name": "Rock_Sandstone"
    },
    {
      "x": -7,
      "y": 1,
      "z": -3,
      "name": "Rock_Sandstone"
    },
    {
      "x": -7,
      "y": 2,
      "z": -3,
      "name": "Rock_Sandstone"
    },
    {
      "x": -7,
      "y": 3,
      "z": -3,
      "name": "Rock_Sandstone"
    },
    {
      "x": -7,
      "y": 4,
      "z": -3,
      "name": "Soil_Dirt_Dry"
    },
    {
      "x": -7,
      "y": 5,
      "z": -3,
      "name": "Soil_Mud_Dry"
    },
    {
      "x": -7,
      "y": 12,
      "z": -3,
      "name": "Cloth_Roof_Leather"
    },
    {
      "x": -7,
      "y": 13,
      "z": -3,
      "name": "Plant_Leaves_Bramble",
      "support": 15
    },
    {
      "x": -7,
      "y": 0,
      "z": -2,
      "name": "Rock_Sandstone"
    },
    {
      "x": -7,
      "y": 1,
      "z": -2,
      "name": "Rock_Sandstone"
    },
    {
      "x": -7,
      "y": 2,
      "z": -2,
      "name": "Rock_Sandstone"
    },
    {
      "x": -7,
      "y": 3,
      "z": -2,
      "name": "Rock_Sandstone",
      "rotation": 1
    },
    {
      "x": -7,
      "y": 4,
      "z": -2,
      "name": "Rock_Sandstone",
      "rotation": 1
    },
    {
      "x": -7,
      "y": 5,
      "z": -2,
      "name": "Rock_Sandstone",
      "rotation": 1
    },
    {
      "x": -7,
      "y": 6,
      "z": -2,
      "name": "Rock_Sandstone",
      "rotation": 1
    },
    {
      "x": -7,
      "y": 7,
      "z": -2,
      "name": "Rock_Sandstone_Red",
      "rotation": 1
    },
    {
      "x": -7,
      "y": 8,
      "z": -2,
      "name": "Rock_Sandstone",
      "rotation": 1
    },
    {
      "x": -7,
      "y": 9,
      "z": -2,
      "name": "Rock_Sandstone_White",
      "rotation": 1
    },
    {
      "x": -7,
      "y": 0,
      "z": -1,
      "name": "Rock_Sandstone"
    },
    {
      "x": -7,
      "y": 1,
      "z": -1,
      "name": "Rock_Sandstone"
    },
    {
      "x": -7,
      "y": 2,
      "z": -1,
      "name": "Rock_Sandstone"
    },
    {
      "x": -7,
      "y": 3,
      "z": -1,
      "name": "Rock_Sandstone",
      "rotation": 1
    },
    {
      "x": -7,
      "y": 4,
      "z": -1,
      "name": "Rock_Sandstone",
      "rotation": 1
    },
    {
      "x": -7,
      "y": 5,
      "z": -1,
      "name": "Rock_Sandstone",
      "rotation": 1
    },
    {
      "x": -7,
      "y": 6,
      "z": -1,
      "name": "Rock_Sandstone",
      "rotation": 1
    },
    {
      "x": -7,
      "y": 7,
      "z": -1,
      "name": "Rock_Sandstone",
      "rotation": 1
    },
    {
      "x": -7,
      "y": 8,
      "z": -1,
      "name": "Rock_Sandstone",
      "rotation": 1
    },
    {
      "x": -7,
      "y": 9,
      "z": -1,
      "name": "Empty"
    },
    {
      "x": -7,
      "y": 0,
      "z": 0,
      "name": "Rock_Sandstone"
    },
    {
      "x": -7,
      "y": 1,
      "z": 0,
      "name": "Rock_Sandstone"
    },
    {
      "x": -7,
      "y": 2,
      "z": 0,
      "name": "Rock_Sandstone"
    },
    {
      "x": -7,
      "y": 3,
      "z": 0,
      "name": "Rock_Sandstone",
      "rotation": 1
    },
    {
      "x": -7,
      "y": 4,
      "z": 0,
      "name": "Rock_Sandstone",
      "rotation": 1
    },
    {
      "x": -7,
      "y": 5,
      "z": 0,
      "name": "Rock_Sandstone",
      "rotation": 1
    },
    {
      "x": -7,
      "y": 6,
      "z": 0,
      "name": "Rock_Sandstone",
      "rotation": 1
    },
    {
      "x": -7,
      "y": 7,
      "z": 0,
      "name": "Empty"
    },
    {
      "x": -7,
      "y": 8,
      "z": 0,
      "name": "Empty"
    },
    {
      "x": -7,
      "y": 9,
      "z": 0,
      "name": "Empty"
    },
    {
      "x": -7,
      "y": 0,
      "z": 1,
      "name": "Rock_Sandstone"
    },
    {
      "x": -7,
      "y": 1,
      "z": 1,
      "name": "Rock_Sandstone"
    },
    {
      "x": -7,
      "y": 2,
      "z": 1,
      "name": "Rock_Sandstone"
    },
    {
      "x": -7,
      "y": 3,
      "z": 1,
      "name": "Rock_Sandstone",
      "rotation": 1
    },
    {
      "x": -7,
      "y": 4,
      "z": 1,
      "name": "Rock_Sandstone",
      "rotation": 1
    },
    {
      "x": -7,
      "y": 5,
      "z": 1,
      "name": "Rock_Sandstone",
      "rotation": 1
    },
    {
      "x": -7,
      "y": 6,
      "z": 1,
      "name": "Rock_Sandstone",
      "rotation": 1
    },
    {
      "x": -7,
      "y": 7,
      "z": 1,
      "name": "Rock_Sandstone",
      "rotation": 1
    },
    {
      "x": -7,
      "y": 8,
      "z": 1,
      "name": "Rock_Sandstone",
      "rotation": 1
    },
    {
      "x": -7,
      "y": 9,
      "z": 1,
      "name": "Empty"
    },
    {
      "x": -7,
      "y": 0,
      "z": 2,
      "name": "Rock_Sandstone"
    },
    {
      "x": -7,
      "y": 1,
      "z": 2,
      "name": "Rock_Sandstone"
    },
    {
      "x": -7,
      "y": 2,
      "z": 2,
      "name": "Rock_Sandstone"
    },
    {
      "x": -7,
      "y": 3,
      "z": 2,
      "name": "Rock_Sandstone",
      "rotation": 1
    },
    {
      "x": -7,
      "y": 4,
      "z": 2,
      "name": "Rock_Sandstone",
      "rotation": 1
    },
    {
      "x": -7,
      "y": 5,
      "z": 2,
      "name": "Rock_Sandstone",
      "rotation": 1
    },
    {
      "x": -7,
      "y": 6,
      "z": 2,
      "name": "Rock_Sandstone",
      "rotation": 1
    },
    {
      "x": -7,
      "y": 7,
      "z": 2,
      "name": "Rock_Sandstone",
      "rotation": 1
    },
    {
      "x": -7,
      "y": 8,
      "z": 2,
      "name": "Rock_Sandstone",
      "rotation": 1
    },
    {
      "x": -7,
      "y": 9,
      "z": 2,
      "name": "Empty"
    },
    {
      "x": -7,
      "y": 0,
      "z": 3,
      "name": "Rock_Sandstone"
    },
    {
      "x": -7,
      "y": 1,
      "z": 3,
      "name": "Rock_Sandstone"
    },
    {
      "x": -7,
      "y": 2,
      "z": 3,
      "name": "Rock_Sandstone"
    },
    {
      "x": -7,
      "y": 3,
      "z": 3,
      "name": "Rock_Sandstone",
      "rotation": 1
    },
    {
      "x": -7,
      "y": 4,
      "z": 3,
      "name": "Rock_Sandstone",
      "rotation": 1
    },
    {
      "x": -7,
      "y": 5,
      "z": 3,
      "name": "Rock_Sandstone",
      "rotation": 1
    },
    {
      "x": -7,
      "y": 6,
      "z": 3,
      "name": "Rock_Sandstone",
      "rotation": 1
    },
    {
      "x": -7,
      "y": 7,
      "z": 3,
      "name": "Rock_Sandstone",
      "rotation": 1
    },
    {
      "x": -7,
      "y": 8,
      "z": 3,
      "name": "Rock_Sandstone",
      "rotation": 1
    },
    {
      "x": -7,
      "y": 9,
      "z": 3,
      "name": "Rock_Sandstone_White",
      "rotation": 1
    },
    {
      "x": -7,
      "y": 12,
      "z": 3,
      "name": "Cloth_Roof_Leather",
      "rotation": 2
    },
    {
      "x": -7,
      "y": 13,
      "z": 3,
      "name": "Plant_Leaves_Bramble",
      "support": 15
    },
    {
      "x": -7,
      "y": 1,
      "z": 4,
      "name": "Rock_Sandstone"
    },
    {
      "x": -7,
      "y": 2,
      "z": 4,
      "name": "Rock_Sandstone"
    },
    {
      "x": -7,
      "y": 3,
      "z": 4,
      "name": "Rock_Sandstone",
      "rotation": 1
    },
    {
      "x": -7,
      "y": 4,
      "z": 4,
      "name": "Rock_Sandstone",
      "rotation": 1
    },
    {
      "x": -7,
      "y": 5,
      "z": 4,
      "name": "Rock_Sandstone_Red",
      "rotation": 1
    },
    {
      "x": -7,
      "y": 6,
      "z": 4,
      "name": "Rock_Sandstone_Red",
      "rotation": 1
    },
    {
      "x": -7,
      "y": 7,
      "z": 4,
      "name": "Rock_Sandstone",
      "rotation": 1
    },
    {
      "x": -7,
      "y": 12,
      "z": 4,
      "name": "Wood_Dry_Branch_Long",
      "support": 15,
      "rotation": 5
    },
    {
      "x": -7,
      "y": 13,
      "z": 4,
      "name": "Cloth_Roof_Leather",
      "rotation": 2
    },
    {
      "x": -7,
      "y": 2,
      "z": 5,
      "name": "Rock_Sandstone"
    },
    {
      "x": -7,
      "y": 3,
      "z": 5,
      "name": "Rock_Sandstone"
    },
    {
      "x": -7,
      "y": 4,
      "z": 5,
      "name": "Soil_Dirt_Dry"
    },
    {
      "x": -7,
      "y": 5,
      "z": 5,
      "name": "Soil_Mud_Dry"
    },
    {
      "x": -7,
      "y": 13,
      "z": 5,
      "name": "Wood_Dry_Trunk",
      "support": 15,
      "rotation": 5
    },
    {
      "x": -7,
      "y": 14,
      "z": 5,
      "name": "Cloth_Roof_Leather",
      "rotation": 2
    },
    {
      "x": -7,
      "y": 3,
      "z": 6,
      "name": "Rock_Sandstone"
    },
    {
      "x": -7,
      "y": 4,
      "z": 6,
      "name": "Soil_Dirt_Dry"
    },
    {
      "x": -7,
      "y": 5,
      "z": 6,
      "name": "Soil_Mud_Dry"
    },
    {
      "x": -7,
      "y": 14,
      "z": 6,
      "name": "Wood_Drywood_Planks_Half",
      "rotation": 4
    },
    {
      "x": -6,
      "y": 3,
      "z": -6,
      "name": "Rock_Sandstone"
    },
    {
      "x": -6,
      "y": 4,
      "z": -6,
      "name": "Soil_Dirt_Dry"
    },
    {
      "x": -6,
      "y": 5,
      "z": -6,
      "name": "Soil_Mud_Dry"
    },
    {
      "x": -6,
      "y": 14,
      "z": -6,
      "name": "Wood_Drywood_Planks_Half",
      "rotation": 6
    },
    {
      "x": -6,
      "y": 2,
      "z": -5,
      "name": "Rock_Sandstone"
    },
    {
      "x": -6,
      "y": 3,
      "z": -5,
      "name": "Rock_Sandstone"
    },
    {
      "x": -6,
      "y": 4,
      "z": -5,
      "name": "Soil_Dirt_Dry"
    },
    {
      "x": -6,
      "y": 5,
      "z": -5,
      "name": "Soil_Mud_Dry"
    },
    {
      "x": -6,
      "y": 13,
      "z": -5,
      "name": "Wood_Dry_Trunk",
      "support": 15,
      "rotation": 5
    },
    {
      "x": -6,
      "y": 14,
      "z": -5,
      "name": "Cloth_Roof_Leather"
    },
    {
      "x": -6,
      "y": 1,
      "z": -4,
      "name": "Rock_Sandstone"
    },
    {
      "x": -6,
      "y": 2,
      "z": -4,
      "name": "Rock_Sandstone"
    },
    {
      "x": -6,
      "y": 3,
      "z": -4,
      "name": "Rock_Sandstone"
    },
    {
      "x": -6,
      "y": 4,
      "z": -4,
      "name": "Soil_Dirt_Dry"
    },
    {
      "x": -6,
      "y": 5,
      "z": -4,
      "name": "Soil_Mud_Dry"
    },
    {
      "x": -6,
      "y": 6,
      "z": -4,
      "name": "Deco_Bone_Pile"
    },
    {
      "x": -6,
      "y": 12,
      "z": -4,
      "name": "Wood_Dry_Branch_Long",
      "support": 15,
      "rotation": 5
    },
    {
      "x": -6,
      "y": 13,
      "z": -4,
      "name": "Cloth_Roof_Leather"
    },
    {
      "x": -6,
      "y": 0,
      "z": -3,
      "name": "Rock_Sandstone"
    },
    {
      "x": -6,
      "y": 1,
      "z": -3,
      "name": "Rock_Sandstone"
    },
    {
      "x": -6,
      "y": 2,
      "z": -3,
      "name": "Rock_Sandstone"
    },
    {
      "x": -6,
      "y": 3,
      "z": -3,
      "name": "Rock_Sandstone"
    },
    {
      "x": -6,
      "y": 4,
      "z": -3,
      "name": "Soil_Dirt_Dry"
    },
    {
      "x": -6,
      "y": 5,
      "z": -3,
      "name": "Soil_Mud_Dry"
    },
    {
      "x": -6,
      "y": 12,
      "z": -3,
      "name": "Cloth_Roof_Leather"
    },
    {
      "x": -6,
      "y": 0,
      "z": -2,
      "name": "Rock_Sandstone"
    },
    {
      "x": -6,
      "y": 1,
      "z": -2,
      "name": "Rock_Sandstone"
    },
    {
      "x": -6,
      "y": 2,
      "z": -2,
      "name": "Rock_Sandstone"
    },
    {
      "x": -6,
      "y": 3,
      "z": -2,
      "name": "Rock_Sandstone",
      "rotation": 1
    },
    {
      "x": -6,
      "y": 4,
      "z": -2,
      "name": "Rock_Sandstone",
      "rotation": 1
    },
    {
      "x": -6,
      "y": 5,
      "z": -2,
      "name": "Rock_Sandstone",
      "rotation": 1
    },
    {
      "x": -6,
      "y": 6,
      "z": -2,
      "name": "Rock_Sandstone"
    },
    {
      "x": -6,
      "y": 8,
      "z": -2,
      "name": "Rock_Sandstone"
    },
    {
      "x": -6,
      "y": 9,
      "z": -2,
      "name": "Rock_Sandstone_White"
    },
    {
      "x": -6,
      "y": 0,
      "z": -1,
      "name": "Rock_Sandstone"
    },
    {
      "x": -6,
      "y": 1,
      "z": -1,
      "name": "Rock_Sandstone"
    },
    {
      "x": -6,
      "y": 2,
      "z": -1,
      "name": "Rock_Sandstone"
    },
    {
      "x": -6,
      "y": 3,
      "z": -1,
      "name": "Rock_Sandstone",
      "rotation": 1
    },
    {
      "x": -6,
      "y": 4,
      "z": -1,
      "name": "Rock_Sandstone",
      "rotation": 1
    },
    {
      "x": -6,
      "y": 5,
      "z": -1,
      "name": "Rock_Sandstone",
      "rotation": 1
    },
    {
      "x": -6,
      "y": 6,
      "z": -1,
      "name": "Rock_Sandstone",
      "rotation": 1
    },
    {
      "x": -6,
      "y": 7,
      "z": -1,
      "name": "Rock_Sandstone_Red",
      "rotation": 1
    },
    {
      "x": -6,
      "y": 8,
      "z": -1,
      "name": "Rock_Sandstone",
      "rotation": 1
    },
    {
      "x": -6,
      "y": 9,
      "z": -1,
      "name": "Empty"
    },
    {
      "x": -6,
      "y": 0,
      "z": 0,
      "name": "Rock_Sandstone"
    },
    {
      "x": -6,
      "y": 1,
      "z": 0,
      "name": "Rock_Sandstone"
    },
    {
      "x": -6,
      "y": 2,
      "z": 0,
      "name": "Rock_Sandstone"
    },
    {
      "x": -6,
      "y": 3,
      "z": 0,
      "name": "Rock_Sandstone",
      "rotation": 1
    },
    {
      "x": -6,
      "y": 4,
      "z": 0,
      "name": "Rock_Sandstone",
      "rotation": 1
    },
    {
      "x": -6,
      "y": 5,
      "z": 0,
      "name": "Rock_Sandstone",
      "rotation": 1
    },
    {
      "x": -6,
      "y": 6,
      "z": 0,
      "name": "Rock_Sandstone",
      "rotation": 1
    },
    {
      "x": -6,
      "y": 7,
      "z": 0,
      "name": "Rock_Sandstone"
    },
    {
      "x": -6,
      "y": 8,
      "z": 0,
      "name": "Rock_Sandstone",
      "rotation": 1
    },
    {
      "x": -6,
      "y": 9,
      "z": 0,
      "name": "Empty"
    },
    {
      "x": -6,
      "y": 0,
      "z": 1,
      "name": "Rock_Sandstone"
    },
    {
      "x": -6,
      "y": 1,
      "z": 1,
      "name": "Rock_Sandstone"
    },
    {
      "x": -6,
      "y": 2,
      "z": 1,
      "name": "Rock_Sandstone"
    },
    {
      "x": -6,
      "y": 3,
      "z": 1,
      "name": "Rock_Sandstone",
      "rotation": 1
    },
    {
      "x": -6,
      "y": 4,
      "z": 1,
      "name": "Rock_Sandstone",
      "rotation": 1
    },
    {
      "x": -6,
      "y": 5,
      "z": 1,
      "name": "Rock_Sandstone",
      "rotation": 1
    },
    {
      "x": -6,
      "y": 6,
      "z": 1,
      "name": "Rock_Sandstone",
      "rotation": 1
    },
    {
      "x": -6,
      "y": 7,
      "z": 1,
      "name": "Rock_Sandstone",
      "rotation": 1
    },
    {
      "x": -6,
      "y": 8,
      "z": 1,
      "name": "Rock_Sandstone",
      "rotation": 1
    },
    {
      "x": -6,
      "y": 9,
      "z": 1,
      "name": "Empty"
    },
    {
      "x": -6,
      "y": 0,
      "z": 2,
      "name": "Rock_Sandstone"
    },
    {
      "x": -6,
      "y": 1,
      "z": 2,
      "name": "Rock_Sandstone"
    },
    {
      "x": -6,
      "y": 2,
      "z": 2,
      "name": "Rock_Sandstone"
    },
    {
      "x": -6,
      "y": 3,
      "z": 2,
      "name": "Rock_Sandstone",
      "rotation": 1
    },
    {
      "x": -6,
      "y": 4,
      "z": 2,
      "name": "Rock_Sandstone",
      "rotation": 1
    },
    {
      "x": -6,
      "y": 5,
      "z": 2,
      "name": "Rock_Sandstone",
      "rotation": 1
    },
    {
      "x": -6,
      "y": 6,
      "z": 2,
      "name": "Rock_Sandstone",
      "rotation": 1
    },
    {
      "x": -6,
      "y": 7,
      "z": 2,
      "name": "Rock_Sandstone",
      "rotation": 1
    },
    {
      "x": -6,
      "y": 8,
      "z": 2,
      "name": "Rock_Sandstone",
      "rotation": 1
    },
    {
      "x": -6,
      "y": 9,
      "z": 2,
      "name": "Empty"
    },
    {
      "x": -6,
      "y": 0,
      "z": 3,
      "name": "Rock_Sandstone"
    },
    {
      "x": -6,
      "y": 1,
      "z": 3,
      "name": "Rock_Sandstone"
    },
    {
      "x": -6,
      "y": 2,
      "z": 3,
      "name": "Rock_Sandstone"
    },
    {
      "x": -6,
      "y": 3,
      "z": 3,
      "name": "Rock_Sandstone",
      "rotation": 1
    },
    {
      "x": -6,
      "y": 4,
      "z": 3,
      "name": "Rock_Sandstone",
      "rotation": 1
    },
    {
      "x": -6,
      "y": 5,
      "z": 3,
      "name": "Rock_Sandstone",
      "rotation": 1
    },
    {
      "x": -6,
      "y": 6,
      "z": 3,
      "name": "Rock_Sandstone_Red",
      "rotation": 1
    },
    {
      "x": -6,
      "y": 7,
      "z": 3,
      "name": "Rock_Sandstone",
      "rotation": 1
    },
    {
      "x": -6,
      "y": 8,
      "z": 3,
      "name": "Rock_Sandstone",
      "rotation": 1
    },
    {
      "x": -6,
      "y": 9,
      "z": 3,
      "name": "Rock_Sandstone_White",
      "rotation": 1
    },
    {
      "x": -6,
      "y": 12,
      "z": 3,
      "name": "Cloth_Roof_Leather",
      "rotation": 2
    },
    {
      "x": -6,
      "y": 1,
      "z": 4,
      "name": "Rock_Sandstone"
    },
    {
      "x": -6,
      "y": 2,
      "z": 4,
      "name": "Rock_Sandstone"
    },
    {
      "x": -6,
      "y": 3,
      "z": 4,
      "name": "Rock_Sandstone"
    },
    {
      "x": -6,
      "y": 4,
      "z": 4,
      "name": "Soil_Dirt_Dry"
    },
    {
      "x": -6,
      "y": 5,
      "z": 4,
      "name": "Soil_Mud_Dry"
    },
    {
      "x": -6,
      "y": 12,
      "z": 4,
      "name": "Wood_Dry_Branch_Long",
      "support": 15,
      "rotation": 5
    },
    {
      "x": -6,
      "y": 13,
      "z": 4,
      "name": "Cloth_Roof_Leather",
      "rotation": 2
    },
    {
      "x": -6,
      "y": 2,
      "z": 5,
      "name": "Rock_Sandstone"
    },
    {
      "x": -6,
      "y": 3,
      "z": 5,
      "name": "Rock_Sandstone"
    },
    {
      "x": -6,
      "y": 4,
      "z": 5,
      "name": "Soil_Dirt_Dry"
    },
    {
      "x": -6,
      "y": 5,
      "z": 5,
      "name": "Soil_Mud_Dry"
    },
    {
      "x": -6,
      "y": 13,
      "z": 5,
      "name": "Wood_Dry_Trunk",
      "support": 15,
      "rotation": 5
    },
    {
      "x": -6,
      "y": 14,
      "z": 5,
      "name": "Cloth_Roof_Leather",
      "rotation": 2
    },
    {
      "x": -6,
      "y": 3,
      "z": 6,
      "name": "Rock_Sandstone"
    },
    {
      "x": -6,
      "y": 4,
      "z": 6,
      "name": "Soil_Dirt_Dry"
    },
    {
      "x": -6,
      "y": 5,
      "z": 6,
      "name": "Soil_Mud_Dry"
    },
    {
      "x": -6,
      "y": 14,
      "z": 6,
      "name": "Wood_Drywood_Planks_Half",
      "rotation": 4
    },
    {
      "x": -5,
      "y": 3,
      "z": -6,
      "name": "Rock_Sandstone"
    },
    {
      "x": -5,
      "y": 4,
      "z": -6,
      "name": "Soil_Dirt_Dry"
    },
    {
      "x": -5,
      "y": 5,
      "z": -6,
      "name": "Soil_Mud_Dry"
    },
    {
      "x": -5,
      "y": 14,
      "z": -6,
      "name": "Wood_Drywood_Planks_Half",
      "rotation": 6
    },
    {
      "x": -5,
      "y": 2,
      "z": -5,
      "name": "Rock_Sandstone"
    },
    {
      "x": -5,
      "y": 3,
      "z": -5,
      "name": "Rock_Sandstone"
    },
    {
      "x": -5,
      "y": 4,
      "z": -5,
      "name": "Soil_Dirt_Dry"
    },
    {
      "x": -5,
      "y": 5,
      "z": -5,
      "name": "Soil_Mud_Dry"
    },
    {
      "x": -5,
      "y": 13,
      "z": -5,
      "name": "Wood_Dry_Trunk",
      "support": 15,
      "rotation": 5
    },
    {
      "x": -5,
      "y": 14,
      "z": -5,
      "name": "Cloth_Roof_Leather"
    },
    {
      "x": -5,
      "y": 1,
      "z": -4,
      "name": "Rock_Sandstone"
    },
    {
      "x": -5,
      "y": 2,
      "z": -4,
      "name": "Rock_Sandstone"
    },
    {
      "x": -5,
      "y": 3,
      "z": -4,
      "name": "Rock_Sandstone"
    },
    {
      "x": -5,
      "y": 4,
      "z": -4,
      "name": "Soil_Dirt_Dry"
    },
    {
      "x": -5,
      "y": 5,
      "z": -4,
      "name": "Soil_Mud_Dry"
    },
    {
      "x": -5,
      "y": 12,
      "z": -4,
      "name": "Wood_Dry_Branch_Long",
      "support": 15,
      "rotation": 5
    },
    {
      "x": -5,
      "y": 13,
      "z": -4,
      "name": "Cloth_Roof_Leather"
    },
    {
      "x": -5,
      "y": 0,
      "z": -3,
      "name": "Rock_Sandstone"
    },
    {
      "x": -5,
      "y": 1,
      "z": -3,
      "name": "Rock_Sandstone"
    },
    {
      "x": -5,
      "y": 2,
      "z": -3,
      "name": "Rock_Sandstone"
    },
    {
      "x": -5,
      "y": 3,
      "z": -3,
      "name": "Rock_Sandstone",
      "rotation": 1
    },
    {
      "x": -5,
      "y": 4,
      "z": -3,
      "name": "Rock_Sandstone",
      "rotation": 1
    },
    {
      "x": -5,
      "y": 5,
      "z": -3,
      "name": "Rock_Sandstone",
      "rotation": 1
    },
    {
      "x": -5,
      "y": 6,
      "z": -3,
      "name": "Rock_Sandstone_Red",
      "rotation": 1
    },
    {
      "x": -5,
      "y": 8,
      "z": -3,
      "name": "Rock_Sandstone"
    },
    {
      "x": -5,
      "y": 9,
      "z": -3,
      "name": "Rock_Sandstone_White"
    },
    {
      "x": -5,
      "y": 12,
      "z": -3,
      "name": "Cloth_Roof_Leather"
    },
    {
      "x": -5,
      "y": 0,
      "z": -2,
      "name": "Rock_Sandstone"
    },
    {
      "x": -5,
      "y": 1,
      "z": -2,
      "name": "Rock_Sandstone"
    },
    {
      "x": -5,
      "y": 2,
      "z": -2,
      "name": "Rock_Sandstone"
    },
    {
      "x": -5,
      "y": 3,
      "z": -2,
      "name": "Rock_Sandstone",
      "rotation": 1
    },
    {
      "x": -5,
      "y": 4,
      "z": -2,
      "name": "Rock_Sandstone",
      "rotation": 1
    },
    {
      "x": -5,
      "y": 5,
      "z": -2,
      "name": "Rock_Sandstone",
      "rotation": 1
    },
    {
      "x": -5,
      "y": 6,
      "z": -2,
      "name": "Rock_Sandstone_Red",
      "rotation": 1
    },
    {
      "x": -5,
      "y": 7,
      "z": -2,
      "name": "Rock_Sandstone",
      "rotation": 1
    },
    {
      "x": -5,
      "y": 8,
      "z": -2,
      "name": "Rock_Sandstone"
    },
    {
      "x": -5,
      "y": 9,
      "z": -2,
      "name": "Empty"
    },
    {
      "x": -5,
      "y": 0,
      "z": -1,
      "name": "Rock_Sandstone"
    },
    {
      "x": -5,
      "y": 1,
      "z": -1,
      "name": "Rock_Sandstone"
    },
    {
      "x": -5,
      "y": 2,
      "z": -1,
      "name": "Rock_Sandstone"
    },
    {
      "x": -5,
      "y": 3,
      "z": -1,
      "name": "Rock_Sandstone",
      "rotation": 1
    },
    {
      "x": -5,
      "y": 4,
      "z": -1,
      "name": "Rock_Sandstone",
      "rotation": 1
    },
    {
      "x": -5,
      "y": 5,
      "z": -1,
      "name": "Rock_Sandstone_Red",
      "rotation": 1
    },
    {
      "x": -5,
      "y": 6,
      "z": -1,
      "name": "Rock_Sandstone_Red",
      "rotation": 1
    },
    {
      "x": -5,
      "y": 7,
      "z": -1,
      "name": "Rock_Sandstone",
      "rotation": 1
    },
    {
      "x": -5,
      "y": 8,
      "z": -1,
      "name": "Rock_Sandstone"
    },
    {
      "x": -5,
      "y": 9,
      "z": -1,
      "name": "Empty"
    },
    {
      "x": -5,
      "y": 0,
      "z": 0,
      "name": "Rock_Sandstone"
    },
    {
      "x": -5,
      "y": 1,
      "z": 0,
      "name": "Rock_Sandstone"
    },
    {
      "x": -5,
      "y": 2,
      "z": 0,
      "name": "Rock_Sandstone"
    },
    {
      "x": -5,
      "y": 3,
      "z": 0,
      "name": "Rock_Sandstone",
      "rotation": 1
    },
    {
      "x": -5,
      "y": 4,
      "z": 0,
      "name": "Rock_Sandstone",
      "rotation": 1
    },
    {
      "x": -5,
      "y": 5,
      "z": 0,
      "name": "Rock_Sandstone_Red",
      "rotation": 1
    },
    {
      "x": -5,
      "y": 6,
      "z": 0,
      "name": "Soil_Sand",
      "rotation": 1
    },
    {
      "x": -5,
      "y": 7,
      "z": 0,
      "name": "Rock_Sandstone_Red",
      "rotation": 1
    },
    {
      "x": -5,
      "y": 8,
      "z": 0,
      "name": "Rock_Sandstone",
      "rotation": 1
    },
    {
      "x": -5,
      "y": 9,
      "z": 0,
      "name": "Empty"
    },
    {
      "x": -5,
      "y": 0,
      "z": 1,
      "name": "Rock_Sandstone"
    },
    {
      "x": -5,
      "y": 1,
      "z": 1,
      "name": "Rock_Sandstone"
    },
    {
      "x": -5,
      "y": 2,
      "z": 1,
      "name": "Rock_Sandstone"
    },
    {
      "x": -5,
      "y": 3,
      "z": 1,
      "name": "Rock_Sandstone",
      "rotation": 1
    },
    {
      "x": -5,
      "y": 4,
      "z": 1,
      "name": "Rock_Sandstone",
      "rotation": 1
    },
    {
      "x": -5,
      "y": 5,
      "z": 1,
      "name": "Rock_Sandstone",
      "rotation": 1
    },
    {
      "x": -5,
      "y": 6,
      "z": 1,
      "name": "Rock_Sandstone_Red",
      "rotation": 1
    },
    {
      "x": -5,
      "y": 7,
      "z": 1,
      "name": "Rock_Sandstone_Red",
      "rotation": 1
    },
    {
      "x": -5,
      "y": 8,
      "z": 1,
      "name": "Rock_Sandstone",
      "rotation": 1
    },
    {
      "x": -5,
      "y": 9,
      "z": 1,
      "name": "Empty"
    },
    {
      "x": -5,
      "y": 0,
      "z": 2,
      "name": "Rock_Sandstone"
    },
    {
      "x": -5,
      "y": 1,
      "z": 2,
      "name": "Rock_Sandstone"
    },
    {
      "x": -5,
      "y": 2,
      "z": 2,
      "name": "Rock_Sandstone"
    },
    {
      "x": -5,
      "y": 3,
      "z": 2,
      "name": "Rock_Sandstone",
      "rotation": 1
    },
    {
      "x": -5,
      "y": 4,
      "z": 2,
      "name": "Rock_Sandstone",
      "rotation": 1
    },
    {
      "x": -5,
      "y": 5,
      "z": 2,
      "name": "Rock_Sandstone",
      "rotation": 1
    },
    {
      "x": -5,
      "y": 6,
      "z": 2,
      "name": "Rock_Sandstone_Red",
      "rotation": 1
    },
    {
      "x": -5,
      "y": 7,
      "z": 2,
      "name": "Rock_Sandstone_Red",
      "rotation": 1
    },
    {
      "x": -5,
      "y": 8,
      "z": 2,
      "name": "Rock_Sandstone",
      "rotation": 1
    },
    {
      "x": -5,
      "y": 9,
      "z": 2,
      "name": "Rock_Sandstone_White",
      "rotation": 1
    },
    {
      "x": -5,
      "y": 0,
      "z": 3,
      "name": "Rock_Sandstone"
    },
    {
      "x": -5,
      "y": 1,
      "z": 3,
      "name": "Rock_Sandstone"
    },
    {
      "x": -5,
      "y": 2,
      "z": 3,
      "name": "Rock_Sandstone"
    },
    {
      "x": -5,
      "y": 3,
      "z": 3,
      "name": "Rock_Sandstone",
      "rotation": 1
    },
    {
      "x": -5,
      "y": 4,
      "z": 3,
      "name": "Rock_Sandstone",
      "rotation": 1
    },
    {
      "x": -5,
      "y": 5,
      "z": 3,
      "name": "Rock_Sandstone",
      "rotation": 1
    },
    {
      "x": -5,
      "y": 6,
      "z": 3,
      "name": "Rock_Sandstone_Red",
      "rotation": 1
    },
    {
      "x": -5,
      "y": 12,
      "z": 3,
      "name": "Cloth_Roof_Leather",
      "rotation": 2
    },
    {
      "x": -5,
      "y": 1,
      "z": 4,
      "name": "Rock_Sandstone"
    },
    {
      "x": -5,
      "y": 2,
      "z": 4,
      "name": "Rock_Sandstone"
    },
    {
      "x": -5,
      "y": 3,
      "z": 4,
      "name": "Rock_Sandstone"
    },
    {
      "x": -5,
      "y": 4,
      "z": 4,
      "name": "Soil_Dirt_Dry"
    },
    {
      "x": -5,
      "y": 5,
      "z": 4,
      "name": "Soil_Mud_Dry"
    },
    {
      "x": -5,
      "y": 12,
      "z": 4,
      "name": "Wood_Dry_Branch_Long",
      "support": 15,
      "rotation": 5
    },
    {
      "x": -5,
      "y": 13,
      "z": 4,
      "name": "Cloth_Roof_Leather",
      "rotation": 2
    },
    {
      "x": -5,
      "y": 2,
      "z": 5,
      "name": "Rock_Sandstone"
    },
    {
      "x": -5,
      "y": 3,
      "z": 5,
      "name": "Rock_Sandstone"
    },
    {
      "x": -5,
      "y": 4,
      "z": 5,
      "name": "Soil_Dirt_Dry"
    },
    {
      "x": -5,
      "y": 5,
      "z": 5,
      "name": "Soil_Mud_Dry"
    },
    {
      "x": -5,
      "y": 13,
      "z": 5,
      "name": "Wood_Dry_Trunk",
      "support": 15,
      "rotation": 5
    },
    {
      "x": -5,
      "y": 14,
      "z": 5,
      "name": "Cloth_Roof_Leather",
      "rotation": 2
    },
    {
      "x": -5,
      "y": 3,
      "z": 6,
      "name": "Rock_Sandstone"
    },
    {
      "x": -5,
      "y": 4,
      "z": 6,
      "name": "Soil_Dirt_Dry"
    },
    {
      "x": -5,
      "y": 5,
      "z": 6,
      "name": "Soil_Mud_Dry"
    },
    {
      "x": -5,
      "y": 14,
      "z": 6,
      "name": "Wood_Drywood_Planks_Half",
      "rotation": 4
    },
    {
      "x": -4,
      "y": 3,
      "z": -6,
      "name": "Rock_Sandstone"
    },
    {
      "x": -4,
      "y": 4,
      "z": -6,
      "name": "Soil_Dirt_Dry"
    },
    {
      "x": -4,
      "y": 5,
      "z": -6,
      "name": "Soil_Mud_Dry"
    },
    {
      "x": -4,
      "y": 14,
      "z": -6,
      "name": "Wood_Drywood_Planks_Half",
      "rotation": 6
    },
    {
      "x": -4,
      "y": 2,
      "z": -5,
      "name": "Rock_Sandstone"
    },
    {
      "x": -4,
      "y": 3,
      "z": -5,
      "name": "Rock_Sandstone"
    },
    {
      "x": -4,
      "y": 4,
      "z": -5,
      "name": "Soil_Dirt_Dry"
    },
    {
      "x": -4,
      "y": 5,
      "z": -5,
      "name": "Soil_Mud_Dry"
    },
    {
      "x": -4,
      "y": 13,
      "z": -5,
      "name": "Wood_Dry_Trunk",
      "support": 15,
      "rotation": 5
    },
    {
      "x": -4,
      "y": 14,
      "z": -5,
      "name": "Cloth_Roof_Leather"
    },
    {
      "x": -4,
      "y": 1,
      "z": -4,
      "name": "Rock_Sandstone"
    },
    {
      "x": -4,
      "y": 2,
      "z": -4,
      "name": "Rock_Sandstone"
    },
    {
      "x": -4,
      "y": 3,
      "z": -4,
      "name": "Rock_Sandstone",
      "rotation": 1
    },
    {
      "x": -4,
      "y": 4,
      "z": -4,
      "name": "Rock_Sandstone",
      "rotation": 1
    },
    {
      "x": -4,
      "y": 5,
      "z": -4,
      "name": "Rock_Sandstone",
      "rotation": 1
    },
    {
      "x": -4,
      "y": 6,
      "z": -4,
      "name": "Rock_Sandstone_Red"
    },
    {
      "x": -4,
      "y": 7,
      "z": -4,
      "name": "Deco_Bone_Skulls"
    },
    {
      "x": -4,
      "y": 12,
      "z": -4,
      "name": "Wood_Dry_Branch_Long",
      "support": 15,
      "rotation": 5
    },
    {
      "x": -4,
      "y": 13,
      "z": -4,
      "name": "Cloth_Roof_Leather"
    },
    {
      "x": -4,
      "y": 0,
      "z": -3,
      "name": "Rock_Sandstone"
    },
    {
      "x": -4,
      "y": 1,
      "z": -3,
      "name": "Rock_Sandstone"
    },
    {
      "x": -4,
      "y": 2,
      "z": -3,
      "name": "Rock_Sandstone"
    },
    {
      "x": -4,
      "y": 3,
      "z": -3,
      "name": "Rock_Sandstone",
      "rotation": 1
    },
    {
      "x": -4,
      "y": 4,
      "z": -3,
      "name": "Rock_Sandstone",
      "rotation": 1
    },
    {
      "x": -4,
      "y": 5,
      "z": -3,
      "name": "Rock_Sandstone",
      "rotation": 1
    },
    {
      "x": -4,
      "y": 6,
      "z": -3,
      "name": "Rock_Sandstone",
      "rotation": 1
    },
    {
      "x": -4,
      "y": 7,
      "z": -3,
      "name": "Rock_Sandstone_Red",
      "rotation": 1
    },
    {
      "x": -4,
      "y": 8,
      "z": -3,
      "name": "Rock_Sandstone",
      "rotation": 1
    },
    {
      "x": -4,
      "y": 9,
      "z": -3,
      "name": "Rock_Sandstone_White",
      "rotation": 1
    },
    {
      "x": -4,
      "y": 12,
      "z": -3,
      "name": "Cloth_Roof_Leather"
    },
    {
      "x": -4,
      "y": 0,
      "z": -2,
      "name": "Rock_Sandstone"
    },
    {
      "x": -4,
      "y": 1,
      "z": -2,
      "name": "Rock_Sandstone"
    },
    {
      "x": -4,
      "y": 2,
      "z": -2,
      "name": "Rock_Sandstone"
    },
    {
      "x": -4,
      "y": 3,
      "z": -2,
      "name": "Rock_Sandstone",
      "rotation": 1
    },
    {
      "x": -4,
      "y": 4,
      "z": -2,
      "name": "Rock_Sandstone",
      "rotation": 1
    },
    {
      "x": -4,
      "y": 5,
      "z": -2,
      "name": "Rock_Sandstone",
      "rotation": 1
    },
    {
      "x": -4,
      "y": 6,
      "z": -2,
      "name": "Rock_Sandstone",
      "rotation": 1
    },
    {
      "x": -4,
      "y": 7,
      "z": -2,
      "name": "Rock_Sandstone",
      "rotation": 1
    },
    {
      "x": -4,
      "y": 8,
      "z": -2,
      "name": "Rock_Sandstone",
      "rotation": 1
    },
    {
      "x": -4,
      "y": 9,
      "z": -2,
      "name": "Empty"
    },
    {
      "x": -4,
      "y": 0,
      "z": -1,
      "name": "Rock_Sandstone"
    },
    {
      "x": -4,
      "y": 1,
      "z": -1,
      "name": "Rock_Sandstone"
    },
    {
      "x": -4,
      "y": 2,
      "z": -1,
      "name": "Rock_Sandstone"
    },
    {
      "x": -4,
      "y": 3,
      "z": -1,
      "name": "Rock_Sandstone",
      "rotation": 1
    },
    {
      "x": -4,
      "y": 4,
      "z": -1,
      "name": "Rock_Sandstone",
      "rotation": 1
    },
    {
      "x": -4,
      "y": 5,
      "z": -1,
      "name": "Rock_Sandstone",
      "rotation": 1
    },
    {
      "x": -4,
      "y": 6,
      "z": -1,
      "name": "Rock_Sandstone",
      "rotation": 1
    },
    {
      "x": -4,
      "y": 7,
      "z": -1,
      "name": "Rock_Sandstone",
      "rotation": 1
    },
    {
      "x": -4,
      "y": 8,
      "z": -1,
      "name": "Rock_Sandstone",
      "rotation": 1
    },
    {
      "x": -4,
      "y": 9,
      "z": -1,
      "name": "Empty"
    },
    {
      "x": -4,
      "y": 0,
      "z": 0,
      "name": "Rock_Sandstone"
    },
    {
      "x": -4,
      "y": 1,
      "z": 0,
      "name": "Rock_Sandstone"
    },
    {
      "x": -4,
      "y": 2,
      "z": 0,
      "name": "Rock_Sandstone"
    },
    {
      "x": -4,
      "y": 3,
      "z": 0,
      "name": "Rock_Sandstone",
      "rotation": 1
    },
    {
      "x": -4,
      "y": 4,
      "z": 0,
      "name": "Rock_Sandstone",
      "rotation": 1
    },
    {
      "x": -4,
      "y": 5,
      "z": 0,
      "name": "Soil_Sand",
      "rotation": 1
    },
    {
      "x": -4,
      "y": 6,
      "z": 0,
      "name": "Soil_Sand",
      "rotation": 1
    },
    {
      "x": -4,
      "y": 7,
      "z": 0,
      "name": "Rock_Sandstone",
      "rotation": 1
    },
    {
      "x": -4,
      "y": 8,
      "z": 0,
      "name": "Rock_Sandstone"
    },
    {
      "x": -4,
      "y": 9,
      "z": 0,
      "name": "Empty"
    },
    {
      "x": -4,
      "y": 0,
      "z": 1,
      "name": "Rock_Sandstone"
    },
    {
      "x": -4,
      "y": 1,
      "z": 1,
      "name": "Rock_Sandstone"
    },
    {
      "x": -4,
      "y": 2,
      "z": 1,
      "name": "Rock_Sandstone"
    },
    {
      "x": -4,
      "y": 3,
      "z": 1,
      "name": "Rock_Sandstone",
      "rotation": 1
    },
    {
      "x": -4,
      "y": 4,
      "z": 1,
      "name": "Rock_Sandstone",
      "rotation": 1
    },
    {
      "x": -4,
      "y": 5,
      "z": 1,
      "name": "Soil_Sand",
      "rotation": 1
    },
    {
      "x": -4,
      "y": 6,
      "z": 1,
      "name": "Rock_Sandstone_Red"
    },
    {
      "x": -4,
      "y": 7,
      "z": 1,
      "name": "Rock_Sandstone"
    },
    {
      "x": -4,
      "y": 8,
      "z": 1,
      "name": "Rock_Sandstone"
    },
    {
      "x": -4,
      "y": 9,
      "z": 1,
      "name": "Empty"
    },
    {
      "x": -4,
      "y": 0,
      "z": 2,
      "name": "Rock_Sandstone"
    },
    {
      "x": -4,
      "y": 1,
      "z": 2,
      "name": "Rock_Sandstone"
    },
    {
      "x": -4,
      "y": 2,
      "z": 2,
      "name": "Rock_Sandstone"
    },
    {
      "x": -4,
      "y": 3,
      "z": 2,
      "name": "Rock_Sandstone"
    },
    {
      "x": -4,
      "y": 4,
      "z": 2,
      "name": "Soil_Dirt_Dry"
    },
    {
      "x": -4,
      "y": 5,
      "z": 2,
      "name": "Soil_Mud_Dry"
    },
    {
      "x": -4,
      "y": 6,
      "z": 2,
      "name": "Rock_Sandstone_Red"
    },
    {
      "x": -4,
      "y": 7,
      "z": 2,
      "name": "Deco_Bone_Pile"
    },
    {
      "x": -4,
      "y": 8,
      "z": 2,
      "name": "Rock_Sandstone"
    },
    {
      "x": -4,
      "y": 9,
      "z": 2,
      "name": "Rock_Sandstone_White"
    },
    {
      "x": -4,
      "y": 0,
      "z": 3,
      "name": "Rock_Sandstone"
    },
    {
      "x": -4,
      "y": 1,
      "z": 3,
      "name": "Rock_Sandstone"
    },
    {
      "x": -4,
      "y": 2,
      "z": 3,
      "name": "Rock_Sandstone"
    },
    {
      "x": -4,
      "y": 3,
      "z": 3,
      "name": "Rock_Sandstone"
    },
    {
      "x": -4,
      "y": 4,
      "z": 3,
      "name": "Soil_Dirt_Dry"
    },
    {
      "x": -4,
      "y": 5,
      "z": 3,
      "name": "Soil_Mud_Dry"
    },
    {
      "x": -4,
      "y": 12,
      "z": 3,
      "name": "Cloth_Roof_Leather",
      "rotation": 2
    },
    {
      "x": -4,
      "y": 1,
      "z": 4,
      "name": "Rock_Sandstone"
    },
    {
      "x": -4,
      "y": 2,
      "z": 4,
      "name": "Rock_Sandstone"
    },
    {
      "x": -4,
      "y": 3,
      "z": 4,
      "name": "Rock_Sandstone"
    },
    {
      "x": -4,
      "y": 4,
      "z": 4,
      "name": "Soil_Dirt_Dry"
    },
    {
      "x": -4,
      "y": 5,
      "z": 4,
      "name": "Soil_Mud_Dry"
    },
    {
      "x": -4,
      "y": 12,
      "z": 4,
      "name": "Wood_Dry_Branch_Long",
