{
  "version": 8,
  "blockIdVersion": 11,
  "anchorX": 0,
  "anchorY": 0,
  "anchorZ": 0,
  "blocks": [
    {
      "x": -15,
      "y": 0,
      "z": -15,
      "name": "Soil_Gravel_Sand"
    },
    {
      "x": -15,
      "y": 1,
      "z": -15,
      "name": "Soil_Dirt_Dry"
    },
    {
      "x": -15,
      "y": 0,
      "z": -14,
      "name": "Soil_Gravel_Sand"
    },
    {
      "x": -15,
      "y": 1,
      "z": -14,
      "name": "Soil_Dirt_Dry"
    },
    {
      "x": -15,
      "y": 0,
      "z": -13,
      "name": "Soil_Gravel_Sand"
    },
    {
      "x": -15,
      "y": 1,
      "z": -13,
      "name": "Soil_Dirt_Dry"
    },
    {
      "x": -15,
      "y": 0,
      "z": -12,
      "name": "Soil_Gravel_Sand"
    },
    {
      "x": -15,
      "y": 1,
      "z": -12,
      "name": "Soil_Dirt_Dry"
    },
    {
      "x": -15,
      "y": 0,
      "z": -11,
      "name": "Soil_Gravel_Sand"
    },
    {
      "x": -15,
      "y": 1,
      "z": -11,
      "name": "Soil_Dirt_Dry"
    },
    {
      "x": -15,
      "y": 0,
      "z": -10,
      "name": "Soil_Gravel_Sand"
    },
    {
      "x": -15,
      "y": 1,
      "z": -10,
      "name": "Soil_Dirt_Dry"
    },
    {
      "x": -15,
      "y": 0,
      "z": -9,
      "name": "Soil_Gravel_Sand"
    },
    {
      "x": -15,
      "y": 1,
      "z": -9,
      "name": "Soil_Dirt_Dry"
    },
    {
      "x": -15,
      "y": 0,
      "z": -8,
      "name": "Soil_Gravel_Sand"
    },
    {
      "x": -15,
      "y": 1,
      "z": -8,
      "name": "Soil_Dirt_Dry"
    },
    {
      "x": -15,
      "y": 0,
      "z": -7,
      "name": "Soil_Gravel_Sand"
    },
    {
      "x": -15,
      "y": 1,
      "z": -7,
      "name": "Soil_Dirt_Dry"
    },
    {
      "x": -15,
      "y": 0,
      "z": -6,
      "name": "Soil_Gravel_Sand"
    },
    {
      "x": -15,
      "y": 1,
      "z": -6,
      "name": "Soil_Dirt_Dry"
    },
    {
      "x": -15,
      "y": 0,
      "z": -5,
      "name": "Soil_Gravel_Sand"
    },
    {
      "x": -15,
      "y": 1,
      "z": -5,
      "name": "Soil_Dirt_Dry"
    },
    {
      "x": -15,
      "y": 0,
      "z": -4,
      "name": "Soil_Gravel_Sand"
    },
    {
      "x": -15,
      "y": 1,
      "z": -4,
      "name": "Soil_Dirt_Dry"
    },
    {
      "x": -15,
      "y": 0,
      "z": -3,
      "name": "Soil_Gravel_Sand"
    },
    {
      "x": -15,
      "y": 1,
      "z": -3,
      "name": "Soil_Dirt_Dry"
    },
    {
      "x": -15,
      "y": 0,
      "z": -2,
      "name": "Soil_Gravel_Sand"
    },
    {
      "x": -15,
      "y": 1,
      "z": -2,
      "name": "Soil_Dirt_Dry"
    },
    {
      "x": -15,
      "y": 0,
      "z": -1,
      "name": "Soil_Gravel_Sand"
    },
    {
      "x": -15,
      "y": 1,
      "z": -1,
      "name": "Soil_Dirt_Dry"
    },
    {
      "x": -15,
      "y": 0,
      "z": 0,
      "name": "Soil_Gravel_Sand"
    },
    {
      "x": -15,
      "y": 1,
      "z": 0,
      "name": "Soil_Dirt_Dry"
    },
    {
      "x": -15,
      "y": 0,
      "z": 1,
      "name": "Soil_Gravel_Sand"
    },
    {
      "x": -15,
      "y": 1,
      "z": 1,
      "name": "Soil_Dirt_Dry"
    },
    {
      "x": -15,
      "y": 0,
      "z": 2,
      "name": "Soil_Gravel_Sand"
    },
    {
      "x": -15,
      "y": 1,
      "z": 2,
      "name": "Soil_Dirt_Dry"
    },
    {
      "x": -15,
      "y": 0,
      "z": 3,
      "name": "Soil_Gravel_Sand"
    },
    {
      "x": -15,
      "y": 1,
      "z": 3,
      "name": "Soil_Dirt_Dry"
    },
    {
      "x": -15,
      "y": 0,
      "z": 4,
      "name": "Soil_Gravel_Sand"
    },
    {
      "x": -15,
      "y": 1,
      "z": 4,
      "name": "Soil_Dirt_Dry"
    },
    {
      "x": -15,
      "y": 0,
      "z": 5,
      "name": "Soil_Gravel_Sand"
    },
    {
      "x": -15,
      "y": 1,
      "z": 5,
      "name": "Soil_Dirt_Dry"
    },
    {
      "x": -15,
      "y": 0,
      "z": 6,
      "name": "Soil_Gravel_Sand"
    },
    {
      "x": -15,
      "y": 1,
      "z": 6,
      "name": "Soil_Dirt_Dry"
    },
    {
      "x": -15,
      "y": 0,
      "z": 7,
      "name": "Soil_Gravel_Sand"
    },
    {
      "x": -15,
      "y": 1,
      "z": 7,
      "name": "Soil_Dirt_Dry"
    },
    {
      "x": -15,
      "y": 0,
      "z": 8,
      "name": "Soil_Gravel_Sand"
    },
    {
      "x": -15,
      "y": 1,
      "z": 8,
      "name": "Soil_Dirt_Dry"
    },
    {
      "x": -15,
      "y": 0,
      "z": 9,
      "name": "Soil_Gravel_Sand"
    },
    {
      "x": -15,
      "y": 1,
      "z": 9,
      "name": "Soil_Dirt_Dry"
    },
    {
      "x": -15,
      "y": 0,
      "z": 10,
      "name": "Soil_Gravel_Sand"
    },
    {
      "x": -15,
      "y": 1,
      "z": 10,
      "name": "Soil_Dirt_Dry"
    },
    {
      "x": -15,
      "y": 0,
      "z": 11,
      "name": "Soil_Gravel_Sand"
    },
    {
      "x": -15,
      "y": 1,
      "z": 11,
      "name": "Soil_Dirt_Dry"
    },
    {
      "x": -15,
      "y": 0,
      "z": 12,
      "name": "Soil_Gravel_Sand"
    },
    {
      "x": -15,
      "y": 1,
      "z": 12,
      "name": "Soil_Dirt_Dry"
    },
    {
      "x": -15,
      "y": 0,
      "z": 13,
      "name": "Soil_Gravel_Sand"
    },
    {
      "x": -15,
      "y": 1,
      "z": 13,
      "name": "Soil_Dirt_Dry"
    },
    {
      "x": -15,
      "y": 0,
      "z": 14,
      "name": "Soil_Gravel_Sand"
    },
    {
      "x": -15,
      "y": 1,
      "z": 14,
      "name": "Soil_Dirt_Dry"
    },
    {
      "x": -15,
      "y": 0,
      "z": 15,
      "name": "Soil_Gravel_Sand"
    },
    {
      "x": -15,
      "y": 1,
      "z": 15,
      "name": "Soil_Dirt_Dry"
    },
    {
      "x": -14,
      "y": 0,
      "z": -15,
      "name": "Soil_Gravel_Sand"
    },
    {
      "x": -14,
      "y": 1,
      "z": -15,
      "name": "Soil_Dirt_Dry"
    },
    {
      "x": -14,
      "y": 0,
      "z": -14,
      "name": "Soil_Gravel_Sand"
    },
    {
      "x": -14,
      "y": 1,
      "z": -14,
      "name": "Soil_Dirt_Dry"
    },
    {
      "x": -14,
      "y": 0,
      "z": -13,
      "name": "Soil_Gravel_Sand"
    },
    {
      "x": -14,
      "y": 1,
      "z": -13,
      "name": "Soil_Dirt_Dry"
    },
    {
      "x": -14,
      "y": 0,
      "z": -12,
      "name": "Soil_Gravel_Sand"
    },
    {
      "x": -14,
      "y": 1,
      "z": -12,
      "name": "Soil_Dirt_Dry"
    },
    {
      "x": -14,
      "y": 0,
      "z": -11,
      "name": "Soil_Gravel_Sand"
    },
    {
      "x": -14,
      "y": 1,
      "z": -11,
      "name": "Soil_Dirt_Dry"
    },
    {
      "x": -14,
      "y": 0,
      "z": -10,
      "name": "Soil_Gravel_Sand"
    },
    {
      "x": -14,
      "y": 1,
      "z": -10,
      "name": "Soil_Dirt_Dry"
    },
    {
      "x": -14,
      "y": 0,
      "z": -9,
      "name": "Soil_Gravel_Sand"
    },
    {
      "x": -14,
      "y": 1,
      "z": -9,
      "name": "Soil_Dirt_Dry"
    },
    {
      "x": -14,
      "y": 0,
      "z": -8,
      "name": "Soil_Gravel_Sand"
    },
    {
      "x": -14,
      "y": 1,
      "z": -8,
      "name": "Soil_Dirt_Dry"
    },
    {
      "x": -14,
      "y": 0,
      "z": -7,
      "name": "Soil_Gravel_Sand"
    },
    {
      "x": -14,
      "y": 1,
      "z": -7,
      "name": "Soil_Dirt_Dry"
    },
    {
      "x": -14,
      "y": 2,
      "z": -7,
      "name": "Rock_Sandstone_Cobble"
    },
    {
      "x": -14,
      "y": 0,
      "z": -6,
      "name": "Soil_Gravel_Sand"
    },
    {
      "x": -14,
      "y": 1,
      "z": -6,
      "name": "Soil_Dirt_Dry"
    },
    {
      "x": -14,
      "y": 2,
      "z": -6,
      "name": "Rock_Sandstone_Cobble"
    },
    {
      "x": -14,
      "y": 0,
      "z": -5,
      "name": "Soil_Gravel_Sand"
    },
    {
      "x": -14,
      "y": 1,
      "z": -5,
      "name": "Soil_Dirt_Dry"
    },
    {
      "x": -14,
      "y": 2,
      "z": -5,
      "name": "Rock_Sandstone"
    },
    {
      "x": -14,
      "y": 3,
      "z": -5,
      "name": "Rubble_Sandstone_Medium",
      "support": 15
    },
    {
      "x": -14,
      "y": 0,
      "z": -4,
      "name": "Soil_Gravel_Sand"
    },
    {
      "x": -14,
      "y": 1,
      "z": -4,
      "name": "Soil_Dirt_Dry"
    },
    {
      "x": -14,
      "y": 2,
      "z": -4,
      "name": "Rock_Sandstone_Cobble"
    },
    {
      "x": -14,
      "y": 0,
      "z": -3,
      "name": "Soil_Gravel_Sand"
    },
    {
      "x": -14,
      "y": 1,
      "z": -3,
      "name": "Soil_Dirt_Dry"
    },
    {
      "x": -14,
      "y": 0,
      "z": -2,
      "name": "Soil_Gravel_Sand"
    },
    {
      "x": -14,
      "y": 1,
      "z": -2,
      "name": "Soil_Dirt_Dry"
    },
    {
      "x": -14,
      "y": 0,
      "z": -1,
      "name": "Soil_Gravel_Sand"
    },
    {
      "x": -14,
      "y": 1,
      "z": -1,
      "name": "Soil_Dirt_Dry"
    },
    {
      "x": -14,
      "y": 0,
      "z": 0,
      "name": "Soil_Gravel_Sand"
    },
    {
      "x": -14,
      "y": 1,
      "z": 0,
      "name": "Soil_Dirt_Dry"
    },
    {
      "x": -14,
      "y": 0,
      "z": 1,
      "name": "Soil_Gravel_Sand"
    },
    {
      "x": -14,
      "y": 1,
      "z": 1,
      "name": "Soil_Dirt_Dry"
    },
    {
      "x": -14,
      "y": 0,
      "z": 2,
      "name": "Soil_Gravel_Sand"
    },
    {
      "x": -14,
      "y": 1,
      "z": 2,
      "name": "Soil_Dirt_Dry"
    },
    {
      "x": -14,
      "y": 0,
      "z": 3,
      "name": "Soil_Gravel_Sand"
    },
    {
      "x": -14,
      "y": 1,
      "z": 3,
      "name": "Soil_Dirt_Dry"
    },
    {
      "x": -14,
      "y": 0,
      "z": 4,
      "name": "Soil_Gravel_Sand"
    },
    {
      "x": -14,
      "y": 1,
      "z": 4,
      "name": "Soil_Dirt_Dry"
    },
    {
      "x": -14,
      "y": 0,
      "z": 5,
      "name": "Soil_Gravel_Sand"
    },
    {
      "x": -14,
      "y": 1,
      "z": 5,
      "name": "Soil_Dirt_Dry"
    },
    {
      "x": -14,
      "y": 0,
      "z": 6,
      "name": "Soil_Gravel_Sand"
    },
    {
      "x": -14,
      "y": 1,
      "z": 6,
      "name": "Soil_Dirt_Dry"
    },
    {
      "x": -14,
      "y": 0,
      "z": 7,
      "name": "Soil_Gravel_Sand"
    },
    {
      "x": -14,
      "y": 1,
      "z": 7,
      "name": "Soil_Dirt_Dry"
    },
    {
      "x": -14,
      "y": 0,
      "z": 8,
      "name": "Soil_Gravel_Sand"
    },
    {
      "x": -14,
      "y": 1,
      "z": 8,
      "name": "Soil_Dirt_Dry"
    },
    {
      "x": -14,
      "y": 0,
      "z": 9,
      "name": "Soil_Gravel_Sand"
    },
    {
      "x": -14,
      "y": 1,
      "z": 9,
      "name": "Soil_Dirt_Dry"
    },
    {
      "x": -14,
      "y": 0,
      "z": 10,
      "name": "Soil_Gravel_Sand"
    },
    {
      "x": -14,
      "y": 1,
      "z": 10,
      "name": "Soil_Dirt_Dry"
    },
    {
      "x": -14,
      "y": 0,
      "z": 11,
      "name": "Soil_Gravel_Sand"
    },
    {
      "x": -14,
      "y": 1,
      "z": 11,
      "name": "Soil_Dirt_Dry"
    },
    {
      "x": -14,
      "y": 0,
      "z": 12,
      "name": "Soil_Gravel_Sand"
    },
    {
      "x": -14,
      "y": 1,
      "z": 12,
      "name": "Soil_Dirt_Dry"
    },
    {
      "x": -14,
      "y": 0,
      "z": 13,
      "name": "Soil_Gravel_Sand"
    },
    {
      "x": -14,
      "y": 1,
      "z": 13,
      "name": "Soil_Dirt_Dry"
    },
    {
      "x": -14,
      "y": 0,
      "z": 14,
      "name": "Soil_Gravel_Sand"
    },
    {
      "x": -14,
      "y": 1,
      "z": 14,
      "name": "Soil_Dirt_Dry"
    },
    {
      "x": -14,
      "y": 0,
      "z": 15,
      "name": "Soil_Gravel_Sand"
    },
    {
      "x": -14,
      "y": 1,
      "z": 15,
      "name": "Soil_Dirt_Dry"
    },
    {
      "x": -13,
      "y": 0,
      "z": -15,
      "name": "Soil_Gravel_Sand"
    },
    {
      "x": -13,
      "y": 1,
      "z": -15,
      "name": "Soil_Dirt_Dry"
    },
    {
      "x": -13,
      "y": 0,
      "z": -14,
      "name": "Soil_Gravel_Sand"
    },
    {
      "x": -13,
      "y": 1,
      "z": -14,
      "name": "Soil_Dirt_Dry"
    },
    {
      "x": -13,
      "y": 0,
      "z": -13,
      "name": "Soil_Gravel_Sand"
    },
    {
      "x": -13,
      "y": 1,
      "z": -13,
      "name": "Soil_Dirt_Dry"
    },
    {
      "x": -13,
      "y": 0,
      "z": -12,
      "name": "Soil_Gravel_Sand"
    },
    {
      "x": -13,
      "y": 1,
      "z": -12,
      "name": "Soil_Dirt_Dry"
    },
    {
      "x": -13,
      "y": 0,
      "z": -11,
      "name": "Soil_Gravel_Sand"
    },
    {
      "x": -13,
      "y": 1,
      "z": -11,
      "name": "Soil_Dirt_Dry"
    },
    {
      "x": -13,
      "y": 0,
      "z": -10,
      "name": "Soil_Gravel_Sand"
    },
    {
      "x": -13,
      "y": 1,
      "z": -10,
      "name": "Soil_Dirt_Dry"
    },
    {
      "x": -13,
      "y": 0,
      "z": -9,
      "name": "Soil_Gravel_Sand"
    },
    {
      "x": -13,
      "y": 1,
      "z": -9,
      "name": "Soil_Dirt_Dry"
    },
    {
      "x": -13,
      "y": 2,
      "z": -9,
      "name": "Rock_Sandstone"
    },
    {
      "x": -13,
      "y": 3,
      "z": -9,
      "name": "Rock_Sandstone"
    },
    {
      "x": -13,
      "y": 4,
      "z": -9,
      "name": "Rubble_Sandstone_Medium",
      "support": 15
    },
    {
      "x": -13,
      "y": 0,
      "z": -8,
      "name": "Soil_Gravel_Sand"
    },
    {
      "x": -13,
      "y": 1,
      "z": -8,
      "name": "Soil_Dirt_Dry"
    },
    {
      "x": -13,
      "y": 2,
      "z": -8,
      "name": "Rock_Sandstone"
    },
    {
      "x": -13,
      "y": 3,
      "z": -8,
      "name": "Rock_Sandstone"
    },
    {
      "x": -13,
      "y": 4,
      "z": -8,
      "name": "Rock_Sandstone_Cobble"
    },
    {
      "x": -13,
      "y": 5,
      "z": -8,
      "name": "Rock_Sandstone_Stalactite_Large"
    },
    {
      "x": -13,
      "y": 6,
      "z": -8,
      "name": "Rock_Sandstone_Stalactite_Large",
      "filler": 1024
    },
    {
      "x": -13,
      "y": 0,
      "z": -7,
      "name": "Soil_Gravel_Sand"
    },
    {
      "x": -13,
      "y": 1,
      "z": -7,
      "name": "Soil_Dirt_Dry"
    },
    {
      "x": -13,
      "y": 2,
      "z": -7,
      "name": "Rock_Sandstone"
    },
    {
      "x": -13,
      "y": 3,
      "z": -7,
      "name": "Rock_Sandstone"
    },
    {
      "x": -13,
      "y": 4,
      "z": -7,
      "name": "Rock_Sandstone"
    },
    {
      "x": -13,
      "y": 0,
      "z": -6,
      "name": "Soil_Gravel_Sand"
    },
    {
      "x": -13,
      "y": 1,
      "z": -6,
      "name": "Soil_Dirt_Dry"
    },
    {
      "x": -13,
      "y": 2,
      "z": -6,
      "name": "Rock_Sandstone_Cobble"
    },
    {
      "x": -13,
      "y": 3,
      "z": -6,
      "name": "Rock_Sandstone_Cobble"
    },
    {
      "x": -13,
      "y": 4,
      "z": -6,
      "name": "Rock_Sandstone"
    },
    {
      "x": -13,
      "y": 5,
      "z": -6,
      "name": "Rock_Sandstone_Cobble"
    },
    {
      "x": -13,
      "y": 6,
      "z": -6,
      "name": "Rubble_Sandstone_Medium",
      "support": 15
    },
    {
      "x": -13,
      "y": 0,
      "z": -5,
      "name": "Soil_Gravel_Sand"
    },
    {
      "x": -13,
      "y": 1,
      "z": -5,
      "name": "Soil_Dirt_Dry"
    },
    {
      "x": -13,
      "y": 2,
      "z": -5,
      "name": "Rock_Sandstone_Cobble"
    },
    {
      "x": -13,
      "y": 3,
      "z": -5,
      "name": "Rock_Sandstone_Cobble"
    },
    {
      "x": -13,
      "y": 4,
      "z": -5,
      "name": "Rock_Sandstone_Cobble"
    },
    {
      "x": -13,
      "y": 0,
      "z": -4,
      "name": "Soil_Gravel_Sand"
    },
    {
      "x": -13,
      "y": 1,
      "z": -4,
      "name": "Soil_Dirt_Dry"
    },
    {
      "x": -13,
      "y": 2,
      "z": -4,
      "name": "Rock_Sandstone_Cobble"
    },
    {
      "x": -13,
      "y": 0,
      "z": -3,
      "name": "Soil_Gravel_Sand"
    },
    {
      "x": -13,
      "y": 1,
      "z": -3,
      "name": "Soil_Dirt_Dry"
    },
    {
      "x": -13,
      "y": 2,
      "z": -3,
      "name": "Rock_Sandstone"
    },
    {
      "x": -13,
      "y": 0,
      "z": -2,
      "name": "Soil_Gravel_Sand"
    },
    {
      "x": -13,
      "y": 1,
      "z": -2,
      "name": "Soil_Dirt_Dry"
    },
    {
      "x": -13,
      "y": 2,
      "z": -2,
      "name": "Rock_Sandstone_Cobble"
    },
    {
      "x": -13,
      "y": 0,
      "z": -1,
      "name": "Soil_Gravel_Sand"
    },
    {
      "x": -13,
      "y": 1,
      "z": -1,
      "name": "Soil_Dirt_Dry"
    },
    {
      "x": -13,
      "y": 0,
      "z": 0,
      "name": "Soil_Gravel_Sand"
    },
    {
      "x": -13,
      "y": 1,
      "z": 0,
      "name": "Soil_Dirt_Dry"
    },
    {
      "x": -13,
      "y": 0,
      "z": 1,
      "name": "Soil_Gravel_Sand"
    },
    {
      "x": -13,
      "y": 1,
      "z": 1,
      "name": "Soil_Dirt_Dry"
    },
    {
      "x": -13,
      "y": 0,
      "z": 2,
      "name": "Soil_Gravel_Sand"
    },
    {
      "x": -13,
      "y": 1,
      "z": 2,
      "name": "Soil_Dirt_Dry"
    },
    {
      "x": -13,
      "y": 0,
      "z": 3,
      "name": "Soil_Gravel_Sand"
    },
    {
      "x": -13,
      "y": 1,
      "z": 3,
      "name": "Soil_Dirt_Dry"
    },
    {
      "x": -13,
      "y": 0,
      "z": 4,
      "name": "Soil_Gravel_Sand"
    },
    {
      "x": -13,
      "y": 1,
      "z": 4,
      "name": "Soil_Dirt_Dry"
    },
    {
      "x": -13,
      "y": 0,
      "z": 5,
      "name": "Soil_Gravel_Sand"
    },
    {
      "x": -13,
      "y": 1,
      "z": 5,
      "name": "Soil_Dirt_Dry"
    },
    {
      "x": -13,
      "y": 0,
      "z": 6,
      "name": "Soil_Gravel_Sand"
    },
    {
      "x": -13,
      "y": 1,
      "z": 6,
      "name": "Soil_Dirt_Dry"
    },
    {
      "x": -13,
      "y": 0,
      "z": 7,
      "name": "Soil_Gravel_Sand"
    },
    {
      "x": -13,
      "y": 1,
      "z": 7,
      "name": "Soil_Dirt_Dry"
    },
    {
      "x": -13,
      "y": 0,
      "z": 8,
      "name": "Soil_Gravel_Sand"
    },
    {
      "x": -13,
      "y": 1,
      "z": 8,
      "name": "Soil_Dirt_Dry"
    },
    {
      "x": -13,
      "y": 0,
      "z": 9,
      "name": "Soil_Gravel_Sand"
    },
    {
      "x": -13,
      "y": 1,
      "z": 9,
      "name": "Soil_Dirt_Dry"
    },
    {
      "x": -13,
      "y": 0,
      "z": 10,
      "name": "Soil_Gravel_Sand"
    },
    {
      "x": -13,
      "y": 1,
      "z": 10,
      "name": "Soil_Dirt_Dry"
    },
    {
      "x": -13,
      "y": 0,
      "z": 11,
      "name": "Soil_Gravel_Sand"
    },
    {
      "x": -13,
      "y": 1,
      "z": 11,
      "name": "Soil_Dirt_Dry"
    },
    {
      "x": -13,
      "y": 0,
      "z": 12,
      "name": "Soil_Gravel_Sand"
    },
    {
      "x": -13,
      "y": 1,
      "z": 12,
      "name": "Soil_Dirt_Dry"
    },
    {
      "x": -13,
      "y": 2,
      "z": 12,
      "name": "Deco_Bone_Full"
    },
    {
      "x": -13,
      "y": 3,
      "z": 12,
      "name": "Deco_Bone_Full"
    },
    {
      "x": -13,
      "y": 4,
      "z": 12,
      "name": "Deco_Bone_Full"
    },
    {
      "x": -13,
      "y": 5,
      "z": 12,
      "name": "Deco_Bone_Full"
    },
    {
      "x": -13,
      "y": 0,
      "z": 13,
      "name": "Soil_Gravel_Sand"
    },
    {
      "x": -13,
      "y": 1,
      "z": 13,
      "name": "Soil_Dirt_Dry"
    },
    {
      "x": -13,
      "y": 2,
      "z": 13,
      "name": "Deco_Bone_Full"
    },
    {
      "x": -13,
      "y": 3,
      "z": 13,
      "name": "Deco_Bone_Full"
    },
    {
      "x": -13,
      "y": 4,
      "z": 13,
      "name": "Deco_Bone_Full"
    },
    {
      "x": -13,
      "y": 5,
      "z": 13,
      "name": "Deco_Bone_Full"
    },
    {
      "x": -13,
      "y": 6,
      "z": 13,
      "name": "Deco_Bone_Full"
    },
    {
      "x": -13,
      "y": 7,
      "z": 13,
      "name": "Deco_Bone_Spike_Large"
    },
    {
      "x": -13,
      "y": 0,
      "z": 14,
      "name": "Soil_Gravel_Sand"
    },
    {
      "x": -13,
      "y": 1,
      "z": 14,
      "name": "Soil_Dirt_Dry"
    },
    {
      "x": -13,
      "y": 0,
      "z": 15,
      "name": "Soil_Gravel_Sand"
    },
    {
      "x": -13,
      "y": 1,
      "z": 15,
      "name": "Soil_Dirt_Dry"
    },
    {
      "x": -12,
      "y": 0,
      "z": -15,
      "name": "Soil_Gravel_Sand"
    },
    {
      "x": -12,
      "y": 1,
      "z": -15,
      "name": "Soil_Dirt_Dry"
    },
    {
      "x": -12,
      "y": 0,
      "z": -14,
      "name": "Soil_Gravel_Sand"
    },
    {
      "x": -12,
      "y": 1,
      "z": -14,
      "name": "Soil_Dirt_Dry"
    },
    {
      "x": -12,
      "y": 0,
      "z": -13,
      "name": "Soil_Gravel_Sand"
    },
    {
      "x": -12,
      "y": 1,
      "z": -13,
      "name": "Soil_Dirt_Dry"
    },
    {
      "x": -12,
      "y": 12,
      "z": -13,
      "name": "*Rock_Sandstone_Red_Cobble_Roof_Hollow_State_Definitions_Corner_Left",
      "rotation": 2
    },
    {
      "x": -12,
      "y": 0,
      "z": -12,
      "name": "Soil_Gravel_Sand"
    },
    {
      "x": -12,
      "y": 1,
      "z": -12,
      "name": "Soil_Dirt_Dry"
    },
    {
      "x": -12,
      "y": 11,
      "z": -12,
      "name": "Rock_Sandstone_Red_Brick_Half",
      "rotation": 7
    },
    {
      "x": -12,
      "y": 12,
      "z": -12,
      "name": "Rock_Sandstone_Red_Cobble_Roof_Hollow",
      "rotation": 3
    },
    {
      "x": -12,
      "y": 0,
      "z": -11,
      "name": "Soil_Gravel_Sand"
    },
    {
      "x": -12,
      "y": 1,
      "z": -11,
      "name": "Soil_Dirt_Dry"
    },
    {
      "x": -12,
      "y": 11,
      "z": -11,
      "name": "Rock_Sandstone_Red_Brick_Half",
      "rotation": 7
    },
    {
      "x": -12,
      "y": 12,
      "z": -11,
      "name": "Rock_Sandstone_Red_Cobble_Roof_Hollow",
      "rotation": 3
    },
    {
      "x": -12,
      "y": 0,
      "z": -10,
      "name": "Soil_Gravel_Sand"
    },
    {
      "x": -12,
      "y": 1,
      "z": -10,
      "name": "Soil_Dirt_Dry"
    },
    {
      "x": -12,
      "y": 2,
      "z": -10,
      "name": "Rock_Sandstone"
    },
    {
      "x": -12,
      "y": 3,
      "z": -10,
      "name": "Rock_Sandstone"
    },
    {
      "x": -12,
      "y": 4,
      "z": -10,
      "name": "Rock_Sandstone"
    },
    {
      "x": -12,
      "y": 5,
      "z": -10,
      "name": "Rock_Sandstone"
    },
    {
      "x": -12,
      "y": 11,
      "z": -10,
      "name": "Rock_Sandstone_Red_Brick_Half",
      "rotation": 7
    },
    {
      "x": -12,
      "y": 12,
      "z": -10,
      "name": "Rock_Sandstone_Red_Cobble_Roof_Hollow",
      "rotation": 3
    },
    {
      "x": -12,
      "y": 0,
      "z": -9,
      "name": "Soil_Gravel_Sand"
    },
    {
      "x": -12,
      "y": 1,
      "z": -9,
      "name": "Soil_Dirt_Dry"
    },
    {
      "x": -12,
      "y": 2,
      "z": -9,
      "name": "Rock_Sandstone"
    },
    {
      "x": -12,
      "y": 3,
      "z": -9,
      "name": "Rock_Sandstone_Cobble"
    },
    {
      "x": -12,
      "y": 4,
      "z": -9,
      "name": "Rock_Sandstone"
    },
    {
      "x": -12,
      "y": 5,
      "z": -9,
      "name": "Rock_Sandstone"
    },
    {
      "x": -12,
      "y": 6,
      "z": -9,
      "name": "Rock_Sandstone"
    },
    {
      "x": -12,
      "y": 7,
      "z": -9,
      "name": "Rubble_Sandstone_Medium",
      "support": 15
    },
    {
      "x": -12,
      "y": 11,
      "z": -9,
      "name": "Rock_Sandstone_Red_Brick_Half",
      "rotation": 7
    },
    {
      "x": -12,
      "y": 12,
      "z": -9,
      "name": "Rock_Sandstone_Red_Cobble_Roof_Hollow",
      "rotation": 3
    },
    {
      "x": -12,
      "y": 0,
      "z": -8,
      "name": "Soil_Gravel_Sand"
    },
    {
      "x": -12,
      "y": 1,
      "z": -8,
      "name": "Soil_Dirt_Dry"
    },
    {
      "x": -12,
      "y": 2,
      "z": -8,
      "name": "Rock_Sandstone"
    },
    {
      "x": -12,
      "y": 3,
      "z": -8,
      "name": "Rock_Sandstone_Cobble"
    },
    {
      "x": -12,
      "y": 4,
      "z": -8,
      "name": "Rock_Sandstone_Cobble"
    },
    {
      "x": -12,
      "y": 5,
      "z": -8,
      "name": "Rock_Sandstone_Cobble"
    },
    {
      "x": -12,
      "y": 6,
      "z": -8,
      "name": "Rock_Sandstone"
    },
    {
      "x": -12,
      "y": 7,
      "z": -8,
      "name": "Rock_Sandstone"
    },
    {
      "x": -12,
      "y": 11,
      "z": -8,
      "name": "Rock_Sandstone_Red_Brick_Half",
      "rotation": 7
    },
    {
      "x": -12,
      "y": 12,
      "z": -8,
      "name": "Rock_Sandstone_Red_Cobble_Roof_Hollow",
      "rotation": 3
    },
    {
      "x": -12,
      "y": 0,
      "z": -7,
      "name": "Soil_Gravel_Sand"
    },
    {
      "x": -12,
      "y": 1,
      "z": -7,
      "name": "Soil_Dirt_Dry"
    },
    {
      "x": -12,
      "y": 2,
      "z": -7,
      "name": "Rock_Sandstone_Cobble"
    },
    {
      "x": -12,
      "y": 3,
      "z": -7,
      "name": "Rock_Sandstone"
    },
    {
      "x": -12,
      "y": 4,
      "z": -7,
      "name": "Rock_Sandstone_Cobble"
    },
    {
      "x": -12,
      "y": 5,
      "z": -7,
      "name": "Rock_Sandstone"
    },
    {
      "x": -12,
      "y": 6,
      "z": -7,
      "name": "Rock_Sandstone"
    },
    {
      "x": -12,
      "y": 7,
      "z": -7,
      "name": "Rock_Sandstone"
    },
    {
      "x": -12,
      "y": 8,
      "z": -7,
      "name": "Rock_Sandstone"
    },
    {
      "x": -12,
      "y": 11,
      "z": -7,
      "name": "Rock_Sandstone_Red_Brick_Half",
      "rotation": 7
    },
    {
      "x": -12,
      "y": 12,
      "z": -7,
      "name": "Rock_Sandstone_Red_Cobble_Roof_Hollow",
      "rotation": 3
    },
    {
      "x": -12,
      "y": 0,
      "z": -6,
      "name": "Soil_Gravel_Sand"
    },
    {
      "x": -12,
      "y": 1,
      "z": -6,
      "name": "Soil_Dirt_Dry"
    },
    {
      "x": -12,
      "y": 2,
      "z": -6,
      "name": "Rock_Sandstone_Cobble"
    },
    {
      "x": -12,
      "y": 3,
      "z": -6,
      "name": "Rock_Sandstone"
    },
    {
      "x": -12,
      "y": 4,
      "z": -6,
      "name": "Rock_Sandstone"
    },
    {
      "x": -12,
      "y": 5,
      "z": -6,
      "name": "Rock_Sandstone"
    },
    {
      "x": -12,
      "y": 6,
      "z": -6,
      "name": "Rock_Sandstone"
    },
    {
      "x": -12,
      "y": 7,
      "z": -6,
      "name": "Rock_Sandstone_Cobble"
    },
    {
      "x": -12,
      "y": 11,
      "z": -6,
      "name": "Rock_Sandstone_Red_Brick_Half",
      "rotation": 7
    },
    {
      "x": -12,
      "y": 12,
      "z": -6,
      "name": "Rock_Sandstone_Red_Cobble_Roof_Hollow",
      "rotation": 3
    },
    {
      "x": -12,
      "y": 0,
      "z": -5,
      "name": "Soil_Gravel_Sand"
    },
    {
      "x": -12,
      "y": 1,
      "z": -5,
      "name": "Soil_Dirt_Dry"
    },
    {
      "x": -12,
      "y": 2,
      "z": -5,
      "name": "Rock_Sandstone"
    },
    {
      "x": -12,
      "y": 3,
      "z": -5,
      "name": "Rock_Sandstone"
    },
    {
      "x": -12,
      "y": 4,
      "z": -5,
      "name": "Rock_Sandstone"
    },
    {
      "x": -12,
      "y": 5,
      "z": -5,
      "name": "Rock_Sandstone"
    },
    {
      "x": -12,
      "y": 6,
      "z": -5,
      "name": "Rock_Sandstone"
    },
    {
      "x": -12,
      "y": 7,
      "z": -5,
      "name": "Rock_Sandstone"
    },
    {
      "x": -12,
      "y": 11,
      "z": -5,
      "name": "Rock_Sandstone_Red_Brick_Half",
      "rotation": 7
    },
    {
      "x": -12,
      "y": 12,
      "z": -5,
      "name": "Rock_Sandstone_Red_Cobble_Roof_Hollow",
      "rotation": 3
    },
    {
      "x": -12,
      "y": 0,
      "z": -4,
      "name": "Soil_Gravel_Sand"
    },
    {
      "x": -12,
      "y": 1,
      "z": -4,
      "name": "Soil_Dirt_Dry"
    },
    {
      "x": -12,
      "y": 2,
      "z": -4,
      "name": "Rock_Sandstone"
    },
    {
      "x": -12,
      "y": 3,
      "z": -4,
      "name": "Rock_Sandstone_Cobble"
    },
    {
      "x": -12,
      "y": 4,
      "z": -4,
      "name": "Rock_Sandstone_Cobble"
    },
    {
      "x": -12,
      "y": 5,
      "z": -4,
      "name": "Rock_Sandstone"
    },
    {
      "x": -12,
      "y": 6,
      "z": -4,
      "name": "Rock_Sandstone"
    },
    {
      "x": -12,
      "y": 7,
      "z": -4,
      "name": "Rock_Sandstone"
    },
    {
      "x": -12,
      "y": 8,
      "z": -4,
      "name": "Rock_Sandstone"
    },
    {
      "x": -12,
      "y": 9,
      "z": -4,
      "name": "Rock_Sandstone_Stalactite_Large"
    },
    {
      "x": -12,
      "y": 10,
      "z": -4,
      "name": "Rock_Sandstone_Stalactite_Large",
      "filler": 1024
    },
    {
      "x": -12,
      "y": 11,
      "z": -4,
      "name": "Rock_Sandstone_Red_Brick_Half",
      "rotation": 7
    },
    {
      "x": -12,
      "y": 12,
      "z": -4,
      "name": "Rock_Sandstone_Red_Cobble_Roof_Hollow",
      "rotation": 3
    },
    {
      "x": -12,
      "y": 0,
      "z": -3,
      "name": "Soil_Gravel_Sand"
    },
    {
      "x": -12,
      "y": 1,
      "z": -3,
      "name": "Soil_Dirt_Dry"
    },
    {
      "x": -12,
      "y": 2,
      "z": -3,
      "name": "Rock_Sandstone"
    },
    {
      "x": -12,
      "y": 3,
      "z": -3,
      "name": "Rock_Sandstone"
    },
    {
      "x": -12,
      "y": 4,
      "z": -3,
      "name": "Rock_Sandstone_Cobble"
    },
    {
      "x": -12,
      "y": 11,
      "z": -3,
      "name": "Rock_Sandstone_Red_Brick_Half",
      "rotation": 7
    },
    {
      "x": -12,
      "y": 12,
      "z": -3,
      "name": "Rock_Sandstone_Red_Cobble_Roof_Hollow",
      "rotation": 3
    },
    {
      "x": -12,
      "y": 0,
      "z": -2,
      "name": "Soil_Gravel_Sand"
    },
    {
      "x": -12,
      "y": 1,
      "z": -2,
      "name": "Soil_Dirt_Dry"
    },
    {
      "x": -12,
      "y": 2,
      "z": -2,
      "name": "Rock_Sandstone"
    },
    {
      "x": -12,
      "y": 11,
      "z": -2,
      "name": "Rock_Sandstone_Red_Brick_Half",
      "rotation": 7
    },
    {
      "x": -12,
      "y": 12,
      "z": -2,
      "name": "Rock_Sandstone_Red_Cobble_Roof_Hollow",
      "rotation": 3
    },
    {
      "x": -12,
      "y": 0,
      "z": -1,
      "name": "Soil_Gravel_Sand"
    },
    {
      "x": -12,
      "y": 1,
      "z": -1,
      "name": "Soil_Dirt_Dry"
    },
    {
      "x": -12,
      "y": 11,
      "z": -1,
      "name": "Rock_Sandstone_Red_Brick_Half",
      "rotation": 7
    },
    {
      "x": -12,
      "y": 12,
      "z": -1,
      "name": "Rock_Sandstone_Red_Cobble_Roof_Hollow",
      "rotation": 3
    },
    {
      "x": -12,
      "y": 0,
      "z": 0,
      "name": "Soil_Gravel_Sand"
    },
    {
      "x": -12,
      "y": 1,
      "z": 0,
      "name": "Soil_Dirt_Dry"
    },
    {
      "x": -12,
      "y": 11,
      "z": 0,
      "name": "Rock_Sandstone_Red_Brick_Half",
      "rotation": 7
    },
    {
      "x": -12,
      "y": 12,
      "z": 0,
      "name": "Rock_Sandstone_Red_Cobble_Roof_Hollow",
      "rotation": 3
    },
    {
      "x": -12,
      "y": 0,
      "z": 1,
      "name": "Soil_Gravel_Sand"
    },
    {
      "x": -12,
      "y": 1,
      "z": 1,
      "name": "Soil_Dirt_Dry"
    },
    {
      "x": -12,
      "y": 11,
      "z": 1,
      "name": "Rock_Sandstone_Red_Brick_Half",
      "rotation": 7
    },
    {
      "x": -12,
      "y": 12,
      "z": 1,
      "name": "Rock_Sandstone_Red_Cobble_Roof_Hollow",
      "rotation": 3
    },
    {
      "x": -12,
      "y": 0,
      "z": 2,
      "name": "Soil_Gravel_Sand"
    },
    {
      "x": -12,
      "y": 1,
      "z": 2,
      "name": "Soil_Dirt_Dry"
    },
    {
      "x": -12,
      "y": 11,
      "z": 2,
      "name": "Rock_Sandstone_Red_Brick_Half",
      "rotation": 7
    },
    {
      "x": -12,
      "y": 12,
      "z": 2,
      "name": "Rock_Sandstone_Red_Cobble_Roof_Hollow",
      "rotation": 3
    },
    {
      "x": -12,
      "y": 0,
      "z": 3,
      "name": "Soil_Gravel_Sand"
    },
    {
      "x": -12,
      "y": 1,
      "z": 3,
      "name": "Soil_Dirt_Dry"
    },
    {
      "x": -12,
      "y": 11,
      "z": 3,
      "name": "Rock_Sandstone_Red_Brick_Half",
      "rotation": 7
    },
    {
      "x": -12,
      "y": 12,
      "z": 3,
      "name": "Rock_Sandstone_Red_Cobble_Roof_Hollow",
      "rotation": 3
    },
    {
      "x": -12,
      "y": 0,
      "z": 4,
      "name": "Soil_Gravel_Sand"
    },
    {
      "x": -12,
      "y": 1,
      "z": 4,
      "name": "Soil_Dirt_Dry"
    },
    {
      "x": -12,
      "y": 12,
      "z": 4,
      "name": "*Rock_Sandstone_Red_Cobble_Roof_Hollow_State_Definitions_Corner_Left",
      "rotation": 3
    },
    {
      "x": -12,
      "y": 0,
      "z": 5,
      "name": "Soil_Gravel_Sand"
    },
    {
      "x": -12,
      "y": 1,
      "z": 5,
      "name": "Soil_Dirt_Dry"
    },
    {
      "x": -12,
      "y": 0,
      "z": 6,
      "name": "Soil_Gravel_Sand"
    },
    {
      "x": -12,
      "y": 1,
      "z": 6,
      "name": "Soil_Dirt_Dry"
    },
    {
      "x": -12,
      "y": 0,
      "z": 7,
      "name": "Soil_Gravel_Sand"
    },
    {
      "x": -12,
      "y": 1,
      "z": 7,
      "name": "Soil_Dirt_Dry"
    },
    {
      "x": -12,
      "y": 0,
      "z": 8,
      "name": "Soil_Gravel_Sand"
    },
    {
      "x": -12,
      "y": 1,
      "z": 8,
      "name": "Soil_Dirt_Dry"
    },
    {
      "x": -12,
      "y": 0,
      "z": 9,
      "name": "Soil_Gravel_Sand"
    },
    {
      "x": -12,
      "y": 1,
      "z": 9,
      "name": "Soil_Dirt_Dry"
    },
    {
      "x": -12,
      "y": 0,
      "z": 10,
      "name": "Soil_Gravel_Sand"
    },
    {
      "x": -12,
      "y": 1,
      "z": 10,
      "name": "Soil_Dirt_Dry"
    },
    {
      "x": -12,
      "y": 0,
      "z": 11,
      "name": "Soil_Gravel_Sand"
    },
    {
      "x": -12,
      "y": 1,
      "z": 11,
      "name": "Soil_Dirt_Dry"
    },
    {
      "x": -12,
      "y": 0,
      "z": 12,
      "name": "Soil_Gravel_Sand"
    },
    {
      "x": -12,
      "y": 1,
      "z": 12,
      "name": "Soil_Dirt_Dry"
    },
    {
      "x": -12,
      "y": 2,
      "z": 12,
      "name": "Deco_Bone_Full"
    },
    {
      "x": -12,
      "y": 3,
      "z": 12,
      "name": "Deco_Bone_Full"
    },
    {
      "x": -12,
      "y": 4,
      "z": 12,
      "name": "Deco_Bone_Full"
    },
    {
      "x": -12,
      "y": 0,
      "z": 13,
      "name": "Soil_Gravel_Sand"
    },
    {
      "x": -12,
      "y": 1,
      "z": 13,
      "name": "Soil_Dirt_Dry"
    },
    {
      "x": -12,
      "y": 2,
      "z": 13,
      "name": "Deco_Bone_Full"
    },
    {
      "x": -12,
      "y": 3,
      "z": 13,
      "name": "Deco_Bone_Full"
    },
    {
      "x": -12,
      "y": 4,
      "z": 13,
      "name": "Deco_Bone_Full"
    },
    {
      "x": -12,
      "y": 5,
      "z": 13,
      "name": "Deco_Bone_Full"
    },
    {
      "x": -12,
      "y": 0,
      "z": 14,
      "name": "Soil_Gravel_Sand"
    },
    {
      "x": -12,
      "y": 1,
      "z": 14,
      "name": "Soil_Dirt_Dry"
    },
    {
      "x": -12,
      "y": 0,
      "z": 15,
      "name": "Soil_Gravel_Sand"
    },
    {
      "x": -12,
      "y": 1,
      "z": 15,
      "name": "Soil_Dirt_Dry"
    },
    {
      "x": -11,
      "y": 0,
      "z": -15,
      "name": "Soil_Gravel_Sand"
    },
    {
      "x": -11,
      "y": 1,
      "z": -15,
      "name": "Soil_Dirt_Dry"
    },
    {
      "x": -11,
      "y": 0,
      "z": -14,
      "name": "Soil_Gravel_Sand"
    },
    {
      "x": -11,
      "y": 1,
      "z": -14,
      "name": "Soil_Dirt_Dry"
    },
    {
      "x": -11,
      "y": 12,
      "z": -14,
      "name": "*Rock_Sandstone_Red_Cobble_Roof_Hollow_State_Definitions_Corner_Right",
      "rotation": 3
    },
    {
      "x": -11,
      "y": 0,
      "z": -13,
      "name": "Soil_Gravel_Sand"
    },
    {
      "x": -11,
      "y": 1,
      "z": -13,
      "name": "Soil_Dirt_Dry"
    },
    {
      "x": -11,
      "y": 2,
      "z": -13,
      "name": "Rock_Sandstone_Red_Brick"
    },
    {
      "x": -11,
      "y": 3,
      "z": -13,
      "name": "Rock_Sandstone_Red_Brick"
    },
    {
      "x": -11,
      "y": 4,
      "z": -13,
      "name": "Rock_Sandstone_Red_Brick"
    },
    {
      "x": -11,
      "y": 5,
      "z": -13,
      "name": "Rock_Sandstone_Red_Brick"
    },
    {
      "x": -11,
      "y": 6,
      "z": -13,
      "name": "Rock_Sandstone_Red_Brick"
    },
    {
      "x": -11,
      "y": 7,
      "z": -13,
      "name": "Rock_Sandstone_Red_Brick"
    },
    {
      "x": -11,
      "y": 8,
      "z": -13,
      "name": "Rock_Sandstone_Red_Brick"
    },
    {
      "x": -11,
      "y": 9,
      "z": -13,
      "name": "Rock_Sandstone_Red_Brick"
    },
    {
      "x": -11,
      "y": 10,
      "z": -13,
      "name": "Rock_Sandstone_Red_Brick"
    },
    {
      "x": -11,
      "y": 11,
      "z": -13,
      "name": "Rock_Sandstone_Red_Brick"
    },
    {
      "x": -11,
      "y": 12,
      "z": -13,
      "name": "*Rock_Sandstone_Red_Cobble_Roof_State_Definitions_Inverted_Corner_Right",
      "rotation": 3
    },
    {
      "x": -11,
      "y": 0,
      "z": -12,
      "name": "Soil_Gravel_Sand"
    },
    {
      "x": -11,
      "y": 1,
      "z": -12,
      "name": "Soil_Dirt_Dry"
    },
    {
      "x": -11,
      "y": 2,
      "z": -12,
      "name": "Wood_Dry_Trunk"
    },
    {
      "x": -11,
      "y": 3,
      "z": -12,
      "name": "Wood_Dry_Trunk"
    },
    {
      "x": -11,
      "y": 4,
      "z": -12,
      "name": "Wood_Dry_Trunk"
    },
    {
      "x": -11,
      "y": 5,
      "z": -12,
      "name": "Wood_Dry_Trunk"
    },
    {
      "x": -11,
      "y": 6,
      "z": -12,
      "name": "Wood_Dry_Trunk"
    },
    {
      "x": -11,
      "y": 7,
      "z": -12,
      "name": "Wood_Dry_Trunk"
    },
    {
      "x": -11,
      "y": 8,
      "z": -12,
      "name": "Wood_Dry_Trunk"
    },
    {
      "x": -11,
      "y": 9,
      "z": -12,
      "name": "Wood_Dry_Trunk"
    },
    {
      "x": -11,
      "y": 10,
      "z": -12,
      "name": "Wood_Dry_Trunk"
    },
    {
      "x": -11,
      "y": 11,
      "z": -12,
      "name": "Wood_Dry_Trunk"
    },
    {
      "x": -11,
      "y": 12,
      "z": -12,
      "name": "Wood_Dry_Trunk"
    },
    {
      "x": -11,
      "y": 13,
      "z": -12,
      "name": "Wood_Dry_Trunk"
    },
    {
      "x": -11,
      "y": 14,
      "z": -12,
      "name": "Wood_Dry_Trunk",
      "support": 15
    },
    {
      "x": -11,
      "y": 15,
      "z": -12,
      "name": "Wood_Dry_Branch_Long",
      "support": 15
    },
    {
      "x": -11,
      "y": 16,
      "z": -12,
      "name": "Survival_Trap_Spike_Wood_Large"
    },
    {
      "x": -11,
      "y": 0,
      "z": -11,
      "name": "Soil_Gravel_Sand"
    },
    {
      "x": -11,
      "y": 1,
      "z": -11,
      "name": "Soil_Dirt_Dry"
    },
    {
      "x": -11,
      "y": 2,
      "z": -11,
      "name": "Rock_Sandstone"
    },
    {
      "x": -11,
      "y": 3,
      "z": -11,
      "name": "Rock_Sandstone"
    },
    {
      "x": -11,
      "y": 4,
      "z": -11,
      "name": "Rock_Sandstone"
    },
    {
      "x": -11,
      "y": 5,
      "z": -11,
      "name": "Rock_Sandstone"
    },
    {
      "x": -11,
      "y": 6,
      "z": -11,
      "name": "Rock_Sandstone"
    },
    {
      "x": -11,
      "y": 7,
      "z": -11,
      "name": "Rock_Sandstone"
    },
    {
      "x": -11,
      "y": 8,
      "z": -11,
      "name": "Rock_Sandstone"
    },
    {
      "x": -11,
      "y": 9,
      "z": -11,
      "name": "Rock_Sandstone_Cobble"
    },
    {
      "x": -11,
      "y": 10,
      "z": -11,
      "name": "Rock_Sandstone_Red_Cobble"
    },
    {
      "x": -11,
      "y": 11,
      "z": -11,
      "name": "Rock_Sandstone_Red_Cobble"
    },
    {
      "x": -11,
      "y": 12,
      "z": -11,
      "name": "Wood_Dry_Trunk",
      "support": 15,
      "rotation": 4
    },
    {
      "x": -11,
      "y": 13,
      "z": -11,
      "name": "Rock_Sandstone_Red_Cobble_Roof_Flat",
      "rotation": 3
    },
    {
      "x": -11,
      "y": 0,
      "z": -10,
      "name": "Soil_Gravel_Sand"
    },
    {
      "x": -11,
      "y": 1,
      "z": -10,
      "name": "Soil_Dirt_Dry"
    },
    {
      "x": -11,
      "y": 2,
      "z": -10,
      "name": "Rock_Sandstone_Cobble"
    },
    {
      "x": -11,
      "y": 3,
      "z": -10,
      "name": "Rock_Sandstone"
    },
    {
      "x": -11,
      "y": 4,
      "z": -10,
      "name": "Rock_Sandstone"
    },
    {
      "x": -11,
      "y": 5,
      "z": -10,
      "name": "Rock_Sandstone"
    },
    {
      "x": -11,
      "y": 6,
      "z": -10,
      "name": "Rock_Sandstone"
    },
    {
      "x": -11,
      "y": 7,
      "z": -10,
      "name": "Rock_Sandstone_Cobble"
    },
    {
      "x": -11,
      "y": 8,
      "z": -10,
      "name": "Rock_Sandstone_Cobble"
    },
    {
      "x": -11,
      "y": 9,
      "z": -10,
      "name": "Rock_Sandstone"
    },
    {
      "x": -11,
      "y": 10,
      "z": -10,
      "name": "Rock_Sandstone"
    },
    {
      "x": -11,
      "y": 11,
      "z": -10,
      "name": "Rock_Sandstone"
    },
    {
      "x": -11,
      "y": 12,
      "z": -10,
      "name": "Wood_Dry_Trunk",
      "support": 15,
      "rotation": 4
    },
    {
      "x": -11,
      "y": 13,
      "z": -10,
      "name": "Rock_Sandstone_Red_Cobble_Roof_Shallow",
      "rotation": 3
    },
    {
      "x": -11,
      "y": 0,
      "z": -9,
      "name": "Soil_Gravel_Sand"
    },
    {
      "x": -11,
      "y": 1,
      "z": -9,
      "name": "Soil_Dirt_Dry"
    },
    {
      "x": -11,
      "y": 2,
      "z": -9,
      "name": "Rock_Sandstone"
    },
    {
      "x": -11,
      "y": 3,
      "z": -9,
      "name": "Rock_Sandstone_Cobble"
    },
    {
      "x": -11,
      "y": 4,
      "z": -9,
      "name": "Rock_Sandstone"
    },
    {
      "x": -11,
      "y": 5,
      "z": -9,
      "name": "Rock_Sandstone"
    },
    {
      "x": -11,
      "y": 6,
      "z": -9,
      "name": "Rock_Sandstone_Cobble"
    },
    {
      "x": -11,
      "y": 7,
      "z": -9,
      "name": "Rock_Sandstone"
    },
    {
      "x": -11,
      "y": 8,
      "z": -9,
      "name": "Rock_Sandstone_Cobble"
    },
    {
      "x": -11,
      "y": 9,
      "z": -9,
      "name": "Rock_Sandstone"
    },
    {
      "x": -11,
      "y": 10,
      "z": -9,
      "name": "Rock_Sandstone_Cobble"
    },
    {
      "x": -11,
      "y": 11,
      "z": -9,
      "name": "Rock_Sandstone_Cobble"
    },
    {
      "x": -11,
      "y": 12,
      "z": -9,
      "name": "Wood_Dry_Trunk",
      "support": 15,
      "rotation": 4
    },
    {
      "x": -11,
      "y": 13,
      "z": -9,
      "name": "Rock_Sandstone_Red_Cobble_Roof_Shallow",
      "rotation": 3
    },
    {
      "x": -11,
      "y": 0,
      "z": -8,
      "name": "Soil_Gravel_Sand"
    },
    {
      "x": -11,
      "y": 1,
      "z": -8,
      "name": "Soil_Dirt_Dry"
    },
    {
      "x": -11,
      "y": 2,
      "z": -8,
      "name": "Rock_Sandstone_Cobble"
    },
    {
      "x": -11,
      "y": 3,
      "z": -8,
      "name": "Rock_Sandstone"
    },
    {
      "x": -11,
      "y": 4,
      "z": -8,
      "name": "Rock_Sandstone_Cobble"
    },
    {
      "x": -11,
      "y": 5,
      "z": -8,
      "name": "Rock_Sandstone_Cobble"
    },
    {
      "x": -11,
      "y": 6,
      "z": -8,
      "name": "Rock_Sandstone_Cobble"
    },
    {
      "x": -11,
      "y": 7,
      "z": -8,
      "name": "Rock_Sandstone"
    },
    {
      "x": -11,
      "y": 8,
      "z": -8,
      "name": "Rock_Sandstone"
    },
    {
      "x": -11,
      "y": 9,
      "z": -8,
      "name": "Rock_Sandstone"
    },
    {
      "x": -11,
      "y": 10,
      "z": -8,
      "name": "Rock_Sandstone_Cobble"
    },
    {
      "x": -11,
      "y": 11,
      "z": -8,
      "name": "Rock_Sandstone"
    },
    {
      "x": -11,
      "y": 12,
      "z": -8,
      "name": "Wood_Dry_Trunk",
      "support": 15,
      "rotation": 4
    },
    {
      "x": -11,
      "y": 13,
      "z": -8,
      "name": "Rock_Sandstone_Red_Cobble_Roof_Shallow",
      "rotation": 3
    },
    {
      "x": -11,
      "y": 0,
      "z": -7,
      "name": "Soil_Gravel_Sand"
    },
    {
      "x": -11,
      "y": 1,
      "z": -7,
      "name": "Soil_Dirt_Dry"
    },
    {
      "x": -11,
      "y": 2,
      "z": -7,
      "name": "Rock_Sandstone"
    },
    {
      "x": -11,
      "y": 3,
      "z": -7,
      "name": "Rock_Sandstone"
    },
    {
      "x": -11,
      "y": 4,
      "z": -7,
      "name": "Rock_Sandstone"
    },
    {
      "x": -11,
      "y": 5,
      "z": -7,
      "name": "Rock_Sandstone_Cobble"
    },
    {
      "x": -11,
      "y": 6,
      "z": -7,
      "name": "Rock_Sandstone"
    },
    {
      "x": -11,
      "y": 7,
      "z": -7,
      "name": "Rock_Sandstone_Cobble"
    },
    {
      "x": -11,
      "y": 8,
      "z": -7,
      "name": "Rock_Sandstone"
    },
    {
      "x": -11,
      "y": 9,
      "z": -7,
      "name": "Rock_Sandstone_Cobble"
    },
    {
      "x": -11,
      "y": 10,
      "z": -7,
      "name": "Rock_Sandstone"
    },
    {
      "x": -11,
      "y": 11,
      "z": -7,
      "name": "Rock_Sandstone_Cobble"
    },
    {
      "x": -11,
      "y": 12,
      "z": -7,
      "name": "Wood_Dry_Trunk",
      "support": 15,
      "rotation": 4
    },
    {
      "x": -11,
      "y": 13,
      "z": -7,
      "name": "Rock_Sandstone_Red_Cobble_Roof_Shallow",
      "rotation": 3
    },
    {
      "x": -11,
      "y": 0,
      "z": -6,
      "name": "Soil_Gravel_Sand"
    },
    {
      "x": -11,
      "y": 1,
      "z": -6,
      "name": "Soil_Dirt_Dry"
    },
    {
      "x": -11,
      "y": 2,
      "z": -6,
      "name": "Rock_Sandstone_Cobble"
    },
    {
      "x": -11,
      "y": 3,
      "z": -6,
      "name": "Rock_Sandstone"
    },
    {
      "x": -11,
      "y": 4,
      "z": -6,
      "name": "Rock_Sandstone"
    },
    {
      "x": -11,
      "y": 5,
      "z": -6,
      "name": "Rock_Sandstone"
    },
    {
      "x": -11,
      "y": 6,
      "z": -6,
      "name": "Rock_Sandstone"
    },
    {
      "x": -11,
      "y": 7,
      "z": -6,
      "name": "Rock_Sandstone_Cobble"
    },
    {
      "x": -11,
      "y": 8,
      "z": -6,
      "name": "Rock_Sandstone_Cobble"
    },
    {
      "x": -11,
      "y": 9,
      "z": -6,
      "name": "Rock_Sandstone"
    },
    {
      "x": -11,
      "y": 10,
      "z": -6,
      "name": "Rock_Sandstone"
    },
    {
      "x": -11,
      "y": 11,
      "z": -6,
      "name": "Rock_Sandstone_Cobble"
    },
    {
      "x": -11,
      "y": 12,
      "z": -6,
      "name": "Wood_Dry_Trunk",
      "support": 15,
      "rotation": 4
    },
    {
      "x": -11,
      "y": 13,
      "z": -6,
      "name": "Rock_Sandstone_Red_Cobble_Roof_Shallow",
      "rotation": 3
    },
    {
      "x": -11,
      "y": 0,
      "z": -5,
      "name": "Soil_Gravel_Sand"
    },
    {
      "x": -11,
      "y": 1,
      "z": -5,
      "name": "Soil_Dirt_Dry"
    },
    {
      "x": -11,
      "y": 2,
      "z": -5,
      "name": "Rock_Sandstone"
    },
    {
      "x": -11,
      "y": 3,
      "z": -5,
      "name": "Rock_Sandstone"
    },
    {
      "x": -11,
      "y": 4,
      "z": -5,
      "name": "Rock_Sandstone_Cobble"
    },
    {
      "x": -11,
      "y": 5,
      "z": -5,
      "name": "Rock_Sandstone_Cobble"
    },
    {
      "x": -11,
      "y": 6,
      "z": -5,
      "name": "Rock_Sandstone"
    },
    {
      "x": -11,
      "y": 7,
      "z": -5,
      "name": "Rock_Sandstone_Cobble"
    },
    {
      "x": -11,
      "y": 8,
      "z": -5,
      "name": "Rock_Sandstone_Cobble"
    },
    {
      "x": -11,
      "y": 9,
      "z": -5,
      "name": "Rock_Sandstone"
    },
    {
      "x": -11,
      "y": 10,
      "z": -5,
      "name": "Rock_Sandstone_Cobble"
    },
    {
      "x": -11,
      "y": 11,
      "z": -5,
      "name": "Rock_Sandstone_Cobble"
    },
    {
      "x": -11,
      "y": 12,
      "z": -5,
      "name": "Wood_Dry_Trunk",
      "support": 15,
      "rotation": 4
    },
    {
      "x": -11,
      "y": 13,
      "z": -5,
      "name": "Rock_Sandstone_Red_Cobble_Roof_Shallow",
      "rotation": 3
    },
    {
      "x": -11,
      "y": 0,
      "z": -4,
      "name": "Soil_Gravel_Sand"
    },
    {
      "x": -11,
      "y": 1,
      "z": -4,
      "name": "Soil_Dirt_Dry"
    },
    {
      "x": -11,
      "y": 2,
      "z": -4,
      "name": "Rock_Sandstone_Cobble"
    },
    {
      "x": -11,
      "y": 3,
      "z": -4,
      "name": "Rock_Sandstone_Cobble"
    },
    {
      "x": -11,
      "y": 4,
      "z": -4,
      "name": "Rock_Sandstone"
    },
    {
      "x": -11,
      "y": 5,
      "z": -4,
      "name": "Rock_Sandstone"
    },
    {
      "x": -11,
      "y": 6,
      "z": -4,
      "name": "Rock_Sandstone"
    },
    {
      "x": -11,
      "y": 7,
      "z": -4,
      "name": "Rock_Sandstone"
    },
    {
      "x": -11,
      "y": 8,
      "z": -4,
      "name": "Rock_Sandstone"
    },
    {
      "x": -11,
      "y": 9,
      "z": -4,
      "name": "Rock_Sandstone"
    },
    {
      "x": -11,
      "y": 10,
      "z": -4,
      "name": "Rock_Sandstone"
    },
    {
      "x": -11,
      "y": 11,
      "z": -4,
      "name": "Rock_Sandstone"
    },
    {
      "x": -11,
      "y": 12,
      "z": -4,
      "name": "Wood_Dry_Trunk",
      "support": 15,
      "rotation": 4
    },
    {
      "x": -11,
      "y": 13,
      "z": -4,
      "name": "Rock_Sandstone_Red_Cobble_Roof_Shallow",
      "rotation": 3
    },
    {
      "x": -11,
      "y": 0,
      "z": -3,
      "name": "Soil_Gravel_Sand"
    },
    {
      "x": -11,
      "y": 1,
      "z": -3,
      "name": "Soil_Dirt_Dry"
    },
    {
      "x": -11,
      "y": 2,
      "z": -3,
      "name": "Rock_Sandstone_Cobble"
    },
    {
      "x": -11,
      "y": 3,
      "z": -3,
      "name": "Rock_Sandstone_Cobble"
    },
    {
      "x": -11,
      "y": 4,
      "z": -3,
      "name": "Rock_Sandstone"
    },
    {
      "x": -11,
      "y": 5,
      "z": -3,
      "name": "Rock_Sandstone"
    },
    {
      "x": -11,
      "y": 6,
      "z": -3,
      "name": "Rock_Sandstone"
    },
    {
      "x": -11,
      "y": 7,
      "z": -3,
      "name": "Rock_Sandstone"
    },
    {
      "x": -11,
      "y": 8,
      "z": -3,
      "name": "Rock_Sandstone"
    },
    {
      "x": -11,
      "y": 9,
      "z": -3,
      "name": "Rock_Sandstone_Cobble"
    },
    {
      "x": -11,
      "y": 10,
      "z": -3,
      "name": "Rock_Sandstone_Cobble"
    },
    {
      "x": -11,
      "y": 11,
      "z": -3,
      "name": "Rock_Sandstone"
    },
    {
      "x": -11,
      "y": 12,
      "z": -3,
      "name": "Wood_Dry_Trunk",
      "support": 15,
      "rotation": 4
    },
    {
      "x": -11,
      "y": 13,
      "z": -3,
      "name": "Rock_Sandstone_Red_Cobble_Roof_Shallow",
      "rotation": 3
    },
    {
      "x": -11,
      "y": 0,
      "z": -2,
      "name": "Soil_Gravel_Sand"
    },
    {
      "x": -11,
      "y": 1,
      "z": -2,
      "name": "Soil_Dirt_Dry"
    },
    {
      "x": -11,
      "y": 2,
      "z": -2,
      "name": "Rock_Sandstone"
    },
    {
      "x": -11,
      "y": 3,
      "z": -2,
      "name": "Rock_Sandstone_Cobble"
    },
    {
      "x": -11,
      "y": 4,
      "z": -2,
      "name": "Rock_Sandstone_Cobble"
    },
    {
      "x": -11,
      "y": 5,
      "z": -2,
      "name": "Rock_Sandstone"
    },
    {
      "x": -11,
      "y": 6,
      "z": -2,
      "name": "Rock_Sandstone"
    },
    {
      "x": -11,
      "y": 7,
      "z": -2,
      "name": "Rock_Sandstone"
    },
    {
      "x": -11,
      "y": 8,
      "z": -2,
      "name": "Rock_Sandstone"
    },
    {
      "x": -11,
      "y": 9,
      "z": -2,
      "name": "Rock_Sandstone"
    },
    {
      "x": -11,
      "y": 10,
      "z": -2,
      "name": "Rock_Sandstone_Cobble"
    },
    {
      "x": -11,
      "y": 11,
      "z": -2,
      "name": "Rock_Sandstone"
    },
    {
      "x": -11,
      "y": 12,
      "z": -2,
      "name": "Wood_Dry_Trunk",
      "support": 15,
      "rotation": 4
    },
    {
      "x": -11,
      "y": 13,
      "z": -2,
      "name": "Rock_Sandstone_Red_Cobble_Roof_Shallow",
      "rotation": 3
    },
    {
      "x": -11,
      "y": 0,
      "z": -1,
      "name": "Soil_Gravel_Sand"
    },
    {
      "x": -11,
      "y": 1,
      "z": -1,
      "name": "Soil_Dirt_Dry"
    },
    {
      "x": -11,
      "y": 2,
      "z": -1,
      "name": "Rock_Sandstone_Cobble"
    },
    {
      "x": -11,
      "y": 3,
      "z": -1,
      "name": "Rock_Sandstone_Cobble"
    },
    {
      "x": -11,
      "y": 4,
      "z": -1,
      "name": "Rock_Sandstone"
    },
    {
      "x": -11,
      "y": 5,
      "z": -1,
      "name": "Rock_Sandstone"
    },
    {
      "x": -11,
      "y": 6,
      "z": -1,
      "name": "Rock_Sandstone"
    },
    {
      "x": -11,
      "y": 7,
      "z": -1,
      "name": "Rock_Sandstone_Cobble"
    },
    {
      "x": -11,
      "y": 8,
      "z": -1,
      "name": "Rock_Sandstone"
    },
    {
      "x": -11,
      "y": 9,
      "z": -1,
      "name": "Rock_Sandstone"
    },
    {
      "x": -11,
      "y": 10,
      "z": -1,
      "name": "Rock_Sandstone_Cobble"
    },
    {
      "x": -11,
      "y": 11,
      "z": -1,
      "name": "Rock_Sandstone_Cobble"
    },
    {
      "x": -11,
      "y": 12,
      "z": -1,
      "name": "Wood_Dry_Trunk",
      "support": 15,
      "rotation": 4
    },
    {
      "x": -11,
      "y": 13,
      "z": -1,
      "name": "Rock_Sandstone_Red_Cobble_Roof_Shallow",
      "rotation": 3
    },
    {
      "x": -11,
      "y": 0,
      "z": 0,
      "name": "Soil_Gravel_Sand"
    },
    {
      "x": -11,
      "y": 1,
      "z": 0,
      "name": "Soil_Dirt_Dry"
    },
    {
      "x": -11,
      "y": 2,
      "z": 0,
      "name": "Rock_Sandstone_Red_Cobble"
    },
    {
      "x": -11,
      "y": 3,
      "z": 0,
      "name": "Rock_Sandstone_Red_Cobble"
    },
    {
      "x": -11,
      "y": 4,
      "z": 0,
      "name": "Rock_Sandstone_Red_Cobble"
    },
    {
      "x": -11,
      "y": 5,
      "z": 0,
      "name": "Rock_Sandstone_Red_Cobble"
    },
    {
      "x": -11,
      "y": 6,
      "z": 0,
      "name": "Rock_Sandstone_Red_Cobble"
    },
    {
      "x": -11,
      "y": 7,
      "z": 0,
      "name": "Rock_Sandstone_Red_Cobble"
    },
    {
      "x": -11,
      "y": 8,
      "z": 0,
      "name": "Rock_Sandstone_Red_Cobble"
    },
    {
      "x": -11,
      "y": 9,
      "z": 0,
      "name": "Rock_Sandstone_Red_Cobble"
    },
    {
      "x": -11,
      "y": 10,
      "z": 0,
      "name": "Rock_Sandstone_Red_Cobble"
    },
    {
      "x": -11,
      "y": 11,
      "z": 0,
      "name": "Rock_Sandstone"
    },
    {
      "x": -11,
      "y": 12,
      "z": 0,
      "name": "Wood_Dry_Trunk",
      "support": 15,
      "rotation": 4
    },
    {
      "x": -11,
      "y": 13,
      "z": 0,
      "name": "Rock_Sandstone_Red_Cobble_Roof_Shallow",
      "rotation": 3
    },
    {
      "x": -11,
      "y": 0,
      "z": 1,
      "name": "Soil_Gravel_Sand"
    },
    {
      "x": -11,
      "y": 1,
      "z": 1,
      "name": "Soil_Dirt_Dry"
    },
    {
      "x": -11,
      "y": 2,
      "z": 1,
      "name": "Rock_Sandstone_Red_Cobble"
    },
    {
      "x": -11,
      "y": 3,
      "z": 1,
      "name": "Rock_Sandstone_Red_Cobble"
    },
    {
      "x": -11,
      "y": 4,
      "z": 1,
      "name": "Rock_Sandstone_Red_Cobble"
    },
    {
      "x": -11,
      "y": 5,
      "z": 1,
      "name": "Rock_Sandstone_Red_Cobble"
    },
    {
      "x": -11,
      "y": 6,
      "z": 1,
      "name": "Rock_Sandstone_Red_Cobble"
    },
    {
      "x": -11,
      "y": 7,
      "z": 1,
      "name": "Rock_Sandstone_Red_Cobble"
    },
    {
      "x": -11,
      "y": 8,
      "z": 1,
      "name": "Rock_Sandstone_Red_Cobble"
    },
    {
      "x": -11,
      "y": 9,
      "z": 1,
      "name": "Rock_Sandstone_Red_Cobble"
    },
    {
      "x": -11,
      "y": 10,
      "z": 1,
      "name": "Rock_Sandstone_Red_Cobble"
    },
    {
      "x": -11,
      "y": 11,
      "z": 1,
      "name": "Rock_Sandstone"
    },
    {
      "x": -11,
      "y": 12,
      "z": 1,
      "name": "Wood_Dry_Trunk",
      "support": 15,
      "rotation": 4
    },
    {
      "x": -11,
      "y": 13,
      "z": 1,
      "name": "Rock_Sandstone_Red_Cobble_Roof_Shallow",
      "rotation": 3
    },
    {
      "x": -11,
      "y": 0,
      "z": 2,
      "name": "Soil_Gravel_Sand"
    },
    {
      "x": -11,
      "y": 1,
      "z": 2,
      "name": "Soil_Dirt_Dry"
    },
    {
      "x": -11,
      "y": 2,
      "z": 2,
      "name": "Rock_Sandstone_Red_Cobble"
    },
    {
      "x": -11,
      "y": 3,
      "z": 2,
      "name": "Rock_Sandstone_Red_Cobble"
    },
    {
      "x": -11,
      "y": 4,
      "z": 2,
      "name": "Rock_Sandstone_Red_Cobble"
    },
    {
      "x": -11,
      "y": 5,
      "z": 2,
      "name": "Rock_Sandstone_Red_Cobble"
    },
    {
      "x": -11,
      "y": 6,
      "z": 2,
      "name": "Rock_Sandstone_Red_Cobble"
    },
    {
      "x": -11,
      "y": 7,
      "z": 2,
      "name": "Rock_Sandstone_Red_Cobble"
    },
    {
      "x": -11,
      "y": 8,
      "z": 2,
      "name": "Rock_Sandstone_Red_Cobble"
    },
    {
      "x": -11,
      "y": 9,
      "z": 2,
      "name": "Rock_Sandstone_Red_Cobble"
    },
    {
      "x": -11,
      "y": 10,
      "z": 2,
      "name": "Rock_Sandstone_Red_Cobble"
    },
    {
      "x": -11,
      "y": 11,
      "z": 2,
      "name": "Rock_Sandstone_Red_Cobble"
    },
    {
      "x": -11,
      "y": 12,
      "z": 2,
      "name": "Wood_Dry_Trunk",
      "support": 15,
      "rotation": 4
    },
    {
      "x": -11,
      "y": 0,
      "z": 3,
      "name": "Soil_Gravel_Sand"
    },
    {
      "x": -11,
      "y": 1,
      "z": 3,
      "name": "Soil_Dirt_Dry"
    },
    {
      "x": -11,
      "y": 2,
      "z": 3,
      "name": "Wood_Dry_Trunk"
    },
    {
      "x": -11,
      "y": 3,
      "z": 3,
      "name": "Wood_Dry_Trunk"
    },
    {
      "x": -11,
      "y": 4,
      "z": 3,
      "name": "Wood_Dry_Trunk"
    },
    {
      "x": -11,
      "y": 5,
      "z": 3,
      "name": "Wood_Dry_Trunk"
    },
    {
      "x": -11,
      "y": 6,
      "z": 3,
      "name": "Wood_Dry_Trunk"
    },
    {
      "x": -11,
      "y": 7,
      "z": 3,
      "name": "Wood_Dry_Trunk"
    },
    {
      "x": -11,
      "y": 8,
      "z": 3,
      "name": "Wood_Dry_Trunk"
    },
    {
      "x": -11,
      "y": 9,
      "z": 3,
      "name": "Wood_Dry_Trunk"
    },
    {
      "x": -11,
      "y": 10,
      "z": 3,
      "name": "Wood_Dry_Trunk"
    },
    {
      "x": -11,
      "y": 11,
      "z": 3,
      "name": "Wood_Dry_Trunk"
    },
    {
      "x": -11,
      "y": 12,
      "z": 3,
      "name": "Wood_Dry_Trunk"
    },
    {
      "x": -11,
      "y": 13,
      "z": 3,
      "name": "Wood_Dry_Trunk"
    },
    {
      "x": -11,
      "y": 14,
      "z": 3,
      "name": "Wood_Dry_Trunk",
      "support": 15
    },
    {
      "x": -11,
      "y": 15,
      "z": 3,
      "name": "Wood_Dry_Branch_Long",
      "support": 15
    },
    {
      "x": -11,
      "y": 16,
      "z": 3,
      "name": "Survival_Trap_Spike_Wood_Large"
    },
    {
      "x": -11,
      "y": 0,
      "z": 4,
      "name": "Soil_Gravel_Sand"
    },
    {
      "x": -11,
      "y": 1,
      "z": 4,
      "name": "Soil_Dirt_Dry"
    },
    {
      "x": -11,
      "y": 2,
      "z": 4,
      "name": "Rock_Sandstone_Red_Brick"
    },
    {
      "x": -11,
      "y": 3,
      "z": 4,
      "name": "Rock_Sandstone_Red_Brick"
    },
    {
      "x": -11,
      "y": 4,
      "z": 4,
      "name": "Rock_Sandstone_Red_Brick"
    },
    {
      "x": -11,
      "y": 5,
      "z": 4,
      "name": "Rock_Sandstone_Red_Brick"
    },
    {
      "x": -11,
      "y": 6,
      "z": 4,
      "name": "Rock_Sandstone_Red_Brick"
    },
    {
      "x": -11,
      "y": 7,
      "z": 4,
      "name": "Rock_Sandstone_Red_Brick"
    },
    {
      "x": -11,
      "y": 8,
      "z": 4,
      "name": "Rock_Sandstone_Red_Brick"
    },
    {
      "x": -11,
      "y": 9,
      "z": 4,
      "name": "Rock_Sandstone_Red_Brick"
    },
    {
      "x": -11,
      "y": 10,
      "z": 4,
      "name": "Rock_Sandstone_Red_Brick"
    },
    {
      "x": -11,
      "y": 11,
      "z": 4,
      "name": "Rock_Sandstone_Red_Brick"
    },
    {
      "x": -11,
      "y": 12,
      "z": 4,
      "name": "*Rock_Sandstone_Red_Cobble_Roof_State_Definitions_Inverted_Corner_Right"
    },
    {
      "x": -11,
      "y": 0,
      "z": 5,
      "name": "Soil_Gravel_Sand"
    },
    {
      "x": -11,
      "y": 1,
      "z": 5,
      "name": "Soil_Dirt_Dry"
    },
    {
      "x": -11,
      "y": 12,
      "z": 5,
      "name": "*Rock_Sandstone_Red_Cobble_Roof_Hollow_State_Definitions_Corner_Left",
      "rotation": 3
    },
    {
      "x": -11,
      "y": 0,
      "z": 6,
      "name": "Soil_Gravel_Sand"
    },
    {
      "x": -11,
      "y": 1,
      "z": 6,
      "name": "Soil_Dirt_Dry"
    },
    {
      "x": -11,
      "y": 0,
      "z": 7,
      "name": "Soil_Gravel_Sand"
    },
    {
      "x": -11,
      "y": 1,
      "z": 7,
      "name": "Soil_Dirt_Dry"
    },
    {
      "x": -11,
      "y": 0,
      "z": 8,
      "name": "Soil_Gravel_Sand"
    },
    {
      "x": -11,
      "y": 1,
      "z": 8,
      "name": "Soil_Dirt_Dry"
    },
    {
      "x": -11,
      "y": 2,
      "z": 8,
      "name": "Deco_Bone_Full"
    },
    {
      "x": -11,
      "y": 3,
      "z": 8,
      "name": "Deco_Bone_Full"
    },
    {
      "x": -11,
      "y": 0,
      "z": 9,
      "name": "Soil_Gravel_Sand"
    },
    {
      "x": -11,
      "y": 1,
      "z": 9,
      "name": "Soil_Dirt_Dry"
    },
    {
      "x": -11,
      "y": 2,
      "z": 9,
      "name": "Deco_Bone_Full"
    },
    {
      "x": -11,
      "y": 3,
      "z": 9,
      "name": "Deco_Bone_Full"
    },
    {
      "x": -11,
      "y": 4,
      "z": 9,
      "name": "Deco_Bone_Full"
    },
    {
      "x": -11,
      "y": 5,
      "z": 9,
      "name": "Deco_Bone_Spike"
    },
    {
      "x": -11,
      "y": 0,
      "z": 10,
      "name": "Soil_Gravel_Sand"
    },
    {
      "x": -11,
      "y": 1,
      "z": 10,
      "name": "Soil_Dirt_Dry"
    },
    {
      "x": -11,
      "y": 0,
      "z": 11,
      "name": "Soil_Gravel_Sand"
    },
    {
      "x": -11,
      "y": 1,
      "z": 11,
      "name": "Soil_Dirt_Dry"
    },
    {
      "x": -11,
      "y": 0,
      "z": 12,
      "name": "Soil_Gravel_Sand"
    },
    {
      "x": -11,
      "y": 1,
      "z": 12,
      "name": "Soil_Dirt_Dry"
    },
    {
      "x": -11,
      "y": 0,
      "z": 13,
      "name": "Soil_Gravel_Sand"
    },
    {
      "x": -11,
      "y": 1,
      "z": 13,
      "name": "Soil_Dirt_Dry"
    },
    {
      "x": -11,
      "y": 0,
      "z": 14,
      "name": "Soil_Gravel_Sand"
    },
    {
      "x": -11,
      "y": 1,
      "z": 14,
      "name": "Soil_Dirt_Dry"
    },
    {
      "x": -11,
      "y": 0,
      "z": 15,
      "name": "Soil_Gravel_Sand"
    },
    {
      "x": -11,
      "y": 1,
      "z": 15,
      "name": "Soil_Dirt_Dry"
    },
    {
      "x": -10,
      "y": 0,
      "z": -15,
      "name": "Soil_Gravel_Sand"
    },
    {
      "x": -10,
      "y": 1,
      "z": -15,
      "name": "Soil_Dirt_Dry"
    },
    {
      "x": -10,
      "y": 0,
      "z": -14,
      "name": "Soil_Gravel_Sand"
    },
    {
      "x": -10,
      "y": 1,
      "z": -14,
      "name": "Soil_Dirt_Dry"
    },
    {
      "x": -10,
      "y": 11,
      "z": -14,
      "name": "Rock_Sandstone_Red_Brick_Half",
      "rotation": 6
    },
    {
      "x": -10,
      "y": 12,
      "z": -14,
      "name": "Rock_Sandstone_Red_Cobble_Roof_Hollow",
      "rotation": 2
    },
    {
      "x": -10,
      "y": 0,
      "z": -13,
      "name": "Soil_Gravel_Sand"
    },
    {
      "x": -10,
      "y": 1,
      "z": -13,
      "name": "Soil_Dirt_Dry"
    },
    {
      "x": -10,
      "y": 2,
      "z": -13,
      "name": "Wood_Dry_Trunk"
    },
    {
      "x": -10,
      "y": 3,
      "z": -13,
      "name": "Wood_Dry_Trunk"
    },
    {
      "x": -10,
      "y": 4,
      "z": -13,
      "name": "Wood_Dry_Trunk"
    },
    {
      "x": -10,
      "y": 5,
      "z": -13,
      "name": "Wood_Dry_Trunk"
    },
    {
      "x": -10,
      "y": 6,
      "z": -13,
      "name": "Wood_Dry_Trunk"
    },
    {
      "x": -10,
      "y": 7,
      "z": -13,
      "name": "Wood_Dry_Trunk"
    },
    {
      "x": -10,
      "y": 8,
      "z": -13,
      "name": "Wood_Dry_Trunk"
    },
    {
      "x": -10,
      "y": 9,
      "z": -13,
      "name": "Wood_Dry_Trunk"
    },
    {
      "x": -10,
      "y": 10,
      "z": -13,
      "name": "Wood_Dry_Trunk"
    },
    {
      "x": -10,
      "y": 11,
      "z": -13,
      "name": "Wood_Dry_Trunk"
    },
    {
      "x": -10,
      "y": 12,
      "z": -13,
      "name": "Wood_Dry_Trunk"
    },
    {
      "x": -10,
      "y": 13,
      "z": -13,
      "name": "Wood_Dry_Trunk"
    },
    {
      "x": -10,
      "y": 14,
      "z": -13,
      "name": "Wood_Dry_Trunk",
      "support": 15
    },
    {
      "x": -10,
      "y": 15,
      "z": -13,
      "name": "Wood_Dry_Branch_Long",
      "support": 15
    },
    {
      "x": -10,
      "y": 16,
      "z": -13,
      "name": "Survival_Trap_Spike_Wood_Large"
    },
    {
      "x": -10,
      "y": 0,
      "z": -12,
      "name": "Soil_Gravel_Sand"
    },
    {
      "x": -10,
      "y": 1,
      "z": -12,
      "name": "Soil_Dirt_Dry"
    },
    {
      "x": -10,
      "y": 2,
      "z": -12,
      "name": "Wood_Dry_Trunk"
    },
    {
      "x": -10,
      "y": 3,
      "z": -12,
      "name": "Wood_Dry_Trunk"
    },
    {
      "x": -10,
      "y": 4,
      "z": -12,
      "name": "Wood_Dry_Trunk"
    },
    {
      "x": -10,
      "y": 5,
      "z": -12,
      "name": "Wood_Dry_Trunk"
    },
    {
      "x": -10,
      "y": 6,
      "z": -12,
      "name": "Wood_Dry_Trunk"
    },
    {
      "x": -10,
      "y": 7,
      "z": -12,
      "name": "Wood_Dry_Trunk"
    },
    {
      "x": -10,
      "y": 8,
      "z": -12,
      "name": "Wood_Dry_Trunk"
    },
    {
      "x": -10,
      "y": 9,
      "z": -12,
      "name": "Wood_Dry_Trunk"
    },
    {
      "x": -10,
      "y": 10,
      "z": -12,
      "name": "Wood_Dry_Trunk"
    },
    {
      "x": -10,
      "y": 11,
      "z": -12,
      "name": "Wood_Dry_Trunk"
    },
    {
      "x": -10,
      "y": 12,
      "z": -12,
      "name": "Wood_Dry_Trunk"
    },
    {
      "x": -10,
      "y": 13,
      "z": -12,
      "name": "Wood_Dry_Trunk"
    },
    {
      "x": -10,
      "y": 14,
      "z": -12,
      "name": "Wood_Dry_Trunk",
      "support": 15
    },
    {
      "x": -10,
      "y": 15,
      "z": -12,
      "name": "Wood_Dry_Trunk",
      "support": 15
    },
    {
      "x": -10,
      "y": 16,
      "z": -12,
      "name": "Furniture_Village_Brazier"
    },
    {
      "x": -10,
      "y": 0,
      "z": -11,
      "name": "Soil_Gravel_Sand"
    },
    {
      "x": -10,
      "y": 1,
      "z": -11,
      "name": "Soil_Dirt_Dry"
    },
    {
      "x": -10,
      "y": 2,
      "z": -11,
      "name": "Wood_Dry_Trunk"
    },
    {
      "x": -10,
      "y": 3,
      "z": -11,
      "name": "Wood_Dry_Trunk"
    },
    {
      "x": -10,
      "y": 4,
      "z": -11,
      "name": "Wood_Dry_Trunk"
    },
    {
      "x": -10,
      "y": 5,
      "z": -11,
      "name": "Wood_Dry_Trunk"
    },
    {
      "x": -10,
      "y": 6,
      "z": -11,
      "name": "Wood_Dry_Trunk"
    },
    {
      "x": -10,
      "y": 7,
      "z": -11,
      "name": "Wood_Dry_Trunk"
    },
    {
      "x": -10,
      "y": 8,
      "z": -11,
      "name": "Wood_Dry_Trunk"
    },
    {
      "x": -10,
      "y": 9,
      "z": -11,
      "name": "Wood_Dry_Trunk"
    },
    {
      "x": -10,
      "y": 10,
      "z": -11,
      "name": "Wood_Dry_Trunk"
    },
    {
      "x": -10,
      "y": 11,
      "z": -11,
      "name": "Wood_Dry_Trunk"
    },
    {
      "x": -10,
      "y": 12,
      "z": -11,
      "name": "Wood_Dry_Trunk"
    },
    {
      "x": -10,
      "y": 13,
      "z": -11,
      "name": "Wood_Dry_Trunk"
    },
    {
      "x": -10,
      "y": 14,
      "z": -11,
      "name": "Wood_Dry_Trunk",
      "support": 15
    },
    {
      "x": -10,
      "y": 15,
      "z": -11,
      "name": "Wood_Dry_Branch_Long",
      "support": 15
    },
    {
      "x": -10,
      "y": 16,
      "z": -11,
      "name": "Survival_Trap_Spike_Wood_Large"
    },
    {
      "x": -10,
      "y": 0,
      "z": -10,
      "name": "Soil_Gravel_Sand"
    },
    {
      "x": -10,
      "y": 1,
      "z": -10,
      "name": "Soil_Dirt_Dry"
    },
    {
      "x": -10,
      "y": 2,
      "z": -10,
      "name": "Rock_Sandstone"
    },
    {
      "x": -10,
      "y": 3,
      "z": -10,
      "name": "Rock_Sandstone"
    },
    {
      "x": -10,
      "y": 4,
      "z": -10,
      "name": "Rock_Sandstone"
    },
    {
      "x": -10,
      "y": 5,
      "z": -10,
      "name": "Rock_Sandstone"
    },
    {
      "x": -10,
      "y": 6,
      "z": -10,
      "name": "Rock_Sandstone"
    },
    {
      "x": -10,
      "y": 7,
      "z": -10,
      "name": "Rock_Sandstone"
    },
    {
      "x": -10,
      "y": 8,
      "z": -10,
      "name": "Rock_Sandstone"
    },
    {
      "x": -10,
      "y": 9,
      "z": -10,
      "name": "Rock_Sandstone"
    },
    {
      "x": -10,
      "y": 10,
      "z": -10,
      "name": "Rock_Sandstone_Cobble"
    },
    {
      "x": -10,
      "y": 11,
      "z": -10,
      "name": "Rock_Sandstone_Cobble"
    },
    {
      "x": -10,
      "y": 12,
      "z": -10,
      "name": "Wood_Dry_Trunk",
      "support": 15,
      "rotation": 4
    },
    {
      "x": -10,
      "y": 13,
      "z": -10,
      "name": "Rock_Sandstone_Red_Cobble_Roof_Shallow",
      "filler": 1,
      "rotation": 3
    },
    {
      "x": -10,
      "y": 0,
      "z": -9,
      "name": "Soil_Gravel_Sand"
    },
    {
      "x": -10,
      "y": 1,
      "z": -9,
      "name": "Soil_Dirt_Dry"
    },
    {
      "x": -10,
      "y": 2,
      "z": -9,
      "name": "Rock_Sandstone_Cobble"
    },
    {
      "x": -10,
      "y": 3,
      "z": -9,
      "name": "Rock_Sandstone"
    },
    {
      "x": -10,
      "y": 4,
      "z": -9,
      "name": "Rock_Sandstone_Cobble"
    },
    {
      "x": -10,
      "y": 5,
      "z": -9,
      "name": "Rock_Sandstone"
    },
    {
      "x": -10,
      "y": 6,
      "z": -9,
      "name": "Rock_Sandstone"
    },
    {
      "x": -10,
      "y": 7,
      "z": -9,
      "name": "Rock_Sandstone"
    },
    {
      "x": -10,
      "y": 8,
      "z": -9,
      "name": "Rock_Sandstone"
    },
    {
      "x": -10,
      "y": 9,
      "z": -9,
      "name": "Rock_Sandstone"
    },
    {
      "x": -10,
      "y": 10,
      "z": -9,
      "name": "Rock_Sandstone"
    },
    {
      "x": -10,
      "y": 11,
      "z": -9,
      "name": "Rock_Sandstone"
    },
    {
      "x": -10,
      "y": 12,
      "z": -9,
      "name": "Wood_Dry_Trunk",
      "support": 15,
      "rotation": 4
    },
    {
      "x": -10,
      "y": 13,
      "z": -9,
      "name": "Rock_Sandstone_Red_Cobble_Roof_Shallow",
      "filler": 1,
      "rotation": 3
    },
    {
      "x": -10,
      "y": 0,
      "z": -8,
      "name": "Soil_Gravel_Sand"
    },
    {
      "x": -10,
      "y": 1,
      "z": -8,
      "name": "Soil_Dirt_Dry"
    },
    {
      "x": -10,
      "y": 2,
      "z": -8,
      "name": "Rock_Sandstone"
    },
    {
      "x": -10,
      "y": 3,
      "z": -8,
      "name": "Rock_Sandstone_Cobble"
    },
    {
      "x": -10,
      "y": 4,
      "z": -8,
      "name": "Rock_Sandstone"
    },
    {
      "x": -10,
      "y": 5,
      "z": -8,
      "name": "Rock_Sandstone_Cobble"
    },
    {
      "x": -10,
      "y": 6,
      "z": -8,
      "name": "Rock_Sandstone"
    },
    {
      "x": -10,
      "y": 7,
      "z": -8,
      "name": "Rock_Sandstone_Cobble"
    },
    {
      "x": -10,
      "y": 8,
      "z": -8,
      "name": "Rock_Sandstone"
    },
    {
      "x": -10,
      "y": 9,
      "z": -8,
      "name": "Rock_Sandstone_Cobble"
    },
    {
      "x": -10,
      "y": 10,
      "z": -8,
      "name": "Rock_Sandstone"
    },
    {
      "x": -10,
      "y": 11,
      "z": -8,
      "name": "Rock_Sandstone"
    },
    {
      "x": -10,
      "y": 12,
      "z": -8,
      "name": "Wood_Dry_Trunk",
      "support": 15,
      "rotation": 4
    },
    {
      "x": -10,
      "y": 13,
      "z": -8,
      "name": "Rock_Sandstone_Red_Cobble_Roof_Shallow",
      "filler": 1,
      "rotation": 3
    },
    {
      "x": -10,
      "y": 0,
      "z": -7,
      "name": "Soil_Gravel_Sand"
    },
    {
      "x": -10,
      "y": 1,
      "z": -7,
      "name": "Soil_Dirt_Dry"
    },
    {
      "x": -10,
      "y": 2,
      "z": -7,
      "name": "Rock_Sandstone_Cobble"
    },
    {
      "x": -10,
      "y": 3,
      "z": -7,
      "name": "Rock_Sandstone"
    },
    {
      "x": -10,
      "y": 4,
      "z": -7,
      "name": "Rock_Sandstone"
    },
    {
      "x": -10,
      "y": 5,
      "z": -7,
      "name": "Rock_Sandstone_Cobble"
    },
    {
      "x": -10,
      "y": 6,
      "z": -7,
      "name": "Rock_Sandstone"
    },
    {
      "x": -10,
      "y": 7,
      "z": -7,
      "name": "Rock_Sandstone"
    },
    {
      "x": -10,
      "y": 8,
      "z": -7,
      "name": "Rock_Sandstone"
    },
    {
      "x": -10,
      "y": 9,
      "z": -7,
      "name": "Rock_Sandstone"
    },
    {
      "x": -10,
      "y": 10,
      "z": -7,
      "name": "Rock_Sandstone"
    },
    {
      "x": -10,
      "y": 11,
      "z": -7,
      "name": "Rock_Sandstone"
    },
    {
      "x": -10,
      "y": 12,
      "z": -7,
      "name": "Wood_Dry_Trunk",
      "support": 15,
      "rotation": 4
    },
    {
      "x": -10,
      "y": 13,
      "z": -7,
      "name": "Rock_Sandstone_Red_Cobble_Roof_Shallow",
      "filler": 1,
      "rotation": 3
    },
    {
      "x": -10,
      "y": 0,
      "z": -6,
      "name": "Soil_Gravel_Sand"
    },
    {
      "x": -10,
      "y": 1,
      "z": -6,
      "name": "Soil_Dirt_Dry"
    },
    {
      "x": -10,
      "y": 2,
      "z": -6,
      "name": "Rock_Sandstone_Cobble"
    },
    {
      "x": -10,
      "y": 3,
      "z": -6,
      "name": "Rock_Sandstone_Cobble"
    },
    {
      "x": -10,
      "y": 4,
      "z": -6,
      "name": "Rock_Sandstone"
    },
    {
      "x": -10,
      "y": 5,
      "z": -6,
      "name": "Rock_Sandstone_Cobble"
    },
    {
      "x": -10,
      "y": 6,
      "z": -6,
      "name": "Rock_Sandstone_Cobble"
    },
    {
      "x": -10,
      "y": 7,
      "z": -6,
      "name": "Rock_Sandstone"
    },
    {
      "x": -10,
      "y": 8,
      "z": -6,
      "name": "Rock_Sandstone"
    },
    {
      "x": -10,
      "y": 9,
      "z": -6,
      "name": "Rock_Sandstone_Cobble"
    },
    {
      "x": -10,
      "y": 10,
      "z": -6,
      "name": "Rock_Sandstone"
    },
    {
      "x": -10,
      "y": 11,
      "z": -6,
      "name": "Rock_Sandstone_Cobble"
    },
    {
      "x": -10,
      "y": 12,
      "z": -6,
      "name": "Wood_Dry_Trunk",
      "support": 15,
      "rotation": 4
    },
    {
      "x": -10,
      "y": 13,
      "z": -6,
      "name": "Rock_Sandstone_Red_Cobble_Roof_Shallow",
      "filler": 1,
      "rotation": 3
    },
    {
      "x": -10,
      "y": 0,
      "z": -5,
      "name": "Soil_Gravel_Sand"
    },
    {
      "x": -10,
      "y": 1,
      "z": -5,
      "name": "Soil_Dirt_Dry"
    },
    {
      "x": -10,
      "y": 2,
      "z": -5,
      "name": "Rock_Sandstone"
    },
    {
      "x": -10,
      "y": 3,
      "z": -5,
      "name": "Rock_Sandstone"
    },
    {
      "x": -10,
      "y": 4,
      "z": -5,
      "name": "Rock_Sandstone"
    },
    {
      "x": -10,
      "y": 5,
      "z": -5,
      "name": "Rock_Sandstone"
    },
    {
      "x": -10,
      "y": 6,
      "z": -5,
      "name": "Rock_Sandstone"
    },
    {
      "x": -10,
      "y": 7,
      "z": -5,
      "name": "Rock_Sandstone"
    },
    {
      "x": -10,
      "y": 8,
      "z": -5,
      "name": "Rock_Sandstone"
    },
    {
      "x": -10,
      "y": 9,
      "z": -5,
      "name": "Rock_Sandstone_Cobble"
    },
    {
      "x": -10,
      "y": 10,
      "z": -5,
      "name": "Rock_Sandstone"
    },
    {
      "x": -10,
      "y": 11,
      "z": -5,
      "name": "Rock_Sandstone"
    },
    {
      "x": -10,
      "y": 12,
      "z": -5,
      "name": "Wood_Dry_Trunk",
      "support": 15,
      "rotation": 4
    },
    {
      "x": -10,
      "y": 13,
      "z": -5,
      "name": "Rock_Sandstone_Red_Cobble_Roof_Shallow",
      "filler": 1,
      "rotation": 3
    },
    {
      "x": -10,
      "y": 0,
      "z": -4,
      "name": "Soil_Gravel_Sand"
    },
    {
      "x": -10,
      "y": 1,
      "z": -4,
      "name": "Soil_Dirt_Dry"
    },
    {
      "x": -10,
      "y": 2,
      "z": -4,
      "name": "Rock_Sandstone"
    },
    {
      "x": -10,
      "y": 3,
      "z": -4,
      "name": "Rock_Sandstone"
    },
    {
      "x": -10,
      "y": 4,
      "z": -4,
      "name": "Rock_Sandstone"
    },
    {
      "x": -10,
      "y": 5,
      "z": -4,
      "name": "Rock_Sandstone_Cobble"
    },
    {
      "x": -10,
      "y": 6,
      "z": -4,
      "name": "Rock_Sandstone"
    },
    {
      "x": -10,
      "y": 7,
      "z": -4,
      "name": "Rock_Sandstone_Cobble"
    },
    {
      "x": -10,
      "y": 8,
      "z": -4,
      "name": "Rock_Sandstone_Cobble"
    },
    {
      "x": -10,
      "y": 9,
      "z": -4,
      "name": "Rock_Sandstone"
    },
    {
      "x": -10,
      "y": 10,
      "z": -4,
      "name": "Rock_Sandstone"
    },
    {
      "x": -10,
      "y": 11,
      "z": -4,
      "name": "Rock_Sandstone_Cobble"
    },
    {
      "x": -10,
      "y": 12,
      "z": -4,
      "name": "Wood_Dry_Trunk",
      "support": 15,
      "rotation": 4
    },
    {
      "x": -10,
      "y": 13,
      "z": -4,
      "name": "Rock_Sandstone_Red_Cobble_Roof_Shallow",
      "filler": 1,
      "rotation": 3
    },
    {
      "x": -10,
      "y": 0,
      "z": -3,
      "name": "Soil_Gravel_Sand"
    },
    {
      "x": -10,
      "y": 1,
      "z": -3,
      "name": "Soil_Dirt_Dry"
    },
    {
      "x": -10,
      "y": 2,
      "z": -3,
      "name": "Rock_Sandstone_Cobble"
    },
    {
      "x": -10,
      "y": 3,
      "z": -3,
      "name": "Rock_Sandstone"
    },
    {
      "x": -10,
      "y": 4,
      "z": -3,
      "name": "Rock_Sandstone"
    },
    {
      "x": -10,
      "y": 5,
      "z": -3,
      "name": "Rock_Sandstone"
    },
    {
      "x": -10,
      "y": 6,
      "z": -3,
      "name": "Rock_Sandstone_Cobble"
    },
    {
      "x": -10,
      "y": 7,
      "z": -3,
      "name": "Rock_Sandstone_Cobble"
    },
    {
      "x": -10,
      "y": 8,
      "z": -3,
      "name": "Rock_Sandstone_Cobble"
    },
    {
      "x": -10,
      "y": 9,
      "z": -3,
      "name": "Rock_Sandstone"
    },
    {
      "x": -10,
      "y": 10,
      "z": -3,
      "name": "Rock_Sandstone"
    },
    {
      "x": -10,
      "y": 11,
      "z": -3,
      "name": "Rock_Sandstone"
    },
    {
      "x": -10,
      "y": 12,
      "z": -3,
      "name": "Wood_Dry_Trunk",
      "support": 15,
      "rotation": 4
    },
    {
      "x": -10,
      "y": 13,
      "z": -3,
      "name": "Rock_Sandstone_Red_Cobble_Roof_Shallow",
      "filler": 1,
      "rotation": 3
    },
    {
      "x": -10,
      "y": 0,
      "z": -2,
      "name": "Soil_Gravel_Sand"
    },
    {
      "x": -10,
      "y": 1,
      "z": -2,
      "name": "Soil_Dirt_Dry"
    },
    {
      "x": -10,
      "y": 2,
      "z": -2,
      "name": "Rock_Sandstone"
    },
    {
      "x": -10,
      "y": 3,
      "z": -2,
      "name": "Rock_Sandstone"
    },
    {
      "x": -10,
      "y": 4,
      "z": -2,
      "name": "Rock_Sandstone"
    },
    {
      "x": -10,
      "y": 5,
      "z": -2,
      "name": "Rock_Sandstone"
    },
    {
      "x": -10,
      "y": 6,
      "z": -2,
      "name": "Rock_Sandstone_Cobble"
    },
    {
      "x": -10,
      "y": 7,
      "z": -2,
      "name": "Rock_Sandstone"
    },
    {
      "x": -10,
      "y": 8,
      "z": -2,
      "name": "Rock_Sandstone"
    },
    {
      "x": -10,
      "y": 9,
      "z": -2,
      "name": "Rock_Sandstone"
    },
    {
      "x": -10,
      "y": 10,
      "z": -2,
      "name": "Rock_Sandstone"
    },
    {
      "x": -10,
      "y": 11,
      "z": -2,
      "name": "Rock_Sandstone"
    },
    {
      "x": -10,
      "y": 12,
      "z": -2,
      "name": "Wood_Dry_Trunk",
      "support": 15,
      "rotation": 4
    },
    {
      "x": -10,
      "y": 13,
      "z": -2,
      "name": "Rock_Sandstone_Red_Cobble_Roof_Shallow",
      "filler": 1,
      "rotation": 3
    },
    {
      "x": -10,
      "y": 0,
      "z": -1,
      "name": "Soil_Gravel_Sand"
    },
    {
      "x": -10,
      "y": 1,
      "z": -1,
      "name": "Soil_Dirt_Dry"
    },
    {
      "x": -10,
      "y": 2,
      "z": -1,
      "name": "Rock_Sandstone"
    },
    {
      "x": -10,
      "y": 3,
      "z": -1,
      "name": "Rock_Sandstone_Cobble"
    },
    {
      "x": -10,
      "y": 4,
      "z": -1,
      "name": "Rock_Sandstone"
    },
    {
      "x": -10,
      "y": 5,
      "z": -1,
      "name": "Rock_Sandstone"
    },
    {
      "x": -10,
      "y": 6,
      "z": -1,
      "name": "Rock_Sandstone"
    },
    {
      "x": -10,
      "y": 7,
      "z": -1,
      "name": "Rock_Sandstone"
    },
    {
      "x": -10,
      "y": 8,
      "z": -1,
      "name": "Rock_Sandstone_Cobble"
    },
    {
      "x": -10,
      "y": 9,
      "z": -1,
      "name": "Rock_Sandstone_Cobble"
    },
    {
      "x": -10,
      "y": 10,
      "z": -1,
      "name": "Rock_Sandstone"
    },
    {
      "x": -10,
      "y": 11,
      "z": -1,
      "name": "Rock_Sandstone_Cobble"
    },
    {
      "x": -10,
      "y": 12,
      "z": -1,
      "name": "Wood_Dry_Trunk",
      "support": 15,
      "rotation": 4
    },
    {
      "x": -10,
      "y": 13,
      "z": -1,
      "name": "Rock_Sandstone_Red_Cobble_Roof_Shallow",
      "filler": 1,
      "rotation": 3
    },
    {
      "x": -10,
      "y": 0,
      "z": 0,
      "name": "Soil_Gravel_Sand"
    },
    {
      "x": -10,
      "y": 1,
      "z": 0,
      "name": "Soil_Dirt_Dry"
    },
    {
      "x": -10,
      "y": 2,
      "z": 0,
      "name": "Rock_Sandstone_Red_Cobble"
    },
    {
      "x": -10,
      "y": 3,
      "z": 0,
      "name": "Rock_Sandstone_Red_Cobble"
    },
    {
      "x": -10,
      "y": 4,
      "z": 0,
      "name": "Rock_Sandstone_Red_Cobble"
    },
    {
      "x": -10,
      "y": 5,
      "z": 0,
      "name": "Rock_Sandstone_Red_Cobble"
    },
    {
      "x": -10,
      "y": 6,
      "z": 0,
      "name": "Rock_Sandstone_Red_Cobble"
    },
    {
      "x": -10,
      "y": 7,
      "z": 0,
      "name": "Rock_Sandstone_Red_Cobble"
    },
    {
      "x": -10,
      "y": 8,
      "z": 0,
      "name": "Rock_Sandstone_Red_Cobble"
    },
    {
      "x": -10,
      "y": 9,
      "z": 0,
      "name": "Rock_Sandstone_Red_Cobble"
    },
    {
      "x": -10,
      "y": 10,
      "z": 0,
      "name": "Rock_Sandstone_Red_Cobble"
    },
    {
      "x": -10,
      "y": 11,
      "z": 0,
      "name": "Rock_Sandstone"
    },
    {
      "x": -10,
      "y": 12,
      "z": 0,
      "name": "Wood_Dry_Trunk",
      "support": 15,
      "rotation": 4
    },
    {
      "x": -10,
      "y": 13,
      "z": 0,
      "name": "Rock_Sandstone_Red_Cobble_Roof_Shallow",
      "filler": 1,
      "rotation": 3
    },
    {
      "x": -10,
      "y": 0,
      "z": 1,
      "name": "Soil_Gravel_Sand"
    },
    {
      "x": -10,
      "y": 1,
      "z": 1,
      "name": "Soil_Dirt_Dry"
    },
    {
      "x": -10,
      "y": 2,
      "z": 1,
      "name": "Rock_Sandstone_Red_Cobble"
    },
    {
      "x": -10,
      "y": 3,
      "z": 1,
      "name": "Rock_Sandstone_Red_Cobble"
    },
    {
      "x": -10,
      "y": 4,
      "z": 1,
      "name": "Rock_Sandstone_Red_Cobble"
    },
    {
      "x": -10,
      "y": 5,
      "z": 1,
      "name": "Rock_Sandstone_Red_Cobble"
    },
    {
      "x": -10,
      "y": 6,
      "z": 1,
      "name": "Rock_Sandstone_Red_Cobble"
    },
    {
      "x": -10,
      "y": 7,
      "z": 1,
      "name": "Rock_Sandstone_Red_Cobble"
    },
    {
      "x": -10,
      "y": 8,
      "z": 1,
      "name": "Rock_Sandstone_Red_Cobble"
    },
    {
      "x": -10,
      "y": 9,
      "z": 1,
      "name": "Rock_Sandstone_Red_Cobble"
    },
    {
      "x": -10,
      "y": 10,
      "z": 1,
      "name": "Rock_Sandstone_Red_Cobble"
    },
    {
      "x": -10,
      "y": 11,
      "z": 1,
      "name": "Rock_Sandstone"
    },
    {
      "x": -10,
      "y": 12,
      "z": 1,
      "name": "Wood_Dry_Trunk",
      "support": 15,
      "rotation": 4
    },
    {
      "x": -10,
      "y": 13,
      "z": 1,
      "name": "Rock_Sandstone_Red_Cobble_Roof_Shallow",
      "filler": 1,
      "rotation": 3
    },
    {
      "x": -10,
      "y": 0,
      "z": 2,
      "name": "Soil_Gravel_Sand"
    },
    {
      "x": -10,
      "y": 1,
      "z": 2,
      "name": "Soil_Dirt_Dry"
    },
    {
      "x": -10,
      "y": 2,
      "z": 2,
      "name": "Wood_Dry_Trunk"
    },
    {
      "x": -10,
      "y": 3,
      "z": 2,
      "name": "Rock_Sandstone_Red_Cobble"
    },
    {
      "x": -10,
      "y": 4,
      "z": 2,
      "name": "Wood_Dry_Trunk"
    },
    {
      "x": -10,
      "y": 5,
      "z": 2,
      "name": "Wood_Dry_Trunk"
    },
    {
      "x": -10,
      "y": 6,
      "z": 2,
      "name": "Wood_Dry_Trunk"
    },
    {
      "x": -10,
      "y": 7,
      "z": 2,
      "name": "Wood_Dry_Trunk"
    },
    {
      "x": -10,
      "y": 8,
      "z": 2,
      "name": "Wood_Dry_Trunk"
    },
    {
      "x": -10,
      "y": 9,
      "z": 2,
      "name": "Wood_Dry_Trunk"
    },
    {
      "x": -10,
      "y": 10,
      "z": 2,
      "name": "Rock_Sandstone_Red_Cobble"
    },
    {
      "x": -10,
      "y": 11,
      "z": 2,
      "name": "Wood_Dry_Trunk"
    },
    {
      "x": -10,
      "y": 12,
      "z": 2,
      "name": "Wood_Dry_Trunk"
    },
    {
      "x": -10,
      "y": 13,
      "z": 2,
      "name": "Wood_Dry_Trunk"
    },
    {
      "x": -10,
      "y": 14,
      "z": 2,
      "name": "Wood_Dry_Trunk",
      "support": 15
    },
    {
      "x": -10,
      "y": 15,
      "z": 2,
      "name": "Wood_Dry_Branch_Long",
      "support": 15
    },
    {
      "x": -10,
      "y": 16,
      "z": 2,
      "name": "Survival_Trap_Spike_Wood_Large"
    },
    {
      "x": -10,
      "y": 0,
      "z": 3,
      "name": "Soil_Gravel_Sand"
    },
    {
      "x": -10,
      "y": 1,
      "z": 3,
      "name": "Soil_Dirt_Dry"
    },
    {
      "x": -10,
      "y": 2,
      "z": 3,
      "name": "Wood_Dry_Trunk"
    },
    {
      "x": -10,
      "y": 3,
      "z": 3,
      "name": "Wood_Dry_Trunk"
    },
    {
      "x": -10,
      "y": 4,
      "z": 3,
      "name": "Wood_Dry_Trunk"
    },
    {
      "x": -10,
      "y": 5,
      "z": 3,
      "name": "Wood_Dry_Trunk"
    },
    {
      "x": -10,
      "y": 6,
      "z": 3,
      "name": "Wood_Dry_Trunk"
    },
    {
      "x": -10,
      "y": 7,
      "z": 3,
      "name": "Wood_Dry_Trunk"
    },
    {
      "x": -10,
      "y": 8,
      "z": 3,
      "name": "Wood_Dry_Trunk"
    },
    {
      "x": -10,
      "y": 9,
      "z": 3,
      "name": "Wood_Dry_Trunk"
    },
    {
      "x": -10,
      "y": 10,
      "z": 3,
      "name": "Wood_Dry_Trunk"
    },
    {
      "x": -10,
      "y": 11,
      "z": 3,
      "name": "Wood_Dry_Trunk"
    },
    {
      "x": -10,
      "y": 12,
      "z": 3,
      "name": "Wood_Dry_Trunk"
    },
    {
      "x": -10,
      "y": 13,
      "z": 3,
      "name": "Wood_Dry_Trunk"
    },
    {
      "x": -10,
      "y": 14,
      "z": 3,
      "name": "Wood_Dry_Trunk",
      "support": 15
    },
    {
      "x": -10,
      "y": 15,
      "z": 3,
      "name": "Wood_Dry_Trunk",
      "support": 15
    },
    {
      "x": -10,
      "y": 16,
      "z": 3,
      "name": "Furniture_Village_Brazier"
    },
    {
      "x": -10,
      "y": 0,
      "z": 4,
      "name": "Soil_Gravel_Sand"
    },
    {
      "x": -10,
      "y": 1,
      "z": 4,
      "name": "Soil_Dirt_Dry"
    },
    {
      "x": -10,
      "y": 2,
      "z": 4,
      "name": "Wood_Dry_Trunk"
    },
    {
      "x": -10,
      "y": 3,
      "z": 4,
      "name": "Wood_Dry_Trunk"
    },
    {
      "x": -10,
      "y": 5,
      "z": 4,
      "name": "Wood_Dry_Trunk"
    },
    {
      "x": -10,
      "y": 6,
      "z": 4,
      "name": "Wood_Dry_Trunk"
    },
    {
      "x": -10,
      "y": 7,
      "z": 4,
      "name": "Wood_Dry_Trunk"
    },
    {
      "x": -10,
      "y": 8,
      "z": 4,
      "name": "Wood_Dry_Trunk"
    },
    {
      "x": -10,
      "y": 9,
      "z": 4,
      "name": "Wood_Dry_Trunk"
    },
    {
      "x": -10,
      "y": 11,
      "z": 4,
      "name": "Wood_Dry_Trunk"
    },
    {
      "x": -10,
      "y": 12,
      "z": 4,
      "name": "Wood_Dry_Trunk"
    },
    {
      "x": -10,
      "y": 13,
      "z": 4,
      "name": "Wood_Dry_Trunk"
    },
    {
      "x": -10,
      "y": 14,
      "z": 4,
      "name": "Wood_Dry_Trunk",
      "support": 15
    },
    {
      "x": -10,
      "y": 15,
      "z": 4,
      "name": "Wood_Dry_Branch_Long",
      "support": 15
    },
    {
      "x": -10,
      "y": 16,
      "z": 4,
      "name": "Survival_Trap_Spike_Wood_Large"
    },
    {
      "x": -10,
      "y": 0,
      "z": 5,
      "name": "Soil_Gravel_Sand"
    },
    {
      "x": -10,
      "y": 1,
      "z": 5,
      "name": "Soil_Dirt_Dry"
    },
    {
      "x": -10,
      "y": 11,
      "z": 5,
      "name": "Rock_Sandstone_Red_Brick"
    },
    {
      "x": -10,
      "y": 12,
      "z": 5,
      "name": "*Rock_Sandstone_Red_Cobble_Roof_State_Definitions_Inverted_Corner_Right"
    },
    {
      "x": -10,
      "y": 0,
      "z": 6,
      "name": "Soil_Gravel_Sand"
    },
    {
      "x": -10,
      "y": 1,
      "z": 6,
      "name": "Soil_Dirt_Dry"
    },
    {
      "x": -10,
      "y": 12,
      "z": 6,
      "name": "*Rock_Sandstone_Red_Cobble_Roof_Hollow_State_Definitions_Corner_Left",
      "rotation": 3
    },
    {
      "x": -10,
      "y": 0,
      "z": 7,
      "name": "Soil_Gravel_Sand"
    },
    {
      "x": -10,
      "y": 1,
      "z": 7,
      "name": "Soil_Dirt_Dry"
    },
    {
      "x": -10,
      "y": 0,
      "z": 8,
      "name": "Soil_Gravel_Sand"
    },
    {
      "x": -10,
      "y": 1,
      "z": 8,
      "name": "Soil_Dirt_Dry"
    },
    {
      "x": -10,
      "y": 2,
      "z": 8,
      "name": "Deco_Bone_Full"
    },
    {
      "x": -10,
      "y": 0,
      "z": 9,
      "name": "Soil_Gravel_Sand"
    },
    {
      "x": -10,
      "y": 1,
      "z": 9,
      "name": "Soil_Dirt_Dry"
    },
    {
      "x": -10,
      "y": 2,
      "z": 9,
      "name": "Deco_Bone_Full"
    },
    {
      "x": -10,
      "y": 3,
      "z": 9,
      "name": "Deco_Bone_Full"
    },
    {
      "x": -10,
      "y": 0,
      "z": 10,
      "name": "Soil_Gravel_Sand"
    },
    {
      "x": -10,
      "y": 1,
      "z": 10,
      "name": "Soil_Dirt_Dry"
    },
    {
      "x": -10,
      "y": 0,
      "z": 11,
      "name": "Soil_Gravel_Sand"
    },
    {
      "x": -10,
      "y": 1,
      "z": 11,
      "name": "Soil_Dirt_Dry"
    },
    {
      "x": -10,
      "y": 0,
      "z": 12,
      "name": "Soil_Gravel_Sand"
    },
    {
      "x": -10,
      "y": 1,
      "z": 12,
      "name": "Soil_Dirt_Dry"
    },
    {
      "x": -10,
      "y": 0,
      "z": 13,
      "name": "Soil_Gravel_Sand"
    },
    {
      "x": -10,
      "y": 1,
      "z": 13,
      "name": "Soil_Dirt_Dry"
    },
    {
      "x": -10,
      "y": 0,
      "z": 14,
      "name": "Soil_Gravel_Sand"
    },
    {
      "x": -10,
      "y": 1,
      "z": 14,
      "name": "Soil_Dirt_Dry"
    },
    {
      "x": -10,
      "y": 0,
      "z": 15,
      "name": "Soil_Gravel_Sand"
    },
    {
      "x": -10,
      "y": 1,
      "z": 15,
      "name": "Soil_Dirt_Dry"
    },
    {
      "x": -9,
      "y": 0,
      "z": -15,
      "name": "Soil_Gravel_Sand"
    },
    {
      "x": -9,
      "y": 1,
      "z": -15,
      "name": "Soil_Dirt_Dry"
    },
    {
      "x": -9,
      "y": 0,
      "z": -14,
      "name": "Soil_Gravel_Sand"
    },
    {
      "x": -9,
      "y": 1,
      "z": -14,
      "name": "Soil_Dirt_Dry"
    },
    {
      "x": -9,
      "y": 11,
      "z": -14,
      "name": "Rock_Sandstone_Red_Brick_Half",
      "rotation": 6
    },
    {
      "x": -9,
      "y": 12,
      "z": -14,
      "name": "Rock_Sandstone_Red_Cobble_Roof_Hollow",
      "rotation": 2
    },
    {
      "x": -9,
      "y": 0,
      "z": -13,
      "name": "Soil_Gravel_Sand"
    },
    {
      "x": -9,
      "y": 1,
      "z": -13,
      "name": "Soil_Dirt_Dry"
    },
    {
      "x": -9,
      "y": 2,
      "z": -13,
      "name": "Rock_Sandstone_Red_Cobble"
    },
    {
      "x": -9,
      "y": 3,
      "z": -13,
      "name": "Rock_Sandstone_Red_Cobble"
    },
    {
      "x": -9,
      "y": 4,
      "z": -13,
      "name": "Rock_Sandstone_Red_Cobble"
    },
    {
      "x": -9,
      "y": 5,
      "z": -13,
      "name": "Rock_Sandstone_Red_Cobble"
    },
    {
      "x": -9,
      "y": 6,
      "z": -13,
      "name": "Rock_Sandstone_Red_Cobble"
    },
    {
      "x": -9,
      "y": 7,
      "z": -13,
      "name": "Rock_Sandstone_Red_Cobble"
    },
    {
      "x": -9,
      "y": 8,
      "z": -13,
      "name": "Rock_Sandstone_Red_Cobble"
    },
    {
      "x": -9,
      "y": 9,
      "z": -13,
      "name": "Rock_Sandstone_Red_Cobble"
    },
    {
      "x": -9,
      "y": 10,
      "z": -13,
      "name": "Rock_Sandstone_Red_Cobble"
    },
    {
      "x": -9,
      "y": 11,
      "z": -13,
      "name": "Rock_Sandstone_Red_Cobble"
    },
    {
      "x": -9,
      "y": 12,
      "z": -13,
      "name": "Wood_Dry_Trunk",
      "support": 15,
      "rotation": 5
    },
    {
      "x": -9,
      "y": 13,
      "z": -13,
      "name": "Rock_Sandstone_Red_Cobble_Roof_Flat",
      "rotation": 2
    },
    {
      "x": -9,
      "y": 0,
      "z": -12,
      "name": "Soil_Gravel_Sand"
    },
    {
      "x": -9,
      "y": 1,
      "z": -12,
      "name": "Soil_Dirt_Dry"
    },
    {
      "x": -9,
      "y": 2,
      "z": -12,
      "name": "Wood_Dry_Trunk"
    },
    {
      "x": -9,
      "y": 3,
      "z": -12,
      "name": "Wood_Dry_Trunk"
    },
    {
      "x": -9,
      "y": 4,
      "z": -12,
      "name": "Wood_Dry_Trunk"
    },
    {
      "x": -9,
      "y": 5,
      "z": -12,
      "name": "Wood_Dry_Trunk"
    },
    {
      "x": -9,
      "y": 6,
      "z": -12,
      "name": "Wood_Dry_Trunk"
    },
    {
      "x": -9,
      "y": 7,
      "z": -12,
      "name": "Wood_Dry_Trunk"
    },
    {
      "x": -9,
      "y": 8,
      "z": -12,
      "name": "Wood_Dry_Trunk"
    },
    {
      "x": -9,
      "y": 9,
      "z": -12,
      "name": "Wood_Dry_Trunk"
    },
    {
      "x": -9,
      "y": 10,
      "z": -12,
      "name": "Wood_Dry_Trunk"
    },
    {
      "x": -9,
      "y": 11,
      "z": -12,
      "name": "Wood_Dry_Trunk"
    },
    {
      "x": -9,
      "y": 12,
      "z": -12,
      "name": "Wood_Dry_Trunk"
    },
    {
      "x": -9,
      "y": 13,
      "z": -12,
      "name": "Wood_Dry_Trunk"
    },
    {
      "x": -9,
      "y": 14,
      "z": -12,
      "name": "Wood_Dry_Trunk",
      "support": 15
    },
    {
      "x": -9,
      "y": 15,
      "z": -12,
      "name": "Wood_Dry_Branch_Long",
      "support": 15
    },
    {
      "x": -9,
      "y": 16,
      "z": -12,
      "name": "Survival_Trap_Spike_Wood_Large"
    },
    {
      "x": -9,
      "y": 0,
      "z": -11,
      "name": "Soil_Gravel_Sand"
    },
    {
      "x": -9,
      "y": 1,
      "z": -11,
      "name": "Soil_Dirt_Dry"
    },
    {
      "x": -9,
      "y": 2,
      "z": -11,
      "name": "Rock_Sandstone_Red_Cobble"
    },
    {
      "x": -9,
      "y": 3,
      "z": -11,
      "name": "Rock_Sandstone_Red_Cobble"
    },
    {
      "x": -9,
      "y": 4,
      "z": -11,
      "name": "Rock_Sandstone_Red_Cobble"
    },
    {
      "x": -9,
      "y": 5,
      "z": -11,
      "name": "Rock_Sandstone_Red_Cobble"
    },
    {
      "x": -9,
      "y": 6,
      "z": -11,
      "name": "Rock_Sandstone_Red_Cobble"
    },
    {
      "x": -9,
      "y": 7,
      "z": -11,
      "name": "Rock_Sandstone_Red_Cobble"
    },
    {
      "x": -9,
      "y": 8,
      "z": -11,
      "name": "Rock_Sandstone_Red_Cobble"
    },
    {
      "x": -9,
      "y": 9,
      "z": -11,
      "name": "Rock_Sandstone_Red_Cobble"
    },
    {
      "x": -9,
      "y": 11,
      "z": -11,
      "name": "Rock_Sandstone_Red_Cobble"
    },
    {
      "x": -9,
      "y": 12,
      "z": -11,
      "name": "Wood_Dry_Trunk",
      "support": 15,
      "rotation": 5
    },
    {
      "x": -9,
      "y": 13,
      "z": -11,
      "name": "Wood_Drywood_Planks"
    },
    {
      "x": -9,
      "y": 14,
      "z": -11,
      "name": "Deco_Bone_Full"
    },
    {
      "x": -9,
      "y": 15,
      "z": -11,
      "name": "Deco_Bone_Full"
    },
    {
      "x": -9,
      "y": 16,
      "z": -11,
      "name": "Deco_Bone_Full"
    },
    {
      "x": -9,
      "y": 17,
      "z": -11,
      "name": "Deco_Bone_Full"
    },
    {
      "x": -9,
      "y": 18,
      "z": -11,
      "name": "Deco_Bone_Full"
    },
    {
      "x": -9,
      "y": 19,
      "z": -11,
      "name": "Deco_Bone_Full"
    },
    {
      "x": -9,
      "y": 20,
      "z": -11,
      "name": "Deco_Bone_Spike_Large"
    },
    {
      "x": -9,
      "y": 0,
      "z": -10,
      "name": "Soil_Gravel_Sand"
    },
    {
      "x": -9,
      "y": 1,
      "z": -10,
      "name": "Soil_Dirt_Dry"
    },
    {
      "x": -9,
      "y": 2,
      "z": -10,
      "name": "Rock_Sandstone"
    },
    {
      "x": -9,
      "y": 3,
      "z": -10,
      "name": "Rock_Sandstone"
    },
    {
      "x": -9,
      "y": 4,
      "z": -10,
      "name": "Rock_Sandstone"
    },
    {
      "x": -9,
      "y": 5,
      "z": -10,
      "name": "Rock_Sandstone"
    },
    {
      "x": -9,
      "y": 6,
      "z": -10,
      "name": "Rock_Sandstone_Cobble"
    },
    {
      "x": -9,
      "y": 7,
      "z": -10,
      "name": "Rock_Sandstone"
    },
    {
      "x": -9,
      "y": 8,
      "z": -10,
      "name": "Rock_Sandstone"
    },
    {
      "x": -9,
      "y": 9,
      "z": -10,
      "name": "Rock_Sandstone"
    },
    {
      "x": -9,
      "y": 10,
      "z": -10,
      "name": "Rock_Sandstone_Cobble"
    },
    {
      "x": -9,
      "y": 11,
      "z": -10,
      "name": "Rock_Sandstone"
    },
    {
      "x": -9,
      "y": 12,
      "z": -10,
      "name": "Wood_Dry_Trunk",
      "support": 15,
      "rotation": 4
    },
    {
      "x": -9,
      "y": 13,
      "z": -10,
      "name": "Wood_Drywood_Planks"
    },
    {
      "x": -9,
      "y": 14,
      "z": -10,
      "name": "Deco_Bone_Full"
    },
    {
      "x": -9,
      "y": 15,
      "z": -10,
      "name": "Deco_Bone_Full"
    },
    {
      "x": -9,
      "y": 18,
      "z": -10,
      "name": "Deco_Bone_Full"
